Workbook

Sheet Index
A1: GDX index
A6: Type | B6: Name | C6: Location | D6: Row | E6: Column
D7: rdim | E7: cdim
A8: dset | B8: mac | C8: sets!a7 | D8: 1
A9: dset | B9: sac | C9: sets!b7 | D9: 1
A10: dset | B10: ac | C10: sets!c7 | D10: 1
A11: dset | B11: a | C11: sets!d7 | D11: 1
A12: dset | B12: c | C12: sets!e7 | D12: 1
A13: dset | B13: f | C13: sets!f7 | D13: 1
A14: dset | B14: t | C14: sets!g7 | D14: 1
A15: set | B15: mapac | C15: sets!d7 | D15: 2 | F15: values=nodata
A16: set | B16: mapmac | C16: sets!j7 | D16: 2 | F16: values=nodata
A17: par | B17: msam | C17: mac!a7 | D17: 1 | E17: 1
A18: par | B18: sut | C18: sut!b7 | D18: 1 | E18: 1
A19: par | B19: use | C19: use!b7 | D19: 1 | E19: 1
A20: par | B20: supply | C20: sup!b7 | D20: 1 | E20: 1

Sheet Sets
A1: Sets
A4: Macro | B4: SUT | C4: Micro | D4: Activities | E4: Commodities | F4: Factors | G4: Taxes | J4: Macro-Micro
A5: accounts | B5: accounts | C5: accounts | J5: MAPMAC
A6: MAC | B6: SAC | C6: AC | D6: A | E6: C | F6: F | G6: T | J6: MAC | K6: AC
A7: mact | B7: prd | C7: asorg | D7: asorg | E7: csorg | F7: flab | G7: atax | J7: mact | K7: asorg
A8: mcom | B8: trd_imp | C8: amaiz | D8: amaiz | E8: cmaiz | F8: flnd | G8: ctax | J8: mact | K8: amaiz
A9: mtrc | B9: tax_prd | C9: awhea | D9: awhea | E9: cwhea | F9: fcap | G9: dtax | J9: mact | K9: awhea
A10: mlab | B10: tax_imp | C10: arice | D10: arice | E10: crice | G10: etax | J10: mact | K10: arice
A11: mlnd | B11: tax_exp | C11: aocer | D11: aocer | E11: cocer | G11: ftax | J11: mact | K11: aocer
A12: mcap | B12: tax_exm | C12: aipot | D12: aipot | E12: cipot | G12: mtax | J12: mact | K12: aipot
A13: ment | B13: tax_sal | C13: aspot | D13: aspot | E13: cspot | G13: stax | J13: mact | K13: aspot
A14: mhhd | B14: tax_vat | C14: acass | D14: acass | E14: ccass | G14: vtax | J14: mact | K14: acass
A15: mgov | B15: tax_exd | C15: aroot | D15: aroot | E15: croot | G15: xtax | J15: mact | K15: aroot
A16: matx | B16: trc_rec | C16: abean | D16: abean | E16: cbean | J16: mact | K16: abean
A17: mctx | B17: tot_sup | C17: apeas | D17: apeas | E17: cpeas | J17: mact | K17: apeas
A18: mdtx | B18: tot_dem | C18: avege | D18: avege | E18: cvege | J18: mact | K18: avege
A19: metx | B19: int | C19: abanb | D19: abanb | E19: cbanb | J19: mact | K19: abanb
A20: mftx | B20: trc_pay | C20: abanc | D20: abanc | E20: cbanc | J20: mact | K20: abanc
A21: mmtx | B21: con_prv | C21: abans | D21: abans | E21: cbans | J21: mact | K21: abans
A22: mstx | B22: con_pub | C22: afrui | D22: afrui | E22: cfrui | J22: mact | K22: afrui
A23: mvtx | B23: inv_dem | C23: agnut | D23: agnut | E23: cgnut | J23: mact | K23: agnut
A24: mxtx | B24: inv_gov | C24: asoya | D24: asoya | E24: csoya | J24: mact | K24: asoya
A25: ms-i | B25: inv_stk | C25: aoils | D25: aoils | E25: coils | J25: mact | K25: aoils
A26: mg-i | B26: trd_exp | C26: acoff | D26: acoff | E26: ccoff | J26: mact | K26: acoff
A27: mstk | C27: ateal | D27: ateal | E27: cteal | J27: mact | K27: ateal
A28: mrow | C28: atoba | D28: atoba | E28: ctoba | J28: mact | K28: atoba
A29: mtot | C29: asugr | D29: asugr | E29: csugr | J29: mact | K29: asugr
C30: apyre | D30: apyre | E30: cpyre | J30: mact | K30: apyre
C31: aocrp | D31: aocrp | E31: cocrp | J31: mact | K31: aocrp
C32: acatt | D32: acatt | E32: ccatt | J32: mact | K32: acatt
C33: asmlr | D33: asmlr | E33: csmlr | J33: mact | K33: asmlr
C34: apoul | D34: apoul | E34: cpoul | J34: mact | K34: apoul
C35: aoliv | D35: aoliv | E35: coliv | J35: mact | K35: aoliv
C36: amilk | D36: amilk | E36: cmilk | J36: mact | K36: amilk
C37: aeggs | D37: aeggs | E37: ceggs | J37: mact | K37: aeggs
C38: ahony | D38: ahony | E38: chony | J38: mact | K38: ahony
C39: ahunt | D39: ahunt | E39: chunt | J39: mact | K39: ahunt
C40: afuel | D40: afuel | E40: cfuel | J40: mact | K40: afuel
C41: achar | D41: achar | E41: cchar | J41: mact | K41: achar
... C110: atrdc | D110: atrdc | E110: ctrdc | J110: mact | K110: atrdc
...

Sheet Notes
A1: =CONCATENATE(B5," ",C4," SAM") -> 2024 Rwanda SAM
A2: Use with 1construct.gms and 2balance.gms
A4: Country | B4: RWA | C4: Rwanda
A5: Year | B5: 2024
A6: Units | B6: Billions of Rwanda Francs
A7: Citation
A9: Activities and commodities (N86) | E9: Other accounts
A10: ="a"&MID(B10,2,4) -> asorg | B10: csorg | C10: Sorghum (A111) | E10: trc | F10: Transaction costs
A11: ="a"&MID(B11,2,4) -> amaiz | B11: cmaiz | C11: Maize (A112) | E11: flab | F11: Labor
A12: ="a"&MID(B12,2,4) -> awhea | B12: cwhea | C12: Wheat (A113) | E12: flnd | F12: Land
A13: ="a"&MID(B13,2,4) -> arice | B13: crice | C13: Paddy & husked rice (A116) | E13: fcap | F13: Capital
A14: ="a"&MID(B14,2,4) -> aocer | B14: cocer | C14: Other cereals (A119) | E14: ent | F14: Enterprises
A15: ="a"&MID(B15,2,4) -> aipot | B15: cipot | C15: Irish potatoes (A121) | E15: hhd | F15: Households
A16: ="a"&MID(B16,2,4) -> aspot | B16: cspot | C16: Sweet potatoes (A122) | E16: gov | F16: Government
A17: ="a"&MID(B17,2,4) -> acass | B17: ccass | C17: Cassava (A123) | E17: atax | F17: Taxes - activity (production)
A18: ="a"&MID(B18,2,4) -> aroot | B18: croot | C18: Other roots & tubers (A129) | E18: ctax | F18: Taxes - customs duties (imports)
A19: ="a"&MID(B19,2,4) -> abean | B19: cbean | C19: Dried beans (A131) | E19: dtax | F19: Taxes - direct (corporate, private)
A20: ="a"&MID(B20,2,4) -> apeas | B20: cpeas | C20: Peas & other legumes (A132) | E20: etax | F20: Taxes - exports
A21: ="a"&MID(B21,2,4) -> avege | B21: cvege | C21: Other vegetables (A139) | E21: ftax | F21: Taxes - factors (royalities)
... A29: ="a"&MID(B29,2,4) -> acoff | B29: ccoff | C29: Coffee, not roasted, not decaffeinated (A210) | E29: total | F29: Total
A30: ="a"&MID(B30,2,4) -> ateal | B30: cteal | C30: Tea (unprocessed green leaf) (A220)
A31: ="a"&MID(B31,2,4) -> atoba | B31: ctoba | C31: Tobacco, raw (A291)
A32: ="a"&MID(B32,2,4) -> asugr | B32: csugr | C32: Sugar cane (A292)
A33: ="a"&MID(B33,2,4) -> apyre | B33: cpyre | C33: Pyrethrum (A293)
A34: ="a"&MID(B34,2,4) -> aocrp | B34: cocrp | C34: Agricultural products n.e.c. (A299)
A35: ="a"&MID(B35,2,4) -> acatt | B35: ccatt | C35: Bovine cattle, live (A311)
A36: ="a"&MID(B36,2,4) -> asmlr | B36: csmlr | C36: Sheep, goats, pigs,live (A312)
A37: ="a"&MID(B37,2,4) -> apoul | B37: cpoul | C37: Poultry, live (A313)
A38: ="a"&MID(B38,2,4) -> aoliv | B38: coliv | C38: Other live animals (A319)
A39: ="a"&MID(B39,2,4) -> amilk | B39: cmilk | C39: Raw milk (A321)
A40: ="a"&MID(B40,2,4) -> aeggs | B40: ceggs | C40: Eggs (A322)
A41: ="a"&MID(B41,2,4) -> ahony | B41: chony | C41: Natural honey (A323)
... A113: ="a"&MID(B113,2,4) -> atrdc | B113: ctrdc | C113: Travel debits & credits (V00)

Sheet MAC
A1: Macro SAM
A2: Final values exported to GAMS
B7: mact | C7: mcom | D7: mtrc | E7: mlab | F7: mlnd | G7: mcap | H7: ment | I7: mhhd | J7: mgov | K7: matx | L7: mctx | M7: mdtx | N7: metx | O7: mftx | P7: mmtx | Q7: mstx | R7: mvtx | S7: mxtx | T7: ms-i | U7: mg-i | V7: mstk | W7: mrow | X7: mtot
A8: mact | B8: =wMAC!C5 -> 0 | C8: =wMAC!D5 -> #DIV/0! | D8: =wMAC!E5 -> 0 | E8: =wMAC!F5 -> 0 | F8: =wMAC!G5 -> 0 | G8: =wMAC!H5 -> 0 | H8: =wMAC!I5 -> 0 | I8: =wMAC!J5 -> 0 | ... X8: =wMAC!Y5 -> #DIV/0!
A9: mcom | B9: =wMAC!C6 -> #DIV/0! | C9: =wMAC!D6 -> 0 | D9: =wMAC!E6 -> #DIV/0! | E9: =wMAC!F6 -> 0 | F9: =wMAC!G6 -> 0 | G9: =wMAC!H6 -> 0 | H9: =wMAC!I6 -> 0 | I9: =wMAC!J6 -> #DIV/0! | ... X9: =wMAC!Y6 -> #DIV/0!
A10: mtrc | B10: =wMAC!C7 -> 0 | C10: =wMAC!D7 -> #DIV/0! | D10: =wMAC!E7 -> 0 | E10: =wMAC!F7 -> 0 | F10: =wMAC!G7 -> 0 | G10: =wMAC!H7 -> 0 | H10: =wMAC!I7 -> 0 | I10: =wMAC!J7 -> 0 | ... X10: =wMAC!Y7 -> #DIV/0!
A11: mlab | B11: =wMAC!C8 -> #DIV/0! | C11: =wMAC!D8 -> 0 | D11: =wMAC!E8 -> 0 | E11: =wMAC!F8 -> 0 | F11: =wMAC!G8 -> 0 | G11: =wMAC!H8 -> 0 | H11: =wMAC!I8 -> 0 | I11: =wMAC!J8 -> 0 | ... X11: =wMAC!Y8 -> #DIV/0!
A12: mlnd | B12: =wMAC!C9 -> #DIV/0! | C12: =wMAC!D9 -> 0 | D12: =wMAC!E9 -> 0 | E12: =wMAC!F9 -> 0 | F12: =wMAC!G9 -> 0 | G12: =wMAC!H9 -> 0 | H12: =wMAC!I9 -> 0 | I12: =wMAC!J9 -> 0 | ... X12: =wMAC!Y9 -> #DIV/0!
A13: mcap | B13: =wMAC!C10 -> #DIV/0! | C13: =wMAC!D10 -> 0 | D13: =wMAC!E10 -> 0 | E13: =wMAC!F10 -> 0 | F13: =wMAC!G10 -> 0 | G13: =wMAC!H10 -> 0 | H13: =wMAC!I10 -> 0 | I13: =wMAC!J10 -> 0 | ... X13: =wMAC!Y10 -> #DIV/0!
A14: ment | B14: =wMAC!C11 -> 0 | C14: =wMAC!D11 -> 0 | D14: =wMAC!E11 -> 0 | E14: =wMAC!F11 -> 0 | F14: =wMAC!G11 -> 0 | G14: =wMAC!H11 -> #DIV/0! | H14: =wMAC!I11 -> 0 | I14: =wMAC!J11 -> 0 | ... X14: =wMAC!Y11 -> #DIV/0!
A15: mhhd | B15: =wMAC!C12 -> 0 | C15: =wMAC!D12 -> 0 | D15: =wMAC!E12 -> 0 | E15: =wMAC!F12 -> #DIV/0! | F15: =wMAC!G12 -> #DIV/0! | G15: =wMAC!H12 -> 0 | H15: =wMAC!I12 -> #DIV/0! | I15: =wMAC!J12 -> 0 | ... X15: =wMAC!Y12 -> #DIV/0!
A16: mgov | B16: =wMAC!C13 -> 0 | C16: =wMAC!D13 -> 0 | D16: =wMAC!E13 -> 0 | E16: =wMAC!F13 -> 0 | F16: =wMAC!G13 -> 0 | G16: =wMAC!H13 -> 0 | H16: =wMAC!I13 -> 18.658538 | I16: =wMAC!J13 -> 432.46991 | ... X16: =wMAC!Y13 -> #DIV/0!
A17: matx | B17: =wMAC!C14 -> #DIV/0! | C17: =wMAC!D14 -> 0 | D17: =wMAC!E14 -> 0 | E17: =wMAC!F14 -> 0 | F17: =wMAC!G14 -> 0 | G17: =wMAC!H14 -> 0 | H17: =wMAC!I14 -> 0 | I17: =wMAC!J14 -> 0 | ... X17: =wMAC!Y14 -> #DIV/0!
A18: mctx | B18: =wMAC!C15 -> 0 | C18: =wMAC!D15 -> #DIV/0! | D18: =wMAC!E15 -> 0 | E18: =wMAC!F15 -> 0 | F18: =wMAC!G15 -> 0 | G18: =wMAC!H15 -> 0 | H18: =wMAC!I15 -> 0 | I18: =wMAC!J15 -> 0 | ... X18: =wMAC!Y15 -> #DIV/0!
A19: mdtx | B19: =wMAC!C16 -> 0 | C19: =wMAC!D16 -> 0 | D19: =wMAC!E16 -> 0 | E19: =wMAC!F16 -> 0 | F19: =wMAC!G16 -> 0 | G19: =wMAC!H16 -> 0 | H19: =wMAC!I16 -> 432.89809 | I19: =wMAC!J16 -> 835.09604 | ... X19: =wMAC!Y16 -> 1267.9941
... A30: mtot | B30: =wMAC!C27 -> #DIV/0! | C30: =wMAC!D27 -> #DIV/0! | D30: =wMAC!E27 -> #DIV/0! | E30: =wMAC!F27 -> #DIV/0! | F30: =wMAC!G27 -> #DIV/0! | G30: =wMAC!H27 -> #DIV/0! | H30: =wMAC!I27 -> #DIV/0! | I30: =wMAC!J27 -> #DIV/0! | ... X30: =wMAC!Y27 -> 0

Sheet SUT
A1: Supply-Use Table
A2: Final values exported to GAMS
C4: Gross | D4: Imports | E4: Tax on | F4: Taxes on products | L4: Trans. | M4: Totals | O4: Inter- | P4: Trans. | Q4: Consumption | S4: GCF | V4: Exports | Y4: Differences
C5: output | E5: producers | F5: Customs duties | G5: Exports | H5: Import excise duties | I5: Subsidies (products) | J5: VAT | K5: Excise & Others | L5: costs | M5: Supply | N5: Demand | O5: mediates | P5: costs | Q5: Private | R5: Public | S5: Private | T5: Public | U5: Stocks | Y5: sup-dem | Z5: % sup
B6: Totals | C6: =SUM(C8:C111) -> #DIV/0! | D6: =SUM(D8:D111) -> 0 | E6: =SUM(E8:E111) -> #DIV/0! | F6: =SUM(F8:F111) -> 0 | G6: =SUM(G8:G111) -> 0 | H6: =SUM(H8:H111) -> 0 | I6: =SUM(I8:I111) -> #DIV/0! | K6: =SUM(K8:K111) -> #DIV/0! | L6: =SUM(L8:L111) -> #DIV/0! | M6: =SUM(M8:M111) -> #DIV/0! | N6: =SUM(N8:N111) -> #DIV/0! | O6: =SUM(O8:O111) -> #DIV/0! | P6: =SUM(P8:P111) -> #DIV/0! | Q6: =SUM(Q8:Q111) -> #DIV/0! | R6: =SUM(R8:R111) -> 0 | ... V6: =SUM(V8:V111) -> 0 | Y6: =M6-N6 -> #DIV/0! | Z6: =IF(M6<>0,Y6/M6*100,0) -> #DIV/0! | AC6: Totals | AE6: Differences
C7: prd | D7: trd_imp | E7: tax_prd | F7: tax_imp | G7: tax_exp | H7: tax_exm | I7: tax_sal | J7: tax_vat | K7: tax_exd | L7: trc_rec | M7: tot_sup | N7: tot_dem | O7: int | P7: trc_pay | Q7: con_prv | R7: con_pub | S7: inv_dem | T7: inv_gov | U7: inv_stk | V7: trd_exp | AC7: Supply | AD7: Demand | AE7: sup-dem | AF7: % sup
A8: Sorghum (A111) | B8: csorg | C8: {=TRANSPOSE(SUP!C4:DB4)} -> #DIV/0! | D8: =wTRD!I8 -> 0 | E8: =wTAX!G8 -> #DIV/0! | F8: =wTAX!K8 -> 0 | G8: =wTAX!O8 -> 0 | H8: =wTAX!S8 -> 0 | I8: =wTAX!W8 -> #DIV/0! | J8: =wTAX!AA8 -> #DIV/0! | K8: =wTAX!AE8 -> #DIV/0! | L8: =wTRC!G8 -> #DIV/0! | M8: =SUM(C8:L8) -> #DIV/0! | N8: =SUM(O8:V8) -> #DIV/0! | O8: =SUM(USE!C8:DB8) -> #DIV/0! | P8: =wTRC!K8 -> #DIV/0! | Q8: =wABS!G7 -> #DIV/0! | R8: =wABS!K7 -> 0 | S8: =wABS!O7 -> 0 | T8: =wABS!S7 -> 0 | U8: =wABS!W7 -> 0 | V8: =wTRD!O8 -> 0 | Y8: =M8-N8 -> #DIV/0! | Z8: =IF(M8<>0,Y8/M8*100,0) -> #DIV/0! | AB8: Agriculture | AC8: =SUM(AC9:AC20) -> #DIV/0! | AD8: =SUM(AD9:AD20) -> #DIV/0! | AE8: =AC8-AD8 -> #DIV/0! | AF8: =IF(AC8<>0,AE8/AC8*100,0) -> #DIV/0!
A9: Maize (A112) | B9: cmaiz | C9: #DIV/0! | D9: =wTRD!I9 -> 0 | E9: =wTAX!G9 -> #DIV/0! | F9: =wTAX!K9 -> 0 | G9: =wTAX!O9 -> 0 | H9: =wTAX!S9 -> 0 | I9: =wTAX!W9 -> #DIV/0! | J9: =wTAX!AA9 -> #DIV/0! | K9: =wTAX!AE9 -> #DIV/0! | L9: =wTRC!G9 -> #DIV/0! | M9: =SUM(C9:L9) -> #DIV/0! | N9: =SUM(O9:V9) -> #DIV/0! | O9: =SUM(USE!C9:DB9) -> #DIV/0! | P9: =wTRC!K9 -> #DIV/0! | Q9: =wABS!G8 -> #DIV/0! | R9: =wABS!K8 -> 0 | S9: =wABS!O8 -> 0 | T9: =wABS!S8 -> 0 | U9: =wABS!W8 -> 0 | V9: =wTRD!O9 -> 0 | Y9: =M9-N9 -> #DIV/0! | Z9: =IF(M9<>0,Y9/M9*100,0) -> #DIV/0! | AB9: Cereals | AC9: =SUM(M8:M12) -> #DIV/0! | AD9: =SUM(N8:N12) -> #DIV/0! | AE9: =AC9-AD9 -> #DIV/0! | AF9: =IF(AC9<>0,AE9/AC9*100,0) -> #DIV/0!
A10: Wheat (A113) | B10: cwhea | C10: #DIV/0! | D10: =wTRD!I10 -> 0 | E10: =wTAX!G10 -> #DIV/0! | F10: =wTAX!K10 -> 0 | G10: =wTAX!O10 -> 0 | H10: =wTAX!S10 -> 0 | I10: =wTAX!W10 -> #DIV/0! | J10: =wTAX!AA10 -> #DIV/0! | K10: =wTAX!AE10 -> #DIV/0! | L10: =wTRC!G10 -> #DIV/0! | M10: =SUM(C10:L10) -> #DIV/0! | N10: =SUM(O10:V10) -> #DIV/0! | O10: =SUM(USE!C10:DB10) -> #DIV/0! | P10: =wTRC!K10 -> #DIV/0! | Q10: =wABS!G9 -> #DIV/0! | R10: =wABS!K9 -> 0 | S10: =wABS!O9 -> 0 | T10: =wABS!S9 -> 0 | U10: =wABS!W9 -> 0 | V10: =wTRD!O10 -> 0 | Y10: =M10-N10 -> #DIV/0! | Z10: =IF(M10<>0,Y10/M10*100,0) -> #DIV/0! | AB10: Roots | AC10: =SUM(M13:M16) -> #DIV/0! | AD10: =SUM(N13:N16) -> #DIV/0! | AE10: =AC10-AD10 -> #DIV/0! | AF10: =IF(AC10<>0,AE10/AC10*100,0) -> #DIV/0!
A11: Paddy & husked rice (A116) | B11: crice | C11: #DIV/0! | D11: =wTRD!I11 -> 0 | E11: =wTAX!G11 -> #DIV/0! | F11: =wTAX!K11 -> 0 | G11: =wTAX!O11 -> 0 | H11: =wTAX!S11 -> 0 | I11: =wTAX!W11 -> #DIV/0! | J11: =wTAX!AA11 -> #DIV/0! | K11: =wTAX!AE11 -> #DIV/0! | L11: =wTRC!G11 -> #DIV/0! | M11: =SUM(C11:L11) -> #DIV/0! | N11: =SUM(O11:V11) -> #DIV/0! | O11: =SUM(USE!C11:DB11) -> #DIV/0! | P11: =wTRC!K11 -> #DIV/0! | Q11: =wABS!G10 -> #DIV/0! | R11: =wABS!K10 -> 0 | S11: =wABS!O10 -> 0 | T11: =wABS!S10 -> 0 | U11: =wABS!W10 -> 0 | V11: =wTRD!O11 -> 0 | Y11: =M11-N11 -> #DIV/0! | Z11: =IF(M11<>0,Y11/M11*100,0) -> #DIV/0! | AB11: Vegetables | AC11: =SUM(M17:M19) -> #DIV/0! | AD11: =SUM(N17:N19) -> #DIV/0! | AE11: =AC11-AD11 -> #DIV/0! | AF11: =IF(AC11<>0,AE11/AC11*100,0) -> #DIV/0!
A12: Other cereals (A119) | B12: cocer | C12: #DIV/0! | D12: =wTRD!I12 -> 0 | E12: =wTAX!G12 -> #DIV/0! | F12: =wTAX!K12 -> 0 | G12: =wTAX!O12 -> 0 | H12: =wTAX!S12 -> 0 | I12: =wTAX!W12 -> #DIV/0! | J12: =wTAX!AA12 -> #DIV/0! | K12: =wTAX!AE12 -> #DIV/0! | L12: =wTRC!G12 -> #DIV/0! | M12: =SUM(C12:L12) -> #DIV/0! | N12: =SUM(O12:V12) -> #DIV/0! | O12: =SUM(USE!C12:DB12) -> #DIV/0! | P12: =wTRC!K12 -> #DIV/0! | Q12: =wABS!G11 -> #DIV/0! | R12: =wABS!K11 -> 0 | S12: =wABS!O11 -> 0 | T12: =wABS!S11 -> 0 | U12: =wABS!W11 -> 0 | V12: =wTRD!O12 -> 0 | Y12: =M12-N12 -> #DIV/0! | Z12: =IF(M12<>0,Y12/M12*100,0) -> #DIV/0! | AB12: Bananas and fruit | AC12: =SUM(M20:M23) -> #DIV/0! | AD12: =SUM(N20:N23) -> #DIV/0! | AE12: =AC12-AD12 -> #DIV/0! | AF12: =IF(AC12<>0,AE12/AC12*100,0) -> #DIV/0!
A13: Irish potatoes (A121) | B13: cipot | C13: #DIV/0! | D13: =wTRD!I13 -> 0 | E13: =wTAX!G13 -> #DIV/0! | F13: =wTAX!K13 -> 0 | G13: =wTAX!O13 -> 0 | H13: =wTAX!S13 -> 0 | I13: =wTAX!W13 -> #DIV/0! | J13: =wTAX!AA13 -> #DIV/0! | K13: =wTAX!AE13 -> #DIV/0! | L13: =wTRC!G13 -> #DIV/0! | M13: =SUM(C13:L13) -> #DIV/0! | N13: =SUM(O13:V13) -> #DIV/0! | O13: =SUM(USE!C13:DB13) -> #DIV/0! | P13: =wTRC!K13 -> #DIV/0! | Q13: =wABS!G12 -> #DIV/0! | R13: =wABS!K12 -> 0 | S13: =wABS!O12 -> 0 | T13: =wABS!S12 -> 0 | U13: =wABS!W12 -> 0 | V13: =wTRD!O13 -> 0 | Y13: =M13-N13 -> #DIV/0! | Z13: =IF(M13<>0,Y13/M13*100,0) -> #DIV/0! | AB13: Oil seeds n.e.c. and oleaginous fruit | AC13: =SUM(M24:M26) -> #DIV/0! | AD13: =SUM(N24:N26) -> #DIV/0! | AE13: =AC13-AD13 -> #DIV/0! | AF13: =IF(AC13<>0,AE13/AC13*100,0) -> #DIV/0!
A14: Sweet potatoes (A122) | B14: cspot | C14: #DIV/0! | D14: =wTRD!I14 -> 0 | E14: =wTAX!G14 -> #DIV/0! | F14: =wTAX!K14 -> 0 | G14: =wTAX!O14 -> 0 | H14: =wTAX!S14 -> 0 | I14: =wTAX!W14 -> #DIV/0! | J14: =wTAX!AA14 -> #DIV/0! | K14: =wTAX!AE14 -> #DIV/0! | L14: =wTRC!G14 -> #DIV/0! | M14: =SUM(C14:L14) -> #DIV/0! | N14: =SUM(O14:V14) -> #DIV/0! | O14: =SUM(USE!C14:DB14) -> #DIV/0! | P14: =wTRC!K14 -> #DIV/0! | Q14: =wABS!G13 -> #DIV/0! | R14: =wABS!K13 -> 0 | S14: =wABS!O13 -> 0 | T14: =wABS!S13 -> 0 | U14: =wABS!W13 -> 0 | V14: =wTRD!O14 -> 0 | Y14: =M14-N14 -> #DIV/0! | Z14: =IF(M14<>0,Y14/M14*100,0) -> #DIV/0! | AB14: Coffee | AC14: =M27 -> #DIV/0! | AD14: =N27 -> #DIV/0! | AE14: =AC14-AD14 -> #DIV/0! | AF14: =IF(AC14<>0,AE14/AC14*100,0) -> #DIV/0!
A15: Cassava (A123) | B15: ccass | C15: #DIV/0! | D15: =wTRD!I15 -> 0 | E15: =wTAX!G15 -> #DIV/0! | F15: =wTAX!K15 -> 0 | G15: =wTAX!O15 -> 0 | H15: =wTAX!S15 -> 0 | I15: =wTAX!W15 -> #DIV/0! | J15: =wTAX!AA15 -> #DIV/0! | K15: =wTAX!AE15 -> #DIV/0! | L15: =wTRC!G15 -> #DIV/0! | M15: =SUM(C15:L15) -> #DIV/0! | N15: =SUM(O15:V15) -> #DIV/0! | O15: =SUM(USE!C15:DB15) -> #DIV/0! | P15: =wTRC!K15 -> #DIV/0! | Q15: =wABS!G14 -> #DIV/0! | R15: =wABS!K14 -> 0 | S15: =wABS!O14 -> 0 | T15: =wABS!S14 -> 0 | U15: =wABS!W14 -> 0 | V15: =wTRD!O15 -> 0 | Y15: =M15-N15 -> #DIV/0! | Z15: =IF(M15<>0,Y15/M15*100,0) -> #DIV/0! | AB15: Tea (unprocessed green leaf) | AC15: =M28 -> #DIV/0! | AD15: =N28 -> #DIV/0! | AE15: =AC15-AD15 -> #DIV/0! | AF15: =IF(AC15<>0,AE15/AC15*100,0) -> #DIV/0!
A16: Other roots & tubers (A129) | B16: croot | C16: #DIV/0! | D16: =wTRD!I16 -> 0 | E16: =wTAX!G16 -> #DIV/0! | F16: =wTAX!K16 -> 0 | G16: =wTAX!O16 -> 0 | H16: =wTAX!S16 -> 0 | I16: =wTAX!W16 -> #DIV/0! | J16: =wTAX!AA16 -> #DIV/0! | K16: =wTAX!AE16 -> #DIV/0! | L16: =wTRC!G16 -> #DIV/0! | M16: =SUM(C16:L16) -> #DIV/0! | N16: =SUM(O16:V16) -> #DIV/0! | O16: =SUM(USE!C16:DB16) -> #DIV/0! | P16: =wTRC!K16 -> #DIV/0! | Q16: =wABS!G15 -> #DIV/0! | R16: =wABS!K15 -> 0 | S16: =wABS!O15 -> 0 | T16: =wABS!S15 -> 0 | U16: =wABS!W15 -> 0 | V16: =wTRD!O16 -> 0 | Y16: =M16-N16 -> #DIV/0! | Z16: =IF(M16<>0,Y16/M16*100,0) -> #DIV/0! | AB16: Other agricultural products | AC16: =SUM(M29:M32) -> #DIV/0! | AD16: =SUM(N29:N32) -> #DIV/0! | AE16: =AC16-AD16 -> #DIV/0! | AF16: =IF(AC16<>0,AE16/AC16*100,0) -> #DIV/0!
A17: Dried beans (A131) | B17: cbean | C17: #DIV/0! | D17: =wTRD!I17 -> 0 | E17: =wTAX!G17 -> #DIV/0! | F17: =wTAX!K17 -> 0 | G17: =wTAX!O17 -> 0 | H17: =wTAX!S17 -> 0 | I17: =wTAX!W17 -> #DIV/0! | J17: =wTAX!AA17 -> #DIV/0! | K17: =wTAX!AE17 -> #DIV/0! | L17: =wTRC!G17 -> #DIV/0! | M17: =SUM(C17:L17) -> #DIV/0! | N17: =SUM(O17:V17) -> #DIV/0! | O17: =SUM(USE!C17:DB17) -> #DIV/0! | P17: =wTRC!K17 -> #DIV/0! | Q17: =wABS!G16 -> #DIV/0! | R17: =wABS!K16 -> 0 | S17: =wABS!O16 -> 0 | T17: =wABS!S16 -> 0 | U17: =wABS!W16 -> 0 | V17: =wTRD!O17 -> 0 | Y17: =M17-N17 -> #DIV/0! | Z17: =IF(M17<>0,Y17/M17*100,0) -> #DIV/0! | AB17: Livestock | AC17: =SUM(M33:M36) -> #DIV/0! | AD17: =SUM(N33:N36) -> #DIV/0! | AE17: =AC17-AD17 -> #DIV/0! | AF17: =IF(AC17<>0,AE17/AC17*100,0) -> #DIV/0!
A18: Peas & other legumes (A132) | B18: cpeas | C18: #DIV/0! | D18: =wTRD!I18 -> 0 | E18: =wTAX!G18 -> #DIV/0! | F18: =wTAX!K18 -> 0 | G18: =wTAX!O18 -> 0 | H18: =wTAX!S18 -> 0 | I18: =wTAX!W18 -> #DIV/0! | J18: =wTAX!AA18 -> #DIV/0! | K18: =wTAX!AE18 -> #DIV/0! | L18: =wTRC!G18 -> #DIV/0! | M18: =SUM(C18:L18) -> #DIV/0! | N18: =SUM(O18:V18) -> #DIV/0! | O18: =SUM(USE!C18:DB18) -> #DIV/0! | P18: =wTRC!K18 -> #DIV/0! | Q18: =wABS!G17 -> #DIV/0! | R18: =wABS!K17 -> 0 | S18: =wABS!O17 -> 0 | T18: =wABS!S17 -> 0 | U18: =wABS!W17 -> 0 | V18: =wTRD!O18 -> 0 | Y18: =M18-N18 -> #DIV/0! | Z18: =IF(M18<>0,Y18/M18*100,0) -> #DIV/0! | AB18: Livestock and hunting products | AC18: =SUM(M37:M40) -> #DIV/0! | AD18: =SUM(N37:N40) -> #DIV/0! | AE18: =AC18-AD18 -> #DIV/0! | AF18: =IF(AC18<>0,AE18/AC18*100,0) -> #DIV/0!
A19: Other vegetables (A139) | B19: cvege | C19: #DIV/0! | D19: =wTRD!I19 -> 0 | E19: =wTAX!G19 -> #DIV/0! | F19: =wTAX!K19 -> 0 | G19: =wTAX!O19 -> 0 | H19: =wTAX!S19 -> 0 | I19: =wTAX!W19 -> #DIV/0! | J19: =wTAX!AA19 -> #DIV/0! | K19: =wTAX!AE19 -> #DIV/0! | L19: =wTRC!G19 -> #DIV/0! | M19: =SUM(C19:L19) -> #DIV/0! | N19: =SUM(O19:V19) -> #DIV/0! | O19: =SUM(USE!C19:DB19) -> #DIV/0! | P19: =wTRC!K19 -> #DIV/0! | Q19: =wABS!G18 -> #DIV/0! | R19: =wABS!K18 -> 0 | S19: =wABS!O18 -> 0 | T19: =wABS!S18 -> 0 | U19: =wABS!W18 -> 0 | V19: =wTRD!O19 -> 0 | Y19: =M19-N19 -> #DIV/0! | Z19: =IF(M19<>0,Y19/M19*100,0) -> #DIV/0! | AB19: Forestry products | AC19: =SUM(M41:M43) -> #DIV/0! | AD19: =SUM(N41:N43) -> #DIV/0! | AE19: =AC19-AD19 -> #DIV/0! | AF19: =IF(AC19<>0,AE19/AC19*100,0) -> #DIV/0!
A20: Bananas for beer (A141) | B20: cbanb | C20: #DIV/0! | D20: =wTRD!I20 -> 0 | E20: =wTAX!G20 -> #DIV/0! | F20: =wTAX!K20 -> 0 | G20: =wTAX!O20 -> 0 | H20: =wTAX!S20 -> 0 | I20: =wTAX!W20 -> #DIV/0! | J20: =wTAX!AA20 -> #DIV/0! | K20: =wTAX!AE20 -> #DIV/0! | L20: =wTRC!G20 -> #DIV/0! | M20: =SUM(C20:L20) -> #DIV/0! | N20: =SUM(O20:V20) -> #DIV/0! | O20: =SUM(USE!C20:DB20) -> #DIV/0! | P20: =wTRC!K20 -> #DIV/0! | Q20: =wABS!G19 -> #DIV/0! | R20: =wABS!K19 -> 0 | S20: =wABS!O19 -> 0 | T20: =wABS!S19 -> 0 | U20: =wABS!W19 -> 0 | V20: =wTRD!O20 -> 0 | Y20: =M20-N20 -> #DIV/0! | Z20: =IF(M20<>0,Y20/M20*100,0) -> #DIV/0! | AB20: Fishery products | AC20: =SUM(M44) -> #DIV/0! | AD20: =SUM(N44) -> #DIV/0! | AE20: =AC20-AD20 -> #DIV/0! | AF20: =IF(AC20<>0,AE20/AC20*100,0) -> #DIV/0!
A21: Bananas for cooking (A142) | B21: cbanc | C21: #DIV/0! | D21: =wTRD!I21 -> 0 | E21: =wTAX!G21 -> #DIV/0! | F21: =wTAX!K21 -> 0 | G21: =wTAX!O21 -> 0 | H21: =wTAX!S21 -> 0 | I21: =wTAX!W21 -> #DIV/0! | J21: =wTAX!AA21 -> #DIV/0! | K21: =wTAX!AE21 -> #DIV/0! | L21: =wTRC!G21 -> #DIV/0! | M21: =SUM(C21:L21) -> #DIV/0! | N21: =SUM(O21:V21) -> #DIV/0! | O21: =SUM(USE!C21:DB21) -> #DIV/0! | P21: =wTRC!K21 -> #DIV/0! | Q21: =wABS!G20 -> #DIV/0! | R21: =wABS!K20 -> 0 | S21: =wABS!O20 -> 0 | T21: =wABS!S20 -> 0 | U21: =wABS!W20 -> 0 | V21: =wTRD!O21 -> 0 | Y21: =M21-N21 -> #DIV/0! | Z21: =IF(M21<>0,Y21/M21*100,0) -> #DIV/0!
A22: Bananas (sweet) (A143) | B22: cbans | C22: #DIV/0! | D22: =wTRD!I22 -> 0 | E22: =wTAX!G22 -> #DIV/0! | F22: =wTAX!K22 -> 0 | G22: =wTAX!O22 -> 0 | H22: =wTAX!S22 -> 0 | I22: =wTAX!W22 -> #DIV/0! | J22: =wTAX!AA22 -> #DIV/0! | K22: =wTAX!AE22 -> #DIV/0! | L22: =wTRC!G22 -> #DIV/0! | M22: =SUM(C22:L22) -> #DIV/0! | N22: =SUM(O22:V22) -> #DIV/0! | O22: =SUM(USE!C22:DB22) -> #DIV/0! | P22: =wTRC!K22 -> #DIV/0! | Q22: =wABS!G21 -> #DIV/0! | R22: =wABS!K21 -> 0 | S22: =wABS!O21 -> 0 | T22: =wABS!S21 -> 0 | U22: =wABS!W21 -> 0 | V22: =wTRD!O22 -> 0 | Y22: =M22-N22 -> #DIV/0! | Z22: =IF(M22<>0,Y22/M22*100,0) -> #DIV/0!
A23: Other fruit & nuts (A149) | B23: cfrui | C23: #DIV/0! | D23: =wTRD!I23 -> 0 | E23: =wTAX!G23 -> #DIV/0! | F23: =wTAX!K23 -> 0 | G23: =wTAX!O23 -> 0 | H23: =wTAX!S23 -> 0 | I23: =wTAX!W23 -> #DIV/0! | J23: =wTAX!AA23 -> #DIV/0! | K23: =wTAX!AE23 -> #DIV/0! | L23: =wTRC!G23 -> #DIV/0! | M23: =SUM(C23:L23) -> #DIV/0! | N23: =SUM(O23:V23) -> #DIV/0! | O23: =SUM(USE!C23:DB23) -> #DIV/0! | P23: =wTRC!K23 -> #DIV/0! | Q23: =wABS!G22 -> #DIV/0! | R23: =wABS!K22 -> 0 | S23: =wABS!O22 -> 0 | T23: =wABS!S22 -> 0 | U23: =wABS!W22 -> 0 | V23: =wTRD!O23 -> 0 | Y23: =M23-N23 -> #DIV/0! | Z23: =IF(M23<>0,Y23/M23*100,0) -> #DIV/0!
A24: Ground nuts (A151) | B24: cgnut | C24: #DIV/0! | D24: =wTRD!I24 -> 0 | E24: =wTAX!G24 -> #DIV/0! | F24: =wTAX!K24 -> 0 | G24: =wTAX!O24 -> 0 | H24: =wTAX!S24 -> 0 | I24: =wTAX!W24 -> #DIV/0! | J24: =wTAX!AA24 -> #DIV/0! | K24: =wTAX!AE24 -> #DIV/0! | L24: =wTRC!G24 -> #DIV/0! | M24: =SUM(C24:L24) -> #DIV/0! | N24: =SUM(O24:V24) -> #DIV/0! | O24: =SUM(USE!C24:DB24) -> #DIV/0! | P24: =wTRC!K24 -> #DIV/0! | Q24: =wABS!G23 -> #DIV/0! | R24: =wABS!K23 -> 0 | S24: =wABS!O23 -> 0 | T24: =wABS!S23 -> 0 | U24: =wABS!W23 -> 0 | V24: =wTRD!O24 -> 0 | Y24: =M24-N24 -> #DIV/0! | Z24: =IF(M24<>0,Y24/M24*100,0) -> #DIV/0!
A25: Soya (A152) | B25: csoya | C25: #DIV/0! | D25: =wTRD!I25 -> 0 | E25: =wTAX!G25 -> #DIV/0! | F25: =wTAX!K25 -> 0 | G25: =wTAX!O25 -> 0 | H25: =wTAX!S25 -> 0 | I25: =wTAX!W25 -> #DIV/0! | J25: =wTAX!AA25 -> #DIV/0! | K25: =wTAX!AE25 -> #DIV/0! | L25: =wTRC!G25 -> #DIV/0! | M25: =SUM(C25:L25) -> #DIV/0! | N25: =SUM(O25:V25) -> #DIV/0! | O25: =SUM(USE!C25:DB25) -> #DIV/0! | P25: =wTRC!K25 -> #DIV/0! | Q25: =wABS!G24 -> #DIV/0! | R25: =wABS!K24 -> 0 | S25: =wABS!O24 -> 0 | T25: =wABS!S24 -> 0 | U25: =wABS!W24 -> 0 | V25: =wTRD!O25 -> 0 | Y25: =M25-N25 -> #DIV/0! | Z25: =IF(M25<>0,Y25/M25*100,0) -> #DIV/0!
A26: Other oil seeds (A159) | B26: coils | C26: #DIV/0! | D26: =wTRD!I26 -> 0 | E26: =wTAX!G26 -> #DIV/0! | F26: =wTAX!K26 -> 0 | G26: =wTAX!O26 -> 0 | H26: =wTAX!S26 -> 0 | I26: =wTAX!W26 -> #DIV/0! | J26: =wTAX!AA26 -> #DIV/0! | K26: =wTAX!AE26 -> #DIV/0! | L26: =wTRC!G26 -> #DIV/0! | M26: =SUM(C26:L26) -> #DIV/0! | N26: =SUM(O26:V26) -> #DIV/0! | O26: =SUM(USE!C26:DB26) -> #DIV/0! | P26: =wTRC!K26 -> #DIV/0! | Q26: =wABS!G25 -> #DIV/0! | R26: =wABS!K25 -> 0 | S26: =wABS!O25 -> 0 | T26: =wABS!S25 -> 0 | U26: =wABS!W25 -> 0 | V26: =wTRD!O26 -> 0 | Y26: =M26-N26 -> #DIV/0! | Z26: =IF(M26<>0,Y26/M26*100,0) -> #DIV/0!
A27: Coffee, not roasted, not decaffeinated (A210) | B27: ccoff | C27: #DIV/0! | D27: =wTRD!I27 -> 0 | E27: =wTAX!G27 -> #DIV/0! | F27: =wTAX!K27 -> 0 | G27: =wTAX!O27 -> 0 | H27: =wTAX!S27 -> 0 | I27: =wTAX!W27 -> #DIV/0! | J27: =wTAX!AA27 -> #DIV/0! | K27: =wTAX!AE27 -> #DIV/0! | L27: =wTRC!G27 -> #DIV/0! | M27: =SUM(C27:L27) -> #DIV/0! | N27: =SUM(O27:V27) -> #DIV/0! | O27: =SUM(USE!C27:DB27) -> #DIV/0! | P27: =wTRC!K27 -> #DIV/0! | Q27: =wABS!G26 -> #DIV/0! | R27: =wABS!K26 -> 0 | S27: =wABS!O26 -> 0 | T27: =wABS!S26 -> 0 | U27: =wABS!W26 -> 0 | V27: =wTRD!O27 -> 0 | Y27: =M27-N27 -> #DIV/0! | Z27: =IF(M27<>0,Y27/M27*100,0) -> #DIV/0!
A28: Tea (unprocessed green leaf) (A220) | B28: cteal | C28: #DIV/0! | D28: =wTRD!I28 -> 0 | E28: =wTAX!G28 -> #DIV/0! | F28: =wTAX!K28 -> 0 | G28: =wTAX!O28 -> 0 | H28: =wTAX!S28 -> 0 | I28: =wTAX!W28 -> #DIV/0! | J28: =wTAX!AA28 -> #DIV/0! | K28: =wTAX!AE28 -> #DIV/0! | L28: =wTRC!G28 -> #DIV/0! | M28: =SUM(C28:L28) -> #DIV/0! | N28: =SUM(O28:V28) -> #DIV/0! | O28: =SUM(USE!C28:DB28) -> #DIV/0! | P28: =wTRC!K28 -> #DIV/0! | Q28: =wABS!G27 -> #DIV/0! | R28: =wABS!K27 -> 0 | S28: =wABS!O27 -> 0 | T28: =wABS!S27 -> 0 | U28: =wABS!W27 -> 0 | V28: =wTRD!O28 -> 0 | Y28: =M28-N28 -> #DIV/0! | Z28: =IF(M28<>0,Y28/M28*100,0) -> #DIV/0!
A29: Tobacco, raw (A291) | B29: ctoba | C29: #DIV/0! | D29: =wTRD!I29 -> 0 | E29: =wTAX!G29 -> #DIV/0! | F29: =wTAX!K29 -> 0 | G29: =wTAX!O29 -> 0 | H29: =wTAX!S29 -> 0 | I29: =wTAX!W29 -> #DIV/0! | J29: =wTAX!AA29 -> #DIV/0! | K29: =wTAX!AE29 -> #DIV/0! | L29: =wTRC!G29 -> #DIV/0! | M29: =SUM(C29:L29) -> #DIV/0! | N29: =SUM(O29:V29) -> #DIV/0! | O29: =SUM(USE!C29:DB29) -> #DIV/0! | P29: =wTRC!K29 -> #DIV/0! | Q29: =wABS!G28 -> #DIV/0! | R29: =wABS!K28 -> 0 | S29: =wABS!O28 -> 0 | T29: =wABS!S28 -> 0 | U29: =wABS!W28 -> 0 | V29: =wTRD!O29 -> 0 | Y29: =M29-N29 -> #DIV/0! | Z29: =IF(M29<>0,Y29/M29*100,0) -> #DIV/0!
A30: Sugar cane (A292) | B30: csugr | C30: #DIV/0! | D30: =wTRD!I30 -> 0 | E30: =wTAX!G30 -> #DIV/0! | F30: =wTAX!K30 -> 0 | G30: =wTAX!O30 -> 0 | H30: =wTAX!S30 -> 0 | I30: =wTAX!W30 -> #DIV/0! | J30: =wTAX!AA30 -> #DIV/0! | K30: =wTAX!AE30 -> #DIV/0! | L30: =wTRC!G30 -> #DIV/0! | M30: =SUM(C30:L30) -> #DIV/0! | N30: =SUM(O30:V30) -> #DIV/0! | O30: =SUM(USE!C30:DB30) -> #DIV/0! | P30: =wTRC!K30 -> #DIV/0! | Q30: =wABS!G29 -> #DIV/0! | R30: =wABS!K29 -> 0 | S30: =wABS!O29 -> 0 | T30: =wABS!S29 -> 0 | U30: =wABS!W29 -> 0 | V30: =wTRD!O30 -> 0 | Y30: =M30-N30 -> #DIV/0! | Z30: =IF(M30<>0,Y30/M30*100,0) -> #DIV/0!
A31: Pyrethrum (A293) | B31: cpyre | C31: #DIV/0! | D31: =wTRD!I31 -> 0 | E31: =wTAX!G31 -> #DIV/0! | F31: =wTAX!K31 -> 0 | G31: =wTAX!O31 -> 0 | H31: =wTAX!S31 -> 0 | I31: =wTAX!W31 -> #DIV/0! | J31: =wTAX!AA31 -> #DIV/0! | K31: =wTAX!AE31 -> #DIV/0! | L31: =wTRC!G31 -> #DIV/0! | M31: =SUM(C31:L31) -> #DIV/0! | N31: =SUM(O31:V31) -> #DIV/0! | O31: =SUM(USE!C31:DB31) -> #DIV/0! | P31: =wTRC!K31 -> #DIV/0! | Q31: =wABS!G30 -> #DIV/0! | R31: =wABS!K30 -> 0 | S31: =wABS!O30 -> 0 | T31: =wABS!S30 -> 0 | U31: =wABS!W30 -> 0 | V31: =wTRD!O31 -> 0 | Y31: =M31-N31 -> #DIV/0! | Z31: =IF(M31<>0,Y31/M31*100,0) -> #DIV/0!
A32: Agricultural products n.e.c. (A299) | B32: cocrp | C32: #DIV/0! | D32: =wTRD!I32 -> 0 | E32: =wTAX!G32 -> #DIV/0! | F32: =wTAX!K32 -> 0 | G32: =wTAX!O32 -> 0 | H32: =wTAX!S32 -> 0 | I32: =wTAX!W32 -> #DIV/0! | J32: =wTAX!AA32 -> #DIV/0! | K32: =wTAX!AE32 -> #DIV/0! | L32: =wTRC!G32 -> #DIV/0! | M32: =SUM(C32:L32) -> #DIV/0! | N32: =SUM(O32:V32) -> #DIV/0! | O32: =SUM(USE!C32:DB32) -> #DIV/0! | P32: =wTRC!K32 -> #DIV/0! | Q32: =wABS!G31 -> #DIV/0! | R32: =wABS!K31 -> 0 | S32: =wABS!O31 -> 0 | T32: =wABS!S31 -> 0 | U32: =wABS!W31 -> 0 | V32: =wTRD!O32 -> 0 | Y32: =M32-N32 -> #DIV/0! | Z32: =IF(M32<>0,Y32/M32*100,0) -> #DIV/0!
... A99: Architectural and engineering activities (M02) | B99: cenga | C99: #DIV/0! | D99: =wTRD!I99 -> 0 | E99: =wTAX!G99 -> #DIV/0! | F99: =wTAX!K99 -> 0 | G99: =wTAX!O99 -> 0 | H99: =wTAX!S99 -> 0 | I99: =wTAX!W99 -> #DIV/0! | J99: =wTAX!AA99 -> #DIV/0! | K99: =wTAX!AE99 -> #DIV/0! | L99: =wTRC!G99 -> #DIV/0! | M99: =SUM(C99:L99) -> #DIV/0! | N99: =SUM(O99:V99) -> #DIV/0! | O99: =SUM(USE!C99:DB99) -> #DIV/0! | P99: =wTRC!K99 -> #DIV/0! | Q99: =wABS!G98 -> #DIV/0! | R99: =wABS!K98 -> 0 | S99: =wABS!O98 -> 0 | T99: =wABS!S98 -> 0 | U99: =wABS!W98 -> 0 | V99: =wTRD!O99 -> 0 | Y99: =M99-N99 -> #DIV/0! | Z99: =IF(M99<>0,Y99/M99*100,0) -> #DIV/0!
A100: Other professional, scientific and technical activities (M03) | B100: cprod | C100: #DIV/0! | D100: =wTRD!I100 -> 0 | E100: =wTAX!G100 -> #DIV/0! | F100: =wTAX!K100 -> 0 | G100: =wTAX!O100 -> 0 | H100: =wTAX!S100 -> 0 | I100: =wTAX!W100 -> #DIV/0! | J100: =wTAX!AA100 -> #DIV/0! | K100: =wTAX!AE100 -> #DIV/0! | L100: =wTRC!G100 -> #DIV/0! | M100: =SUM(C100:L100) -> #DIV/0! | N100: =SUM(O100:V100) -> #DIV/0! | O100: =SUM(USE!C100:DB100) -> #DIV/0! | P100: =wTRC!K100 -> #DIV/0! | Q100: =wABS!G99 -> #DIV/0! | R100: =wABS!K99 -> 0 | S100: =wABS!O99 -> 0 | T100: =wABS!S99 -> 0 | U100: =wABS!W99 -> 0 | V100: =wTRD!O100 -> 0 | W100: xxx | Y100: =M100-N100 -> #DIV/0! | Z100: =IF(M100<>0,Y100/M100*100,0) -> #DIV/0!
A101: Travel agents and tour operators (N01) | B101: ctrvl | C101: #DIV/0! | D101: =wTRD!I101 -> 0 | E101: =wTAX!G101 -> #DIV/0! | F101: =wTAX!K101 -> 0 | G101: =wTAX!O101 -> 0 | H101: =wTAX!S101 -> 0 | I101: =wTAX!W101 -> #DIV/0! | J101: =wTAX!AA101 -> #DIV/0! | K101: =wTAX!AE101 -> #DIV/0! | L101: =wTRC!G101 -> #DIV/0! | M101: =SUM(C101:L101) -> #DIV/0! | N101: =SUM(O101:V101) -> #DIV/0! | O101: =SUM(USE!C101:DB101) -> #DIV/0! | P101: =wTRC!K101 -> #DIV/0! | Q101: =wABS!G100 -> #DIV/0! | R101: =wABS!K100 -> 0 | S101: =wABS!O100 -> 0 | T101: =wABS!S100 -> 0 | U101: =wABS!W100 -> 0 | V101: =wTRD!O101 -> 0 | Y101: =M101-N101 -> #DIV/0! | Z101: =IF(M101<>0,Y101/M101*100,0) -> #DIV/0!
A102: Other administrative and support service activities (N09) | B102: cobsv | C102: #DIV/0! | D102: =wTRD!I102 -> 0 | E102: =wTAX!G102 -> #DIV/0! | F102: =wTAX!K102 -> 0 | G102: =wTAX!O102 -> 0 | H102: =wTAX!S102 -> 0 | I102: =wTAX!W102 -> #DIV/0! | J102: =wTAX!AA102 -> #DIV/0! | K102: =wTAX!AE102 -> #DIV/0! | L102: =wTRC!G102 -> #DIV/0! | M102: =SUM(C102:L102) -> #DIV/0! | N102: =SUM(O102:V102) -> #DIV/0! | O102: =SUM(USE!C102:DB102) -> #DIV/0! | P102: =wTRC!K102 -> #DIV/0! | Q102: =wABS!G101 -> #DIV/0! | R102: =wABS!K101 -> 0 | S102: =wABS!O101 -> 0 | T102: =wABS!S101 -> 0 | U102: =wABS!W101 -> 0 | V102: =wTRD!O102 -> 0 | Y102: =M102-N102 -> #DIV/0! | Z102: =IF(M102<>0,Y102/M102*100,0) -> #DIV/0!
A103: Public administration and defence; compulsory social security (O00) | B103: cpadm | C103: #DIV/0! | D103: =wTRD!I103 -> 0 | E103: =wTAX!G103 -> #DIV/0! | F103: =wTAX!K103 -> 0 | G103: =wTAX!O103 -> 0 | H103: =wTAX!S103 -> 0 | I103: =wTAX!W103 -> #DIV/0! | J103: =wTAX!AA103 -> #DIV/0! | K103: =wTAX!AE103 -> #DIV/0! | L103: =wTRC!G103 -> #DIV/0! | M103: =SUM(C103:L103) -> #DIV/0! | N103: =SUM(O103:V103) -> #DIV/0! | O103: =SUM(USE!C103:DB103) -> #DIV/0! | P103: =wTRC!K103 -> #DIV/0! | Q103: =wABS!G102 -> #DIV/0! | R103: =wABS!K102 -> 0 | S103: =wABS!O102 -> 0 | T103: =wABS!S102 -> 0 | U103: =wABS!W102 -> 0 | V103: =wTRD!O103 -> 0 | Y103: =M103-N103 -> #DIV/0! | Z103: =IF(M103<>0,Y103/M103*100,0) -> #DIV/0!
A104: Education (P00) | B104: ceduc | C104: #DIV/0! | D104: =wTRD!I104 -> 0 | E104: =wTAX!G104 -> #DIV/0! | F104: =wTAX!K104 -> 0 | G104: =wTAX!O104 -> 0 | H104: =wTAX!S104 -> 0 | I104: =wTAX!W104 -> #DIV/0! | J104: =wTAX!AA104 -> #DIV/0! | K104: =wTAX!AE104 -> #DIV/0! | L104: =wTRC!G104 -> #DIV/0! | M104: =SUM(C104:L104) -> #DIV/0! | N104: =SUM(O104:V104) -> #DIV/0! | O104: =SUM(USE!C104:DB104) -> #DIV/0! | P104: =wTRC!K104 -> #DIV/0! | Q104: =wABS!G103 -> #DIV/0! | R104: =wABS!K103 -> 0 | S104: =wABS!O103 -> 0 | T104: =wABS!S103 -> 0 | U104: =wABS!W103 -> 0 | V104: =wTRD!O104 -> 0 | Y104: =M104-N104 -> #DIV/0! | Z104: =IF(M104<>0,Y104/M104*100,0) -> #DIV/0!
A105: Human health activities (Q01) | B105: cheal | C105: #DIV/0! | D105: =wTRD!I105 -> 0 | E105: =wTAX!G105 -> #DIV/0! | F105: =wTAX!K105 -> 0 | G105: =wTAX!O105 -> 0 | H105: =wTAX!S105 -> 0 | I105: =wTAX!W105 -> #DIV/0! | J105: =wTAX!AA105 -> #DIV/0! | K105: =wTAX!AE105 -> #DIV/0! | L105: =wTRC!G105 -> #DIV/0! | M105: =SUM(C105:L105) -> #DIV/0! | N105: =SUM(O105:V105) -> #DIV/0! | O105: =SUM(USE!C105:DB105) -> #DIV/0! | P105: =wTRC!K105 -> #DIV/0! | Q105: =wABS!G104 -> #DIV/0! | R105: =wABS!K104 -> 0 | S105: =wABS!O104 -> 0 | T105: =wABS!S104 -> 0 | U105: =wABS!W104 -> 0 | V105: =wTRD!O105 -> 0 | Y105: =M105-N105 -> #DIV/0! | Z105: =IF(M105<>0,Y105/M105*100,0) -> #DIV/0!
A106: Social work activities (Q02) | B106: csocw | C106: #DIV/0! | D106: =wTRD!I106 -> 0 | E106: =wTAX!G106 -> #DIV/0! | F106: =wTAX!K106 -> 0 | G106: =wTAX!O106 -> 0 | H106: =wTAX!S106 -> 0 | I106: =wTAX!W106 -> #DIV/0! | J106: =wTAX!AA106 -> #DIV/0! | K106: =wTAX!AE106 -> #DIV/0! | L106: =wTRC!G106 -> #DIV/0! | M106: =SUM(C106:L106) -> #DIV/0! | N106: =SUM(O106:V106) -> #DIV/0! | O106: =SUM(USE!C106:DB106) -> #DIV/0! | P106: =wTRC!K106 -> #DIV/0! | Q106: =wABS!G105 -> #DIV/0! | R106: =wABS!K105 -> 0 | S106: =wABS!O105 -> 0 | T106: =wABS!S105 -> 0 | U106: =wABS!W105 -> 0 | V106: =wTRD!O106 -> 0 | Y106: =M106-N106 -> #DIV/0! | Z106: =IF(M106<>0,Y106/M106*100,0) -> #DIV/0!
A107: Libraries, archives, museums and other cultural activities (R01) | B107: ccult | C107: #DIV/0! | D107: =wTRD!I107 -> 0 | E107: =wTAX!G107 -> #DIV/0! | F107: =wTAX!K107 -> 0 | G107: =wTAX!O107 -> 0 | H107: =wTAX!S107 -> 0 | I107: =wTAX!W107 -> #DIV/0! | J107: =wTAX!AA107 -> #DIV/0! | K107: =wTAX!AE107 -> #DIV/0! | L107: =wTRC!G107 -> #DIV/0! | M107: =SUM(C107:L107) -> #DIV/0! | N107: =SUM(O107:V107) -> #DIV/0! | O107: =SUM(USE!C107:DB107) -> #DIV/0! | P107: =wTRC!K107 -> #DIV/0! | Q107: =wABS!G106 -> #DIV/0! | R107: =wABS!K106 -> 0 | S107: =wABS!O106 -> 0 | T107: =wABS!S106 -> 0 | U107: =wABS!W106 -> 0 | V107: =wTRD!O107 -> 0 | Y107: =M107-N107 -> #DIV/0! | Z107: =IF(M107<>0,Y107/M107*100,0) -> #DIV/0!
...

Sheet USE
A1: Use Table
A2: Final values exported to GAMS
B3: From w-GDP | C3: {=TRANSPOSE(wGDPp!D8:D111)} -> 21.594729 | D3: 46.224396 | E3: 1.9919861 | F3: 26.906478 | G3: 7.1618331e-05 | H3: 115.17255 | I3: 119.65299 | J3: 77.058038 | K3: 13.498447 | L3: 239.84649 | M3: 520.88434 | N3: 6.7888873 | O3: 7.5439806 | P3: 201.88779 | Q3: 34.792013 | R3: 160.85445 | S3: 2.4697221 | T3: 0.83264683 | U3: 0 | V3: 0 | W3: 0 | X3: 0 | Y3: 0 | Z3: 0 | AA3: 0 | AB3: 149.49015 | AC3: 54.471183 | AD3: 23.696522 | AE3: 4.226682 | AF3: 64.412811 | AG3: 27.889836 | AH3: 1.0051477 | AI3: 6.807672 | AJ3: 424.56725 | AK3: 81.840908 | AL3: 27.591839 | AM3: 36 | AN3: 0.086892472 | AO3: 85.957092 | AP3: 120.95602 | AQ3: 39.25963 | AR3: 0 | AS3: 10.909306 | AT3: 14.465852 | AU3: 8.0749184 | AV3: 187.69429 | AW3: 29.411046 | AX3: 7.0349646 | AY3: 79.149992 | AZ3: 182.6314 | BA3: 35.771021 | BB3: 8.5975797 | BC3: 112 | BD3: 36.541827 | BE3: 25.458173 | BF3: 0.6744782 | BG3: 76.148853 | BH3: 17.083977 | BI3: 11.092692 | BJ3: 4.3289072 | BK3: 39.807103 | BL3: 21.86399 | BM3: 45.561608 | BN3: 19.96855 | BO3: 10.469842 | BP3: 32.749415 | BQ3: 50.980499 | BR3: 0.27008587 | BS3: 159 | BT3: 34.228894 | BU3: 4.7711056 | BV3: 811 | BW3: 0 | BX3: 57.119505 | BY3: 6.8804952 | BZ3: 388.68805 | CA3: 897.31195 | CB3: 364.08207 | CC3: 170.03773 | CD3: 78.130054 | CE3: 17.750151 | CF3: 0 | CG3: #DIV/0! | CH3: #DIV/0! | CI3: #DIV/0! | CJ3: #DIV/0! | CK3: #DIV/0! | CL3: #DIV/0! | CM3: #DIV/0! | CN3: #DIV/0! | CO3: #DIV/0! | CP3: #DIV/0! | CQ3: #DIV/0! | CR3: #DIV/0! | CS3: #DIV/0! | CT3: 0 | CU3: 0 | CV3: #DIV/0! | CW3: #DIV/0! | CX3: #DIV/0! | CY3: #DIV/0! | CZ3: #DIV/0! | DA3: #DIV/0! | DB3: #DIV/0!
B4: To Supply | C4: =SUM(C8:C114) -> 23.143032 | D4: =SUM(D8:D114) -> 49.538603 | E4: =SUM(E8:E114) -> 2.1348079 | F4: =SUM(F8:F114) -> 28.835624 | G4: =SUM(G8:G114) -> 7.6753237e-05 | H4: =SUM(H8:H114) -> 123.14102 | I4: =SUM(I8:I114) -> 127.93145 | J4: =SUM(J8:J114) -> 82.389468 | ... DB4: =SUM(DB8:DB114) -> #DIV/0!
C7: asorg | D7: amaiz | E7: awhea | F7: arice | G7: aocer | H7: aipot | I7: aspot | J7: acass | K7: aroot | L7: abean | M7: apeas | N7: avege | O7: abanb | P7: abanc | Q7: abans | R7: afrui | S7: agnut | T7: asoya | U7: aoils | V7: acoff | W7: ateal | X7: atoba | Y7: asugr | Z7: apyre | AA7: aocrp | AB7: acatt | AC7: asmlr | AD7: apoul | AE7: aoliv | AF7: amilk | AG7: aeggs | AH7: ahony | AI7: ahunt | AJ7: afuel | AK7: achar | AL7: afore | AM7: afish | AN7: angas | AO7: amore | AP7: aomin | AQ7: ameat | AR7: afsea | AS7: afveg | AT7: afoil | AU7: adair | AV7: agmll | AW7: abake | AX7: afeed | AY7: afood | AZ7: aalco | BA7: abeve | BB7: aptob | BC7: atext | BD7: awood | BE7: aprnt | BF7: apetr | BG7: achem | BH7: aphar | BI7: aprub | BJ7: anmet | BK7: aceme | BL7: aclay | BM7: ametl | BN7: amach | BO7: avehi | BP7: afurn | BQ7: aoman | BR7: arepr | BS7: aelec | BT7: awatr | BU7: awast | BV7: acons | BW7: acont | BX7: avehr | BY7: aveht | BZ7: atrdw | CA7: atrdr | CB7: atrnl | CC7: atrna | CD7: atrns | CE7: apost | CF7: ahotl | CG7: apubl | CH7: acomm | CI7: ainfo | CJ7: abank | CK7: ainsu | CL7: aofsv | CM7: arent | CN7: areal | CO7: alegl | CP7: aenga | CQ7: aprod | CR7: atrvl | CS7: aobsv | CT7: apadm | CU7: aeduc | CV7: aheal | CW7: asocw | CX7: acult | CY7: aarts | CZ7: aosrv | DA7: adsrv | DB7: atrdc
B8: csorg | C8: =IF(SUM(wUSE!C$112:C$114),C$3*wUSE!C8/SUM(wUSE!C$112:C$114),0) -> 0.17417571 | D8: =IF(SUM(wUSE!D$112:D$114),D$3*wUSE!D8/SUM(wUSE!D$112:D$114),0) -> 0 | E8: =IF(SUM(wUSE!E$112:E$114),E$3*wUSE!E8/SUM(wUSE!E$112:E$114),0) -> 0 | F8: =IF(SUM(wUSE!F$112:F$114),F$3*wUSE!F8/SUM(wUSE!F$112:F$114),0) -> 0 | G8: =IF(SUM(wUSE!G$112:G$114),G$3*wUSE!G8/SUM(wUSE!G$112:G$114),0) -> 0 | H8: =IF(SUM(wUSE!H$112:H$114),H$3*wUSE!H8/SUM(wUSE!H$112:H$114),0) -> 0 | I8: =IF(SUM(wUSE!I$112:I$114),I$3*wUSE!I8/SUM(wUSE!I$112:I$114),0) -> 0 | J8: =IF(SUM(wUSE!J$112:J$114),J$3*wUSE!J8/SUM(wUSE!J$112:J$114),0) -> 0 | ... DB8: =IF(SUM(wUSE!DB$112:DB$114),DB$3*wUSE!DB8/SUM(wUSE!DB$112:DB$114),0) -> #DIV/0!
B9: cmaiz | C9: =IF(SUM(wUSE!C$112:C$114),C$3*wUSE!C9/SUM(wUSE!C$112:C$114),0) -> 0 | D9: =IF(SUM(wUSE!D$112:D$114),D$3*wUSE!D9/SUM(wUSE!D$112:D$114),0) -> 0.37283019 | E9: =IF(SUM(wUSE!E$112:E$114),E$3*wUSE!E9/SUM(wUSE!E$112:E$114),0) -> 0 | F9: =IF(SUM(wUSE!F$112:F$114),F$3*wUSE!F9/SUM(wUSE!F$112:F$114),0) -> 0 | G9: =IF(SUM(wUSE!G$112:G$114),G$3*wUSE!G9/SUM(wUSE!G$112:G$114),0) -> 0 | H9: =IF(SUM(wUSE!H$112:H$114),H$3*wUSE!H9/SUM(wUSE!H$112:H$114),0) -> 0 | I9: =IF(SUM(wUSE!I$112:I$114),I$3*wUSE!I9/SUM(wUSE!I$112:I$114),0) -> 0 | J9: =IF(SUM(wUSE!J$112:J$114),J$3*wUSE!J9/SUM(wUSE!J$112:J$114),0) -> 0 | ... DB9: =IF(SUM(wUSE!DB$112:DB$114),DB$3*wUSE!DB9/SUM(wUSE!DB$112:DB$114),0) -> #DIV/0!
B10: cwhea | C10: =IF(SUM(wUSE!C$112:C$114),C$3*wUSE!C10/SUM(wUSE!C$112:C$114),0) -> 0 | D10: =IF(SUM(wUSE!D$112:D$114),D$3*wUSE!D10/SUM(wUSE!D$112:D$114),0) -> 0 | E10: =IF(SUM(wUSE!E$112:E$114),E$3*wUSE!E10/SUM(wUSE!E$112:E$114),0) -> 0.016066679 | F10: =IF(SUM(wUSE!F$112:F$114),F$3*wUSE!F10/SUM(wUSE!F$112:F$114),0) -> 0 | G10: =IF(SUM(wUSE!G$112:G$114),G$3*wUSE!G10/SUM(wUSE!G$112:G$114),0) -> 0 | H10: =IF(SUM(wUSE!H$112:H$114),H$3*wUSE!H10/SUM(wUSE!H$112:H$114),0) -> 0 | I10: =IF(SUM(wUSE!I$112:I$114),I$3*wUSE!I10/SUM(wUSE!I$112:I$114),0) -> 0 | J10: =IF(SUM(wUSE!J$112:J$114),J$3*wUSE!J10/SUM(wUSE!J$112:J$114),0) -> 0 | ... DB10: =IF(SUM(wUSE!DB$112:DB$114),DB$3*wUSE!DB10/SUM(wUSE!DB$112:DB$114),0) -> #DIV/0!
B11: crice | C11: =IF(SUM(wUSE!C$112:C$114),C$3*wUSE!C11/SUM(wUSE!C$112:C$114),0) -> 0 | D11: =IF(SUM(wUSE!D$112:D$114),D$3*wUSE!D11/SUM(wUSE!D$112:D$114),0) -> 0 | E11: =IF(SUM(wUSE!E$112:E$114),E$3*wUSE!E11/SUM(wUSE!E$112:E$114),0) -> 0 | F11: =IF(SUM(wUSE!F$112:F$114),F$3*wUSE!F11/SUM(wUSE!F$112:F$114),0) -> 0.21701846 | G11: =IF(SUM(wUSE!G$112:G$114),G$3*wUSE!G11/SUM(wUSE!G$112:G$114),0) -> 0 | H11: =IF(SUM(wUSE!H$112:H$114),H$3*wUSE!H11/SUM(wUSE!H$112:H$114),0) -> 0 | I11: =IF(SUM(wUSE!I$112:I$114),I$3*wUSE!I11/SUM(wUSE!I$112:I$114),0) -> 0 | J11: =IF(SUM(wUSE!J$112:J$114),J$3*wUSE!J11/SUM(wUSE!J$112:J$114),0) -> 0 | ... DB11: =IF(SUM(wUSE!DB$112:DB$114),DB$3*wUSE!DB11/SUM(wUSE!DB$112:DB$114),0) -> #DIV/0!
B12: cocer | C12: =IF(SUM(wUSE!C$112:C$114),C$3*wUSE!C12/SUM(wUSE!C$112:C$114),0) -> 0 | D12: =IF(SUM(wUSE!D$112:D$114),D$3*wUSE!D12/SUM(wUSE!D$112:D$114),0) -> 0 | E12: =IF(SUM(wUSE!E$112:E$114),E$3*wUSE!E12/SUM(wUSE!E$112:E$114),0) -> 0 | F12: =IF(SUM(wUSE!F$112:F$114),F$3*wUSE!F12/SUM(wUSE!F$112:F$114),0) -> 0 | G12: =IF(SUM(wUSE!G$112:G$114),G$3*wUSE!G12/SUM(wUSE!G$112:G$114),0) -> 5.77649e-07 | H12: =IF(SUM(wUSE!H$112:H$114),H$3*wUSE!H12/SUM(wUSE!H$112:H$114),0) -> 0 | I12: =IF(SUM(wUSE!I$112:I$114),I$3*wUSE!I12/SUM(wUSE!I$112:I$114),0) -> 0 | J12: =IF(SUM(wUSE!J$112:J$114),J$3*wUSE!J12/SUM(wUSE!J$112:J$114),0) -> 0 | ... DB12: =IF(SUM(wUSE!DB$112:DB$114),DB$3*wUSE!DB12/SUM(wUSE!DB$112:DB$114),0) -> #DIV/0!
B13: cipot | C13: =IF(SUM(wUSE!C$112:C$114),C$3*wUSE!C13/SUM(wUSE!C$112:C$114),0) -> 0 | D13: =IF(SUM(wUSE!D$112:D$114),D$3*wUSE!D13/SUM(wUSE!D$112:D$114),0) -> 0 | E13: =IF(SUM(wUSE!E$112:E$114),E$3*wUSE!E13/SUM(wUSE!E$112:E$114),0) -> 0 | F13: =IF(SUM(wUSE!F$112:F$114),F$3*wUSE!F13/SUM(wUSE!F$112:F$114),0) -> 0 | G13: =IF(SUM(wUSE!G$112:G$114),G$3*wUSE!G13/SUM(wUSE!G$112:G$114),0) -> 0 | H13: =IF(SUM(wUSE!H$112:H$114),H$3*wUSE!H13/SUM(wUSE!H$112:H$114),0) -> 1.4084817 | I13: =IF(SUM(wUSE!I$112:I$114),I$3*wUSE!I13/SUM(wUSE!I$112:I$114),0) -> 0 | J13: =IF(SUM(wUSE!J$112:J$114),J$3*wUSE!J13/SUM(wUSE!J$112:J$114),0) -> 0 | ... DB13: =IF(SUM(wUSE!DB$112:DB$114),DB$3*wUSE!DB13/SUM(wUSE!DB$112:DB$114),0) -> #DIV/0!
B14: cspot | C14: =IF(SUM(wUSE!C$112:C$114),C$3*wUSE!C14/SUM(wUSE!C$112:C$114),0) -> 0 | D14: =IF(SUM(wUSE!D$112:D$114),D$3*wUSE!D14/SUM(wUSE!D$112:D$114),0) -> 0 | E14: =IF(SUM(wUSE!E$112:E$114),E$3*wUSE!E14/SUM(wUSE!E$112:E$114),0) -> 0 | F14: =IF(SUM(wUSE!F$112:F$114),F$3*wUSE!F14/SUM(wUSE!F$112:F$114),0) -> 0 | G14: =IF(SUM(wUSE!G$112:G$114),G$3*wUSE!G14/SUM(wUSE!G$112:G$114),0) -> 0 | H14: =IF(SUM(wUSE!H$112:H$114),H$3*wUSE!H14/SUM(wUSE!H$112:H$114),0) -> 0 | I14: =IF(SUM(wUSE!I$112:I$114),I$3*wUSE!I14/SUM(wUSE!I$112:I$114),0) -> 1.4632744 | J14: =IF(SUM(wUSE!J$112:J$114),J$3*wUSE!J14/SUM(wUSE!J$112:J$114),0) -> 0 | ... DB14: =IF(SUM(wUSE!DB$112:DB$114),DB$3*wUSE!DB14/SUM(wUSE!DB$112:DB$114),0) -> #DIV/0!
B15: ccass | C15: =IF(SUM(wUSE!C$112:C$114),C$3*wUSE!C15/SUM(wUSE!C$112:C$114),0) -> 0 | D15: =IF(SUM(wUSE!D$112:D$114),D$3*wUSE!D15/SUM(wUSE!D$112:D$114),0) -> 0 | E15: =IF(SUM(wUSE!E$112:E$114),E$3*wUSE!E15/SUM(wUSE!E$112:E$114),0) -> 0 | F15: =IF(SUM(wUSE!F$112:F$114),F$3*wUSE!F15/SUM(wUSE!F$112:F$114),0) -> 0 | G15: =IF(SUM(wUSE!G$112:G$114),G$3*wUSE!G15/SUM(wUSE!G$112:G$114),0) -> 0 | H15: =IF(SUM(wUSE!H$112:H$114),H$3*wUSE!H15/SUM(wUSE!H$112:H$114),0) -> 0 | I15: =IF(SUM(wUSE!I$112:I$114),I$3*wUSE!I15/SUM(wUSE!I$112:I$114),0) -> 0 | J15: =IF(SUM(wUSE!J$112:J$114),J$3*wUSE!J15/SUM(wUSE!J$112:J$114),0) -> 0.9423672 | ... DB15: =IF(SUM(wUSE!DB$112:DB$114),DB$3*wUSE!DB15/SUM(wUSE!DB$112:DB$114),0) -> #DIV/0!
B16: croot | C16: =IF(SUM(wUSE!C$112:C$114),C$3*wUSE!C16/SUM(wUSE!C$112:C$114),0) -> 0 | D16: =IF(SUM(wUSE!D$112:D$114),D$3*wUSE!D16/SUM(wUSE!D$112:D$114),0) -> 0 | E16: =IF(SUM(wUSE!E$112:E$114),E$3*wUSE!E16/SUM(wUSE!E$112:E$114),0) -> 0 | F16: =IF(SUM(wUSE!F$112:F$114),F$3*wUSE!F16/SUM(wUSE!F$112:F$114),0) -> 0 | G16: =IF(SUM(wUSE!G$112:G$114),G$3*wUSE!G16/SUM(wUSE!G$112:G$114),0) -> 0 | H16: =IF(SUM(wUSE!H$112:H$114),H$3*wUSE!H16/SUM(wUSE!H$112:H$114),0) -> 0 | I16: =IF(SUM(wUSE!I$112:I$114),I$3*wUSE!I16/SUM(wUSE!I$112:I$114),0) -> 0 | J16: =IF(SUM(wUSE!J$112:J$114),J$3*wUSE!J16/SUM(wUSE!J$112:J$114),0) -> 0 | ... DB16: =IF(SUM(wUSE!DB$112:DB$114),DB$3*wUSE!DB16/SUM(wUSE!DB$112:DB$114),0) -> #DIV/0!
B17: cbean | C17: =IF(SUM(wUSE!C$112:C$114),C$3*wUSE!C17/SUM(wUSE!C$112:C$114),0) -> 0 | D17: =IF(SUM(wUSE!D$112:D$114),D$3*wUSE!D17/SUM(wUSE!D$112:D$114),0) -> 0 | E17: =IF(SUM(wUSE!E$112:E$114),E$3*wUSE!E17/SUM(wUSE!E$112:E$114),0) -> 0 | F17: =IF(SUM(wUSE!F$112:F$114),F$3*wUSE!F17/SUM(wUSE!F$112:F$114),0) -> 0 | G17: =IF(SUM(wUSE!G$112:G$114),G$3*wUSE!G17/SUM(wUSE!G$112:G$114),0) -> 0 | H17: =IF(SUM(wUSE!H$112:H$114),H$3*wUSE!H17/SUM(wUSE!H$112:H$114),0) -> 0 | I17: =IF(SUM(wUSE!I$112:I$114),I$3*wUSE!I17/SUM(wUSE!I$112:I$114),0) -> 0 | J17: =IF(SUM(wUSE!J$112:J$114),J$3*wUSE!J17/SUM(wUSE!J$112:J$114),0) -> 0 | ... DB17: =IF(SUM(wUSE!DB$112:DB$114),DB$3*wUSE!DB17/SUM(wUSE!DB$112:DB$114),0) -> #DIV/0!
B18: cpeas | C18: =IF(SUM(wUSE!C$112:C$114),C$3*wUSE!C18/SUM(wUSE!C$112:C$114),0) -> 0 | D18: =IF(SUM(wUSE!D$112:D$114),D$3*wUSE!D18/SUM(wUSE!D$112:D$114),0) -> 0 | E18: =IF(SUM(wUSE!E$112:E$114),E$3*wUSE!E18/SUM(wUSE!E$112:E$114),0) -> 0 | F18: =IF(SUM(wUSE!F$112:F$114),F$3*wUSE!F18/SUM(wUSE!F$112:F$114),0) -> 0 | G18: =IF(SUM(wUSE!G$112:G$114),G$3*wUSE!G18/SUM(wUSE!G$112:G$114),0) -> 0 | H18: =IF(SUM(wUSE!H$112:H$114),H$3*wUSE!H18/SUM(wUSE!H$112:H$114),0) -> 0 | I18: =IF(SUM(wUSE!I$112:I$114),I$3*wUSE!I18/SUM(wUSE!I$112:I$114),0) -> 0 | J18: =IF(SUM(wUSE!J$112:J$114),J$3*wUSE!J18/SUM(wUSE!J$112:J$114),0) -> 0 | ... DB18: =IF(SUM(wUSE!DB$112:DB$114),DB$3*wUSE!DB18/SUM(wUSE!DB$112:DB$114),0) -> #DIV/0!
B19: cvege | C19: =IF(SUM(wUSE!C$112:C$114),C$3*wUSE!C19/SUM(wUSE!C$112:C$114),0) -> 0 | D19: =IF(SUM(wUSE!D$112:D$114),D$3*wUSE!D19/SUM(wUSE!D$112:D$114),0) -> 0 | E19: =IF(SUM(wUSE!E$112:E$114),E$3*wUSE!E19/SUM(wUSE!E$112:E$114),0) -> 0 | F19: =IF(SUM(wUSE!F$112:F$114),F$3*wUSE!F19/SUM(wUSE!F$112:F$114),0) -> 0 | G19: =IF(SUM(wUSE!G$112:G$114),G$3*wUSE!G19/SUM(wUSE!G$112:G$114),0) -> 0 | H19: =IF(SUM(wUSE!H$112:H$114),H$3*wUSE!H19/SUM(wUSE!H$112:H$114),0) -> 0 | I19: =IF(SUM(wUSE!I$112:I$114),I$3*wUSE!I19/SUM(wUSE!I$112:I$114),0) -> 0 | J19: =IF(SUM(wUSE!J$112:J$114),J$3*wUSE!J19/SUM(wUSE!J$112:J$114),0) -> 0 | ... DB19: =IF(SUM(wUSE!DB$112:DB$114),DB$3*wUSE!DB19/SUM(wUSE!DB$112:DB$114),0) -> #DIV/0!
... B114: fcap | C114: =IF(SUM(wUSE!C$112:C$114),C$3*wUSE!C114/SUM(wUSE!C$112:C$114),0) -> 1.5833994 | D114: =IF(SUM(wUSE!D$112:D$114),D$3*wUSE!D114/SUM(wUSE!D$112:D$114),0) -> 3.7016583 | E114: =IF(SUM(wUSE!E$112:E$114),E$3*wUSE!E114/SUM(wUSE!E$112:E$114),0) -> 0.18461394 | F114: =IF(SUM(wUSE!F$112:F$114),F$3*wUSE!F114/SUM(wUSE!F$112:F$114),0) -> 3.0093701 | G114: =IF(SUM(wUSE!G$112:G$114),G$3*wUSE!G114/SUM(wUSE!G$112:G$114),0) -> 5.2513011e-06 | H114: =IF(SUM(wUSE!H$112:H$114),H$3*wUSE!H114/SUM(wUSE!H$112:H$114),0) -> 12.411987 | I114: =IF(SUM(wUSE!I$112:I$114),I$3*wUSE!I114/SUM(wUSE!I$112:I$114),0) -> 8.6756779 | J114: =IF(SUM(wUSE!J$112:J$114),J$3*wUSE!J114/SUM(wUSE!J$112:J$114),0) -> 6.2152382 | ... DB114: =IF(SUM(wUSE!DB$112:DB$114),DB$3*wUSE!DB114/SUM(wUSE!DB$112:DB$114),0) -> #DIV/0!

Sheet wBOP
A1: Balance of Payments
A2: Workings | G2: =B4 -> 2024 | I2: 2010 | J2: 2011 | K2: 2012 | L2: 2013 | M2: 2014 | N2: 2015 | O2: 2016 | P2: 2017 | Q2: 2018 | R2: 2019 | S2: 2020 | T2: 2021 | U2: 2022 | V2: 2023 | W2: 2024 | X2: 2025
G3: =SUMIF($I$2:$W$2,$G$2,$I$3:$W$3) -> 1318 | H3: Exchange rate (RwF/USD) | I3: 583.13 | J3: 600.31 | K3: 614.3 | L3: 646.64 | M3: 681.86 | N3: 720.98 | O3: 787.25 | P3: 831.53 | Q3: 861.09 | R3: 899.35 | S3: 943.23 | T3: 988.62 | U3: 1030.5 | V3: 1160.1 | W3: 1318
B4: =Notes!B5 -> 2024 | C4: Year
B5: 0.001 | C5: Scaling (multiplier)
B6: =G3 -> 1318 | C6: Exchange rate | H6: Rwanda: Balance of Payments Standard Presentation
H7: Millions of U.S. Dollars
H8: https://www.bnr.rw/browse-in/statistics/external-sector-statistics/
I9: =IF(ISERR(LEFT(I10,4)/1),"",LEFT(I10,4)/1) -> 2010 | J9: =IF(ISERR(LEFT(J10,4)/1),"",LEFT(J10,4)/1) -> 2011 | K9: =IF(ISERR(LEFT(K10,4)/1),"",LEFT(K10,4)/1) -> 2012 | L9: =IF(ISERR(LEFT(L10,4)/1),"",LEFT(L10,4)/1) -> 2013 | M9: =IF(ISERR(LEFT(M10,4)/1),"",LEFT(M10,4)/1) -> 2014 | N9: =IF(ISERR(LEFT(N10,4)/1),"",LEFT(N10,4)/1) -> 2015 | O9: =IF(ISERR(LEFT(O10,4)/1),"",LEFT(O10,4)/1) -> 2016 | P9: =IF(ISERR(LEFT(P10,4)/1),"",LEFT(P10,4)/1) -> 2017 | ... AQ9: =IF(ISERR(LEFT(AQ10,4)/1),"",LEFT(AQ10,4)/1) -> 2023 | AR9: 2024 | AS9: 2024 | AT9: 2024 | AU9: 2024
B10: Receipts | D10: Payments | G10: =B4 -> 2024 | I10: 2010 | J10: 2011 | K10: 2012 | L10: 2013 | M10: 2014 | N10: 2015 | O10: 2016 | P10: 2017Q1 | Q10: 2017Q2 | R10: 2017Q3 | S10: 2017Q4 | T10: 2018Q1 | U10: 2018Q2 | V10: 2018Q3 | W10: 2018Q4 | X10: 2019Q1 | Y10: 2019Q2 | Z10: 2019Q3 | AA10: 2019Q4 | AB10: 2020Q1 | AC10: 2020Q2 | AD10: 2020Q3 | AE10: 2020Q4 | AF10: 2021Q1 | AG10: 2021Q2 | AH10: 2021Q3 | AI10: 2021Q4 | AJ10: 2022Q1 | AK10: 2022Q3 | AL10: 2022Q4 | AM10: 2022Q4 | AN10: 2023Q1 | AO10: 2023Q2 | AP10: 2023Q3 | AQ10: 2023Q4 | AR10: 2024Q1 | AS10: 2024Q2 | AT10: 2024Q3 | AU10: 2024Q4
B11: Export goods | C11: =G18 -> 4218.9202 | D11: Import goods | E11: =G19 -> 7308.8389 | G11: =SUMIF($I$9:$AU$9,G$10,$I11:$AU11)*$G$3*$B$5 -> -2382.3751 | H11: Current account | I11: -399.14244 | J11: -477.01051 | K11: -741.01596 | L11: -585.10561 | M11: -934.6195 | N11: -1083.6715 | O11: -1330.8224 | P11: -228.63633 | Q11: -186.39793 | R11: -251.98705 | S11: -194.48914 | T11: -280.72792 | U11: -225.60469 | V11: -202.27277 | W11: -270.90445 | X11: -275.24323 | Y11: -357.0171 | Z11: -342.57241 | AA11: -278.90948 | AB11: -419.57532 | AC11: -280.33188 | AD11: -330.31812 | AE11: -255.60268 | AF11: -242.38958 | AG11: -315.59641 | AH11: -354.34116 | AI11: -290.75533 | AJ11: -236.71477 | AK11: -190.80021 | AL11: -456.86498 | AM11: -362.05442 | AN11: -415.92611 | AO11: -334.87943 | AP11: -438.73794 | AQ11: -457.67931 | AR11: -517.45115 | AS11: -437.45608 | AT11: -501.16921 | AU11: -351.4919
B12: Export services | C12: =G27 -> 1424.7745 | D12: Import services | E12: =G28 -> 1305.9994 | G12: =SUMIF($I$9:$AU$9,G$10,$I12:$AU12)*$G$3*$B$5 -> 6803.2312 | H12: Credit | I12: 1356.1006 | J12: 1845.7334 | K12: 1841.6682 | L12: 2131.8792 | M12: 2006.8038 | N12: 2075.4025 | O12: 2138.3967 | P12: 558.48411 | Q12: 653.86231 | R12: 683.39402 | S12: 724.95065 | T12: 647.27323 | U12: 666.65626 | V12: 776.29843 | W12: 723.78899 | X12: 658.57486 | Y12: 649.84801 | Z12: 784.95347 | AA12: 830.20898 | AB12: 652.54253 | AC12: 514.87885 | AD12: 796.30553 | AE12: 672.50405 | AF12: 624.25364 | AG12: 731.31684 | AH12: 747.52042 | AI12: 864.868 | AJ12: 888.68048 | AK12: 1135.3487 | AL12: 1033.457 | AM12: 1039.0368 | AN12: 1009.9781 | AO12: 1262.4272 | AP12: 1140.4417 | AQ12: 1108.3894 | AR12: 1053.1167 | AS12: 1260.8225 | AT12: 1428.5321 | AU12: 1419.3126
B13: Labor | C13: =G87 -> 19.263854 | D13: Labor | E13: =G88 -> 59.218529 | G13: =SUMIF($I$9:$AU$9,G$10,$I13:$AU13)*$G$3*$B$5 -> 9185.6062 | H13: Debit | I13: 1755.243 | J13: 2322.7439 | K13: 2582.6841 | L13: 2716.9848 | M13: 2941.4233 | N13: 3159.074 | O13: 3469.219 | P13: 787.12044 | Q13: 840.26024 | R13: 935.38107 | S13: 919.43979 | T13: 928.00115 | U13: 892.26095 | V13: 978.5712 | W13: 994.69345 | X13: 933.81809 | Y13: 1006.8651 | Z13: 1127.5259 | AA13: 1109.1185 | AB13: 1072.1178 | AC13: 795.21073 | AD13: 1126.6237 | AE13: 928.10673 | AF13: 866.64322 | AG13: 1046.9132 | AH13: 1101.8616 | AI13: 1155.6233 | AJ13: 1125.3952 | AK13: 1326.1489 | AL13: 1490.3219 | AM13: 1401.0912 | AN13: 1425.9042 | AO13: 1597.3067 | AP13: 1579.1797 | AQ13: 1566.0687 | AR13: 1570.5678 | AS13: 1698.2786 | AT13: 1929.7013 | AU13: 1770.8045
B14: Land | D14: Land | G14: =SUMIF($I$9:$AU$9,G$10,$I14:$AU14)*$G$3*$B$5 -> -2971.1436 | H14: Goods and services | I14: -941.10324 | J14: -1224.7229 | K14: -1253.8153 | L14: -1154.6482 | M14: -1325.2429 | N14: -1489.7128 | O14: -1539.5993 | P14: -281.676 | Q14: -274.05727 | R14: -324.33402 | S14: -286.622 | T14: -347.59872 | U14: -276.2825 | V14: -297.68464 | W14: -377.62723 | X14: -335.35322 | Y14: -381.04758 | Z14: -396.10287 | AA14: -377.75982 | AB14: -478.51934 | AC14: -377.53732 | AD14: -437.15315 | AE14: -381.03578 | AF14: -372.19657 | AG14: -473.39611 | AH14: -485.5405 | AI14: -451.9952 | AJ14: -402.58064 | AK14: -505.31337 | AL14: -563.24827 | AM14: -513.84728 | AN14: -521.66477 | AO14: -608.88488 | AP14: -563.78236 | AQ14: -573.48829 | AR14: -594.67644 | AS14: -606.51655 | AT14: -583.57093 | AU14: -469.51806
B15: Capital | C15: =G90 -> 21.74132 | D15: Capital | E15: =G91 -> 421.17383 | G15: =SUMIF($I$9:$AU$9,G$10,$I15:$AU15)*$G$3*$B$5 -> 5643.6947 | H15: Credit | I15: 702.72842 | J15: 953.28799 | K15: 1120.3809 | L15: 1298.832 | M15: 1328.2776 | N15: 1449.0252 | O15: 1516.6459 | P15: 425.1013 | Q15: 466.64141 | R15: 491.13054 | S15: 521.02998 | T15: 468.49011 | U15: 495.3209 | V15: 574.35979 | W15: 505.08566 | X15: 481.15911 | Y15: 512.25048 | Z15: 622.77711 | AA15: 630.59644 | AB15: 498.46569 | AC15: 356.21443 | AD15: 617.73805 | AE15: 485.86369 | AF15: 422.72663 | AG15: 502.22296 | AH15: 545.80546 | AI15: 636.42268 | AJ15: 619.98772 | AK15: 746.45655 | AL15: 819.92835 | AM15: 806.71935 | AN15: 817.25225 | AO15: 900.31283 | AP15: 907.82297 | AQ15: 885.30058 | AR15: 868.51177 | AS15: 978.91883 | AT15: 1238.3711 | AU15: 1196.2125
B16: Households | C16: =G129 -> 662.20001 | D16: Households | E16: =G130 -> 72.601948 | G16: =SUMIF($I$9:$AU$9,G$10,$I16:$AU16)*$G$3*$B$5 -> 8614.8383 | H16: Debit | I16: 1643.8317 | J16: 2178.0108 | K16: 2374.1961 | L16: 2453.4802 | M16: 2653.5206 | N16: 2938.738 | O16: 3056.2452 | P16: 706.7773 | Q16: 740.69868 | R16: 815.46456 | S16: 807.65199 | T16: 816.08883 | U16: 771.60341 | V16: 872.04443 | W16: 882.71289 | X16: 816.51233 | Y16: 893.29806 | Z16: 1018.88 | AA16: 1008.3563 | AB16: 976.98503 | AC16: 733.75175 | AD16: 1054.8912 | AE16: 866.89947 | AF16: 794.92321 | AG16: 975.61907 | AH16: 1031.346 | AI16: 1088.4179 | AJ16: 1022.5684 | AK16: 1251.7699 | AL16: 1383.1766 | AM16: 1320.5666 | AN16: 1338.917 | AO16: 1509.1977 | AP16: 1471.6053 | AQ16: 1458.7889 | AR16: 1463.1882 | AS16: 1585.4354 | AT16: 1821.942 | AU16: 1665.7305
B17: Enterprises | C17: =G135 -> 98.215884 | D17: Enterprises | E17: =G136 -> 6.3768699 | G17: =SUMIF($I$9:$AU$9,G$10,$I17:$AU17)*$G$3*$B$5 -> -3089.9187 | H17: Goods | I17: -786.69823 | J17: -1104.8407 | K17: -1273.698 | L17: -1150.7782 | M17: -1268.5694 | N17: -1236.6056 | O17: -1294.1432 | P17: -243.92757 | Q17: -240.92931 | R17: -247.81955 | S17: -241.2251 | T17: -268.93842 | U17: -243.35249 | V17: -302.39128 | W17: -340.90782 | X17: -303.02834 | Y17: -378.44714 | Z17: -396.40056 | AA17: -394.94548 | AB17: -441.25589 | AC17: -366.49477 | AD17: -449.28193 | AE17: -420.49038 | AF17: -369.95261 | AG17: -444.78011 | AH17: -413.84844 | AI17: -430.11281 | AJ17: -360.23804 | AK17: -519.32108 | AL17: -619.54863 | AM17: -489.42472 | AN17: -527.36584 | AO17: -594.48766 | AP17: -644.06238 | AQ17: -602.84394 | AR17: -599.16535 | AS17: -609.54795 | AT17: -651.87229 | AU17: -483.81399
B18: Government | C18: =G123 -> 358.11541 | D18: Government | E18: =G124 -> 11.396738 | G18: =SUMIF($I$9:$AU$9,G$10,$I18:$AU18)*$G$3*$B$5 -> 4218.9202 | H18: Credit | I18: 297.27526 | J18: 464.2351 | K18: 590.75048 | L18: 703.01008 | M18: 723.0906 | N18: 682.04487 | O18: 726.6109 | P18: 223.62202 | Q18: 255.20577 | R18: 277.62813 | S18: 284.00712 | T18: 280.82884 | U18: 290.33357 | V18: 285.83251 | W18: 272.63106 | X18: 255.77903 | Y18: 287.40533 | Z18: 331.33986 | AA18: 357.28585 | AB18: 317.6034 | AC18: 279.34182 | AD18: 485.07296 | AE18: 342.1364 | AF18: 289.62498 | AG18: 370.39972 | AH18: 401.02814 | AI18: 469.77762 | AJ18: 458.71861 | AK18: 523.6826 | AL18: 562.97717 | AM18: 566.51294 | AN18: 591.79711 | AO18: 686.18421 | AP18: 590.62738 | AQ18: 597.34056 | AR18: 644.84475 | AS18: 737.81919 | AT18: 891.80587 | AU18: 926.53188
B19: Balance | C19: =-G11 -> 2382.3751 | G19: =SUMIF($I$9:$AU$9,G$10,$I19:$AU19)*$G$3*$B$5 -> 7308.8389 | H19: Debit | I19: 1083.9735 | J19: 1569.0758 | K19: 1864.4485 | L19: 1853.7883 | M19: 1991.66 | N19: 1918.6505 | O19: 2020.7541 | P19: 467.54959 | Q19: 496.13509 | R19: 525.44769 | S19: 525.23221 | T19: 549.76726 | U19: 533.68606 | V19: 588.22379 | W19: 613.53888 | X19: 558.80737 | Y19: 665.85247 | Z19: 727.74042 | AA19: 752.23132 | AB19: 758.85929 | AC19: 645.83659 | AD19: 934.35488 | AE19: 762.62678 | AF19: 659.5776 | AG19: 815.17983 | AH19: 814.87658 | AI19: 899.89043 | AJ19: 818.95665 | AK19: 1043.0037 | AL19: 1182.5258 | AM19: 1055.9377 | AN19: 1119.1629 | AO19: 1280.6719 | AP19: 1234.6898 | AQ19: 1200.1845 | AR19: 1244.0101 | AS19: 1347.3671 | AT19: 1543.6782 | AU19: 1410.3459
B20: Total | C20: =SUM(C11:C19) -> 9185.6062 | D20: Total | E20: =SUM(E11:E19) -> 9185.6062 | G20: =SUMIF($I$9:$AU$9,G$10,$I20:$AU20)*$G$3*$B$5 -> -3130.9932 | H20: General merchandise on a balance of payments basis | I20: -786.69823 | J20: -1104.8407 | K20: -1273.698 | L20: -1150.7782 | M20: -1268.5694 | N20: -1236.6056 | O20: -1294.1432 | P20: -266.55257 | Q20: -263.55432 | R20: -270.44455 | S20: -263.8501 | T20: -287.34183 | U20: -261.7559 | V20: -320.79469 | W20: -359.31123 | X20: -316.88921 | Y20: -386.24798 | Z20: -403.84434 | AA20: -402.86639 | AB20: -440.94998 | AC20: -346.36419 | AD20: -458.10855 | AE20: -424.22036 | AF20: -360.20813 | AG20: -443.3026 | AH20: -417.85139 | AI20: -432.2105 | AJ20: -358.29144 | AK20: -517.67374 | AL20: -609.70991 | AM20: -548.62399 | AN20: -510.33629 | AO20: -588.21794 | AP20: -621.21817 | AQ20: -603.20717 | AR20: -577.23427 | AS20: -633.69166 | AT20: -607.51902 | AU20: -557.11898
D21: Difference | E21: =E20-C20 -> 0 | G21: =SUMIF($I$9:$AU$9,G$10,$I21:$AU21)*$G$3*$B$5 -> 2229.9874 | H21: Credit | I21: 297.27526 | J21: 464.2351 | K21: 590.75048 | L21: 703.01008 | M21: 723.0906 | N21: 682.04487 | O21: 726.6109 | P21: 200.99702 | Q21: 232.58077 | R21: 255.00313 | S21: 261.38212 | T21: 262.42543 | U21: 271.93016 | V21: 267.4291 | W21: 254.22765 | X21: 241.91816 | Y21: 279.60449 | Z21: 212.49777 | AA21: 221.41603 | AB21: 210.41226 | AC21: 142.28026 | AD21: 190.85227 | AE21: 217.80375 | AF21: 239.16892 | AG21: 276.92775 | AH21: 298.51631 | AI21: 353.03346 | AJ21: 342.2218 | AK21: 363.49717 | AL21: 418.36788 | AM21: 432.06406 | AN21: 401.51346 | AO21: 383.49133 | AP21: 402.61359 | AQ21: 394.723 | AR21: 390.78911 | AS21: 386.93113 | AT21: 457.0785 | AU21: 457.14922
