Workbook

Sheet Index
A1: GDX index
A6: Type | B6: Name | C6: Location | D6: Row | E6: Column
D7: rdim | E7: cdim
A8: dset | B8: mac | C8: sets!a7 | D8: 1
A9: dset | B9: sac | C9: sets!b7 | D9: 1
A10: dset | B10: ac | C10: sets!c7 | D10: 1
A11: dset | B11: a | C11: sets!d7 | D11: 1
A12: dset | B12: c | C12: sets!e7 | D12: 1
A13: dset | B13: f | C13: sets!f7 | D13: 1
A14: dset | B14: t | C14: sets!g7 | D14: 1
A15: set | B15: mapac | C15: sets!d7 | D15: 2 | F15: values=nodata
A16: set | B16: mapmac | C16: sets!j7 | D16: 2 | F16: values=nodata
A17: par | B17: msam | C17: mac!a7 | D17: 1 | E17: 1
A18: par | B18: sut | C18: sut!b7 | D18: 1 | E18: 1
A19: par | B19: use | C19: use!b7 | D19: 1 | E19: 1
A20: par | B20: supply | C20: sup!b7 | D20: 1 | E20: 1

Sheet Sets
A1: Sets
A4: Macro | B4: SUT | C4: Micro | D4: Activities | E4: Commodities | F4: Factors | G4: Taxes | J4: Macro-Micro
A5: accounts | B5: accounts | C5: accounts | J5: MAPMAC
A6: MAC | B6: SAC | C6: AC | D6: A | E6: C | F6: F | G6: T | J6: MAC | K6: AC
A7: mact | B7: prd | C7: asorg | D7: asorg | E7: csorg | F7: flab | G7: atax | J7: mact | K7: asorg
A8: mcom | B8: trd_imp | C8: amaiz | D8: amaiz | E8: cmaiz | F8: flnd | G8: ctax | J8: mact | K8: amaiz
A9: mtrc | B9: tax_prd | C9: awhea | D9: awhea | E9: cwhea | F9: fcap | G9: dtax | J9: mact | K9: awhea
A10: mlab | B10: tax_imp | C10: arice | D10: arice | E10: crice | G10: etax | J10: mact | K10: arice
A11: mlnd | B11: tax_exp | C11: aocer | D11: aocer | E11: cocer | G11: ftax | J11: mact | K11: aocer
A12: mcap | B12: tax_exm | C12: aipot | D12: aipot | E12: cipot | G12: mtax | J12: mact | K12: aipot
A13: ment | B13: tax_sal | C13: aspot | D13: aspot | E13: cspot | G13: stax | J13: mact | K13: aspot
A14: mhhd | B14: tax_vat | C14: acass | D14: acass | E14: ccass | G14: vtax | J14: mact | K14: acass
A15: mgov | B15: tax_exd | C15: aroot | D15: aroot | E15: croot | G15: xtax | J15: mact | K15: aroot
A16: matx | B16: trc_rec | C16: abean | D16: abean | E16: cbean | J16: mact | K16: abean
A17: mctx | B17: tot_sup | C17: apeas | D17: apeas | E17: cpeas | J17: mact | K17: apeas
A18: mdtx | B18: tot_dem | C18: avege | D18: avege | E18: cvege | J18: mact | K18: avege
A19: metx | B19: int | C19: abanb | D19: abanb | E19: cbanb | J19: mact | K19: abanb
A20: mftx | B20: trc_pay | C20: abanc | D20: abanc | E20: cbanc | J20: mact | K20: abanc
A21: mmtx | B21: con_prv | C21: abans | D21: abans | E21: cbans | J21: mact | K21: abans
A22: mstx | B22: con_pub | C22: afrui | D22: afrui | E22: cfrui | J22: mact | K22: afrui
A23: mvtx | B23: inv_dem | C23: agnut | D23: agnut | E23: cgnut | J23: mact | K23: agnut
A24: mxtx | B24: inv_gov | C24: asoya | D24: asoya | E24: csoya | J24: mact | K24: asoya
A25: ms-i | B25: inv_stk | C25: aoils | D25: aoils | E25: coils | J25: mact | K25: aoils
A26: mg-i | B26: trd_exp | C26: acoff | D26: acoff | E26: ccoff | J26: mact | K26: acoff
A27: mstk | C27: ateal | D27: ateal | E27: cteal | J27: mact | K27: ateal
A28: mrow | C28: atoba | D28: atoba | E28: ctoba | J28: mact | K28: atoba
A29: mtot | C29: asugr | D29: asugr | E29: csugr | J29: mact | K29: asugr
C30: apyre | D30: apyre | E30: cpyre | J30: mact | K30: apyre
C31: aocrp | D31: aocrp | E31: cocrp | J31: mact | K31: aocrp
C32: acatt | D32: acatt | E32: ccatt | J32: mact | K32: acatt
C33: asmlr | D33: asmlr | E33: csmlr | J33: mact | K33: asmlr
C34: apoul | D34: apoul | E34: cpoul | J34: mact | K34: apoul
C35: aoliv | D35: aoliv | E35: coliv | J35: mact | K35: aoliv
C36: amilk | D36: amilk | E36: cmilk | J36: mact | K36: amilk
C37: aeggs | D37: aeggs | E37: ceggs | J37: mact | K37: aeggs
C38: ahony | D38: ahony | E38: chony | J38: mact | K38: ahony
C39: ahunt | D39: ahunt | E39: chunt | J39: mact | K39: ahunt
C40: afuel | D40: afuel | E40: cfuel | J40: mact | K40: afuel
C41: achar | D41: achar | E41: cchar | J41: mact | K41: achar
... C110: atrdc | D110: atrdc | E110: ctrdc | J110: mact | K110: atrdc
...

Sheet Notes
A1: =CONCATENATE(B5," ",C4," SAM") -> 2017 Rwanda SAM
A2: Use with 1construct.gms and 2balance.gms
A4: Country | B4: RWA | C4: Rwanda
A5: Year | B5: 2017
A6: Units | B6: Billions of Rwanda Francs
A9: Activities and commodities (N86) | E9: Other accounts
A10: ="a"&MID(B10,2,4) -> asorg | B10: csorg | C10: Sorghum (A111) | E10: trc | F10: Transaction costs
A11: ="a"&MID(B11,2,4) -> amaiz | B11: cmaiz | C11: Maize (A112) | E11: flab | F11: Labor
A12: ="a"&MID(B12,2,4) -> awhea | B12: cwhea | C12: Wheat (A113) | E12: flnd | F12: Land
A13: ="a"&MID(B13,2,4) -> arice | B13: crice | C13: Paddy & husked rice (A116) | E13: fcap | F13: Capital
A14: ="a"&MID(B14,2,4) -> aocer | B14: cocer | C14: Other cereals (A119) | E14: ent | F14: Enterprises
A15: ="a"&MID(B15,2,4) -> aipot | B15: cipot | C15: Irish potatoes (A121) | E15: hhd | F15: Households
A16: ="a"&MID(B16,2,4) -> aspot | B16: cspot | C16: Sweet potatoes (A122) | E16: gov | F16: Government
A17: ="a"&MID(B17,2,4) -> acass | B17: ccass | C17: Cassava (A123) | E17: atax | F17: Taxes - activity (production)
A18: ="a"&MID(B18,2,4) -> aroot | B18: croot | C18: Other roots & tubers (A129) | E18: ctax | F18: Taxes - customs duties (imports)
A19: ="a"&MID(B19,2,4) -> abean | B19: cbean | C19: Dried beans (A131) | E19: dtax | F19: Taxes - direct (corporate, private)
A20: ="a"&MID(B20,2,4) -> apeas | B20: cpeas | C20: Peas & other legumes (A132) | E20: etax | F20: Taxes - exports
A21: ="a"&MID(B21,2,4) -> avege | B21: cvege | C21: Other vegetables (A139) | E21: ftax | F21: Taxes - factors (royalities)
... A29: ="a"&MID(B29,2,4) -> acoff | B29: ccoff | C29: Coffee, not roasted, not decaffeinated (A210) | E29: total | F29: Total
A30: ="a"&MID(B30,2,4) -> ateal | B30: cteal | C30: Tea (unprocessed green leaf) (A220)
A31: ="a"&MID(B31,2,4) -> atoba | B31: ctoba | C31: Tobacco, raw (A291)
A32: ="a"&MID(B32,2,4) -> asugr | B32: csugr | C32: Sugar cane (A292)
A33: ="a"&MID(B33,2,4) -> apyre | B33: cpyre | C33: Pyrethrum (A293)
A34: ="a"&MID(B34,2,4) -> aocrp | B34: cocrp | C34: Agricultural products n.e.c. (A299)
A35: ="a"&MID(B35,2,4) -> acatt | B35: ccatt | C35: Bovine cattle, live (A311)
A36: ="a"&MID(B36,2,4) -> asmlr | B36: csmlr | C36: Sheep, goats, pigs,live (A312)
A37: ="a"&MID(B37,2,4) -> apoul | B37: cpoul | C37: Poultry, live (A313)
A38: ="a"&MID(B38,2,4) -> aoliv | B38: coliv | C38: Other live animals (A319)
A39: ="a"&MID(B39,2,4) -> amilk | B39: cmilk | C39: Raw milk (A321)
A40: ="a"&MID(B40,2,4) -> aeggs | B40: ceggs | C40: Eggs (A322)
A41: ="a"&MID(B41,2,4) -> ahony | B41: chony | C41: Natural honey (A323)
... A113: ="a"&MID(B113,2,4) -> atrdc | B113: ctrdc | C113: Travel debits & credits (V00)

Sheet MAC
A1: Macro SAM
A2: Final values exported to GAMS
B7: mact | C7: mcom | D7: mtrc | E7: mlab | F7: mlnd | G7: mcap | H7: ment | I7: mhhd | J7: mgov | K7: matx | L7: mctx | M7: mdtx | N7: metx | O7: mftx | P7: mmtx | Q7: mstx | R7: mvtx | S7: mxtx | T7: ms-i | U7: mg-i | V7: mstk | W7: mrow | X7: mtot
A8: mact | B8: =wMAC!C5 -> 0 | C8: =wMAC!D5 -> 11563.342 | D8: =wMAC!E5 -> 0 | E8: =wMAC!F5 -> 0 | F8: =wMAC!G5 -> 0 | G8: =wMAC!H5 -> 0 | H8: =wMAC!I5 -> 0 | I8: =wMAC!J5 -> 0 | ... X8: =wMAC!Y5 -> 11563.342
A9: mcom | B9: =wMAC!C6 -> 4606.6764 | C9: =wMAC!D6 -> 0 | D9: =wMAC!E6 -> 1053.7156 | E9: =wMAC!F6 -> 0 | F9: =wMAC!G6 -> 0 | G9: =wMAC!H6 -> 0 | H9: =wMAC!I6 -> 0 | I9: =wMAC!J6 -> 5676.1316 | ... X9: =wMAC!Y6 -> 15905.025
A10: mtrc | B10: =wMAC!C7 -> 0 | C10: =wMAC!D7 -> 1053.7156 | D10: =wMAC!E7 -> 0 | E10: =wMAC!F7 -> 0 | F10: =wMAC!G7 -> 0 | G10: =wMAC!H7 -> 0 | H10: =wMAC!I7 -> 0 | I10: =wMAC!J7 -> 0 | ... X10: =wMAC!Y7 -> 1053.7156
A11: mlab | B11: =wMAC!C8 -> 3889.2332 | C11: =wMAC!D8 -> 0 | D11: =wMAC!E8 -> 0 | E11: =wMAC!F8 -> 0 | F11: =wMAC!G8 -> 0 | G11: =wMAC!H8 -> 0 | H11: =wMAC!I8 -> 0 | I11: =wMAC!J8 -> 0 | ... X11: =wMAC!Y8 -> 3895.6427
A12: mlnd | B12: =wMAC!C9 -> 575.64093 | C12: =wMAC!D9 -> 0 | D12: =wMAC!E9 -> 0 | E12: =wMAC!F9 -> 0 | F12: =wMAC!G9 -> 0 | G12: =wMAC!H9 -> 0 | H12: =wMAC!I9 -> 0 | I12: =wMAC!J9 -> 0 | ... X12: =wMAC!Y9 -> 575.64093
A13: mcap | B13: =wMAC!C10 -> 2577.1259 | C13: =wMAC!D10 -> 0 | D13: =wMAC!E10 -> 0 | E13: =wMAC!F10 -> 0 | F13: =wMAC!G10 -> 0 | G13: =wMAC!H10 -> 0 | H13: =wMAC!I10 -> 0 | I13: =wMAC!J10 -> 0 | ... X13: =wMAC!Y10 -> 2588.7438
A14: ment | B14: =wMAC!C11 -> 0 | C14: =wMAC!D11 -> 0 | D14: =wMAC!E11 -> 0 | E14: =wMAC!F11 -> 0 | F14: =wMAC!G11 -> 0 | G14: =wMAC!H11 -> 2357.6183 | H14: =wMAC!I11 -> 0 | I14: =wMAC!J11 -> 0 | ... X14: =wMAC!Y11 -> 2512.2712
A15: mhhd | B15: =wMAC!C12 -> 0 | C15: =wMAC!D12 -> 0 | D15: =wMAC!E12 -> 0 | E15: =wMAC!F12 -> 3865.4278 | F15: =wMAC!G12 -> 575.64093 | G15: =wMAC!H12 -> 0 | H15: =wMAC!I12 -> 2032.1044 | I15: =wMAC!J12 -> 0 | ... X15: =wMAC!Y12 -> 6897.8259
A16: mgov | B16: =wMAC!C13 -> 0 | C16: =wMAC!D13 -> 0 | D16: =wMAC!E13 -> 0 | E16: =wMAC!F13 -> 0 | F16: =wMAC!G13 -> 0 | G16: =wMAC!H13 -> 0 | H16: =wMAC!I13 -> 69.912831 | I16: =wMAC!J13 -> 196.14963 | ... X16: =wMAC!Y13 -> 1745.3736
A17: matx | B17: =wMAC!C14 -> -85.334627 | C17: =wMAC!D14 -> 0 | D17: =wMAC!E14 -> 0 | E17: =wMAC!F14 -> 0 | F17: =wMAC!G14 -> 0 | G17: =wMAC!H14 -> 0 | H17: =wMAC!I14 -> 0 | I17: =wMAC!J14 -> 0 | ... X17: =wMAC!Y14 -> -85.334627
A18: mctx | B18: =wMAC!C15 -> 0 | C18: =wMAC!D15 -> 99.754257 | D18: =wMAC!E15 -> 0 | E18: =wMAC!F15 -> 0 | F18: =wMAC!G15 -> 0 | G18: =wMAC!H15 -> 0 | H18: =wMAC!I15 -> 0 | I18: =wMAC!J15 -> 0 | ... X18: =wMAC!Y15 -> 99.754257
A19: mdtx | B19: =wMAC!C16 -> 0 | C19: =wMAC!D16 -> 0 | D19: =wMAC!E16 -> 0 | E19: =wMAC!F16 -> 0 | F19: =wMAC!G16 -> 0 | G19: =wMAC!H16 -> 0 | H19: =wMAC!I16 -> 163.58467 | I19: =wMAC!J16 -> 315.56829 | ... X19: =wMAC!Y16 -> 479.15296
... A30: mtot | B30: =wMAC!C27 -> 11563.342 | C30: =wMAC!D27 -> 15906.328 | D30: =wMAC!E27 -> 1053.7156 | E30: =wMAC!F27 -> 3895.6427 | F30: =wMAC!G27 -> 575.64093 | G30: =wMAC!H27 -> 2588.7438 | H30: =wMAC!I27 -> 2512.2712 | I30: =wMAC!J27 -> 6897.8259 | ... X30: =wMAC!Y27 -> 0

Sheet SUT
A1: Supply-Use Table
A2: Final values exported to GAMS
C4: Gross | D4: Imports | E4: Tax on | F4: Taxes on products | L4: Trans. | M4: Totals | O4: Inter- | P4: Trans. | Q4: Consumption | S4: GCF | V4: Exports | Y4: Differences
C5: output | E5: producers | F5: Customs duties | G5: Exports | H5: Import excise duties | I5: Subsidies (products) | J5: VAT | K5: Excise & Others | L5: costs | M5: Supply | N5: Demand | O5: mediates | P5: costs | Q5: Private | R5: Public | S5: Private | T5: Public | U5: Stocks | Y5: sup-dem | Z5: % sup
B6: Totals | C6: =SUM(C8:C111) -> 11648.676 | D6: =SUM(D8:D111) -> 2550.3991 | E6: =SUM(E8:E111) -> -85.334627 | F6: =SUM(F8:F111) -> 99.754257 | G6: =SUM(G8:G111) -> 0 | H6: =SUM(H8:H111) -> 64.958051 | I6: =SUM(I8:I111) -> -30.138079 | K6: =SUM(K8:K111) -> 206.88431 | L6: =SUM(L8:L111) -> 1053.7156 | M6: =SUM(M8:M111) -> 15906.328 | N6: =SUM(N8:N111) -> 15905.025 | O6: =SUM(O8:O111) -> 4606.6764 | P6: =SUM(P8:P111) -> 1053.7156 | Q6: =SUM(Q8:Q111) -> 5676.1316 | R6: =SUM(R8:R111) -> 1155 | ... V6: =SUM(V8:V111) -> 1579.5017 | Y6: =M6-N6 -> 1.3031426 | Z6: =IF(M6<>0,Y6/M6*100,0) -> 0.0081926044 | AC6: Totals | AE6: Differences
C7: prd | D7: trd_imp | E7: tax_prd | F7: tax_imp | G7: tax_exp | H7: tax_exm | I7: tax_sal | J7: tax_vat | K7: tax_exd | L7: trc_rec | M7: tot_sup | N7: tot_dem | O7: int | P7: trc_pay | Q7: con_prv | R7: con_pub | S7: inv_dem | T7: inv_gov | U7: inv_stk | V7: trd_exp | AC7: Supply | AD7: Demand | AE7: sup-dem | AF7: % sup
A8: Sorghum (A111) | B8: csorg | C8: {=TRANSPOSE(SUP!C4:DB4)} -> 45.186128 | D8: =wTRD!I8 -> 1.0534168 | E8: =wTAX!G8 -> 0 | F8: =wTAX!K8 -> 0 | G8: =wTAX!O8 -> 0 | H8: =wTAX!S8 -> 0 | I8: =wTAX!W8 -> 0 | J8: =wTAX!AA8 -> 0.014953109 | K8: =wTAX!AE8 -> 0 | L8: =wTRC!G8 -> 0.52381858 | M8: =SUM(C8:L8) -> 46.778316 | N8: =SUM(O8:V8) -> 46.876135 | O8: =SUM(USE!C8:DB8) -> 39.453683 | P8: =wTRC!K8 -> 0 | Q8: =wABS!G7 -> 5.595082 | R8: =wABS!K7 -> 0 | S8: =wABS!O7 -> 0 | T8: =wABS!S7 -> 0 | U8: =wABS!W7 -> 0.2512223 | V8: =wTRD!O8 -> 1.5761482 | Y8: =M8-N8 -> -0.097819245 | Z8: =IF(M8<>0,Y8/M8*100,0) -> -0.20911237 | AB8: Agriculture | AC8: =SUM(AC9:AC20) -> 2380.4511 | AD8: =SUM(AD9:AD20) -> 2385.218 | AE8: =AC8-AD8 -> -4.7669471 | AF8: =IF(AC8<>0,AE8/AC8*100,0) -> -0.20025394
A9: Maize (A112) | B9: cmaiz | C9: 98.112675 | D9: =wTRD!I9 -> 25.349828 | E9: =wTAX!G9 -> 0 | F9: =wTAX!K9 -> 0.53905915 | G9: =wTAX!O9 -> 0 | H9: =wTAX!S9 -> 0 | I9: =wTAX!W9 -> 0 | J9: =wTAX!AA9 -> 0.032696955 | K9: =wTAX!AE9 -> 0.36276888 | L9: =wTRC!G9 -> 1.1543252 | M9: =SUM(C9:L9) -> 125.55135 | N9: =SUM(O9:V9) -> 129.66341 | O9: =SUM(USE!C9:DB9) -> 73.138612 | P9: =wTRC!K9 -> 0 | Q9: =wABS!G8 -> 41.735846 | R9: =wABS!K8 -> 0 | S9: =wABS!O8 -> 0 | T9: =wABS!S8 -> 0 | U9: =wABS!W8 -> 5.3465792 | V9: =wTRD!O9 -> 9.4423747 | Y9: =M9-N9 -> -4.1120586 | Z9: =IF(M9<>0,Y9/M9*100,0) -> -3.2752006 | AB9: Cereals | AC9: =SUM(M8:M12) -> 324.64064 | AD9: =SUM(N8:N12) -> 326.86549 | AE9: =AC9-AD9 -> -2.2248515 | AF9: =IF(AC9<>0,AE9/AC9*100,0) -> -0.68532746
A10: Wheat (A113) | B10: cwhea | C10: 3.2540333 | D10: =wTRD!I10 -> 54.390816 | E10: =wTAX!G10 -> 0 | F10: =wTAX!K10 -> 0 | G10: =wTAX!O10 -> 0 | H10: =wTAX!S10 -> 0 | I10: =wTAX!W10 -> 0 | J10: =wTAX!AA10 -> 0.016125022 | K10: =wTAX!AE10 -> 0.78637771 | L10: =wTRC!G10 -> 0.71507849 | M10: =SUM(C10:L10) -> 59.162431 | N10: =SUM(O10:V10) -> 62.323153 | O10: =SUM(USE!C10:DB10) -> 56.529221 | P10: =wTRC!K10 -> 0 | Q10: =wABS!G9 -> 0.72771824 | R10: =wABS!K9 -> 0 | S10: =wABS!O9 -> 0 | T10: =wABS!S9 -> 0 | U10: =wABS!W9 -> 4.786616 | V10: =wTRD!O10 -> 0.27959753 | Y10: =M10-N10 -> -3.1607221 | Z10: =IF(M10<>0,Y10/M10*100,0) -> -5.342448 | AB10: Roots | AC10: =SUM(M13:M16) -> 508.3511 | AD10: =SUM(N13:N16) -> 505.42778 | AE10: =AC10-AD10 -> 2.9233157 | AF10: =IF(AC10<>0,AE10/AC10*100,0) -> 0.5750584
A11: Paddy & husked rice (A116) | B11: crice | C11: 59.900399 | D11: =wTRD!I11 -> 17.6277 | E11: =wTAX!G11 -> 0 | F11: =wTAX!K11 -> 6.2061593 | G11: =wTAX!O11 -> 0 | H11: =wTAX!S11 -> 0 | I11: =wTAX!W11 -> 0 | J11: =wTAX!AA11 -> 2.6701794 | K11: =wTAX!AE11 -> 0.24129892 | L11: =wTRC!G11 -> 0.82326616 | M11: =SUM(C11:L11) -> 87.469003 | N11: =SUM(O11:V11) -> 83.838418 | O11: =SUM(USE!C11:DB11) -> 7.5612554 | P11: =wTRC!K11 -> 0 | Q11: =wABS!G10 -> 73.451634 | R11: =wABS!K10 -> 0 | S11: =wABS!O10 -> 0 | T11: =wABS!S10 -> 0 | U11: =wABS!W10 -> -1.9129959 | V11: =wTRD!O11 -> 4.7385243 | Y11: =M11-N11 -> 3.6305847 | Z11: =IF(M11<>0,Y11/M11*100,0) -> 4.15071 | AB11: Vegetables | AC11: =SUM(M17:M19) -> 420.76035 | AD11: =SUM(N17:N19) -> 417.95016 | AE11: =AC11-AD11 -> 2.8101816 | AF11: =IF(AC11<>0,AE11/AC11*100,0) -> 0.66788176
A12: Other cereals (A119) | B12: cocer | C12: 0.29091626 | D12: =wTRD!I12 -> 5.2367139 | E12: =wTAX!G12 -> 0 | F12: =wTAX!K12 -> 0.030887925 | G12: =wTAX!O12 -> 0 | H12: =wTAX!S12 -> 0 | I12: =wTAX!W12 -> 0 | J12: =wTAX!AA12 -> 0 | K12: =wTAX!AE12 -> 0.074708701 | L12: =wTRC!G12 -> 0.046313731 | M12: =SUM(C12:L12) -> 5.6795405 | N12: =SUM(O12:V12) -> 4.1643767 | O12: =SUM(USE!C12:DB12) -> 3.83321 | P12: =wTRC!K12 -> 0 | Q12: =wABS!G11 -> 0.10782244 | R12: =wABS!K11 -> 0 | S12: =wABS!O11 -> 0 | T12: =wABS!S11 -> 0 | U12: =wABS!W11 -> 0.0096081101 | V12: =wTRD!O12 -> 0.21373611 | Y12: =M12-N12 -> 1.5151638 | Z12: =IF(M12<>0,Y12/M12*100,0) -> 26.677577 | AB12: Bananas and fruit | AC12: =SUM(M20:M23) -> 303.02439 | AD12: =SUM(N20:N23) -> 304.48991 | AE12: =AC12-AD12 -> -1.4655183 | AF12: =IF(AC12<>0,AE12/AC12*100,0) -> -0.48363049
A13: Irish potatoes (A121) | B13: cipot | C13: 170.10332 | D13: =wTRD!I13 -> 4.7535362 | E13: =wTAX!G13 -> 0 | F13: =wTAX!K13 -> 0.011621994 | G13: =wTAX!O13 -> 0 | H13: =wTAX!S13 -> 0 | I13: =wTAX!W13 -> 0 | J13: =wTAX!AA13 -> 0.26287637 | K13: =wTAX!AE13 -> 0.053293658 | L13: =wTRC!G13 -> 9.5056657 | M13: =SUM(C13:L13) -> 184.69031 | N13: =SUM(O13:V13) -> 185.0201 | O13: =SUM(USE!C13:DB13) -> 2.2121453 | P13: =wTRC!K13 -> 0 | Q13: =wABS!G12 -> 177.67462 | R13: =wABS!K12 -> 0 | S13: =wABS!O12 -> 0 | T13: =wABS!S12 -> 0 | U13: =wABS!W12 -> -0.05596473 | V13: =wTRD!O13 -> 5.1893028 | Y13: =M13-N13 -> -0.32978913 | Z13: =IF(M13<>0,Y13/M13*100,0) -> -0.1785633 | AB13: Oil seeds n.e.c. and oleaginous fruit | AC13: =SUM(M24:M26) -> 25.246313 | AD13: =SUM(N24:N26) -> 25.072272 | AE13: =AC13-AD13 -> 0.17404028 | AF13: =IF(AC13<>0,AE13/AC13*100,0) -> 0.68936909
A14: Sweet potatoes (A122) | B14: cspot | C14: 151.42836 | D14: =wTRD!I14 -> 0.52079596 | E14: =wTAX!G14 -> 0 | F14: =wTAX!K14 -> 4.6517458e-05 | G14: =wTAX!O14 -> 0 | H14: =wTAX!S14 -> 0 | I14: =wTAX!W14 -> 0 | J14: =wTAX!AA14 -> 0.12884959 | K14: =wTAX!AE14 -> 0.0019898308 | L14: =wTRC!G14 -> 4.6469112 | M14: =SUM(C14:L14) -> 156.72695 | N14: =SUM(O14:V14) -> 156.73066 | O14: =SUM(USE!C14:DB14) -> 2.0009957 | P14: =wTRC!K14 -> 0 | Q14: =wABS!G13 -> 154.62993 | R14: =wABS!K13 -> 0 | S14: =wABS!O13 -> 0 | T14: =wABS!S13 -> 0 | U14: =wABS!W13 -> 0.0188386 | V14: =wTRD!O14 -> 0.080892994 | Y14: =M14-N14 -> -0.0037099101 | Z14: =IF(M14<>0,Y14/M14*100,0) -> -0.0023671169 | AB14: Coffee | AC14: =M27 -> 78.816824 | AD14: =N27 -> 87.891102 | AE14: =AC14-AD14 -> -9.074278 | AF14: =IF(AC14<>0,AE14/AC14*100,0) -> -11.513123
A15: Cassava (A123) | B15: ccass | C15: 125.44618 | D15: =wTRD!I15 -> 10.525037 | E15: =wTAX!G15 -> 0 | F15: =wTAX!K15 -> 0.00072855952 | G15: =wTAX!O15 -> 0 | H15: =wTAX!S15 -> 0 | I15: =wTAX!W15 -> 0 | J15: =wTAX!AA15 -> 0 | K15: =wTAX!AE15 -> 0.16768466 | L15: =wTRC!G15 -> 8.8321559 | M15: =SUM(C15:L15) -> 144.97179 | N15: =SUM(O15:V15) -> 141.1219 | O15: =SUM(USE!C15:DB15) -> 77.249343 | P15: =wTRC!K15 -> 0 | Q15: =wABS!G14 -> 63.780195 | R15: =wABS!K14 -> 0 | S15: =wABS!O14 -> 0 | T15: =wABS!S14 -> 0 | U15: =wABS!W14 -> -0.0024814996 | V15: =wTRD!O15 -> 0.094846383 | Y15: =M15-N15 -> 3.8498848 | Z15: =IF(M15<>0,Y15/M15*100,0) -> 2.6556097 | AB15: Tea (unprocessed green leaf) | AC15: =M28 -> 25.057749 | AD15: =N28 -> 25.805573 | AE15: =AC15-AD15 -> -0.74782384 | AF15: =IF(AC15<>0,AE15/AC15*100,0) -> -2.9844015
A16: Other roots & tubers (A129) | B16: croot | C16: 21.322825 | D16: =wTRD!I16 -> 0.051590165 | E16: =wTAX!G16 -> 0 | F16: =wTAX!K16 -> 0.00033623186 | G16: =wTAX!O16 -> 0 | H16: =wTAX!S16 -> 0 | I16: =wTAX!W16 -> 0 | J16: =wTAX!AA16 -> 0.015457469 | K16: =wTAX!AE16 -> 2.9327548e-05 | L16: =wTRC!G16 -> 0.57181159 | M16: =SUM(C16:L16) -> 21.96205 | N16: =SUM(O16:V16) -> 22.55512 | O16: =SUM(USE!C16:DB16) -> 0.67724229 | P16: =wTRC!K16 -> 0 | Q16: =wABS!G15 -> 21.836842 | R16: =wABS!K15 -> 0 | S16: =wABS!O15 -> 0 | T16: =wABS!S15 -> 0 | U16: =wABS!W15 -> 0 | V16: =wTRD!O16 -> 0.041035951 | Y16: =M16-N16 -> -0.59307011 | Z16: =IF(M16<>0,Y16/M16*100,0) -> -2.7004315 | AB16: Other agricultural products | AC16: =SUM(M29:M32) -> 51.205297 | AD16: =SUM(N29:N32) -> 53.016986 | AE16: =AC16-AD16 -> -1.8116881 | AF16: =IF(AC16<>0,AE16/AC16*100,0) -> -3.5380873
A17: Dried beans (A131) | B17: cbean | C17: 225.71312 | D17: =wTRD!I17 -> 1.6038528 | E17: =wTAX!G17 -> 0 | F17: =wTAX!K17 -> 0.0028139099 | G17: =wTAX!O17 -> 0 | H17: =wTAX!S17 -> 0 | I17: =wTAX!W17 -> 0 | J17: =wTAX!AA17 -> 0.25476555 | K17: =wTAX!AE17 -> 0.018300945 | L17: =wTRC!G17 -> 9.6211128 | M17: =SUM(C17:L17) -> 237.21397 | N17: =SUM(O17:V17) -> 237.70874 | O17: =SUM(USE!C17:DB17) -> 6.6503043 | P17: =wTRC!K17 -> 0 | Q17: =wABS!G16 -> 219.39461 | R17: =wABS!K16 -> 0 | S17: =wABS!O16 -> 0 | T17: =wABS!S16 -> 0 | U17: =wABS!W16 -> -0.89508085 | V17: =wTRD!O17 -> 12.558905 | Y17: =M17-N17 -> -0.49476855 | Z17: =IF(M17<>0,Y17/M17*100,0) -> -0.2085748 | AB17: Livestock | AC17: =SUM(M33:M36) -> 150.15703 | AD17: =SUM(N33:N36) -> 144.69632 | AE17: =AC17-AD17 -> 5.4607034 | AF17: =IF(AC17<>0,AE17/AC17*100,0) -> 3.6366619
A18: Peas & other legumes (A132) | B18: cpeas | C18: 22.070413 | D18: =wTRD!I18 -> 0.067616629 | E18: =wTAX!G18 -> 0 | F18: =wTAX!K18 -> 0.0035085651 | G18: =wTAX!O18 -> 0 | H18: =wTAX!S18 -> 0 | I18: =wTAX!W18 -> 0 | J18: =wTAX!AA18 -> 0 | K18: =wTAX!AE18 -> 0.00047776255 | L18: =wTRC!G18 -> 1.1435333 | M18: =SUM(C18:L18) -> 23.285549 | N18: =SUM(O18:V18) -> 20.114949 | O18: =SUM(USE!C18:DB18) -> 1.8403145 | P18: =wTRC!K18 -> 0 | Q18: =wABS!G17 -> 17.899128 | R18: =wABS!K17 -> 0 | S18: =wABS!O17 -> 0 | T18: =wABS!S17 -> 0 | U18: =wABS!W17 -> -0.0014514351 | V18: =wTRD!O18 -> 0.37695823 | Y18: =M18-N18 -> 3.1705997 | Z18: =IF(M18<>0,Y18/M18*100,0) -> 13.616169 | AB18: Livestock and hunting products | AC18: =SUM(M37:M40) -> 56.318745 | AD18: =SUM(N37:N40) -> 60.872287 | AE18: =AC18-AD18 -> -4.553542 | AF18: =IF(AC18<>0,AE18/AC18*100,0) -> -8.0853045
A19: Other vegetables (A139) | B19: cvege | C19: 149.13716 | D19: =wTRD!I19 -> 2.0750742 | E19: =wTAX!G19 -> 0 | F19: =wTAX!K19 -> 0.0016149336 | G19: =wTAX!O19 -> 0 | H19: =wTAX!S19 -> 0 | I19: =wTAX!W19 -> 0 | J19: =wTAX!AA19 -> 0.23453505 | K19: =wTAX!AE19 -> 0.026407349 | L19: =wTRC!G19 -> 8.7860369 | M19: =SUM(C19:L19) -> 160.26083 | N19: =SUM(O19:V19) -> 160.12648 | O19: =SUM(USE!C19:DB19) -> 5.1103751 | P19: =wTRC!K19 -> 0 | Q19: =wABS!G18 -> 151.97639 | R19: =wABS!K18 -> 0 | S19: =wABS!O18 -> 0 | T19: =wABS!S18 -> 0 | U19: =wABS!W18 -> -0.084160701 | V19: =wTRD!O19 -> 3.1238748 | Y19: =M19-N19 -> 0.13435042 | Z19: =IF(M19<>0,Y19/M19*100,0) -> 0.083832352 | AB19: Forestry products | AC19: =SUM(M41:M43) -> 404.20062 | AD19: =SUM(N41:N43) -> 401.15729 | AE19: =AC19-AD19 -> 3.0433346 | AF19: =IF(AC19<>0,AE19/AC19*100,0) -> 0.75292675
A20: Bananas for beer (A141) | B20: cbanb | C20: 81.996625 | D20: =wTRD!I20 -> 0 | E20: =wTAX!G20 -> 0 | F20: =wTAX!K20 -> 0 | G20: =wTAX!O20 -> 0 | H20: =wTAX!S20 -> 0 | I20: =wTAX!W20 -> 0 | J20: =wTAX!AA20 -> 0.02680285 | K20: =wTAX!AE20 -> 0 | L20: =wTRC!G20 -> 1.0858245 | M20: =SUM(C20:L20) -> 83.109253 | N20: =SUM(O20:V20) -> 79.140909 | O20: =SUM(USE!C20:DB20) -> 64.968406 | P20: =wTRC!K20 -> 0 | Q20: =wABS!G19 -> 6.2864969 | R20: =wABS!K19 -> 0 | S20: =wABS!O19 -> 0 | T20: =wABS!S19 -> 0 | U20: =wABS!W19 -> 7.8860059 | V20: =wTRD!O20 -> 0 | Y20: =M20-N20 -> 3.968344 | Z20: =IF(M20<>0,Y20/M20*100,0) -> 4.7748523 | AB20: Fishery products | AC20: =SUM(M44) -> 32.672003 | AD20: =SUM(N44) -> 31.972824 | AE20: =AC20-AD20 -> 0.69917902 | AF20: =IF(AC20<>0,AE20/AC20*100,0) -> 2.1399944
A21: Bananas for cooking (A142) | B21: cbanc | C21: 149.29912 | D21: =wTRD!I21 -> 0 | E21: =wTAX!G21 -> 0 | F21: =wTAX!K21 -> 0 | G21: =wTAX!O21 -> 0 | H21: =wTAX!S21 -> 0 | I21: =wTAX!W21 -> 0 | J21: =wTAX!AA21 -> 0 | K21: =wTAX!AE21 -> 0 | L21: =wTRC!G21 -> 7.8310607 | M21: =SUM(C21:L21) -> 157.13018 | N21: =SUM(O21:V21) -> 157.5686 | O21: =SUM(USE!C21:DB21) -> 4.3395681 | P21: =wTRC!K21 -> 0 | Q21: =wABS!G20 -> 153.22903 | R21: =wABS!K20 -> 0 | S21: =wABS!O20 -> 0 | T21: =wABS!S20 -> 0 | U21: =wABS!W20 -> 0 | V21: =wTRD!O21 -> 0 | Y21: =M21-N21 -> -0.43842263 | Z21: =IF(M21<>0,Y21/M21*100,0) -> -0.27901873
A22: Bananas (sweet) (A143) | B22: cbans | C22: 27.075522 | D22: =wTRD!I22 -> 0.41475799 | E22: =wTAX!G22 -> 0 | F22: =wTAX!K22 -> 0 | G22: =wTAX!O22 -> 0 | H22: =wTAX!S22 -> 0 | I22: =wTAX!W22 -> 0 | J22: =wTAX!AA22 -> 0.053319703 | K22: =wTAX!AE22 -> 0 | L22: =wTRC!G22 -> 1.8044565 | M22: =SUM(C22:L22) -> 29.348056 | N22: =SUM(O22:V22) -> 31.602882 | O22: =SUM(USE!C22:DB22) -> 0.52964074 | P22: =wTRC!K22 -> 0 | Q22: =wABS!G21 -> 30.448103 | R22: =wABS!K21 -> 0 | S22: =wABS!O21 -> 0 | T22: =wABS!S21 -> 0 | U22: =wABS!W21 -> -0.0037393247 | V22: =wTRD!O22 -> 0.62887799 | Y22: =M22-N22 -> -2.2548259 | Z22: =IF(M22<>0,Y22/M22*100,0) -> -7.6830504
A23: Other fruit & nuts (A149) | B23: cfrui | C23: 25.31831 | D23: =wTRD!I23 -> 5.9242395 | E23: =wTAX!G23 -> 0 | F23: =wTAX!K23 -> 0.29684318 | G23: =wTAX!O23 -> 0 | H23: =wTAX!S23 -> 0 | I23: =wTAX!W23 -> 0 | J23: =wTAX!AA23 -> 0.051246513 | K23: =wTAX!AE23 -> 0.093720851 | L23: =wTRC!G23 -> 1.7525436 | M23: =SUM(C23:L23) -> 33.436904 | N23: =SUM(O23:V23) -> 36.177517 | O23: =SUM(USE!C23:DB23) -> 0.94472221 | P23: =wTRC!K23 -> 0 | Q23: =wABS!G22 -> 33.809848 | R23: =wABS!K22 -> 0 | S23: =wABS!O22 -> 0 | T23: =wABS!S22 -> 0 | U23: =wABS!W22 -> 0.030378481 | V23: =wTRD!O23 -> 1.3925687 | Y23: =M23-N23 -> -2.7406138 | Z23: =IF(M23<>0,Y23/M23*100,0) -> -8.1963744
A24: Ground nuts (A151) | B24: cgnut | C24: 11.29778 | D24: =wTRD!I24 -> 2.6663743 | E24: =wTAX!G24 -> 0 | F24: =wTAX!K24 -> 0.022272394 | G24: =wTAX!O24 -> 0 | H24: =wTAX!S24 -> 0 | I24: =wTAX!W24 -> 0 | J24: =wTAX!AA24 -> 0.029128714 | K24: =wTAX!AE24 -> 0.042914822 | L24: =wTRC!G24 -> 0.99482031 | M24: =SUM(C24:L24) -> 15.05329 | N24: =SUM(O24:V24) -> 15.06378 | O24: =SUM(USE!C24:DB24) -> 13.816022 | P24: =wTRC!K24 -> 0 | Q24: =wABS!G23 -> 1.3784852 | R24: =wABS!K23 -> 0 | S24: =wABS!O23 -> 0 | T24: =wABS!S23 -> 0 | U24: =wABS!W23 -> -0.61086273 | V24: =wTRD!O24 -> 0.4801356 | Y24: =M24-N24 -> -0.010489798 | Z24: =IF(M24<>0,Y24/M24*100,0) -> -0.06968442
A25: Soya (A152) | B25: csoya | C25: 3.7090505 | D25: =wTRD!I25 -> 0.02941353 | E25: =wTAX!G25 -> 0 | F25: =wTAX!K25 -> 0 | G25: =wTAX!O25 -> 0 | H25: =wTAX!S25 -> 0 | I25: =wTAX!W25 -> 0 | J25: =wTAX!AA25 -> 0 | K25: =wTAX!AE25 -> 0 | L25: =wTRC!G25 -> 0.27705296 | M25: =SUM(C25:L25) -> 4.015517 | N25: =SUM(O25:V25) -> 4.1401632 | O25: =SUM(USE!C25:DB25) -> 2.9595119 | P25: =wTRC!K25 -> 0 | Q25: =wABS!G24 -> 0.9170293 | R25: =wABS!K24 -> 0 | S25: =wABS!O24 -> 0 | T25: =wABS!S24 -> 0 | U25: =wABS!W24 -> 0.17476968 | V25: =wTRD!O25 -> 0.088852277 | Y25: =M25-N25 -> -0.12464619 | Z25: =IF(M25<>0,Y25/M25*100,0) -> -3.104113
A26: Other oil seeds (A159) | B26: coils | C26: 0 | D26: =wTRD!I26 -> 5.9846523 | E26: =wTAX!G26 -> 0 | F26: =wTAX!K26 -> 0.0045607132 | G26: =wTAX!O26 -> 0 | H26: =wTAX!S26 -> 0 | I26: =wTAX!W26 -> 0 | J26: =wTAX!AA26 -> 0.02688628 | K26: =wTAX!AE26 -> 0.097818641 | L26: =wTRC!G26 -> 0.063587358 | M26: =SUM(C26:L26) -> 6.1775053 | N26: =SUM(O26:V26) -> 5.8683291 | O26: =SUM(USE!C26:DB26) -> 5.7220628 | P26: =wTRC!K26 -> 0 | Q26: =wABS!G25 -> 0 | R26: =wABS!K25 -> 0 | S26: =wABS!O25 -> 0 | T26: =wABS!S25 -> 0 | U26: =wABS!W25 -> 0.047947885 | V26: =wTRD!O26 -> 0.098318397 | Y26: =M26-N26 -> 0.30917626 | Z26: =IF(M26<>0,Y26/M26*100,0) -> 5.0048725
A27: Coffee, not roasted, not decaffeinated (A210) | B27: ccoff | C27: 77.23931 | D27: =wTRD!I27 -> 1.422821 | E27: =wTAX!G27 -> 0 | F27: =wTAX!K27 -> 0.0010978173 | G27: =wTAX!O27 -> 0 | H27: =wTAX!S27 -> 0 | I27: =wTAX!W27 -> 0 | J27: =wTAX!AA27 -> 0.0036042173 | K27: =wTAX!AE27 -> 0.00032881548 | L27: =wTRC!G27 -> 0.149662 | M27: =SUM(C27:L27) -> 78.816824 | N27: =SUM(O27:V27) -> 87.891102 | O27: =SUM(USE!C27:DB27) -> 7.4416417 | P27: =wTRC!K27 -> 0 | Q27: =wABS!G26 -> 0 | R27: =wABS!K26 -> 0 | S27: =wABS!O26 -> 0 | T27: =wABS!S26 -> 0 | U27: =wABS!W26 -> 26.939791 | V27: =wTRD!O27 -> 53.509669 | Y27: =M27-N27 -> -9.074278 | Z27: =IF(M27<>0,Y27/M27*100,0) -> -11.513123
A28: Tea (unprocessed green leaf) (A220) | B28: cteal | C28: 24.516516 | D28: =wTRD!I28 -> 0.20298914 | E28: =wTAX!G28 -> 0 | F28: =wTAX!K28 -> 0.00059266885 | G28: =wTAX!O28 -> 0 | H28: =wTAX!S28 -> 0 | I28: =wTAX!W28 -> 0 | J28: =wTAX!AA28 -> 0.037695047 | K28: =wTAX!AE28 -> 0.0033214239 | L28: =wTRC!G28 -> 0.29663475 | M28: =SUM(C28:L28) -> 25.057749 | N28: =SUM(O28:V28) -> 25.805573 | O28: =SUM(USE!C28:DB28) -> 23.399379 | P28: =wTRC!K28 -> 0 | Q28: =wABS!G27 -> 3.9758412e-14 | R28: =wABS!K27 -> 0 | S28: =wABS!O27 -> 0 | T28: =wABS!S27 -> 0 | U28: =wABS!W27 -> 2.4061937 | V28: =wTRD!O28 -> 0 | Y28: =M28-N28 -> -0.74782384 | Z28: =IF(M28<>0,Y28/M28*100,0) -> -2.9844015
A29: Tobacco, raw (A291) | B29: ctoba | C29: 4.1958653 | D29: =wTRD!I29 -> 0.41730792 | E29: =wTAX!G29 -> 0 | F29: =wTAX!K29 -> 0.00081479944 | G29: =wTAX!O29 -> 0 | H29: =wTAX!S29 -> 0 | I29: =wTAX!W29 -> 0 | J29: =wTAX!AA29 -> 0.001359976 | K29: =wTAX!AE29 -> 0.0026557946 | L29: =wTRC!G29 -> 0.049605048 | M29: =SUM(C29:L29) -> 4.6676088 | N29: =SUM(O29:V29) -> 4.6009673 | O29: =SUM(USE!C29:DB29) -> 0.039770034 | P29: =wTRC!K29 -> 0 | Q29: =wABS!G28 -> 4.6082119 | R29: =wABS!K28 -> 0 | S29: =wABS!O28 -> 0 | T29: =wABS!S28 -> 0 | U29: =wABS!W28 -> -0.049116805 | V29: =wTRD!O29 -> 0.0021022222 | Y29: =M29-N29 -> 0.066641476 | Z29: =IF(M29<>0,Y29/M29*100,0) -> 1.4277434
A30: Sugar cane (A292) | B30: csugr | C30: 9.6086734 | D30: =wTRD!I30 -> 0.082659146 | E30: =wTAX!G30 -> 0 | F30: =wTAX!K30 -> 5.8054121e-06 | G30: =wTAX!O30 -> 0 | H30: =wTAX!S30 -> 0 | I30: =wTAX!W30 -> 0 | J30: =wTAX!AA30 -> 0.0025991823 | K30: =wTAX!AE30 -> 1.0636648e-06 | L30: =wTRC!G30 -> 0.06174218 | M30: =SUM(C30:L30) -> 9.7556808 | N30: =SUM(O30:V30) -> 6.0085959 | O30: =SUM(USE!C30:DB30) -> 0.091074722 | P30: =wTRC!K30 -> 0 | Q30: =wABS!G29 -> 4.770436 | R30: =wABS!K29 -> 0 | S30: =wABS!O29 -> 0 | T30: =wABS!S29 -> 0 | U30: =wABS!W29 -> 0 | V30: =wTRD!O30 -> 1.1470852 | Y30: =M30-N30 -> 3.7470848 | Z30: =IF(M30<>0,Y30/M30*100,0) -> 38.409261
A31: Pyrethrum (A293) | B31: cpyre | C31: 5.588236 | D31: =wTRD!I31 -> 0 | E31: =wTAX!G31 -> 0 | F31: =wTAX!K31 -> 0 | G31: =wTAX!O31 -> 0 | H31: =wTAX!S31 -> 0 | I31: =wTAX!W31 -> 0 | J31: =wTAX!AA31 -> 0.0017227413 | K31: =wTAX!AE31 -> 0 | L31: =wTRC!G31 -> 0.064734908 | M31: =SUM(C31:L31) -> 5.6546937 | N31: =SUM(O31:V31) -> 5.6351931 | O31: =SUM(USE!C31:DB31) -> 0.052967462 | P31: =wTRC!K31 -> 0 | Q31: =wABS!G30 -> 0 | R31: =wABS!K30 -> 0 | S31: =wABS!O30 -> 0 | T31: =wABS!S30 -> 0 | U31: =wABS!W30 -> 0 | V31: =wTRD!O31 -> 5.5822257 | Y31: =M31-N31 -> 0.019500539 | Z31: =IF(M31<>0,Y31/M31*100,0) -> 0.3448558
A32: Agricultural products n.e.c. (A299) | B32: cocrp | C32: 28.84254 | D32: =wTRD!I32 -> 1.8305554 | E32: =wTAX!G32 -> 0 | F32: =wTAX!K32 -> 0.0022134426 | G32: =wTAX!O32 -> 0 | H32: =wTAX!S32 -> 0 | I32: =wTAX!W32 -> 0 | J32: =wTAX!AA32 -> 0.019984906 | K32: =wTAX!AE32 -> 0.012578293 | L32: =wTRC!G32 -> 0.41944261 | M32: =SUM(C32:L32) -> 31.127314 | N32: =SUM(O32:V32) -> 36.772229 | O32: =SUM(USE!C32:DB32) -> 27.108743 | P32: =wTRC!K32 -> 0 | Q32: =wABS!G31 -> 1.9419286 | R32: =wABS!K31 -> 0 | S32: =wABS!O31 -> 0 | T32: =wABS!S31 -> 0 | U32: =wABS!W31 -> 5.7045392 | V32: =wTRD!O32 -> 2.0170181 | Y32: =M32-N32 -> -5.644915 | Z32: =IF(M32<>0,Y32/M32*100,0) -> -18.134925
... A78: Waste collection and management (E02) | B78: cwast | C78: 8.6127437 | D78: =wTRD!I78 -> 0 | E78: =wTAX!G78 -> 0 | F78: =wTAX!K78 -> 0 | G78: =wTAX!O78 -> 0 | H78: =wTAX!S78 -> 0 | I78: =wTAX!W78 -> 0 | J78: =wTAX!AA78 -> 0 | K78: =wTAX!AE78 -> 0 | L78: =wTRC!G78 -> 0 | M78: =SUM(C78:L78) -> 8.6127437 | N78: =SUM(O78:V78) -> 8.6071662 | O78: =SUM(USE!C78:DB78) -> 4.865261 | P78: =wTRC!K78 -> 0 | Q78: =wABS!G77 -> 3.7419052 | R78: =wABS!K77 -> 0 | S78: =wABS!O77 -> 0 | T78: =wABS!S77 -> 0 | U78: =wABS!W77 -> 0 | V78: =wTRD!O78 -> 0 | Y78: =M78-N78 -> 0.0055775672 | Z78: =IF(M78<>0,Y78/M78*100,0) -> 0.064759471
A79: Construction (modern) (F01) | B79: ccons | C79: 1286.9555 | D79: =wTRD!I79 -> 16.625815 | E79: =wTAX!G79 -> 0 | F79: =wTAX!K79 -> 0 | G79: =wTAX!O79 -> 0 | H79: =wTAX!S79 -> 0 | I79: =wTAX!W79 -> 0 | J79: =wTAX!AA79 -> 68.877012 | K79: =wTAX!AE79 -> 0 | L79: =wTRC!G79 -> 0 | M79: =SUM(C79:L79) -> 1372.4583 | N79: =SUM(O79:V79) -> 1376.4557 | O79: =SUM(USE!C79:DB79) -> 130.41273 | P79: =wTRC!K79 -> 0 | Q79: =wABS!G78 -> 62.903839 | R79: =wABS!K78 -> 0 | S79: =wABS!O78 -> 751.64126 | T79: =wABS!S78 -> 395.73968 | U79: =wABS!W78 -> 0 | V79: =[1]SUT!AD79 -> 35.75817 | W79: =[1]SUT!U79 -> 16.625815 | Y79: =M79-N79 -> -3.9973886 | Z79: =IF(M79<>0,Y79/M79*100,0) -> -0.29125757
A80: Construction (traditional) (F02) | B80: ccont | C80: 0 | D80: =wTRD!I80 -> 0 | E80: =wTAX!G80 -> 0 | F80: =wTAX!K80 -> 0 | G80: =wTAX!O80 -> 0 | H80: =wTAX!S80 -> 0 | I80: =wTAX!W80 -> 0 | J80: =wTAX!AA80 -> 0 | K80: =wTAX!AE80 -> 0 | L80: =wTRC!G80 -> 0 | M80: =SUM(C80:L80) -> 0 | N80: =SUM(O80:V80) -> 0 | O80: =SUM(USE!C80:DB80) -> 0 | P80: =wTRC!K80 -> 0 | Q80: =wABS!G79 -> 0 | R80: =wABS!K79 -> 0 | S80: =wABS!O79 -> 0 | T80: =wABS!S79 -> 0 | U80: =wABS!W79 -> 0 | V80: =[1]SUT!AD80 -> 0 | W80: =[1]SUT!U80 -> 0 | Y80: =M80-N80 -> 0 | Z80: =IF(M80<>0,Y80/M80*100,0) -> 0
A81: Maintenance and repair of motor vehicles (G10) | B81: cvehr | C81: 45.580684 | D81: =wTRD!I81 -> 0.066082117 | E81: =wTAX!G81 -> 0 | F81: =wTAX!K81 -> 0 | G81: =wTAX!O81 -> 0 | H81: =wTAX!S81 -> 0 | I81: =wTAX!W81 -> 0 | J81: =wTAX!AA81 -> 0.30225698 | K81: =wTAX!AE81 -> 0 | L81: =wTRC!G81 -> 0 | M81: =SUM(C81:L81) -> 45.949023 | N81: =SUM(O81:V81) -> 51.173371 | O81: =SUM(USE!C81:DB81) -> 42.882659 | P81: =wTRC!K81 -> 0 | Q81: =wABS!G80 -> 8.1249167 | R81: =wABS!K80 -> 0 | S81: =wABS!O80 -> 0 | T81: =wABS!S80 -> 0 | U81: =wABS!W80 -> 0 | V81: =[1]SUT!AD81 -> 0.16579485 | W81: =[1]SUT!U81 -> 0.066082117 | Y81: =M81-N81 -> -5.2243482 | Z81: =IF(M81<>0,Y81/M81*100,0) -> -11.369879
A82: Wholesale and retail trade of motor vehicles and motorcycles (G21) | B82: cveht | C82: 8.5434633 | D82: =wTRD!I82 -> 0 | E82: =wTAX!G82 -> 0 | F82: =wTAX!K82 -> 0 | G82: =wTAX!O82 -> 0 | H82: =wTAX!S82 -> 0 | I82: =wTAX!W82 -> 0 | J82: =wTAX!AA82 -> 0 | K82: =wTAX!AE82 -> 0 | L82: =wTRC!G82 -> 0 | M82: =SUM(C82:L82) -> 8.5434633 | N82: =SUM(O82:V82) -> 9.4328712 | O82: =SUM(USE!C82:DB82) -> 0 | P82: =wTRC!K82 -> 9.4328712 | Q82: =wABS!G81 -> 5.2228096e-13 | R82: =wABS!K81 -> 0 | S82: =wABS!O81 -> 0 | T82: =wABS!S81 -> 0 | U82: =wABS!W81 -> 0 | V82: =[1]SUT!AD82 -> 0 | W82: =[1]SUT!U82 -> 0 | Y82: =M82-N82 -> -0.88940793 | Z82: =IF(M82<>0,Y82/M82*100,0) -> -10.410391
A83: Wholesale trade, except of motor vehicles and motorcycles (G22) | B83: ctrdw | C83: 369.40298 | D83: =wTRD!I83 -> 0 | E83: =wTAX!G83 -> 0 | F83: =wTAX!K83 -> 0 | G83: =wTAX!O83 -> 0 | H83: =wTAX!S83 -> 0 | I83: =wTAX!W83 -> 0 | J83: =wTAX!AA83 -> 0 | K83: =wTAX!AE83 -> 0 | L83: =wTRC!G83 -> 0 | M83: =SUM(C83:L83) -> 369.40298 | N83: =SUM(O83:V83) -> 366.8969 | O83: =SUM(USE!C83:DB83) -> 0 | P83: =wTRC!K83 -> 366.8969 | Q83: =wABS!G82 -> 0 | R83: =wABS!K82 -> 0 | S83: =wABS!O82 -> 0 | T83: =wABS!S82 -> 0 | U83: =wABS!W82 -> 0 | V83: =[1]SUT!AD83 -> 0 | W83: =[1]SUT!U83 -> 0 | Y83: =M83-N83 -> 2.5060751 | Z83: =IF(M83<>0,Y83/M83*100,0) -> 0.67841225
A84: Retail trade, except of motor vehicles and motorcycles (G23) | B84: ctrdr | C84: 682.96525 | D84: =wTRD!I84 -> 0 | E84: =wTAX!G84 -> 0 | F84: =wTAX!K84 -> 0 | G84: =wTAX!O84 -> 0 | H84: =wTAX!S84 -> 0 | I84: =wTAX!W84 -> 0 | J84: =wTAX!AA84 -> 0 | K84: =wTAX!AE84 -> 0 | L84: =wTRC!G84 -> 0 | M84: =SUM(C84:L84) -> 682.96525 | N84: =SUM(O84:V84) -> 677.38585 | O84: =SUM(USE!C84:DB84) -> 0 | P84: =wTRC!K84 -> 677.38585 | Q84: =wABS!G83 -> 0 | R84: =wABS!K83 -> 0 | S84: =wABS!O83 -> 0 | T84: =wABS!S83 -> 0 | U84: =wABS!W83 -> 0 | V84: =[1]SUT!AD84 -> 0 | W84: =[1]SUT!U84 -> 0 | Y84: =M84-N84 -> 5.5794079 | Z84: =IF(M84<>0,Y84/M84*100,0) -> 0.81693877
A85: Land transport (H10) | B85: ctrnl | C85: 443.17788 | D85: =wTRD!I85 -> -12.14762 | E85: =wTAX!G85 -> 0 | F85: =wTAX!K85 -> 0 | G85: =wTAX!O85 -> 0 | H85: =wTAX!S85 -> 0 | I85: =wTAX!W85 -> 0 | J85: =wTAX!AA85 -> 3.1801699 | K85: =wTAX!AE85 -> 35.145485 | L85: =wTRC!G85 -> 0 | M85: =SUM(C85:L85) -> 469.35592 | N85: =SUM(O85:V85) -> 466.71452 | O85: =SUM(USE!C85:DB85) -> 194.19443 | P85: =wTRC!K85 -> 0 | Q85: =wABS!G84 -> 265.42917 | R85: =wABS!K84 -> 0 | S85: =wABS!O84 -> 0 | T85: =wABS!S84 -> 0 | U85: =wABS!W84 -> 0 | V85: =[1]SUT!AD85 -> 7.0909288 | W85: =[1]SUT!U85 -> -12.14762 | Y85: =M85-N85 -> 2.6413968 | Z85: =IF(M85<>0,Y85/M85*100,0) -> 0.56277054
A86: Air transport (H20) | B86: ctrna | C86: 180.52282 | D86: =wTRD!I86 -> 63.779916 | E86: =wTAX!G86 -> -85.334627 | F86: =wTAX!K86 -> 0 | G86: =wTAX!O86 -> 0 | H86: =wTAX!S86 -> 0 | I86: =wTAX!W86 -> 0 | J86: =wTAX!AA86 -> 1.3779153 | K86: =wTAX!AE86 -> 0 | L86: =wTRC!G86 -> 0 | M86: =SUM(C86:L86) -> 160.34602 | N86: =SUM(O86:V86) -> 162.42091 | O86: =SUM(USE!C86:DB86) -> 60.119947 | P86: =wTRC!K86 -> 0 | Q86: =wABS!G85 -> 11.83282 | R86: =wABS!K85 -> 0 | S86: =wABS!O85 -> 0 | T86: =wABS!S85 -> 0 | U86: =wABS!W85 -> 0 | V86: =[1]SUT!AD86 -> 90.46814 | W86: =[1]SUT!U86 -> 63.779916 | Y86: =M86-N86 -> -2.0748867 | Z86: =IF(M86<>0,Y86/M86*100,0) -> -1.2940058
...

Sheet USE
A1: Use Table
A2: Final values exported to GAMS
B4: From w-GDP | C4: {=TRANSPOSE(wGDPp!D8:D111)} -> 42.163108 | D4: 91.54879 | E4: 3.0363336 | F4: 55.892973 | G4: 0.27145353 | H4: 159.09592 | I4: 141.62941 | J4: 117.32855 | K4: 19.943023 | L4: 214.58619 | M4: 20.982413 | N4: 141.78518 | O4: 80.184602 | P4: 145.99979 | Q4: 26.477187 | R4: 24.758807 | S4: 8.5193652 | T4: 2.7968996 | U4: 0 | V4: 70.943429 | W4: 22.405977 | X4: 3.8840398 | Y4: 8.8945824 | Z4: 5.1729332 | AA4: 26.699039 | AB4: 76.457883 | AC4: 44.055757 | AD4: 12.119768 | AE4: 2.1617689 | AF4: 32.944426 | AG4: 14.264471 | AH4: 0.51409051 | AI4: 3.4818361 | AJ4: 300.53637 | AK4: 57.932328 | AL4: 19.531302 | AM4: 29 | AN4: 0.069262115 | AO4: 68.516522 | AP4: 96.414216 | AQ4: 21.926921 | AR4: 0 | AS4: 6.0929636 | AT4: 8.0793322 | AU4: 4.5099278 | AV4: 104.82926 | AW4: 16.426382 | AX4: 3.9291026 | AY4: 44.206113 | AZ4: 127.92243 | BA4: 25.055473 | BB4: 6.0220933 | BC4: 34 | BD4: 15.323992 | BE4: 10.676008 | BF4: 0.21840247 | BG4: 24.657724 | BH4: 5.5319545 | BI4: 3.5919192 | BJ4: 2.2300431 | BK4: 20.506689 | BL4: 11.263268 | BM4: 19.183835 | BN4: 8.4078105 | BO4: 4.4083546 | BP4: 23.782313 | BQ4: 37.021553 | BR4: 0.19613379 | BS4: 84 | BT4: 28.085247 | BU4: 3.9147533 | BV4: 458 | BW4: 0 | BX4: 35.699691 | BY4: 4.3003095 | BZ4: 180.44072 | CA4: 416.55928 | CB4: 205.15736 | CC4: 95.814909 | CD4: 44.025665 | CE4: 10.002069 | CF4: 140 | CG4: 22.681642 | CH4: 89.229867 | CI4: 22.088491 | CJ4: 53.971869 | CK4: 39.923725 | CL4: 97.104407 | CM4: 414.40535 | CN4: 145.59465 | CO4: 46.915941 | CP4: 14.49952 | CQ4: 101.58454 | CR4: 20.526827 | CS4: 256.47317 | CT4: 446 | CU4: 231 | CV4: 101.34991 | CW4: 58.650093 | CX4: 12.292706 | CY4: 52.356976 | CZ4: 301.47796 | DA4: 24.872356 | DB4: 0
B5: To Supply | C5: =SUM(C8:C114) -> 45.186128 | D5: =SUM(D8:D114) -> 98.112675 | E5: =SUM(E8:E114) -> 3.2540333 | F5: =SUM(F8:F114) -> 59.900399 | G5: =SUM(G8:G114) -> 0.29091626 | H5: =SUM(H8:H114) -> 170.10332 | I5: =SUM(I8:I114) -> 151.42836 | J5: =SUM(J8:J114) -> 125.44618 | ... DB5: =SUM(DB8:DB114) -> 0
C7: asorg | D7: amaiz | E7: awhea | F7: arice | G7: aocer | H7: aipot | I7: aspot | J7: acass | K7: aroot | L7: abean | M7: apeas | N7: avege | O7: abanb | P7: abanc | Q7: abans | R7: afrui | S7: agnut | T7: asoya | U7: aoils | V7: acoff | W7: ateal | X7: atoba | Y7: asugr | Z7: apyre | AA7: aocrp | AB7: acatt | AC7: asmlr | AD7: apoul | AE7: aoliv | AF7: amilk | AG7: aeggs | AH7: ahony | AI7: ahunt | AJ7: afuel | AK7: achar | AL7: afore | AM7: afish | AN7: angas | AO7: amore | AP7: aomin | AQ7: ameat | AR7: afsea | AS7: afveg | AT7: afoil | AU7: adair | AV7: agmll | AW7: abake | AX7: afeed | AY7: afood | AZ7: aalco | BA7: abeve | BB7: aptob | BC7: atext | BD7: awood | BE7: aprnt | BF7: apetr | BG7: achem | BH7: aphar | BI7: aprub | BJ7: anmet | BK7: aceme | BL7: aclay | BM7: ametl | BN7: amach | BO7: avehi | BP7: afurn | BQ7: aoman | BR7: arepr | BS7: aelec | BT7: awatr | BU7: awast | BV7: acons | BW7: acont | BX7: avehr | BY7: aveht | BZ7: atrdw | CA7: atrdr | CB7: atrnl | CC7: atrna | CD7: atrns | CE7: apost | CF7: ahotl | CG7: apubl | CH7: acomm | CI7: ainfo | CJ7: abank | CK7: ainsu | CL7: aofsv | CM7: arent | CN7: areal | CO7: alegl | CP7: aenga | CQ7: aprod | CR7: atrvl | CS7: aobsv | CT7: apadm | CU7: aeduc | CV7: aheal | CW7: asocw | CX7: acult | CY7: aarts | CZ7: aosrv | DA7: adsrv | DB7: atrdc
B8: csorg | C8: =IF(SUM(wUSE!C$113:C$115),C$4*wUSE!C9/SUM(wUSE!C$113:C$115),0) -> 0.34007323 | D8: =IF(SUM(wUSE!D$113:D$115),D$4*wUSE!D9/SUM(wUSE!D$113:D$115),0) -> 0 | E8: =IF(SUM(wUSE!E$113:E$115),E$4*wUSE!E9/SUM(wUSE!E$113:E$115),0) -> 0 | F8: =IF(SUM(wUSE!F$113:F$115),F$4*wUSE!F9/SUM(wUSE!F$113:F$115),0) -> 0 | G8: =IF(SUM(wUSE!G$113:G$115),G$4*wUSE!G9/SUM(wUSE!G$113:G$115),0) -> 0 | H8: =IF(SUM(wUSE!H$113:H$115),H$4*wUSE!H9/SUM(wUSE!H$113:H$115),0) -> 0 | I8: =IF(SUM(wUSE!I$113:I$115),I$4*wUSE!I9/SUM(wUSE!I$113:I$115),0) -> 0 | J8: =IF(SUM(wUSE!J$113:J$115),J$4*wUSE!J9/SUM(wUSE!J$113:J$115),0) -> 0 | ... DB8: =IF(SUM(wUSE!DB$113:DB$115),DB$4*wUSE!DB9/SUM(wUSE!DB$113:DB$115),0) -> 0
B9: cmaiz | C9: =IF(SUM(wUSE!C$113:C$115),C$4*wUSE!C10/SUM(wUSE!C$113:C$115),0) -> 0 | D9: =IF(SUM(wUSE!D$113:D$115),D$4*wUSE!D10/SUM(wUSE!D$113:D$115),0) -> 0.73840128 | E9: =IF(SUM(wUSE!E$113:E$115),E$4*wUSE!E10/SUM(wUSE!E$113:E$115),0) -> 0 | F9: =IF(SUM(wUSE!F$113:F$115),F$4*wUSE!F10/SUM(wUSE!F$113:F$115),0) -> 0 | G9: =IF(SUM(wUSE!G$113:G$115),G$4*wUSE!G10/SUM(wUSE!G$113:G$115),0) -> 0 | H9: =IF(SUM(wUSE!H$113:H$115),H$4*wUSE!H10/SUM(wUSE!H$113:H$115),0) -> 0 | I9: =IF(SUM(wUSE!I$113:I$115),I$4*wUSE!I10/SUM(wUSE!I$113:I$115),0) -> 0 | J9: =IF(SUM(wUSE!J$113:J$115),J$4*wUSE!J10/SUM(wUSE!J$113:J$115),0) -> 0 | ... DB9: =IF(SUM(wUSE!DB$113:DB$115),DB$4*wUSE!DB10/SUM(wUSE!DB$113:DB$115),0) -> 0
B10: cwhea | C10: =IF(SUM(wUSE!C$113:C$115),C$4*wUSE!C11/SUM(wUSE!C$113:C$115),0) -> 0 | D10: =IF(SUM(wUSE!D$113:D$115),D$4*wUSE!D11/SUM(wUSE!D$113:D$115),0) -> 0 | E10: =IF(SUM(wUSE!E$113:E$115),E$4*wUSE!E11/SUM(wUSE!E$113:E$115),0) -> 0.02449003 | F10: =IF(SUM(wUSE!F$113:F$115),F$4*wUSE!F11/SUM(wUSE!F$113:F$115),0) -> 0 | G10: =IF(SUM(wUSE!G$113:G$115),G$4*wUSE!G11/SUM(wUSE!G$113:G$115),0) -> 0 | H10: =IF(SUM(wUSE!H$113:H$115),H$4*wUSE!H11/SUM(wUSE!H$113:H$115),0) -> 0 | I10: =IF(SUM(wUSE!I$113:I$115),I$4*wUSE!I11/SUM(wUSE!I$113:I$115),0) -> 0 | J10: =IF(SUM(wUSE!J$113:J$115),J$4*wUSE!J11/SUM(wUSE!J$113:J$115),0) -> 0 | ... DB10: =IF(SUM(wUSE!DB$113:DB$115),DB$4*wUSE!DB11/SUM(wUSE!DB$113:DB$115),0) -> 0
B11: crice | C11: =IF(SUM(wUSE!C$113:C$115),C$4*wUSE!C12/SUM(wUSE!C$113:C$115),0) -> 0 | D11: =IF(SUM(wUSE!D$113:D$115),D$4*wUSE!D12/SUM(wUSE!D$113:D$115),0) -> 0 | E11: =IF(SUM(wUSE!E$113:E$115),E$4*wUSE!E12/SUM(wUSE!E$113:E$115),0) -> 0 | F11: =IF(SUM(wUSE!F$113:F$115),F$4*wUSE!F12/SUM(wUSE!F$113:F$115),0) -> 0.45081363 | G11: =IF(SUM(wUSE!G$113:G$115),G$4*wUSE!G12/SUM(wUSE!G$113:G$115),0) -> 0 | H11: =IF(SUM(wUSE!H$113:H$115),H$4*wUSE!H12/SUM(wUSE!H$113:H$115),0) -> 0 | I11: =IF(SUM(wUSE!I$113:I$115),I$4*wUSE!I12/SUM(wUSE!I$113:I$115),0) -> 0 | J11: =IF(SUM(wUSE!J$113:J$115),J$4*wUSE!J12/SUM(wUSE!J$113:J$115),0) -> 0 | ... DB11: =IF(SUM(wUSE!DB$113:DB$115),DB$4*wUSE!DB12/SUM(wUSE!DB$113:DB$115),0) -> 0
B12: cocer | C12: =IF(SUM(wUSE!C$113:C$115),C$4*wUSE!C13/SUM(wUSE!C$113:C$115),0) -> 0 | D12: =IF(SUM(wUSE!D$113:D$115),D$4*wUSE!D13/SUM(wUSE!D$113:D$115),0) -> 0 | E12: =IF(SUM(wUSE!E$113:E$115),E$4*wUSE!E13/SUM(wUSE!E$113:E$115),0) -> 0 | F12: =IF(SUM(wUSE!F$113:F$115),F$4*wUSE!F13/SUM(wUSE!F$113:F$115),0) -> 0 | G12: =IF(SUM(wUSE!G$113:G$115),G$4*wUSE!G13/SUM(wUSE!G$113:G$115),0) -> 0.0021894514 | H12: =IF(SUM(wUSE!H$113:H$115),H$4*wUSE!H13/SUM(wUSE!H$113:H$115),0) -> 0 | I12: =IF(SUM(wUSE!I$113:I$115),I$4*wUSE!I13/SUM(wUSE!I$113:I$115),0) -> 0 | J12: =IF(SUM(wUSE!J$113:J$115),J$4*wUSE!J13/SUM(wUSE!J$113:J$115),0) -> 0 | ... DB12: =IF(SUM(wUSE!DB$113:DB$115),DB$4*wUSE!DB13/SUM(wUSE!DB$113:DB$115),0) -> 0
B13: cipot | C13: =IF(SUM(wUSE!C$113:C$115),C$4*wUSE!C14/SUM(wUSE!C$113:C$115),0) -> 0 | D13: =IF(SUM(wUSE!D$113:D$115),D$4*wUSE!D14/SUM(wUSE!D$113:D$115),0) -> 0 | E13: =IF(SUM(wUSE!E$113:E$115),E$4*wUSE!E14/SUM(wUSE!E$113:E$115),0) -> 0 | F13: =IF(SUM(wUSE!F$113:F$115),F$4*wUSE!F14/SUM(wUSE!F$113:F$115),0) -> 0 | G13: =IF(SUM(wUSE!G$113:G$115),G$4*wUSE!G14/SUM(wUSE!G$113:G$115),0) -> 0 | H13: =IF(SUM(wUSE!H$113:H$115),H$4*wUSE!H14/SUM(wUSE!H$113:H$115),0) -> 1.9456344 | I13: =IF(SUM(wUSE!I$113:I$115),I$4*wUSE!I14/SUM(wUSE!I$113:I$115),0) -> 0 | J13: =IF(SUM(wUSE!J$113:J$115),J$4*wUSE!J14/SUM(wUSE!J$113:J$115),0) -> 0 | ... DB13: =IF(SUM(wUSE!DB$113:DB$115),DB$4*wUSE!DB14/SUM(wUSE!DB$113:DB$115),0) -> 0
B14: cspot | C14: =IF(SUM(wUSE!C$113:C$115),C$4*wUSE!C15/SUM(wUSE!C$113:C$115),0) -> 0 | D14: =IF(SUM(wUSE!D$113:D$115),D$4*wUSE!D15/SUM(wUSE!D$113:D$115),0) -> 0 | E14: =IF(SUM(wUSE!E$113:E$115),E$4*wUSE!E15/SUM(wUSE!E$113:E$115),0) -> 0 | F14: =IF(SUM(wUSE!F$113:F$115),F$4*wUSE!F15/SUM(wUSE!F$113:F$115),0) -> 0 | G14: =IF(SUM(wUSE!G$113:G$115),G$4*wUSE!G15/SUM(wUSE!G$113:G$115),0) -> 0 | H14: =IF(SUM(wUSE!H$113:H$115),H$4*wUSE!H15/SUM(wUSE!H$113:H$115),0) -> 0 | I14: =IF(SUM(wUSE!I$113:I$115),I$4*wUSE!I15/SUM(wUSE!I$113:I$115),0) -> 1.732031 | J14: =IF(SUM(wUSE!J$113:J$115),J$4*wUSE!J15/SUM(wUSE!J$113:J$115),0) -> 0 | ... DB14: =IF(SUM(wUSE!DB$113:DB$115),DB$4*wUSE!DB15/SUM(wUSE!DB$113:DB$115),0) -> 0
B15: ccass | C15: =IF(SUM(wUSE!C$113:C$115),C$4*wUSE!C16/SUM(wUSE!C$113:C$115),0) -> 0 | D15: =IF(SUM(wUSE!D$113:D$115),D$4*wUSE!D16/SUM(wUSE!D$113:D$115),0) -> 0 | E15: =IF(SUM(wUSE!E$113:E$115),E$4*wUSE!E16/SUM(wUSE!E$113:E$115),0) -> 0 | F15: =IF(SUM(wUSE!F$113:F$115),F$4*wUSE!F16/SUM(wUSE!F$113:F$115),0) -> 0 | G15: =IF(SUM(wUSE!G$113:G$115),G$4*wUSE!G16/SUM(wUSE!G$113:G$115),0) -> 0 | H15: =IF(SUM(wUSE!H$113:H$115),H$4*wUSE!H16/SUM(wUSE!H$113:H$115),0) -> 0 | I15: =IF(SUM(wUSE!I$113:I$115),I$4*wUSE!I16/SUM(wUSE!I$113:I$115),0) -> 0 | J15: =IF(SUM(wUSE!J$113:J$115),J$4*wUSE!J16/SUM(wUSE!J$113:J$115),0) -> 1.434848 | ... DB15: =IF(SUM(wUSE!DB$113:DB$115),DB$4*wUSE!DB16/SUM(wUSE!DB$113:DB$115),0) -> 0
B16: croot | C16: =IF(SUM(wUSE!C$113:C$115),C$4*wUSE!C17/SUM(wUSE!C$113:C$115),0) -> 0 | D16: =IF(SUM(wUSE!D$113:D$115),D$4*wUSE!D17/SUM(wUSE!D$113:D$115),0) -> 0 | E16: =IF(SUM(wUSE!E$113:E$115),E$4*wUSE!E17/SUM(wUSE!E$113:E$115),0) -> 0 | F16: =IF(SUM(wUSE!F$113:F$115),F$4*wUSE!F17/SUM(wUSE!F$113:F$115),0) -> 0 | G16: =IF(SUM(wUSE!G$113:G$115),G$4*wUSE!G17/SUM(wUSE!G$113:G$115),0) -> 0 | H16: =IF(SUM(wUSE!H$113:H$115),H$4*wUSE!H17/SUM(wUSE!H$113:H$115),0) -> 0 | I16: =IF(SUM(wUSE!I$113:I$115),I$4*wUSE!I17/SUM(wUSE!I$113:I$115),0) -> 0 | J16: =IF(SUM(wUSE!J$113:J$115),J$4*wUSE!J17/SUM(wUSE!J$113:J$115),0) -> 0 | ... DB16: =IF(SUM(wUSE!DB$113:DB$115),DB$4*wUSE!DB17/SUM(wUSE!DB$113:DB$115),0) -> 0
B17: cbean | C17: =IF(SUM(wUSE!C$113:C$115),C$4*wUSE!C18/SUM(wUSE!C$113:C$115),0) -> 0 | D17: =IF(SUM(wUSE!D$113:D$115),D$4*wUSE!D18/SUM(wUSE!D$113:D$115),0) -> 0 | E17: =IF(SUM(wUSE!E$113:E$115),E$4*wUSE!E18/SUM(wUSE!E$113:E$115),0) -> 0 | F17: =IF(SUM(wUSE!F$113:F$115),F$4*wUSE!F18/SUM(wUSE!F$113:F$115),0) -> 0 | G17: =IF(SUM(wUSE!G$113:G$115),G$4*wUSE!G18/SUM(wUSE!G$113:G$115),0) -> 0 | H17: =IF(SUM(wUSE!H$113:H$115),H$4*wUSE!H18/SUM(wUSE!H$113:H$115),0) -> 0 | I17: =IF(SUM(wUSE!I$113:I$115),I$4*wUSE!I18/SUM(wUSE!I$113:I$115),0) -> 0 | J17: =IF(SUM(wUSE!J$113:J$115),J$4*wUSE!J18/SUM(wUSE!J$113:J$115),0) -> 0 | ... DB17: =IF(SUM(wUSE!DB$113:DB$115),DB$4*wUSE!DB18/SUM(wUSE!DB$113:DB$115),0) -> 0
B18: cpeas | C18: =IF(SUM(wUSE!C$113:C$115),C$4*wUSE!C19/SUM(wUSE!C$113:C$115),0) -> 0 | D18: =IF(SUM(wUSE!D$113:D$115),D$4*wUSE!D19/SUM(wUSE!D$113:D$115),0) -> 0 | E18: =IF(SUM(wUSE!E$113:E$115),E$4*wUSE!E19/SUM(wUSE!E$113:E$115),0) -> 0 | F18: =IF(SUM(wUSE!F$113:F$115),F$4*wUSE!F19/SUM(wUSE!F$113:F$115),0) -> 0 | G18: =IF(SUM(wUSE!G$113:G$115),G$4*wUSE!G19/SUM(wUSE!G$113:G$115),0) -> 0 | H18: =IF(SUM(wUSE!H$113:H$115),H$4*wUSE!H19/SUM(wUSE!H$113:H$115),0) -> 0 | I18: =IF(SUM(wUSE!I$113:I$115),I$4*wUSE!I19/SUM(wUSE!I$113:I$115),0) -> 0 | J18: =IF(SUM(wUSE!J$113:J$115),J$4*wUSE!J19/SUM(wUSE!J$113:J$115),0) -> 0 | ... DB18: =IF(SUM(wUSE!DB$113:DB$115),DB$4*wUSE!DB19/SUM(wUSE!DB$113:DB$115),0) -> 0
B19: cvege | C19: =IF(SUM(wUSE!C$113:C$115),C$4*wUSE!C20/SUM(wUSE!C$113:C$115),0) -> 0 | D19: =IF(SUM(wUSE!D$113:D$115),D$4*wUSE!D20/SUM(wUSE!D$113:D$115),0) -> 0 | E19: =IF(SUM(wUSE!E$113:E$115),E$4*wUSE!E20/SUM(wUSE!E$113:E$115),0) -> 0 | F19: =IF(SUM(wUSE!F$113:F$115),F$4*wUSE!F20/SUM(wUSE!F$113:F$115),0) -> 0 | G19: =IF(SUM(wUSE!G$113:G$115),G$4*wUSE!G20/SUM(wUSE!G$113:G$115),0) -> 0 | H19: =IF(SUM(wUSE!H$113:H$115),H$4*wUSE!H20/SUM(wUSE!H$113:H$115),0) -> 0 | I19: =IF(SUM(wUSE!I$113:I$115),I$4*wUSE!I20/SUM(wUSE!I$113:I$115),0) -> 0 | J19: =IF(SUM(wUSE!J$113:J$115),J$4*wUSE!J20/SUM(wUSE!J$113:J$115),0) -> 0 | ... DB19: =IF(SUM(wUSE!DB$113:DB$115),DB$4*wUSE!DB20/SUM(wUSE!DB$113:DB$115),0) -> 0
... B114: fcap | C114: =IF(SUM(wUSE!C$113:C$115),C$4*wUSE!C115/SUM(wUSE!C$113:C$115),0) -> 3.0915433 | D114: =IF(SUM(wUSE!D$113:D$115),D$4*wUSE!D115/SUM(wUSE!D$113:D$115),0) -> 7.3312442 | E114: =IF(SUM(wUSE!E$113:E$115),E$4*wUSE!E115/SUM(wUSE!E$113:E$115),0) -> 0.28140232 | F114: =IF(SUM(wUSE!F$113:F$115),F$4*wUSE!F115/SUM(wUSE!F$113:F$115),0) -> 6.2513809 | G114: =IF(SUM(wUSE!G$113:G$115),G$4*wUSE!G115/SUM(wUSE!G$113:G$115),0) -> 0.019903901 | H114: =IF(SUM(wUSE!H$113:H$115),H$4*wUSE!H115/SUM(wUSE!H$113:H$115),0) -> 17.145547 | I114: =IF(SUM(wUSE!I$113:I$115),I$4*wUSE!I115/SUM(wUSE!I$113:I$115),0) -> 10.269122 | J114: =IF(SUM(wUSE!J$113:J$115),J$4*wUSE!J115/SUM(wUSE!J$113:J$115),0) -> 9.46332 | ... DB114: =IF(SUM(wUSE!DB$113:DB$115),DB$4*wUSE!DB115/SUM(wUSE!DB$113:DB$115),0) -> 0

Sheet SUP
A1: Supply Table
A2: Final values exported to GAMS
B4: To SUT | C4: =SUM(C8:C111) -> 45.186128 | D4: =SUM(D8:D111) -> 98.112675 | E4: =SUM(E8:E111) -> 3.2540333 | F4: =SUM(F8:F111) -> 59.900399 | G4: =SUM(G8:G111) -> 0.29091626 | H4: =SUM(H8:H111) -> 170.10332 | I4: =SUM(I8:I111) -> 151.42836 | J4: =SUM(J8:J111) -> 125.44618 | ... DB4: =SUM(DB8:DB111) -> 0
A7: From Use | C7: csorg | D7: cmaiz | E7: cwhea | F7: crice | G7: cocer | H7: cipot | I7: cspot | J7: ccass | K7: croot | L7: cbean | M7: cpeas | N7: cvege | O7: cbanb | P7: cbanc | Q7: cbans | R7: cfrui | S7: cgnut | T7: csoya | U7: coils | V7: ccoff | W7: cteal | X7: ctoba | Y7: csugr | Z7: cpyre | AA7: cocrp | AB7: ccatt | AC7: csmlr | AD7: cpoul | AE7: coliv | AF7: cmilk | AG7: ceggs | AH7: chony | AI7: chunt | AJ7: cfuel | AK7: cchar | AL7: cfore | AM7: cfish | AN7: cngas | AO7: cmore | AP7: comin | AQ7: cmeat | AR7: cfsea | AS7: cfveg | AT7: cfoil | AU7: cdair | AV7: cgmll | AW7: cbake | AX7: cfeed | AY7: cfood | AZ7: calco | BA7: cbeve | BB7: cptob | BC7: ctext | BD7: cwood | BE7: cprnt | BF7: cpetr | BG7: cchem | BH7: cphar | BI7: cprub | BJ7: cnmet | BK7: cceme | BL7: cclay | BM7: cmetl | BN7: cmach | BO7: cvehi | BP7: cfurn | BQ7: coman | BR7: crepr | BS7: celec | BT7: cwatr | BU7: cwast | BV7: ccons | BW7: ccont | BX7: cvehr | BY7: cveht | BZ7: ctrdw | CA7: ctrdr | CB7: ctrnl | CC7: ctrna | CD7: ctrns | CE7: cpost | CF7: chotl | CG7: cpubl | CH7: ccomm | CI7: cinfo | CJ7: cbank | CK7: cinsu | CL7: cofsv | CM7: crent | CN7: creal | CO7: clegl | CP7: cenga | CQ7: cprod | CR7: ctrvl | CS7: cobsv | CT7: cpadm | CU7: ceduc | CV7: cheal | CW7: csocw | CX7: ccult | CY7: carts | CZ7: cosrv | DA7: cdsrv | DB7: ctrdc
A8: {=TRANSPOSE(USE!C5:DB5)} -> 45.186128 | B8: asorg | C8: =IF(SUM(wSUP!$C8:$DB8),$A8*wSUP!C8/SUM(wSUP!$C8:$DB8),0) -> 45.186128 | D8: =IF(SUM(wSUP!$C8:$DB8),$A8*wSUP!D8/SUM(wSUP!$C8:$DB8),0) -> 0 | E8: =IF(SUM(wSUP!$C8:$DB8),$A8*wSUP!E8/SUM(wSUP!$C8:$DB8),0) -> 0 | F8: =IF(SUM(wSUP!$C8:$DB8),$A8*wSUP!F8/SUM(wSUP!$C8:$DB8),0) -> 0 | G8: =IF(SUM(wSUP!$C8:$DB8),$A8*wSUP!G8/SUM(wSUP!$C8:$DB8),0) -> 0 | H8: =IF(SUM(wSUP!$C8:$DB8),$A8*wSUP!H8/SUM(wSUP!$C8:$DB8),0) -> 0 | I8: =IF(SUM(wSUP!$C8:$DB8),$A8*wSUP!I8/SUM(wSUP!$C8:$DB8),0) -> 0 | J8: =IF(SUM(wSUP!$C8:$DB8),$A8*wSUP!J8/SUM(wSUP!$C8:$DB8),0) -> 0 | ... DB8: =IF(SUM(wSUP!$C8:$DB8),$A8*wSUP!DB8/SUM(wSUP!$C8:$DB8),0) -> 0
A9: 98.112675 | B9: amaiz | C9: =IF(SUM(wSUP!$C9:$DB9),$A9*wSUP!C9/SUM(wSUP!$C9:$DB9),0) -> 0 | D9: =IF(SUM(wSUP!$C9:$DB9),$A9*wSUP!D9/SUM(wSUP!$C9:$DB9),0) -> 98.112675 | E9: =IF(SUM(wSUP!$C9:$DB9),$A9*wSUP!E9/SUM(wSUP!$C9:$DB9),0) -> 0 | F9: =IF(SUM(wSUP!$C9:$DB9),$A9*wSUP!F9/SUM(wSUP!$C9:$DB9),0) -> 0 | G9: =IF(SUM(wSUP!$C9:$DB9),$A9*wSUP!G9/SUM(wSUP!$C9:$DB9),0) -> 0 | H9: =IF(SUM(wSUP!$C9:$DB9),$A9*wSUP!H9/SUM(wSUP!$C9:$DB9),0) -> 0 | I9: =IF(SUM(wSUP!$C9:$DB9),$A9*wSUP!I9/SUM(wSUP!$C9:$DB9),0) -> 0 | J9: =IF(SUM(wSUP!$C9:$DB9),$A9*wSUP!J9/SUM(wSUP!$C9:$DB9),0) -> 0 | ... DB9: =IF(SUM(wSUP!$C9:$DB9),$A9*wSUP!DB9/SUM(wSUP!$C9:$DB9),0) -> 0
A10: 3.2540333 | B10: awhea | C10: =IF(SUM(wSUP!$C10:$DB10),$A10*wSUP!C10/SUM(wSUP!$C10:$DB10),0) -> 0 | D10: =IF(SUM(wSUP!$C10:$DB10),$A10*wSUP!D10/SUM(wSUP!$C10:$DB10),0) -> 0 | E10: =IF(SUM(wSUP!$C10:$DB10),$A10*wSUP!E10/SUM(wSUP!$C10:$DB10),0) -> 3.2540333 | F10: =IF(SUM(wSUP!$C10:$DB10),$A10*wSUP!F10/SUM(wSUP!$C10:$DB10),0) -> 0 | G10: =IF(SUM(wSUP!$C10:$DB10),$A10*wSUP!G10/SUM(wSUP!$C10:$DB10),0) -> 0 | H10: =IF(SUM(wSUP!$C10:$DB10),$A10*wSUP!H10/SUM(wSUP!$C10:$DB10),0) -> 0 | I10: =IF(SUM(wSUP!$C10:$DB10),$A10*wSUP!I10/SUM(wSUP!$C10:$DB10),0) -> 0 | J10: =IF(SUM(wSUP!$C10:$DB10),$A10*wSUP!J10/SUM(wSUP!$C10:$DB10),0) -> 0 | ... DB10: =IF(SUM(wSUP!$C10:$DB10),$A10*wSUP!DB10/SUM(wSUP!$C10:$DB10),0) -> 0
A11: 59.900399 | B11: arice | C11: =IF(SUM(wSUP!$C11:$DB11),$A11*wSUP!C11/SUM(wSUP!$C11:$DB11),0) -> 0 | D11: =IF(SUM(wSUP!$C11:$DB11),$A11*wSUP!D11/SUM(wSUP!$C11:$DB11),0) -> 0 | E11: =IF(SUM(wSUP!$C11:$DB11),$A11*wSUP!E11/SUM(wSUP!$C11:$DB11),0) -> 0 | F11: =IF(SUM(wSUP!$C11:$DB11),$A11*wSUP!F11/SUM(wSUP!$C11:$DB11),0) -> 59.900399 | G11: =IF(SUM(wSUP!$C11:$DB11),$A11*wSUP!G11/SUM(wSUP!$C11:$DB11),0) -> 0 | H11: =IF(SUM(wSUP!$C11:$DB11),$A11*wSUP!H11/SUM(wSUP!$C11:$DB11),0) -> 0 | I11: =IF(SUM(wSUP!$C11:$DB11),$A11*wSUP!I11/SUM(wSUP!$C11:$DB11),0) -> 0 | J11: =IF(SUM(wSUP!$C11:$DB11),$A11*wSUP!J11/SUM(wSUP!$C11:$DB11),0) -> 0 | ... DB11: =IF(SUM(wSUP!$C11:$DB11),$A11*wSUP!DB11/SUM(wSUP!$C11:$DB11),0) -> 0
A12: 0.29091626 | B12: aocer | C12: =IF(SUM(wSUP!$C12:$DB12),$A12*wSUP!C12/SUM(wSUP!$C12:$DB12),0) -> 0 | D12: =IF(SUM(wSUP!$C12:$DB12),$A12*wSUP!D12/SUM(wSUP!$C12:$DB12),0) -> 0 | E12: =IF(SUM(wSUP!$C12:$DB12),$A12*wSUP!E12/SUM(wSUP!$C12:$DB12),0) -> 0 | F12: =IF(SUM(wSUP!$C12:$DB12),$A12*wSUP!F12/SUM(wSUP!$C12:$DB12),0) -> 0 | G12: =IF(SUM(wSUP!$C12:$DB12),$A12*wSUP!G12/SUM(wSUP!$C12:$DB12),0) -> 0.29091626 | H12: =IF(SUM(wSUP!$C12:$DB12),$A12*wSUP!H12/SUM(wSUP!$C12:$DB12),0) -> 0 | I12: =IF(SUM(wSUP!$C12:$DB12),$A12*wSUP!I12/SUM(wSUP!$C12:$DB12),0) -> 0 | J12: =IF(SUM(wSUP!$C12:$DB12),$A12*wSUP!J12/SUM(wSUP!$C12:$DB12),0) -> 0 | ... DB12: =IF(SUM(wSUP!$C12:$DB12),$A12*wSUP!DB12/SUM(wSUP!$C12:$DB12),0) -> 0
A13: 170.10332 | B13: aipot | C13: =IF(SUM(wSUP!$C13:$DB13),$A13*wSUP!C13/SUM(wSUP!$C13:$DB13),0) -> 0 | D13: =IF(SUM(wSUP!$C13:$DB13),$A13*wSUP!D13/SUM(wSUP!$C13:$DB13),0) -> 0 | E13: =IF(SUM(wSUP!$C13:$DB13),$A13*wSUP!E13/SUM(wSUP!$C13:$DB13),0) -> 0 | F13: =IF(SUM(wSUP!$C13:$DB13),$A13*wSUP!F13/SUM(wSUP!$C13:$DB13),0) -> 0 | G13: =IF(SUM(wSUP!$C13:$DB13),$A13*wSUP!G13/SUM(wSUP!$C13:$DB13),0) -> 0 | H13: =IF(SUM(wSUP!$C13:$DB13),$A13*wSUP!H13/SUM(wSUP!$C13:$DB13),0) -> 170.10332 | I13: =IF(SUM(wSUP!$C13:$DB13),$A13*wSUP!I13/SUM(wSUP!$C13:$DB13),0) -> 0 | J13: =IF(SUM(wSUP!$C13:$DB13),$A13*wSUP!J13/SUM(wSUP!$C13:$DB13),0) -> 0 | ... DB13: =IF(SUM(wSUP!$C13:$DB13),$A13*wSUP!DB13/SUM(wSUP!$C13:$DB13),0) -> 0
A14: 151.42836 | B14: aspot | C14: =IF(SUM(wSUP!$C14:$DB14),$A14*wSUP!C14/SUM(wSUP!$C14:$DB14),0) -> 0 | D14: =IF(SUM(wSUP!$C14:$DB14),$A14*wSUP!D14/SUM(wSUP!$C14:$DB14),0) -> 0 | E14: =IF(SUM(wSUP!$C14:$DB14),$A14*wSUP!E14/SUM(wSUP!$C14:$DB14),0) -> 0 | F14: =IF(SUM(wSUP!$C14:$DB14),$A14*wSUP!F14/SUM(wSUP!$C14:$DB14),0) -> 0 | G14: =IF(SUM(wSUP!$C14:$DB14),$A14*wSUP!G14/SUM(wSUP!$C14:$DB14),0) -> 0 | H14: =IF(SUM(wSUP!$C14:$DB14),$A14*wSUP!H14/SUM(wSUP!$C14:$DB14),0) -> 0 | I14: =IF(SUM(wSUP!$C14:$DB14),$A14*wSUP!I14/SUM(wSUP!$C14:$DB14),0) -> 151.42836 | J14: =IF(SUM(wSUP!$C14:$DB14),$A14*wSUP!J14/SUM(wSUP!$C14:$DB14),0) -> 0 | ... DB14: =IF(SUM(wSUP!$C14:$DB14),$A14*wSUP!DB14/SUM(wSUP!$C14:$DB14),0) -> 0
A15: 125.44618 | B15: acass | C15: =IF(SUM(wSUP!$C15:$DB15),$A15*wSUP!C15/SUM(wSUP!$C15:$DB15),0) -> 0 | D15: =IF(SUM(wSUP!$C15:$DB15),$A15*wSUP!D15/SUM(wSUP!$C15:$DB15),0) -> 0 | E15: =IF(SUM(wSUP!$C15:$DB15),$A15*wSUP!E15/SUM(wSUP!$C15:$DB15),0) -> 0 | F15: =IF(SUM(wSUP!$C15:$DB15),$A15*wSUP!F15/SUM(wSUP!$C15:$DB15),0) -> 0 | G15: =IF(SUM(wSUP!$C15:$DB15),$A15*wSUP!G15/SUM(wSUP!$C15:$DB15),0) -> 0 | H15: =IF(SUM(wSUP!$C15:$DB15),$A15*wSUP!H15/SUM(wSUP!$C15:$DB15),0) -> 0 | I15: =IF(SUM(wSUP!$C15:$DB15),$A15*wSUP!I15/SUM(wSUP!$C15:$DB15),0) -> 0 | J15: =IF(SUM(wSUP!$C15:$DB15),$A15*wSUP!J15/SUM(wSUP!$C15:$DB15),0) -> 125.44618 | ... DB15: =IF(SUM(wSUP!$C15:$DB15),$A15*wSUP!DB15/SUM(wSUP!$C15:$DB15),0) -> 0
A16: 21.322825 | B16: aroot | C16: =IF(SUM(wSUP!$C16:$DB16),$A16*wSUP!C16/SUM(wSUP!$C16:$DB16),0) -> 0 | D16: =IF(SUM(wSUP!$C16:$DB16),$A16*wSUP!D16/SUM(wSUP!$C16:$DB16),0) -> 0 | E16: =IF(SUM(wSUP!$C16:$DB16),$A16*wSUP!E16/SUM(wSUP!$C16:$DB16),0) -> 0 | F16: =IF(SUM(wSUP!$C16:$DB16),$A16*wSUP!F16/SUM(wSUP!$C16:$DB16),0) -> 0 | G16: =IF(SUM(wSUP!$C16:$DB16),$A16*wSUP!G16/SUM(wSUP!$C16:$DB16),0) -> 0 | H16: =IF(SUM(wSUP!$C16:$DB16),$A16*wSUP!H16/SUM(wSUP!$C16:$DB16),0) -> 0 | I16: =IF(SUM(wSUP!$C16:$DB16),$A16*wSUP!I16/SUM(wSUP!$C16:$DB16),0) -> 0 | J16: =IF(SUM(wSUP!$C16:$DB16),$A16*wSUP!J16/SUM(wSUP!$C16:$DB16),0) -> 0 | ... DB16: =IF(SUM(wSUP!$C16:$DB16),$A16*wSUP!DB16/SUM(wSUP!$C16:$DB16),0) -> 0
A17: 225.71312 | B17: abean | C17: =IF(SUM(wSUP!$C17:$DB17),$A17*wSUP!C17/SUM(wSUP!$C17:$DB17),0) -> 0 | D17: =IF(SUM(wSUP!$C17:$DB17),$A17*wSUP!D17/SUM(wSUP!$C17:$DB17),0) -> 0 | E17: =IF(SUM(wSUP!$C17:$DB17),$A17*wSUP!E17/SUM(wSUP!$C17:$DB17),0) -> 0 | F17: =IF(SUM(wSUP!$C17:$DB17),$A17*wSUP!F17/SUM(wSUP!$C17:$DB17),0) -> 0 | G17: =IF(SUM(wSUP!$C17:$DB17),$A17*wSUP!G17/SUM(wSUP!$C17:$DB17),0) -> 0 | H17: =IF(SUM(wSUP!$C17:$DB17),$A17*wSUP!H17/SUM(wSUP!$C17:$DB17),0) -> 0 | I17: =IF(SUM(wSUP!$C17:$DB17),$A17*wSUP!I17/SUM(wSUP!$C17:$DB17),0) -> 0 | J17: =IF(SUM(wSUP!$C17:$DB17),$A17*wSUP!J17/SUM(wSUP!$C17:$DB17),0) -> 0 | ... DB17: =IF(SUM(wSUP!$C17:$DB17),$A17*wSUP!DB17/SUM(wSUP!$C17:$DB17),0) -> 0
A18: 22.070413 | B18: apeas | C18: =IF(SUM(wSUP!$C18:$DB18),$A18*wSUP!C18/SUM(wSUP!$C18:$DB18),0) -> 0 | D18: =IF(SUM(wSUP!$C18:$DB18),$A18*wSUP!D18/SUM(wSUP!$C18:$DB18),0) -> 0 | E18: =IF(SUM(wSUP!$C18:$DB18),$A18*wSUP!E18/SUM(wSUP!$C18:$DB18),0) -> 0 | F18: =IF(SUM(wSUP!$C18:$DB18),$A18*wSUP!F18/SUM(wSUP!$C18:$DB18),0) -> 0 | G18: =IF(SUM(wSUP!$C18:$DB18),$A18*wSUP!G18/SUM(wSUP!$C18:$DB18),0) -> 0 | H18: =IF(SUM(wSUP!$C18:$DB18),$A18*wSUP!H18/SUM(wSUP!$C18:$DB18),0) -> 0 | I18: =IF(SUM(wSUP!$C18:$DB18),$A18*wSUP!I18/SUM(wSUP!$C18:$DB18),0) -> 0 | J18: =IF(SUM(wSUP!$C18:$DB18),$A18*wSUP!J18/SUM(wSUP!$C18:$DB18),0) -> 0 | ... DB18: =IF(SUM(wSUP!$C18:$DB18),$A18*wSUP!DB18/SUM(wSUP!$C18:$DB18),0) -> 0
A19: 149.13716 | B19: avege | C19: =IF(SUM(wSUP!$C19:$DB19),$A19*wSUP!C19/SUM(wSUP!$C19:$DB19),0) -> 0 | D19: =IF(SUM(wSUP!$C19:$DB19),$A19*wSUP!D19/SUM(wSUP!$C19:$DB19),0) -> 0 | E19: =IF(SUM(wSUP!$C19:$DB19),$A19*wSUP!E19/SUM(wSUP!$C19:$DB19),0) -> 0 | F19: =IF(SUM(wSUP!$C19:$DB19),$A19*wSUP!F19/SUM(wSUP!$C19:$DB19),0) -> 0 | G19: =IF(SUM(wSUP!$C19:$DB19),$A19*wSUP!G19/SUM(wSUP!$C19:$DB19),0) -> 0 | H19: =IF(SUM(wSUP!$C19:$DB19),$A19*wSUP!H19/SUM(wSUP!$C19:$DB19),0) -> 0 | I19: =IF(SUM(wSUP!$C19:$DB19),$A19*wSUP!I19/SUM(wSUP!$C19:$DB19),0) -> 0 | J19: =IF(SUM(wSUP!$C19:$DB19),$A19*wSUP!J19/SUM(wSUP!$C19:$DB19),0) -> 0 | ... DB19: =IF(SUM(wSUP!$C19:$DB19),$A19*wSUP!DB19/SUM(wSUP!$C19:$DB19),0) -> 0
A20: 81.996625 | B20: abanb | C20: =IF(SUM(wSUP!$C20:$DB20),$A20*wSUP!C20/SUM(wSUP!$C20:$DB20),0) -> 0 | D20: =IF(SUM(wSUP!$C20:$DB20),$A20*wSUP!D20/SUM(wSUP!$C20:$DB20),0) -> 0 | E20: =IF(SUM(wSUP!$C20:$DB20),$A20*wSUP!E20/SUM(wSUP!$C20:$DB20),0) -> 0 | F20: =IF(SUM(wSUP!$C20:$DB20),$A20*wSUP!F20/SUM(wSUP!$C20:$DB20),0) -> 0 | G20: =IF(SUM(wSUP!$C20:$DB20),$A20*wSUP!G20/SUM(wSUP!$C20:$DB20),0) -> 0 | H20: =IF(SUM(wSUP!$C20:$DB20),$A20*wSUP!H20/SUM(wSUP!$C20:$DB20),0) -> 0 | I20: =IF(SUM(wSUP!$C20:$DB20),$A20*wSUP!I20/SUM(wSUP!$C20:$DB20),0) -> 0 | J20: =IF(SUM(wSUP!$C20:$DB20),$A20*wSUP!J20/SUM(wSUP!$C20:$DB20),0) -> 0 | ... DB20: =IF(SUM(wSUP!$C20:$DB20),$A20*wSUP!DB20/SUM(wSUP!$C20:$DB20),0) -> 0
