Workbook

Sheet Index
A1: GDX index
A4: Type | B4: Name | C4: Location | D4: Row | E4: Column
D5: rdim | E5: cdim
A6: par | B6: inctab | C6: data!aa5 | D6: 1 | E6: 1
A7: par | B7: exptab | C7: data!aa40 | D7: 1 | E7: 1
A8: par | B8: hhddata | C8: data!aa75 | D8: 1 | E8: 1

Sheet Data
A3: Household income table
A4: INCTAB
B5: flab-rn | C5: flab-rp | D5: flab-rs | E5: flab-rt | F5: flab-un | G5: flab-up | H5: flab-us | I5: flab-ut | J5: flab-kn | K5: flab-kp | L5: flab-ks | M5: flab-kt | N5: flnd | O5: fcap-c | P5: fcap-l | Q5: ent | R5: gov | S5: row | T5: total | AB5: flab-rn | AC5: flab-rp | AD5: flab-rs | AE5: flab-rt | AF5: flab-un | AG5: flab-up | AH5: flab-us | AI5: flab-ut | AJ5: flab-kn | AK5: flab-kp | AL5: flab-ks | AM5: flab-kt | AN5: flnd | AO5: fcap-c | AP5: fcap-l | AQ5: ent | AR5: gov | AS5: row | AT5: total
A6: hhd-f1 | B6: =IF(ISNA(INDEX($AB$6:$AT$25,MATCH($A6,$AA$6:$AA$25,0),MATCH(B$5,$AB$5:$AT$5,0))),0,INDEX($AB$6:$AT$25,MATCH($A6,$AA$6:$AA$25,0),MATCH(B$5,$AB$5:$AT$5,0))) -> 119.06684 | C6: =IF(ISNA(INDEX($AB$6:$AT$25,MATCH($A6,$AA$6:$AA$25,0),MATCH(C$5,$AB$5:$AT$5,0))),0,INDEX($AB$6:$AT$25,MATCH($A6,$AA$6:$AA$25,0),MATCH(C$5,$AB$5:$AT$5,0))) -> 77.873941 | D6: =IF(ISNA(INDEX($AB$6:$AT$25,MATCH($A6,$AA$6:$AA$25,0),MATCH(D$5,$AB$5:$AT$5,0))),0,INDEX($AB$6:$AT$25,MATCH($A6,$AA$6:$AA$25,0),MATCH(D$5,$AB$5:$AT$5,0))) -> 2.9336712 | E6: =IF(ISNA(INDEX($AB$6:$AT$25,MATCH($A6,$AA$6:$AA$25,0),MATCH(E$5,$AB$5:$AT$5,0))),0,INDEX($AB$6:$AT$25,MATCH($A6,$AA$6:$AA$25,0),MATCH(E$5,$AB$5:$AT$5,0))) -> 0.15527475 | F6: =IF(ISNA(INDEX($AB$6:$AT$25,MATCH($A6,$AA$6:$AA$25,0),MATCH(F$5,$AB$5:$AT$5,0))),0,INDEX($AB$6:$AT$25,MATCH($A6,$AA$6:$AA$25,0),MATCH(F$5,$AB$5:$AT$5,0))) -> 0 | G6: =IF(ISNA(INDEX($AB$6:$AT$25,MATCH($A6,$AA$6:$AA$25,0),MATCH(G$5,$AB$5:$AT$5,0))),0,INDEX($AB$6:$AT$25,MATCH($A6,$AA$6:$AA$25,0),MATCH(G$5,$AB$5:$AT$5,0))) -> 0 | H6: =IF(ISNA(INDEX($AB$6:$AT$25,MATCH($A6,$AA$6:$AA$25,0),MATCH(H$5,$AB$5:$AT$5,0))),0,INDEX($AB$6:$AT$25,MATCH($A6,$AA$6:$AA$25,0),MATCH(H$5,$AB$5:$AT$5,0))) -> 0 | I6: =IF(ISNA(INDEX($AB$6:$AT$25,MATCH($A6,$AA$6:$AA$25,0),MATCH(I$5,$AB$5:$AT$5,0))),0,INDEX($AB$6:$AT$25,MATCH($A6,$AA$6:$AA$25,0),MATCH(I$5,$AB$5:$AT$5,0))) -> 0 | ... T6: =IF(ISNA(INDEX($AB$6:$AT$25,MATCH($A6,$AA$6:$AA$25,0),MATCH(T$5,$AB$5:$AT$5,0))),0,INDEX($AB$6:$AT$25,MATCH($A6,$AA$6:$AA$25,0),MATCH(T$5,$AB$5:$AT$5,0))) -> 352.66969 | AA6: hhd-f1 | AB6: 119.06684 | AC6: 77.873941 | AD6: 2.9336712 | AE6: 0.15527475 | AN6: 69.428867 | AO6: 35.231461 | AP6: 7.5632189 | AQ6: 18.126722 | AR6: 19.817945 | AS6: 2.4717513 | AT6: 352.66969
A7: hhd-f2 | B7: =IF(ISNA(INDEX($AB$6:$AT$25,MATCH($A7,$AA$6:$AA$25,0),MATCH(B$5,$AB$5:$AT$5,0))),0,INDEX($AB$6:$AT$25,MATCH($A7,$AA$6:$AA$25,0),MATCH(B$5,$AB$5:$AT$5,0))) -> 125.59889 | C7: =IF(ISNA(INDEX($AB$6:$AT$25,MATCH($A7,$AA$6:$AA$25,0),MATCH(C$5,$AB$5:$AT$5,0))),0,INDEX($AB$6:$AT$25,MATCH($A7,$AA$6:$AA$25,0),MATCH(C$5,$AB$5:$AT$5,0))) -> 114.39973 | D7: =IF(ISNA(INDEX($AB$6:$AT$25,MATCH($A7,$AA$6:$AA$25,0),MATCH(D$5,$AB$5:$AT$5,0))),0,INDEX($AB$6:$AT$25,MATCH($A7,$AA$6:$AA$25,0),MATCH(D$5,$AB$5:$AT$5,0))) -> 9.906001 | E7: =IF(ISNA(INDEX($AB$6:$AT$25,MATCH($A7,$AA$6:$AA$25,0),MATCH(E$5,$AB$5:$AT$5,0))),0,INDEX($AB$6:$AT$25,MATCH($A7,$AA$6:$AA$25,0),MATCH(E$5,$AB$5:$AT$5,0))) -> 1.3257162 | F7: =IF(ISNA(INDEX($AB$6:$AT$25,MATCH($A7,$AA$6:$AA$25,0),MATCH(F$5,$AB$5:$AT$5,0))),0,INDEX($AB$6:$AT$25,MATCH($A7,$AA$6:$AA$25,0),MATCH(F$5,$AB$5:$AT$5,0))) -> 0 | G7: =IF(ISNA(INDEX($AB$6:$AT$25,MATCH($A7,$AA$6:$AA$25,0),MATCH(G$5,$AB$5:$AT$5,0))),0,INDEX($AB$6:$AT$25,MATCH($A7,$AA$6:$AA$25,0),MATCH(G$5,$AB$5:$AT$5,0))) -> 0 | H7: =IF(ISNA(INDEX($AB$6:$AT$25,MATCH($A7,$AA$6:$AA$25,0),MATCH(H$5,$AB$5:$AT$5,0))),0,INDEX($AB$6:$AT$25,MATCH($A7,$AA$6:$AA$25,0),MATCH(H$5,$AB$5:$AT$5,0))) -> 0 | I7: =IF(ISNA(INDEX($AB$6:$AT$25,MATCH($A7,$AA$6:$AA$25,0),MATCH(I$5,$AB$5:$AT$5,0))),0,INDEX($AB$6:$AT$25,MATCH($A7,$AA$6:$AA$25,0),MATCH(I$5,$AB$5:$AT$5,0))) -> 0 | ... T7: =IF(ISNA(INDEX($AB$6:$AT$25,MATCH($A7,$AA$6:$AA$25,0),MATCH(T$5,$AB$5:$AT$5,0))),0,INDEX($AB$6:$AT$25,MATCH($A7,$AA$6:$AA$25,0),MATCH(T$5,$AB$5:$AT$5,0))) -> 461.72785 | AA7: hhd-f2 | AB7: 125.59889 | AC7: 114.39973 | AD7: 9.906001 | AE7: 1.3257162 | AN7: 86.579001 | AO7: 43.559058 | AP7: 10.278078 | AQ7: 45.728616 | AR7: 20.592045 | AS7: 3.7607142 | AT7: 461.72785
A8: hhd-f3 | B8: =IF(ISNA(INDEX($AB$6:$AT$25,MATCH($A8,$AA$6:$AA$25,0),MATCH(B$5,$AB$5:$AT$5,0))),0,INDEX($AB$6:$AT$25,MATCH($A8,$AA$6:$AA$25,0),MATCH(B$5,$AB$5:$AT$5,0))) -> 166.80105 | C8: =IF(ISNA(INDEX($AB$6:$AT$25,MATCH($A8,$AA$6:$AA$25,0),MATCH(C$5,$AB$5:$AT$5,0))),0,INDEX($AB$6:$AT$25,MATCH($A8,$AA$6:$AA$25,0),MATCH(C$5,$AB$5:$AT$5,0))) -> 165.00562 | D8: =IF(ISNA(INDEX($AB$6:$AT$25,MATCH($A8,$AA$6:$AA$25,0),MATCH(D$5,$AB$5:$AT$5,0))),0,INDEX($AB$6:$AT$25,MATCH($A8,$AA$6:$AA$25,0),MATCH(D$5,$AB$5:$AT$5,0))) -> 15.958498 | E8: =IF(ISNA(INDEX($AB$6:$AT$25,MATCH($A8,$AA$6:$AA$25,0),MATCH(E$5,$AB$5:$AT$5,0))),0,INDEX($AB$6:$AT$25,MATCH($A8,$AA$6:$AA$25,0),MATCH(E$5,$AB$5:$AT$5,0))) -> 1.1400639 | F8: =IF(ISNA(INDEX($AB$6:$AT$25,MATCH($A8,$AA$6:$AA$25,0),MATCH(F$5,$AB$5:$AT$5,0))),0,INDEX($AB$6:$AT$25,MATCH($A8,$AA$6:$AA$25,0),MATCH(F$5,$AB$5:$AT$5,0))) -> 0 | G8: =IF(ISNA(INDEX($AB$6:$AT$25,MATCH($A8,$AA$6:$AA$25,0),MATCH(G$5,$AB$5:$AT$5,0))),0,INDEX($AB$6:$AT$25,MATCH($A8,$AA$6:$AA$25,0),MATCH(G$5,$AB$5:$AT$5,0))) -> 0 | H8: =IF(ISNA(INDEX($AB$6:$AT$25,MATCH($A8,$AA$6:$AA$25,0),MATCH(H$5,$AB$5:$AT$5,0))),0,INDEX($AB$6:$AT$25,MATCH($A8,$AA$6:$AA$25,0),MATCH(H$5,$AB$5:$AT$5,0))) -> 0 | I8: =IF(ISNA(INDEX($AB$6:$AT$25,MATCH($A8,$AA$6:$AA$25,0),MATCH(I$5,$AB$5:$AT$5,0))),0,INDEX($AB$6:$AT$25,MATCH($A8,$AA$6:$AA$25,0),MATCH(I$5,$AB$5:$AT$5,0))) -> 0 | ... T8: =IF(ISNA(INDEX($AB$6:$AT$25,MATCH($A8,$AA$6:$AA$25,0),MATCH(T$5,$AB$5:$AT$5,0))),0,INDEX($AB$6:$AT$25,MATCH($A8,$AA$6:$AA$25,0),MATCH(T$5,$AB$5:$AT$5,0))) -> 623.34927 | AA8: hhd-f3 | AB8: 166.80105 | AC8: 165.00562 | AD8: 15.958498 | AE8: 1.1400639 | AN8: 125.61094 | AO8: 63.20047 | AP8: 14.259224 | AQ8: 41.062074 | AR8: 22.932416 | AS8: 7.378909 | AT8: 623.34927
A9: hhd-f4 | B9: =IF(ISNA(INDEX($AB$6:$AT$25,MATCH($A9,$AA$6:$AA$25,0),MATCH(B$5,$AB$5:$AT$5,0))),0,INDEX($AB$6:$AT$25,MATCH($A9,$AA$6:$AA$25,0),MATCH(B$5,$AB$5:$AT$5,0))) -> 169.88053 | C9: =IF(ISNA(INDEX($AB$6:$AT$25,MATCH($A9,$AA$6:$AA$25,0),MATCH(C$5,$AB$5:$AT$5,0))),0,INDEX($AB$6:$AT$25,MATCH($A9,$AA$6:$AA$25,0),MATCH(C$5,$AB$5:$AT$5,0))) -> 193.78904 | D9: =IF(ISNA(INDEX($AB$6:$AT$25,MATCH($A9,$AA$6:$AA$25,0),MATCH(D$5,$AB$5:$AT$5,0))),0,INDEX($AB$6:$AT$25,MATCH($A9,$AA$6:$AA$25,0),MATCH(D$5,$AB$5:$AT$5,0))) -> 32.491154 | E9: =IF(ISNA(INDEX($AB$6:$AT$25,MATCH($A9,$AA$6:$AA$25,0),MATCH(E$5,$AB$5:$AT$5,0))),0,INDEX($AB$6:$AT$25,MATCH($A9,$AA$6:$AA$25,0),MATCH(E$5,$AB$5:$AT$5,0))) -> 28.969573 | F9: =IF(ISNA(INDEX($AB$6:$AT$25,MATCH($A9,$AA$6:$AA$25,0),MATCH(F$5,$AB$5:$AT$5,0))),0,INDEX($AB$6:$AT$25,MATCH($A9,$AA$6:$AA$25,0),MATCH(F$5,$AB$5:$AT$5,0))) -> 0 | G9: =IF(ISNA(INDEX($AB$6:$AT$25,MATCH($A9,$AA$6:$AA$25,0),MATCH(G$5,$AB$5:$AT$5,0))),0,INDEX($AB$6:$AT$25,MATCH($A9,$AA$6:$AA$25,0),MATCH(G$5,$AB$5:$AT$5,0))) -> 0 | H9: =IF(ISNA(INDEX($AB$6:$AT$25,MATCH($A9,$AA$6:$AA$25,0),MATCH(H$5,$AB$5:$AT$5,0))),0,INDEX($AB$6:$AT$25,MATCH($A9,$AA$6:$AA$25,0),MATCH(H$5,$AB$5:$AT$5,0))) -> 0 | I9: =IF(ISNA(INDEX($AB$6:$AT$25,MATCH($A9,$AA$6:$AA$25,0),MATCH(I$5,$AB$5:$AT$5,0))),0,INDEX($AB$6:$AT$25,MATCH($A9,$AA$6:$AA$25,0),MATCH(I$5,$AB$5:$AT$5,0))) -> 0 | ... T9: =IF(ISNA(INDEX($AB$6:$AT$25,MATCH($A9,$AA$6:$AA$25,0),MATCH(T$5,$AB$5:$AT$5,0))),0,INDEX($AB$6:$AT$25,MATCH($A9,$AA$6:$AA$25,0),MATCH(T$5,$AB$5:$AT$5,0))) -> 875.63923 | AA9: hhd-f4 | AB9: 169.88053 | AC9: 193.78904 | AD9: 32.491154 | AE9: 28.969573 | AN9: 132.86358 | AO9: 66.290637 | AP9: 18.219064 | AQ9: 187.66527 | AR9: 34.082846 | AS9: 11.387532 | AT9: 875.63923
A10: hhd-f5 | B10: =IF(ISNA(INDEX($AB$6:$AT$25,MATCH($A10,$AA$6:$AA$25,0),MATCH(B$5,$AB$5:$AT$5,0))),0,INDEX($AB$6:$AT$25,MATCH($A10,$AA$6:$AA$25,0),MATCH(B$5,$AB$5:$AT$5,0))) -> 94.420166 | C10: =IF(ISNA(INDEX($AB$6:$AT$25,MATCH($A10,$AA$6:$AA$25,0),MATCH(C$5,$AB$5:$AT$5,0))),0,INDEX($AB$6:$AT$25,MATCH($A10,$AA$6:$AA$25,0),MATCH(C$5,$AB$5:$AT$5,0))) -> 170.12491 | D10: =IF(ISNA(INDEX($AB$6:$AT$25,MATCH($A10,$AA$6:$AA$25,0),MATCH(D$5,$AB$5:$AT$5,0))),0,INDEX($AB$6:$AT$25,MATCH($A10,$AA$6:$AA$25,0),MATCH(D$5,$AB$5:$AT$5,0))) -> 70.584018 | E10: =IF(ISNA(INDEX($AB$6:$AT$25,MATCH($A10,$AA$6:$AA$25,0),MATCH(E$5,$AB$5:$AT$5,0))),0,INDEX($AB$6:$AT$25,MATCH($A10,$AA$6:$AA$25,0),MATCH(E$5,$AB$5:$AT$5,0))) -> 114.56714 | F10: =IF(ISNA(INDEX($AB$6:$AT$25,MATCH($A10,$AA$6:$AA$25,0),MATCH(F$5,$AB$5:$AT$5,0))),0,INDEX($AB$6:$AT$25,MATCH($A10,$AA$6:$AA$25,0),MATCH(F$5,$AB$5:$AT$5,0))) -> 0 | G10: =IF(ISNA(INDEX($AB$6:$AT$25,MATCH($A10,$AA$6:$AA$25,0),MATCH(G$5,$AB$5:$AT$5,0))),0,INDEX($AB$6:$AT$25,MATCH($A10,$AA$6:$AA$25,0),MATCH(G$5,$AB$5:$AT$5,0))) -> 0 | H10: =IF(ISNA(INDEX($AB$6:$AT$25,MATCH($A10,$AA$6:$AA$25,0),MATCH(H$5,$AB$5:$AT$5,0))),0,INDEX($AB$6:$AT$25,MATCH($A10,$AA$6:$AA$25,0),MATCH(H$5,$AB$5:$AT$5,0))) -> 0 | I10: =IF(ISNA(INDEX($AB$6:$AT$25,MATCH($A10,$AA$6:$AA$25,0),MATCH(I$5,$AB$5:$AT$5,0))),0,INDEX($AB$6:$AT$25,MATCH($A10,$AA$6:$AA$25,0),MATCH(I$5,$AB$5:$AT$5,0))) -> 0 | ... T10: =IF(ISNA(INDEX($AB$6:$AT$25,MATCH($A10,$AA$6:$AA$25,0),MATCH(T$5,$AB$5:$AT$5,0))),0,INDEX($AB$6:$AT$25,MATCH($A10,$AA$6:$AA$25,0),MATCH(T$5,$AB$5:$AT$5,0))) -> 942.36613 | AA10: hhd-f5 | AB10: 94.420166 | AC10: 170.12491 | AD10: 70.584018 | AE10: 114.56714 | AN10: 89.25147 | AO10: 44.554274 | AP10: 13.931625 | AQ10: 284.60777 | AR10: 29.968274 | AS10: 30.356467 | AT10: 942.36613
A11: hhd-n1 | B11: =IF(ISNA(INDEX($AB$6:$AT$25,MATCH($A11,$AA$6:$AA$25,0),MATCH(B$5,$AB$5:$AT$5,0))),0,INDEX($AB$6:$AT$25,MATCH($A11,$AA$6:$AA$25,0),MATCH(B$5,$AB$5:$AT$5,0))) -> 0.54979765 | C11: =IF(ISNA(INDEX($AB$6:$AT$25,MATCH($A11,$AA$6:$AA$25,0),MATCH(C$5,$AB$5:$AT$5,0))),0,INDEX($AB$6:$AT$25,MATCH($A11,$AA$6:$AA$25,0),MATCH(C$5,$AB$5:$AT$5,0))) -> 0.21888958 | D11: =IF(ISNA(INDEX($AB$6:$AT$25,MATCH($A11,$AA$6:$AA$25,0),MATCH(D$5,$AB$5:$AT$5,0))),0,INDEX($AB$6:$AT$25,MATCH($A11,$AA$6:$AA$25,0),MATCH(D$5,$AB$5:$AT$5,0))) -> 0 | E11: =IF(ISNA(INDEX($AB$6:$AT$25,MATCH($A11,$AA$6:$AA$25,0),MATCH(E$5,$AB$5:$AT$5,0))),0,INDEX($AB$6:$AT$25,MATCH($A11,$AA$6:$AA$25,0),MATCH(E$5,$AB$5:$AT$5,0))) -> 0 | F11: =IF(ISNA(INDEX($AB$6:$AT$25,MATCH($A11,$AA$6:$AA$25,0),MATCH(F$5,$AB$5:$AT$5,0))),0,INDEX($AB$6:$AT$25,MATCH($A11,$AA$6:$AA$25,0),MATCH(F$5,$AB$5:$AT$5,0))) -> 0 | G11: =IF(ISNA(INDEX($AB$6:$AT$25,MATCH($A11,$AA$6:$AA$25,0),MATCH(G$5,$AB$5:$AT$5,0))),0,INDEX($AB$6:$AT$25,MATCH($A11,$AA$6:$AA$25,0),MATCH(G$5,$AB$5:$AT$5,0))) -> 0 | H11: =IF(ISNA(INDEX($AB$6:$AT$25,MATCH($A11,$AA$6:$AA$25,0),MATCH(H$5,$AB$5:$AT$5,0))),0,INDEX($AB$6:$AT$25,MATCH($A11,$AA$6:$AA$25,0),MATCH(H$5,$AB$5:$AT$5,0))) -> 0 | I11: =IF(ISNA(INDEX($AB$6:$AT$25,MATCH($A11,$AA$6:$AA$25,0),MATCH(I$5,$AB$5:$AT$5,0))),0,INDEX($AB$6:$AT$25,MATCH($A11,$AA$6:$AA$25,0),MATCH(I$5,$AB$5:$AT$5,0))) -> 0 | ... T11: =IF(ISNA(INDEX($AB$6:$AT$25,MATCH($A11,$AA$6:$AA$25,0),MATCH(T$5,$AB$5:$AT$5,0))),0,INDEX($AB$6:$AT$25,MATCH($A11,$AA$6:$AA$25,0),MATCH(T$5,$AB$5:$AT$5,0))) -> 0.83859937 | AA11: hhd-n1 | AB11: 0.54979765 | AC11: 0.21888958 | AR11: 0.068936101 | AS11: 0.0009760339 | AT11: 0.83859937
A12: hhd-n2 | B12: =IF(ISNA(INDEX($AB$6:$AT$25,MATCH($A12,$AA$6:$AA$25,0),MATCH(B$5,$AB$5:$AT$5,0))),0,INDEX($AB$6:$AT$25,MATCH($A12,$AA$6:$AA$25,0),MATCH(B$5,$AB$5:$AT$5,0))) -> 0.45314945 | C12: =IF(ISNA(INDEX($AB$6:$AT$25,MATCH($A12,$AA$6:$AA$25,0),MATCH(C$5,$AB$5:$AT$5,0))),0,INDEX($AB$6:$AT$25,MATCH($A12,$AA$6:$AA$25,0),MATCH(C$5,$AB$5:$AT$5,0))) -> 0.59426507 | D12: =IF(ISNA(INDEX($AB$6:$AT$25,MATCH($A12,$AA$6:$AA$25,0),MATCH(D$5,$AB$5:$AT$5,0))),0,INDEX($AB$6:$AT$25,MATCH($A12,$AA$6:$AA$25,0),MATCH(D$5,$AB$5:$AT$5,0))) -> 0.062743988 | E12: =IF(ISNA(INDEX($AB$6:$AT$25,MATCH($A12,$AA$6:$AA$25,0),MATCH(E$5,$AB$5:$AT$5,0))),0,INDEX($AB$6:$AT$25,MATCH($A12,$AA$6:$AA$25,0),MATCH(E$5,$AB$5:$AT$5,0))) -> 0 | F12: =IF(ISNA(INDEX($AB$6:$AT$25,MATCH($A12,$AA$6:$AA$25,0),MATCH(F$5,$AB$5:$AT$5,0))),0,INDEX($AB$6:$AT$25,MATCH($A12,$AA$6:$AA$25,0),MATCH(F$5,$AB$5:$AT$5,0))) -> 0 | G12: =IF(ISNA(INDEX($AB$6:$AT$25,MATCH($A12,$AA$6:$AA$25,0),MATCH(G$5,$AB$5:$AT$5,0))),0,INDEX($AB$6:$AT$25,MATCH($A12,$AA$6:$AA$25,0),MATCH(G$5,$AB$5:$AT$5,0))) -> 0 | H12: =IF(ISNA(INDEX($AB$6:$AT$25,MATCH($A12,$AA$6:$AA$25,0),MATCH(H$5,$AB$5:$AT$5,0))),0,INDEX($AB$6:$AT$25,MATCH($A12,$AA$6:$AA$25,0),MATCH(H$5,$AB$5:$AT$5,0))) -> 0 | I12: =IF(ISNA(INDEX($AB$6:$AT$25,MATCH($A12,$AA$6:$AA$25,0),MATCH(I$5,$AB$5:$AT$5,0))),0,INDEX($AB$6:$AT$25,MATCH($A12,$AA$6:$AA$25,0),MATCH(I$5,$AB$5:$AT$5,0))) -> 0 | ... T12: =IF(ISNA(INDEX($AB$6:$AT$25,MATCH($A12,$AA$6:$AA$25,0),MATCH(T$5,$AB$5:$AT$5,0))),0,INDEX($AB$6:$AT$25,MATCH($A12,$AA$6:$AA$25,0),MATCH(T$5,$AB$5:$AT$5,0))) -> 1.2045185 | AA12: hhd-n2 | AB12: 0.45314945 | AC12: 0.59426507 | AD12: 0.062743988 | AR12: 0.094359973 | AT12: 1.2045185
A13: hhd-n3 | B13: =IF(ISNA(INDEX($AB$6:$AT$25,MATCH($A13,$AA$6:$AA$25,0),MATCH(B$5,$AB$5:$AT$5,0))),0,INDEX($AB$6:$AT$25,MATCH($A13,$AA$6:$AA$25,0),MATCH(B$5,$AB$5:$AT$5,0))) -> 1.7759154 | C13: =IF(ISNA(INDEX($AB$6:$AT$25,MATCH($A13,$AA$6:$AA$25,0),MATCH(C$5,$AB$5:$AT$5,0))),0,INDEX($AB$6:$AT$25,MATCH($A13,$AA$6:$AA$25,0),MATCH(C$5,$AB$5:$AT$5,0))) -> 1.8270413 | D13: =IF(ISNA(INDEX($AB$6:$AT$25,MATCH($A13,$AA$6:$AA$25,0),MATCH(D$5,$AB$5:$AT$5,0))),0,INDEX($AB$6:$AT$25,MATCH($A13,$AA$6:$AA$25,0),MATCH(D$5,$AB$5:$AT$5,0))) -> 0.47742916 | E13: =IF(ISNA(INDEX($AB$6:$AT$25,MATCH($A13,$AA$6:$AA$25,0),MATCH(E$5,$AB$5:$AT$5,0))),0,INDEX($AB$6:$AT$25,MATCH($A13,$AA$6:$AA$25,0),MATCH(E$5,$AB$5:$AT$5,0))) -> 0 | F13: =IF(ISNA(INDEX($AB$6:$AT$25,MATCH($A13,$AA$6:$AA$25,0),MATCH(F$5,$AB$5:$AT$5,0))),0,INDEX($AB$6:$AT$25,MATCH($A13,$AA$6:$AA$25,0),MATCH(F$5,$AB$5:$AT$5,0))) -> 0 | G13: =IF(ISNA(INDEX($AB$6:$AT$25,MATCH($A13,$AA$6:$AA$25,0),MATCH(G$5,$AB$5:$AT$5,0))),0,INDEX($AB$6:$AT$25,MATCH($A13,$AA$6:$AA$25,0),MATCH(G$5,$AB$5:$AT$5,0))) -> 0 | H13: =IF(ISNA(INDEX($AB$6:$AT$25,MATCH($A13,$AA$6:$AA$25,0),MATCH(H$5,$AB$5:$AT$5,0))),0,INDEX($AB$6:$AT$25,MATCH($A13,$AA$6:$AA$25,0),MATCH(H$5,$AB$5:$AT$5,0))) -> 0 | I13: =IF(ISNA(INDEX($AB$6:$AT$25,MATCH($A13,$AA$6:$AA$25,0),MATCH(I$5,$AB$5:$AT$5,0))),0,INDEX($AB$6:$AT$25,MATCH($A13,$AA$6:$AA$25,0),MATCH(I$5,$AB$5:$AT$5,0))) -> 0 | ... T13: =IF(ISNA(INDEX($AB$6:$AT$25,MATCH($A13,$AA$6:$AA$25,0),MATCH(T$5,$AB$5:$AT$5,0))),0,INDEX($AB$6:$AT$25,MATCH($A13,$AA$6:$AA$25,0),MATCH(T$5,$AB$5:$AT$5,0))) -> 4.4118705 | AA13: hhd-n3 | AB13: 1.7759154 | AC13: 1.8270413 | AD13: 0.47742916 | AQ13: 0.18019994 | AR13: 0.12189143 | AS13: 0.029393212 | AT13: 4.4118705
A14: hhd-n4 | B14: =IF(ISNA(INDEX($AB$6:$AT$25,MATCH($A14,$AA$6:$AA$25,0),MATCH(B$5,$AB$5:$AT$5,0))),0,INDEX($AB$6:$AT$25,MATCH($A14,$AA$6:$AA$25,0),MATCH(B$5,$AB$5:$AT$5,0))) -> 4.5812878 | C14: =IF(ISNA(INDEX($AB$6:$AT$25,MATCH($A14,$AA$6:$AA$25,0),MATCH(C$5,$AB$5:$AT$5,0))),0,INDEX($AB$6:$AT$25,MATCH($A14,$AA$6:$AA$25,0),MATCH(C$5,$AB$5:$AT$5,0))) -> 5.0570386 | D14: =IF(ISNA(INDEX($AB$6:$AT$25,MATCH($A14,$AA$6:$AA$25,0),MATCH(D$5,$AB$5:$AT$5,0))),0,INDEX($AB$6:$AT$25,MATCH($A14,$AA$6:$AA$25,0),MATCH(D$5,$AB$5:$AT$5,0))) -> 1.7466958 | E14: =IF(ISNA(INDEX($AB$6:$AT$25,MATCH($A14,$AA$6:$AA$25,0),MATCH(E$5,$AB$5:$AT$5,0))),0,INDEX($AB$6:$AT$25,MATCH($A14,$AA$6:$AA$25,0),MATCH(E$5,$AB$5:$AT$5,0))) -> 1.5129254 | F14: =IF(ISNA(INDEX($AB$6:$AT$25,MATCH($A14,$AA$6:$AA$25,0),MATCH(F$5,$AB$5:$AT$5,0))),0,INDEX($AB$6:$AT$25,MATCH($A14,$AA$6:$AA$25,0),MATCH(F$5,$AB$5:$AT$5,0))) -> 0 | G14: =IF(ISNA(INDEX($AB$6:$AT$25,MATCH($A14,$AA$6:$AA$25,0),MATCH(G$5,$AB$5:$AT$5,0))),0,INDEX($AB$6:$AT$25,MATCH($A14,$AA$6:$AA$25,0),MATCH(G$5,$AB$5:$AT$5,0))) -> 0 | H14: =IF(ISNA(INDEX($AB$6:$AT$25,MATCH($A14,$AA$6:$AA$25,0),MATCH(H$5,$AB$5:$AT$5,0))),0,INDEX($AB$6:$AT$25,MATCH($A14,$AA$6:$AA$25,0),MATCH(H$5,$AB$5:$AT$5,0))) -> 0 | I14: =IF(ISNA(INDEX($AB$6:$AT$25,MATCH($A14,$AA$6:$AA$25,0),MATCH(I$5,$AB$5:$AT$5,0))),0,INDEX($AB$6:$AT$25,MATCH($A14,$AA$6:$AA$25,0),MATCH(I$5,$AB$5:$AT$5,0))) -> 0 | ... T14: =IF(ISNA(INDEX($AB$6:$AT$25,MATCH($A14,$AA$6:$AA$25,0),MATCH(T$5,$AB$5:$AT$5,0))),0,INDEX($AB$6:$AT$25,MATCH($A14,$AA$6:$AA$25,0),MATCH(T$5,$AB$5:$AT$5,0))) -> 13.572834 | AA14: hhd-n4 | AB14: 4.5812878 | AC14: 5.0570386 | AD14: 1.7466958 | AE14: 1.5129254 | AQ14: 0.36768057 | AR14: 0.29412952 | AS14: 0.01307663 | AT14: 13.572834
A15: hhd-n5 | B15: =IF(ISNA(INDEX($AB$6:$AT$25,MATCH($A15,$AA$6:$AA$25,0),MATCH(B$5,$AB$5:$AT$5,0))),0,INDEX($AB$6:$AT$25,MATCH($A15,$AA$6:$AA$25,0),MATCH(B$5,$AB$5:$AT$5,0))) -> 7.0508192 | C15: =IF(ISNA(INDEX($AB$6:$AT$25,MATCH($A15,$AA$6:$AA$25,0),MATCH(C$5,$AB$5:$AT$5,0))),0,INDEX($AB$6:$AT$25,MATCH($A15,$AA$6:$AA$25,0),MATCH(C$5,$AB$5:$AT$5,0))) -> 20.625618 | D15: =IF(ISNA(INDEX($AB$6:$AT$25,MATCH($A15,$AA$6:$AA$25,0),MATCH(D$5,$AB$5:$AT$5,0))),0,INDEX($AB$6:$AT$25,MATCH($A15,$AA$6:$AA$25,0),MATCH(D$5,$AB$5:$AT$5,0))) -> 17.798422 | E15: =IF(ISNA(INDEX($AB$6:$AT$25,MATCH($A15,$AA$6:$AA$25,0),MATCH(E$5,$AB$5:$AT$5,0))),0,INDEX($AB$6:$AT$25,MATCH($A15,$AA$6:$AA$25,0),MATCH(E$5,$AB$5:$AT$5,0))) -> 53.459895 | F15: =IF(ISNA(INDEX($AB$6:$AT$25,MATCH($A15,$AA$6:$AA$25,0),MATCH(F$5,$AB$5:$AT$5,0))),0,INDEX($AB$6:$AT$25,MATCH($A15,$AA$6:$AA$25,0),MATCH(F$5,$AB$5:$AT$5,0))) -> 0 | G15: =IF(ISNA(INDEX($AB$6:$AT$25,MATCH($A15,$AA$6:$AA$25,0),MATCH(G$5,$AB$5:$AT$5,0))),0,INDEX($AB$6:$AT$25,MATCH($A15,$AA$6:$AA$25,0),MATCH(G$5,$AB$5:$AT$5,0))) -> 0 | H15: =IF(ISNA(INDEX($AB$6:$AT$25,MATCH($A15,$AA$6:$AA$25,0),MATCH(H$5,$AB$5:$AT$5,0))),0,INDEX($AB$6:$AT$25,MATCH($A15,$AA$6:$AA$25,0),MATCH(H$5,$AB$5:$AT$5,0))) -> 0 | I15: =IF(ISNA(INDEX($AB$6:$AT$25,MATCH($A15,$AA$6:$AA$25,0),MATCH(I$5,$AB$5:$AT$5,0))),0,INDEX($AB$6:$AT$25,MATCH($A15,$AA$6:$AA$25,0),MATCH(I$5,$AB$5:$AT$5,0))) -> 0 | ... T15: =IF(ISNA(INDEX($AB$6:$AT$25,MATCH($A15,$AA$6:$AA$25,0),MATCH(T$5,$AB$5:$AT$5,0))),0,INDEX($AB$6:$AT$25,MATCH($A15,$AA$6:$AA$25,0),MATCH(T$5,$AB$5:$AT$5,0))) -> 127.07087 | AA15: hhd-n5 | AB15: 7.0508192 | AC15: 20.625618 | AD15: 17.798422 | AE15: 53.459895 | AQ15: 24.306941 | AR15: 3.1388331 | AS15: 0.69034371 | AT15: 127.07087
A16: hhd-u1 | B16: =IF(ISNA(INDEX($AB$6:$AT$25,MATCH($A16,$AA$6:$AA$25,0),MATCH(B$5,$AB$5:$AT$5,0))),0,INDEX($AB$6:$AT$25,MATCH($A16,$AA$6:$AA$25,0),MATCH(B$5,$AB$5:$AT$5,0))) -> 0 | C16: =IF(ISNA(INDEX($AB$6:$AT$25,MATCH($A16,$AA$6:$AA$25,0),MATCH(C$5,$AB$5:$AT$5,0))),0,INDEX($AB$6:$AT$25,MATCH($A16,$AA$6:$AA$25,0),MATCH(C$5,$AB$5:$AT$5,0))) -> 0 | D16: =IF(ISNA(INDEX($AB$6:$AT$25,MATCH($A16,$AA$6:$AA$25,0),MATCH(D$5,$AB$5:$AT$5,0))),0,INDEX($AB$6:$AT$25,MATCH($A16,$AA$6:$AA$25,0),MATCH(D$5,$AB$5:$AT$5,0))) -> 0 | E16: =IF(ISNA(INDEX($AB$6:$AT$25,MATCH($A16,$AA$6:$AA$25,0),MATCH(E$5,$AB$5:$AT$5,0))),0,INDEX($AB$6:$AT$25,MATCH($A16,$AA$6:$AA$25,0),MATCH(E$5,$AB$5:$AT$5,0))) -> 0 | F16: =IF(ISNA(INDEX($AB$6:$AT$25,MATCH($A16,$AA$6:$AA$25,0),MATCH(F$5,$AB$5:$AT$5,0))),0,INDEX($AB$6:$AT$25,MATCH($A16,$AA$6:$AA$25,0),MATCH(F$5,$AB$5:$AT$5,0))) -> 8.3787533 | G16: =IF(ISNA(INDEX($AB$6:$AT$25,MATCH($A16,$AA$6:$AA$25,0),MATCH(G$5,$AB$5:$AT$5,0))),0,INDEX($AB$6:$AT$25,MATCH($A16,$AA$6:$AA$25,0),MATCH(G$5,$AB$5:$AT$5,0))) -> 4.8066007 | H16: =IF(ISNA(INDEX($AB$6:$AT$25,MATCH($A16,$AA$6:$AA$25,0),MATCH(H$5,$AB$5:$AT$5,0))),0,INDEX($AB$6:$AT$25,MATCH($A16,$AA$6:$AA$25,0),MATCH(H$5,$AB$5:$AT$5,0))) -> 0.36879069 | I16: =IF(ISNA(INDEX($AB$6:$AT$25,MATCH($A16,$AA$6:$AA$25,0),MATCH(I$5,$AB$5:$AT$5,0))),0,INDEX($AB$6:$AT$25,MATCH($A16,$AA$6:$AA$25,0),MATCH(I$5,$AB$5:$AT$5,0))) -> 0.4648147 | ... T16: =IF(ISNA(INDEX($AB$6:$AT$25,MATCH($A16,$AA$6:$AA$25,0),MATCH(T$5,$AB$5:$AT$5,0))),0,INDEX($AB$6:$AT$25,MATCH($A16,$AA$6:$AA$25,0),MATCH(T$5,$AB$5:$AT$5,0))) -> 21.779539 | AA16: hhd-u1 | AF16: 8.3787533 | AG16: 4.8066007 | AH16: 0.36879069 | AI16: 0.4648147 | AN16: 3.2298518 | AO16: 1.6310137 | AP16: 0.44296082 | AQ16: 1.3209115 | AR16: 1.0262638 | AS16: 0.1095783 | AT16: 21.779539
A17: hhd-u2 | B17: =IF(ISNA(INDEX($AB$6:$AT$25,MATCH($A17,$AA$6:$AA$25,0),MATCH(B$5,$AB$5:$AT$5,0))),0,INDEX($AB$6:$AT$25,MATCH($A17,$AA$6:$AA$25,0),MATCH(B$5,$AB$5:$AT$5,0))) -> 0 | C17: =IF(ISNA(INDEX($AB$6:$AT$25,MATCH($A17,$AA$6:$AA$25,0),MATCH(C$5,$AB$5:$AT$5,0))),0,INDEX($AB$6:$AT$25,MATCH($A17,$AA$6:$AA$25,0),MATCH(C$5,$AB$5:$AT$5,0))) -> 0 | D17: =IF(ISNA(INDEX($AB$6:$AT$25,MATCH($A17,$AA$6:$AA$25,0),MATCH(D$5,$AB$5:$AT$5,0))),0,INDEX($AB$6:$AT$25,MATCH($A17,$AA$6:$AA$25,0),MATCH(D$5,$AB$5:$AT$5,0))) -> 0 | E17: =IF(ISNA(INDEX($AB$6:$AT$25,MATCH($A17,$AA$6:$AA$25,0),MATCH(E$5,$AB$5:$AT$5,0))),0,INDEX($AB$6:$AT$25,MATCH($A17,$AA$6:$AA$25,0),MATCH(E$5,$AB$5:$AT$5,0))) -> 0 | F17: =IF(ISNA(INDEX($AB$6:$AT$25,MATCH($A17,$AA$6:$AA$25,0),MATCH(F$5,$AB$5:$AT$5,0))),0,INDEX($AB$6:$AT$25,MATCH($A17,$AA$6:$AA$25,0),MATCH(F$5,$AB$5:$AT$5,0))) -> 9.6752028 | G17: =IF(ISNA(INDEX($AB$6:$AT$25,MATCH($A17,$AA$6:$AA$25,0),MATCH(G$5,$AB$5:$AT$5,0))),0,INDEX($AB$6:$AT$25,MATCH($A17,$AA$6:$AA$25,0),MATCH(G$5,$AB$5:$AT$5,0))) -> 7.5511293 | H17: =IF(ISNA(INDEX($AB$6:$AT$25,MATCH($A17,$AA$6:$AA$25,0),MATCH(H$5,$AB$5:$AT$5,0))),0,INDEX($AB$6:$AT$25,MATCH($A17,$AA$6:$AA$25,0),MATCH(H$5,$AB$5:$AT$5,0))) -> 0.84535815 | I17: =IF(ISNA(INDEX($AB$6:$AT$25,MATCH($A17,$AA$6:$AA$25,0),MATCH(I$5,$AB$5:$AT$5,0))),0,INDEX($AB$6:$AT$25,MATCH($A17,$AA$6:$AA$25,0),MATCH(I$5,$AB$5:$AT$5,0))) -> 1.0655349 | ... T17: =IF(ISNA(INDEX($AB$6:$AT$25,MATCH($A17,$AA$6:$AA$25,0),MATCH(T$5,$AB$5:$AT$5,0))),0,INDEX($AB$6:$AT$25,MATCH($A17,$AA$6:$AA$25,0),MATCH(T$5,$AB$5:$AT$5,0))) -> 32.551968 | AA17: hhd-u2 | AF17: 9.6752028 | AG17: 7.5511293 | AH17: 0.84535815 | AI17: 1.0655349 | AN17: 3.4479838 | AO17: 1.7349635 | AP17: 0.56932087 | AQ17: 6.1777418 | AR17: 1.1658679 | AS17: 0.31886503 | AT17: 32.551968
A18: hhd-u3 | B18: =IF(ISNA(INDEX($AB$6:$AT$25,MATCH($A18,$AA$6:$AA$25,0),MATCH(B$5,$AB$5:$AT$5,0))),0,INDEX($AB$6:$AT$25,MATCH($A18,$AA$6:$AA$25,0),MATCH(B$5,$AB$5:$AT$5,0))) -> 0 | C18: =IF(ISNA(INDEX($AB$6:$AT$25,MATCH($A18,$AA$6:$AA$25,0),MATCH(C$5,$AB$5:$AT$5,0))),0,INDEX($AB$6:$AT$25,MATCH($A18,$AA$6:$AA$25,0),MATCH(C$5,$AB$5:$AT$5,0))) -> 0 | D18: =IF(ISNA(INDEX($AB$6:$AT$25,MATCH($A18,$AA$6:$AA$25,0),MATCH(D$5,$AB$5:$AT$5,0))),0,INDEX($AB$6:$AT$25,MATCH($A18,$AA$6:$AA$25,0),MATCH(D$5,$AB$5:$AT$5,0))) -> 0 | E18: =IF(ISNA(INDEX($AB$6:$AT$25,MATCH($A18,$AA$6:$AA$25,0),MATCH(E$5,$AB$5:$AT$5,0))),0,INDEX($AB$6:$AT$25,MATCH($A18,$AA$6:$AA$25,0),MATCH(E$5,$AB$5:$AT$5,0))) -> 0 | F18: =IF(ISNA(INDEX($AB$6:$AT$25,MATCH($A18,$AA$6:$AA$25,0),MATCH(F$5,$AB$5:$AT$5,0))),0,INDEX($AB$6:$AT$25,MATCH($A18,$AA$6:$AA$25,0),MATCH(F$5,$AB$5:$AT$5,0))) -> 13.159444 | G18: =IF(ISNA(INDEX($AB$6:$AT$25,MATCH($A18,$AA$6:$AA$25,0),MATCH(G$5,$AB$5:$AT$5,0))),0,INDEX($AB$6:$AT$25,MATCH($A18,$AA$6:$AA$25,0),MATCH(G$5,$AB$5:$AT$5,0))) -> 17.20417 | H18: =IF(ISNA(INDEX($AB$6:$AT$25,MATCH($A18,$AA$6:$AA$25,0),MATCH(H$5,$AB$5:$AT$5,0))),0,INDEX($AB$6:$AT$25,MATCH($A18,$AA$6:$AA$25,0),MATCH(H$5,$AB$5:$AT$5,0))) -> 1.8257391 | I18: =IF(ISNA(INDEX($AB$6:$AT$25,MATCH($A18,$AA$6:$AA$25,0),MATCH(I$5,$AB$5:$AT$5,0))),0,INDEX($AB$6:$AT$25,MATCH($A18,$AA$6:$AA$25,0),MATCH(I$5,$AB$5:$AT$5,0))) -> 2.3002951 | ... T18: =IF(ISNA(INDEX($AB$6:$AT$25,MATCH($A18,$AA$6:$AA$25,0),MATCH(T$5,$AB$5:$AT$5,0))),0,INDEX($AB$6:$AT$25,MATCH($A18,$AA$6:$AA$25,0),MATCH(T$5,$AB$5:$AT$5,0))) -> 59.160668 | AA18: hhd-u3 | AF18: 13.159444 | AG18: 17.20417 | AH18: 1.8257391 | AI18: 2.3002951 | AN18: 5.3271571 | AO18: 2.6852725 | AP18: 1.0682427 | AQ18: 13.999868 | AR18: 1.3179287 | AS18: 0.27255136 | AT18: 59.160668
A19: hhd-u4 | B19: =IF(ISNA(INDEX($AB$6:$AT$25,MATCH($A19,$AA$6:$AA$25,0),MATCH(B$5,$AB$5:$AT$5,0))),0,INDEX($AB$6:$AT$25,MATCH($A19,$AA$6:$AA$25,0),MATCH(B$5,$AB$5:$AT$5,0))) -> 0 | C19: =IF(ISNA(INDEX($AB$6:$AT$25,MATCH($A19,$AA$6:$AA$25,0),MATCH(C$5,$AB$5:$AT$5,0))),0,INDEX($AB$6:$AT$25,MATCH($A19,$AA$6:$AA$25,0),MATCH(C$5,$AB$5:$AT$5,0))) -> 0 | D19: =IF(ISNA(INDEX($AB$6:$AT$25,MATCH($A19,$AA$6:$AA$25,0),MATCH(D$5,$AB$5:$AT$5,0))),0,INDEX($AB$6:$AT$25,MATCH($A19,$AA$6:$AA$25,0),MATCH(D$5,$AB$5:$AT$5,0))) -> 0 | E19: =IF(ISNA(INDEX($AB$6:$AT$25,MATCH($A19,$AA$6:$AA$25,0),MATCH(E$5,$AB$5:$AT$5,0))),0,INDEX($AB$6:$AT$25,MATCH($A19,$AA$6:$AA$25,0),MATCH(E$5,$AB$5:$AT$5,0))) -> 0 | F19: =IF(ISNA(INDEX($AB$6:$AT$25,MATCH($A19,$AA$6:$AA$25,0),MATCH(F$5,$AB$5:$AT$5,0))),0,INDEX($AB$6:$AT$25,MATCH($A19,$AA$6:$AA$25,0),MATCH(F$5,$AB$5:$AT$5,0))) -> 8.9380024 | G19: =IF(ISNA(INDEX($AB$6:$AT$25,MATCH($A19,$AA$6:$AA$25,0),MATCH(G$5,$AB$5:$AT$5,0))),0,INDEX($AB$6:$AT$25,MATCH($A19,$AA$6:$AA$25,0),MATCH(G$5,$AB$5:$AT$5,0))) -> 19.600906 | H19: =IF(ISNA(INDEX($AB$6:$AT$25,MATCH($A19,$AA$6:$AA$25,0),MATCH(H$5,$AB$5:$AT$5,0))),0,INDEX($AB$6:$AT$25,MATCH($A19,$AA$6:$AA$25,0),MATCH(H$5,$AB$5:$AT$5,0))) -> 8.0853777 | I19: =IF(ISNA(INDEX($AB$6:$AT$25,MATCH($A19,$AA$6:$AA$25,0),MATCH(I$5,$AB$5:$AT$5,0))),0,INDEX($AB$6:$AT$25,MATCH($A19,$AA$6:$AA$25,0),MATCH(I$5,$AB$5:$AT$5,0))) -> 10.16731 | ... T19: =IF(ISNA(INDEX($AB$6:$AT$25,MATCH($A19,$AA$6:$AA$25,0),MATCH(T$5,$AB$5:$AT$5,0))),0,INDEX($AB$6:$AT$25,MATCH($A19,$AA$6:$AA$25,0),MATCH(T$5,$AB$5:$AT$5,0))) -> 91.95691 | AA19: hhd-u4 | AF19: 8.9380024 | AG19: 19.600906 | AH19: 8.0853777 | AI19: 10.16731 | AN19: 6.8768156 | AO19: 3.4530871 | AP19: 1.8955243 | AQ19: 29.667828 | AR19: 2.3801619 | AS19: 0.89189623 | AT19: 91.95691
A20: hhd-u5 | B20: =IF(ISNA(INDEX($AB$6:$AT$25,MATCH($A20,$AA$6:$AA$25,0),MATCH(B$5,$AB$5:$AT$5,0))),0,INDEX($AB$6:$AT$25,MATCH($A20,$AA$6:$AA$25,0),MATCH(B$5,$AB$5:$AT$5,0))) -> 0 | C20: =IF(ISNA(INDEX($AB$6:$AT$25,MATCH($A20,$AA$6:$AA$25,0),MATCH(C$5,$AB$5:$AT$5,0))),0,INDEX($AB$6:$AT$25,MATCH($A20,$AA$6:$AA$25,0),MATCH(C$5,$AB$5:$AT$5,0))) -> 0 | D20: =IF(ISNA(INDEX($AB$6:$AT$25,MATCH($A20,$AA$6:$AA$25,0),MATCH(D$5,$AB$5:$AT$5,0))),0,INDEX($AB$6:$AT$25,MATCH($A20,$AA$6:$AA$25,0),MATCH(D$5,$AB$5:$AT$5,0))) -> 0 | E20: =IF(ISNA(INDEX($AB$6:$AT$25,MATCH($A20,$AA$6:$AA$25,0),MATCH(E$5,$AB$5:$AT$5,0))),0,INDEX($AB$6:$AT$25,MATCH($A20,$AA$6:$AA$25,0),MATCH(E$5,$AB$5:$AT$5,0))) -> 0 | F20: =IF(ISNA(INDEX($AB$6:$AT$25,MATCH($A20,$AA$6:$AA$25,0),MATCH(F$5,$AB$5:$AT$5,0))),0,INDEX($AB$6:$AT$25,MATCH($A20,$AA$6:$AA$25,0),MATCH(F$5,$AB$5:$AT$5,0))) -> 23.198569 | G20: =IF(ISNA(INDEX($AB$6:$AT$25,MATCH($A20,$AA$6:$AA$25,0),MATCH(G$5,$AB$5:$AT$5,0))),0,INDEX($AB$6:$AT$25,MATCH($A20,$AA$6:$AA$25,0),MATCH(G$5,$AB$5:$AT$5,0))) -> 46.425026 | H20: =IF(ISNA(INDEX($AB$6:$AT$25,MATCH($A20,$AA$6:$AA$25,0),MATCH(H$5,$AB$5:$AT$5,0))),0,INDEX($AB$6:$AT$25,MATCH($A20,$AA$6:$AA$25,0),MATCH(H$5,$AB$5:$AT$5,0))) -> 57.657474 | I20: =IF(ISNA(INDEX($AB$6:$AT$25,MATCH($A20,$AA$6:$AA$25,0),MATCH(I$5,$AB$5:$AT$5,0))),0,INDEX($AB$6:$AT$25,MATCH($A20,$AA$6:$AA$25,0),MATCH(I$5,$AB$5:$AT$5,0))) -> 281.86646 | ... T20: =IF(ISNA(INDEX($AB$6:$AT$25,MATCH($A20,$AA$6:$AA$25,0),MATCH(T$5,$AB$5:$AT$5,0))),0,INDEX($AB$6:$AT$25,MATCH($A20,$AA$6:$AA$25,0),MATCH(T$5,$AB$5:$AT$5,0))) -> 722.05484 | AA20: hhd-u5 | AF20: 23.198569 | AG20: 46.425026 | AH20: 57.657474 | AI20: 281.86646 | AN20: 14.267122 | AO20: 7.1569677 | AP20: 4.840362 | AQ20: 247.93707 | AR20: 27.986535 | AS20: 10.719252 | AT20: 722.05484
A21: hhd-k1 | B21: =IF(ISNA(INDEX($AB$6:$AT$25,MATCH($A21,$AA$6:$AA$25,0),MATCH(B$5,$AB$5:$AT$5,0))),0,INDEX($AB$6:$AT$25,MATCH($A21,$AA$6:$AA$25,0),MATCH(B$5,$AB$5:$AT$5,0))) -> 0 | C21: =IF(ISNA(INDEX($AB$6:$AT$25,MATCH($A21,$AA$6:$AA$25,0),MATCH(C$5,$AB$5:$AT$5,0))),0,INDEX($AB$6:$AT$25,MATCH($A21,$AA$6:$AA$25,0),MATCH(C$5,$AB$5:$AT$5,0))) -> 0 | D21: =IF(ISNA(INDEX($AB$6:$AT$25,MATCH($A21,$AA$6:$AA$25,0),MATCH(D$5,$AB$5:$AT$5,0))),0,INDEX($AB$6:$AT$25,MATCH($A21,$AA$6:$AA$25,0),MATCH(D$5,$AB$5:$AT$5,0))) -> 0 | E21: =IF(ISNA(INDEX($AB$6:$AT$25,MATCH($A21,$AA$6:$AA$25,0),MATCH(E$5,$AB$5:$AT$5,0))),0,INDEX($AB$6:$AT$25,MATCH($A21,$AA$6:$AA$25,0),MATCH(E$5,$AB$5:$AT$5,0))) -> 0 | F21: =IF(ISNA(INDEX($AB$6:$AT$25,MATCH($A21,$AA$6:$AA$25,0),MATCH(F$5,$AB$5:$AT$5,0))),0,INDEX($AB$6:$AT$25,MATCH($A21,$AA$6:$AA$25,0),MATCH(F$5,$AB$5:$AT$5,0))) -> 0 | G21: =IF(ISNA(INDEX($AB$6:$AT$25,MATCH($A21,$AA$6:$AA$25,0),MATCH(G$5,$AB$5:$AT$5,0))),0,INDEX($AB$6:$AT$25,MATCH($A21,$AA$6:$AA$25,0),MATCH(G$5,$AB$5:$AT$5,0))) -> 0 | H21: =IF(ISNA(INDEX($AB$6:$AT$25,MATCH($A21,$AA$6:$AA$25,0),MATCH(H$5,$AB$5:$AT$5,0))),0,INDEX($AB$6:$AT$25,MATCH($A21,$AA$6:$AA$25,0),MATCH(H$5,$AB$5:$AT$5,0))) -> 0 | I21: =IF(ISNA(INDEX($AB$6:$AT$25,MATCH($A21,$AA$6:$AA$25,0),MATCH(I$5,$AB$5:$AT$5,0))),0,INDEX($AB$6:$AT$25,MATCH($A21,$AA$6:$AA$25,0),MATCH(I$5,$AB$5:$AT$5,0))) -> 0 | ... T21: =IF(ISNA(INDEX($AB$6:$AT$25,MATCH($A21,$AA$6:$AA$25,0),MATCH(T$5,$AB$5:$AT$5,0))),0,INDEX($AB$6:$AT$25,MATCH($A21,$AA$6:$AA$25,0),MATCH(T$5,$AB$5:$AT$5,0))) -> 7.7708614 | AA21: hhd-k1 | AJ21: 4.7125447 | AK21: 0.78958269 | AN21: 1.0347639 | AO21: 0.52077907 | AP21: 0.047242205 | AR21: 0.59334259 | AS21: 0.072606279 | AT21: 7.7708614
A22: hhd-k2 | B22: =IF(ISNA(INDEX($AB$6:$AT$25,MATCH($A22,$AA$6:$AA$25,0),MATCH(B$5,$AB$5:$AT$5,0))),0,INDEX($AB$6:$AT$25,MATCH($A22,$AA$6:$AA$25,0),MATCH(B$5,$AB$5:$AT$5,0))) -> 0 | C22: =IF(ISNA(INDEX($AB$6:$AT$25,MATCH($A22,$AA$6:$AA$25,0),MATCH(C$5,$AB$5:$AT$5,0))),0,INDEX($AB$6:$AT$25,MATCH($A22,$AA$6:$AA$25,0),MATCH(C$5,$AB$5:$AT$5,0))) -> 0 | D22: =IF(ISNA(INDEX($AB$6:$AT$25,MATCH($A22,$AA$6:$AA$25,0),MATCH(D$5,$AB$5:$AT$5,0))),0,INDEX($AB$6:$AT$25,MATCH($A22,$AA$6:$AA$25,0),MATCH(D$5,$AB$5:$AT$5,0))) -> 0 | E22: =IF(ISNA(INDEX($AB$6:$AT$25,MATCH($A22,$AA$6:$AA$25,0),MATCH(E$5,$AB$5:$AT$5,0))),0,INDEX($AB$6:$AT$25,MATCH($A22,$AA$6:$AA$25,0),MATCH(E$5,$AB$5:$AT$5,0))) -> 0 | F22: =IF(ISNA(INDEX($AB$6:$AT$25,MATCH($A22,$AA$6:$AA$25,0),MATCH(F$5,$AB$5:$AT$5,0))),0,INDEX($AB$6:$AT$25,MATCH($A22,$AA$6:$AA$25,0),MATCH(F$5,$AB$5:$AT$5,0))) -> 0 | G22: =IF(ISNA(INDEX($AB$6:$AT$25,MATCH($A22,$AA$6:$AA$25,0),MATCH(G$5,$AB$5:$AT$5,0))),0,INDEX($AB$6:$AT$25,MATCH($A22,$AA$6:$AA$25,0),MATCH(G$5,$AB$5:$AT$5,0))) -> 0 | H22: =IF(ISNA(INDEX($AB$6:$AT$25,MATCH($A22,$AA$6:$AA$25,0),MATCH(H$5,$AB$5:$AT$5,0))),0,INDEX($AB$6:$AT$25,MATCH($A22,$AA$6:$AA$25,0),MATCH(H$5,$AB$5:$AT$5,0))) -> 0 | I22: =IF(ISNA(INDEX($AB$6:$AT$25,MATCH($A22,$AA$6:$AA$25,0),MATCH(I$5,$AB$5:$AT$5,0))),0,INDEX($AB$6:$AT$25,MATCH($A22,$AA$6:$AA$25,0),MATCH(I$5,$AB$5:$AT$5,0))) -> 0 | ... T22: =IF(ISNA(INDEX($AB$6:$AT$25,MATCH($A22,$AA$6:$AA$25,0),MATCH(T$5,$AB$5:$AT$5,0))),0,INDEX($AB$6:$AT$25,MATCH($A22,$AA$6:$AA$25,0),MATCH(T$5,$AB$5:$AT$5,0))) -> 25.877243 | AA22: hhd-k2 | AJ22: 7.5537376 | AK22: 5.1988453 | AL22: 2.6945601 | AM22: 2.350258 | AN22: 1.8829349 | AO22: 0.94804581 | AP22: 0.51177752 | AQ22: 2.8830098 | AR22: 1.7066944 | AS22: 0.14737932 | AT22: 25.877243
A23: hhd-k3 | B23: =IF(ISNA(INDEX($AB$6:$AT$25,MATCH($A23,$AA$6:$AA$25,0),MATCH(B$5,$AB$5:$AT$5,0))),0,INDEX($AB$6:$AT$25,MATCH($A23,$AA$6:$AA$25,0),MATCH(B$5,$AB$5:$AT$5,0))) -> 0 | C23: =IF(ISNA(INDEX($AB$6:$AT$25,MATCH($A23,$AA$6:$AA$25,0),MATCH(C$5,$AB$5:$AT$5,0))),0,INDEX($AB$6:$AT$25,MATCH($A23,$AA$6:$AA$25,0),MATCH(C$5,$AB$5:$AT$5,0))) -> 0 | D23: =IF(ISNA(INDEX($AB$6:$AT$25,MATCH($A23,$AA$6:$AA$25,0),MATCH(D$5,$AB$5:$AT$5,0))),0,INDEX($AB$6:$AT$25,MATCH($A23,$AA$6:$AA$25,0),MATCH(D$5,$AB$5:$AT$5,0))) -> 0 | E23: =IF(ISNA(INDEX($AB$6:$AT$25,MATCH($A23,$AA$6:$AA$25,0),MATCH(E$5,$AB$5:$AT$5,0))),0,INDEX($AB$6:$AT$25,MATCH($A23,$AA$6:$AA$25,0),MATCH(E$5,$AB$5:$AT$5,0))) -> 0 | F23: =IF(ISNA(INDEX($AB$6:$AT$25,MATCH($A23,$AA$6:$AA$25,0),MATCH(F$5,$AB$5:$AT$5,0))),0,INDEX($AB$6:$AT$25,MATCH($A23,$AA$6:$AA$25,0),MATCH(F$5,$AB$5:$AT$5,0))) -> 0 | G23: =IF(ISNA(INDEX($AB$6:$AT$25,MATCH($A23,$AA$6:$AA$25,0),MATCH(G$5,$AB$5:$AT$5,0))),0,INDEX($AB$6:$AT$25,MATCH($A23,$AA$6:$AA$25,0),MATCH(G$5,$AB$5:$AT$5,0))) -> 0 | H23: =IF(ISNA(INDEX($AB$6:$AT$25,MATCH($A23,$AA$6:$AA$25,0),MATCH(H$5,$AB$5:$AT$5,0))),0,INDEX($AB$6:$AT$25,MATCH($A23,$AA$6:$AA$25,0),MATCH(H$5,$AB$5:$AT$5,0))) -> 0 | I23: =IF(ISNA(INDEX($AB$6:$AT$25,MATCH($A23,$AA$6:$AA$25,0),MATCH(I$5,$AB$5:$AT$5,0))),0,INDEX($AB$6:$AT$25,MATCH($A23,$AA$6:$AA$25,0),MATCH(I$5,$AB$5:$AT$5,0))) -> 0 | ... T23: =IF(ISNA(INDEX($AB$6:$AT$25,MATCH($A23,$AA$6:$AA$25,0),MATCH(T$5,$AB$5:$AT$5,0))),0,INDEX($AB$6:$AT$25,MATCH($A23,$AA$6:$AA$25,0),MATCH(T$5,$AB$5:$AT$5,0))) -> 43.350997 | AA23: hhd-k3 | AJ23: 11.090036 | AK23: 9.5839684 | AL23: 2.9566835 | AM23: 2.5776513 | AN23: 6.1709302 | AO23: 3.1139931 | AP23: 0.87799149 | AQ23: 5.4986194 | AR23: 1.2968449 | AS23: 0.18427917 | AT23: 43.350997
A24: hhd-k4 | B24: =IF(ISNA(INDEX($AB$6:$AT$25,MATCH($A24,$AA$6:$AA$25,0),MATCH(B$5,$AB$5:$AT$5,0))),0,INDEX($AB$6:$AT$25,MATCH($A24,$AA$6:$AA$25,0),MATCH(B$5,$AB$5:$AT$5,0))) -> 0 | C24: =IF(ISNA(INDEX($AB$6:$AT$25,MATCH($A24,$AA$6:$AA$25,0),MATCH(C$5,$AB$5:$AT$5,0))),0,INDEX($AB$6:$AT$25,MATCH($A24,$AA$6:$AA$25,0),MATCH(C$5,$AB$5:$AT$5,0))) -> 0 | D24: =IF(ISNA(INDEX($AB$6:$AT$25,MATCH($A24,$AA$6:$AA$25,0),MATCH(D$5,$AB$5:$AT$5,0))),0,INDEX($AB$6:$AT$25,MATCH($A24,$AA$6:$AA$25,0),MATCH(D$5,$AB$5:$AT$5,0))) -> 0 | E24: =IF(ISNA(INDEX($AB$6:$AT$25,MATCH($A24,$AA$6:$AA$25,0),MATCH(E$5,$AB$5:$AT$5,0))),0,INDEX($AB$6:$AT$25,MATCH($A24,$AA$6:$AA$25,0),MATCH(E$5,$AB$5:$AT$5,0))) -> 0 | F24: =IF(ISNA(INDEX($AB$6:$AT$25,MATCH($A24,$AA$6:$AA$25,0),MATCH(F$5,$AB$5:$AT$5,0))),0,INDEX($AB$6:$AT$25,MATCH($A24,$AA$6:$AA$25,0),MATCH(F$5,$AB$5:$AT$5,0))) -> 0 | G24: =IF(ISNA(INDEX($AB$6:$AT$25,MATCH($A24,$AA$6:$AA$25,0),MATCH(G$5,$AB$5:$AT$5,0))),0,INDEX($AB$6:$AT$25,MATCH($A24,$AA$6:$AA$25,0),MATCH(G$5,$AB$5:$AT$5,0))) -> 0 | H24: =IF(ISNA(INDEX($AB$6:$AT$25,MATCH($A24,$AA$6:$AA$25,0),MATCH(H$5,$AB$5:$AT$5,0))),0,INDEX($AB$6:$AT$25,MATCH($A24,$AA$6:$AA$25,0),MATCH(H$5,$AB$5:$AT$5,0))) -> 0 | I24: =IF(ISNA(INDEX($AB$6:$AT$25,MATCH($A24,$AA$6:$AA$25,0),MATCH(I$5,$AB$5:$AT$5,0))),0,INDEX($AB$6:$AT$25,MATCH($A24,$AA$6:$AA$25,0),MATCH(I$5,$AB$5:$AT$5,0))) -> 0 | ... T24: =IF(ISNA(INDEX($AB$6:$AT$25,MATCH($A24,$AA$6:$AA$25,0),MATCH(T$5,$AB$5:$AT$5,0))),0,INDEX($AB$6:$AT$25,MATCH($A24,$AA$6:$AA$25,0),MATCH(T$5,$AB$5:$AT$5,0))) -> 123.62397 | AA24: hhd-k4 | AJ24: 21.838883 | AK24: 23.202736 | AL24: 9.8265723 | AM24: 8.5588047 | AN24: 11.008699 | AO24: 5.5393416 | AP24: 6.5208296 | AQ24: 32.616017 | AR24: 4.0319802 | AS24: 0.48011019 | AT24: 123.62397
A25: hhd-k5 | B25: =IF(ISNA(INDEX($AB$6:$AT$25,MATCH($A25,$AA$6:$AA$25,0),MATCH(B$5,$AB$5:$AT$5,0))),0,INDEX($AB$6:$AT$25,MATCH($A25,$AA$6:$AA$25,0),MATCH(B$5,$AB$5:$AT$5,0))) -> 0 | C25: =IF(ISNA(INDEX($AB$6:$AT$25,MATCH($A25,$AA$6:$AA$25,0),MATCH(C$5,$AB$5:$AT$5,0))),0,INDEX($AB$6:$AT$25,MATCH($A25,$AA$6:$AA$25,0),MATCH(C$5,$AB$5:$AT$5,0))) -> 0 | D25: =IF(ISNA(INDEX($AB$6:$AT$25,MATCH($A25,$AA$6:$AA$25,0),MATCH(D$5,$AB$5:$AT$5,0))),0,INDEX($AB$6:$AT$25,MATCH($A25,$AA$6:$AA$25,0),MATCH(D$5,$AB$5:$AT$5,0))) -> 0 | E25: =IF(ISNA(INDEX($AB$6:$AT$25,MATCH($A25,$AA$6:$AA$25,0),MATCH(E$5,$AB$5:$AT$5,0))),0,INDEX($AB$6:$AT$25,MATCH($A25,$AA$6:$AA$25,0),MATCH(E$5,$AB$5:$AT$5,0))) -> 0 | F25: =IF(ISNA(INDEX($AB$6:$AT$25,MATCH($A25,$AA$6:$AA$25,0),MATCH(F$5,$AB$5:$AT$5,0))),0,INDEX($AB$6:$AT$25,MATCH($A25,$AA$6:$AA$25,0),MATCH(F$5,$AB$5:$AT$5,0))) -> 0 | G25: =IF(ISNA(INDEX($AB$6:$AT$25,MATCH($A25,$AA$6:$AA$25,0),MATCH(G$5,$AB$5:$AT$5,0))),0,INDEX($AB$6:$AT$25,MATCH($A25,$AA$6:$AA$25,0),MATCH(G$5,$AB$5:$AT$5,0))) -> 0 | H25: =IF(ISNA(INDEX($AB$6:$AT$25,MATCH($A25,$AA$6:$AA$25,0),MATCH(H$5,$AB$5:$AT$5,0))),0,INDEX($AB$6:$AT$25,MATCH($A25,$AA$6:$AA$25,0),MATCH(H$5,$AB$5:$AT$5,0))) -> 0 | I25: =IF(ISNA(INDEX($AB$6:$AT$25,MATCH($A25,$AA$6:$AA$25,0),MATCH(I$5,$AB$5:$AT$5,0))),0,INDEX($AB$6:$AT$25,MATCH($A25,$AA$6:$AA$25,0),MATCH(I$5,$AB$5:$AT$5,0))) -> 0 | ... T25: =IF(ISNA(INDEX($AB$6:$AT$25,MATCH($A25,$AA$6:$AA$25,0),MATCH(T$5,$AB$5:$AT$5,0))),0,INDEX($AB$6:$AT$25,MATCH($A25,$AA$6:$AA$25,0),MATCH(T$5,$AB$5:$AT$5,0))) -> 2374.4754 | AA25: hhd-k5 | AJ25: 52.702883 | AK25: 86.863386 | AL25: 163.9042 | AM25: 1133.9744 | AN25: 18.910211 | AO25: 9.4859542 | AP25: 9.3228154 | AQ25: 712.79876 | AR25: 81.470815 | AS25: 105.04191 | AT25: 2374.4754
A26: Farm | B26: =SUM(B6:B10) -> 675.76748 | C26: =SUM(C6:C10) -> 721.19325 | D26: =SUM(D6:D10) -> 131.87334 | E26: =SUM(E6:E10) -> 146.15777 | F26: =SUM(F6:F10) -> 0 | G26: =SUM(G6:G10) -> 0 | H26: =SUM(H6:H10) -> 0 | I26: =SUM(I6:I10) -> 0 | ... T26: =SUM(T6:T10) -> 3255.7522
A27: Non-farm | B27: =SUM(B11:B15) -> 14.410969 | C27: =SUM(C11:C15) -> 28.322852 | D27: =SUM(D11:D15) -> 20.085291 | E27: =SUM(E11:E15) -> 54.97282 | F27: =SUM(F11:F15) -> 0 | G27: =SUM(G11:G15) -> 0 | H27: =SUM(H11:H15) -> 0 | I27: =SUM(I11:I15) -> 0 | ... T27: =SUM(T11:T15) -> 147.09869
A28: Urban | B28: =SUM(B16:B20) -> 0 | C28: =SUM(C16:C20) -> 0 | D28: =SUM(D16:D20) -> 0 | E28: =SUM(E16:E20) -> 0 | F28: =SUM(F16:F20) -> 63.349972 | G28: =SUM(G16:G20) -> 95.587832 | H28: =SUM(H16:H20) -> 68.78274 | I28: =SUM(I16:I20) -> 295.86441 | ... T28: =SUM(T16:T20) -> 927.50393
A29: Kigali | B29: =SUM(B21:B25) -> 0 | C29: =SUM(C21:C25) -> 0 | D29: =SUM(D21:D25) -> 0 | E29: =SUM(E21:E25) -> 0 | F29: =SUM(F21:F25) -> 0 | G29: =SUM(G21:G25) -> 0 | H29: =SUM(H21:H25) -> 0 | I29: =SUM(I21:I25) -> 0 | ... T29: =SUM(T21:T25) -> 2575.0984
A30: Total | B30: =SUM(B26:B29) -> 690.17844 | C30: =SUM(C26:C29) -> 749.5161 | D30: =SUM(D26:D29) -> 151.95863 | E30: =SUM(E26:E29) -> 201.13059 | F30: =SUM(F26:F29) -> 63.349972 | G30: =SUM(G26:G29) -> 95.587832 | H30: =SUM(H26:H29) -> 68.78274 | I30: =SUM(I26:I29) -> 295.86441 | ... T30: =SUM(T26:T29) -> 6905.4532
A31: Q1 | B31: =B6+B11+B16+B21 -> 119.61664 | C31: =C6+C11+C16+C21 -> 78.09283 | D31: =D6+D11+D16+D21 -> 2.9336712 | E31: =E6+E11+E16+E21 -> 0.15527475 | F31: =F6+F11+F16+F21 -> 8.3787533 | G31: =G6+G11+G16+G21 -> 4.8066007 | H31: =H6+H11+H16+H21 -> 0.36879069 | I31: =I6+I11+I16+I21 -> 0.4648147 | ... T31: =T6+T11+T16+T21 -> 383.05869
A32: Q2 | B32: =B7+B12+B17+B22 -> 126.05204 | C32: =C7+C12+C17+C22 -> 114.99399 | D32: =D7+D12+D17+D22 -> 9.968745 | E32: =E7+E12+E17+E22 -> 1.3257162 | F32: =F7+F12+F17+F22 -> 9.6752028 | G32: =G7+G12+G17+G22 -> 7.5511293 | H32: =H7+H12+H17+H22 -> 0.84535815 | I32: =I7+I12+I17+I22 -> 1.0655349 | ... T32: =T7+T12+T17+T22 -> 521.36158
A33: Q3 | B33: =B8+B13+B18+B23 -> 168.57696 | C33: =C8+C13+C18+C23 -> 166.83267 | D33: =D8+D13+D18+D23 -> 16.435927 | E33: =E8+E13+E18+E23 -> 1.1400639 | F33: =F8+F13+F18+F23 -> 13.159444 | G33: =G8+G13+G18+G23 -> 17.20417 | H33: =H8+H13+H18+H23 -> 1.8257391 | I33: =I8+I13+I18+I23 -> 2.3002951 | ... T33: =T8+T13+T18+T23 -> 730.2728
A34: Q4 | B34: =B9+B14+B19+B24 -> 174.46182 | C34: =C9+C14+C19+C24 -> 198.84608 | D34: =D9+D14+D19+D24 -> 34.237849 | E34: =E9+E14+E19+E24 -> 30.482498 | F34: =F9+F14+F19+F24 -> 8.9380024 | G34: =G9+G14+G19+G24 -> 19.600906 | H34: =H9+H14+H19+H24 -> 8.0853777 | I34: =I9+I14+I19+I24 -> 10.16731 | ... T34: =T9+T14+T19+T24 -> 1104.7929
A35: Q5 | B35: =B10+B15+B20+B25 -> 101.47099 | C35: =C10+C15+C20+C25 -> 190.75053 | D35: =D10+D15+D20+D25 -> 88.38244 | E35: =E10+E15+E20+E25 -> 168.02704 | F35: =F10+F15+F20+F25 -> 23.198569 | G35: =G10+G15+G20+G25 -> 46.425026 | H35: =H10+H15+H20+H25 -> 57.657474 | I35: =I10+I15+I20+I25 -> 281.86646 | ... T35: =T10+T15+T20+T25 -> 4165.9672
A38: Household expenditure table
A39: EXPTAB
B40: amaiz | C40: cmaiz | D40: cfood | E40: gov | F40: dtax | G40: s-i | H40: row | I40: total | AB40: amaiz | AC40: cmaiz | AD40: cfood | AE40: gov | AF40: dtax | AG40: s-i | AH40: row | AI40: total
A41: hhd-f1 | B41: =IF(ISNA(INDEX($AB$41:$AI$60,MATCH($A41,$AA$41:$AA$60,0),MATCH(B$40,$AB$40:$AI$40,0))),0,INDEX($AB$41:$AI$60,MATCH($A41,$AA$41:$AA$60,0),MATCH(B$40,$AB$40:$AI$40,0))) -> 113.6174 | C41: =IF(ISNA(INDEX($AB$41:$AI$60,MATCH($A41,$AA$41:$AA$60,0),MATCH(C$40,$AB$40:$AI$40,0))),0,INDEX($AB$41:$AI$60,MATCH($A41,$AA$41:$AA$60,0),MATCH(C$40,$AB$40:$AI$40,0))) -> 224.68157 | D41: =IF(ISNA(INDEX($AB$41:$AI$60,MATCH($A41,$AA$41:$AA$60,0),MATCH(D$40,$AB$40:$AI$40,0))),0,INDEX($AB$41:$AI$60,MATCH($A41,$AA$41:$AA$60,0),MATCH(D$40,$AB$40:$AI$40,0))) -> 59.630031 | E41: =IF(ISNA(INDEX($AB$41:$AI$60,MATCH($A41,$AA$41:$AA$60,0),MATCH(E$40,$AB$40:$AI$40,0))),0,INDEX($AB$41:$AI$60,MATCH($A41,$AA$41:$AA$60,0),MATCH(E$40,$AB$40:$AI$40,0))) -> 0.31483112 | F41: =IF(ISNA(INDEX($AB$41:$AI$60,MATCH($A41,$AA$41:$AA$60,0),MATCH(F$40,$AB$40:$AI$40,0))),0,INDEX($AB$41:$AI$60,MATCH($A41,$AA$41:$AA$60,0),MATCH(F$40,$AB$40:$AI$40,0))) -> 1.7129819 | G41: =IF(ISNA(INDEX($AB$41:$AI$60,MATCH($A41,$AA$41:$AA$60,0),MATCH(G$40,$AB$40:$AI$40,0))),0,INDEX($AB$41:$AI$60,MATCH($A41,$AA$41:$AA$60,0),MATCH(G$40,$AB$40:$AI$40,0))) -> 11.185573 | H41: =IF(ISNA(INDEX($AB$41:$AI$60,MATCH($A41,$AA$41:$AA$60,0),MATCH(H$40,$AB$40:$AI$40,0))),0,INDEX($AB$41:$AI$60,MATCH($A41,$AA$41:$AA$60,0),MATCH(H$40,$AB$40:$AI$40,0))) -> 1.157336 | I41: =IF(ISNA(INDEX($AB$41:$AI$60,MATCH($A41,$AA$41:$AA$60,0),MATCH(I$40,$AB$40:$AI$40,0))),0,INDEX($AB$41:$AI$60,MATCH($A41,$AA$41:$AA$60,0),MATCH(I$40,$AB$40:$AI$40,0))) -> 352.66969 | AA41: hhd-f1 | AB41: 113.6174 | AC41: 224.68157 | AD41: 59.630031 | AE41: 0.31483112 | AF41: 1.7129819 | AG41: 11.185573 | AH41: 1.157336 | AI41: 352.66969
A42: hhd-f2 | B42: =IF(ISNA(INDEX($AB$41:$AI$60,MATCH($A42,$AA$41:$AA$60,0),MATCH(B$40,$AB$40:$AI$40,0))),0,INDEX($AB$41:$AI$60,MATCH($A42,$AA$41:$AA$60,0),MATCH(B$40,$AB$40:$AI$40,0))) -> 156.6676 | C42: =IF(ISNA(INDEX($AB$41:$AI$60,MATCH($A42,$AA$41:$AA$60,0),MATCH(C$40,$AB$40:$AI$40,0))),0,INDEX($AB$41:$AI$60,MATCH($A42,$AA$41:$AA$60,0),MATCH(C$40,$AB$40:$AI$40,0))) -> 286.93687 | D42: =IF(ISNA(INDEX($AB$41:$AI$60,MATCH($A42,$AA$41:$AA$60,0),MATCH(D$40,$AB$40:$AI$40,0))),0,INDEX($AB$41:$AI$60,MATCH($A42,$AA$41:$AA$60,0),MATCH(D$40,$AB$40:$AI$40,0))) -> 102.13871 | E42: =IF(ISNA(INDEX($AB$41:$AI$60,MATCH($A42,$AA$41:$AA$60,0),MATCH(E$40,$AB$40:$AI$40,0))),0,INDEX($AB$41:$AI$60,MATCH($A42,$AA$41:$AA$60,0),MATCH(E$40,$AB$40:$AI$40,0))) -> 1.0543925 | F42: =IF(ISNA(INDEX($AB$41:$AI$60,MATCH($A42,$AA$41:$AA$60,0),MATCH(F$40,$AB$40:$AI$40,0))),0,INDEX($AB$41:$AI$60,MATCH($A42,$AA$41:$AA$60,0),MATCH(F$40,$AB$40:$AI$40,0))) -> 2.2430669 | G42: =IF(ISNA(INDEX($AB$41:$AI$60,MATCH($A42,$AA$41:$AA$60,0),MATCH(G$40,$AB$40:$AI$40,0))),0,INDEX($AB$41:$AI$60,MATCH($A42,$AA$41:$AA$60,0),MATCH(G$40,$AB$40:$AI$40,0))) -> 13.570561 | H42: =IF(ISNA(INDEX($AB$41:$AI$60,MATCH($A42,$AA$41:$AA$60,0),MATCH(H$40,$AB$40:$AI$40,0))),0,INDEX($AB$41:$AI$60,MATCH($A42,$AA$41:$AA$60,0),MATCH(H$40,$AB$40:$AI$40,0))) -> 1.2553558 | I42: =IF(ISNA(INDEX($AB$41:$AI$60,MATCH($A42,$AA$41:$AA$60,0),MATCH(I$40,$AB$40:$AI$40,0))),0,INDEX($AB$41:$AI$60,MATCH($A42,$AA$41:$AA$60,0),MATCH(I$40,$AB$40:$AI$40,0))) -> 461.72785 | AA42: hhd-f2 | AB42: 156.6676 | AC42: 286.93687 | AD42: 102.13871 | AE42: 1.0543925 | AF42: 2.2430669 | AG42: 13.570561 | AH42: 1.2553558 | AI42: 461.72785
A43: hhd-f3 | B43: =IF(ISNA(INDEX($AB$41:$AI$60,MATCH($A43,$AA$41:$AA$60,0),MATCH(B$40,$AB$40:$AI$40,0))),0,INDEX($AB$41:$AI$60,MATCH($A43,$AA$41:$AA$60,0),MATCH(B$40,$AB$40:$AI$40,0))) -> 202.11893 | C43: =IF(ISNA(INDEX($AB$41:$AI$60,MATCH($A43,$AA$41:$AA$60,0),MATCH(C$40,$AB$40:$AI$40,0))),0,INDEX($AB$41:$AI$60,MATCH($A43,$AA$41:$AA$60,0),MATCH(C$40,$AB$40:$AI$40,0))) -> 394.07807 | D43: =IF(ISNA(INDEX($AB$41:$AI$60,MATCH($A43,$AA$41:$AA$60,0),MATCH(D$40,$AB$40:$AI$40,0))),0,INDEX($AB$41:$AI$60,MATCH($A43,$AA$41:$AA$60,0),MATCH(D$40,$AB$40:$AI$40,0))) -> 145.01664 | E43: =IF(ISNA(INDEX($AB$41:$AI$60,MATCH($A43,$AA$41:$AA$60,0),MATCH(E$40,$AB$40:$AI$40,0))),0,INDEX($AB$41:$AI$60,MATCH($A43,$AA$41:$AA$60,0),MATCH(E$40,$AB$40:$AI$40,0))) -> 1.8690184 | F43: =IF(ISNA(INDEX($AB$41:$AI$60,MATCH($A43,$AA$41:$AA$60,0),MATCH(F$40,$AB$40:$AI$40,0))),0,INDEX($AB$41:$AI$60,MATCH($A43,$AA$41:$AA$60,0),MATCH(F$40,$AB$40:$AI$40,0))) -> 3.5881142 | G43: =IF(ISNA(INDEX($AB$41:$AI$60,MATCH($A43,$AA$41:$AA$60,0),MATCH(G$40,$AB$40:$AI$40,0))),0,INDEX($AB$41:$AI$60,MATCH($A43,$AA$41:$AA$60,0),MATCH(G$40,$AB$40:$AI$40,0))) -> 19.229197 | H43: =IF(ISNA(INDEX($AB$41:$AI$60,MATCH($A43,$AA$41:$AA$60,0),MATCH(H$40,$AB$40:$AI$40,0))),0,INDEX($AB$41:$AI$60,MATCH($A43,$AA$41:$AA$60,0),MATCH(H$40,$AB$40:$AI$40,0))) -> 2.465933 | I43: =IF(ISNA(INDEX($AB$41:$AI$60,MATCH($A43,$AA$41:$AA$60,0),MATCH(I$40,$AB$40:$AI$40,0))),0,INDEX($AB$41:$AI$60,MATCH($A43,$AA$41:$AA$60,0),MATCH(I$40,$AB$40:$AI$40,0))) -> 623.34927 | AA43: hhd-f3 | AB43: 202.11893 | AC43: 394.07807 | AD43: 145.01664 | AE43: 1.8690184 | AF43: 3.5881142 | AG43: 19.229197 | AH43: 2.465933 | AI43: 623.34927
A44: hhd-f4 | B44: =IF(ISNA(INDEX($AB$41:$AI$60,MATCH($A44,$AA$41:$AA$60,0),MATCH(B$40,$AB$40:$AI$40,0))),0,INDEX($AB$41:$AI$60,MATCH($A44,$AA$41:$AA$60,0),MATCH(B$40,$AB$40:$AI$40,0))) -> 256.09221 | C44: =IF(ISNA(INDEX($AB$41:$AI$60,MATCH($A44,$AA$41:$AA$60,0),MATCH(C$40,$AB$40:$AI$40,0))),0,INDEX($AB$41:$AI$60,MATCH($A44,$AA$41:$AA$60,0),MATCH(C$40,$AB$40:$AI$40,0))) -> 564.2855 | D44: =IF(ISNA(INDEX($AB$41:$AI$60,MATCH($A44,$AA$41:$AA$60,0),MATCH(D$40,$AB$40:$AI$40,0))),0,INDEX($AB$41:$AI$60,MATCH($A44,$AA$41:$AA$60,0),MATCH(D$40,$AB$40:$AI$40,0))) -> 191.70493 | E44: =IF(ISNA(INDEX($AB$41:$AI$60,MATCH($A44,$AA$41:$AA$60,0),MATCH(E$40,$AB$40:$AI$40,0))),0,INDEX($AB$41:$AI$60,MATCH($A44,$AA$41:$AA$60,0),MATCH(E$40,$AB$40:$AI$40,0))) -> 4.1442806 | F44: =IF(ISNA(INDEX($AB$41:$AI$60,MATCH($A44,$AA$41:$AA$60,0),MATCH(F$40,$AB$40:$AI$40,0))),0,INDEX($AB$41:$AI$60,MATCH($A44,$AA$41:$AA$60,0),MATCH(F$40,$AB$40:$AI$40,0))) -> 10.941351 | G44: =IF(ISNA(INDEX($AB$41:$AI$60,MATCH($A44,$AA$41:$AA$60,0),MATCH(G$40,$AB$40:$AI$40,0))),0,INDEX($AB$41:$AI$60,MATCH($A44,$AA$41:$AA$60,0),MATCH(G$40,$AB$40:$AI$40,0))) -> 36.767094 | H44: =IF(ISNA(INDEX($AB$41:$AI$60,MATCH($A44,$AA$41:$AA$60,0),MATCH(H$40,$AB$40:$AI$40,0))),0,INDEX($AB$41:$AI$60,MATCH($A44,$AA$41:$AA$60,0),MATCH(H$40,$AB$40:$AI$40,0))) -> 3.4087924 | I44: =IF(ISNA(INDEX($AB$41:$AI$60,MATCH($A44,$AA$41:$AA$60,0),MATCH(I$40,$AB$40:$AI$40,0))),0,INDEX($AB$41:$AI$60,MATCH($A44,$AA$41:$AA$60,0),MATCH(I$40,$AB$40:$AI$40,0))) -> 875.63923 | AA44: hhd-f4 | AB44: 256.09221 | AC44: 564.2855 | AD44: 191.70493 | AE44: 4.1442806 | AF44: 10.941351 | AG44: 36.767094 | AH44: 3.4087924 | AI44: 875.63923
...

Sheet Workings
A1: Household Income Sources and Expenditure Patterns
A5: Household incomes | C5: Labor | H5: Farm earnnings | L5: Non-farm earnings
C6: Total | D6: None | E6: Primary | F6: Second. | G6: Tertiary | H6: Total | I6: Land | J6: Crops | K6: Livestock | L6: Enterprises | M6: Government | N6: Rest of world | O6: Total
A7: Rural - farm q1 | B7: hhd-f1 | C7: =SUM(D7:G7) -> 56.718718 | D7: =SUM(Data!B6,Data!F6,Data!J6)/Data!$T6*100 -> 33.761575 | E7: =SUM(Data!C6,Data!G6,Data!K6)/Data!$T6*100 -> 22.081268 | F7: =SUM(Data!D6,Data!H6,Data!L6)/Data!$T6*100 -> 0.83184668 | G7: =SUM(Data!E6,Data!I6,Data!M6)/Data!$T6*100 -> 0.044028379 | H7: =SUM(I7:K7) -> 31.821148 | I7: =Data!N6/Data!$T6*100 -> 19.686655 | J7: =Data!O6/Data!$T6*100 -> 9.9899314 | K7: =Data!P6/Data!$T6*100 -> 2.1445616 | L7: =Data!Q6/Data!$T6*100 -> 5.1398583 | M7: =Data!R6/Data!$T6*100 -> 5.6194069 | N7: =Data!S6/Data!$T6*100 -> 0.70086865 | O7: =C7+H7+L7+M7+N7 -> 100
A8: Rural - farm q2 | B8: hhd-f2 | C8: =SUM(D8:G8) -> 54.410913 | D8: =SUM(Data!B7,Data!F7,Data!J7)/Data!$T7*100 -> 27.201931 | E8: =SUM(Data!C7,Data!G7,Data!K7)/Data!$T7*100 -> 24.776441 | F8: =SUM(Data!D7,Data!H7,Data!L7)/Data!$T7*100 -> 2.1454199 | G8: =SUM(Data!E7,Data!I7,Data!M7)/Data!$T7*100 -> 0.28712068 | H8: =SUM(I8:K8) -> 30.411018 | I8: =Data!N7/Data!$T7*100 -> 18.751089 | J8: =Data!O7/Data!$T7*100 -> 9.4339247 | K8: =Data!P7/Data!$T7*100 -> 2.2260035 | L8: =Data!Q7/Data!$T7*100 -> 9.903803 | M8: =Data!R7/Data!$T7*100 -> 4.4597797 | N8: =Data!S7/Data!$T7*100 -> 0.8144872 | O8: =C8+H8+L8+M8+N8 -> 100
A9: Rural - farm q3 | B9: hhd-f3 | C9: =SUM(D9:G9) -> 55.972671 | D9: =SUM(Data!B8,Data!F8,Data!J8)/Data!$T8*100 -> 26.758842 | E9: =SUM(Data!C8,Data!G8,Data!K8)/Data!$T8*100 -> 26.470814 | F9: =SUM(Data!D8,Data!H8,Data!L8)/Data!$T8*100 -> 2.5601213 | G9: =SUM(Data!E8,Data!I8,Data!M8)/Data!$T8*100 -> 0.18289328 | H9: =SUM(I9:K9) -> 32.577344 | I9: =Data!N8/Data!$T8*100 -> 20.150973 | J9: =Data!O8/Data!$T8*100 -> 10.138854 | K9: =Data!P8/Data!$T8*100 -> 2.2875176 | L9: =Data!Q8/Data!$T8*100 -> 6.5873301 | M9: =Data!R8/Data!$T8*100 -> 3.6789031 | N9: =Data!S8/Data!$T8*100 -> 1.1837519 | O9: =C9+H9+L9+M9+N9 -> 100
A10: Rural - farm q4 | B10: hhd-f4 | C10: =SUM(D10:G10) -> 48.550851 | D10: =SUM(Data!B9,Data!F9,Data!J9)/Data!$T9*100 -> 19.400744 | E10: =SUM(Data!C9,Data!G9,Data!K9)/Data!$T9*100 -> 22.131151 | F10: =SUM(Data!D9,Data!H9,Data!L9)/Data!$T9*100 -> 3.710564 | G10: =SUM(Data!E9,Data!I9,Data!M9)/Data!$T9*100 -> 3.3083914 | H10: =SUM(I10:K10) -> 24.824525 | I10: =Data!N9/Data!$T9*100 -> 15.173325 | J10: =Data!O9/Data!$T9*100 -> 7.5705421 | K10: =Data!P9/Data!$T9*100 -> 2.0806587 | L10: =Data!Q9/Data!$T9*100 -> 21.431803 | M10: =Data!R9/Data!$T9*100 -> 3.8923388 | N10: =Data!S9/Data!$T9*100 -> 1.3004822 | O10: =C10+H10+L10+M10+N10 -> 100
A11: Rural - farm q5 | B11: hhd-f5 | C11: =SUM(D11:G11) -> 47.719907 | D11: =SUM(Data!B10,Data!F10,Data!J10)/Data!$T10*100 -> 10.019478 | E11: =SUM(Data!C10,Data!G10,Data!K10)/Data!$T10*100 -> 18.052953 | F11: =SUM(Data!D10,Data!H10,Data!L10)/Data!$T10*100 -> 7.4900843 | G11: =SUM(Data!E10,Data!I10,Data!M10)/Data!$T10*100 -> 12.157392 | H11: =SUM(I11:K11) -> 15.677279 | I11: =Data!N10/Data!$T10*100 -> 9.4709973 | J11: =Data!O10/Data!$T10*100 -> 4.7279155 | K11: =Data!P10/Data!$T10*100 -> 1.4783665 | L11: =Data!Q10/Data!$T10*100 -> 30.201401 | M11: =Data!R10/Data!$T10*100 -> 3.1801094 | N11: =Data!S10/Data!$T10*100 -> 3.2213029 | O11: =C11+H11+L11+M11+N11 -> 100
A12: Rural - nonfarm q1 | B12: hhd-n1 | C12: =SUM(D12:G12) -> 91.663226 | D12: =SUM(Data!B11,Data!F11,Data!J11)/Data!$T11*100 -> 65.56142 | E12: =SUM(Data!C11,Data!G11,Data!K11)/Data!$T11*100 -> 26.101806 | F12: =SUM(Data!D11,Data!H11,Data!L11)/Data!$T11*100 -> 0 | G12: =SUM(Data!E11,Data!I11,Data!M11)/Data!$T11*100 -> 0 | H12: =SUM(I12:K12) -> 0 | I12: =Data!N11/Data!$T11*100 -> 0 | J12: =Data!O11/Data!$T11*100 -> 0 | K12: =Data!P11/Data!$T11*100 -> 0 | L12: =Data!Q11/Data!$T11*100 -> 0 | M12: =Data!R11/Data!$T11*100 -> 8.2203856 | N12: =Data!S11/Data!$T11*100 -> 0.11638858 | O12: =C12+H12+L12+M12+N12 -> 100
A13: Rural - nonfarm q2 | B13: hhd-n2 | C13: =SUM(D13:G13) -> 92.166166 | D13: =SUM(Data!B12,Data!F12,Data!J12)/Data!$T12*100 -> 37.620797 | E13: =SUM(Data!C12,Data!G12,Data!K12)/Data!$T12*100 -> 49.336318 | F13: =SUM(Data!D12,Data!H12,Data!L12)/Data!$T12*100 -> 5.2090515 | G13: =SUM(Data!E12,Data!I12,Data!M12)/Data!$T12*100 -> 0 | H13: =SUM(I13:K13) -> 0 | I13: =Data!N12/Data!$T12*100 -> 0 | J13: =Data!O12/Data!$T12*100 -> 0 | K13: =Data!P12/Data!$T12*100 -> 0 | L13: =Data!Q12/Data!$T12*100 -> 0 | M13: =Data!R12/Data!$T12*100 -> 7.8338336 | N13: =Data!S12/Data!$T12*100 -> 0 | O13: =C13+H13+L13+M13+N13 -> 100
A14: Rural - nonfarm q3 | B14: hhd-n3 | C14: =SUM(D14:G14) -> 92.48653 | D14: =SUM(Data!B13,Data!F13,Data!J13)/Data!$T13*100 -> 40.253118 | E14: =SUM(Data!C13,Data!G13,Data!K13)/Data!$T13*100 -> 41.411943 | F14: =SUM(Data!D13,Data!H13,Data!L13)/Data!$T13*100 -> 10.821468 | G14: =SUM(Data!E13,Data!I13,Data!M13)/Data!$T13*100 -> 0 | H14: =SUM(I14:K14) -> 0 | I14: =Data!N13/Data!$T13*100 -> 0 | J14: =Data!O13/Data!$T13*100 -> 0 | K14: =Data!P13/Data!$T13*100 -> 0 | L14: =Data!Q13/Data!$T13*100 -> 4.0844341 | M14: =Data!R13/Data!$T13*100 -> 2.7628062 | N14: =Data!S13/Data!$T13*100 -> 0.66623016 | O14: =C14+H14+L14+M14+N14 -> 100
A15: Rural - nonfarm q4 | B15: hhd-n4 | C15: =SUM(D15:G15) -> 95.027665 | D15: =SUM(Data!B14,Data!F14,Data!J14)/Data!$T14*100 -> 33.753361 | E15: =SUM(Data!C14,Data!G14,Data!K14)/Data!$T14*100 -> 37.258531 | F15: =SUM(Data!D14,Data!H14,Data!L14)/Data!$T14*100 -> 12.869057 | G15: =SUM(Data!E14,Data!I14,Data!M14)/Data!$T14*100 -> 11.146717 | H15: =SUM(I15:K15) -> 0 | I15: =Data!N14/Data!$T14*100 -> 0 | J15: =Data!O14/Data!$T14*100 -> 0 | K15: =Data!P14/Data!$T14*100 -> 0 | L15: =Data!Q14/Data!$T14*100 -> 2.7089447 | M15: =Data!R14/Data!$T14*100 -> 2.1670457 | N15: =Data!S14/Data!$T14*100 -> 0.09634414 | O15: =C15+H15+L15+M15+N15 -> 100
A16: Rural - nonfarm q5 | B16: hhd-n5 | C16: =SUM(D16:G16) -> 77.857933 | D16: =SUM(Data!B15,Data!F15,Data!J15)/Data!$T15*100 -> 5.5487297 | E16: =SUM(Data!C15,Data!G15,Data!K15)/Data!$T15*100 -> 16.231586 | F16: =SUM(Data!D15,Data!H15,Data!L15)/Data!$T15*100 -> 14.006689 | G16: =SUM(Data!E15,Data!I15,Data!M15)/Data!$T15*100 -> 42.070928 | H16: =SUM(I16:K16) -> 0 | I16: =Data!N15/Data!$T15*100 -> 0 | J16: =Data!O15/Data!$T15*100 -> 0 | K16: =Data!P15/Data!$T15*100 -> 0 | L16: =Data!Q15/Data!$T15*100 -> 19.128649 | M16: =Data!R15/Data!$T15*100 -> 2.4701437 | N16: =Data!S15/Data!$T15*100 -> 0.54327455 | O16: =C16+H16+L16+M16+N16 -> 100
A17: Urban - q1 | B17: hhd-u1 | C17: =SUM(D17:G17) -> 64.367566 | D17: =SUM(Data!B16,Data!F16,Data!J16)/Data!$T16*100 -> 38.470756 | E17: =SUM(Data!C16,Data!G16,Data!K16)/Data!$T16*100 -> 22.069341 | F17: =SUM(Data!D16,Data!H16,Data!L16)/Data!$T16*100 -> 1.6932897 | G17: =SUM(Data!E16,Data!I16,Data!M16)/Data!$T16*100 -> 2.1341806 | H17: =SUM(I17:K17) -> 24.352334 | I17: =Data!N16/Data!$T16*100 -> 14.829752 | J17: =Data!O16/Data!$T16*100 -> 7.4887427 | K17: =Data!P16/Data!$T16*100 -> 2.0338392 | L17: =Data!Q16/Data!$T16*100 -> 6.0649195 | M17: =Data!R16/Data!$T16*100 -> 4.7120547 | N17: =Data!S16/Data!$T16*100 -> 0.50312497 | O17: =C17+H17+L17+M17+N17 -> 100
A18: Urban - q2 | B18: hhd-u2 | C18: =SUM(D18:G18) -> 58.789764 | D18: =SUM(Data!B17,Data!F17,Data!J17)/Data!$T17*100 -> 29.722328 | E18: =SUM(Data!C17,Data!G17,Data!K17)/Data!$T17*100 -> 23.197151 | F18: =SUM(Data!D17,Data!H17,Data!L17)/Data!$T17*100 -> 2.5969494 | G18: =SUM(Data!E17,Data!I17,Data!M17)/Data!$T17*100 -> 3.2733349 | H18: =SUM(I18:K18) -> 17.67103 | I18: =Data!N17/Data!$T17*100 -> 10.592244 | J18: =Data!O17/Data!$T17*100 -> 5.3298266 | K18: =Data!P17/Data!$T17*100 -> 1.7489599 | L18: =Data!Q17/Data!$T17*100 -> 18.97809 | M18: =Data!R17/Data!$T17*100 -> 3.5815589 | N18: =Data!S17/Data!$T17*100 -> 0.97955685 | O18: =C18+H18+L18+M18+N18 -> 100
... A36: Q5 | B36: Q5 | C36: =SUM(D36:G36) -> 57.495014 | D36: =SUM(Data!B35,Data!F35,Data!J35)/Data!$T35*100 -> 4.2576532 | E36: =SUM(Data!C35,Data!G35,Data!K35)/Data!$T35*100 -> 7.7782404 | F36: =SUM(Data!D35,Data!H35,Data!L35)/Data!$T35*100 -> 7.4399077 | G36: =SUM(Data!E35,Data!I35,Data!M35)/Data!$T35*100 -> 38.019213 | H36: =SUM(I36:K36) -> 5.0821524 | I36: =Data!N35/Data!$T35*100 -> 2.9387846 | J36: =Data!O35/Data!$T35*100 -> 1.4689793 | K36: =Data!P35/Data!$T35*100 -> 0.67438848 | L36: =Data!Q35/Data!$T35*100 -> 30.476729 | M36: =Data!R35/Data!$T35*100 -> 3.4221214 | N36: =Data!S35/Data!$T35*100 -> 3.523983 | O36: =C36+H36+L36+M36+N36 -> 100
A40: Household expenses | C40: Consumption | G40: Other expenditures | M40: Per capita consumption | Q40: Ratios | S40: Inc-Exp differences
C41: Total | D41: Own | E41: Marketed | F41: Foods | G41: Government | H41: Taxes | I41: Saving | J41: Rest of world | K41: Total | O41: SAM | P41: Survey | Q41: SAM | R41: Survey | S41: Abs | T41: % exp
A42: Rural - farm q1 | B42: hhd-f1 | C42: =SUM(D42:E42) -> 95.925161 | D42: =Data!B41/Data!$I41*100 -> 32.216378 | E42: =Data!C41/Data!$I41*100 -> 63.708783 | F42: =Data!D41/Data!$I41*100 -> 16.908181 | G42: =Data!E41/Data!$I41*100 -> 0.089270819 | H42: =Data!F41/Data!$I41*100 -> 0.48571849 | I42: =Data!G41/Data!$I41*100 -> 3.1716854 | J42: =Data!H41/Data!$I41*100 -> 0.3281643 | K42: =Data!I41/Data!$I41*100 -> 100 | M42: Rural - farm q1 | N42: hhd-f1 | O42: =SUM(Data!B41:C41)/Data!C76*1000 -> 157.24714 | P42: =Data!B76/Data!C76 -> 136.77129 | Q42: =O42/O$66 -> 0.32518334 | R42: =P42/P$66 -> 0.36010269 | S42: =Data!T6-Data!I41 -> 0 | T42: =S42/Data!I41*100 -> 0
A43: Rural - farm q2 | B43: hhd-f2 | C43: =SUM(D43:E43) -> 96.074879 | D43: =Data!B42/Data!$I42*100 -> 33.930723 | E43: =Data!C42/Data!$I42*100 -> 62.144156 | F43: =Data!D42/Data!$I42*100 -> 22.120976 | G43: =Data!E42/Data!$I42*100 -> 0.22835801 | H43: =Data!F42/Data!$I42*100 -> 0.4857985 | I43: =Data!G42/Data!$I42*100 -> 2.9390821 | J43: =Data!H42/Data!$I42*100 -> 0.27188219 | K43: =Data!I42/Data!$I42*100 -> 100 | M43: Rural - farm q2 | N43: hhd-f2 | O43: =SUM(Data!B42:C42)/Data!C77*1000 -> 212.99531 | P43: =Data!B77/Data!C77 -> 206.40706 | Q43: =O43/O$66 -> 0.44046924 | R43: =P43/P$66 -> 0.54344546 | S43: =Data!T7-Data!I42 -> 0 | T43: =S43/Data!I42*100 -> 0
A44: Rural - farm q3 | B44: hhd-f3 | C44: =SUM(D44:E44) -> 95.644133 | D44: =Data!B43/Data!$I43*100 -> 32.424669 | E44: =Data!C43/Data!$I43*100 -> 63.219465 | F44: =Data!D43/Data!$I43*100 -> 23.264106 | G44: =Data!E43/Data!$I43*100 -> 0.29983487 | H44: =Data!F43/Data!$I43*100 -> 0.57561858 | I44: =Data!G43/Data!$I43*100 -> 3.084819 | J44: =Data!H43/Data!$I43*100 -> 0.39559412 | K44: =Data!I43/Data!$I43*100 -> 100 | M44: Rural - farm q3 | N44: hhd-f3 | O44: =SUM(Data!B43:C43)/Data!C78*1000 -> 294.25262 | P44: =Data!B78/Data!C78 -> 272.74963 | Q44: =O44/O$66 -> 0.60850744 | R44: =P44/P$66 -> 0.71811762 | S44: =Data!T8-Data!I43 -> 0 | T44: =S44/Data!I43*100 -> 0
A45: Rural - farm q4 | B45: hhd-f4 | C45: =SUM(D45:E45) -> 93.689008 | D45: =Data!B44/Data!$I44*100 -> 29.246315 | E45: =Data!C44/Data!$I44*100 -> 64.442693 | F45: =Data!D44/Data!$I44*100 -> 21.893141 | G45: =Data!E44/Data!$I44*100 -> 0.47328631 | H45: =Data!F44/Data!$I44*100 -> 1.2495273 | I45: =Data!G44/Data!$I44*100 -> 4.1988861 | J45: =Data!H44/Data!$I44*100 -> 0.38929188 | K45: =Data!I44/Data!$I44*100 -> 100 | M45: Rural - farm q4 | N45: hhd-f4 | O45: =SUM(Data!B44:C44)/Data!C79*1000 -> 434.01475 | P45: =Data!B79/Data!C79 -> 382.33112 | Q45: =O45/O$66 -> 0.8975322 | R45: =P45/P$66 -> 1.0066328 | S45: =Data!T9-Data!I44 -> 0 | T45: =S45/Data!I44*100 -> 0
A46: Rural - farm q5 | B46: hhd-f5 | C46: =SUM(D46:E46) -> 89.502337 | D46: =Data!B45/Data!$I45*100 -> 19.447036 | E46: =Data!C45/Data!$I45*100 -> 70.055301 | F46: =Data!D45/Data!$I45*100 -> 13.301622 | G46: =Data!E45/Data!$I45*100 -> 2.0156933 | H46: =Data!F45/Data!$I45*100 -> 2.9714081 | I46: =Data!G45/Data!$I45*100 -> 4.6893253 | J46: =Data!H45/Data!$I45*100 -> 0.82123604 | K46: =Data!I45/Data!$I45*100 -> 100 | M46: Rural - farm q5 | N46: hhd-f5 | O46: =SUM(Data!B45:C45)/Data!C80*1000 -> 869.30017 | P46: =Data!B80/Data!C80 -> 676.42395 | Q46: =O46/O$66 -> 1.7976921 | R46: =P46/P$66 -> 1.7809445 | S46: =Data!T10-Data!I45 -> 0 | T46: =S46/Data!I45*100 -> 0
A47: Rural - nonfarm q1 | B47: hhd-n1 | C47: =SUM(D47:E47) -> 99.152965 | D47: =Data!B46/Data!$I46*100 -> 16.485923 | E47: =Data!C46/Data!$I46*100 -> 82.667041 | F47: =Data!D46/Data!$I46*100 -> 0 | G47: =Data!E46/Data!$I46*100 -> 0 | H47: =Data!F46/Data!$I46*100 -> 0 | I47: =Data!G46/Data!$I46*100 -> 0.35379699 | J47: =Data!H46/Data!$I46*100 -> 0.49323825 | K47: =Data!I46/Data!$I46*100 -> 100 | M47: Rural - nonfarm q1 | N47: hhd-n1 | O47: =SUM(Data!B46:C46)/Data!C81*1000 -> 93.748849 | P47: =Data!B81/Data!C81 -> 111.40167 | Q47: =O47/O$66 -> 0.19387039 | R47: =P47/P$66 -> 0.29330746 | S47: =Data!T11-Data!I46 -> 0 | T47: =S47/Data!I46*100 -> 0
A48: Rural - nonfarm q2 | B48: hhd-n2 | C48: =SUM(D48:E48) -> 95.131436 | D48: =Data!B47/Data!$I47*100 -> 8.7932868 | E48: =Data!C47/Data!$I47*100 -> 86.33815 | F48: =Data!D47/Data!$I47*100 -> 0.074513573 | G48: =Data!E47/Data!$I47*100 -> 0.74400552 | H48: =Data!F47/Data!$I47*100 -> 2.7135841 | I48: =Data!G47/Data!$I47*100 -> 1.4109739 | J48: =Data!H47/Data!$I47*100 -> 0 | K48: =Data!I47/Data!$I47*100 -> 100 | M48: Rural - nonfarm q2 | N48: hhd-n2 | O48: =SUM(Data!B47:C47)/Data!C82*1000 -> 124.95225 | P48: =Data!B82/Data!C82 -> 117.6019 | Q48: =O48/O$66 -> 0.25839829 | R48: =P48/P$66 -> 0.30963193 | S48: =Data!T12-Data!I47 -> 0 | T48: =S48/Data!I47*100 -> 0
