Workbook

Sheet FinUSE
A1: Final Coefficients
A3: GDP/GO | C3: =C$20 -> amaiz | D3: =D$20 -> asorg | E3: =E$20 -> arice | F3: =F$20 -> awhea | G3: =G$20 -> aocer | H3: =H$20 -> apuls | I3: =I$20 -> agnut | J3: =J$20 -> aoils | ... DO3: =DO$20 -> aosrv
B4: Orig. | C4: =#REF! -> #REF! | D4: =#REF! -> #REF! | E4: =#REF! -> #REF! | F4: =#REF! -> #REF! | G4: =#REF! -> #REF! | H4: =#REF! -> #REF! | I4: =#REF! -> #REF! | J4: =#REF! -> #REF! | ... DO4: =#REF! -> #REF!
B5: Alt 1
B6: Alt 2
B7: Final | C7: =C4 -> #REF! | D7: =D4 -> #REF! | E7: =E4 -> #REF! | F7: =F4 -> #REF! | G7: =G4 -> #REF! | H7: =H4 -> #REF! | I7: =I4 -> #REF! | J7: =J4 -> #REF! | ... DO7: =DO4 -> #REF!
A10: FAC SHR | C10: =C$20 -> amaiz | D10: =D$20 -> asorg | E10: =E$20 -> arice | F10: =F$20 -> awhea | G10: =G$20 -> aocer | H10: =H$20 -> apuls | I10: =I$20 -> agnut | J10: =J$20 -> aoils | ... DO10: =DO$20 -> aosrv
B11: flab | C11: =#REF! -> #REF! | D11: =#REF! -> #REF! | E11: =#REF! -> #REF! | F11: =#REF! -> #REF! | G11: =#REF! -> #REF! | H11: =#REF! -> #REF! | I11: =#REF! -> #REF! | J11: =#REF! -> #REF! | ... DO11: =#REF! -> #REF!
B12: flnd | C12: =#REF! -> #REF! | D12: =#REF! -> #REF! | E12: =#REF! -> #REF! | F12: =#REF! -> #REF! | G12: =#REF! -> #REF! | H12: =#REF! -> #REF! | I12: =#REF! -> #REF! | J12: =#REF! -> #REF! | ... DO12: =#REF! -> #REF!
B13: fcap | C13: =#REF! -> #REF! | D13: =#REF! -> #REF! | E13: =#REF! -> #REF! | F13: =#REF! -> #REF! | G13: =#REF! -> #REF! | H13: =#REF! -> #REF! | I13: =#REF! -> #REF! | J13: =#REF! -> #REF! | ... DO13: =#REF! -> #REF!
B14: flab | C14: =C11 -> #REF! | D14: =D11 -> #REF! | E14: =E11 -> #REF! | F14: =F11 -> #REF! | G14: =G11 -> #REF! | H14: =H11 -> #REF! | I14: =I11 -> #REF! | J14: =J11 -> #REF! | ... DO14: =DO11 -> #REF!
B15: flnd | C15: =C12 -> #REF! | D15: =D12 -> #REF! | E15: =E12 -> #REF! | F15: =F12 -> #REF! | G15: =G12 -> #REF! | H15: =H12 -> #REF! | I15: =I12 -> #REF! | J15: =J12 -> #REF! | ... DO15: =DO12 -> #REF!
B16: fcap | C16: =1-SUM(C14:C15) -> #REF! | D16: =1-SUM(D14:D15) -> #REF! | E16: =1-SUM(E14:E15) -> #REF! | F16: =1-SUM(F14:F15) -> #REF! | G16: =1-SUM(G14:G15) -> #REF! | H16: =1-SUM(H14:H15) -> #REF! | I16: =1-SUM(I14:I15) -> #REF! | J16: =1-SUM(J14:J15) -> #REF! | ... DO16: =1-SUM(DO14:DO15) -> #REF!
C19: =SUM(C21:C109) -> 0 | D19: =SUM(D21:D109) -> 0 | E19: =SUM(E21:E109) -> 0 | F19: =SUM(F21:F109) -> 0 | G19: =SUM(G21:G109) -> 0 | H19: =SUM(H21:H109) -> 0 | I19: =SUM(I21:I109) -> 0 | J19: =SUM(J21:J109) -> 0 | ... CJ19: =SUM(CJ21:CJ109) -> 0
C20: amaiz | D20: asorg | E20: arice | F20: awhea | G20: aocer | H20: apuls | I20: agnut | J20: aoils | K20: acass | L20: aipot | M20: aspot | N20: aroot | O20: aleaf | P20: avege | Q20: asugr | R20: atoba | S20: acott | T20: anuts | U20: abana | V20: afrui | W20: ateal | X20: acoff | Y20: acoco | Z20: aflwr | AA20: arubb | AB20: aocrp | AC20: acatt | AD20: amilk | AE20: apoul | AF20: aeggs | AG20: asmlr | AH20: aoliv | AI20: afore | AJ20: aaqua | AK20: afish | AL20: acoal | AM20: acoil | AN20: angas | AO20: amore | AP20: aomin | AQ20: ameat | AR20: afsea | AS20: adair | AT20: afveg | AU20: afoil | AV20: ammill | AW20: asmll | AX20: armll | AY20: awmll | AZ20: agmll | BA20: asref | BB20: apcof | BC20: aptea | BD20: abake | BE20: afood | BF20: afeed | BG20: aalco | BH20: abeve | BI20: aptob | BJ20: ayarn | BK20: atext | BL20: aclth | BM20: aleat | BN20: awood | BO20: apapr | BP20: aprnt | BQ20: apetr | BR20: afert | BS20: aphar | BT20: aprub | BU20: achem | BV20: anmet | BW20: aceme | BX20: aclay | BY20: ametl | BZ20: amach | CA20: aequi | CB20: avehi | CC20: afurn | CD20: aoman | CE20: arepr | CF20: aelec | CG20: awatr | CH20: awast | CI20: acons | CJ20: acont | CK20: avehr | CL20: aveht | CM20: atrdw | CN20: atrdr | CO20: atrnl | CP20: atrna | CQ20: atrns | CR20: apost | CS20: ahotl | CT20: arest | CU20: apubl | CV20: acomm | CW20: ainfo | CX20: abank | CY20: ainsu | CZ20: aofsv | DA20: arent | DB20: areal | DC20: alegl | DD20: aenga | DE20: aprod | DF20: atrvl | DG20: aobsv | DH20: apadm | DI20: aeduc | DJ20: aheal | DK20: asocw | DL20: acult | DM20: aarts | DN20: adsrv | DO20: aosrv
B21: cmaiz
B22: csorg
B23: crice
B24: cwhea
B25: cocer
B26: cpuls
B27: cgnut
B28: coils
B29: ccass
B30: cipot
B31: cspot
B32: croot
... B141: atax

Sheet oSUP
A1: SUT Part D: Make matrix
A2: Billions of FRW
E4: Activities
E5: Cereals | F5: Roots and Tubers | G5: Vegetables | H5: Bananas and fruit | I5: Oil seeds n.e.c. and oleaginous fruit | J5: Coffee | K5: Tea (unprocessed green leaf) | L5: Other agricultural products | M5: Livestock | N5: Livestock and hunting products | O5: Forestry products | P5: Fishery products | Q5: Natural gas | R5: Metal ores | S5: Quarry & other mining products | T5: Meat and meat products | U5: Prepared and preserved fish | V5: Prepared and preserved vegetables | W5: Animal and vegetable oils and fats | X5: Dairy products | Y5: Grain mill products | Z5: Bakery products | AA5: Animal feed & other by-products | AB5: Other manufactured food products | AC5: Alcoholic drinks | AD5: Soft drinks | AE5: Tobacco products | AF5: Textiles, clothing & leather products | AG5: Wood, paper and related products | AH5: Printing and reproduction of recorded media | AI5: Coke and refined petroleum products | AJ5: Chemicals and chemical products | AK5: Pharmaceutical products | AL5: Rubber and plastics products | AM5: Non-metallic mineral products n.e.c. | AN5: Manufacture of cement, lime and plaster | AO5: Manufacture of clay building materials | AP5: Metals & metal products, except machinery and equipment | AQ5: Machinery and equipment (except transport) | AR5: Transport equipment | AS5: Furniture | AT5: Other manufacturing | AU5: Repair and installation of machinery and equipment | AV5: Electricity, gas, steam and air conditioning supply | AW5: Water collection, treatment and supply: sewrage | AX5: Waste collection and management | AY5: Construction (modern) | AZ5: Construction (traditional) | BA5: Maintenance and repair of motor vehicles | BB5: Wholesale and retail trade of motor vehicles and motorcycles | BC5: Wholesale trade, except of motor vehicles and motorcycles | BD5: Retail trade, except of motor vehicles and motorcycles | BE5: Land transport | BF5: Air transport | BG5: Services related to transport | BH5: Postal and courier activities | BI5: Hotels & restaurants | BJ5: Publishing, video making, programming & broadcasting activities | BK5: Telecommunication | BL5: Information technology services | BM5: Monetary institutions | BN5: Insurance, reinsurance and pension funding, except compulsory social security | BO5: Other financial services | BP5: Rental value of dwellings | BQ5: Other real estate activities | BR5: Legal, accounting management & head office activities | BS5: Architectural and engineering activities | BT5: Other professional, scientific and technical activities | BU5: Travel agents and tour operators | BV5: Other administrative and support service activities | BW5: Public administration and defence; compulsory social security | BX5: Education | BY5: Human health activities | BZ5: Social work activities | CA5: Libraries, archives, museums and other cultural activities | CB5: Other arts, entertainment and recreation | CC5: Other service activities | CD5: Domestic services
E6: A11 | F6: A12 | G6: A13 | H6: A14 | I6: A15 | J6: A21 | K6: A22 | L6: A29 | M6: A31 | N6: A32 | O6: A40 | P6: A50 | Q6: B01 | R6: B03 | S6: B09 | T6: C11 | U6: C12 | V6: C13 | W6: C14 | X6: C15 | Y6: C16 | Z6: C17 | AA6: C18 | AB6: C19 | AC6: C21 | AD6: C22 | AE6: C23 | AF6: C30 | AG6: C41 | AH6: C42 | AI6: C51 | AJ6: C52 | AK6: C53 | AL6: C54 | AM6: C61 | AN6: C62 | AO6: C63 | AP6: C72 | AQ6: C74 | AR6: C76 | AS6: C81 | AT6: C82 | AU6: C83 | AV6: D00 | AW6: E01 | AX6: E02 | AY6: F01 | AZ6: F02 | BA6: G10 | BB6: G21 | BC6: G22 | BD6: G23 | BE6: H10 | BF6: H20 | BG6: H31 | BH6: H32 | BI6: I00 | BJ6: J10 | BK6: J20 | BL6: J30 | BM6: K01 | BN6: K02 | BO6: K03 | BP6: L01 | BQ6: L09 | BR6: M01 | BS6: M02 | BT6: M03 | BU6: N01 | BV6: N09 | BW6: O00 | BX6: P00 | BY6: Q01 | BZ6: Q02 | CA6: R01 | CB6: R09 | CC6: S00 | CD6: T00
D7: =SUM(E7:CD7) -> 11646.996 | E7: =SUM(E8:E86) -> 206.67601 | F7: =SUM(F8:F86) -> 468.14634 | G7: =SUM(G8:G86) -> 396.78988 | H7: =SUM(H8:H86) -> 283.59608 | I7: =SUM(I8:I86) -> 15.001884 | J7: =SUM(J8:J86) -> 77.156236 | K7: =SUM(K8:K86) -> 24.490147 | L7: =SUM(L8:L86) -> 48.183435 | ... CD7: =SUM(CD8:CD86) -> 25.436762
B8: Cereals | C8: A11 | D8: =SUM(E8:CD8) -> 206.67601 | E8: 206.67601 | F8: 0 | G8: 0 | H8: 0 | I8: 0 | J8: 0 | K8: 0 | L8: 0 | M8: 0 | N8: 0 | O8: 0 | P8: 0 | Q8: 0 | R8: 0 | S8: 0 | T8: 0 | U8: 0 | V8: 0 | W8: 0 | X8: 0 | Y8: 0 | Z8: 0 | AA8: 0 | AB8: 0 | AC8: 0 | AD8: 0 | AE8: 0 | AF8: 0 | AG8: 0 | AH8: 0 | AI8: 0 | AJ8: 0 | AK8: 0 | AL8: 0 | AM8: 0 | AN8: 0 | AO8: 0 | AP8: 0 | AQ8: 0 | AR8: 0 | AS8: 0 | AT8: 0 | AU8: 0 | AV8: 0 | AW8: 0 | AX8: 0 | AY8: 0 | AZ8: 0 | BA8: 0 | BB8: 0 | BC8: 0 | BD8: 0 | BE8: 0 | BF8: 0 | BG8: 0 | BH8: 0 | BI8: 0 | BJ8: 0 | BK8: 0 | BL8: 0 | BM8: 0 | BN8: 0 | BO8: 0 | BP8: 0 | BQ8: 0 | BR8: 0 | BS8: 0 | BT8: 0 | BU8: 0 | BV8: 0 | BW8: 0 | BX8: 0 | BY8: 0 | BZ8: 0 | CA8: 0 | CB8: 0 | CC8: 0 | CD8: 0
B9: Roots and Tubers | C9: A12 | D9: =SUM(E9:CD9) -> 468.14634 | E9: 0 | F9: 468.14634 | G9: 0 | H9: 0 | I9: 0 | J9: 0 | K9: 0 | L9: 0 | M9: 0 | N9: 0 | O9: 0 | P9: 0 | Q9: 0 | R9: 0 | S9: 0 | T9: 0 | U9: 0 | V9: 0 | W9: 0 | X9: 0 | Y9: 0 | Z9: 0 | AA9: 0 | AB9: 0 | AC9: 0 | AD9: 0 | AE9: 0 | AF9: 0 | AG9: 0 | AH9: 0 | AI9: 0 | AJ9: 0 | AK9: 0 | AL9: 0 | AM9: 0 | AN9: 0 | AO9: 0 | AP9: 0 | AQ9: 0 | AR9: 0 | AS9: 0 | AT9: 0 | AU9: 0 | AV9: 0 | AW9: 0 | AX9: 0 | AY9: 0 | AZ9: 0 | BA9: 0 | BB9: 0 | BC9: 0 | BD9: 0 | BE9: 0 | BF9: 0 | BG9: 0 | BH9: 0 | BI9: 0 | BJ9: 0 | BK9: 0 | BL9: 0 | BM9: 0 | BN9: 0 | BO9: 0 | BP9: 0 | BQ9: 0 | BR9: 0 | BS9: 0 | BT9: 0 | BU9: 0 | BV9: 0 | BW9: 0 | BX9: 0 | BY9: 0 | BZ9: 0 | CA9: 0 | CB9: 0 | CC9: 0 | CD9: 0
B10: Vegetables | C10: A13 | D10: =SUM(E10:CD10) -> 396.78988 | E10: 0 | F10: 0 | G10: 396.78988 | H10: 0 | I10: 0 | J10: 0 | K10: 0 | L10: 0 | M10: 0 | N10: 0 | O10: 0 | P10: 0 | Q10: 0 | R10: 0 | S10: 0 | T10: 0 | U10: 0 | V10: 0 | W10: 0 | X10: 0 | Y10: 0 | Z10: 0 | AA10: 0 | AB10: 0 | AC10: 0 | AD10: 0 | AE10: 0 | AF10: 0 | AG10: 0 | AH10: 0 | AI10: 0 | AJ10: 0 | AK10: 0 | AL10: 0 | AM10: 0 | AN10: 0 | AO10: 0 | AP10: 0 | AQ10: 0 | AR10: 0 | AS10: 0 | AT10: 0 | AU10: 0 | AV10: 0 | AW10: 0 | AX10: 0 | AY10: 0 | AZ10: 0 | BA10: 0 | BB10: 0 | BC10: 0 | BD10: 0 | BE10: 0 | BF10: 0 | BG10: 0 | BH10: 0 | BI10: 0 | BJ10: 0 | BK10: 0 | BL10: 0 | BM10: 0 | BN10: 0 | BO10: 0 | BP10: 0 | BQ10: 0 | BR10: 0 | BS10: 0 | BT10: 0 | BU10: 0 | BV10: 0 | BW10: 0 | BX10: 0 | BY10: 0 | BZ10: 0 | CA10: 0 | CB10: 0 | CC10: 0 | CD10: 0
B11: Bananas and fruit | C11: A14 | D11: =SUM(E11:CD11) -> 283.59608 | E11: 0 | F11: 0 | G11: 0 | H11: 283.59608 | I11: 0 | J11: 0 | K11: 0 | L11: 0 | M11: 0 | N11: 0 | O11: 0 | P11: 0 | Q11: 0 | R11: 0 | S11: 0 | T11: 0 | U11: 0 | V11: 0 | W11: 0 | X11: 0 | Y11: 0 | Z11: 0 | AA11: 0 | AB11: 0 | AC11: 0 | AD11: 0 | AE11: 0 | AF11: 0 | AG11: 0 | AH11: 0 | AI11: 0 | AJ11: 0 | AK11: 0 | AL11: 0 | AM11: 0 | AN11: 0 | AO11: 0 | AP11: 0 | AQ11: 0 | AR11: 0 | AS11: 0 | AT11: 0 | AU11: 0 | AV11: 0 | AW11: 0 | AX11: 0 | AY11: 0 | AZ11: 0 | BA11: 0 | BB11: 0 | BC11: 0 | BD11: 0 | BE11: 0 | BF11: 0 | BG11: 0 | BH11: 0 | BI11: 0 | BJ11: 0 | BK11: 0 | BL11: 0 | BM11: 0 | BN11: 0 | BO11: 0 | BP11: 0 | BQ11: 0 | BR11: 0 | BS11: 0 | BT11: 0 | BU11: 0 | BV11: 0 | BW11: 0 | BX11: 0 | BY11: 0 | BZ11: 0 | CA11: 0 | CB11: 0 | CC11: 0 | CD11: 0
B12: Oil seeds n.e.c. and oleaginous fruit | C12: A15 | D12: =SUM(E12:CD12) -> 15.001884 | E12: 0 | F12: 0 | G12: 0 | H12: 0 | I12: 15.001884 | J12: 0 | K12: 0 | L12: 0 | M12: 0 | N12: 0 | O12: 0 | P12: 0 | Q12: 0 | R12: 0 | S12: 0 | T12: 0 | U12: 0 | V12: 0 | W12: 0 | X12: 0 | Y12: 0 | Z12: 0 | AA12: 0 | AB12: 0 | AC12: 0 | AD12: 0 | AE12: 0 | AF12: 0 | AG12: 0 | AH12: 0 | AI12: 0 | AJ12: 0 | AK12: 0 | AL12: 0 | AM12: 0 | AN12: 0 | AO12: 0 | AP12: 0 | AQ12: 0 | AR12: 0 | AS12: 0 | AT12: 0 | AU12: 0 | AV12: 0 | AW12: 0 | AX12: 0 | AY12: 0 | AZ12: 0 | BA12: 0 | BB12: 0 | BC12: 0 | BD12: 0 | BE12: 0 | BF12: 0 | BG12: 0 | BH12: 0 | BI12: 0 | BJ12: 0 | BK12: 0 | BL12: 0 | BM12: 0 | BN12: 0 | BO12: 0 | BP12: 0 | BQ12: 0 | BR12: 0 | BS12: 0 | BT12: 0 | BU12: 0 | BV12: 0 | BW12: 0 | BX12: 0 | BY12: 0 | BZ12: 0 | CA12: 0 | CB12: 0 | CC12: 0 | CD12: 0
B13: Coffee | C13: A21 | D13: =SUM(E13:CD13) -> 77.156236 | E13: 0 | F13: 0 | G13: 0 | H13: 0 | I13: 0 | J13: 77.156236 | K13: 0 | L13: 0 | M13: 0 | N13: 0 | O13: 0 | P13: 0 | Q13: 0 | R13: 0 | S13: 0 | T13: 0 | U13: 0 | V13: 0 | W13: 0 | X13: 0 | Y13: 0 | Z13: 0 | AA13: 0 | AB13: 0 | AC13: 0 | AD13: 0 | AE13: 0 | AF13: 0 | AG13: 0 | AH13: 0 | AI13: 0 | AJ13: 0 | AK13: 0 | AL13: 0 | AM13: 0 | AN13: 0 | AO13: 0 | AP13: 0 | AQ13: 0 | AR13: 0 | AS13: 0 | AT13: 0 | AU13: 0 | AV13: 0 | AW13: 0 | AX13: 0 | AY13: 0 | AZ13: 0 | BA13: 0 | BB13: 0 | BC13: 0 | BD13: 0 | BE13: 0 | BF13: 0 | BG13: 0 | BH13: 0 | BI13: 0 | BJ13: 0 | BK13: 0 | BL13: 0 | BM13: 0 | BN13: 0 | BO13: 0 | BP13: 0 | BQ13: 0 | BR13: 0 | BS13: 0 | BT13: 0 | BU13: 0 | BV13: 0 | BW13: 0 | BX13: 0 | BY13: 0 | BZ13: 0 | CA13: 0 | CB13: 0 | CC13: 0 | CD13: 0
B14: Tea (unprocessed green leaf) | C14: A22 | D14: =SUM(E14:CD14) -> 24.490147 | E14: 0 | F14: 0 | G14: 0 | H14: 0 | I14: 0 | J14: 0 | K14: 24.490147 | L14: 0 | M14: 0 | N14: 0 | O14: 0 | P14: 0 | Q14: 0 | R14: 0 | S14: 0 | T14: 0 | U14: 0 | V14: 0 | W14: 0 | X14: 0 | Y14: 0 | Z14: 0 | AA14: 0 | AB14: 0 | AC14: 0 | AD14: 0 | AE14: 0 | AF14: 0 | AG14: 0 | AH14: 0 | AI14: 0 | AJ14: 0 | AK14: 0 | AL14: 0 | AM14: 0 | AN14: 0 | AO14: 0 | AP14: 0 | AQ14: 0 | AR14: 0 | AS14: 0 | AT14: 0 | AU14: 0 | AV14: 0 | AW14: 0 | AX14: 0 | AY14: 0 | AZ14: 0 | BA14: 0 | BB14: 0 | BC14: 0 | BD14: 0 | BE14: 0 | BF14: 0 | BG14: 0 | BH14: 0 | BI14: 0 | BJ14: 0 | BK14: 0 | BL14: 0 | BM14: 0 | BN14: 0 | BO14: 0 | BP14: 0 | BQ14: 0 | BR14: 0 | BS14: 0 | BT14: 0 | BU14: 0 | BV14: 0 | BW14: 0 | BX14: 0 | BY14: 0 | BZ14: 0 | CA14: 0 | CB14: 0 | CC14: 0 | CD14: 0
B15: Other agricultural products | C15: A29 | D15: =SUM(E15:CD15) -> 48.183435 | E15: 0 | F15: 0 | G15: 0 | H15: 0 | I15: 0 | J15: 0 | K15: 0 | L15: 48.183435 | M15: 0 | N15: 0 | O15: 0 | P15: 0 | Q15: 0 | R15: 0 | S15: 0 | T15: 0 | U15: 0 | V15: 0 | W15: 0 | X15: 0 | Y15: 0 | Z15: 0 | AA15: 0 | AB15: 0 | AC15: 0 | AD15: 0 | AE15: 0 | AF15: 0 | AG15: 0 | AH15: 0 | AI15: 0 | AJ15: 0 | AK15: 0 | AL15: 0 | AM15: 0 | AN15: 0 | AO15: 0 | AP15: 0 | AQ15: 0 | AR15: 0 | AS15: 0 | AT15: 0 | AU15: 0 | AV15: 0 | AW15: 0 | AX15: 0 | AY15: 0 | AZ15: 0 | BA15: 0 | BB15: 0 | BC15: 0 | BD15: 0 | BE15: 0 | BF15: 0 | BG15: 0 | BH15: 0 | BI15: 0 | BJ15: 0 | BK15: 0 | BL15: 0 | BM15: 0 | BN15: 0 | BO15: 0 | BP15: 0 | BQ15: 0 | BR15: 0 | BS15: 0 | BT15: 0 | BU15: 0 | BV15: 0 | BW15: 0 | BX15: 0 | BY15: 0 | BZ15: 0 | CA15: 0 | CB15: 0 | CC15: 0 | CD15: 0
B16: Livestock | C16: A31 | D16: =SUM(E16:CD16) -> 141.46606 | E16: 0 | F16: 0 | G16: 0 | H16: 0 | I16: 0 | J16: 0 | K16: 0 | L16: 0 | M16: 141.46606 | N16: 0 | O16: 0 | P16: 0 | Q16: 0 | R16: 0 | S16: 0 | T16: 0 | U16: 0 | V16: 0 | W16: 0 | X16: 0 | Y16: 0 | Z16: 0 | AA16: 0 | AB16: 0 | AC16: 0 | AD16: 0 | AE16: 0 | AF16: 0 | AG16: 0 | AH16: 0 | AI16: 0 | AJ16: 0 | AK16: 0 | AL16: 0 | AM16: 0 | AN16: 0 | AO16: 0 | AP16: 0 | AQ16: 0 | AR16: 0 | AS16: 0 | AT16: 0 | AU16: 0 | AV16: 0 | AW16: 0 | AX16: 0 | AY16: 0 | AZ16: 0 | BA16: 0 | BB16: 0 | BC16: 0 | BD16: 0 | BE16: 0 | BF16: 0 | BG16: 0 | BH16: 0 | BI16: 0 | BJ16: 0 | BK16: 0 | BL16: 0 | BM16: 0 | BN16: 0 | BO16: 0 | BP16: 0 | BQ16: 0 | BR16: 0 | BS16: 0 | BT16: 0 | BU16: 0 | BV16: 0 | BW16: 0 | BX16: 0 | BY16: 0 | BZ16: 0 | CA16: 0 | CB16: 0 | CC16: 0 | CD16: 0
B17: Livestock and hunting products | C17: A32 | D17: =SUM(E17:CD17) -> 57.506207 | E17: 0 | F17: 0 | G17: 0 | H17: 0 | I17: 0 | J17: 0 | K17: 0 | L17: 0 | M17: 0 | N17: 57.506207 | O17: 0 | P17: 0 | Q17: 0 | R17: 0 | S17: 0 | T17: 0 | U17: 0 | V17: 0 | W17: 0 | X17: 0 | Y17: 0 | Z17: 0 | AA17: 0 | AB17: 0 | AC17: 0 | AD17: 0 | AE17: 0 | AF17: 0 | AG17: 0 | AH17: 0 | AI17: 0 | AJ17: 0 | AK17: 0 | AL17: 0 | AM17: 0 | AN17: 0 | AO17: 0 | AP17: 0 | AQ17: 0 | AR17: 0 | AS17: 0 | AT17: 0 | AU17: 0 | AV17: 0 | AW17: 0 | AX17: 0 | AY17: 0 | AZ17: 0 | BA17: 0 | BB17: 0 | BC17: 0 | BD17: 0 | BE17: 0 | BF17: 0 | BG17: 0 | BH17: 0 | BI17: 0 | BJ17: 0 | BK17: 0 | BL17: 0 | BM17: 0 | BN17: 0 | BO17: 0 | BP17: 0 | BQ17: 0 | BR17: 0 | BS17: 0 | BT17: 0 | BU17: 0 | BV17: 0 | BW17: 0 | BX17: 0 | BY17: 0 | BZ17: 0 | CA17: 0 | CB17: 0 | CC17: 0 | CD17: 0
B18: Forestry products | C18: A40 | D18: =SUM(E18:CD18) -> 379.13228 | E18: 0 | F18: 0 | G18: 0 | H18: 0 | I18: 0 | J18: 0 | K18: 0 | L18: 0 | M18: 0 | N18: 0 | O18: 379.13228 | P18: 0 | Q18: 0 | R18: 0 | S18: 0 | T18: 0 | U18: 0 | V18: 0 | W18: 0 | X18: 0 | Y18: 0 | Z18: 0 | AA18: 0 | AB18: 0 | AC18: 0 | AD18: 0 | AE18: 0 | AF18: 0 | AG18: 0 | AH18: 0 | AI18: 0 | AJ18: 0 | AK18: 0 | AL18: 0 | AM18: 0 | AN18: 0 | AO18: 0 | AP18: 0 | AQ18: 0 | AR18: 0 | AS18: 0 | AT18: 0 | AU18: 0 | AV18: 0 | AW18: 0 | AX18: 0 | AY18: 0 | AZ18: 0 | BA18: 0 | BB18: 0 | BC18: 0 | BD18: 0 | BE18: 0 | BF18: 0 | BG18: 0 | BH18: 0 | BI18: 0 | BJ18: 0 | BK18: 0 | BL18: 0 | BM18: 0 | BN18: 0 | BO18: 0 | BP18: 0 | BQ18: 0 | BR18: 0 | BS18: 0 | BT18: 0 | BU18: 0 | BV18: 0 | BW18: 0 | BX18: 0 | BY18: 0 | BZ18: 0 | CA18: 0 | CB18: 0 | CC18: 0 | CD18: 0
B19: Fishery products | C19: A50 | D19: =SUM(E19:CD19) -> 29.763623 | E19: 0 | F19: 0 | G19: 0 | H19: 0 | I19: 0 | J19: 0 | K19: 0 | L19: 0 | M19: 0 | N19: 0 | O19: 0 | P19: 29.763623 | Q19: 0 | R19: 0 | S19: 0 | T19: 0 | U19: 0 | V19: 0 | W19: 0 | X19: 0 | Y19: 0 | Z19: 0 | AA19: 0 | AB19: 0 | AC19: 0 | AD19: 0 | AE19: 0 | AF19: 0 | AG19: 0 | AH19: 0 | AI19: 0 | AJ19: 0 | AK19: 0 | AL19: 0 | AM19: 0 | AN19: 0 | AO19: 0 | AP19: 0 | AQ19: 0 | AR19: 0 | AS19: 0 | AT19: 0 | AU19: 0 | AV19: 0 | AW19: 0 | AX19: 0 | AY19: 0 | AZ19: 0 | BA19: 0 | BB19: 0 | BC19: 0 | BD19: 0 | BE19: 0 | BF19: 0 | BG19: 0 | BH19: 0 | BI19: 0 | BJ19: 0 | BK19: 0 | BL19: 0 | BM19: 0 | BN19: 0 | BO19: 0 | BP19: 0 | BQ19: 0 | BR19: 0 | BS19: 0 | BT19: 0 | BU19: 0 | BV19: 0 | BW19: 0 | BX19: 0 | BY19: 0 | BZ19: 0 | CA19: 0 | CB19: 0 | CC19: 0 | CD19: 0
... B86: Travel debits & credits | C86: V00 | D86: =SUM(E86:CD86) -> 0 | E86: 0 | F86: 0 | G86: 0 | H86: 0 | I86: 0 | J86: 0 | K86: 0 | L86: 0 | M86: 0 | N86: 0 | O86: 0 | P86: 0 | Q86: 0 | R86: 0 | S86: 0 | T86: 0 | U86: 0 | V86: 0 | W86: 0 | X86: 0 | Y86: 0 | Z86: 0 | AA86: 0 | AB86: 0 | AC86: 0 | AD86: 0 | AE86: 0 | AF86: 0 | AG86: 0 | AH86: 0 | AI86: 0 | AJ86: 0 | AK86: 0 | AL86: 0 | AM86: 0 | AN86: 0 | AO86: 0 | AP86: 0 | AQ86: 0 | AR86: 0 | AS86: 0 | AT86: 0 | AU86: 0 | AV86: 0 | AW86: 0 | AX86: 0 | AY86: 0 | AZ86: 0 | BA86: 0 | BB86: 0 | BC86: 0 | BD86: 0 | BE86: 0 | BF86: 0 | BG86: 0 | BH86: 0 | BI86: 0 | BJ86: 0 | BK86: 0 | BL86: 0 | BM86: 0 | BN86: 0 | BO86: 0 | BP86: 0 | BQ86: 0 | BR86: 0 | BS86: 0 | BT86: 0 | BU86: 0 | BV86: 0 | BW86: 0 | BX86: 0 | BY86: 0 | BZ86: 0 | CA86: 0 | CB86: 0 | CC86: 0 | CD86: 0

Sheet Notes
A1: SAM Accounts
A6: RCPA2 | B6: RCPA3 | C6: Abbrev. | D6: Activity | E6: Commodity | F6: Description | M6: RCPA2 | N6: Description
A7: A11 | B7: A111 | C7: sorg | D7: asorg | E7: csorg | F7: Sorghum (A111) | M7: A11 | N7: Cereals | S7: apota | T7: Sorghum (A111) | U7: A111 | X7: asorg | Y7: Sorghum (A111)
A8: A11 | B8: A112 | C8: maiz | D8: amaiz | E8: cmaiz | F8: Maize (A112) | M8: A12 | N8: Roots and Tubers | S8: aspot | T8: Maize (A112) | U8: A112 | X8: amaiz | Y8: Maize (A112)
A9: A11 | B9: A113 | C9: whea | D9: awhea | E9: cwhea | F9: Wheat (A113) | M9: A13 | N9: Vegetables | S9: acass | T9: Wheat (A113) | U9: A113 | X9: awhea | Y9: Wheat (A113)
A10: A11 | B10: A116 | C10: rice | D10: arice | E10: crice | F10: Paddy & husked rice (A116) | M10: A14 | N10: Bananas and fruit | S10: aroot | T10: Paddy & husked rice (A116) | U10: A116 | X10: arice | Y10: Paddy & husked rice (A116)
A11: A11 | B11: A119 | C11: ocer | D11: aocer | E11: cocer | F11: Other cereals (A119) | M11: A15 | N11: Oil seeds n.e.c. and oleaginous fruit | S11: apuls | T11: Other cereals (A119) | U11: A119 | Y11: Other cereals (A119)
A12: A12 | B12: A121 | C12: ipot | D12: aipot | E12: cipot | F12: Irish potatoes (A121) | M12: A21 | N12: Coffee | S12: apuls | T12: Irish potatoes (A121) | U12: A121 | X12: apota | Y12: Irish potatoes (A121)
A13: A12 | B13: A122 | C13: spot | D13: aspot | E13: cspot | F13: Sweet potatoes (A122) | M13: A22 | N13: Tea (unprocessed green leaf) | S13: avege | T13: Sweet potatoes (A122) | U13: A122 | X13: aspot | Y13: Sweet potatoes (A122)
A14: A12 | B14: A123 | C14: cass | D14: acass | E14: ccass | F14: Cassava (A123) | M14: A29 | N14: Other agricultural products | S14: abana | T14: Cassava (A123) | U14: A123 | X14: acass | Y14: Cassava (A123)
A15: A12 | B15: A129 | C15: root | D15: aroot | E15: croot | F15: Other roots & tubers (A129) | M15: A31 | N15: Livestock | S15: abana | T15: Other roots & tubers (A129) | U15: A129 | X15: aroot | Y15: Other roots & tubers (A129)
A16: A13 | B16: A131 | C16: bean | D16: abean | E16: cbean | F16: Dried beans (A131) | M16: A32 | N16: Livestock and hunting products | S16: abana | T16: Dried beans (A131) | U16: A131 | X16: apuls | Y16: Dried beans (A131)
A17: A13 | B17: A132 | C17: peas | D17: apeas | E17: cpeas | F17: Peas & other legumes (A132) | M17: A40 | N17: Forestry products | S17: afrui | T17: Peas & other legumes (A132) | U17: A132 | X17: apuls | Y17: Peas & other legumes (A132)
A18: A13 | B18: A139 | C18: vege | D18: avege | E18: cvege | F18: Other vegetables (A139) | M18: A50 | N18: Fishery products | S18: aoils | T18: Other vegetables (A139) | U18: A139 | X18: avege | Y18: Other vegetables (A139)
A19: A14 | B19: A141 | C19: banb | D19: abanb | E19: cbanb | F19: Bananas for beer (A141) | M19: B01 | N19: Natural gas | S19: aoils | T19: Bananas for beer (A141) | U19: A141 | X19: abana | Y19: Bananas for beer (A141)
A20: A14 | B20: A142 | C20: banc | D20: abanc | E20: cbanc | F20: Bananas for cooking (A142) | M20: B03 | N20: Metal ores | S20: aoils | T20: Bananas for cooking (A142) | U20: A142 | X20: abana | Y20: Bananas for cooking (A142)
A21: A14 | B21: A143 | C21: bans | D21: abans | E21: cbans | F21: Bananas (sweet) (A143) | M21: B09 | N21: Quarry & other mining products | S21: acoff | T21: Bananas (sweet) (A143) | U21: A143 | X21: abana | Y21: Bananas (sweet) (A143)
A22: A14 | B22: A149 | C22: frui | D22: afrui | E22: cfrui | F22: Other fruit & nuts (A149) | M22: C11 | N22: Meat and meat products | S22: agtea | T22: Other fruit & nuts (A149) | U22: A149 | X22: afrui | Y22: Other fruit & nuts (A149)
A23: A15 | B23: A151 | C23: gnut | D23: agnut | E23: cgnut | F23: Ground nuts (A151) | M23: C12 | N23: Prepared and preserved fish | S23: aotex | T23: Ground nuts (A151) | U23: A151 | X23: aoils | Y23: Ground nuts (A151)
... A86: H31 | B86: H31 | C86: trns | D86: atrns | E86: ctrns | F86: Services related to transport (H31) | M86: X00 | N86: Unallocated products | S86: acomm | T86: Services related to transport (H31) | U86: H31 | X86: atran | Y86: Services related to transport (H31)
A87: H32 | B87: H32 | C87: post | D87: apost | E87: cpost | F87: Postal and courier activities (H32) | S87: afina | T87: Postal and courier activities (H32) | U87: H32 | X87: atran | Y87: Postal and courier activities (H32)
A88: I00 | B88: I00 | C88: hotl | D88: ahotl | E88: chotl | F88: Hotels & restaurants (I00) | S88: afina | T88: Hotels & restaurants (I00) | U88: I00 | X88: ahote | Y88: Hotels & restaurants (I00)
A89: J10 | B89: J10 | C89: publ | D89: apubl | E89: cpubl | F89: Publishing, video making, programming & broadcasting activities (J10) | S89: afina | T89: Publishing, video making, programming & broadcasting activities (J10) | U89: J10 | X89: acomm | Y89: Publishing, video making, programming & broadcasting activities (J10)
A90: J20 | B90: J20 | C90: comm | D90: acomm | E90: ccomm | F90: Telecommunication (J20) | S90: arsta | T90: Telecommunication (J20) | U90: J20 | X90: acomm | Y90: Telecommunication (J20)
A91: J30 | B91: J30 | C91: info | D91: ainfo | E91: cinfo | F91: Information technology services (J30) | S91: arsta | T91: Information technology services (J30) | U91: J30 | X91: acomm | Y91: Information technology services (J30)
A92: K01 | B92: K01 | C92: bank | D92: abank | E92: cbank | F92: Monetary institutions (K01) | S92: aserv | T92: Monetary institutions (K01) | U92: K01 | X92: afina | Y92: Monetary institutions (K01)
A93: K02 | B93: K02 | C93: insu | D93: ainsu | E93: cinsu | F93: Insurance, reinsurance and pension funding, except compulsory social security (K02) | S93: aserv | T93: Insurance, reinsurance and pension funding, except compulsory social security (K02) | U93: K02 | X93: afina | Y93: Insurance, reinsurance and pension funding, except compulsory social security (K02)
A94: K03 | B94: K03 | C94: ofsv | D94: aofsv | E94: cofsv | F94: Other financial services (K03) | S94: aserv | T94: Other financial services (K03) | U94: K03 | X94: afina | Y94: Other financial services (K03)
A95: L01 | B95: L01 | C95: rent | D95: arent | E95: crent | F95: Rental value of dwellings (L01) | S95: aserv | T95: Rental value of dwellings (L01) | U95: L01 | X95: arsta | Y95: Rental value of dwellings (L01)
A96: L09 | B96: L09 | C96: real | D96: areal | E96: creal | F96: Other real estate activities (L09) | S96: aserv | T96: Other real estate activities (L09) | U96: L09 | X96: arsta | Y96: Other real estate activities (L09)
A97: M01 | B97: M01 | C97: legl | D97: alegl | E97: clegl | F97: Legal, accounting management & head office activities (M01) | S97: agov | T97: Legal, accounting management & head office activities (M01) | U97: M01 | X97: aserv | Y97: Legal, accounting management & head office activities (M01)
A98: M02 | B98: M02 | C98: enga | D98: aenga | E98: cenga | F98: Architectural and engineering activities (M02) | S98: aeduc | T98: Architectural and engineering activities (M02) | U98: M02 | X98: aserv | Y98: Architectural and engineering activities (M02)
... A109: T00 | B109: T00 | C109: dsrv | D109: adsrv | E109: cdsrv | F109: Domestic services (T00) | S109: arsta | T109: Domestic services (T00) | U109: T00 | X109: aoser | Y109: Domestic services (T00)
A110: V00 | B110: V00 | D110: atrdc | E110: ctrdc | F110: Travel debits & credits (V00) | S110: arsta | T110: Travel debits & credits (V00) | U110: V00 | X110: aoser | Y110: Travel debits & credits (V00)
A111: X00 | B111: X00 | F111: Unallocated products (X00) | S111: aserv | T111: Unallocated products (X00) | U111: X00 | X111: aoser | Y111: Unallocated products (X00)

Sheet Final
A1: Final Supply and Use Tables
D2: INT = 1 - GDP/GO | F2: GO = GDP + INT
A3: Use table coefficients | D3: Sorghum (A111) | E3: Maize (A112) | F3: Wheat (A113) | G3: Paddy & husked rice (A116) | H3: Other cereals (A119) | I3: Irish potatoes (A121) | J3: Sweet potatoes (A122) | K3: Cassava (A123) | L3: Other roots & tubers (A129) | M3: Dried beans (A131) | N3: Peas & other legumes (A132) | O3: Other vegetables (A139) | P3: Bananas for beer (A141) | Q3: Bananas for cooking (A142) | R3: Bananas (sweet) (A143) | S3: Other fruit & nuts (A149) | T3: Ground nuts (A151) | U3: Soya (A152) | V3: Other oil seeds (A159) | W3: Coffee, not roasted, not decaffeinated (A210) | X3: Tea (unprocessed green leaf) (A220) | Y3: Tobacco, raw (A291) | Z3: Sugar cane (A292) | AA3: Pyrethrum (A293) | AB3: Agricultural products n.e.c. (A299) | AC3: Bovine cattle, live (A311) | AD3: Sheep, goats, pigs,live (A312) | AE3: Poultry, live (A313) | AF3: Other live animals (A319) | AG3: Raw milk (A321) | AH3: Eggs (A322) | AI3: Natural honey (A323) | AJ3: Other livestock & hunting products (A329) | AK3: Fuel wood (A401) | AL3: Charcoal (A402) | AM3: Other forestry products (A409) | AN3: Fishery products (A500) | AO3: Natural gas (B01) | AP3: Metal ores (B03) | AQ3: Quarry & other mining products (B09) | AR3: Meat and meat products (C11) | AS3: Prepared and preserved fish (C12) | AT3: Prepared and preserved vegetables (C13) | AU3: Animal and vegetable oils and fats (C14) | AV3: Dairy products (C15) | AW3: Grain mill products (C16) | AX3: Bakery products (C17) | AY3: Animal feed & other by-products (C18) | AZ3: Other manufactured food products (C19) | BA3: Alcoholic drinks (C21) | BB3: Soft drinks (C22) | BC3: Tobacco products (C23) | BD3: Textiles, clothing & leather products (C30) | BE3: Wood, paper and related products (C41) | BF3: Printing and reproduction of recorded media (C42) | BG3: Coke and refined petroleum products (C51) | BH3: Chemicals and chemical products (C52) | BI3: Pharmaceutical products (C53) | BJ3: Rubber and plastics products (C54) | BK3: Non-metallic mineral products n.e.c. (C61) | BL3: Manufacture of cement, lime and plaster (C62) | BM3: Manufacture of clay building materials (C63) | BN3: Metals & metal products, except machinery and equipment (C72) | BO3: Machinery and equipment (except transport) (C74) | BP3: Transport equipment (C76) | BQ3: Furniture (C81) | BR3: Other manufacturing (C82) | BS3: Repair and installation of machinery and equipment (C83) | BT3: Electricity, gas, steam and air conditioning supply (D00) | BU3: Water collection, treatment and supply: sewrage (E01) | BV3: Waste collection and management (E02) | BW3: Construction (modern) (F01) | BX3: Construction (traditional) (F02) | BY3: Maintenance and repair of motor vehicles (G10) | BZ3: Wholesale and retail trade of motor vehicles and motorcycles (G21) | CA3: Wholesale trade, except of motor vehicles and motorcycles (G22) | CB3: Retail trade, except of motor vehicles and motorcycles (G23) | CC3: Land transport (H10) | CD3: Air transport (H20) | CE3: Services related to transport (H31) | CF3: Postal and courier activities (H32) | CG3: Hotels & restaurants (I00) | CH3: Publishing, video making, programming & broadcasting activities (J10) | CI3: Telecommunication (J20) | CJ3: Information technology services (J30) | CK3: Monetary institutions (K01) | CL3: Insurance, reinsurance and pension funding, except compulsory social security (K02) | CM3: Other financial services (K03) | CN3: Rental value of dwellings (L01) | CO3: Other real estate activities (L09) | CP3: Legal, accounting management & head office activities (M01) | CQ3: Architectural and engineering activities (M02) | CR3: Other professional, scientific and technical activities (M03) | CS3: Travel agents and tour operators (N01) | CT3: Other administrative and support service activities (N09) | CU3: Public administration and defence; compulsory social security (O00) | CV3: Education (P00) | CW3: Human health activities (Q01) | CX3: Social work activities (Q02) | CY3: Libraries, archives, museums and other cultural activities (R01) | CZ3: Other arts, entertainment and recreation (R09) | DA3: Other service activities (S00) | DB3: Domestic services (T00) | DC3: Travel debits & credits (V00)
B4: GDP/GO | C4: Orig. | D4: {=TRANSPOSE(GDP!W7:W111)} -> 0.93309851 | E4: 0.93309851 | F4: 0.93309851 | G4: 0.93309851 | H4: 0.93309851 | I4: 0.9352899 | J4: 0.9352899 | K4: 0.9352899 | L4: 0.9352899 | M4: 0.95070324 | N4: 0.95070324 | O4: 0.95070324 | P4: 0.97790125 | Q4: 0.97790125 | R4: 0.97790125 | S4: 0.97790125 | T4: 0.75407428 | U4: 0.75407428 | V4: 0.75407428 | W4: 0.91848864 | X4: 0.91391359 | Y4: 0.92568267 | Z4: 0.92568267 | AA4: 0.92568267 | AB4: 0.92568267 | AC4: 0.91678309 | AD4: 0.91678309 | AE4: 0.91678309 | AF4: 0.91678309 | AG4: 0.97371875 | AH4: 0.97371875 | AI4: 0.97371875 | AJ4: 0.97371875 | AK4: 0.99816602 | AL4: 0.99816602 | AM4: 0.99816602 | AN4: 0.95855384 | AO4: 1 | AP4: 0.6416892 | AQ4: 0.7314137 | AR4: 0.2266543 | AS4: 0.2266543 | AT4: 0.32565389 | AU4: 0.49112069 | AV4: 0.57009698 | AW4: 0.27681751 | AX4: 0.24094973 | AY4: 0.94501676 | AZ4: 0.40607617 | BA4: 0.4883556 | BB4: 0.57494378 | BC4: 0.76946244 | BD4: 0.48790814 | BE4: 0.48876047 | BF4: 0.41458021 | BG4: 0.86046312 | BH4: 0.36286877 | BI4: 0.78781152 | BJ4: 0.26019123 | BK4: 0.28141842 | BL4: 0.38147134 | BM4: 0.55609693 | BN4: 0.1559116 | BO4: 0.64203789 | BP4: 0.50321092 | BQ4: 0.61979088 | BR4: 0.79911143 | BS4: 0.25122961 | BT4: 0.5155325 | BU4: 0.63688917 | BV4: 0.42852161 | BW4: 0.35223586 | BX4: 0.35223586 | BY4: 0.71823903 | BZ4: 0.41214028 | CA4: 0.50163381 | CB4: 0.6134132 | CC4: 0.50004408 | CD4: 0.53332365 | CE4: 0.63866813 | CF4: 0.62636219 | CG4: 0.27276413 | CH4: 0.71682835 | CI4: 0.47015673 | CJ4: 0.59216837 | CK4: 0.46601904 | CL4: 0.81756387 | CM4: 0.68170899 | CN4: 1 | CO4: 0.88758421 | CP4: 0.84616728 | CQ4: 0.77425173 | CR4: 0.90286586 | CS4: 0.55541203 | CT4: 0.92930972 | CU4: 0.40177469 | CV4: 0.62857876 | CW4: 0.48138281 | CX4: 0.59039791 | CY4: 0.8148947 | CZ4: 0.95194844 | DA4: 0.73665734 | DB4: 0.97663132 | DC4: 1
C5: Used | D5: =D4 -> 0.93309851 | E5: =E4 -> 0.93309851 | F5: =F4 -> 0.93309851 | G5: =G4 -> 0.93309851 | H5: =H4 -> 0.93309851 | I5: =I4 -> 0.9352899 | J5: =J4 -> 0.9352899 | K5: =K4 -> 0.9352899 | ... DC5: =DC4 -> 1
B7: Orig. | C7: flab | D7: {=TRANSPOSE(GDP!L7:N111)} -> 0.42220218 | E7: 0.44086658 | F7: 0.45348046 | G7: 0.4532881 | H7: 0.42220218 | I7: 0.47058963 | J7: 0.43368245 | K7: 0.42490888 | L7: 0.46228215 | M7: 0.51205744 | N7: 0.51205744 | O7: 0.56833808 | P7: 0.46534412 | Q7: 0.46534412 | R7: 0.46534412 | S7: 0.56228195 | T7: 0.46263043 | U7: 0.46263043 | V7: 0.46263043 | W7: 0.67904408 | X7: 0.66358066 | Y7: 0.5372261 | Z7: 0.5372261 | AA7: 0.5243602 | AB7: 0.5372261 | AC7: 0.45338998 | AD7: 0.45408331 | AE7: 0.45077431 | AF7: 0.45548988 | AG7: 0.45593561 | AH7: 0.45558062 | AI7: 0.4739655 | AJ7: 0.4739655 | AK7: 0.59955647 | AL7: 0.59955647 | AM7: 0.59955647 | AN7: 0.64999756 | AO7: 0.48154359 | AP7: 0.48154359 | AQ7: 0.48154359 | AR7: 0.47345894 | AS7: 0.47345894 | AT7: 0.47345894 | AU7: 0.4982256 | AV7: 0.47345894 | AW7: 0.53745677 | AX7: 0.4982256 | AY7: 0.4982256 | AZ7: 0.4982256 | BA7: 0.38282644 | BB7: 0.38282644 | BC7: 0.27416796 | BD7: 0.62064856 | BE7: 0.37779779 | BF7: 0.37779779 | BG7: 0.19346372 | BH7: 0.19346372 | BI7: 0.19346372 | BJ7: 0.19346372 | BK7: 0.19928649 | BL7: 0.19928649 | BM7: 0.19928649 | BN7: 0.29785743 | BO7: 0.29785743 | BP7: 0.29785743 | BQ7: 0.29785743 | BR7: 0.29785743 | BS7: 0.38173186 | BT7: 0.5638309 | BU7: 0.5638309 | BV7: 0.5638309 | BW7: 0.5638309 | BX7: 0.5638309 | BY7: 0.51658773 | BZ7: 0.51658773 | CA7: 0.51658773 | CB7: 0.51658773 | CC7: 0.59792235 | CD7: 0.59792235 | CE7: 0.59792235 | CF7: 0.59792235 | CG7: 0.50245285 | CH7: 0.4104047 | CI7: 0.4104047 | CJ7: 0.4104047 | CK7: 0.60717415 | CL7: 0.60717415 | CM7: 0.60717415 | CN7: 0.18842179 | CO7: 0.18842179 | CP7: 0.54906236 | CQ7: 0.54906236 | CR7: 0.54906236 | CS7: 0.54906236 | CT7: 0.54906236 | CU7: 1 | CV7: 0.77181106 | CW7: 0.71198926 | CX7: 0.71198926 | CY7: 0.87667501 | CZ7: 0.87667501 | DA7: 0.87667501 | DB7: 0.87667501 | DC7: 0.87667501
C8: flnd | D8: 0.5044744 | E8: 0.47905324 | F8: 0.45384121 | G8: 0.43486634 | H8: 0.5044744 | I8: 0.42164176 | J8: 0.49381057 | K8: 0.49443453 | L8: 0.45213772 | M8: 0.34841381 | N8: 0.34841381 | O8: 0.31138237 | P8: 0.4258277 | Q8: 0.4258277 | R8: 0.4258277 | S8: 0.33387151 | T8: 0.4433428 | U8: 0.4433428 | V8: 0.4433428 | W8: 0.18801515 | X8: 0.21246482 | Y8: 0.34917301 | Z8: 0.34917301 | AA8: 0.32156415 | AB8: 0.34917301 | AC8: 0 | AD8: 0 | AE8: 0 | AF8: 0 | AG8: 0 | AH8: 0 | AI8: 0 | AJ8: 0 | AK8: 0 | AL8: 0 | AM8: 0 | AN8: 0 | AO8: 0 | AP8: 0 | AQ8: 0 | AR8: 0 | AS8: 0 | AT8: 0 | AU8: 0 | AV8: 0 | AW8: 0 | AX8: 0 | AY8: 0 | AZ8: 0 | BA8: 0 | BB8: 0 | BC8: 0 | BD8: 0 | BE8: 0 | BF8: 0 | BG8: 0 | BH8: 0 | BI8: 0 | BJ8: 0 | BK8: 0 | BL8: 0 | BM8: 0 | BN8: 0 | BO8: 0 | BP8: 0 | BQ8: 0 | BR8: 0 | BS8: 0 | BT8: 0 | BU8: 0 | BV8: 0 | BW8: 0 | BX8: 0 | BY8: 0 | BZ8: 0 | CA8: 0 | CB8: 0 | CC8: 0 | CD8: 0 | CE8: 0 | CF8: 0 | CG8: 0 | CH8: 0 | CI8: 0 | CJ8: 0 | CK8: 0 | CL8: 0 | CM8: 0 | CN8: 0 | CO8: 0 | CP8: 0 | CQ8: 0 | CR8: 0 | CS8: 0 | CT8: 0 | CU8: 0 | CV8: 0 | CW8: 0 | CX8: 0 | CY8: 0 | CZ8: 0 | DA8: 0 | DB8: 0 | DC8: 0
C9: fcap | D9: 0.073323421 | E9: 0.080080187 | F9: 0.092678327 | G9: 0.11184556 | H9: 0.073323421 | I9: 0.10776862 | J9: 0.072506988 | K9: 0.080656585 | L9: 0.085580135 | M9: 0.13952875 | N9: 0.13952875 | O9: 0.12027955 | P9: 0.10882819 | Q9: 0.10882819 | R9: 0.10882819 | S9: 0.10384653 | T9: 0.094026777 | U9: 0.094026777 | V9: 0.094026777 | W9: 0.13294077 | X9: 0.12395452 | Y9: 0.11360088 | Z9: 0.11360088 | AA9: 0.15407565 | AB9: 0.11360088 | AC9: 0.54661002 | AD9: 0.54591669 | AE9: 0.54922569 | AF9: 0.54451012 | AG9: 0.54406439 | AH9: 0.54441938 | AI9: 0.5260345 | AJ9: 0.5260345 | AK9: 0.40044353 | AL9: 0.40044353 | AM9: 0.40044353 | AN9: 0.35000244 | AO9: 0.51845641 | AP9: 0.51845641 | AQ9: 0.51845641 | AR9: 0.52654106 | AS9: 0.52654106 | AT9: 0.52654106 | AU9: 0.5017744 | AV9: 0.52654106 | AW9: 0.46254323 | AX9: 0.5017744 | AY9: 0.5017744 | AZ9: 0.5017744 | BA9: 0.61717356 | BB9: 0.61717356 | BC9: 0.72583204 | BD9: 0.37935144 | BE9: 0.62220221 | BF9: 0.62220221 | BG9: 0.80653628 | BH9: 0.80653628 | BI9: 0.80653628 | BJ9: 0.80653628 | BK9: 0.80071351 | BL9: 0.80071351 | BM9: 0.80071351 | BN9: 0.70214257 | BO9: 0.70214257 | BP9: 0.70214257 | BQ9: 0.70214257 | BR9: 0.70214257 | BS9: 0.61826814 | BT9: 0.4361691 | BU9: 0.4361691 | BV9: 0.4361691 | BW9: 0.4361691 | BX9: 0.4361691 | BY9: 0.48341227 | BZ9: 0.48341227 | CA9: 0.48341227 | CB9: 0.48341227 | CC9: 0.40207765 | CD9: 0.40207765 | CE9: 0.40207765 | CF9: 0.40207765 | CG9: 0.49754715 | CH9: 0.5895953 | CI9: 0.5895953 | CJ9: 0.5895953 | CK9: 0.39282585 | CL9: 0.39282585 | CM9: 0.39282585 | CN9: 0.81157821 | CO9: 0.81157821 | CP9: 0.45093764 | CQ9: 0.45093764 | CR9: 0.45093764 | CS9: 0.45093764 | CT9: 0.45093764 | CU9: 0 | CV9: 0.22818894 | CW9: 0.28801074 | CX9: 0.28801074 | CY9: 0.12332499 | CZ9: 0.12332499 | DA9: 0.12332499 | DB9: 0.12332499 | DC9: 0.12332499
B10: Used | C10: flab | D10: =D7 -> 0.42220218 | E10: =E7 -> 0.44086658 | F10: =F7 -> 0.45348046 | G10: =G7 -> 0.4532881 | H10: =H7 -> 0.42220218 | I10: =I7 -> 0.47058963 | J10: =J7 -> 0.43368245 | K10: =K7 -> 0.42490888 | ... DC10: =DC7 -> 0.87667501
C11: flnd | D11: =D8 -> 0.5044744 | E11: =E8 -> 0.47905324 | F11: =F8 -> 0.45384121 | G11: =G8 -> 0.43486634 | H11: =H8 -> 0.5044744 | I11: =I8 -> 0.42164176 | J11: =J8 -> 0.49381057 | K11: =K8 -> 0.49443453 | ... DC11: =DC8 -> 0
C12: fcap | D12: =1-SUM(D10:D11) -> 0.073323421 | E12: =1-SUM(E10:E11) -> 0.080080187 | F12: =1-SUM(F10:F11) -> 0.092678327 | G12: =1-SUM(G10:G11) -> 0.11184556 | H12: =1-SUM(H10:H11) -> 0.073323421 | I12: =1-SUM(I10:I11) -> 0.10776862 | J12: =1-SUM(J10:J11) -> 0.072506988 | K12: =1-SUM(K10:K11) -> 0.080656585 | ... DC12: =1-SUM(DC10:DC11) -> 0.12332499
D14: =SUM(D17:D123) -> 1 | E14: =SUM(E17:E123) -> 1 | F14: =SUM(F17:F123) -> 1 | G14: =SUM(G17:G123) -> 1 | H14: =SUM(H17:H123) -> 1 | I14: =SUM(I17:I123) -> 1 | J14: =SUM(J17:J123) -> 1 | K14: =SUM(K17:K123) -> 1 | ... DC14: =SUM(DC17:DC123) -> 1
D15: Sorghum (A111) | E15: Maize (A112) | F15: Wheat (A113) | G15: Paddy & husked rice (A116) | H15: Other cereals (A119) | I15: Irish potatoes (A121) | J15: Sweet potatoes (A122) | K15: Cassava (A123) | L15: Other roots & tubers (A129) | M15: Dried beans (A131) | N15: Peas & other legumes (A132) | O15: Other vegetables (A139) | P15: Bananas for beer (A141) | Q15: Bananas for cooking (A142) | R15: Bananas (sweet) (A143) | S15: Other fruit & nuts (A149) | T15: Ground nuts (A151) | U15: Soya (A152) | V15: Other oil seeds (A159) | W15: Coffee, not roasted, not decaffeinated (A210) | X15: Tea (unprocessed green leaf) (A220) | Y15: Tobacco, raw (A291) | Z15: Sugar cane (A292) | AA15: Pyrethrum (A293) | AB15: Agricultural products n.e.c. (A299) | AC15: Bovine cattle, live (A311) | AD15: Sheep, goats, pigs,live (A312) | AE15: Poultry, live (A313) | AF15: Other live animals (A319) | AG15: Raw milk (A321) | AH15: Eggs (A322) | AI15: Natural honey (A323) | AJ15: Other livestock & hunting products (A329) | AK15: Fuel wood (A401) | AL15: Charcoal (A402) | AM15: Other forestry products (A409) | AN15: Fishery products (A500) | AO15: Natural gas (B01) | AP15: Metal ores (B03) | AQ15: Quarry & other mining products (B09) | AR15: Meat and meat products (C11) | AS15: Prepared and preserved fish (C12) | AT15: Prepared and preserved vegetables (C13) | AU15: Animal and vegetable oils and fats (C14) | AV15: Dairy products (C15) | AW15: Grain mill products (C16) | AX15: Bakery products (C17) | AY15: Animal feed & other by-products (C18) | AZ15: Other manufactured food products (C19) | BA15: Alcoholic drinks (C21) | BB15: Soft drinks (C22) | BC15: Tobacco products (C23) | BD15: Textiles, clothing & leather products (C30) | BE15: Wood, paper and related products (C41) | BF15: Printing and reproduction of recorded media (C42) | BG15: Coke and refined petroleum products (C51) | BH15: Chemicals and chemical products (C52) | BI15: Pharmaceutical products (C53) | BJ15: Rubber and plastics products (C54) | BK15: Non-metallic mineral products n.e.c. (C61) | BL15: Manufacture of cement, lime and plaster (C62) | BM15: Manufacture of clay building materials (C63) | BN15: Metals & metal products, except machinery and equipment (C72) | BO15: Machinery and equipment (except transport) (C74) | BP15: Transport equipment (C76) | BQ15: Furniture (C81) | BR15: Other manufacturing (C82) | BS15: Repair and installation of machinery and equipment (C83) | BT15: Electricity, gas, steam and air conditioning supply (D00) | BU15: Water collection, treatment and supply: sewrage (E01) | BV15: Waste collection and management (E02) | BW15: Construction (modern) (F01) | BX15: Construction (traditional) (F02) | BY15: Maintenance and repair of motor vehicles (G10) | BZ15: Wholesale and retail trade of motor vehicles and motorcycles (G21) | CA15: Wholesale trade, except of motor vehicles and motorcycles (G22) | CB15: Retail trade, except of motor vehicles and motorcycles (G23) | CC15: Land transport (H10) | CD15: Air transport (H20) | CE15: Services related to transport (H31) | CF15: Postal and courier activities (H32) | CG15: Hotels & restaurants (I00) | CH15: Publishing, video making, programming & broadcasting activities (J10) | CI15: Telecommunication (J20) | CJ15: Information technology services (J30) | CK15: Monetary institutions (K01) | CL15: Insurance, reinsurance and pension funding, except compulsory social security (K02) | CM15: Other financial services (K03) | CN15: Rental value of dwellings (L01) | CO15: Other real estate activities (L09) | CP15: Legal, accounting management & head office activities (M01) | CQ15: Architectural and engineering activities (M02) | CR15: Other professional, scientific and technical activities (M03) | CS15: Travel agents and tour operators (N01) | CT15: Other administrative and support service activities (N09) | CU15: Public administration and defence; compulsory social security (O00) | CV15: Education (P00) | CW15: Human health activities (Q01) | CX15: Social work activities (Q02) | CY15: Libraries, archives, museums and other cultural activities (R01) | CZ15: Other arts, entertainment and recreation (R09) | DA15: Other service activities (S00) | DB15: Domestic services (T00) | DC15: Travel debits & credits (V00)
D16: asorg | E16: amaiz | F16: awhea | G16: arice | H16: aocer | I16: aipot | J16: aspot | K16: acass | L16: aroot | M16: abean | N16: apeas | O16: avege | P16: abanb | Q16: abanc | R16: abans | S16: afrui | T16: agnut | U16: asoya | V16: aoils | W16: acoff | X16: ateal | Y16: atoba | Z16: asugr | AA16: apyre | AB16: aocrp | AC16: acatt | AD16: asmlr | AE16: apoul | AF16: aoliv | AG16: amilk | AH16: aeggs | AI16: ahony | AJ16: ahunt | AK16: afuel | AL16: achar | AM16: afore | AN16: afish | AO16: angas | AP16: amore | AQ16: aomin | AR16: ameat | AS16: afsea | AT16: afveg | AU16: afoil | AV16: adair | AW16: agmll | AX16: abake | AY16: afeed | AZ16: afood | BA16: aalco | BB16: abeve | BC16: aptob | BD16: atext | BE16: awood | BF16: aprnt | BG16: apetr | BH16: achem | BI16: aphar | BJ16: aprub | BK16: anmet | BL16: aceme | BM16: aclay | BN16: ametl | BO16: amach | BP16: avehi | BQ16: afurn | BR16: aoman | BS16: arepr | BT16: aelec | BU16: awatr | BV16: awast | BW16: acons | BX16: acont | BY16: avehr | BZ16: aveht | CA16: atrdw | CB16: atrdr | CC16: atrnl | CD16: atrna | CE16: atrns | CF16: apost | CG16: ahotl | CH16: apubl | CI16: acomm | CJ16: ainfo | CK16: abank | CL16: ainsu | CM16: aofsv | CN16: arent | CO16: areal | CP16: alegl | CQ16: aenga | CR16: aprod | CS16: atrvl | CT16: aobsv | CU16: apadm | CV16: aeduc | CW16: aheal | CX16: asocw | CY16: acult | CZ16: aarts | DA16: aosrv | DB16: adsrv | DC16: atrdc
B17: Sorghum (A111) | C17: csorg | D17: =IF(USE!E$538<>0,(1-D$5)*USE!E542/USE!E$538,(1-D$5)*USE!E318) -> 0.0075260539 | E17: =IF(USE!F$538<>0,(1-E$5)*USE!F542/USE!F$538,(1-E$5)*USE!F318) -> 0 | F17: =IF(USE!G$538<>0,(1-F$5)*USE!G542/USE!G$538,(1-F$5)*USE!G318) -> 0 | G17: =IF(USE!H$538<>0,(1-G$5)*USE!H542/USE!H$538,(1-G$5)*USE!H318) -> 0 | H17: =IF(USE!I$538<>0,(1-H$5)*USE!I542/USE!I$538,(1-H$5)*USE!I318) -> 0 | I17: =IF(USE!J$538<>0,(1-I$5)*USE!J542/USE!J$538,(1-I$5)*USE!J318) -> 0 | J17: =IF(USE!K$538<>0,(1-J$5)*USE!K542/USE!K$538,(1-J$5)*USE!K318) -> 0 | K17: =IF(USE!L$538<>0,(1-K$5)*USE!L542/USE!L$538,(1-K$5)*USE!L318) -> 0 | ... DC17: =IF(USE!DD$538<>0,(1-DC$5)*USE!DD542/USE!DD$538,(1-DC$5)*USE!DD318) -> 0
B18: Maize (A112) | C18: cmaiz | D18: =IF(USE!E$538<>0,(1-D$5)*USE!E543/USE!E$538,(1-D$5)*USE!E319) -> 0 | E18: =IF(USE!F$538<>0,(1-E$5)*USE!F543/USE!F$538,(1-E$5)*USE!F319) -> 0.0075260539 | F18: =IF(USE!G$538<>0,(1-F$5)*USE!G543/USE!G$538,(1-F$5)*USE!G319) -> 0 | G18: =IF(USE!H$538<>0,(1-G$5)*USE!H543/USE!H$538,(1-G$5)*USE!H319) -> 0 | H18: =IF(USE!I$538<>0,(1-H$5)*USE!I543/USE!I$538,(1-H$5)*USE!I319) -> 0 | I18: =IF(USE!J$538<>0,(1-I$5)*USE!J543/USE!J$538,(1-I$5)*USE!J319) -> 0 | J18: =IF(USE!K$538<>0,(1-J$5)*USE!K543/USE!K$538,(1-J$5)*USE!K319) -> 0 | K18: =IF(USE!L$538<>0,(1-K$5)*USE!L543/USE!L$538,(1-K$5)*USE!L319) -> 0 | ... DC18: =IF(USE!DD$538<>0,(1-DC$5)*USE!DD543/USE!DD$538,(1-DC$5)*USE!DD319) -> 0
B19: Wheat (A113) | C19: cwhea | D19: =IF(USE!E$538<>0,(1-D$5)*USE!E544/USE!E$538,(1-D$5)*USE!E320) -> 0 | E19: =IF(USE!F$538<>0,(1-E$5)*USE!F544/USE!F$538,(1-E$5)*USE!F320) -> 0 | F19: =IF(USE!G$538<>0,(1-F$5)*USE!G544/USE!G$538,(1-F$5)*USE!G320) -> 0.0075260539 | G19: =IF(USE!H$538<>0,(1-G$5)*USE!H544/USE!H$538,(1-G$5)*USE!H320) -> 0 | H19: =IF(USE!I$538<>0,(1-H$5)*USE!I544/USE!I$538,(1-H$5)*USE!I320) -> 0 | I19: =IF(USE!J$538<>0,(1-I$5)*USE!J544/USE!J$538,(1-I$5)*USE!J320) -> 0 | J19: =IF(USE!K$538<>0,(1-J$5)*USE!K544/USE!K$538,(1-J$5)*USE!K320) -> 0 | K19: =IF(USE!L$538<>0,(1-K$5)*USE!L544/USE!L$538,(1-K$5)*USE!L320) -> 0 | ... DC19: =IF(USE!DD$538<>0,(1-DC$5)*USE!DD544/USE!DD$538,(1-DC$5)*USE!DD320) -> 0
B20: Paddy & husked rice (A116) | C20: crice | D20: =IF(USE!E$538<>0,(1-D$5)*USE!E545/USE!E$538,(1-D$5)*USE!E321) -> 0 | E20: =IF(USE!F$538<>0,(1-E$5)*USE!F545/USE!F$538,(1-E$5)*USE!F321) -> 0 | F20: =IF(USE!G$538<>0,(1-F$5)*USE!G545/USE!G$538,(1-F$5)*USE!G321) -> 0 | G20: =IF(USE!H$538<>0,(1-G$5)*USE!H545/USE!H$538,(1-G$5)*USE!H321) -> 0.0075260539 | H20: =IF(USE!I$538<>0,(1-H$5)*USE!I545/USE!I$538,(1-H$5)*USE!I321) -> 0 | I20: =IF(USE!J$538<>0,(1-I$5)*USE!J545/USE!J$538,(1-I$5)*USE!J321) -> 0 | J20: =IF(USE!K$538<>0,(1-J$5)*USE!K545/USE!K$538,(1-J$5)*USE!K321) -> 0 | K20: =IF(USE!L$538<>0,(1-K$5)*USE!L545/USE!L$538,(1-K$5)*USE!L321) -> 0 | ... DC20: =IF(USE!DD$538<>0,(1-DC$5)*USE!DD545/USE!DD$538,(1-DC$5)*USE!DD321) -> 0
B21: Other cereals (A119) | C21: cocer | D21: =IF(USE!E$538<>0,(1-D$5)*USE!E546/USE!E$538,(1-D$5)*USE!E322) -> 0 | E21: =IF(USE!F$538<>0,(1-E$5)*USE!F546/USE!F$538,(1-E$5)*USE!F322) -> 0 | F21: =IF(USE!G$538<>0,(1-F$5)*USE!G546/USE!G$538,(1-F$5)*USE!G322) -> 0 | G21: =IF(USE!H$538<>0,(1-G$5)*USE!H546/USE!H$538,(1-G$5)*USE!H322) -> 0 | H21: =IF(USE!I$538<>0,(1-H$5)*USE!I546/USE!I$538,(1-H$5)*USE!I322) -> 0.0075260539 | I21: =IF(USE!J$538<>0,(1-I$5)*USE!J546/USE!J$538,(1-I$5)*USE!J322) -> 0 | J21: =IF(USE!K$538<>0,(1-J$5)*USE!K546/USE!K$538,(1-J$5)*USE!K322) -> 0 | K21: =IF(USE!L$538<>0,(1-K$5)*USE!L546/USE!L$538,(1-K$5)*USE!L322) -> 0 | ... DC21: =IF(USE!DD$538<>0,(1-DC$5)*USE!DD546/USE!DD$538,(1-DC$5)*USE!DD322) -> 0
B22: Irish potatoes (A121) | C22: cipot | D22: =IF(USE!E$538<>0,(1-D$5)*USE!E547/USE!E$538,(1-D$5)*USE!E323) -> 0 | E22: =IF(USE!F$538<>0,(1-E$5)*USE!F547/USE!F$538,(1-E$5)*USE!F323) -> 0 | F22: =IF(USE!G$538<>0,(1-F$5)*USE!G547/USE!G$538,(1-F$5)*USE!G323) -> 0 | G22: =IF(USE!H$538<>0,(1-G$5)*USE!H547/USE!H$538,(1-G$5)*USE!H323) -> 0 | H22: =IF(USE!I$538<>0,(1-H$5)*USE!I547/USE!I$538,(1-H$5)*USE!I323) -> 0 | I22: =IF(USE!J$538<>0,(1-I$5)*USE!J547/USE!J$538,(1-I$5)*USE!J323) -> 0.011437957 | J22: =IF(USE!K$538<>0,(1-J$5)*USE!K547/USE!K$538,(1-J$5)*USE!K323) -> 0 | K22: =IF(USE!L$538<>0,(1-K$5)*USE!L547/USE!L$538,(1-K$5)*USE!L323) -> 0 | ... DC22: =IF(USE!DD$538<>0,(1-DC$5)*USE!DD547/USE!DD$538,(1-DC$5)*USE!DD323) -> 0
B23: Sweet potatoes (A122) | C23: cspot | D23: =IF(USE!E$538<>0,(1-D$5)*USE!E548/USE!E$538,(1-D$5)*USE!E324) -> 0 | E23: =IF(USE!F$538<>0,(1-E$5)*USE!F548/USE!F$538,(1-E$5)*USE!F324) -> 0 | F23: =IF(USE!G$538<>0,(1-F$5)*USE!G548/USE!G$538,(1-F$5)*USE!G324) -> 0 | G23: =IF(USE!H$538<>0,(1-G$5)*USE!H548/USE!H$538,(1-G$5)*USE!H324) -> 0 | H23: =IF(USE!I$538<>0,(1-H$5)*USE!I548/USE!I$538,(1-H$5)*USE!I324) -> 0 | I23: =IF(USE!J$538<>0,(1-I$5)*USE!J548/USE!J$538,(1-I$5)*USE!J324) -> 0 | J23: =IF(USE!K$538<>0,(1-J$5)*USE!K548/USE!K$538,(1-J$5)*USE!K324) -> 0.011437957 | K23: =IF(USE!L$538<>0,(1-K$5)*USE!L548/USE!L$538,(1-K$5)*USE!L324) -> 0 | ... DC23: =IF(USE!DD$538<>0,(1-DC$5)*USE!DD548/USE!DD$538,(1-DC$5)*USE!DD324) -> 0
B24: Cassava (A123) | C24: ccass | D24: =IF(USE!E$538<>0,(1-D$5)*USE!E549/USE!E$538,(1-D$5)*USE!E325) -> 0 | E24: =IF(USE!F$538<>0,(1-E$5)*USE!F549/USE!F$538,(1-E$5)*USE!F325) -> 0 | F24: =IF(USE!G$538<>0,(1-F$5)*USE!G549/USE!G$538,(1-F$5)*USE!G325) -> 0 | G24: =IF(USE!H$538<>0,(1-G$5)*USE!H549/USE!H$538,(1-G$5)*USE!H325) -> 0 | H24: =IF(USE!I$538<>0,(1-H$5)*USE!I549/USE!I$538,(1-H$5)*USE!I325) -> 0 | I24: =IF(USE!J$538<>0,(1-I$5)*USE!J549/USE!J$538,(1-I$5)*USE!J325) -> 0 | J24: =IF(USE!K$538<>0,(1-J$5)*USE!K549/USE!K$538,(1-J$5)*USE!K325) -> 0 | K24: =IF(USE!L$538<>0,(1-K$5)*USE!L549/USE!L$538,(1-K$5)*USE!L325) -> 0.011437957 | ... DC24: =IF(USE!DD$538<>0,(1-DC$5)*USE!DD549/USE!DD$538,(1-DC$5)*USE!DD325) -> 0
B25: Other roots & tubers (A129) | C25: croot | D25: =IF(USE!E$538<>0,(1-D$5)*USE!E550/USE!E$538,(1-D$5)*USE!E326) -> 0 | E25: =IF(USE!F$538<>0,(1-E$5)*USE!F550/USE!F$538,(1-E$5)*USE!F326) -> 0 | F25: =IF(USE!G$538<>0,(1-F$5)*USE!G550/USE!G$538,(1-F$5)*USE!G326) -> 0 | G25: =IF(USE!H$538<>0,(1-G$5)*USE!H550/USE!H$538,(1-G$5)*USE!H326) -> 0 | H25: =IF(USE!I$538<>0,(1-H$5)*USE!I550/USE!I$538,(1-H$5)*USE!I326) -> 0 | I25: =IF(USE!J$538<>0,(1-I$5)*USE!J550/USE!J$538,(1-I$5)*USE!J326) -> 0 | J25: =IF(USE!K$538<>0,(1-J$5)*USE!K550/USE!K$538,(1-J$5)*USE!K326) -> 0 | K25: =IF(USE!L$538<>0,(1-K$5)*USE!L550/USE!L$538,(1-K$5)*USE!L326) -> 0 | ... DC25: =IF(USE!DD$538<>0,(1-DC$5)*USE!DD550/USE!DD$538,(1-DC$5)*USE!DD326) -> 0
B26: Dried beans (A131) | C26: cbean | D26: =IF(USE!E$538<>0,(1-D$5)*USE!E551/USE!E$538,(1-D$5)*USE!E327) -> 0 | E26: =IF(USE!F$538<>0,(1-E$5)*USE!F551/USE!F$538,(1-E$5)*USE!F327) -> 0 | F26: =IF(USE!G$538<>0,(1-F$5)*USE!G551/USE!G$538,(1-F$5)*USE!G327) -> 0 | G26: =IF(USE!H$538<>0,(1-G$5)*USE!H551/USE!H$538,(1-G$5)*USE!H327) -> 0 | H26: =IF(USE!I$538<>0,(1-H$5)*USE!I551/USE!I$538,(1-H$5)*USE!I327) -> 0 | I26: =IF(USE!J$538<>0,(1-I$5)*USE!J551/USE!J$538,(1-I$5)*USE!J327) -> 0 | J26: =IF(USE!K$538<>0,(1-J$5)*USE!K551/USE!K$538,(1-J$5)*USE!K327) -> 0 | K26: =IF(USE!L$538<>0,(1-K$5)*USE!L551/USE!L$538,(1-K$5)*USE!L327) -> 0 | ... DC26: =IF(USE!DD$538<>0,(1-DC$5)*USE!DD551/USE!DD$538,(1-DC$5)*USE!DD327) -> 0
B27: Peas & other legumes (A132) | C27: cpeas | D27: =IF(USE!E$538<>0,(1-D$5)*USE!E552/USE!E$538,(1-D$5)*USE!E328) -> 0 | E27: =IF(USE!F$538<>0,(1-E$5)*USE!F552/USE!F$538,(1-E$5)*USE!F328) -> 0 | F27: =IF(USE!G$538<>0,(1-F$5)*USE!G552/USE!G$538,(1-F$5)*USE!G328) -> 0 | G27: =IF(USE!H$538<>0,(1-G$5)*USE!H552/USE!H$538,(1-G$5)*USE!H328) -> 0 | H27: =IF(USE!I$538<>0,(1-H$5)*USE!I552/USE!I$538,(1-H$5)*USE!I328) -> 0 | I27: =IF(USE!J$538<>0,(1-I$5)*USE!J552/USE!J$538,(1-I$5)*USE!J328) -> 0 | J27: =IF(USE!K$538<>0,(1-J$5)*USE!K552/USE!K$538,(1-J$5)*USE!K328) -> 0 | K27: =IF(USE!L$538<>0,(1-K$5)*USE!L552/USE!L$538,(1-K$5)*USE!L328) -> 0 | ... DC27: =IF(USE!DD$538<>0,(1-DC$5)*USE!DD552/USE!DD$538,(1-DC$5)*USE!DD328) -> 0
B28: Other vegetables (A139) | C28: cvege | D28: =IF(USE!E$538<>0,(1-D$5)*USE!E553/USE!E$538,(1-D$5)*USE!E329) -> 0 | E28: =IF(USE!F$538<>0,(1-E$5)*USE!F553/USE!F$538,(1-E$5)*USE!F329) -> 0 | F28: =IF(USE!G$538<>0,(1-F$5)*USE!G553/USE!G$538,(1-F$5)*USE!G329) -> 0 | G28: =IF(USE!H$538<>0,(1-G$5)*USE!H553/USE!H$538,(1-G$5)*USE!H329) -> 0 | H28: =IF(USE!I$538<>0,(1-H$5)*USE!I553/USE!I$538,(1-H$5)*USE!I329) -> 0 | I28: =IF(USE!J$538<>0,(1-I$5)*USE!J553/USE!J$538,(1-I$5)*USE!J329) -> 0 | J28: =IF(USE!K$538<>0,(1-J$5)*USE!K553/USE!K$538,(1-J$5)*USE!K329) -> 0 | K28: =IF(USE!L$538<>0,(1-K$5)*USE!L553/USE!L$538,(1-K$5)*USE!L329) -> 0 | ... DC28: =IF(USE!DD$538<>0,(1-DC$5)*USE!DD553/USE!DD$538,(1-DC$5)*USE!DD329) -> 0
... B120: Travel debits & credits (V00) | C120: ctrdc | D120: =IF(USE!E$538<>0,(1-D$5)*USE!E645/USE!E$538,(1-D$5)*USE!E421) -> 0 | E120: =IF(USE!F$538<>0,(1-E$5)*USE!F645/USE!F$538,(1-E$5)*USE!F421) -> 0 | F120: =IF(USE!G$538<>0,(1-F$5)*USE!G645/USE!G$538,(1-F$5)*USE!G421) -> 0 | G120: =IF(USE!H$538<>0,(1-G$5)*USE!H645/USE!H$538,(1-G$5)*USE!H421) -> 0 | H120: =IF(USE!I$538<>0,(1-H$5)*USE!I645/USE!I$538,(1-H$5)*USE!I421) -> 0 | I120: =IF(USE!J$538<>0,(1-I$5)*USE!J645/USE!J$538,(1-I$5)*USE!J421) -> 0 | J120: =IF(USE!K$538<>0,(1-J$5)*USE!K645/USE!K$538,(1-J$5)*USE!K421) -> 0 | K120: =IF(USE!L$538<>0,(1-K$5)*USE!L645/USE!L$538,(1-K$5)*USE!L421) -> 0 | ... DC120: =IF(USE!DD$538<>0,(1-DC$5)*USE!DD645/USE!DD$538,(1-DC$5)*USE!DD421) -> 0
B121: Labor | C121: flab | D121: =D$5*D10 -> 0.39395623 | E121: =E$5*E10 -> 0.41137194 | F121: =F$5*F10 -> 0.42314194 | G121: =G$5*G10 -> 0.42296245 | H121: =H$5*H10 -> 0.39395623 | I121: =I$5*I10 -> 0.44013773 | J121: =J$5*J10 -> 0.40561881 | K121: =K$5*K10 -> 0.39741299 | ... DC121: =DC$5*DC10 -> 0.87667501
B122: Land transport (H10) | C122: flnd | D122: =D$5*D11 -> 0.47072431 | E122: =E$5*E11 -> 0.44700386 | F122: =F$5*F11 -> 0.42347856 | G122: =G$5*G11 -> 0.40577314 | H122: =H$5*H11 -> 0.47072431 | I122: =I$5*I11 -> 0.39435728 | J122: =J$5*J11 -> 0.46185604 | K122: =K$5*K11 -> 0.46243963 | ... DC122: =DC$5*DC11 -> 0
B123: Capital | C123: fcap | D123: =D$5*D12 -> 0.068417975 | E123: =E$5*E12 -> 0.074722703 | F123: =F$5*F12 -> 0.086478008 | G123: =G$5*G12 -> 0.10436292 | H123: =H$5*H12 -> 0.068417975 | I123: =I$5*I12 -> 0.1007949 | J123: =J$5*J12 -> 0.067815054 | K123: =K$5*K12 -> 0.07543729 | ... DC123: =DC$5*DC12 -> 0.12332499
A126: Supply table coefficients
D127: Sorghum (A111) | E127: Maize (A112) | F127: Wheat (A113) | G127: Paddy & husked rice (A116) | H127: Other cereals (A119) | I127: Irish potatoes (A121) | J127: Sweet potatoes (A122) | K127: Cassava (A123) | L127: Other roots & tubers (A129) | M127: Dried beans (A131) | N127: Peas & other legumes (A132) | O127: Other vegetables (A139) | P127: Bananas for beer (A141) | Q127: Bananas for cooking (A142) | R127: Bananas (sweet) (A143) | S127: Other fruit & nuts (A149) | T127: Ground nuts (A151) | U127: Soya (A152) | V127: Other oil seeds (A159) | W127: Coffee, not roasted, not decaffeinated (A210) | X127: Tea (unprocessed green leaf) (A220) | Y127: Tobacco, raw (A291) | Z127: Sugar cane (A292) | AA127: Pyrethrum (A293) | AB127: Agricultural products n.e.c. (A299) | AC127: Bovine cattle, live (A311) | AD127: Sheep, goats, pigs,live (A312) | AE127: Poultry, live (A313) | AF127: Other live animals (A319) | AG127: Raw milk (A321) | AH127: Eggs (A322) | AI127: Natural honey (A323) | AJ127: Other livestock & hunting products (A329) | AK127: Fuel wood (A401) | AL127: Charcoal (A402) | AM127: Other forestry products (A409) | AN127: Fishery products (A500) | AO127: Natural gas (B01) | AP127: Metal ores (B03) | AQ127: Quarry & other mining products (B09) | AR127: Meat and meat products (C11) | AS127: Prepared and preserved fish (C12) | AT127: Prepared and preserved vegetables (C13) | AU127: Animal and vegetable oils and fats (C14) | AV127: Dairy products (C15) | AW127: Grain mill products (C16) | AX127: Bakery products (C17) | AY127: Animal feed & other by-products (C18) | AZ127: Other manufactured food products (C19) | BA127: Alcoholic drinks (C21) | BB127: Soft drinks (C22) | BC127: Tobacco products (C23) | BD127: Textiles, clothing & leather products (C30) | BE127: Wood, paper and related products (C41) | BF127: Printing and reproduction of recorded media (C42) | BG127: Coke and refined petroleum products (C51) | BH127: Chemicals and chemical products (C52) | BI127: Pharmaceutical products (C53) | BJ127: Rubber and plastics products (C54) | BK127: Non-metallic mineral products n.e.c. (C61) | BL127: Manufacture of cement, lime and plaster (C62) | BM127: Manufacture of clay building materials (C63) | BN127: Metals & metal products, except machinery and equipment (C72) | BO127: Machinery and equipment (except transport) (C74) | BP127: Transport equipment (C76) | BQ127: Furniture (C81) | BR127: Other manufacturing (C82) | BS127: Repair and installation of machinery and equipment (C83) | BT127: Electricity, gas, steam and air conditioning supply (D00) | BU127: Water collection, treatment and supply: sewrage (E01) | BV127: Waste collection and management (E02) | BW127: Construction (modern) (F01) | BX127: Construction (traditional) (F02) | BY127: Maintenance and repair of motor vehicles (G10) | BZ127: Wholesale and retail trade of motor vehicles and motorcycles (G21) | CA127: Wholesale trade, except of motor vehicles and motorcycles (G22) | CB127: Retail trade, except of motor vehicles and motorcycles (G23) | CC127: Land transport (H10) | CD127: Air transport (H20) | CE127: Services related to transport (H31) | CF127: Postal and courier activities (H32) | CG127: Hotels & restaurants (I00) | CH127: Publishing, video making, programming & broadcasting activities (J10) | CI127: Telecommunication (J20) | CJ127: Information technology services (J30) | CK127: Monetary institutions (K01) | CL127: Insurance, reinsurance and pension funding, except compulsory social security (K02) | CM127: Other financial services (K03) | CN127: Rental value of dwellings (L01) | CO127: Other real estate activities (L09) | CP127: Legal, accounting management & head office activities (M01) | CQ127: Architectural and engineering activities (M02) | CR127: Other professional, scientific and technical activities (M03) | CS127: Travel agents and tour operators (N01) | CT127: Other administrative and support service activities (N09) | CU127: Public administration and defence; compulsory social security (O00) | CV127: Education (P00) | CW127: Human health activities (Q01) | CX127: Social work activities (Q02) | CY127: Libraries, archives, museums and other cultural activities (R01) | CZ127: Other arts, entertainment and recreation (R09) | DA127: Other service activities (S00) | DB127: Domestic services (T00) | DC127: Travel debits & credits (V00)
