Workbook

Sheet Notes
A1: =CONCATENATE(B5," ",C4," SAM") -> 2017 Rwanda SAM
A2: Use with 1construct.gms and 2balance.gms
A4: Country | B4: RWA | C4: =IF(ISNA(INDEX([1]wEXR!$A$8:$A$196,MATCH([1]Notes!B4,[1]wEXR!$B$8:$B$196,0))),"Check name",INDEX([1]wEXR!$A$8:$A$196,MATCH([1]Notes!B4,[1]wEXR!$B$8:$B$196,0))) -> Rwanda
A5: Year | B5: 2017
A6: Units | B6: Billions of Rwanda Francs
A7: Citation
A9: Activities and commodities (X104) | E9: Factors | H9: Households | K9: Other accounts
A10: ="a"&MID(B10,2,4) -> asorg | B10: csorg | C10: Sorghum (A111) | E10: flab-rn | F10: Labor - rural uneducated | H10: hhd-f1 | I10: Rural - farm q1 | K10: trc | L10: Transaction costs
A11: ="a"&MID(B11,2,4) -> amaiz | B11: cmaiz | C11: Maize (A112) | E11: flab-rp | F11: Labor - rural primary | H11: hhd-f2 | I11: Rural - farm q2 | K11: flab | L11: Labor
A12: ="a"&MID(B12,2,4) -> awhea | B12: cwhea | C12: Wheat (A113) | E12: flab-rs | F12: Labor - rural secondary | H12: hhd-f3 | I12: Rural - farm q3 | K12: flnd | L12: Land
A13: ="a"&MID(B13,2,4) -> arice | B13: crice | C13: Paddy & husked rice (A116) | E13: flab-rt | F13: Labor - rural tertiary | H13: hhd-f4 | I13: Rural - farm q4 | K13: fcap | L13: Capital
A14: ="a"&MID(B14,2,4) -> aocer | B14: cocer | C14: Other cereals (A119) | E14: flab-un | F14: Labor - urban uneducated | H14: hhd-f5 | I14: Rural - farm q5 | K14: ent | L14: Enterprises
A15: ="a"&MID(B15,2,4) -> aipot | B15: cipot | C15: Irish potatoes (A121) | E15: flab-up | F15: Labor - urban primary | H15: hhd-n1 | I15: Rural - nonfarm q1 | K15: hhd | L15: Households
A16: ="a"&MID(B16,2,4) -> aspot | B16: cspot | C16: Sweet potatoes (A122) | E16: flab-us | F16: Labor - urban secondary | H16: hhd-n2 | I16: Rural - nonfarm q2 | K16: gov | L16: Government
A17: ="a"&MID(B17,2,4) -> acass | B17: ccass | C17: Cassava (A123) | E17: flab-ut | F17: Labor - urban tertiary | H17: hhd-n3 | I17: Rural - nonfarm q3 | K17: atax | L17: Taxes - activity (production)
A18: ="a"&MID(B18,2,4) -> aroot | B18: croot | C18: Other roots & tubers (A129) | E18: flab-kn | F18: Labor - Kigali uneducated | H18: hhd-n4 | I18: Rural - nonfarm q4 | K18: ctax | L18: Taxes - customs duties (imports)
A19: ="a"&MID(B19,2,4) -> abean | B19: cbean | C19: Dried beans (A131) | E19: flab-kp | F19: Labor - Kigali primary | H19: hhd-n5 | I19: Rural - nonfarm q5 | K19: dtax | L19: Taxes - direct (corporate, private)
A20: ="a"&MID(B20,2,4) -> apeas | B20: cpeas | C20: Peas & other legumes (A132) | E20: flab-ks | F20: Labor - Kigali secondary | H20: hhd-u1 | I20: Urban - q1 | K20: etax | L20: Taxes - exports
A21: ="a"&MID(B21,2,4) -> avege | B21: cvege | C21: Other vegetables (A139) | E21: flab-kt | F21: Labor - Kigali tertiary | H21: hhd-u2 | I21: Urban - q2 | K21: ftax | L21: Taxes - factors (royalities)
... A26: ="a"&MID(B26,2,4) -> agnut | B26: cgnut | C26: Ground nuts (A151) | E26: fcap-n | F26: Capital - non-primary | H26: hhd-k2 | I26: Kigali - q2 | K26: s-i | L26: Savings-investment
A27: ="a"&MID(B27,2,4) -> asoya | B27: csoya | C27: Soya (A152) | H27: hhd-k3 | I27: Kigali - q3 | K27: dstk | L27: Change in stocks
A28: ="a"&MID(B28,2,4) -> aoils | B28: coils | C28: Other oil seeds (A159) | H28: hhd-k4 | I28: Kigali - q4 | K28: row | L28: Rest of world
A29: ="a"&MID(B29,2,4) -> acoff | B29: ccoff | C29: Coffee, not roasted, not decaffeinated (A210) | H29: hhd-k5 | I29: Kigali - q5 | K29: total | L29: Total
A30: ="a"&MID(B30,2,4) -> ateal | B30: cteal | C30: Tea (unprocessed green leaf) (A220)
A31: ="a"&MID(B31,2,4) -> atoba | B31: ctoba | C31: Tobacco, raw (A291)
A32: ="a"&MID(B32,2,4) -> asugr | B32: csugr | C32: Sugar cane (A292)
A33: ="a"&MID(B33,2,4) -> apyre | B33: cpyre | C33: Pyrethrum (A293)
A34: ="a"&MID(B34,2,4) -> aocrp | B34: cocrp | C34: Agricultural products n.e.c. (A299)
A35: ="a"&MID(B35,2,4) -> acatt | B35: ccatt | C35: Bovine cattle, live (A311)
A36: ="a"&MID(B36,2,4) -> asmlr | B36: csmlr | C36: Sheep, goats, pigs,live (A312)
A37: ="a"&MID(B37,2,4) -> apoul | B37: cpoul | C37: Poultry, live (A313)
A38: ="a"&MID(B38,2,4) -> aoliv | B38: coliv | C38: Other live animals (A319)
A39: ="a"&MID(B39,2,4) -> amilk | B39: cmilk | C39: Raw milk (A321)
A40: ="a"&MID(B40,2,4) -> aeggs | B40: ceggs | C40: Eggs (A322)
A41: ="a"&MID(B41,2,4) -> ahony | B41: chony | C41: Natural honey (A323)
... A113: ="a"&MID(B113,2,4) -> atrdc | B113: ctrdc | C113: Travel debits & credits (V00)

Sheet Index
A1: GDX index
A6: Type | B6: Name | C6: Location | D6: Row | E6: Column
D7: rdim | E7: cdim
A8: dset | B8: mac | C8: sets!a7 | D8: 1
A9: dset | B9: ac | C9: sets!b7 | D9: 1
A10: dset | B10: aac | C10: sets!c7 | D10: 1
A11: dset | B11: a | C11: sets!d7 | D11: 1
A12: dset | B12: aliv | C12: sets!e7 | D12: 1
A13: dset | B13: amin | C13: sets!f7 | D13: 1
A14: dset | B14: c | C14: sets!g7 | D14: 1
A15: dset | B15: f | C15: sets!h7 | D15: 1
A16: dset | B16: flab | C16: sets!i7 | D16: 1
A17: dset | B17: flnd | C17: sets!j7 | D17: 1
A18: dset | B18: fcap | C18: sets!k7 | D18: 1
A19: dset | B19: h | C19: sets!l7 | D19: 1
... A21: dset | B21: food | C21: sets!n7 | D21: 1
A22: set | B22: mapmac | C22: sets!q7 | D22: 2 | F22: values=nodata
A23: set | B23: mapac | C23: sets!t7 | D23: 2 | F23: values=nodata
A24: set | B24: mapaacac | C24: sets!w7 | D24: 2 | F24: values=nodata
A25: par | B25: facact | C25: fa!b7 | D25: 1 | E25: 1
A26: par | B26: miscfac | C26: mf!b6 | D26: 1 | E26: 2
A27: par | B27: hhdfac | C27: hf!b7 | D27: 1 | E27: 1
A28: par | B28: ownshr | C28: ah!b8 | D28: 1
A29: par | B29: acthhd | C29: ah!f7 | D29: 1 | E29: 1
A30: par | B30: comhhd | C30: ch!b7 | D30: 1 | E30: 1
A31: par | B31: mischhd | C31: mh!b6 | D31: 1 | E31: 2
A32: par | B32: hhddata | C32: mh!t7 | D32: 1 | E32: 1

Sheet Sets
A1: Sets | Q1: Mappings
A2: a | B2: b | C2: c | D2: d | E2: e | F2: f | G2: g | H2: h | I2: i | J2: j | K2: k | L2: l | M2: m | N2: n | O2: o | P2: p | Q2: q | R2: r | S2: s | T2: t | U2: u | V2: v | W2: w | X2: x | Y2: y | Z2: z
A4: Macro | B4: Micro accounts | D4: Activities | G4: Commodities | H4: Factors | L4: Households | M4: Taxes | N4: Food | Q4: Macro-micro accounts | T4: Activities-commodities | W4: National-all
A5: accounts | B5: All | C5: National | D5: All | E5: Livestock | F5: Mining | G5: All | H5: All | I5: Labor | J5: Land | K5: Capital | L5: All | N5: items | Q5: MMAC | T5: MAC | W5: MAACAC
A6: MAC | B6: AC | C6: AAC | D6: A | E6: ALIV | F6: AMIN | G6: C | H6: F | I6: FLAB | J6: FLND | K6: FCAP | L6: H | M6: T | N6: FOOD | Q6: MAC | R6: AC | T6: A | U6: C | W6: AAC | X6: AC
A7: mact | B7: asorg | C7: asorg | D7: asorg | E7: acatt | F7: angas | G7: csorg | H7: flab | I7: flab | J7: flnd | K7: fcap | L7: hhd | M7: atax | N7: asorg | Q7: mact | R7: asorg | T7: asorg | U7: csorg | W7: asorg | X7: asorg
A8: mcom | B8: amaiz | C8: amaiz | D8: amaiz | E8: asmlr | F8: amore | G8: cmaiz | H8: flab-rn | I8: flab-rn | K8: fcap-c | L8: hhd-f1 | M8: ctax | N8: amaiz | Q8: mact | R8: amaiz | T8: amaiz | U8: cmaiz | W8: amaiz | X8: amaiz
A9: mtrc | B9: awhea | C9: awhea | D9: awhea | E9: apoul | F9: aomin | G9: cwhea | H9: flab-rp | I9: flab-rp | K9: fcap-l | L9: hhd-f2 | M9: dtax | N9: awhea | Q9: mact | R9: awhea | T9: awhea | U9: cwhea | W9: awhea | X9: awhea
A10: mlab | B10: arice | C10: arice | D10: arice | E10: aoliv | G10: crice | H10: flab-rs | I10: flab-rs | K10: fcap-m | L10: hhd-f3 | M10: etax | N10: arice | Q10: mact | R10: arice | T10: arice | U10: crice | W10: arice | X10: arice
A11: mlnd | B11: aocer | C11: aocer | D11: aocer | E11: amilk | G11: cocer | H11: flab-rt | I11: flab-rt | K11: fcap-n | L11: hhd-f4 | M11: ftax | N11: aocer | Q11: mact | R11: aocer | T11: aocer | U11: cocer | W11: aocer | X11: aocer
A12: mcap | B12: aipot | C12: aipot | D12: aipot | E12: aeggs | G12: cipot | H12: flab-un | I12: flab-un | L12: hhd-f5 | M12: mtax | N12: aipot | Q12: mact | R12: aipot | T12: aipot | U12: cipot | W12: aipot | X12: aipot
A13: ment | B13: aspot | C13: aspot | D13: aspot | E13: ahony | G13: cspot | H13: flab-up | I13: flab-up | L13: hhd-n1 | M13: stax | N13: aspot | Q13: mact | R13: aspot | T13: aspot | U13: cspot | W13: aspot | X13: aspot
A14: mhhd | B14: acass | C14: acass | D14: acass | E14: ahunt | G14: ccass | H14: flab-us | I14: flab-us | L14: hhd-n2 | M14: vtax | N14: acass | Q14: mact | R14: acass | T14: acass | U14: ccass | W14: acass | X14: acass
A15: mgov | B15: aroot | C15: aroot | D15: aroot | G15: croot | H15: flab-ut | I15: flab-ut | L15: hhd-n3 | M15: xtax | N15: aroot | Q15: mact | R15: aroot | T15: aroot | U15: croot | W15: aroot | X15: aroot
A16: matx | B16: abean | C16: abean | D16: abean | G16: cbean | H16: flab-kn | I16: flab-kn | L16: hhd-n4 | N16: abean | Q16: mact | R16: abean | T16: abean | U16: cbean | W16: abean | X16: abean
A17: mctx | B17: apeas | C17: apeas | D17: apeas | G17: cpeas | H17: flab-kp | I17: flab-kp | L17: hhd-n5 | N17: apeas | Q17: mact | R17: apeas | T17: apeas | U17: cpeas | W17: apeas | X17: apeas
A18: mdtx | B18: avege | C18: avege | D18: avege | G18: cvege | H18: flab-ks | I18: flab-ks | L18: hhd-u1 | N18: avege | Q18: mact | R18: avege | T18: avege | U18: cvege | W18: avege | X18: avege
A19: metx | B19: abanb | C19: abanb | D19: abanb | G19: cbanb | H19: flab-kt | I19: flab-kt | L19: hhd-u2 | N19: abanb | Q19: mact | R19: abanb | T19: abanb | U19: cbanb | W19: abanb | X19: abanb
A20: mftx | B20: abanc | C20: abanc | D20: abanc | G20: cbanc | H20: flnd | L20: hhd-u3 | N20: abanc | Q20: mact | R20: abanc | T20: abanc | U20: cbanc | W20: abanc | X20: abanc
A21: mmtx | B21: abans | C21: abans | D21: abans | G21: cbans | H21: fcap | L21: hhd-u4 | N21: abans | Q21: mact | R21: abans | T21: abans | U21: cbans | W21: abans | X21: abans
A22: mstx | B22: afrui | C22: afrui | D22: afrui | G22: cfrui | H22: fcap-c | L22: hhd-u5 | N22: afrui | Q22: mact | R22: afrui | T22: afrui | U22: cfrui | W22: afrui | X22: afrui
A23: mvtx | B23: agnut | C23: agnut | D23: agnut | G23: cgnut | H23: fcap-l | L23: hhd-k1 | N23: agnut | Q23: mact | R23: agnut | T23: agnut | U23: cgnut | W23: agnut | X23: agnut
A24: mxtx | B24: asoya | C24: asoya | D24: asoya | G24: csoya | H24: fcap-m | L24: hhd-k2 | N24: asoya | Q24: mact | R24: asoya | T24: asoya | U24: csoya | W24: asoya | X24: asoya
A25: ms-i | B25: aoils | C25: aoils | D25: aoils | G25: coils | H25: fcap-n | L25: hhd-k3 | N25: aoils | Q25: mact | R25: aoils | T25: aoils | U25: coils | W25: aoils | X25: aoils
A26: mg-i | B26: acoff | C26: acoff | D26: acoff | G26: ccoff | L26: hhd-k4 | N26: asugr | Q26: mact | R26: acoff | T26: acoff | U26: ccoff | W26: acoff | X26: acoff
A27: mstk | B27: ateal | C27: ateal | D27: ateal | G27: cteal | L27: hhd-k5 | N27: acatt | Q27: mact | R27: ateal | T27: ateal | U27: cteal | W27: ateal | X27: ateal
A28: mrow | B28: atoba | C28: atoba | D28: atoba | G28: ctoba | N28: asmlr | Q28: mact | R28: atoba | T28: atoba | U28: ctoba | W28: atoba | X28: atoba
A29: mtot | B29: asugr | C29: asugr | D29: asugr | G29: csugr | N29: apoul | Q29: mact | R29: asugr | T29: asugr | U29: csugr | W29: asugr | X29: asugr
B30: apyre | C30: apyre | D30: apyre | G30: cpyre | N30: aoliv | Q30: mact | R30: apyre | T30: apyre | U30: cpyre | W30: apyre | X30: apyre
B31: aocrp | C31: aocrp | D31: aocrp | G31: cocrp | N31: amilk | Q31: mact | R31: aocrp | T31: aocrp | U31: cocrp | W31: aocrp | X31: aocrp
B32: acatt | C32: acatt | D32: acatt | G32: ccatt | N32: aeggs | Q32: mact | R32: acatt | T32: acatt | U32: ccatt | W32: acatt | X32: acatt
B33: asmlr | C33: asmlr | D33: asmlr | G33: csmlr | N33: ahony | Q33: mact | R33: asmlr | T33: asmlr | U33: csmlr | W33: asmlr | X33: asmlr
B34: apoul | C34: apoul | D34: apoul | G34: cpoul | N34: ahunt | Q34: mact | R34: apoul | T34: apoul | U34: cpoul | W34: apoul | X34: apoul
B35: aoliv | C35: aoliv | D35: aoliv | G35: coliv | N35: afish | Q35: mact | R35: aoliv | T35: aoliv | U35: coliv | W35: aoliv | X35: aoliv
B36: amilk | C36: amilk | D36: amilk | G36: cmilk | N36: ameat | Q36: mact | R36: amilk | T36: amilk | U36: cmilk | W36: amilk | X36: amilk
B37: aeggs | C37: aeggs | D37: aeggs | G37: ceggs | N37: afsea | Q37: mact | R37: aeggs | T37: aeggs | U37: ceggs | W37: aeggs | X37: aeggs
B38: ahony | C38: ahony | D38: ahony | G38: chony | N38: afveg | Q38: mact | R38: ahony | T38: ahony | U38: chony | W38: ahony | X38: ahony
B39: ahunt | C39: ahunt | D39: ahunt | G39: chunt | N39: afoil | Q39: mact | R39: ahunt | T39: ahunt | U39: chunt | W39: ahunt | X39: ahunt
B40: afuel | C40: afuel | D40: afuel | G40: cfuel | N40: adair | Q40: mact | R40: afuel | T40: afuel | U40: cfuel | W40: afuel | X40: afuel
B41: achar | C41: achar | D41: achar | G41: cchar | N41: agmll | Q41: mact | R41: achar | T41: achar | U41: cchar | W41: achar | X41: achar
...

Sheet FA
A1: Factor income generation
A4: Disaggregated factors' share of national aggregate factor value-added
A5: FACACT | C5: Labor | O5: Land | P5: Capital
C6: Rural uneducated | D6: Rural primary | E6: Rural secondary | F6: Rural tertiary | G6: Urban uneducated | H6: Urban primary | I6: Urban secondary | J6: Urban tertiary | K6: Kigali uneducated | L6: Kigali primary | M6: Kigali secondary | N6: Kigali tertiary | O6: Crops | P6: Crops | Q6: Livestock | R6: Mining | S6: Other
C7: flab-rn | D7: flab-rp | E7: flab-rs | F7: flab-rt | G7: flab-un | H7: flab-up | I7: flab-us | J7: flab-ut | K7: flab-kn | L7: flab-kp | M7: flab-ks | N7: flab-kt | O7: flnd | P7: fcap-c | Q7: fcap-l | R7: fcap-m | S7: fcap-n
A8: Sorghum (A111) | B8: asorg | C8: =SVY!D7 -> 0.49259772 | D8: =SVY!E7 -> 0.3616742 | E8: =SVY!F7 -> 0.039480441 | F8: =SVY!G7 -> 0.010552685 | G8: =SVY!H7 -> 0.010225128 | H8: =SVY!I7 -> 0.018300974 | I8: =SVY!J7 -> 0.0045167072 | J8: =SVY!K7 -> 0.0054580675 | ... N8: =SVY!O7 -> 0.0087581275 | O8: 1 | P8: 1
A9: Maize (A112) | B9: amaiz | C9: =SVY!D8 -> 0.49922869 | D9: =SVY!E8 -> 0.36654278 | E9: =SVY!F8 -> 0.040011896 | F9: =SVY!G8 -> 0.010694737 | G9: =SVY!H8 -> 0.010577163 | H9: =SVY!I8 -> 0.018931048 | I9: =SVY!J8 -> 0.0046722106 | J9: =SVY!K8 -> 0.0056459805 | ... N9: =SVY!O8 -> 0.006691091 | O9: 1 | P9: 1
A10: Wheat (A113) | B10: awhea | C10: =SVY!D9 -> 0.52564511 | D10: =SVY!E9 -> 0.38593819 | E10: =SVY!F9 -> 0.042129104 | F10: =SVY!G9 -> 0.011260643 | G10: =SVY!H9 -> 0.006800444 | H10: =SVY!I9 -> 0.012171461 | I10: =SVY!J9 -> 0.0030039345 | J10: =SVY!K9 -> 0.0036300068 | ... N10: =SVY!O9 -> 0.0014426538 | O10: 1 | P10: 1
A11: Paddy & husked rice (A116) | B11: arice | C11: =SVY!D10 -> 0.50532883 | D11: =SVY!E10 -> 0.37102161 | E11: =SVY!F10 -> 0.040500806 | F11: =SVY!G10 -> 0.010825417 | G11: =SVY!H10 -> 0.015833767 | H11: =SVY!I10 -> 0.028339338 | I11: =SVY!J10 -> 0.0069941903 | J11: =SVY!K10 -> 0.0084519012 | ... N11: =SVY!O10 -> 0.0019453855 | O11: 1 | P11: 1
A12: Other cereals (A119) | B12: aocer | C12: =SVY!D11 -> 0.53530655 | D12: =SVY!E11 -> 0.39303179 | E12: =SVY!F11 -> 0.042903443 | F12: =SVY!G11 -> 0.011467615 | G12: =SVY!H11 -> 0.0026795475 | H12: =SVY!I11 -> 0.0047958646 | I12: =SVY!J11 -> 0.0011836264 | J12: =SVY!K11 -> 0.0014303148 | ... N12: =SVY!O11 -> 0.001102727 | O12: 1 | P12: 1
A13: Irish potatoes (A121) | B13: aipot | C13: =SVY!D12 -> 0.46720129 | D13: =SVY!E12 -> 0.37726805 | E13: =SVY!F12 -> 0.026879792 | F13: =SVY!G12 -> 0.011946 | G13: =SVY!H12 -> 0.025108999 | H13: =SVY!I12 -> 0.026689454 | I13: =SVY!J12 -> 0.037589338 | J13: =SVY!K12 -> 0.0074107533 | ... N13: =SVY!O12 -> 0.0035005913 | O13: 1 | P13: 1
A14: Sweet potatoes (A122) | B14: aspot | C14: =SVY!D13 -> 0.50527702 | D14: =SVY!E13 -> 0.40801445 | E14: =SVY!F13 -> 0.029070428 | F14: =SVY!G13 -> 0.012919569 | G14: =SVY!H13 -> 0.005590998 | H14: =SVY!I13 -> 0.0059429163 | I14: =SVY!J13 -> 0.0083699836 | J14: =SVY!K13 -> 0.0016501457 | ... N14: =SVY!O13 -> 0.0040735494 | O14: 1 | P14: 1
A15: Cassava (A123) | B15: acass | C15: =SVY!D14 -> 0.49036261 | D15: =SVY!E14 -> 0.39597097 | E15: =SVY!F14 -> 0.028212347 | F15: =SVY!G14 -> 0.012538219 | G15: =SVY!H14 -> 0.0082632319 | H15: =SVY!I14 -> 0.0087833506 | I15: =SVY!J14 -> 0.012370442 | J15: =SVY!K14 -> 0.0024388376 | ... N15: =SVY!O14 -> 0.0072205318 | O15: 1 | P15: 1
A16: Other roots & tubers (A129) | B16: aroot | C16: =SVY!D15 -> 0.49775754 | D16: =SVY!E15 -> 0.40194242 | E16: =SVY!F15 -> 0.028637804 | F16: =SVY!G15 -> 0.012727302 | G16: =SVY!H15 -> 0.0070264783 | H16: =SVY!I15 -> 0.0074687511 | I16: =SVY!J15 -> 0.010518964 | J16: =SVY!K15 -> 0.0020738181 | ... N16: =SVY!O15 -> 0.005600384 | O16: 1 | P16: 1
A17: Dried beans (A131) | B17: abean | C17: =SVY!D16 -> 0.47919011 | D17: =SVY!E16 -> 0.3588048 | E17: =SVY!F16 -> 0.029643078 | F17: =SVY!G16 -> 0.011400722 | G17: =SVY!H16 -> 0.010822825 | H17: =SVY!I16 -> 0.016164162 | I17: =SVY!J16 -> 0.0054678963 | J17: =SVY!K16 -> 0.0036284212 | ... N17: =SVY!O16 -> 0.028753901 | O17: 1 | P17: 1
A18: Peas & other legumes (A132) | B18: apeas | C18: =SVY!D17 -> 0.47919011 | D18: =SVY!E17 -> 0.3588048 | E18: =SVY!F17 -> 0.029643078 | F18: =SVY!G17 -> 0.011400722 | G18: =SVY!H17 -> 0.010822825 | H18: =SVY!I17 -> 0.016164162 | I18: =SVY!J17 -> 0.0054678963 | J18: =SVY!K17 -> 0.0036284212 | ... N18: =SVY!O17 -> 0.028753901 | O18: 1 | P18: 1
A19: Other vegetables (A139) | B19: avege | C19: =SVY!D18 -> 0.47666172 | D19: =SVY!E18 -> 0.35691162 | E19: =SVY!F18 -> 0.02948667 | F19: =SVY!G18 -> 0.011340567 | G19: =SVY!H18 -> 0.019748059 | H19: =SVY!I18 -> 0.029494225 | I19: =SVY!J18 -> 0.0099770938 | J19: =SVY!K18 -> 0.006620663 | ... N19: =SVY!O18 -> 0.020244537 | O19: 1 | P19: 1
... A32: Agricultural products n.e.c. (A299) | B32: aocrp | C32: =SVY!D31 -> 0.47617212 | D32: =SVY!E31 -> 0.41450317 | E32: =SVY!F31 -> 0.015059169 | F32: =SVY!G31 -> 0.013068783 | G32: =SVY!H31 -> 0.032551894 | H32: =SVY!I31 -> 0.012207592 | I32: =SVY!J31 -> 0.0054582272 | J32: =SVY!K31 -> 0.016426124 | ... N32: =SVY!O31 -> 0.00041980755 | O32: 1 | P32: 1
A33: Bovine cattle, live (A311) | B33: acatt | C33: =SVY!D32 -> 0.44064905 | D33: =SVY!E32 -> 0.29085561 | E33: =SVY!F32 -> 0.027823024 | F33: =SVY!G32 -> 0.015604799 | G33: =SVY!H32 -> 0.017860947 | H33: =SVY!I32 -> 0.025417589 | I33: =SVY!J32 -> 0.022653569 | J33: =SVY!K32 -> 0.015675612 | ... N33: =SVY!O32 -> 0.029486613 | Q33: 1
A34: Sheep, goats, pigs,live (A312) | B34: asmlr | C34: =SVY!D33 -> 0.47916601 | D34: =SVY!E33 -> 0.34824836 | E34: =SVY!F33 -> 0.02921921 | F34: =SVY!G33 -> 0.013476399 | G34: =SVY!H33 -> 0.018838165 | H34: =SVY!I33 -> 0.025188021 | I34: =SVY!J33 -> 0.004754479 | J34: =SVY!K33 -> 0.0038552281 | ... N34: =SVY!O33 -> 0.021664515 | Q34: 1
A35: Poultry, live (A313) | B35: apoul | C35: =SVY!D34 -> 0.46923066 | D35: =SVY!E34 -> 0.2519272 | E35: =SVY!F34 -> 0.025170528 | F35: =SVY!G34 -> 0.036820588 | G35: =SVY!H34 -> 0.016914831 | H35: =SVY!I34 -> 0.041870871 | I35: =SVY!J34 -> 0.012848248 | J35: =SVY!K34 -> 0.051554101 | ... N35: =SVY!O34 -> 0.016602008 | Q35: 1
A36: Other live animals (A319) | B36: aoliv | C36: =SVY!D35 -> 0.46424309 | D36: =SVY!E35 -> 0.33740268 | E36: =SVY!F35 -> 0.028309221 | F36: =SVY!G35 -> 0.013056697 | G36: =SVY!H35 -> 0.019186691 | H36: =SVY!I35 -> 0.025654027 | I36: =SVY!J35 -> 0.0048424421 | J36: =SVY!K35 -> 0.003926554 | ... N36: =SVY!O35 -> 0.028990647 | Q36: 1
A37: Raw milk (A321) | B37: amilk | C37: =SVY!D36 -> 0.24418869 | D37: =SVY!E36 -> 0.16647005 | E37: =SVY!F36 -> 0.022646827 | F37: =SVY!G36 -> 0.0086551802 | G37: =SVY!H36 -> 0.018401586 | H37: =SVY!I36 -> 0.03540589 | I37: =SVY!J36 -> 0.026246361 | J37: =SVY!K36 -> 0.01877357 | ... N37: =SVY!O36 -> 0.1119317 | Q37: 1
A38: Eggs (A322) | B38: aeggs | C38: =SVY!D37 -> 0.29290897 | D38: =SVY!E37 -> 0.30232267 | E38: =SVY!F37 -> 0.013736516 | F38: =SVY!G37 -> 0.005926831 | G38: =SVY!H37 -> 0.018325613 | H38: =SVY!I37 -> 0.0091038585 | I38: =SVY!J37 -> 0.0047548965 | J38: =SVY!K37 -> 0.16574323 | ... N38: =SVY!O37 -> 0.0019851997 | Q38: 1
A39: Natural honey (A323) | B39: ahony | C39: =SVY!D38 -> 0.46424309 | D39: =SVY!E38 -> 0.33740268 | E39: =SVY!F38 -> 0.028309221 | F39: =SVY!G38 -> 0.013056697 | G39: =SVY!H38 -> 0.019186691 | H39: =SVY!I38 -> 0.025654027 | I39: =SVY!J38 -> 0.0048424421 | J39: =SVY!K38 -> 0.003926554 | ... N39: =SVY!O38 -> 0.028990647 | Q39: 1
A40: Other livestock & hunting products (A329) | B40: ahunt | C40: =SVY!D39 -> 0.4547593 | D40: =SVY!E39 -> 0.33051004 | E40: =SVY!F39 -> 0.027730906 | F40: =SVY!G39 -> 0.012789968 | G40: =SVY!H39 -> 0.042360641 | H40: =SVY!I39 -> 0.056639314 | I40: =SVY!J39 -> 0.01069121 | J40: =SVY!K39 -> 0.0086690999 | ... N40: =SVY!O39 -> 0.015661983 | Q40: 1
A41: Fuel wood (A401) | B41: afuel | C41: =SVY!D40 -> 0.394288 | D41: =SVY!E40 -> 0.49627498 | E41: =SVY!F40 -> 0.025290128 | F41: =SVY!G40 -> 0 | G41: =SVY!H40 -> 0.035301789 | H41: =SVY!I40 -> 0.012803404 | I41: =SVY!J40 -> 0 | J41: =SVY!K40 -> 0 | ... N41: =SVY!O40 -> 0 | P41: 1
A42: Charcoal (A402) | B42: achar | C42: =SVY!D41 -> 0.394288 | D42: =SVY!E41 -> 0.49627498 | E42: =SVY!F41 -> 0.025290128 | F42: =SVY!G41 -> 0 | G42: =SVY!H41 -> 0.035301789 | H42: =SVY!I41 -> 0.012803404 | I42: =SVY!J41 -> 0 | J42: =SVY!K41 -> 0 | ... N42: =SVY!O41 -> 0 | P42: 1
A43: Other forestry products (A409) | B43: afore | C43: =SVY!D42 -> 0.394288 | D43: =SVY!E42 -> 0.49627498 | E43: =SVY!F42 -> 0.025290128 | F43: =SVY!G42 -> 0 | G43: =SVY!H42 -> 0.035301789 | H43: =SVY!I42 -> 0.012803404 | I43: =SVY!J42 -> 0 | J43: =SVY!K42 -> 0 | ... N43: =SVY!O42 -> 0 | P43: 1
A44: Fishery products (A500) | B44: afish | C44: =SVY!D43 -> 0.52569482 | D44: =SVY!E43 -> 0.43704433 | E44: =SVY!F43 -> 0.037260841 | F44: =SVY!G43 -> 0 | G44: =SVY!H43 -> 0 | H44: =SVY!I43 -> 0 | I44: =SVY!J43 -> 0 | J44: =SVY!K43 -> 0 | ... N44: =SVY!O43 -> 0 | P44: 1
A45: Natural gas (B01) | B45: angas | C45: =SVY!D44 -> 0.35876341 | D45: =SVY!E44 -> 0.56076169 | E45: =SVY!F44 -> 0.01558566 | F45: =SVY!G44 -> 0 | G45: =SVY!H44 -> 0 | H45: =SVY!I44 -> 0.0060375086 | I45: =SVY!J44 -> 0 | J45: =SVY!K44 -> 0 | ... N45: =SVY!O44 -> 0.038798807 | R45: 1
A46: Metal ores (B03) | B46: amore | C46: =SVY!D45 -> 0.34721191 | D46: =SVY!E45 -> 0.54270623 | E46: =SVY!F45 -> 0.015083831 | F46: =SVY!G45 -> 0 | G46: =SVY!H45 -> 0 | H46: =SVY!I45 -> 0.012075017 | I46: =SVY!J45 -> 0 | J46: =SVY!K45 -> 0 | ... N46: =SVY!O45 -> 0.054668128 | R46: 1
A47: Quarry & other mining products (B09) | B47: aomin | C47: =SVY!D46 -> 0.37031491 | D47: =SVY!E46 -> 0.57881715 | E47: =SVY!F46 -> 0.016087488 | F47: =SVY!G46 -> 0 | G47: =SVY!H46 -> 0 | H47: =SVY!I46 -> 0 | I47: =SVY!J46 -> 0 | J47: =SVY!K46 -> 0 | ... N47: =SVY!O46 -> 0.022929486 | R47: 1
A48: Meat and meat products (C11) | B48: ameat | C48: =SVY!D47 -> 0.23432434 | D48: =SVY!E47 -> 0.42270003 | E48: =SVY!F47 -> 0.0889595 | F48: =SVY!G47 -> 0.050460745 | G48: =SVY!H47 -> 0.023204384 | H48: =SVY!I47 -> 0.032578796 | I48: =SVY!J47 -> 0.022611435 | J48: =SVY!K47 -> 0 | ... N48: =SVY!O47 -> 0.030962795 | S48: 1
A49: Prepared and preserved fish (C12) | B49: afsea | C49: =SVY!D48 -> 0.25170213 | D49: =SVY!E48 -> 0.45404801 | E49: =SVY!F48 -> 0.095556851 | F49: =SVY!G48 -> 0.054202979 | G49: =SVY!H48 -> 0.011977674 | H49: =SVY!I48 -> 0.016816572 | I49: =SVY!J48 -> 0.011671605 | J49: =SVY!K48 -> 0 | ... N49: =SVY!O48 -> 0.025733937 | S49: 1
A50: Prepared and preserved vegetables (C13) | B50: afveg | C50: =SVY!D49 -> 0.25158408 | D50: =SVY!E49 -> 0.45383506 | E50: =SVY!F49 -> 0.095512034 | F50: =SVY!G49 -> 0.054177557 | G50: =SVY!H49 -> 0.014966548 | H50: =SVY!I49 -> 0.02101293 | I50: =SVY!J49 -> 0.014584103 | J50: =SVY!K49 -> 0 | ... N50: =SVY!O49 -> 0.023335179 | S50: 1
A51: Animal and vegetable oils and fats (C14) | B51: afoil | C51: =SVY!D50 -> 0.26092101 | D51: =SVY!E50 -> 0.47067803 | E51: =SVY!F50 -> 0.09905673 | F51: =SVY!G50 -> 0.056188225 | G51: =SVY!H50 -> 0.010444608 | H51: =SVY!I50 -> 0.014664158 | I51: =SVY!J50 -> 0.010177713 | J51: =SVY!K50 -> 0 | ... N51: =SVY!O50 -> 0.019263689 | S51: 1
A52: Dairy products (C15) | B52: adair | C52: =SVY!D51 -> 0.16961094 | D52: =SVY!E51 -> 0.30596288 | E52: =SVY!F51 -> 0.064391537 | F52: =SVY!G51 -> 0.036524991 | G52: =SVY!H51 -> 0.026603865 | H52: =SVY!I51 -> 0.037351643 | I52: =SVY!J51 -> 0.025924047 | J52: =SVY!K51 -> 0 | ... N52: =SVY!O51 -> 0.082534812 | S52: 1
A53: Grain mill products (C16) | B53: agmll | C53: =SVY!D52 -> 0.26514288 | D53: =SVY!E52 -> 0.4782939 | E53: =SVY!F52 -> 0.10065953 | F53: =SVY!G52 -> 0.057097386 | G53: =SVY!H52 -> 0.012558725 | H53: =SVY!I52 -> 0.017632363 | I53: =SVY!J52 -> 0.012237808 | J53: =SVY!K52 -> 0 | ... N53: =SVY!O52 -> 0.013946879 | S53: 1
A54: Bakery products (C17) | B54: abake | C54: =SVY!D53 -> 0.20919129 | D54: =SVY!E53 -> 0.37736227 | E54: =SVY!F53 -> 0.079417925 | F54: =SVY!G53 -> 0.045048451 | G54: =SVY!H53 -> 0.023955349 | H54: =SVY!I53 -> 0.033633144 | I54: =SVY!J53 -> 0.02334321 | J54: =SVY!K53 -> 0 | ... N54: =SVY!O53 -> 0.051467874 | S54: 1
...

Sheet MF
A1: Miscellaneous factor accounts
A3: Disaggregated factors' income and expenditure shares
A4: MISCFAC | C4: Expenditure shares (sums to 1) | G4: Income shares (need not sum to 1)
C5: Households | D5: Government | E5: Factor taxes | F5: Rest of world | G5: Government | H5: Rest of world
C6: exp | D6: exp | E6: exp | F6: exp | G6: inc | H6: inc
C7: hhd | D7: gov | E7: ftax | F7: row | G7: gov | H7: row
A8: Labor - rural uneducated | B8: flab-rn | C8: =SVY!D505 -> 0.98354243 | D8: =SVY!E505 -> 0 | E8: =SVY!F505 -> 0 | F8: =SVY!G505 -> 0.016457574 | G8: =SVY!H505 -> 0 | H8: =SVY!I505 -> 0.0016453087
A9: Labor - rural primary | B9: flab-rp | C9: =SVY!D506 -> 0.98354243 | D9: =SVY!E506 -> 0 | E9: =SVY!F506 -> 0 | F9: =SVY!G506 -> 0.016457574 | G9: =SVY!H506 -> 0 | H9: =SVY!I506 -> 0.0016453087
A10: Labor - rural secondary | B10: flab-rs | C10: =SVY!D507 -> 0.98354243 | D10: =SVY!E507 -> 0 | E10: =SVY!F507 -> 0 | F10: =SVY!G507 -> 0.016457574 | G10: =SVY!H507 -> 0 | H10: =SVY!I507 -> 0.0016453087
A11: Labor - rural tertiary | B11: flab-rt | C11: =SVY!D508 -> 0.98354243 | D11: =SVY!E508 -> 0 | E11: =SVY!F508 -> 0 | F11: =SVY!G508 -> 0.016457574 | G11: =SVY!H508 -> 0 | H11: =SVY!I508 -> 0.0016453087
A12: Labor - urban uneducated | B12: flab-un | C12: =SVY!D509 -> 0.98354243 | D12: =SVY!E509 -> 0 | E12: =SVY!F509 -> 0 | F12: =SVY!G509 -> 0.016457574 | G12: =SVY!H509 -> 0 | H12: =SVY!I509 -> 0.0016453087
A13: Labor - urban primary | B13: flab-up | C13: =SVY!D510 -> 0.98354243 | D13: =SVY!E510 -> 0 | E13: =SVY!F510 -> 0 | F13: =SVY!G510 -> 0.016457574 | G13: =SVY!H510 -> 0 | H13: =SVY!I510 -> 0.0016453087
A14: Labor - urban secondary | B14: flab-us | C14: =SVY!D511 -> 0.98354243 | D14: =SVY!E511 -> 0 | E14: =SVY!F511 -> 0 | F14: =SVY!G511 -> 0.016457574 | G14: =SVY!H511 -> 0 | H14: =SVY!I511 -> 0.0016453087
A15: Labor - urban tertiary | B15: flab-ut | C15: =SVY!D512 -> 0.98354243 | D15: =SVY!E512 -> 0 | E15: =SVY!F512 -> 0 | F15: =SVY!G512 -> 0.016457574 | G15: =SVY!H512 -> 0 | H15: =SVY!I512 -> 0.0016453087
A16: Labor - Kigali uneducated | B16: flab-kn | C16: =SVY!D513 -> 0.98354243 | D16: =SVY!E513 -> 0 | E16: =SVY!F513 -> 0 | F16: =SVY!G513 -> 0.016457574 | G16: =SVY!H513 -> 0 | H16: =SVY!I513 -> 0.0016453087
A17: Labor - Kigali primary | B17: flab-kp | C17: =SVY!D514 -> 0.98354243 | D17: =SVY!E514 -> 0 | E17: =SVY!F514 -> 0 | F17: =SVY!G514 -> 0.016457574 | G17: =SVY!H514 -> 0 | H17: =SVY!I514 -> 0.0016453087
A18: Labor - Kigali secondary | B18: flab-ks | C18: =SVY!D515 -> 0.98354243 | D18: =SVY!E515 -> 0 | E18: =SVY!F515 -> 0 | F18: =SVY!G515 -> 0.016457574 | G18: =SVY!H515 -> 0 | H18: =SVY!I515 -> 0.0016453087
A19: Labor - Kigali tertiary | B19: flab-kt | C19: =SVY!D516 -> 0.98354243 | D19: =SVY!E516 -> 0 | E19: =SVY!F516 -> 0 | F19: =SVY!G516 -> 0.016457574 | G19: =SVY!H516 -> 0 | H19: =SVY!I516 -> 0.0016453087
... A24: Capital - non-primary | B24: fcap-n | C24: =SVY!D521 -> 0.92203986 | D24: =SVY!E521 -> 0.00045503844 | E24: =SVY!F521 -> 0 | F24: =SVY!G521 -> 0.077505104 | G24: =SVY!H521 -> 0 | H24: =SVY!I521 -> 0.0039541628

Sheet HF
A1: Factor payments to households
A4: Share of factor incomes distributed to different households
A5: HHDFAC | C5: Labor | O5: Land | P5: Capital
C6: Labor - rural uneducated | D6: Labor - rural primary | E6: Labor - rural secondary | F6: Labor - rural tertiary | G6: Labor - urban uneducated | H6: Labor - urban primary | I6: Labor - urban secondary | J6: Labor - urban tertiary | K6: Labor - Kigali uneducated | L6: Labor - Kigali primary | M6: Labor - Kigali secondary | N6: Labor - Kigali tertiary | O6: Crop land | P6: Crops | Q6: Livestock
C7: flab-rn | D7: flab-rp | E7: flab-rs | F7: flab-rt | G7: flab-un | H7: flab-up | I7: flab-us | J7: flab-ut | K7: flab-kn | L7: flab-kp | M7: flab-ks | N7: flab-kt | O7: flnd | P7: fcap-c | Q7: fcap-l
A8: Rural - farm q1 | B8: hhd-f1 | C8: =SVY!D452 -> 0.19998698 | D8: =SVY!E452 -> 0.12327347 | E8: =SVY!F452 -> 0.022663474 | F8: =SVY!G452 -> 0.00090909863 | G8: =SVY!H452 -> 0 | H8: =SVY!I452 -> 0 | I8: =SVY!J452 -> 0 | J8: =SVY!K452 -> 0 | ... Q8: =SVY!R452 -> 0.10079254
A9: Rural - farm q2 | B9: hhd-f2 | C9: =SVY!D453 -> 0.16962729 | D9: =SVY!E453 -> 0.1465441 | E9: =SVY!F453 -> 0.062567709 | F9: =SVY!G453 -> 0.0063945346 | G9: =SVY!H453 -> 0 | H9: =SVY!I453 -> 0 | I9: =SVY!J453 -> 0 | J9: =SVY!K453 -> 0 | ... Q9: =SVY!R453 -> 0.11383123
A10: Rural - farm q3 | B10: hhd-f3 | C10: =SVY!D454 -> 0.22046459 | D10: =SVY!E454 -> 0.20923347 | E10: =SVY!F454 -> 0.099784582 | F10: =SVY!G454 -> 0.0054874271 | G10: =SVY!H454 -> 0 | H10: =SVY!I454 -> 0 | I10: =SVY!J454 -> 0 | J10: =SVY!K454 -> 0 | ... Q10: =SVY!R454 -> 0.15986297
A11: Rural - farm q4 | B11: hhd-f4 | C11: =SVY!D455 -> 0.20649287 | D11: =SVY!E455 -> 0.22545432 | E11: =SVY!F455 -> 0.18535615 | F11: =SVY!G455 -> 0.12605772 | G11: =SVY!H455 -> 0 | H11: =SVY!I455 -> 0 | I11: =SVY!J455 -> 0 | J11: =SVY!K455 -> 0 | ... Q11: =SVY!R455 -> 0.19494254
A12: Rural - farm q5 | B12: hhd-f5 | C12: =SVY!D456 -> 0.103778 | D12: =SVY!E456 -> 0.17284774 | E12: =SVY!F456 -> 0.32959945 | F12: =SVY!G456 -> 0.38031867 | G12: =SVY!H456 -> 0 | H12: =SVY!I456 -> 0 | I12: =SVY!J456 -> 0 | J12: =SVY!K456 -> 0 | ... Q12: =SVY!R456 -> 0.12893035
A13: Rural - nonfarm q1 | B13: hhd-n1 | C13: =SVY!D457 -> 0.0092585833 | D13: =SVY!E457 -> 0.0033831982 | E13: =SVY!F457 -> 0 | F13: =SVY!G457 -> 0 | G13: =SVY!H457 -> 0 | H13: =SVY!I457 -> 0 | I13: =SVY!J457 -> 0 | J13: =SVY!K457 -> 0 | ... Q13: =SVY!R457 -> 0
A14: Rural - nonfarm q2 | B14: hhd-n2 | C14: =SVY!D458 -> 0.0031128255 | D14: =SVY!E458 -> 0.0037687682 | E14: =SVY!F458 -> 0.0019443243 | F14: =SVY!G458 -> 0 | G14: =SVY!H458 -> 0 | H14: =SVY!I458 -> 0 | I14: =SVY!J458 -> 0 | J14: =SVY!K458 -> 0 | ... Q14: =SVY!R458 -> 0
A15: Rural - nonfarm q3 | B15: hhd-n3 | C15: =SVY!D459 -> 0.010525274 | D15: =SVY!E459 -> 0.0099784499 | E15: =SVY!F459 -> 0.012743831 | F15: =SVY!G459 -> 0 | G15: =SVY!H459 -> 0 | H15: =SVY!I459 -> 0 | I15: =SVY!J459 -> 0 | J15: =SVY!K459 -> 0 | ... Q15: =SVY!R459 -> 0
A16: Rural - nonfarm q4 | B16: hhd-n4 | C16: =SVY!D460 -> 0.060890531 | D16: =SVY!E460 -> 0.062007005 | E16: =SVY!F460 -> 0.10484692 | F16: =SVY!G460 -> 0.068621996 | G16: =SVY!H460 -> 0 | H16: =SVY!I460 -> 0 | I16: =SVY!J460 -> 0 | J16: =SVY!K460 -> 0 | ... Q16: =SVY!R460 -> 0
A17: Rural - nonfarm q5 | B17: hhd-n5 | C17: =SVY!D461 -> 0.015863055 | D17: =SVY!E461 -> 0.043509482 | E17: =SVY!F461 -> 0.18049355 | F17: =SVY!G461 -> 0.41221056 | G17: =SVY!H461 -> 0 | H17: =SVY!I461 -> 0 | I17: =SVY!J461 -> 0 | J17: =SVY!K461 -> 0 | ... Q17: =SVY!R461 -> 0
A18: Urban - q1 | B18: hhd-u1 | C18: =SVY!D462 -> 0 | D18: =SVY!E462 -> 0 | E18: =SVY!F462 -> 0 | F18: =SVY!G462 -> 0 | G18: =SVY!H462 -> 0.15180034 | H18: =SVY!I462 -> 0.058134351 | I18: =SVY!J462 -> 0.0061220309 | J18: =SVY!K462 -> 0.0017944513 | ... Q18: =SVY!R462 -> 0.0056056852
A19: Urban - q2 | B19: hhd-u2 | C19: =SVY!D463 -> 0 | D19: =SVY!E463 -> 0 | E19: =SVY!F463 -> 0 | F19: =SVY!G463 -> 0 | G19: =SVY!H463 -> 0.15009388 | H19: =SVY!I463 -> 0.079049772 | I19: =SVY!J463 -> 0.012260127 | J19: =SVY!K463 -> 0.0035936116 | ... Q19: =SVY!R463 -> 0.0062917267
... A27: Kigali - q5 | B27: hhd-k5 | C27: =SVY!D471 -> 0 | D27: =SVY!E471 -> 0 | E27: =SVY!F471 -> 0 | F27: =SVY!G471 -> 0 | G27: =SVY!H471 -> 0 | H27: =SVY!I471 -> 0 | I27: =SVY!J471 -> 0 | J27: =SVY!K471 -> 0 | ... Q27: =SVY!R471 -> 0.10748496

Sheet AH
A1: Household own consumption
F4: Households' share of own consumption
B5: Own consumption share of | F5: ACTHHD | G5: Households
B6: total household consumption | G6: Rural - farm q1 | H6: Rural - farm q2 | I6: Rural - farm q3 | J6: Rural - farm q4 | K6: Rural - farm q5 | L6: Rural - nonfarm q1 | M6: Rural - nonfarm q2 | N6: Rural - nonfarm q3 | O6: Rural - nonfarm q4 | P6: Rural - nonfarm q5 | Q6: Urban - q1 | R6: Urban - q2 | S6: Urban - q3 | T6: Urban - q4 | U6: Urban - q5 | V6: Kigali - q1 | W6: Kigali - q2 | X6: Kigali - q3 | Y6: Kigali - q4 | Z6: Kigali - q5
B7: OWNSHR | G7: hhd-f1 | H7: hhd-f2 | I7: hhd-f3 | J7: hhd-f4 | K7: hhd-f5 | L7: hhd-n1 | M7: hhd-n2 | N7: hhd-n3 | O7: hhd-n4 | P7: hhd-n5 | Q7: hhd-u1 | R7: hhd-u2 | S7: hhd-u3 | T7: hhd-u4 | U7: hhd-u5 | V7: hhd-k1 | W7: hhd-k2 | X7: hhd-k3 | Y7: hhd-k4 | Z7: hhd-k5
A8: Sorghum (A111) | B8: asorg | C8: =SVY!D117 -> 0.0090826841 | F8: asorg | G8: =SVY!D229 -> 0.10115023 | H8: =SVY!E229 -> 0.28651565 | I8: =SVY!F229 -> 0.13900145 | J8: =SVY!G229 -> 0.047965076 | K8: =SVY!H229 -> 0.11535926 | L8: =SVY!I229 -> 0 | M8: =SVY!J229 -> 0 | N8: =SVY!K229 -> 0 | ... Z8: =SVY!W229 -> 0.0077483372
A9: Maize (A112) | B9: amaiz | C9: =SVY!D118 -> 0.37819606 | F9: amaiz | G9: =SVY!D230 -> 0.1136522 | H9: =SVY!E230 -> 0.21170351 | I9: =SVY!F230 -> 0.22793792 | J9: =SVY!G230 -> 0.28953884 | K9: =SVY!H230 -> 0.13328287 | L9: =SVY!I230 -> 0 | M9: =SVY!J230 -> 0 | N9: =SVY!K230 -> 0 | ... Z9: =SVY!W230 -> 0.0046313071
A10: Wheat (A113) | B10: awhea | C10: =SVY!D119 -> 0.054519829 | F10: awhea | G10: =SVY!D231 -> 0.42169484 | H10: =SVY!E231 -> 0.43043722 | I10: =SVY!F231 -> 0.037551381 | J10: =SVY!G231 -> 0.067828857 | K10: =SVY!H231 -> 0.042487705 | L10: =SVY!I231 -> 0 | M10: =SVY!J231 -> 0 | N10: =SVY!K231 -> 0 | ... Z10: =SVY!W231 -> 0
A11: Paddy & husked rice (A116) | B11: arice | C11: =SVY!D120 -> 0.048623734 | F11: arice | G11: =SVY!D232 -> 0.042879806 | H11: =SVY!E232 -> 0.11070648 | I11: =SVY!F232 -> 0.17345243 | J11: =SVY!G232 -> 0.3518898 | K11: =SVY!H232 -> 0.26399988 | L11: =SVY!I232 -> 0 | M11: =SVY!J232 -> 0 | N11: =SVY!K232 -> 0 | ... Z11: =SVY!W232 -> 0
A12: Other cereals (A119) | B12: aocer | C12: =SVY!D121 -> 0 | F12: aocer | G12: =SVY!D233 -> 0 | H12: =SVY!E233 -> 0 | I12: =SVY!F233 -> 0 | J12: =SVY!G233 -> 0 | K12: =SVY!H233 -> 0 | L12: =SVY!I233 -> 0 | M12: =SVY!J233 -> 0 | N12: =SVY!K233 -> 0 | ... Z12: =SVY!W233 -> 0
A13: Irish potatoes (A121) | B13: aipot | C13: =SVY!D122 -> 0.74961992 | F13: aipot | G13: =SVY!D234 -> 0.068822373 | H13: =SVY!E234 -> 0.15511119 | I13: =SVY!F234 -> 0.21288179 | J13: =SVY!G234 -> 0.31738814 | K13: =SVY!H234 -> 0.22016748 | L13: =SVY!I234 -> 0 | M13: =SVY!J234 -> 0 | N13: =SVY!K234 -> 0 | ... Z13: =SVY!W234 -> 0.0022190598
A14: Sweet potatoes (A122) | B14: aspot | C14: =SVY!D123 -> 0.91713353 | F14: aspot | G14: =SVY!D235 -> 0.10126147 | H14: =SVY!E235 -> 0.20386101 | I14: =SVY!F235 -> 0.26130222 | J14: =SVY!G235 -> 0.27309641 | K14: =SVY!H235 -> 0.11945566 | L14: =SVY!I235 -> 0 | M14: =SVY!J235 -> 0 | N14: =SVY!K235 -> 0 | ... Z14: =SVY!W235 -> 0.010096242
A15: Cassava (A123) | B15: acass | C15: =SVY!D124 -> 0.23666939 | F15: acass | G15: =SVY!D236 -> 0.10113466 | H15: =SVY!E236 -> 0.15450757 | I15: =SVY!F236 -> 0.25943373 | J15: =SVY!G236 -> 0.30141685 | K15: =SVY!H236 -> 0.13318656 | L15: =SVY!I236 -> 0 | M15: =SVY!J236 -> 0 | N15: =SVY!K236 -> 0 | ... Z15: =SVY!W236 -> 0.015612611
A16: Other roots & tubers (A129) | B16: aroot | C16: =SVY!D125 -> 0.63020242 | F16: aroot | G16: =SVY!D237 -> 0.076354836 | H16: =SVY!E237 -> 0.15917166 | I16: =SVY!F237 -> 0.25811781 | J16: =SVY!G237 -> 0.3085671 | K16: =SVY!H237 -> 0.15161946 | L16: =SVY!I237 -> 0 | M16: =SVY!J237 -> 0 | N16: =SVY!K237 -> 0 | ... Z16: =SVY!W237 -> 0.013955795
A17: Dried beans (A131) | B17: abean | C17: =SVY!D126 -> 0.40271014 | F17: abean | G17: =SVY!D238 -> 0.1036524 | H17: =SVY!E238 -> 0.17727513 | I17: =SVY!F238 -> 0.22625055 | J17: =SVY!G238 -> 0.2772591 | K17: =SVY!H238 -> 0.15391815 | L17: =SVY!I238 -> 0 | M17: =SVY!J238 -> 0 | N17: =SVY!K238 -> 0 | ... Z17: =SVY!W238 -> 0.020588644
A18: Peas & other legumes (A132) | B18: apeas | C18: =SVY!D127 -> 0.066835422 | F18: apeas | G18: =SVY!D239 -> 0.056417716 | H18: =SVY!E239 -> 0.099033795 | I18: =SVY!F239 -> 0.21664893 | J18: =SVY!G239 -> 0.32256826 | K18: =SVY!H239 -> 0.2942151 | L18: =SVY!I239 -> 0 | M18: =SVY!J239 -> 0 | N18: =SVY!K239 -> 0 | ... Z18: =SVY!W239 -> 0.0031703605
A19: Other vegetables (A139) | B19: avege | C19: =SVY!D128 -> 0.10262336 | F19: avege | G19: =SVY!D240 -> 0.16266407 | H19: =SVY!E240 -> 0.18662736 | I19: =SVY!F240 -> 0.21966372 | J19: =SVY!G240 -> 0.21845125 | K19: =SVY!H240 -> 0.12270148 | L19: =SVY!I240 -> 0 | M19: =SVY!J240 -> 0 | N19: =SVY!K240 -> 0 | ... Z19: =SVY!W240 -> 0.014586378
... A111: Travel debits & credits (V00) | B111: atrdc | C111: =SVY!D220 -> 0 | F111: atrdc | G111: =SVY!D332 -> 0 | H111: =SVY!E332 -> 0 | I111: =SVY!F332 -> 0 | J111: =SVY!G332 -> 0 | K111: =SVY!H332 -> 0 | L111: =SVY!I332 -> 0 | M111: =SVY!J332 -> 0 | N111: =SVY!K332 -> 0 | ... Z111: =SVY!W332 -> 0

Sheet CH
A1: Household market consumption
A4: Households' share of marketed consumption
A5: COMHHD | C5: Households
C6: Rural - farm q1 | D6: Rural - farm q2 | E6: Rural - farm q3 | F6: Rural - farm q4 | G6: Rural - farm q5 | H6: Rural - nonfarm q1 | I6: Rural - nonfarm q2 | J6: Rural - nonfarm q3 | K6: Rural - nonfarm q4 | L6: Rural - nonfarm q5 | M6: Urban - q1 | N6: Urban - q2 | O6: Urban - q3 | P6: Urban - q4 | Q6: Urban - q5 | R6: Kigali - q1 | S6: Kigali - q2 | T6: Kigali - q3 | U6: Kigali - q4 | V6: Kigali - q5
C7: hhd-f1 | D7: hhd-f2 | E7: hhd-f3 | F7: hhd-f4 | G7: hhd-f5 | H7: hhd-n1 | I7: hhd-n2 | J7: hhd-n3 | K7: hhd-n4 | L7: hhd-n5 | M7: hhd-u1 | N7: hhd-u2 | O7: hhd-u3 | P7: hhd-u4 | Q7: hhd-u5 | R7: hhd-k1 | S7: hhd-k2 | T7: hhd-k3 | U7: hhd-k4 | V7: hhd-k5
A8: Sorghum (A111) | B8: csorg | C8: =SVY!D339 -> 0.077741863 | D8: =SVY!E339 -> 0.12811141 | E8: =SVY!F339 -> 0.21020468 | F8: =SVY!G339 -> 0.22813236 | G8: =SVY!H339 -> 0.20098426 | H8: =SVY!I339 -> 0.0021867699 | I8: =SVY!J339 -> 0 | J8: =SVY!K339 -> 0.00067208422 | ... V8: =SVY!W339 -> 0.023773125
A9: Maize (A112) | B9: cmaiz | C9: =SVY!D340 -> 0.17060048 | D9: =SVY!E340 -> 0.21754572 | E9: =SVY!F340 -> 0.2275114 | F9: =SVY!G340 -> 0.20681815 | G9: =SVY!H340 -> 0.091803822 | H9: =SVY!I340 -> 0.00049287001 | I9: =SVY!J340 -> 0.00015037411 | J9: =SVY!K340 -> 0.0011701526 | ... V9: =SVY!W340 -> 0.01557963
A10: Wheat (A113) | B10: cwhea | C10: =SVY!D341 -> 0.068464788 | D10: =SVY!E341 -> 0.098109475 | E10: =SVY!F341 -> 0.19578451 | F10: =SVY!G341 -> 0.19386283 | G10: =SVY!H341 -> 0.20407486 | H10: =SVY!I341 -> 0 | I10: =SVY!J341 -> 0 | J10: =SVY!K341 -> 0 | ... V10: =SVY!W341 -> 0.054709886
A11: Paddy & husked rice (A116) | B11: crice | C11: =SVY!D342 -> 0.056059242 | D11: =SVY!E342 -> 0.10462678 | E11: =SVY!F342 -> 0.15515738 | F11: =SVY!G342 -> 0.23357403 | G11: =SVY!H342 -> 0.18380854 | H11: =SVY!I342 -> 0.00046554919 | I11: =SVY!J342 -> 0.00045526679 | J11: =SVY!K342 -> 0.0019178109 | ... V11: =SVY!W342 -> 0.070517857
A12: Other cereals (A119) | B12: cocer | C12: =SVY!D343 -> 0.0050302063 | D12: =SVY!E343 -> 0.027685586 | E12: =SVY!F343 -> 0.13193012 | F12: =SVY!G343 -> 0.23138419 | G12: =SVY!H343 -> 0.24998625 | H12: =SVY!I343 -> 0 | I12: =SVY!J343 -> 0 | J12: =SVY!K343 -> 0 | ... V12: =SVY!W343 -> 0.13615702
A13: Irish potatoes (A121) | B13: cipot | C13: =SVY!D344 -> 0.17219315 | D13: =SVY!E344 -> 0.17695376 | E13: =SVY!F344 -> 0.18602358 | F13: =SVY!G344 -> 0.18228436 | G13: =SVY!H344 -> 0.094836318 | H13: =SVY!I344 -> 0.00024600233 | I13: =SVY!J344 -> 0 | J13: =SVY!K344 -> 0.00054400047 | ... V13: =SVY!W344 -> 0.058759348
A14: Sweet potatoes (A122) | B14: cspot | C14: =SVY!D345 -> 0.14163004 | D14: =SVY!E345 -> 0.17597503 | E14: =SVY!F345 -> 0.20096087 | F14: =SVY!G345 -> 0.20865496 | G14: =SVY!H345 -> 0.10287793 | H14: =SVY!I345 -> 0.00029258777 | I14: =SVY!J345 -> 0.0017971324 | J14: =SVY!K345 -> 0.0015210908 | ... V14: =SVY!W345 -> 0.065155861
A15: Cassava (A123) | B15: ccass | C15: =SVY!D346 -> 0.11846543 | D15: =SVY!E346 -> 0.15521952 | E15: =SVY!F346 -> 0.15617267 | F15: =SVY!G346 -> 0.17627424 | G15: =SVY!H346 -> 0.1114607 | H15: =SVY!I346 -> 0.0003820972 | I15: =SVY!J346 -> 0.00015627299 | J15: =SVY!K346 -> 0.0011793543 | ... V15: =SVY!W346 -> 0.092414932
A16: Other roots & tubers (A129) | B16: croot | C16: =SVY!D347 -> 0.13982378 | D16: =SVY!E347 -> 0.13131621 | E16: =SVY!F347 -> 0.18823388 | F16: =SVY!G347 -> 0.22084367 | G16: =SVY!H347 -> 0.12941565 | H16: =SVY!I347 -> 0 | I16: =SVY!J347 -> 0 | J16: =SVY!K347 -> 0 | ... V16: =SVY!W347 -> 0.027422214
A17: Dried beans (A131) | B17: cbean | C17: =SVY!D348 -> 0.13270662 | D17: =SVY!E348 -> 0.16695994 | E17: =SVY!F348 -> 0.19413236 | F17: =SVY!G348 -> 0.16528468 | G17: =SVY!H348 -> 0.10126751 | H17: =SVY!I348 -> 0.00034794324 | I17: =SVY!J348 -> 0.00045396527 | J17: =SVY!K348 -> 0.0016795315 | ... V17: =SVY!W348 -> 0.076607752
A18: Peas & other legumes (A132) | B18: cpeas | C18: =SVY!D349 -> 0.040115535 | D18: =SVY!E349 -> 0.076599112 | E18: =SVY!F349 -> 0.11137276 | F18: =SVY!G349 -> 0.17619194 | G18: =SVY!H349 -> 0.17325637 | H18: =SVY!I349 -> 0.00020371018 | I18: =SVY!J349 -> 0.0003008408 | J18: =SVY!K349 -> 0.0014509771 | ... V18: =SVY!W349 -> 0.20785116
A19: Other vegetables (A139) | B19: cvege | C19: =SVY!D350 -> 0.10924466 | D19: =SVY!E350 -> 0.1327151 | E19: =SVY!F350 -> 0.14412991 | F19: =SVY!G350 -> 0.1490009 | G19: =SVY!H350 -> 0.11880746 | H19: =SVY!I350 -> 0.00063747654 | I19: =SVY!J350 -> 0.00049546066 | J19: =SVY!K350 -> 0.001560689 | ... V19: =SVY!W350 -> 0.15726347
... A111: Travel debits & credits (V00) | B111: ctrdc | C111: =SVY!D442 -> 0.052673169 | D111: =SVY!E442 -> 0.076797628 | E111: =SVY!F442 -> 0.10082863 | F111: =SVY!G442 -> 0.13875894 | G111: =SVY!H442 -> 0.14489328 | H111: =SVY!I442 -> 0.00022639625 | I111: =SVY!J442 -> 0.00026641325 | J111: =SVY!K442 -> 0.001044192 | ... V111: =SVY!W442 -> 0.30123323

Sheet MH
A1: Miscellaneous household accounts
A3: Disaggregated households' income and expenditure shares
A4: MISCHHD | C4: Income shares (sums to 1) | G4: Expenditure shares (sums to 1)
C5: Factors | D5: Enterprises | E5: Government | F5: Rest of world | G5: Consumption | H5: Government | I5: Direct taxes | J5: Savings | K5: Rest of world
C6: inc | D6: inc | E6: inc | F6: inc | G6: exp | H6: exp | I6: exp | J6: exp | K6: exp | T6: Survey data
C7: fac | D7: ent | E7: gov | F7: row | G7: con | H7: gov | I7: dtax | J7: s-i | K7: row | U7: tcons | V7: pop
A8: Rural - farm q1 | B8: hhd-f1 | C8: =SVY!D530 -> 0.90609066 | D8: =SVY!E530 -> 0.021969066 | E8: =SVY!F530 -> 0.060957768 | F8: =SVY!G530 -> 0.01098251 | G8: =SVY!H530 -> 0.96084668 | H8: =SVY!I530 -> 0.0008419057 | I8: =SVY!J530 -> 0.0050205176 | J8: =SVY!K530 -> 0.03015304 | K8: =SVY!L530 -> 0.0031378599 | S8: Rural - farm q1 | T8: hhd-f1 | U8: =SVY!Y530 -> 294247.57 | V8: =SVY!D566 -> 2151.384
A9: Rural - farm q2 | B9: hhd-f2 | C9: =SVY!D531 -> 0.92236556 | D9: =SVY!E531 -> 0.030149855 | E9: =SVY!F531 -> 0.038403151 | F9: =SVY!G531 -> 0.0090814314 | G9: =SVY!H531 -> 0.96242339 | H9: =SVY!I531 -> 0.0021495348 | I9: =SVY!J531 -> 0.0050108697 | J9: =SVY!K531 -> 0.027821513 | K9: =SVY!L531 -> 0.0025946947 | S9: Rural - farm q2 | T9: hhd-f2 | U9: =SVY!Y531 -> 429883.16 | V9: =SVY!D567 -> 2082.696
A10: Rural - farm q3 | B10: hhd-f3 | C10: =SVY!D532 -> 0.93474497 | D10: =SVY!E532 -> 0.020093062 | E10: =SVY!F532 -> 0.031897306 | F10: =SVY!G532 -> 0.013264662 | G10: =SVY!H532 -> 0.95806307 | H10: =SVY!I532 -> 0.0028349943 | I10: =SVY!J532 -> 0.0059643142 | J10: =SVY!K532 -> 0.029347719 | K10: =SVY!L532 -> 0.0037899035 | S10: Rural - farm q3 | T10: hhd-f3 | U10: =SVY!Y532 -> 552628.93 | V10: =SVY!D568 -> 2026.14
A11: Rural - farm q4 | B11: hhd-f4 | C11: =SVY!D533 -> 0.89390197 | D11: =SVY!E533 -> 0.060272903 | E11: =SVY!F533 -> 0.032504148 | F11: =SVY!G533 -> 0.013320982 | G11: =SVY!H533 -> 0.93762172 | H11: =SVY!I533 -> 0.0045680542 | I11: =SVY!J533 -> 0.013214437 | J11: =SVY!K533 -> 0.040789791 | K11: =SVY!L533 -> 0.0038059949 | S11: Rural - farm q4 | T11: hhd-f4 | U11: =SVY!Y533 -> 722684.96 | V11: =SVY!D569 -> 1890.207
A12: Rural - farm q5 | B12: hhd-f5 | C12: =SVY!D534 -> 0.8682289 | D12: =SVY!E534 -> 0.075416484 | E12: =SVY!F534 -> 0.026995192 | F12: =SVY!G534 -> 0.029359422 | G12: =SVY!H534 -> 0.89055292 | H12: =SVY!I534 -> 0.020362578 | I12: =SVY!J534 -> 0.032912972 | J12: =SVY!K534 -> 0.047783121 | K12: =SVY!L534 -> 0.0083884063 | S12: Rural - farm q5 | T12: hhd-f5 | U12: =SVY!Y534 -> 656301.28 | V12: =SVY!D570 -> 970.2514
A13: Rural - nonfarm q1 | B13: hhd-n1 | C13: =SVY!D535 -> 0.90892374 | D13: =SVY!E535 -> 0 | E13: =SVY!F535 -> 0.075094827 | F13: =SVY!G535 -> 0.015981434 | G13: =SVY!H535 -> 0.99217669 | H13: =SVY!I535 -> 0 | I13: =SVY!J535 -> 0 | J13: =SVY!K535 -> 0.003257181 | K13: =SVY!L535 -> 0.0045661241 | S13: Rural - nonfarm q1 | T13: hhd-n1 | U13: =SVY!Y535 -> 988.06606 | V13: =SVY!D571 -> 8.869401
A14: Rural - nonfarm q2 | B14: hhd-n2 | C14: =SVY!D536 -> 0.92648872 | D14: =SVY!E536 -> 0 | E14: =SVY!F536 -> 0.073511284 | F14: =SVY!G536 -> 0 | G14: =SVY!H536 -> 0.95106898 | H14: =SVY!I536 -> 0.0070773368 | I14: =SVY!J536 -> 0.028309347 | J14: =SVY!K536 -> 0.013544333 | K14: =SVY!L536 -> 0 | S14: Rural - nonfarm q2 | T14: hhd-n2 | U14: =SVY!Y536 -> 1078.4692 | V14: =SVY!D572 -> 9.170509
A15: Rural - nonfarm q3 | B15: hhd-n3 | C15: =SVY!D537 -> 0.88447385 | D15: =SVY!E537 -> 0.055682486 | E15: =SVY!F537 -> 0.026404509 | F15: =SVY!G537 -> 0.033439157 | G15: =SVY!H537 -> 0.89630657 | H15: =SVY!I537 -> 0.0039281072 | I15: =SVY!J537 -> 0.050215348 | J15: =SVY!K537 -> 0.039995935 | K15: =SVY!L537 -> 0.0095540448 | S15: Rural - nonfarm q3 | T15: hhd-n3 | U15: =SVY!Y537 -> 3985.0376 | V15: =SVY!D573 -> 18.082
A16: Rural - nonfarm q4 | B16: hhd-n4 | C16: =SVY!D538 -> 0.88697175 | D16: =SVY!E538 -> 0.081994121 | E16: =SVY!F538 -> 0.0202944 | F16: =SVY!G538 -> 0.010739728 | G16: =SVY!H538 -> 0.83091202 | H16: =SVY!I538 -> 0.032673172 | I16: =SVY!J538 -> 0.054590341 | J16: =SVY!K538 -> 0.078755969 | K16: =SVY!L538 -> 0.0030684938 | S16: Rural - nonfarm q4 | T16: hhd-n4 | U16: =SVY!Y538 -> 9749.9734 | V16: =SVY!D574 -> 30.3314
A17: Rural - nonfarm q5 | B17: hhd-n5 | C17: =SVY!D539 -> 0.83629267 | D17: =SVY!E539 -> 0.12222508 | E17: =SVY!F539 -> 0.029152479 | F17: =SVY!G539 -> 0.012329766 | G17: =SVY!H539 -> 0.81322401 | H17: =SVY!I539 -> 0.042530336 | I17: =SVY!J539 -> 0.076779839 | J17: =SVY!K539 -> 0.063943026 | K17: =SVY!L539 -> 0.0035227903 | S17: Rural - nonfarm q5 | T17: hhd-n5 | U17: =SVY!Y539 -> 58158.204 | V17: =SVY!D575 -> 63.09233
A18: Urban - q1 | B18: hhd-u1 | C18: =SVY!D540 -> 0.91466938 | D18: =SVY!E540 -> 0.025621419 | E18: =SVY!F540 -> 0.051911684 | F18: =SVY!G540 -> 0.0077975124 | G18: =SVY!H540 -> 0.94097383 | H18: =SVY!I540 -> 0.0043648121 | I18: =SVY!J540 -> 0.01747804 | J18: =SVY!K540 -> 0.034955454 | K18: =SVY!L540 -> 0.0022278607 | S18: Urban - q1 | T18: hhd-u1 | U18: =SVY!Y540 -> 16732.514 | V18: =SVY!D576 -> 128.8187
A19: Urban - q2 | B19: hhd-u2 | C19: =SVY!D541 -> 0.89252967 | D19: =SVY!E541 -> 0.062500561 | E19: =SVY!F541 -> 0.03318368 | F19: =SVY!G541 -> 0.01178609 | G19: =SVY!H541 -> 0.94265348 | H19: =SVY!I541 -> 0.0032247044 | I19: =SVY!J541 -> 0.019744999 | J19: =SVY!K541 -> 0.031009361 | K19: =SVY!L541 -> 0.0033674544 | S19: Urban - q2 | T19: hhd-u2 | U19: =SVY!Y541 -> 29661.714 | V19: =SVY!D577 -> 142.283
... A27: Kigali - q5 | B27: hhd-k5 | C27: =SVY!D549 -> 0.81610025 | D27: =SVY!E549 -> 0.0999817 | E27: =SVY!F549 -> 0.02975909 | F27: =SVY!G549 -> 0.054158962 | G27: =SVY!H549 -> 0.57144256 | H27: =SVY!I549 -> 0.068843307 | I27: =SVY!J549 -> 0.11684938 | J27: =SVY!K549 -> 0.22739077 | K27: =SVY!L549 -> 0.015473989 | S27: Kigali - q5 | T27: hhd-k5 | U27: =SVY!Y549 -> 1093372.5 | V27: =SVY!D585 -> 959.8911

Sheet SVY
A1: Data tables extracted from household and labor force surveys
A4: Factor income generation | EG4: Survey data table - Labor wages | EQ4: Scaling | ER4: Scaled | ES4: Original | EU4: Survey data table - Nonfarm enterprises earnings | FE4: Scaling | FF4: Scaled | FG4: Original | FI4: Survey data table - Crop earnings | FS4: Scaling | FT4: Scaled | FU4: Original | FW4: Survey data table - Livestock earnings | GG4: Scaling | GH4: Scaled | GI4: Original | GK4: Survey data table - Labor wages | GU4: Scaling | GV4: Scaled | GW4: Original
A5: FACACT | R5: Shares | AE5: Education levels | AI5: Original | AK5: Selected | AN5: Scaled | AQ5: Shares | BE5: Adjustment factors | BS5: Adjusted values | CH5: Assigned to sectors | CV5: Adjusted values | DK5: Combined data | DY5: Selected sector data sources | EG5: Household survey (act_wage) | EQ5: 1 | ER5: =EQ5*ES5 -> 1895875.9 | ES5: =SUM(EH7:ES110) -> 1895875.9 | EU5: Household survey (act_entr) | FE5: 1 | FF5: =FE5*FG5 -> 11272241 | FG5: =SUM(EV7:FG110) -> 11272241 | FI5: Household survey (act_crop) | FS5: 1 | FT5: =FS5*FU5 -> 524967.34 | FU5: =SUM(FJ7:FU110) -> 524967.34 | FW5: Household survey (act_live) | GG5: 1 | GH5: =GG5*GI5 -> 345167.15 | GI5: =SUM(FX7:GI110) -> 345167.15 | GK5: Labor force survey (act_wage) | GU5: 1 | GV5: =GU5*GW5 -> 2970969.4 | GW5: =SUM(GL7:GW110) -> 2970969.4
D6: flab-rn | E6: flab-rp | F6: flab-rs | G6: flab-rt | H6: flab-un | I6: flab-up | J6: flab-us | K6: flab-ut | L6: flab-kn | M6: flab-kp | N6: flab-ks | O6: flab-kt | S6: flab-rn | T6: flab-rp | U6: flab-rs | V6: flab-rt | W6: flab-un | X6: flab-up | Y6: flab-us | Z6: flab-ut | AA6: flab-kn | AB6: flab-kp | AC6: flab-ks | AD6: flab-kt | AE6: None | AF6: Primary | AG6: Secondary | AH6: Tertiary | AI6: Rural | AJ6: Urban | AK6: Rural | AL6: Urban | AM6: Kigali | AN6: Rural | AO6: Urban | AR6: flab-rn | AS6: flab-rp | AT6: flab-rs | AU6: flab-rt | AV6: flab-un | AW6: flab-up | AX6: flab-us | AY6: flab-ut | AZ6: flab-kn | BA6: flab-kp | BB6: flab-ks | BC6: flab-kt | BF6: flab-rn | BG6: flab-rp | BH6: flab-rs | BI6: flab-rt | BJ6: flab-un | BK6: flab-up | BL6: flab-us | BM6: flab-ut | BN6: flab-kn | BO6: flab-kp | BP6: flab-ks | BQ6: flab-kt | BT6: flab-rn | BU6: flab-rp | BV6: flab-rs | BW6: flab-rt | BX6: flab-un | BY6: flab-up | BZ6: flab-us | CA6: flab-ut | CB6: flab-kn | CC6: flab-kp | CD6: flab-ks | CE6: flab-kt | CG6: Use which sector? | CI6: flab-rn | CJ6: flab-rp | CK6: flab-rs | CL6: flab-rt | CM6: flab-un | CN6: flab-up | CO6: flab-us | CP6: flab-ut | CQ6: flab-kn | CR6: flab-kp | CS6: flab-ks | CT6: flab-kt | CW6: flab-rn | CX6: flab-rp | CY6: flab-rs | CZ6: flab-rt | DA6: flab-un | DB6: flab-up | DC6: flab-us | DD6: flab-ut | DE6: flab-kn | DF6: flab-kp | DG6: flab-ks | DH6: flab-kt | DJ6: Aggregate to which sectors? | DL6: flab-rn | DM6: flab-rp | DN6: flab-rs | DO6: flab-rt | DP6: flab-un | DQ6: flab-up | DR6: flab-us | DS6: flab-ut | DT6: flab-kn | DU6: flab-kp | DV6: flab-ks | DW6: flab-kt | DZ6: Wages | EA6: Enterprises | EB6: Crops | EC6: Livestock | ED6: Other | EG6: samdesc | EH6: flab11 | EI6: flab12 | EJ6: flab13 | EK6: flab14 | EL6: flab21 | EM6: flab22 | EN6: flab23 | EO6: flab24 | EP6: flab31 | EQ6: flab32 | ER6: flab33 | ES6: flab34 | EU6: samdesc | EV6: flab11 | EW6: flab12 | EX6: flab13 | EY6: flab14 | EZ6: flab21 | FA6: flab22 | FB6: flab23 | FC6: flab24 | FD6: flab31 | FE6: flab32 | FF6: flab33 | FG6: flab34 | FI6: samdesc | FJ6: flab11 | FK6: flab12 | FL6: flab13 | FM6: flab14 | FN6: flab21 | FO6: flab22 | FP6: flab23 | FQ6: flab24 | FR6: flab31 | FS6: flab32 | FT6: flab33 | FU6: flab34 | FW6: samdesc | FX6: flab11 | FY6: flab12 | FZ6: flab13 | GA6: flab14 | GB6: flab21 | GC6: flab22 | GD6: flab23 | GE6: flab24 | GF6: flab31 | GG6: flab32 | GH6: flab33 | GI6: flab34 | GK6: samdesc | GL6: flab11 | GM6: flab12 | GN6: flab13 | GO6: flab14 | GP6: flab21 | GQ6: flab22 | GR6: flab23 | GS6: flab24 | GT6: flab31 | GU6: flab32 | GV6: flab33 | GW6: flab34
C7: asorg | D7: =IF(SUM($S7:$AD7),S7/SUM($S7:$AD7),0) -> 0.49259772 | E7: =IF(SUM($S7:$AD7),T7/SUM($S7:$AD7),0) -> 0.3616742 | F7: =IF(SUM($S7:$AD7),U7/SUM($S7:$AD7),0) -> 0.039480441 | G7: =IF(SUM($S7:$AD7),V7/SUM($S7:$AD7),0) -> 0.010552685 | H7: =IF(SUM($S7:$AD7),W7/SUM($S7:$AD7),0) -> 0.010225128 | I7: =IF(SUM($S7:$AD7),X7/SUM($S7:$AD7),0) -> 0.018300974 | J7: =IF(SUM($S7:$AD7),Y7/SUM($S7:$AD7),0) -> 0.0045167072 | K7: =IF(SUM($S7:$AD7),Z7/SUM($S7:$AD7),0) -> 0.0054580675 | ... O7: =IF(SUM($S7:$AD7),AD7/SUM($S7:$AD7),0) -> 0.0087581275 | P7: =SUM(D7:O7) -> 1 | R7: asorg | S7: =IF(SUM($AR7:$AU7),$AK7*AR7/SUM($AR7:$AU7),0) -> 0.49259772 | T7: =IF(SUM($AR7:$AU7),$AK7*AS7/SUM($AR7:$AU7),0) -> 0.3616742 | U7: =IF(SUM($AR7:$AU7),$AK7*AT7/SUM($AR7:$AU7),0) -> 0.039480441 | V7: =IF(SUM($AR7:$AU7),$AK7*AU7/SUM($AR7:$AU7),0) -> 0.010552685 | W7: =IF(SUM($AV7:$AY7),$AL7*AV7/SUM($AV7:$AY7),0) -> 0.010225128 | X7: =IF(SUM($AV7:$AY7),$AL7*AW7/SUM($AV7:$AY7),0) -> 0.018300974 | Y7: =IF(SUM($AV7:$AY7),$AL7*AX7/SUM($AV7:$AY7),0) -> 0.0045167072 | Z7: =IF(SUM($AV7:$AY7),$AL7*AY7/SUM($AV7:$AY7),0) -> 0.0054580675 | AA7: =IF(SUM($AZ7:$BC7),(1-$AL7-$AK7)*AZ7/SUM($AZ7:$BC7),0) -> 0.020208753 | AB7: =IF(SUM($AZ7:$BC7),(1-$AL7-$AK7)*BA7/SUM($AZ7:$BC7),0) -> 0.022175616 | AC7: =IF(SUM($AZ7:$BC7),(1-$AL7-$AK7)*BB7/SUM($AZ7:$BC7),0) -> 0.006051581 | AD7: =IF(SUM($AZ7:$BC7),(1-$AL7-$AK7)*BC7/SUM($AZ7:$BC7),0) -> 0.0087581275 | AE7: =S7+W7+AA7 -> 0.5230316 | AF7: =T7+X7+AB7 -> 0.40215079 | AG7: =U7+Y7+AC7 -> 0.050048729 | AH7: =V7+Z7+AD7 -> 0.02476888 | AI7: =IF(SUM($DL7:$DW7),SUM(DL7:DO7)/SUM($DL7:$DW7),0) -> 0.90430505 | AJ7: =IF(SUM($DL7:$DW7),SUM(DP7:DS7)/SUM($DL7:$DW7),0) -> 0.038500876 | AK7: =AI7 -> 0.90430505 | AL7: =AJ7 -> 0.038500876 | AM7: =1-SUM(AK7:AL7) -> 0.057194077 | AN7: 1 | AO7: 1 | AQ7: asorg | AR7: =IF(SUM($BT7:$CE7),BT7/SUM($BT7:$CE7),0) -> 0.49922991 | AS7: =IF(SUM($BT7:$CE7),BU7/SUM($BT7:$CE7),0) -> 0.36654367 | AT7: =IF(SUM($BT7:$CE7),BV7/SUM($BT7:$CE7),0) -> 0.040011994 | AU7: =IF(SUM($BT7:$CE7),BW7/SUM($BT7:$CE7),0) -> 0.010694763 | AV7: =IF(SUM($BT7:$CE7),BX7/SUM($BT7:$CE7),0) -> 0.011165037 | AW7: =IF(SUM($BT7:$CE7),BY7/SUM($BT7:$CE7),0) -> 0.019983226 | AX7: =IF(SUM($BT7:$CE7),BZ7/SUM($BT7:$CE7),0) -> 0.0049318896 | AY7: =IF(SUM($BT7:$CE7),CA7/SUM($BT7:$CE7),0) -> 0.0059597812 | ... BC7: =IF(SUM($BT7:$CE7),CE7/SUM($BT7:$CE7),0) -> 0.0063517897 | BE7: asorg | BF7: 1 | BG7: 1 | BH7: 1 | BI7: 1 | BJ7: 1 | BK7: 1 | BL7: 1 | BM7: 1 | BN7: 1 | BO7: 1 | BP7: 1 | BQ7: 1 | BS7: asorg | BT7: =BF7*CI7 -> 42948.13 | BU7: =BG7*CJ7 -> 31533.298 | BV7: =BH7*CK7 -> 3442.1822 | BW7: =BI7*CL7 -> 920.0572 | BX7: =BJ7*CM7 -> 960.51426 | BY7: =BK7*CN7 -> 1719.1322 | BZ7: =BL7*CO7 -> 424.28435 | CA7: =BM7*CP7 -> 512.71259 | ... CE7: =BQ7*CT7 -> 546.43659 | CG7: =DJ7 -> asorg | CH7: asorg | CI7: =SUMIF($CV$7:$CV$110,$CG7,CW$7:CW$110) -> 42948.13 | CJ7: =SUMIF($CV$7:$CV$110,$CG7,CX$7:CX$110) -> 31533.298 | CK7: =SUMIF($CV$7:$CV$110,$CG7,CY$7:CY$110) -> 3442.1822 | CL7: =SUMIF($CV$7:$CV$110,$CG7,CZ$7:CZ$110) -> 920.0572 | CM7: =SUMIF($CV$7:$CV$110,$CG7,DA$7:DA$110) -> 960.51426 | CN7: =SUMIF($CV$7:$CV$110,$CG7,DB$7:DB$110) -> 1719.1322 | CO7: =SUMIF($CV$7:$CV$110,$CG7,DC$7:DC$110) -> 424.28435 | CP7: =SUMIF($CV$7:$CV$110,$CG7,DD$7:DD$110) -> 512.71259 | ... CT7: =SUMIF($CV$7:$CV$110,$CG7,DH$7:DH$110) -> 546.43659 | CV7: asorg | CW7: =SUMIF($DJ$7:$DJ$110,$CV7,DL$7:DL$110) -> 42948.13 | CX7: =SUMIF($DJ$7:$DJ$110,$CV7,DM$7:DM$110) -> 31533.298 | CY7: =SUMIF($DJ$7:$DJ$110,$CV7,DN$7:DN$110) -> 3442.1822 | CZ7: =SUMIF($DJ$7:$DJ$110,$CV7,DO$7:DO$110) -> 920.0572 | DA7: =SUMIF($DJ$7:$DJ$110,$CV7,DP$7:DP$110) -> 960.51426 | DB7: =SUMIF($DJ$7:$DJ$110,$CV7,DQ$7:DQ$110) -> 1719.1322 | DC7: =SUMIF($DJ$7:$DJ$110,$CV7,DR$7:DR$110) -> 424.28435 | DD7: =SUMIF($DJ$7:$DJ$110,$CV7,DS$7:DS$110) -> 512.71259 | ... DH7: =SUMIF($DJ$7:$DJ$110,$CV7,DW$7:DW$110) -> 546.43659 | DJ7: asorg | DK7: asorg | DL7: =SUMIF($EF$7:$EF$110,$DK7,EH$7:EH$110)*$DZ7*$EQ$5+SUMIF($ET$7:$ET$110,$DK7,EV$7:EV$110)*$EA7*$FE$5+SUMIF($FH$7:$FH$110,$DK7,FJ$7:FJ$110)*$EB7*$FS$5+SUMIF($FV$7:$FV$110,$DK7,FX$7:FX$110)*$EC7*$GG$5+SUMIF($GJ$7:$GJ$110,$DK7,GL$7:GL$110)*$ED7*$GU$5 -> 10925.36 | DM7: =SUMIF($EF$7:$EF$110,$DK7,EI$7:EI$110)*$DZ7*$EQ$5+SUMIF($ET$7:$ET$110,$DK7,EW$7:EW$110)*$EA7*$FE$5+SUMIF($FH$7:$FH$110,$DK7,FK$7:FK$110)*$EB7*$FS$5+SUMIF($FV$7:$FV$110,$DK7,FY$7:FY$110)*$EC7*$GG$5+SUMIF($GJ$7:$GJ$110,$DK7,GM$7:GM$110)*$ED7*$GU$5 -> 8040.616 | DN7: =SUMIF($EF$7:$EF$110,$DK7,EJ$7:EJ$110)*$DZ7*$EQ$5+SUMIF($ET$7:$ET$110,$DK7,EX$7:EX$110)*$EA7*$FE$5+SUMIF($FH$7:$FH$110,$DK7,FL$7:FL$110)*$EB7*$FS$5+SUMIF($FV$7:$FV$110,$DK7,FZ$7:FZ$110)*$EC7*$GG$5+SUMIF($GJ$7:$GJ$110,$DK7,GN$7:GN$110)*$ED7*$GU$5 -> 669.4517 | DO7: =SUMIF($EF$7:$EF$110,$DK7,EK$7:EK$110)*$DZ7*$EQ$5+SUMIF($ET$7:$ET$110,$DK7,EY$7:EY$110)*$EA7*$FE$5+SUMIF($FH$7:$FH$110,$DK7,FM$7:FM$110)*$EB7*$FS$5+SUMIF($FV$7:$FV$110,$DK7,GA$7:GA$110)*$EC7*$GG$5+SUMIF($GJ$7:$GJ$110,$DK7,GO$7:GO$110)*$ED7*$GU$5 -> 271.1942 | DP7: =SUMIF($EF$7:$EF$110,$DK7,EL$7:EL$110)*$DZ7*$EQ$5+SUMIF($ET$7:$ET$110,$DK7,EZ$7:EZ$110)*$EA7*$FE$5+SUMIF($FH$7:$FH$110,$DK7,FN$7:FN$110)*$EB7*$FS$5+SUMIF($FV$7:$FV$110,$DK7,GB$7:GB$110)*$EC7*$GG$5+SUMIF($GJ$7:$GJ$110,$DK7,GP$7:GP$110)*$ED7*$GU$5 -> 266.2394 | DQ7: =SUMIF($EF$7:$EF$110,$DK7,EM$7:EM$110)*$DZ7*$EQ$5+SUMIF($ET$7:$ET$110,$DK7,FA$7:FA$110)*$EA7*$FE$5+SUMIF($FH$7:$FH$110,$DK7,FO$7:FO$110)*$EB7*$FS$5+SUMIF($FV$7:$FV$110,$DK7,GC$7:GC$110)*$EC7*$GG$5+SUMIF($GJ$7:$GJ$110,$DK7,GQ$7:GQ$110)*$ED7*$GU$5 -> 382.885 | DR7: =SUMIF($EF$7:$EF$110,$DK7,EN$7:EN$110)*$DZ7*$EQ$5+SUMIF($ET$7:$ET$110,$DK7,FB$7:FB$110)*$EA7*$FE$5+SUMIF($FH$7:$FH$110,$DK7,FP$7:FP$110)*$EB7*$FS$5+SUMIF($FV$7:$FV$110,$DK7,GD$7:GD$110)*$EC7*$GG$5+SUMIF($GJ$7:$GJ$110,$DK7,GR$7:GR$110)*$ED7*$GU$5 -> 70.75178 | DS7: =SUMIF($EF$7:$EF$110,$DK7,EO$7:EO$110)*$DZ7*$EQ$5+SUMIF($ET$7:$ET$110,$DK7,FC$7:FC$110)*$EA7*$FE$5+SUMIF($FH$7:$FH$110,$DK7,FQ$7:FQ$110)*$EB7*$FS$5+SUMIF($FV$7:$FV$110,$DK7,GE$7:GE$110)*$EC7*$GG$5+SUMIF($GJ$7:$GJ$110,$DK7,GS$7:GS$110)*$ED7*$GU$5 -> 127.6502 | ... DW7: =SUMIF($EF$7:$EF$110,$DK7,ES$7:ES$110)*$DZ7*$EQ$5+SUMIF($ET$7:$ET$110,$DK7,FG$7:FG$110)*$EA7*$FE$5+SUMIF($FH$7:$FH$110,$DK7,FU$7:FU$110)*$EB7*$FS$5+SUMIF($FV$7:$FV$110,$DK7,GI$7:GI$110)*$EC7*$GG$5+SUMIF($GJ$7:$GJ$110,$DK7,GW$7:GW$110)*$ED7*$GU$5 -> 27.28041 | DY7: asorg | EB7: 1 | EF7: asorg | EG7: asorg | EH7: 203840.1 | EI7: 110616 | EJ7: 5835.801 | EK7: 3262.225 | EL7: 10266.58 | EM7: 5551.206 | EN7: 2781.239 | EO7: 2664.473 | EP7: 11009.96 | EQ7: 10010.09 | ER7: 534.5046 | ES7: 11988.09 | ET7: asorg | EU7: asorg | EV7: 116761.2 | EW7: 56703.02 | EX7: 1276.127 | EY7: 1920.307 | EZ7: 820.746 | FA7: 1620.492 | FB7: 1031.184 | FC7: 2424.438 | FH7: asorg | FI7: asorg | FJ7: 10925.36 | FK7: 8040.616 | FL7: 669.4517 | FM7: 271.1942 | FN7: 266.2394 | FO7: 382.885 | FP7: 70.75178 | FQ7: 127.6502 | FR7: 606.6286 | FS7: 601.7004 | FT7: 23.4136 | FU7: 27.28041 | FV7: asorg | FW7: asorg | GJ7: asorg | GK7: asorg | GL7: 239409.9 | GM7: 182258.8 | GN7: 8501.997 | GO7: 11772.6 | GP7: 11413.77 | GQ7: 7730.901 | GR7: 2652.024 | GS7: 1477.278 | GT7: 2303.398 | GU7: 1577.814 | GV7: 1268.048 | GW7: 11178.09
