Workbook

Sheet SUT
F1: -1105256.9
B3: Table 1: Summary Supply and Use Table: Rwanda 2024, RWF billions
B4: RCPA | D4: Product | E4: Domestic Production | F4: Imports of Goods & Services | G4: Margins | H4: Taxes on products less Subsidies on products | I4: Total Supply | K4: Intermediate Demand/Inputs | L4: Household Final Consumption Expenditure | M4: General Government and NGO Final Consumption Expenditure | N4: Gross Capital Formation | O4: Exports of Goods & Services | P4: Total Use
D5: Total | E5: 36361.057 | F5: 8617.777 | G5: 0 | H5: 984.86997 | I5: 45963.704 | K5: 17427.604 | L5: 12281.372 | M5: 3677.8829 | N5: 6915.8119 | O5: 5661.0322 | P5: 45963.704
B6: A1 | D6: Food crops | E6: 3161.4498 | F6: 335.6825 | G6: 51.893756 | H6: 98.427355 | I6: 3647.4534 | K6: 788.5308 | L6: 2277.7547 | M6: 0 | N6: -6.8671913 | O6: 101.80196 | P6: 3647.4534
B7: A2 | D7: Export crops | E7: 401.71853 | F7: 13.221865 | G7: 2.0439917 | H7: 1.1743897 | I7: 418.15878 | K7: 50.426098 | L7: 18.44116 | M7: 0 | N7: 33.399948 | O7: 126.71832 | P7: 418.15878
B8: A3 | D8: Livestock & livestock products | E8: 626.23418 | F8: 6.5002416 | G8: 1.0048839 | H8: 3.3470281 | I8: 637.08633 | K8: 45.353664 | L8: 102.20075 | M8: 0 | N8: 289.65723 | O8: 73.823951 | P8: 637.08633
B9: A4 | D9: Forestry | E9: 798.46498 | F9: 21.150288 | G9: 0 | H9: 0.049792977 | I9: 819.66506 | K9: 15.9693 | L9: 725.52804 | M9: 0 | N9: 14.616934 | O9: 8.4852825 | P9: 819.66506
B10: A5 | D10: Fishing | E10: 75.119865 | F10: 0.13394473 | G10: 0 | H10: 5.3675451 | I10: 80.621355 | K10: 21.033562 | L10: 78.237665 | M10: 0 | N10: -0.15227379 | O10: 0.03992349 | P10: 80.621355
B11: B0 | D11: Mining & quarrying | E11: 717.4452 | F11: 30.63852 | G11: 0 | H11: 0.014779417 | I11: 748.0985 | K11: 363.17479 | L11: 0 | M11: 0 | N11: -1.5270268 | O11: 313.89832 | P11: 748.09868
B12: C1 | D12: Manufacturing of food | E12: 1880.5578 | F12: 1173.6587 | G12: 374.03996 | H12: 224.17734 | I12: 3652.4338 | K12: 1497.6699 | L12: 2205.8209 | M12: 0 | N12: 3.8693541 | O12: 745.52504 | P12: 3652.4338
B13: C2 | D13: Manufacturing of beverages & tobacco | E13: 984.94936 | F13: 213.48988 | G13: 288.56952 | H13: 235.67457 | I13: 1722.6833 | K13: 499.02935 | L13: 917.22206 | M13: 0 | N13: -2.416955 | O13: 84.783058 | P13: 1722.6833
B14: C3 | D14: Manufacturing of textiles, clothing & leather goods | E14: 388.37276 | F14: 287.67483 | G14: 212.20701 | H14: 84.137104 | I14: 972.3917 | K14: 253.58972 | L14: 480.84086 | M14: 0 | N14: -1.9873543 | O14: 98.399836 | P14: 972.3917
B15: C4 | D15: Manufacturing of wood & paper; printing | E15: 315.86347 | F15: 135.15001 | G15: 90.83598 | H15: 16.127225 | I15: 557.97669 | K15: 237.10462 | L15: 111.59154 | M15: 0 | N15: 5.6633409 | O15: 19.179983 | P15: 557.97669
B16: C5 | D16: Manufacturing of chemicals, rubber & plastic products | E16: 596.95755 | F16: 1743.3812 | G16: 520.69234 | H16: 206.26512 | I16: 3067.2962 | K16: 409.78197 | L16: 722.0435 | M16: 0 | N16: -0.076010051 | O16: 330.60589 | P16: 3067.2962
B17: C6 | D17: Manufacturing of non-metalic mineral products | E17: 409.70983 | F17: 262.59847 | G17: 116.57285 | H17: 9.3230889 | I17: 798.20424 | K17: 287.84441 | L17: 5.8832639 | M17: 0 | N17: 18.176835 | O17: 77.518653 | P17: 798.20424
... B42: V0 | D42: Travel debits & credits | E42: 0 | F42: 0 | G42: 0 | H42: 0 | I42: 0 | K42: 0 | L42: 0 | M42: 0 | N42: 0 | O42: 0 | P42: 0
B43: Source: NISR 2024 Supply & Use Table | E43: 0 | F43: 0 | G43: 0 | H43: 0 | I43: 0 | K43: 0 | L43: 0 | M43: 0 | N43: 0 | O43: 0 | P43: 0
D44: Total | E44: 36361.057 | F44: 8617.777 | G44: 0 | H44: 984.86997 | I44: 45963.704 | K44: 17427.604 | L44: 12626.057 | M44: 3677.8829 | N44: 6915.8119 | O44: 5661.0322 | P44: 45963.704
B45: A11 | C45: =LEFT(B45,2) -> A1 | D45: Cereals | E45: 435.92018 | F45: 170.1639 | G45: 26.30594 | H45: 19.039993 | I45: 651.43001 | K45: 120.33668 | L45: 157.8498 | M45: 0 | N45: -11.895283 | O45: 9.9504714 | P45: 651.43001
B46: A12 | C46: =LEFT(B46,2) -> A1 | D46: Roots and Tubers | E46: 1246.6708 | F46: 46.479834 | G46: 7.1854003 | H46: 37.587408 | I46: 1337.9234 | K46: 266.42784 | L46: 943.80033 | M46: 0 | N46: 0.19479392 | O46: 9.9502182 | P46: 1337.9234
B47: A13 | C47: =LEFT(B47,2) -> A1 | D47: Vegetables | E47: 867.33682 | F47: 25.119651 | G47: 3.8832915 | H47: 31.601127 | I47: 927.94089 | K47: 297.15009 | L47: 774.34865 | M47: 0 | N47: 0.11413216 | O47: 50.043702 | P47: 927.94088
B48: A14 | C48: =LEFT(B48,2) -> A1 | D48: Bananas and fruit | E48: 545.16436 | F48: 37.87169 | G48: 5.854652 | H48: 9.723817 | I48: 598.61452 | K48: 80.328615 | L48: 395.79358 | M48: 0 | N48: 5.9944158 | O48: 21.587817 | P48: 598.61452
B49: A15 | C49: =LEFT(B49,2) -> A1 | D49: Oil seeds n.e.c. and oleaginous fruit | E49: 66.35767 | F49: 56.047431 | G49: 8.6644722 | H49: 0.47501118 | I49: 131.54458 | K49: 24.28758 | L49: 5.9622992 | M49: 0 | N49: -1.2752507 | O49: 10.269748 | P49: 131.54458
B50: A21 | C50: =LEFT(B50,2) -> A2 | D50: Coffee | E50: 184.52589 | F50: 2.7763957 | G50: 0.42920795 | H50: 0.014648008 | I50: 187.74614 | K50: 11.851916 | L50: 0 | M50: 0 | N50: 29.486245 | O50: 121.01187 | P50: 187.74614
B51: A22 | C51: =LEFT(B51,2) -> A2 | D51: Tea (unprocessed green leaf) | E51: 64.076693 | F51: 0 | G51: 0 | H51: 0 | I51: 64.076693 | K51: 4.1155828 | L51: 0 | M51: 0 | N51: 3.6957381 | O51: 0 | P51: 64.076692
B52: A29 | C52: =LEFT(B52,2) -> A2 | D52: Other agricultural products | E52: 153.11595 | F52: 10.445469 | G52: 1.6147837 | H52: 1.1597417 | I52: 166.33595 | K52: 34.458599 | L52: 18.44116 | M52: 0 | N52: 0.21796481 | O52: 5.7064472 | P52: 166.33594
B53: A31 | C53: =LEFT(B53,2) -> A3 | D53: Livestock | E53: 413.67065 | F53: 2.7126389 | G53: 0.41935168 | H53: 1.632639 | I53: 418.43528 | K53: 28.956945 | L53: 15.276696 | M53: 0 | N53: 289.79135 | O53: 68.152039 | P53: 418.43527
B54: A32 | C54: =LEFT(B54,2) -> A3 | D54: Livestock and hunting products | E54: 212.56353 | F54: 3.7876027 | G54: 0.58553224 | H54: 1.7143892 | I54: 218.65106 | K54: 16.396719 | L54: 86.924053 | M54: 0 | N54: -0.13412195 | O54: 5.6719122 | P54: 218.65105
B55: A40 | C55: =LEFT(B55,2) -> A4 | D55: Forestry products | E55: 798.46498 | F55: 21.150288 | G55: 0 | H55: 0.049792977 | I55: 819.66506 | K55: 15.9693 | L55: 725.52804 | M55: 0 | N55: 14.616934 | O55: 8.4852825 | P55: 819.66506
B56: A50 | C56: =LEFT(B56,2) -> A5 | D56: Fishery products | E56: 75.119865 | F56: 0.13394473 | G56: 0 | H56: 5.3675451 | I56: 80.621355 | K56: 21.033562 | L56: 78.237665 | M56: 0 | N56: -0.15227379 | O56: 0.03992349 | P56: 80.621355
... B124: X00 | C124: =LEFT(B124,2) -> X0 | D124: Unallocated products | E124: 0 | F124: 0 | G124: 0 | H124: 0 | I124: 0 | K124: 0 | L124: 0 | M124: 0 | N124: 0 | O124: 0 | P124: 0

Sheet IO_Table
B3: Table 2: Summary Input Output ratios by economic activity: Rwanda 2024, RWF billions
B5: =SUT!B4 -> RCPA | C5: Activity | D5: Domestic output | E5: Intermediate Consumption/Inputs | F5: Gross Value Added (GVA)/GDP
C6: Total | D6: =SUM(D7:D40) -> 36361.057 | E6: =SUM(E7:E40) -> 17427.604 | F6: =SUM(F7:F41) -> 19918.452
B7: =SUT!B6 -> A1 | C7: =SUT!D6 -> Food crops | D7: 3161.4498 | E7: 788.5308 | F7: =D7-E7 -> 2372.919
B8: =SUT!B7 -> A2 | C8: =SUT!D7 -> Export crops | D8: 401.71853 | E8: 50.426098 | F8: =D8-E8 -> 351.29244
B9: =SUT!B8 -> A3 | C9: =SUT!D8 -> Livestock & livestock products | D9: 626.23418 | E9: 45.353664 | F9: =D9-E9 -> 580.88052
B10: =SUT!B9 -> A4 | C10: =SUT!D9 -> Forestry | D10: 798.46498 | E10: 15.9693 | F10: =D10-E10 -> 782.49568
B11: =SUT!B10 -> A5 | C11: =SUT!D10 -> Fishing | D11: 75.119865 | E11: 21.033562 | F11: =D11-E11 -> 54.086303
B12: =SUT!B11 -> B0 | C12: =SUT!D11 -> Mining & quarrying | D12: 717.4452 | E12: 363.17479 | F12: =D12-E12 -> 354.27041
B13: =SUT!B12 -> C1 | C13: =SUT!D12 -> Manufacturing of food | D13: 1880.5578 | E13: 1497.6699 | F13: =D13-E13 -> 382.88794
B14: =SUT!B13 -> C2 | C14: =SUT!D13 -> Manufacturing of beverages & tobacco | D14: 984.94936 | E14: 499.02935 | F14: =D14-E14 -> 485.92
B15: =SUT!B14 -> C3 | C15: =SUT!D14 -> Manufacturing of textiles, clothing & leather goods | D15: 388.37276 | E15: 253.58972 | F15: =D15-E15 -> 134.78304
B16: =SUT!B15 -> C4 | C16: =SUT!D15 -> Manufacturing of wood & paper; printing | D16: 315.86347 | E16: 237.10462 | F16: =D16-E16 -> 78.758851
B17: =SUT!B16 -> C5 | C17: =SUT!D16 -> Manufacturing of chemicals, rubber & plastic products | D17: 596.95755 | E17: 409.78197 | F17: =D17-E17 -> 187.17558
B18: =SUT!B17 -> C6 | C18: =SUT!D17 -> Manufacturing of non-metalic mineral products | D18: 409.70983 | E18: 287.84441 | F18: =D18-E18 -> 121.86542
... B39: =SUT!B38 -> Q0 | C39: =SUT!D38 -> Human health & social work activities | D39: 523.21682 | E39: 274.64612 | F39: =D39-E39 -> 248.5707
B40: R_S_T | C40: Cultural, domestic & other services | D40: 897.98096 | E40: 258.20725 | F40: =D40-E40 -> 639.77371
C41: Taxes less subsidies on products | F41: 985
B43: Source: NISR 2024 Supply & Use Table

Sheet RCPA
A6: =LEFT(C6,2) -> A1 | B6: =LEFT(C6,1) -> A | C6: A11 | D6: Cereals | I6: A | J6: Agtriculture, Forestry and Fishing | N6: RCPA2 | O6: Len | P6: Labels | S6: RCPA2 | T6: Len | U6: Labels
A7: =LEFT(C7,2) -> A1 | B7: =LEFT(C7,1) -> A | C7: A12 | D7: Roots and Tubers | I7: B | J7: Mning & Quarrying | N7: A1 | O7: 2 | P7: Food crops | S7: A1 | T7: 2 | U7: Food crops
A8: =LEFT(C8,2) -> A1 | B8: =LEFT(C8,1) -> A | C8: A13 | D8: Vegetables | I8: C | J8: Manufacturing | N8: A11 | O8: 3 | P8: Cereals | S8: A2 | T8: 2 | U8: Export crops
A9: =LEFT(C9,2) -> A1 | B9: =LEFT(C9,1) -> A | C9: A14 | D9: Bananas and fruit | I9: D | J9: =U21 -> Electricity | N9: A111 | O9: 4 | P9: Sorghum | S9: A3 | T9: 2 | U9: Livestock & livestock products
A10: =LEFT(C10,2) -> A1 | B10: =LEFT(C10,1) -> A | C10: A15 | D10: Oil seeds n.e.c. and oleaginous fruit | I10: E | J10: =U22 -> Water & waste management | N10: A112 | O10: 4 | P10: Maize | S10: A4 | T10: 2 | U10: Forestry
A11: =LEFT(C11,2) -> A2 | B11: =LEFT(C11,1) -> A | C11: A21 | D11: Coffee | I11: F | J11: =U23 -> Construction | N11: A113 | O11: 4 | P11: Wheat | S11: A5 | T11: 2 | U11: Fishing
A12: =LEFT(C12,2) -> A2 | B12: =LEFT(C12,1) -> A | C12: A22 | D12: Tea (unprocessed green leaf) | I12: G | J12: =U25&" and "&U24 -> Wholesale & retail trade and Maintenance & repair of motor vehicles | N12: A116 | O12: 4 | P12: Paddy & husked rice | S12: B0 | T12: 2 | U12: Mining & quarrying
A13: =LEFT(C13,2) -> A2 | B13: =LEFT(C13,1) -> A | C13: A29 | D13: Other agricultural products | I13: H | J13: Transportation Services | N13: A119 | O13: 4 | P13: Other cereals | S13: C1 | T13: 2 | U13: Manufacturing of food
A14: =LEFT(C14,2) -> A3 | B14: =LEFT(C14,1) -> A | C14: A31 | D14: Livestock | I14: I | J14: =U29 -> Hotels & restaurants | N14: A12 | O14: 3 | P14: Roots & Tubers | S14: C2 | T14: 2 | U14: Manufacturing of beverages & tobacco
A15: =LEFT(C15,2) -> A3 | B15: =LEFT(C15,1) -> A | C15: A32 | D15: Livestock and hunting products | I15: J | J15: Telecoms, IT and Publishng services | N15: A121 | O15: 4 | P15: Irish potatoes | S15: C3 | T15: 2 | U15: Manufacturing of textiles, clothing & leather goods
A16: =LEFT(C16,2) -> A4 | B16: =LEFT(C16,1) -> A | C16: A40 | D16: Forestry products | I16: K | J16: =U33 -> Financial services | N16: A122 | O16: 4 | P16: Sweet potatoes | S16: C4 | T16: 2 | U16: Manufacturing of wood & paper; printing
A17: =LEFT(C17,2) -> A5 | B17: =LEFT(C17,1) -> A | C17: A50 | D17: Fishery products | I17: L | J17: =U34 -> Real estate activities | N17: A123 | O17: 4 | P17: Cassava | S17: C5 | T17: 2 | U17: Manufacturing of chemicals, rubber & plastic products
A18: =LEFT(C18,2) -> B0 | B18: =LEFT(C18,1) -> B | C18: B01 | D18: Natural gas | I18: M | J18: =U35 -> Professional, scientific & technical activities | N18: A129 | O18: 4 | P18: Other roots & tubers | S18: C6 | T18: 2 | U18: Manufacturing of non-metalic mineral products
A19: =LEFT(C19,2) -> B0 | B19: =LEFT(C19,1) -> B | C19: B03 | D19: Metal ores | I19: N | J19: =U36 -> Administrative & support service activities | N19: A13 | O19: 3 | P19: Vegetables | S19: C7 | T19: 2 | U19: Manufacturing of metal products, machinery & equipment
A20: =LEFT(C20,2) -> B0 | B20: =LEFT(C20,1) -> B | C20: B09 | D20: Quarry & other mining products | I20: O | J20: =U37 -> Public administration & defence; compulsory social security | N20: A131 | O20: 4 | P20: Dried beans | S20: C8 | T20: 2 | U20: Furniture & other manufacturing
A21: =LEFT(C21,2) -> C1 | B21: =LEFT(C21,1) -> C | C21: C11 | D21: Meat and meat products | I21: P | J21: =U38 -> Education | N21: A132 | O21: 4 | P21: Peas & other legumes | S21: D0 | T21: 2 | U21: Electricity
A22: =LEFT(C22,2) -> C1 | B22: =LEFT(C22,1) -> C | C22: C12 | D22: Prepared and preserved fish | I22: Q | J22: =U39 -> Human health & social work activities | N22: A139 | O22: 4 | P22: Other vegetables | S22: E0 | T22: 2 | U22: Water & waste management
A23: =LEFT(C23,2) -> C1 | B23: =LEFT(C23,1) -> C | C23: C13 | D23: Prepared and preserved vegetables | I23: R | J23: =U40 -> Arts, entertainment & recreation | N23: A14 | O23: 3 | P23: Bananas & fruit | S23: F0 | T23: 2 | U23: Construction
A24: =LEFT(C24,2) -> C1 | B24: =LEFT(C24,1) -> C | C24: C14 | D24: Animal and vegetable oils and fats | I24: S | J24: =U41 -> Other service activities | N24: A141 | O24: 4 | P24: Bananas for beer | S24: G1 | T24: 2 | U24: Maintenance & repair of motor vehicles
A25: =LEFT(C25,2) -> C1 | B25: =LEFT(C25,1) -> C | C25: C15 | D25: Dairy products | I25: T | J25: =U42 -> Domestic services | N25: A142 | O25: 4 | P25: Bananas for cooking | S25: G2 | T25: 2 | U25: Wholesale & retail trade
A26: =LEFT(C26,2) -> C1 | B26: =LEFT(C26,1) -> C | C26: C16 | D26: Grain mill products | I26: V | J26: =U43 -> Travel debits & credits | N26: A143 | O26: 4 | P26: Bananas (sweet) | S26: H1 | T26: 2 | U26: Land transport
A27: =LEFT(C27,2) -> C1 | B27: =LEFT(C27,1) -> C | C27: C17 | D27: Bakery products | N27: A149 | O27: 4 | P27: Other fruit & nuts | S27: H2 | T27: 2 | U27: Air transport
A28: =LEFT(C28,2) -> C1 | B28: =LEFT(C28,1) -> C | C28: C18 | D28: Animal feed & other by-products | N28: A15 | O28: 3 | P28: Oil seeds n.e.c. & oleaginous fruit | S28: H3 | T28: 2 | U28: Other transport & postal services
A29: =LEFT(C29,2) -> C1 | B29: =LEFT(C29,1) -> C | C29: C19 | D29: Other manufactured food products | N29: A151 | O29: 4 | P29: Ground nuts | S29: I0 | T29: 2 | U29: Hotels & restaurants
A30: =LEFT(C30,2) -> C2 | B30: =LEFT(C30,1) -> C | C30: C21 | D30: Alcoholic drinks | N30: A152 | O30: 4 | P30: Soya | S30: J1 | T30: 2 | U30: Publishing & broadcasting activities
A31: =LEFT(C31,2) -> C2 | B31: =LEFT(C31,1) -> C | C31: C22 | D31: Soft drinks | N31: A159 | O31: 4 | P31: Other oil seeds | S31: J2 | T31: 2 | U31: Telecommunication
A32: =LEFT(C32,2) -> C2 | B32: =LEFT(C32,1) -> C | C32: C23 | D32: Tobacco products | N32: A2 | O32: 2 | P32: Export crops | S32: J3 | T32: 2 | U32: Information technology services
A33: =LEFT(C33,2) -> C3 | B33: =LEFT(C33,1) -> C | C33: C30 | D33: Textiles, clothing & leather products | N33: A21 | O33: 3 | P33: Coffee | S33: K0 | T33: 2 | U33: Financial services
A34: =LEFT(C34,2) -> C4 | B34: =LEFT(C34,1) -> C | C34: C41 | D34: Wood, paper and related products | N34: A210 | O34: 4 | P34: Coffee, not roasted, not decaffeinated | S34: L0 | T34: 2 | U34: Real estate activities
A35: =LEFT(C35,2) -> C4 | B35: =LEFT(C35,1) -> C | C35: C42 | D35: Printing and reproduction of recorded media | N35: A22 | O35: 3 | P35: Tea (unprocessed green leaf) | S35: M0 | T35: 2 | U35: Professional, scientific & technical activities
A36: =LEFT(C36,2) -> C5 | B36: =LEFT(C36,1) -> C | C36: C51 | D36: Coke and refined petroleum products | N36: A220 | O36: 4 | P36: Tea (unprocessed green leaf) | S36: N0 | T36: 2 | U36: Administrative & support service activities
A37: =LEFT(C37,2) -> C5 | B37: =LEFT(C37,1) -> C | C37: C52 | D37: Chemicals and chemical products | N37: A29 | O37: 3 | P37: Other agricultural products | S37: O0 | T37: 2 | U37: Public administration & defence; compulsory social security
A38: =LEFT(C38,2) -> C5 | B38: =LEFT(C38,1) -> C | C38: C53 | D38: Pharmaceutical products | N38: A291 | O38: 4 | P38: Tobacco, raw | S38: P0 | T38: 2 | U38: Education
... A85: =LEFT(C85,2) -> X0 | B85: =LEFT(C85,1) -> X | C85: X00 | D85: Unallocated products | N85: C161 | O85: 4 | P85: Maize flour | S85: C81 | T85: 3 | U85: Furniture
N86: C162 | O86: 4 | P86: Wheat flour | S86: C82 | T86: 3 | U86: Other manufactures
N87: C164 | O87: 4 | P87: Cassava flour | S87: C83 | T87: 3 | U87: Repair & installation of machinery & equipment
N88: C166 | O88: 4 | P88: Rice, semi- or wholly milled | S88: D00 | T88: 3 | U88: Electricity, gas, steam & air conditioning supply
N89: C169 | O89: 4 | P89: Other grain mill products | S89: E01 | T89: 3 | U89: Water collection, treatment & supply: sewrage
N90: C17 | O90: 3 | P90: Bakery products | S90: E02 | T90: 3 | U90: Waste collection & management
N91: C170 | O91: 4 | P91: Bakery products | S91: F01 | T91: 3 | U91: Construction (modern)
...
