Workbook

Sheet Notes
A1: Exercise 2x - Detailed SAM Analysis
A7: Activities and commodities | F7: Factors | I7: Households | M7: Other accounts
A8: acere | B8: ccere | C8: Cereals | F8: flab-n | G8: Labor - uneducated | I8: hhd-1 | J8: Household - quintile 1 | M8: trc | N8: Transaction costs
A9: apoil | B9: cpoil | C9: Pulses and oilseeds | F9: flab-p | G9: Labor - primary | I9: hhd-2 | J9: Household - quintile 2 | M9: ent | N9: Enterprises
A10: aroot | B10: croot | C10: Root crops | F10: flab-s | G10: Labor - secondary | I10: hhd-3 | J10: Household - quintile 3 | M10: gov | N10: Government
A11: ahort | B11: chort | C11: Vegetables & fruits | F11: flab-t | G11: Labor - tertiary | I11: hhd-4 | J11: Household - quintile 4 | M11: atax | N11: Taxes - activity
A12: axcrp | B12: cxcrp | C12: Export-oriented crops | F12: flnd | G12: Land - crops | I12: hhd-5 | J12: Household - quintile 5 | M12: dtax | N12: Taxes - direct
A13: acatt | B13: ccatt | C13: Cattle and milk | F13: fcap | G13: Capital | M13: etax | N13: Taxes - export
A14: apoul | B14: cpoul | C14: Poultry and eggs | M14: ftax | N14: Taxes - factor
A15: aoliv | B15: coliv | C15: Other livestock | M15: mtax | N15: Taxes - import
A16: afore | B16: cfore | C16: Forestry | M16: stax | N16: Taxes - sales
A17: afish | B17: cfish | C17: Fisheries | M17: s-i | N17: Savings-investment
A18: amine | B18: cmine | C18: Mining | M18: dstk | N18: Change in stocks
A19: ameat | B19: cmeat | C19: Meat, fish and dairy | M19: row | N19: Rest of world
A20: afveg | B20: cfveg | C20: Fruits and vegetables | M20: total | N20: Total
A21: afoil | B21: cfoil | C21: Fats and oils
A22: agmll | B22: cgmll | C22: Grain milling
A23: afood | B23: cfood | C23: Other food processing
A24: abeve | B24: cbeve | C24: Beverages and tobacco
A25: atext | B25: ctext | C25: Textiles, clothing and footwear
A26: awood | B26: cwood | C26: Wood and paper products
A27: achem | B27: cchem | C27: Chemicals
A28: anmet | B28: cnmet | C28: Nonmetal minerals
A29: amach | B29: cmach | C29: Metals and machinery
A30: aoman | B30: coman | C30: Other manufacturing
A31: autil | B31: cutil | C31: Electricity and water
A32: acons | B32: ccons | C32: Construction
... A37: aosrv | B37: cosrv | C37: Other services

Sheet Structure
A1: Structure of the Micro SAM
B3: Activities | C3: Commodities | D3: Transaction costs | E3: Labor | F3: Land | G3: Capital | H3: Enterprises | I3: Households | J3: Government | K3: Direct taxes | L3: Factor taxes | M3: Import tariffs | N3: Sales taxes | O3: Investment | P3: Stock changes | Q3: Rest of world | R3: Total
A4: Activities | C4: 30 x 30 | I4: 30 x 5
A5: Commodities | B5: 30 x 30 | D5: 30 x 1 | I5: 30 x 5 | J5: 30 x 1 | O5: 30 x 1 | P5: 30 x 1 | Q5: 30 x 1
A6: Transaction costs | C6: 1 x 30
A7: Labor | B7: 4 x 30
A8: Land | B8: 1 x 30
A9: Capital | B9: 1 x 30
A10: Enterprises | G10: 1 x 1 | J10: 1 x 1
A11: Households | E11: 5 x 4 | F11: 5 x 1 | G11: 5 x 1 | H11: 5 x 1 | J11: 5 x 1 | Q11: 5 x 1
A12: Government | H12: 1 x 1 | I12: 1 x 5 | K12: 1 x 1 | L12: 1 x 1 | M12: 1 x 1 | N12: 1 x 1
A13: Direct taxes | H13: 1 x 1 | I13: 1 x 5
A14: Factor taxes | G14: 1 x 1
A15: Import tariffs | C15: 1 x 30
A16: Sales taxes | C16: 1 x 30
A17: Savings | H17: 1 x 1 | I17: 1 x 5 | J17: 1 x 1 | Q17: 1 x 1
A18: Stock changes | O18: 1 x 1
A19: Rest of world | C19: 1 x 30 | E19: 1 x 4 | G19: 1 x 1 | H19: 1 x 1 | I19: 1 x 5 | J19: 1 x 1
A20: Total

Sheet SAM
A1: 30-Sector Social Accounting Matrix
C4: Cereals | D4: Pulses and oilseeds | E4: Root crops | F4: Vegetables & fruits | G4: Export-oriented crops | H4: Cattle and milk | I4: Poultry and eggs | J4: Other livestock | K4: Forestry | L4: Fisheries | M4: Mining | N4: Meat, fish and dairy | O4: Fruits and vegetables | P4: Fats and oils | Q4: Grain milling | R4: Other food processing | S4: Beverages and tobacco | T4: Textiles, clothing and footwear | U4: Wood and paper products | V4: Chemicals | W4: Nonmetal minerals | X4: Metals and machinery | Y4: Other manufacturing | Z4: Electricity and water | AA4: Construction | AB4: Trade, hotels and food services | AC4: Transport and communication | AD4: Finance, business and real estate | AE4: Government, health and education | AF4: Other services | AG4: Cereals | AH4: Pulses and oilseeds | AI4: Root crops | AJ4: Vegetables & fruits | AK4: Export-oriented crops | AL4: Cattle and milk | AM4: Poultry and eggs | AN4: Other livestock | AO4: Forestry | AP4: Fisheries | AQ4: Mining | AR4: Meat, fish and dairy | AS4: Fruits and vegetables | AT4: Fats and oils | AU4: Grain milling | AV4: Other food processing | AW4: Beverages and tobacco | AX4: Textiles, clothing and footwear | AY4: Wood and paper products | AZ4: Chemicals | BA4: Nonmetal minerals | BB4: Metals and machinery | BC4: Other manufacturing | BD4: Electricity and water | BE4: Construction | BF4: Trade, hotels and food services | BG4: Transport and communication | BH4: Finance, business and real estate | BI4: Government, health and education | BJ4: Other services | BK4: Transaction costs | BL4: Labor - uneducated | BM4: Labor - primary | BN4: Labor - secondary | BO4: Labor - tertiary | BP4: Land - crops | BQ4: Capital | BR4: Enterprise | BS4: Household - quintile 1 | BT4: Household - quintile 2 | BU4: Household - quintile 3 | BV4: Household - quintile 4 | BW4: Household - quintile 5 | BX4: Government | BY4: Taxes - direct | BZ4: Taxes - factor | CA4: Taxes - import | CB4: Taxes - sales | CC4: Savings-investment | CD4: Change in stocks | CE4: Rest of world | CF4: Total
C5: acere | D5: apoil | E5: aroot | F5: ahort | G5: axcrp | H5: acatt | I5: apoul | J5: aoliv | K5: afore | L5: afish | M5: amine | N5: ameat | O5: afveg | P5: afoil | Q5: agmll | R5: afood | S5: abeve | T5: atext | U5: awood | V5: achem | W5: anmet | X5: amach | Y5: aoman | Z5: autil | AA5: acons | AB5: atrad | AC5: atran | AD5: afbsv | AE5: agsrv | AF5: aosrv | AG5: ccere | AH5: cpoil | AI5: croot | AJ5: chort | AK5: cxcrp | AL5: ccatt | AM5: cpoul | AN5: coliv | AO5: cfore | AP5: cfish | AQ5: cmine | AR5: cmeat | AS5: cfveg | AT5: cfoil | AU5: cgmll | AV5: cfood | AW5: cbeve | AX5: ctext | AY5: cwood | AZ5: cchem | BA5: cnmet | BB5: cmach | BC5: coman | BD5: cutil | BE5: ccons | BF5: ctrad | BG5: ctran | BH5: cfbsv | BI5: cgsrv | BJ5: cosrv | BK5: trc | BL5: flab-n | BM5: flab-p | BN5: flab-s | BO5: flab-t | BP5: flnd | BQ5: fcap | BR5: ent | BS5: hhd-1 | BT5: hhd-2 | BU5: hhd-3 | BV5: hhd-4 | BW5: hhd-5 | BX5: gov | BY5: dtax | BZ5: ftax | CA5: mtax | CB5: stax | CC5: s-i | CD5: dstk | CE5: row | CF5: total
A6: =VLOOKUP(B6,Notes!$A$8:$C$37,3,0) -> Cereals | B6: acere | AG6: 969.53395 | CF6: 969.53395
A7: =VLOOKUP(B7,Notes!$A$8:$C$37,3,0) -> Pulses and oilseeds | B7: apoil | AH7: 74.351835 | BS7: 14.77499 | BT7: 13.761288 | BU7: 12.052192 | BV7: 9.8723053 | BW7: 7.6293315 | CF7: 132.44194
A8: =VLOOKUP(B8,Notes!$A$8:$C$37,3,0) -> Root crops | B8: aroot | AI8: 242.53103 | BS8: 0.21788978 | BT8: 0.29512099 | BU8: 0.31696875 | BV8: 0.29258783 | BW8: 0.28924826 | CF8: 243.94285
A9: =VLOOKUP(B9,Notes!$A$8:$C$37,3,0) -> Vegetables & fruits | B9: ahort | AJ9: 246.45957 | BS9: 2.1688955 | BT9: 2.877557 | BU9: 3.4852292 | BV9: 4.1966037 | BW9: 4.241083 | CF9: 263.42893
A10: =VLOOKUP(B10,Notes!$A$8:$C$37,3,0) -> Export-oriented crops | B10: axcrp | AK10: 281.47193 | BS10: 0.2431864 | BT10: 0.40081479 | BU10: 0.42775311 | BV10: 0.51922648 | BW10: 0.4949684 | CF10: 283.55788
A11: =VLOOKUP(B11,Notes!$A$8:$C$37,3,0) -> Cattle and milk | B11: acatt | AL11: 296.85477 | BS11: 4.0473873 | BT11: 5.6346297 | BU11: 6.4581882 | BV11: 7.8957979 | BW11: 7.7989888 | CF11: 328.68976
A12: =VLOOKUP(B12,Notes!$A$8:$C$37,3,0) -> Poultry and eggs | B12: apoul | AM12: 291.72804 | BS12: 1.6348228 | BT12: 2.255715 | BU12: 2.7789321 | BV12: 2.7799192 | BW12: 2.9881319 | CF12: 304.16557
A13: =VLOOKUP(B13,Notes!$A$8:$C$37,3,0) -> Other livestock | B13: aoliv | AN13: 214.76319 | BS13: 0.56908462 | BT13: 1.134716 | BU13: 3.7144439 | BV13: 5.7918237 | BW13: 12.560758 | CF13: 238.53401
A14: =VLOOKUP(B14,Notes!$A$8:$C$37,3,0) -> Forestry | B14: afore | AO14: 377.39082 | BS14: 12.286033 | BT14: 15.181252 | BU14: 17.581972 | BV14: 18.149081 | BW14: 18.219826 | CF14: 458.80898
A15: =VLOOKUP(B15,Notes!$A$8:$C$37,3,0) -> Fisheries | B15: afish | AP15: 1199.0117 | BS15: 4.4799055 | BT15: 6.4840277 | BU15: 6.3349985 | BV15: 6.3085901 | BW15: 5.9300739 | CF15: 1228.5493
A16: =VLOOKUP(B16,Notes!$A$8:$C$37,3,0) -> Mining | B16: amine | AQ16: 517.75716 | CF16: 517.75716
A17: =VLOOKUP(B17,Notes!$A$8:$C$37,3,0) -> Meat, fish and dairy | B17: ameat | AR17: 135.36841 | BS17: 0.011182487 | BT17: 0.025454126 | BU17: 0.026304269 | BV17: 0.032435584 | BW17: 0.088365274 | CF17: 135.55216
A18: =VLOOKUP(B18,Notes!$A$8:$C$37,3,0) -> Fruits and vegetables | B18: afveg | AS18: 14.570814 | CF18: 14.570814
A19: =VLOOKUP(B19,Notes!$A$8:$C$37,3,0) -> Fats and oils | B19: afoil | AT19: 129.34793 | BS19: 0.13118549 | BT19: 0.14309611 | BU19: 0.18376864 | BV19: 0.27325234 | BW19: 0.18900089 | CF19: 130.26823
A20: =VLOOKUP(B20,Notes!$A$8:$C$37,3,0) -> Grain milling | B20: agmll | AU20: 832.39335 | BS20: 26.054551 | BT20: 34.194055 | BU20: 33.448208 | BV20: 32.306775 | BW20: 26.443203 | CF20: 984.84014
A21: =VLOOKUP(B21,Notes!$A$8:$C$37,3,0) -> Other food processing | B21: afood | AV21: 405.26453 | BS21: 0.13282444 | BT21: 0.19685539 | BU21: 0.2915151 | BV21: 0.35458652 | BW21: 0.7404851 | CF21: 406.98079
A22: =VLOOKUP(B22,Notes!$A$8:$C$37,3,0) -> Beverages and tobacco | B22: abeve | AW22: 289.16367 | CF22: 289.16367
A23: =VLOOKUP(B23,Notes!$A$8:$C$37,3,0) -> Textiles, clothing and footwear | B23: atext | AX23: 3548.1146 | CF23: 3548.1146
A24: =VLOOKUP(B24,Notes!$A$8:$C$37,3,0) -> Wood and paper products | B24: awood | AY24: 451.88793 | CF24: 451.88793
A25: =VLOOKUP(B25,Notes!$A$8:$C$37,3,0) -> Chemicals | B25: achem | AZ25: 401.13925 | CF25: 401.13925
A26: =VLOOKUP(B26,Notes!$A$8:$C$37,3,0) -> Nonmetal minerals | B26: anmet | BA26: 793.09756 | CF26: 793.09756
A27: =VLOOKUP(B27,Notes!$A$8:$C$37,3,0) -> Metals and machinery | B27: amach | BB27: 1767.9933 | CF27: 1767.9933
A28: =VLOOKUP(B28,Notes!$A$8:$C$37,3,0) -> Other manufacturing | B28: aoman | BC28: 546.81909 | CF28: 546.81909
A29: =VLOOKUP(B29,Notes!$A$8:$C$37,3,0) -> Electricity and water | B29: autil | BD29: 1038.6952 | CF29: 1038.6952
A30: =VLOOKUP(B30,Notes!$A$8:$C$37,3,0) -> Construction | B30: acons | BE30: 3926.0191 | CF30: 3926.0191
A31: =VLOOKUP(B31,Notes!$A$8:$C$37,3,0) -> Trade, hotels and food services | B31: atrad | BF31: 3220.384 | CF31: 3220.384
A32: =VLOOKUP(B32,Notes!$A$8:$C$37,3,0) -> Transport and communication | B32: atran | BG32: 2859.1981 | CF32: 2859.1981
A33: =VLOOKUP(B33,Notes!$A$8:$C$37,3,0) -> Finance, business and real estate | B33: afbsv | BH33: 2508.2331 | CF33: 2508.2331
A34: =VLOOKUP(B34,Notes!$A$8:$C$37,3,0) -> Government, health and education | B34: agsrv | BI34: 2262.4773 | CF34: 2262.4773
A35: =VLOOKUP(B35,Notes!$A$8:$C$37,3,0) -> Other services | B35: aosrv | BJ35: 1998.7722 | CF35: 1998.7722
A36: =VLOOKUP(B36,Notes!$B$8:$C$37,2,0) -> Cereals | B36: ccere | C36: 76.166746 | H36: 46.53707 | I36: 11.91275 | J36: 22.035207 | O36: 0.021601231 | Q36: 842.25167 | R36: 69.31527 | AB36: 1.7216086 | CE36: 3.2781518e-05 | CF36: 1069.962
A37: =VLOOKUP(B37,Notes!$B$8:$C$37,2,0) -> Pulses and oilseeds | B37: cpoil | D37: 12.285982 | H37: 4.256976 | I37: 15.425749 | J37: 2.0543881 | O37: 0.022248977 | P37: 38.560376 | R37: 14.989752 | AB37: 2.491125 | BS37: 8.7673975 | BT37: 13.519074 | BU37: 18.321062 | BV37: 28.467058 | BW37: 74.211649 | CE37: 1.4929173 | CF37: 234.86576
A38: =VLOOKUP(B38,Notes!$B$8:$C$37,2,0) -> Root crops | B38: croot | E38: 16.041846 | O38: 0.02208082 | R38: 12.426866 | AB38: 11.716584 | BS38: 14.972512 | BT38: 20.067856 | BU38: 26.251144 | BV38: 39.649146 | BW38: 99.844176 | CE38: 1.5388236 | CF38: 242.53103
A39: =VLOOKUP(B39,Notes!$B$8:$C$37,2,0) -> Vegetables & fruits | B39: chort | F39: 12.045377 | N39: 1.1247402 | O39: 7.625098 | P39: 3.9833823 | R39: 2.6797187 | AB39: 13.832118 | BS39: 44.110106 | BT39: 67.041442 | BU39: 93.294094 | BV39: 138.85002 | BW39: 337.12326 | CE39: 2.7266931 | CF39: 724.43605
A40: =VLOOKUP(B40,Notes!$B$8:$C$37,2,0) -> Export-oriented crops | B40: cxcrp | G40: 39.217189 | H40: 4.3148955 | J40: 2.0807402 | N40: 0.17076597 | O40: 0.086731209 | P40: 0.63190806 | R40: 33.123757 | S40: 25.208417 | T40: 140.11263 | U40: 2.6039802 | V40: 10.616452 | Y40: 31.664381 | AB40: 18.053364 | AE40: 1.786524 | AF40: 3.608282 | BS40: 34.675371 | BT40: 52.200432 | BU40: 67.523348 | BV40: 93.772653 | BW40: 186.1576 | CE40: 19.558832 | CF40: 767.16825
A41: =VLOOKUP(B41,Notes!$B$8:$C$37,2,0) -> Cattle and milk | B41: ccatt | C41: 7.4343915 | D41: 3.486659 | E41: 3.3496726 | F41: 3.5428494 | G41: 2.1263618 | H41: 6.3608092 | I41: 0.70564461 | J41: 3.0727469 | N41: 17.7265 | R41: 2.660695 | T41: 23.525761 | Y41: 8.7364229 | AB41: 60.967344 | AE41: 6.702686 | BS41: 8.8757688 | BT41: 17.793366 | BU41: 31.016927 | BV41: 53.571237 | BW41: 132.48333 | CE41: 0.0029315303 | CF41: 394.1421
A42: =VLOOKUP(B42,Notes!$B$8:$C$37,2,0) -> Poultry and eggs | B42: cpoul | I42: 100.35734 | N42: 2.5922074 | R42: 4.6210309 | BS42: 13.596365 | BT42: 22.467029 | BU42: 32.067258 | BV42: 46.26297 | BW42: 107.39434 | CE42: 0.028450019 | CF42: 329.38699
...

Sheet Ex2x_Question
A1: Questions | C1: Answers | D1: Hints and suggestions
A2: Use the information contained in the SAM to answer the following questions.
A4: GDP
A5: 1 | B5: What is the value of total GDP measured at factor cost? | D5: GDP at factor is the sum of all factor incomes earned during the production process (payments from producers/activities to land, labor and capital)
A6: 2 | B6: What are the shares of agriculture, industry and services in total GDP? | D6: Agriculture = cereals to fisheries; Industry = mining to construction; Services = Trade to other services. First calculate total agricultural GDP, and then divide by national GDP.
A7: 3 | B7: Which is the largest agricultural subsector in terms of GDP? | D7: First calculate GDP for each (by summing across factors), and then calculate shares across totals
A8: 4 | B8: What is the share of food and agriculture-related processing within manufacturing GDP? | D8: Food and Ag-processing includes Meat, fish and dairy; fruit and vegetables; Fats and oils; Grain milling; Other food processing; and beverage and tobaco sectors
A9: 5 | B9: What is the share of the government (incl. health and education) in total GDP? | D9: Divide Government, health and education sector with total GDP
A10: 6 | B10: What is the value of GDP measured at market prices? | D10: GDP mp = C + I + G + X - M
A12: Production technologies
A13: =MAX(A1:A12)+1 -> 7 | B13: What share of labor value-added is generated by uneducated workers? | D13: divide uneducated labor value-added with total labor value added
A14: =MAX(A2:A13)+1 -> 8 | B14: Which is the most capital-intensive sector in the economy? | D14: Treat capital separate from land
A15: =MAX(A4:A14)+1 -> 9 | B15: Which is the most skill-intensive sector of the economy? | D15: Share of labor value added earned by high skill worker to total labor value added
A16: =MAX(A5:A15)+1 -> 10 | B16: Which sector has the highest of production costs associated with petroleum products (chemicals)? | D16: Divide intermediate demand spending on chemical inputs by value of gross output
A17: =MAX(A6:A16)+1 -> 11 | B17: Which sector has the lowest GDP to gross output ratio? | D17: Divide GDP to value of gross output
A19: Transaction costs
A20: =MAX(A8:A19)+1 -> 12 | B20: Which product has the highest transaction costs? (calculate transaction costs as a share of total supply) | D20: Transaction costs are in the account TRC
A21: =MAX(A9:A20)+1 -> 13 | B21: What share of total transaction costs generates demand for transport services? | D21: Divide transaction costs demand on transport services with total demand of transport services
A23: Trade
A24: =MAX(A12:A23)+1 -> 14 | B24: What share of domestic production is exported? | D24: Divide total exports by total gross output
A25: =MAX(A13:A24)+1 -> 15 | B25: What share of domestic demand is supplied by imports? | D25: First subtract exports from total demand
A27: Government finance
A28: =MAX(A16:A27)+1 -> 16 | B28: What is the share of tax collections in total government revenue? | D28: Divide total taxes revenue by total government revenue
A29: =MAX(A17:A28)+1 -> 17 | B29: What share of tax revenues come from indirect and direct taxes? | D29: Divide direct and indirect taxes revenue by total government revenue
A30: =MAX(A18:A29)+1 -> 18 | B30: What is the average direct tax rate on household and enterprise incomes? | D30: Divide tax expenditure spent by enterprise and households by its total income
A31: =MAX(A19:A30)+1 -> 19 | B31: Which imported product faces the highest tariff rate? | D31: Take tariff collection (MTAX) and divide by import value (ROW)
A32: =MAX(A20:A31)+1 -> 20 | B32: What product has the highest sales tax rate? (as a share of intermediate and final demand for goods and services) | D32: First calculate total demand less exports for each product. Then take sales taxes (STAX) and divide by demand less exports
A33: =MAX(A21:A32)+1 -> 21 | B33: What share of government revenues comes from foreign grants? | D33: Divide government revenue from rest of the world by total government revenue
A34: =MAX(A22:A33)+1 -> 22 | B34: What share of government spending are transfers to domestic enterprises? What could this transfer include? | D34: Divied government spending on enterprise with total government spending
A35: =MAX(A23:A34)+1 -> 23 | B35: Does the government run a recurrent deficit or surplus, and what is it as a share of total recurrent expenditures? | D35: Look at value of government spending on savings-investment account
A37: Household incomes and expenditures | K37: Population (millions)
A38: =MAX(A26:A37)+1 -> 24 | B38: What is the total value of consumption spending for each household group? | D38: Consumption spending only includes commodities | K38: 32.105198 | L38: Household - quintile 1
A39: =MAX(A27:A38)+1 -> 25 | B39: What is the average level of per capita consumption for each household quintile? (see population data) | D39: Divide consumption spending by total household population | K39: 32.018407 | L39: Household - quintile 2
A40: =MAX(A28:A39)+1 -> 26 | B40: What share of consumption spending for each quintile is spent on agricultural and food products? | D40: For foods, include from Meat-Beverages | K40: 32.056355 | L40: Household - quintile 3
A41: =MAX(A29:A40)+1 -> 27 | B41: What share of incomes for each household group comes from factors, enterprises, government and rest of world? | D41: First collect on income source values in a single table, and then calculate shares | K41: 32.086998 | L41: Household - quintile 4
A42: =MAX(A30:A41)+1 -> 28 | B42: What is the average marginal propensity to save for households? (average for all groups) | D42: Divide total household savings with total expenditure | K42: 32.010027 | L42: Household - quintile 5
K43: =SUM(K38:K42) -> 160.27698 | L43: All households
A44: Other accounts
A45: =MAX(A35:A44)+1 -> 29 | B45: What share of gross fixed capital formation is demand for construction? | D45: Divide investment demand on construction by total construction demand
A46: =MAX(A36:A45)+1 -> 30 | B46: What share of gross capital formation is changes in stocks? | D46: GCF includes GFCF plus stock changes
...

Sheet Workings

Sheet Ex2x_Answers
A1: Questions | C1: Answers | D1: Hints and suggestions
A2: Use the information contained in the SAM to answer the following questions.
A4: GDP
A5: 1 | B5: What is the value of total GDP measured at factor cost? | C5: =SUM(SAM!C67:AF72) -> 16253.846 | D5: GDP at factor is the sum of all factor incomes earned during the production process (payments from producers/activities to land, labor and capital)
A6: 2 | B6: What are the shares of agriculture, industry and services in total GDP? | C6: 16.287266 | D6: Agriculture = cereals to fisheries; Industry = mining to construction; Services = Trade to other services. First calculate total agricultural GDP, and then divide by national GDP.
A7: 3 | B7: Which is the largest agricultural subsector in terms of GDP? | C7: Cereal | D7: First calculate GDP for each (by summing across factors), and then calculate shares across totals
A8: 4 | B8: What is the share of food and agriculture-related processing within manufacturing GDP? | C8: 11.565084 | D8: Food and Ag-processing includes Meat, fish and dairy; fruit and vegetables; Fats and oils; Grain milling; Other food processing; and beverage and tobaco sectors
A9: 5 | B9: What is the share of the government (incl. health and education) in total GDP? | C9: 9.0816054 | D9: Divide Government, health and education sector with total GDP
A10: 6 | B10: What is the value of GDP measured at market prices? | C10: 13147.974 | D10: GDP mp = C + I + G + X - M
A12: Production technologies
A13: =MAX(A1:A12)+1 -> 7 | B13: What share of labor value-added is generated by uneducated workers? | C13: 49.016714 | D13: divide uneducated labor value-added with total labor value added
A14: =MAX(A2:A13)+1 -> 8 | B14: Which is the most capital-intensive sector in the economy? | C14: Other services | D14: Treat capital separate from land
A15: =MAX(A4:A14)+1 -> 9 | B15: Which is the most skill-intensive sector of the economy? | C15: Gov. services | D15: Share of labor value added earned by high skill worker to total labor value added
A16: =MAX(A5:A15)+1 -> 10 | B16: Which sector has the highest of production costs associated with petroleum products (chemicals)? | C16: chemical | D16: Divide intermediate demand spending on chemical inputs by value of gross output
A17: =MAX(A6:A16)+1 -> 11 | B17: Which sector has the lowest GDP to gross output ratio? | C17: grain milling | D17: Divide GDP to value of gross output
A19: Transaction costs
A20: =MAX(A8:A19)+1 -> 12 | B20: Which product has the highest transaction costs? (calculate transaction costs as a share of total supply) | C20: Horticulture | D20: Transaction costs are in the account TRC
A21: =MAX(A9:A20)+1 -> 13 | B21: What share of total transaction costs generates demand for transport services? | C21: =SAM!BK62/SAM!CF62*100 -> 45.68624 | D21: Divide transaction costs demand on transport services with total demand of transport services
A23: Trade
A24: =MAX(A12:A23)+1 -> 14 | B24: What share of domestic production is exported? | C24: =SUM(SAM!CE36:CE65)/SUM(SAM!CF6:CF29)*100 -> 21.083173 | D24: Divide total exports by total gross output
A25: =MAX(A13:A24)+1 -> 15 | B25: What share of domestic demand is supplied by imports? | C25: 10.144958 | D25: First subtract exports from total demand
A27: Government finance
A28: =MAX(A16:A27)+1 -> 16 | B28: What is the share of tax collections in total government revenue? | C28: 83.359335 | D28: Divide total taxes revenue by total government revenue
A29: =MAX(A17:A28)+1 -> 17 | B29: What share of tax revenues come from indirect and direct taxes? | C29: 30.7 and 52.7 | D29: Divide direct and indirect taxes revenue by total government revenue
A30: =MAX(A18:A29)+1 -> 18 | B30: What is the average direct tax rate on household and enterprise incomes? | C30: 3.5 and 1 | D30: Divide tax expenditure spent by enterprise and households by its total income
A31: =MAX(A19:A30)+1 -> 19 | B31: Which imported product faces the highest tariff rate? | C31: Poultry | D31: Take tariff collection (MTAX) and divide by import value (ROW)
A32: =MAX(A20:A31)+1 -> 20 | B32: What product has the highest sales tax rate? (as a share of intermediate and final demand for goods and services) | C32: fats and oil | D32: First calculate total demand less exports for each product. Then take sales taxes (STAX) and divide by demand less exports
A33: =MAX(A21:A32)+1 -> 21 | B33: What share of government revenues comes from foreign grants? | C33: =SAM!CE79/SAM!CF79*100 -> 1.3238126 | D33: Divide government revenue from rest of the world by total government revenue
A34: =MAX(A22:A33)+1 -> 22 | B34: What share of government spending are transfers to domestic enterprises? What could this transfer include? | C34: =SAM!BX73/SAM!BX87 -> 0.28138206 | D34: Divied government spending on enterprise with total government spending
A35: =MAX(A23:A34)+1 -> 23 | B35: Does the government run a recurrent deficit or surplus, and what is it as a share of total recurrent expenditures? | C35: deficit | D35: Look at value of government spending on savings-investment account
C36: =SAM!BX84/SAM!BX87 -> -0.020963826
A37: Household incomes and expenditures | L37: Population (millions)
A38: =MAX(A26:A37)+1 -> 24 | B38: What is the total value of consumption spending for each household group? | C38: look at answer_workings sheet | D38: Consumption spending only includes commodities | L38: 32.105198 | M38: Household - quintile 1
A39: =MAX(A27:A38)+1 -> 25 | B39: What is the average level of per capita consumption for each household quintile? (see population data) | C39: look at answer_workings sheet | D39: Divide consumption spending by total household population | L39: 32.018407 | M39: Household - quintile 2
A40: =MAX(A28:A39)+1 -> 26 | B40: What share of consumption spending for each quintile is spent on agricultural and food products? | C40: look at answer_workings sheet | D40: For foods, include from Meat-Beverages | L40: 32.056355 | M40: Household - quintile 3
A41: =MAX(A29:A40)+1 -> 27 | B41: What share of incomes for each household group comes from factors, enterprises, government and rest of world? | C41: look at answer_workings sheet | D41: First collect on income source values in a single table, and then calculate shares | L41: 32.086998 | M41: Household - quintile 4
A42: =MAX(A30:A41)+1 -> 28 | B42: What is the average marginal propensity to save for households? (average for all groups) | C42: 20.039658 | D42: Divide total household savings with total expenditure | L42: 32.010027 | M42: Household - quintile 5
L43: =SUM(L38:L42) -> 160.27698 | M43: All households
A44: Other accounts
A45: =MAX(A35:A44)+1 -> 29 | B45: What share of gross fixed capital formation is demand for construction? | C45: =SAM!CC60/SAM!CF60*100 -> 92.681752 | D45: Divide investment demand on construction by total construction demand
...

Sheet Answer_Workings
B2: Answer calculations
C4: GDP | D4: GDP Share (%)
A5: No.1-2 | B5: Agr | C5: =SUM(SAM!C67:L72) -> 2647.3071 | D5: =C5/$C$8*100 -> 16.287266
B6: Ind | C6: =SUM(SAM!M67:AA72) -> 4565.9838 | D6: =C6/$C$8*100 -> 28.091713
B7: Srv | C7: =SUM(SAM!AB67:AF72) -> 9040.555 | D7: =C7/$C$8*100 -> 55.621021
C8: =SUM(C5:C7) -> 16253.846
A12: 3 | C12: acere | D12: apoil | E12: aroot | F12: ahort | G12: axcrp | H12: acatt | I12: apoul | J12: aoliv | K12: afore | L12: afish | M12: tot_AgGDP
B13: AgGDP | C13: =SUM(SAM!C67:C72) -> 740.92884 | D13: =SUM(SAM!D67:D72) -> 97.492398 | E13: =SUM(SAM!E67:E72) -> 134.87066 | F13: =SUM(SAM!F67:F72) -> 200.43711 | G13: =SUM(SAM!G67:G72) -> 194.59724 | H13: =SUM(SAM!H67:H72) -> 111.40071 | I13: =SUM(SAM!I67:I72) -> 107.54334 | J13: =SUM(SAM!J67:J72) -> 138.85469 | ... L13: =SUM(SAM!L67:L72) -> 705.08827 | M13: =SUM(C13:L13) -> 2647.3071
B14: Share | C14: =C13/$M$13 -> 0.2798802 | D14: =D13/$M$13 -> 0.036827007 | E14: =E13/$M$13 -> 0.050946359 | F14: =F13/$M$13 -> 0.075713583 | G14: =G13/$M$13 -> 0.073507617 | H14: =H13/$M$13 -> 0.042080765 | I14: =I13/$M$13 -> 0.040623675 | J14: =J13/$M$13 -> 0.052451297 | ... L14: =L13/$M$13 -> 0.26634169
C19: amine | D19: ameat | E19: afveg | F19: afoil | G19: agmll | H19: afood | I19: abeve | J19: atext | K19: awood | L19: achem | M19: anmet | N19: amach | O19: aoman | P19: tot_MnfGDP
B20: MnfGDP | C20: =SUM(SAM!M67:M72) -> 285.66544 | D20: =SUM(SAM!N67:N72) -> 41.871902 | E20: =SUM(SAM!O67:O72) -> 5.7964931 | F20: =SUM(SAM!P67:P72) -> 35.76687 | G20: =SUM(SAM!Q67:Q72) -> 70.725832 | H20: =SUM(SAM!R67:R72) -> 144.98203 | I20: =SUM(SAM!S67:S72) -> 56.223209 | J20: =SUM(SAM!T67:T72) -> 1303.4073 | ... O20: =SUM(SAM!Y67:Y72) -> 182.4607 | P20: =SUM(C20:O20) -> 3072.7518
B21: Share | C21: =C20/$P$20 -> 0.092967298 | D21: =D20/$P$20 -> 0.013626841 | E21: =E20/$P$20 -> 0.0018864176 | F21: =F20/$P$20 -> 0.011640013 | G21: =G20/$P$20 -> 0.023017099 | H21: =H20/$P$20 -> 0.047183124 | I21: =I20/$P$20 -> 0.018297348 | J21: =J20/$P$20 -> 0.42418243 | ... O21: =O20/$P$20 -> 0.059380227
A23: 4 | B23: Food_Shr | C23: =SUM(D21:I21) -> 0.11565084
C27: autil | D27: acons | E27: atrad | F27: atran | G27: afbsv | H27: agsrv | I27: aosrv | J27: Tot_srvGDP | K27: Tot_GDP
B28: Srv_GDP | C28: =SUM(SAM!Z67:Z72) -> 238.05542 | D28: =SUM(SAM!AA67:AA72) -> 1255.1766 | E28: =SUM(SAM!AB67:AB72) -> 2361.0753 | F28: =SUM(SAM!AC67:AC72) -> 1704.8172 | G28: =SUM(SAM!AD67:AD72) -> 1787.2901 | H28: =SUM(SAM!AE67:AE72) -> 1476.1101 | I28: =SUM(SAM!AF67:AF72) -> 1711.2624 | J28: =SUM(C28:I28) -> 10533.787 | K28: =M13+P20+J28 -> 16253.846
C29: =C28/$J$28 -> 0.022599225 | D29: =D28/$J$28 -> 0.1191572 | E29: =E28/$J$28 -> 0.22414306 | F29: =F28/$J$28 -> 0.16184276 | G29: =G28/$J$28 -> 0.16967213 | H29: =H28/$J$28 -> 0.140131 | I29: =I28/$J$28 -> 0.16245462
A31: 5 | B31: Gov/GDP | C31: =H28/K28 -> 0.090816054
A35: 6 | C35: hhd-1 | D35: hhd-2 | E35: hhd-3 | F35: hhd-4 | G35: hhd-5 | H35: gov | I35: s-i | J35: dstk | K35: X | L35: M | M35: GDP at market price
B36: Demand | C36: =SAM!BS87 -> 901.88537 | D36: =SAM!BT87 -> 1476.4525 | E36: =SAM!BU87 -> 2142.0386 | F36: =SAM!BV87 -> 3052.4561 | G36: =SAM!BW87 -> 6819.2478 | H36: =SAM!BX87 -> 1634.08 | I36: =SAM!BY87 -> 501.63124 | J36: =SAM!BZ87 -> 0 | K36: =SAM!CA87 -> 369.20103 | L36: =-SUM(SAM!AG86:BJ86) -> -3749.0183 | M36: =SUM(C36:L36) -> 13147.974
C38: Labor VA | D38: Share
A39: 7 | B39: flab-n | C39: =SUM(SAM!C67:AF67) -> 2633.8017 | D39: =C39/SUM($C$39:$C$42) -> 0.49016714
B40: flab-p | C40: =SUM(SAM!C68:AF68) -> 998.46741 | D40: =C40/SUM($C$39:$C$42) -> 0.18582109
B41: flab-s | C41: =SUM(SAM!C69:AF69) -> 1075.2943 | D41: =C41/SUM($C$39:$C$42) -> 0.20011906
B42: flab-t | C42: =SUM(SAM!C70:AF70) -> 665.70931 | D42: =C42/SUM($C$39:$C$42) -> 0.12389271
C44: acere | D44: apoil | E44: aroot | F44: ahort | G44: axcrp | H44: acatt | I44: apoul | J44: aoliv | K44: afore | L44: afish | M44: amine | N44: ameat | O44: afveg | P44: afoil | Q44: agmll | R44: afood | S44: abeve | T44: atext | U44: awood | V44: achem | W44: anmet | X44: amach | Y44: aoman | Z44: autil | AA44: acons | AB44: atrad | AC44: atran | AD44: afbsv | AE44: agsrv | AF44: aosrv
A45: 8 | B45: Lab | C45: =SUM(SAM!C67:C70) -> 401.28302 | D45: =SUM(SAM!D67:D70) -> 44.498826 | E45: =SUM(SAM!E67:E70) -> 52.657895 | F45: =SUM(SAM!F67:F70) -> 47.283362 | G45: =SUM(SAM!G67:G70) -> 81.575699 | H45: =SUM(SAM!H67:H70) -> 35.919842 | I45: =SUM(SAM!I67:I70) -> 31.003562 | J45: =SUM(SAM!J67:J70) -> 45.454459 | ... AF45: =SUM(SAM!AF67:AF70) -> 95.148653
B46: Land | C46: =SAM!C71 -> 321.32354 | D46: =SAM!D71 -> 50.448344 | E46: =SAM!E71 -> 78.613767 | F46: =SAM!F71 -> 145.94398 | G46: =SAM!G71 -> 107.83477 | H46: =SAM!H71 -> 0 | I46: =SAM!I71 -> 0 | J46: =SAM!J71 -> 0 | ... AF46: =SAM!AF71 -> 0
B47: Cap | C47: =SAM!C72 -> 18.322282 | D47: =SAM!D72 -> 2.5452273 | E47: =SAM!E72 -> 3.598996 | F47: =SAM!F72 -> 7.2097639 | G47: =SAM!G72 -> 5.1867693 | H47: =SAM!H72 -> 75.480868 | I47: =SAM!I72 -> 76.539782 | J47: =SAM!J72 -> 93.400233 | ... AF47: =SAM!AF72 -> 1616.1137
C48: =SUM(C45:C47) -> 740.92884 | D48: =SUM(D45:D47) -> 97.492398 | E48: =SUM(E45:E47) -> 134.87066 | F48: =SUM(F45:F47) -> 200.43711 | G48: =SUM(G45:G47) -> 194.59724 | H48: =SUM(H45:H47) -> 111.40071 | I48: =SUM(I45:I47) -> 107.54334 | J48: =SUM(J45:J47) -> 138.85469 | ... AF48: =SUM(AF45:AF47) -> 1711.2624
A50: 8 | B50: Cap_shr | C50: =C47/C48 -> 0.024728801 | D50: =D47/D48 -> 0.026106931 | E50: =E47/E48 -> 0.026684796 | F50: =F47/F48 -> 0.035970205 | G50: =G47/G48 -> 0.026653869 | H50: =H47/H48 -> 0.67756182 | I50: =I47/I48 -> 0.71171101 | J50: =J47/J48 -> 0.6726473 | ... AF50: =AF47/AF48 -> 0.94439856
A52: 9 | B52: Labor Value Added (VA)
C53: acere | D53: apoil | E53: aroot | F53: ahort | G53: axcrp | H53: acatt | I53: apoul | J53: aoliv | K53: afore | L53: afish | M53: amine | N53: ameat | O53: afveg | P53: afoil | Q53: agmll | R53: afood | S53: abeve | T53: atext | U53: awood | V53: achem | W53: anmet | X53: amach | Y53: aoman | Z53: autil | AA53: acons | AB53: atrad | AC53: atran | AD53: afbsv | AE53: agsrv | AF53: aosrv
B54: flab-n | C54: =SAM!C67 -> 253.06585 | D54: =SAM!D67 -> 31.335264 | E54: =SAM!E67 -> 33.111534 | F54: =SAM!F67 -> 35.857197 | G54: =SAM!G67 -> 58.190466 | H54: =SAM!H67 -> 26.851769 | I54: =SAM!I67 -> 19.983084 | J54: =SAM!J67 -> 34.764707 | ... AF54: =SAM!AF67 -> 52.182106
B55: flab-p | C55: =SAM!C68 -> 91.093868 | D55: =SAM!D68 -> 8.1207166 | E55: =SAM!E68 -> 9.9106708 | F55: =SAM!F68 -> 6.7002911 | G55: =SAM!G68 -> 12.766427 | H55: =SAM!H68 -> 5.8375581 | I55: =SAM!I68 -> 6.7737852 | J55: =SAM!J68 -> 7.09196 | ... AF55: =SAM!AF68 -> 23.993462
B56: flab-s | C56: =SAM!C69 -> 45.1545 | D56: =SAM!D69 -> 4.1656224 | E56: =SAM!E69 -> 7.4408616 | F56: =SAM!F69 -> 3.1016722 | G56: =SAM!G69 -> 9.2752248 | H56: =SAM!H69 -> 2.5135062 | I56: =SAM!I69 -> 3.748948 | J56: =SAM!J69 -> 2.5688282 | ... AF56: =SAM!AF69 -> 8.3987315
B57: flab-t | C57: =SAM!C70 -> 11.968807 | D57: =SAM!D70 -> 0.87722305 | E57: =SAM!E70 -> 2.1948293 | F57: =SAM!F70 -> 1.6242014 | G57: =SAM!G70 -> 1.3435815 | H57: =SAM!H70 -> 0.71700839 | I57: =SAM!I70 -> 0.49774475 | J57: =SAM!J70 -> 1.0289632 | ... AF57: =SAM!AF70 -> 10.574353
B59: Labor VA share
A60: 9 | B60: flab-n | C60: =C54/C$48 -> 0.34155216 | D60: =D54/D$48 -> 0.32141239 | E60: =E54/E$48 -> 0.24550583 | F60: =F54/F$48 -> 0.178895 | G60: =G54/G$48 -> 0.29903027 | H60: =H54/H$48 -> 0.24103768 | I60: =I54/I$48 -> 0.18581424 | J60: =J54/J$48 -> 0.25036754 | ... AF60: =AF54/AF$48 -> 0.030493341
B61: flab-p | C61: =C55/C$48 -> 0.1229455 | D61: =D55/D$48 -> 0.083295895 | E61: =E55/E$48 -> 0.073482779 | F61: =F55/F$48 -> 0.033428396 | G61: =G55/G$48 -> 0.065604357 | H61: =H55/H$48 -> 0.052401444 | I61: =I55/I$48 -> 0.062986559 | J61: =J55/J$48 -> 0.051074687 | ... AF61: =AF55/AF$48 -> 0.014020914
B62: flab-s | C62: =C56/C$48 -> 0.060943099 | D62: =D56/D$48 -> 0.042727664 | E62: =E56/E$48 -> 0.055170352 | F62: =F56/F$48 -> 0.015474541 | G62: =G56/G$48 -> 0.047663702 | H62: =H56/H$48 -> 0.022562748 | I62: =I56/I$48 -> 0.03485988 | J62: =J56/J$48 -> 0.018500118 | ... AF62: =AF56/AF$48 -> 0.0049079158
...
