Workbook

Sheet Notes
A1: ="Static Standard Reporting | "&E3&" ("&E4&")" -> Static Standard Reporting | Nepal (2022)
D3: Country | E3: Nepal
D4: Year | E4: 2022
D5: Units | E5: Billions of Nepalese Rupee
C7: Activities and commodities | I7: Factors | N7: Households | T7: Appearance in reporting tables
C8: Level | D8: Account | E8: Description (activities) | F8: Description (commodities) | I8: Level | J8: Account | K8: Description | N8: Level | O8: Account | P8: Description | T8: Activities | U8: Commodities | V8: Factors | W8: Households
C9: 1 | D9: aa_GDP | E9: All sectors | F9: All products | I9: 1 | J9: ff_LAB | K9: Labor | N9: 1 | O9: hh_ALL | P9: All households | T9: =IF(C9=1,E9,IF(C9=2," "&E9,IF(C9=3," "&E9,IF(C9=4," "&E9," "&E9)))) -> All sectors | U9: =IF(C9=1,F9,IF(C9=2," "&F9,IF(C9=3," "&F9,IF(C9=4," "&F9," "&F9)))) -> All products | V9: =IF(I9=1,K9,IF(I9=2," "&K9,IF(I9=3," "&K9,IF(I9=4," "&K9," "&K9)))) -> Labor | W9: =IF(N9=1,P9,IF(N9=2," "&P9,IF(N9=3," "&P9,IF(N9=4," "&P9," "&P9)))) -> All households
C10: 1 | D10: aa_AGRI | E10: Agriculture | F10: Agriculture | I10: 3 | J10: ff_LAB_N | K10: Labor - uneducated | N10: 3 | O10: hh_D1 | P10: Decile 1 (low) | T10: =IF(C10=1,E10,IF(C10=2," "&E10,IF(C10=3," "&E10,IF(C10=4," "&E10," "&E10)))) -> Agriculture | U10: =IF(C10=1,F10,IF(C10=2," "&F10,IF(C10=3," "&F10,IF(C10=4," "&F10," "&F10)))) -> Agriculture | V10: =IF(I10=1,K10,IF(I10=2," "&K10,IF(I10=3," "&K10,IF(I10=4," "&K10," "&K10)))) -> Labor - uneducated | W10: =IF(N10=1,P10,IF(N10=2," "&P10,IF(N10=3," "&P10,IF(N10=4," "&P10," "&P10)))) -> Decile 1 (low)
C11: 2 | D11: aa_CROP | E11: Crops | F11: Crops | I11: 3 | J11: ff_LAB_P | K11: Labor - primary | N11: 3 | O11: hh_D2 | P11: Decile 2 | T11: =IF(C11=1,E11,IF(C11=2," "&E11,IF(C11=3," "&E11,IF(C11=4," "&E11," "&E11)))) -> Crops | U11: =IF(C11=1,F11,IF(C11=2," "&F11,IF(C11=3," "&F11,IF(C11=4," "&F11," "&F11)))) -> Crops | V11: =IF(I11=1,K11,IF(I11=2," "&K11,IF(I11=3," "&K11,IF(I11=4," "&K11," "&K11)))) -> Labor - primary | W11: =IF(N11=1,P11,IF(N11=2," "&P11,IF(N11=3," "&P11,IF(N11=4," "&P11," "&P11)))) -> Decile 2
C12: 3 | D12: a_maiz | E12: Maize | F12: Maize | I12: 3 | J12: ff_LAB_S | K12: Labor - secondary | N12: 3 | O12: hh_D3 | P12: Decile 3 | T12: =IF(C12=1,E12,IF(C12=2," "&E12,IF(C12=3," "&E12,IF(C12=4," "&E12," "&E12)))) -> Maize | U12: =IF(C12=1,F12,IF(C12=2," "&F12,IF(C12=3," "&F12,IF(C12=4," "&F12," "&F12)))) -> Maize | V12: =IF(I12=1,K12,IF(I12=2," "&K12,IF(I12=3," "&K12,IF(I12=4," "&K12," "&K12)))) -> Labor - secondary | W12: =IF(N12=1,P12,IF(N12=2," "&P12,IF(N12=3," "&P12,IF(N12=4," "&P12," "&P12)))) -> Decile 3
C13: 3 | D13: a_sorg | E13: Sorghum and millet | F13: Sorghum and millet | I13: 3 | J13: ff_LAB_T | K13: Labor - tertiary | N13: 3 | O13: hh_D4 | P13: Decile 4 | T13: =IF(C13=1,E13,IF(C13=2," "&E13,IF(C13=3," "&E13,IF(C13=4," "&E13," "&E13)))) -> Sorghum and millet | U13: =IF(C13=1,F13,IF(C13=2," "&F13,IF(C13=3," "&F13,IF(C13=4," "&F13," "&F13)))) -> Sorghum and millet | V13: =IF(I13=1,K13,IF(I13=2," "&K13,IF(I13=3," "&K13,IF(I13=4," "&K13," "&K13)))) -> Labor - tertiary | W13: =IF(N13=1,P13,IF(N13=2," "&P13,IF(N13=3," "&P13,IF(N13=4," "&P13," "&P13)))) -> Decile 4
C14: 3 | D14: a_aman | E14: Rice paddy (Aman) | F14: Rice paddy (Aman) | I14: 2 | J14: ff_RUR | K14: Labor - rural | N14: 3 | O14: hh_D5 | P14: Decile 5 | T14: =IF(C14=1,E14,IF(C14=2," "&E14,IF(C14=3," "&E14,IF(C14=4," "&E14," "&E14)))) -> Rice paddy (Aman) | U14: =IF(C14=1,F14,IF(C14=2," "&F14,IF(C14=3," "&F14,IF(C14=4," "&F14," "&F14)))) -> Rice paddy (Aman) | V14: =IF(I14=1,K14,IF(I14=2," "&K14,IF(I14=3," "&K14,IF(I14=4," "&K14," "&K14)))) -> Labor - rural | W14: =IF(N14=1,P14,IF(N14=2," "&P14,IF(N14=3," "&P14,IF(N14=4," "&P14," "&P14)))) -> Decile 5
C15: 3 | D15: a_boro | E15: Rice paddy (Boro) | F15: Rice paddy (Boro) | I15: 3 | J15: f_lab-rn | K15: Labor - rural uneducated | N15: 3 | O15: hh_D6 | P15: Decile 6 | T15: =IF(C15=1,E15,IF(C15=2," "&E15,IF(C15=3," "&E15,IF(C15=4," "&E15," "&E15)))) -> Rice paddy (Boro) | U15: =IF(C15=1,F15,IF(C15=2," "&F15,IF(C15=3," "&F15,IF(C15=4," "&F15," "&F15)))) -> Rice paddy (Boro) | V15: =IF(I15=1,K15,IF(I15=2," "&K15,IF(I15=3," "&K15,IF(I15=4," "&K15," "&K15)))) -> Labor - rural uneducated | W15: =IF(N15=1,P15,IF(N15=2," "&P15,IF(N15=3," "&P15,IF(N15=4," "&P15," "&P15)))) -> Decile 6
C16: 3 | D16: a_whea | E16: Wheat and barley | F16: Wheat and barley | I16: 3 | J16: f_lab-rp | K16: Labor - rural primary | N16: 3 | O16: hh_D7 | P16: Decile 7 | T16: =IF(C16=1,E16,IF(C16=2," "&E16,IF(C16=3," "&E16,IF(C16=4," "&E16," "&E16)))) -> Wheat and barley | U16: =IF(C16=1,F16,IF(C16=2," "&F16,IF(C16=3," "&F16,IF(C16=4," "&F16," "&F16)))) -> Wheat and barley | V16: =IF(I16=1,K16,IF(I16=2," "&K16,IF(I16=3," "&K16,IF(I16=4," "&K16," "&K16)))) -> Labor - rural primary | W16: =IF(N16=1,P16,IF(N16=2," "&P16,IF(N16=3," "&P16,IF(N16=4," "&P16," "&P16)))) -> Decile 7
C17: 3 | D17: a_ocer | E17: Other cereals | F17: Other cereals | I17: 3 | J17: f_lab-rs | K17: Labor - rural secondary | N17: 3 | O17: hh_D8 | P17: Decile 8 | T17: =IF(C17=1,E17,IF(C17=2," "&E17,IF(C17=3," "&E17,IF(C17=4," "&E17," "&E17)))) -> Other cereals | U17: =IF(C17=1,F17,IF(C17=2," "&F17,IF(C17=3," "&F17,IF(C17=4," "&F17," "&F17)))) -> Other cereals | V17: =IF(I17=1,K17,IF(I17=2," "&K17,IF(I17=3," "&K17,IF(I17=4," "&K17," "&K17)))) -> Labor - rural secondary | W17: =IF(N17=1,P17,IF(N17=2," "&P17,IF(N17=3," "&P17,IF(N17=4," "&P17," "&P17)))) -> Decile 8
C18: 3 | D18: a_puls | E18: Pulses | F18: Pulses | I18: 3 | J18: f_lab-rt | K18: Labor - rural tertiary | N18: 3 | O18: hh_D9 | P18: Decile 9 | T18: =IF(C18=1,E18,IF(C18=2," "&E18,IF(C18=3," "&E18,IF(C18=4," "&E18," "&E18)))) -> Pulses | U18: =IF(C18=1,F18,IF(C18=2," "&F18,IF(C18=3," "&F18,IF(C18=4," "&F18," "&F18)))) -> Pulses | V18: =IF(I18=1,K18,IF(I18=2," "&K18,IF(I18=3," "&K18,IF(I18=4," "&K18," "&K18)))) -> Labor - rural tertiary | W18: =IF(N18=1,P18,IF(N18=2," "&P18,IF(N18=3," "&P18,IF(N18=4," "&P18," "&P18)))) -> Decile 9
C19: 3 | D19: a_gnut | E19: Groundnuts | F19: Groundnuts | I19: 2 | J19: ff_URB | K19: Labor - urban | N19: 3 | O19: hh_D10 | P19: Decile 10 (high) | T19: =IF(C19=1,E19,IF(C19=2," "&E19,IF(C19=3," "&E19,IF(C19=4," "&E19," "&E19)))) -> Groundnuts | U19: =IF(C19=1,F19,IF(C19=2," "&F19,IF(C19=3," "&F19,IF(C19=4," "&F19," "&F19)))) -> Groundnuts | V19: =IF(I19=1,K19,IF(I19=2," "&K19,IF(I19=3," "&K19,IF(I19=4," "&K19," "&K19)))) -> Labor - urban | W19: =IF(N19=1,P19,IF(N19=2," "&P19,IF(N19=3," "&P19,IF(N19=4," "&P19," "&P19)))) -> Decile 10 (high)
C20: 3 | D20: a_oils | E20: Other oilseeds | F20: Other oilseeds | I20: 3 | J20: f_lab-un | K20: Labor - urban uneducated | N20: 2 | O20: hh_RUR | P20: Rural households | T20: =IF(C20=1,E20,IF(C20=2," "&E20,IF(C20=3," "&E20,IF(C20=4," "&E20," "&E20)))) -> Other oilseeds | U20: =IF(C20=1,F20,IF(C20=2," "&F20,IF(C20=3," "&F20,IF(C20=4," "&F20," "&F20)))) -> Other oilseeds | V20: =IF(I20=1,K20,IF(I20=2," "&K20,IF(I20=3," "&K20,IF(I20=4," "&K20," "&K20)))) -> Labor - urban uneducated | W20: =IF(N20=1,P20,IF(N20=2," "&P20,IF(N20=3," "&P20,IF(N20=4," "&P20," "&P20)))) -> Rural households
... C29: 3 | D29: a_cott | E29: Cotton and fibres | F29: Cotton and fibres | I29: 2 | J29: f_cap-n | K29: Capital - non-primary | N29: 3 | O29: h_hhd-r8 | P29: Rural - decile 9 | T29: =IF(C29=1,E29,IF(C29=2," "&E29,IF(C29=3," "&E29,IF(C29=4," "&E29," "&E29)))) -> Cotton and fibres | U29: =IF(C29=1,F29,IF(C29=2," "&F29,IF(C29=3," "&F29,IF(C29=4," "&F29," "&F29)))) -> Cotton and fibres | V29: =IF(I29=1,K29,IF(I29=2," "&K29,IF(I29=3," "&K29,IF(I29=4," "&K29," "&K29)))) -> Capital - non-primary | W29: =IF(N29=1,P29,IF(N29=2," "&P29,IF(N29=3," "&P29,IF(N29=4," "&P29," "&P29)))) -> Rural - decile 9
C30: 3 | D30: a_jute | E30: Jute | F30: Jute | N30: 3 | O30: h_hhd-r9 | P30: Rural - decile 10 (high) | T30: =IF(C30=1,E30,IF(C30=2," "&E30,IF(C30=3," "&E30,IF(C30=4," "&E30," "&E30)))) -> Jute | U30: =IF(C30=1,F30,IF(C30=2," "&F30,IF(C30=3," "&F30,IF(C30=4," "&F30," "&F30)))) -> Jute | V30: =IF(I30=1,K30,IF(I30=2," "&K30,IF(I30=3," "&K30,IF(I30=4," "&K30," "&K30)))) | W30: =IF(N30=1,P30,IF(N30=2," "&P30,IF(N30=3," "&P30,IF(N30=4," "&P30," "&P30)))) -> Rural - decile 10 (high)
C31: 3 | D31: a_nuts | E31: Nuts | F31: Nuts | N31: 2 | O31: hh_URB | P31: Urban households | T31: =IF(C31=1,E31,IF(C31=2," "&E31,IF(C31=3," "&E31,IF(C31=4," "&E31," "&E31)))) -> Nuts | U31: =IF(C31=1,F31,IF(C31=2," "&F31,IF(C31=3," "&F31,IF(C31=4," "&F31," "&F31)))) -> Nuts | V31: =IF(I31=1,K31,IF(I31=2," "&K31,IF(I31=3," "&K31,IF(I31=4," "&K31," "&K31)))) | W31: =IF(N31=1,P31,IF(N31=2," "&P31,IF(N31=3," "&P31,IF(N31=4," "&P31," "&P31)))) -> Urban households
C32: 3 | D32: a_bana | E32: Bananas and plantains | F32: Bananas and plantains | N32: 3 | O32: h_hhd-u0 | P32: Urban - decile 1 (low) | T32: =IF(C32=1,E32,IF(C32=2," "&E32,IF(C32=3," "&E32,IF(C32=4," "&E32," "&E32)))) -> Bananas and plantains | U32: =IF(C32=1,F32,IF(C32=2," "&F32,IF(C32=3," "&F32,IF(C32=4," "&F32," "&F32)))) -> Bananas and plantains | V32: =IF(I32=1,K32,IF(I32=2," "&K32,IF(I32=3," "&K32,IF(I32=4," "&K32," "&K32)))) | W32: =IF(N32=1,P32,IF(N32=2," "&P32,IF(N32=3," "&P32,IF(N32=4," "&P32," "&P32)))) -> Urban - decile 1 (low)
C33: 3 | D33: a_frui | E33: Other fruits | F33: Other fruits | N33: 3 | O33: h_hhd-u1 | P33: Urban - decile 2 | T33: =IF(C33=1,E33,IF(C33=2," "&E33,IF(C33=3," "&E33,IF(C33=4," "&E33," "&E33)))) -> Other fruits | U33: =IF(C33=1,F33,IF(C33=2," "&F33,IF(C33=3," "&F33,IF(C33=4," "&F33," "&F33)))) -> Other fruits | V33: =IF(I33=1,K33,IF(I33=2," "&K33,IF(I33=3," "&K33,IF(I33=4," "&K33," "&K33)))) | W33: =IF(N33=1,P33,IF(N33=2," "&P33,IF(N33=3," "&P33,IF(N33=4," "&P33," "&P33)))) -> Urban - decile 2
C34: 3 | D34: a_teal | E34: Leaf tea | F34: Leaf tea | N34: 3 | O34: h_hhd-u2 | P34: Urban - decile 3 | T34: =IF(C34=1,E34,IF(C34=2," "&E34,IF(C34=3," "&E34,IF(C34=4," "&E34," "&E34)))) -> Leaf tea | U34: =IF(C34=1,F34,IF(C34=2," "&F34,IF(C34=3," "&F34,IF(C34=4," "&F34," "&F34)))) -> Leaf tea | V34: =IF(I34=1,K34,IF(I34=2," "&K34,IF(I34=3," "&K34,IF(I34=4," "&K34," "&K34)))) | W34: =IF(N34=1,P34,IF(N34=2," "&P34,IF(N34=3," "&P34,IF(N34=4," "&P34," "&P34)))) -> Urban - decile 3
C35: 3 | D35: a_coff | E35: Coffee | F35: Coffee | N35: 3 | O35: h_hhd-u3 | P35: Urban - decile 4 | T35: =IF(C35=1,E35,IF(C35=2," "&E35,IF(C35=3," "&E35,IF(C35=4," "&E35," "&E35)))) -> Coffee | U35: =IF(C35=1,F35,IF(C35=2," "&F35,IF(C35=3," "&F35,IF(C35=4," "&F35," "&F35)))) -> Coffee | V35: =IF(I35=1,K35,IF(I35=2," "&K35,IF(I35=3," "&K35,IF(I35=4," "&K35," "&K35)))) | W35: =IF(N35=1,P35,IF(N35=2," "&P35,IF(N35=3," "&P35,IF(N35=4," "&P35," "&P35)))) -> Urban - decile 4
C36: 3 | D36: a_coco | E36: Cocoa | F36: Cocoa | N36: 3 | O36: h_hhd-u4 | P36: Urban - decile 5 | T36: =IF(C36=1,E36,IF(C36=2," "&E36,IF(C36=3," "&E36,IF(C36=4," "&E36," "&E36)))) -> Cocoa | U36: =IF(C36=1,F36,IF(C36=2," "&F36,IF(C36=3," "&F36,IF(C36=4," "&F36," "&F36)))) -> Cocoa | V36: =IF(I36=1,K36,IF(I36=2," "&K36,IF(I36=3," "&K36,IF(I36=4," "&K36," "&K36)))) | W36: =IF(N36=1,P36,IF(N36=2," "&P36,IF(N36=3," "&P36,IF(N36=4," "&P36," "&P36)))) -> Urban - decile 5
C37: 3 | D37: a_flwr | E37: Cut flowers | F37: Cut flowers | N37: 3 | O37: h_hhd-u5 | P37: Urban - decile 6 | T37: =IF(C37=1,E37,IF(C37=2," "&E37,IF(C37=3," "&E37,IF(C37=4," "&E37," "&E37)))) -> Cut flowers | U37: =IF(C37=1,F37,IF(C37=2," "&F37,IF(C37=3," "&F37,IF(C37=4," "&F37," "&F37)))) -> Cut flowers | V37: =IF(I37=1,K37,IF(I37=2," "&K37,IF(I37=3," "&K37,IF(I37=4," "&K37," "&K37)))) | W37: =IF(N37=1,P37,IF(N37=2," "&P37,IF(N37=3," "&P37,IF(N37=4," "&P37," "&P37)))) -> Urban - decile 6
C38: 3 | D38: a_rubb | E38: Rubber | F38: Rubber | N38: 3 | O38: h_hhd-u6 | P38: Urban - decile 7 | T38: =IF(C38=1,E38,IF(C38=2," "&E38,IF(C38=3," "&E38,IF(C38=4," "&E38," "&E38)))) -> Rubber | U38: =IF(C38=1,F38,IF(C38=2," "&F38,IF(C38=3," "&F38,IF(C38=4," "&F38," "&F38)))) -> Rubber | V38: =IF(I38=1,K38,IF(I38=2," "&K38,IF(I38=3," "&K38,IF(I38=4," "&K38," "&K38)))) | W38: =IF(N38=1,P38,IF(N38=2," "&P38,IF(N38=3," "&P38,IF(N38=4," "&P38," "&P38)))) -> Urban - decile 7
C39: 3 | D39: a_ocrp | E39: Other crops | F39: Other crops | N39: 3 | O39: h_hhd-u7 | P39: Urban - decile 8 | T39: =IF(C39=1,E39,IF(C39=2," "&E39,IF(C39=3," "&E39,IF(C39=4," "&E39," "&E39)))) -> Other crops | U39: =IF(C39=1,F39,IF(C39=2," "&F39,IF(C39=3," "&F39,IF(C39=4," "&F39," "&F39)))) -> Other crops | V39: =IF(I39=1,K39,IF(I39=2," "&K39,IF(I39=3," "&K39,IF(I39=4," "&K39," "&K39)))) | W39: =IF(N39=1,P39,IF(N39=2," "&P39,IF(N39=3," "&P39,IF(N39=4," "&P39," "&P39)))) -> Urban - decile 8
C40: 2 | D40: aa_LIVE | E40: Livestock | F40: Livestock | N40: 3 | O40: h_hhd-u8 | P40: Urban - decile 9 | T40: =IF(C40=1,E40,IF(C40=2," "&E40,IF(C40=3," "&E40,IF(C40=4," "&E40," "&E40)))) -> Livestock | U40: =IF(C40=1,F40,IF(C40=2," "&F40,IF(C40=3," "&F40,IF(C40=4," "&F40," "&F40)))) -> Livestock | V40: =IF(I40=1,K40,IF(I40=2," "&K40,IF(I40=3," "&K40,IF(I40=4," "&K40," "&K40)))) | W40: =IF(N40=1,P40,IF(N40=2," "&P40,IF(N40=3," "&P40,IF(N40=4," "&P40," "&P40)))) -> Urban - decile 9
C41: 3 | D41: a_catt | E41: Cattle | F41: Cattle | N41: 3 | O41: h_hhd-u9 | P41: Urban - decile 10 (high) | T41: =IF(C41=1,E41,IF(C41=2," "&E41,IF(C41=3," "&E41,IF(C41=4," "&E41," "&E41)))) -> Cattle | U41: =IF(C41=1,F41,IF(C41=2," "&F41,IF(C41=3," "&F41,IF(C41=4," "&F41," "&F41)))) -> Cattle | V41: =IF(I41=1,K41,IF(I41=2," "&K41,IF(I41=3," "&K41,IF(I41=4," "&K41," "&K41)))) | W41: =IF(N41=1,P41,IF(N41=2," "&P41,IF(N41=3," "&P41,IF(N41=4," "&P41," "&P41)))) -> Urban - decile 10 (high)
C42: 3 | D42: a_milk | E42: Raw milk | F42: Raw milk | T42: =IF(C42=1,E42,IF(C42=2," "&E42,IF(C42=3," "&E42,IF(C42=4," "&E42," "&E42)))) -> Raw milk | U42: =IF(C42=1,F42,IF(C42=2," "&F42,IF(C42=3," "&F42,IF(C42=4," "&F42," "&F42)))) -> Raw milk | V42: =IF(I42=1,K42,IF(I42=2," "&K42,IF(I42=3," "&K42,IF(I42=4," "&K42," "&K42)))) | W42: =IF(N42=1,P42,IF(N42=2," "&P42,IF(N42=3," "&P42,IF(N42=4," "&P42," "&P42))))
C43: 3 | D43: a_poul | E43: Poultry | F43: Poultry | T43: =IF(C43=1,E43,IF(C43=2," "&E43,IF(C43=3," "&E43,IF(C43=4," "&E43," "&E43)))) -> Poultry | U43: =IF(C43=1,F43,IF(C43=2," "&F43,IF(C43=3," "&F43,IF(C43=4," "&F43," "&F43)))) -> Poultry | V43: =IF(I43=1,K43,IF(I43=2," "&K43,IF(I43=3," "&K43,IF(I43=4," "&K43," "&K43)))) | W43: =IF(N43=1,P43,IF(N43=2," "&P43,IF(N43=3," "&P43,IF(N43=4," "&P43," "&P43))))
C44: 3 | D44: a_eggs | E44: Eggs | F44: Eggs | T44: =IF(C44=1,E44,IF(C44=2," "&E44,IF(C44=3," "&E44,IF(C44=4," "&E44," "&E44)))) -> Eggs | U44: =IF(C44=1,F44,IF(C44=2," "&F44,IF(C44=3," "&F44,IF(C44=4," "&F44," "&F44)))) -> Eggs | V44: =IF(I44=1,K44,IF(I44=2," "&K44,IF(I44=3," "&K44,IF(I44=4," "&K44," "&K44)))) | W44: =IF(N44=1,P44,IF(N44=2," "&P44,IF(N44=3," "&P44,IF(N44=4," "&P44," "&P44))))
C45: 3 | D45: a_smlr | E45: Small ruminants | F45: Small ruminants | T45: =IF(C45=1,E45,IF(C45=2," "&E45,IF(C45=3," "&E45,IF(C45=4," "&E45," "&E45)))) -> Small ruminants | U45: =IF(C45=1,F45,IF(C45=2," "&F45,IF(C45=3," "&F45,IF(C45=4," "&F45," "&F45)))) -> Small ruminants | V45: =IF(I45=1,K45,IF(I45=2," "&K45,IF(I45=3," "&K45,IF(I45=4," "&K45," "&K45)))) | W45: =IF(N45=1,P45,IF(N45=2," "&P45,IF(N45=3," "&P45,IF(N45=4," "&P45," "&P45))))
C46: 3 | D46: a_oliv | E46: Other livestock | F46: Other livestock | T46: =IF(C46=1,E46,IF(C46=2," "&E46,IF(C46=3," "&E46,IF(C46=4," "&E46," "&E46)))) -> Other livestock | U46: =IF(C46=1,F46,IF(C46=2," "&F46,IF(C46=3," "&F46,IF(C46=4," "&F46," "&F46)))) -> Other livestock | V46: =IF(I46=1,K46,IF(I46=2," "&K46,IF(I46=3," "&K46,IF(I46=4," "&K46," "&K46)))) | W46: =IF(N46=1,P46,IF(N46=2," "&P46,IF(N46=3," "&P46,IF(N46=4," "&P46," "&P46))))
C47: 2 | D47: aa_OAGR | E47: Other agriculture | F47: Other agriculture | T47: =IF(C47=1,E47,IF(C47=2," "&E47,IF(C47=3," "&E47,IF(C47=4," "&E47," "&E47)))) -> Other agriculture | U47: =IF(C47=1,F47,IF(C47=2," "&F47,IF(C47=3," "&F47,IF(C47=4," "&F47," "&F47)))) -> Other agriculture | V47: =IF(I47=1,K47,IF(I47=2," "&K47,IF(I47=3," "&K47,IF(I47=4," "&K47," "&K47)))) | W47: =IF(N47=1,P47,IF(N47=2," "&P47,IF(N47=3," "&P47,IF(N47=4," "&P47," "&P47))))
C48: 3 | D48: a_fore | E48: Forestry | F48: Forestry | T48: =IF(C48=1,E48,IF(C48=2," "&E48,IF(C48=3," "&E48,IF(C48=4," "&E48," "&E48)))) -> Forestry | U48: =IF(C48=1,F48,IF(C48=2," "&F48,IF(C48=3," "&F48,IF(C48=4," "&F48," "&F48)))) -> Forestry | V48: =IF(I48=1,K48,IF(I48=2," "&K48,IF(I48=3," "&K48,IF(I48=4," "&K48," "&K48)))) | W48: =IF(N48=1,P48,IF(N48=2," "&P48,IF(N48=3," "&P48,IF(N48=4," "&P48," "&P48))))
C49: 3 | D49: a_aqua | E49: Aquaculture | F49: Aquaculture | T49: =IF(C49=1,E49,IF(C49=2," "&E49,IF(C49=3," "&E49,IF(C49=4," "&E49," "&E49)))) -> Aquaculture | U49: =IF(C49=1,F49,IF(C49=2," "&F49,IF(C49=3," "&F49,IF(C49=4," "&F49," "&F49)))) -> Aquaculture | V49: =IF(I49=1,K49,IF(I49=2," "&K49,IF(I49=3," "&K49,IF(I49=4," "&K49," "&K49)))) | W49: =IF(N49=1,P49,IF(N49=2," "&P49,IF(N49=3," "&P49,IF(N49=4," "&P49," "&P49))))
C50: 3 | D50: a_fish | E50: Capture fisheries | F50: Capture fisheries | T50: =IF(C50=1,E50,IF(C50=2," "&E50,IF(C50=3," "&E50,IF(C50=4," "&E50," "&E50)))) -> Capture fisheries | U50: =IF(C50=1,F50,IF(C50=2," "&F50,IF(C50=3," "&F50,IF(C50=4," "&F50," "&F50)))) -> Capture fisheries | V50: =IF(I50=1,K50,IF(I50=2," "&K50,IF(I50=3," "&K50,IF(I50=4," "&K50," "&K50)))) | W50: =IF(N50=1,P50,IF(N50=2," "&P50,IF(N50=3," "&P50,IF(N50=4," "&P50," "&P50))))
...

Sheet Base
A1: Base Year Economic Structure and Tax Revenues | L1: Tables: | M1: =C5 -> Economic structure
M2: =X5 -> Indirect taxes
C5: Economic structure | X5: Indirect taxes
E6: Share of total (%) | P6: Intensity ratios | S6: Transaction cost rates (%) | Z6: Import tariffs | AC6: Export taxes | AF6: Sales taxes | AI6: Activity taxes | AL6: Value-added taxes
E7: Value- | F7: Output | G7: Employ- | H7: Comp. | I7: Private consumption | L7: Gov. | M7: Invest. | N7: Export | O7: Import | P7: Own con. | Q7: Exports | R7: Imports | S7: Exports | T7: Imports | U7: Domestic | Z7: Tax base | AA7: Tax | AB7: Revenue | AC7: Tax base | AD7: Tax | AE7: Revenue | AF7: Tax base | AG7: Tax | AH7: Revenue | AI7: Tax base | AJ7: Tax | AK7: Revenue | AL7: Tax base | AM7: Tax | AN7: Revenue
E8: added | F8: value | G8: ment | H8: supply | I8: Total | J8: Own | K8: Market | L8: cons. | M8: demand | N8: value | O8: value | P8: / output | Q8: / output | R8: / demand | Z8: shares | AA8: rate | AB8: share | AC8: shares | AD8: rate | AE8: share | AF8: shares | AG8: rate | AH8: share | AI8: shares | AJ8: rate | AK8: share | AL8: shares | AM8: rate | AN8: share
E9: VAshr | F9: PRDshr | G9: EMPshr | H9: QQshr | I9: HHDshr | J9: OWNshr | K9: MKTshr | L9: GOVshr | M9: INVshr | N9: EXPshr | O9: IMPshr | P9: OWN-OUTshr | Q9: EXP-OUTshr | R9: IMP-DEMshr | S9: TRErate | T9: TRMrate | U9: TRDrate | Z9: tIMPshr | AA9: tIMPtax | AB9: tIMPrev | AC9: tEXPshr | AD9: tEXPtax | AE9: tEXPrev | AF9: tSALshr | AG9: tSALtax | AH9: tSALrev | AI9: tACTshr | AJ9: tACTtax | AK9: tACTrev | AL9: tVADshr | AM9: tVADtax | AN9: tVADrev
A10: 1 | C10: =Notes!U9 -> All products | D10: aa_GDP | E10: 100 | F10: 100 | G10: 100 | H10: 100 | I10: 100 | J10: 100 | K10: 100 | L10: 100 | M10: 100 | N10: 100 | O10: 100 | P10: 0.60475287 | Q10: 4.7997568 | R10: 8.6630262 | S10: 10.899257 | T10: 12.088755 | U10: 7.9429173 | X10: =Notes!U9 -> All products | Y10: aa_GDP | Z10: 100 | AA10: 3.6487805 | AB10: 100 | AC10: 100 | AD10: 0.00010507789 | AE10: 100 | AF10: 100 | AG10: 1.2247334 | AH10: 100 | AI10: 100 | AJ10: Eps | AK10: Eps | AL10: 100 | AM10: Eps | AN10: Eps
A11: 2 | C11: =Notes!U10 -> Agriculture | D11: aa_AGRI | E11: 11.553747 | F11: 10.238637 | G11: 13.109828 | H11: 11.359471 | I11: 12.187737 | J11: 100 | K11: 10.634928 | L11: Eps | M11: Eps | N11: 1.2441389 | O11: 12.301297 | P11: 5.9065757 | Q11: 0.59052269 | R11: 9.2389667 | S11: 14.598563 | T11: 10.892793 | U11: 18.461649 | X11: =Notes!U10 -> Agriculture | Y11: aa_AGRI | Z11: 12.301297 | AA11: 4.737806 | AB11: 15.972778 | AC11: 1.2441389 | AD11: Eps | AE11: Eps | AF11: 11.359471 | AG11: 0.0096402411 | AH11: 0.089413778 | AI11: 10.238637 | AJ11: Eps | AK11: Eps | AL11: 11.553747 | AM11: Eps | AN11: Eps
A12: 3 | C12: =Notes!U11 -> Crops | D12: aa_CROP | E12: 5.8017781 | F12: 3.9325564 | G12: 7.8527519 | H12: 5.1209736 | I12: 3.5585992 | J12: 11.866097 | K12: 3.4116954 | L12: Eps | M12: Eps | N12: 0.77696186 | O12: 12.276392 | P12: 1.8247816 | Q12: 0.97093689 | R12: 20.450527 | S12: 9.8918325 | T12: 10.895827 | U12: 17.606889 | X12: =Notes!U11 -> Crops | Y12: aa_CROP | Z12: 12.276392 | AA12: 4.7112615 | AB12: 15.85113 | AC12: 0.77696186 | AD12: Eps | AE12: Eps | AF12: 5.1209736 | AG12: 0.021384222 | AH12: 0.089413778 | AI12: 3.9325564 | AJ12: Eps | AK12: Eps | AL12: 5.8017781 | AM12: Eps | AN12: Eps
A13: 4 | C13: =Notes!U12 -> Maize | D13: a_maiz | E13: 0.057176284 | F13: 0.035421683 | G13: 0.065273844 | H13: 0.11106867 | I13: 0.00095890009 | J13: 0.055185278 | K13: Eps | L13: Eps | M13: Eps | N13: Eps | O13: 0.91911364 | P13: 0.94217587 | Q13: Eps | R13: 68.414527 | S13: Eps | T13: 12.213567 | U13: 12.213567 | X13: =Notes!U12 -> Maize | Y13: a_maiz | Z13: 0.91911364 | AA13: Eps | AB13: Eps | AC13: Eps | AD13: Eps | AE13: Eps | AF13: 0.11106867 | AG13: Eps | AH13: Eps | AI13: 0.035421683 | AJ13: Eps | AK13: Eps | AL13: 0.057176284 | AM13: Eps | AN13: Eps
A14: 5 | C14: =Notes!U13 -> Sorghum and millet | D14: a_sorg | E14: Eps | F14: Eps | G14: Eps | H14: Eps | I14: Eps | J14: Eps | K14: Eps | L14: Eps | M14: Eps | N14: Eps | O14: Eps | P14: Eps | Q14: Eps | R14: Eps | S14: Eps | T14: Eps | U14: Eps | X14: =Notes!U13 -> Sorghum and millet | Y14: a_sorg | Z14: Eps | AA14: Eps | AB14: Eps | AC14: Eps | AD14: Eps | AE14: Eps | AF14: Eps | AG14: Eps | AH14: Eps | AI14: Eps | AJ14: Eps | AK14: Eps | AL14: Eps | AM14: Eps | AN14: Eps
A15: 6 | C15: =Notes!U14 -> Rice paddy (Aman) | D15: a_aman | E15: 1.7790835 | F15: 1.0235941 | G15: 2.7223872 | H15: 1.1263284 | I15: Eps | J15: Eps | K15: Eps | L15: Eps | M15: Eps | N15: Eps | O15: Eps | P15: Eps | Q15: Eps | R15: Eps | S15: Eps | T15: Eps | U15: 20.235236 | X15: =Notes!U14 -> Rice paddy (Aman) | Y15: a_aman | Z15: Eps | AA15: Eps | AB15: Eps | AC15: Eps | AD15: Eps | AE15: Eps | AF15: 1.1263284 | AG15: Eps | AH15: Eps | AI15: 1.0235941 | AJ15: Eps | AK15: Eps | AL15: 1.7790835 | AM15: Eps | AN15: Eps
A16: 7 | C16: =Notes!U15 -> Rice paddy (Boro) | D16: a_boro | E16: 1.7183562 | F16: 1.1733921 | G16: 2.6294443 | H16: 1.2816833 | I16: Eps | J16: Eps | K16: Eps | L16: Eps | M16: Eps | N16: Eps | O16: Eps | P16: Eps | Q16: Eps | R16: Eps | S16: Eps | T16: Eps | U16: 19.645386 | X16: =Notes!U15 -> Rice paddy (Boro) | Y16: a_boro | Z16: Eps | AA16: Eps | AB16: Eps | AC16: Eps | AD16: Eps | AE16: Eps | AF16: 1.2816833 | AG16: Eps | AH16: Eps | AI16: 1.1733921 | AJ16: Eps | AK16: Eps | AL16: 1.7183562 | AM16: Eps | AN16: Eps
A17: 8 | C17: =Notes!U16 -> Wheat and barley | D17: a_whea | E17: 0.019864455 | F17: 0.013934424 | G17: 0.025794146 | H17: 0.33105043 | I17: 0.024401669 | J17: 1.4043308 | K17: Eps | L17: Eps | M17: Eps | N17: Eps | O17: 4.078035 | P17: 60.947838 | Q17: Eps | R17: 98.411888 | S17: Eps | T17: 9.1536886 | U17: 9.1536886 | X17: =Notes!U16 -> Wheat and barley | Y17: a_whea | Z17: 4.078035 | AA17: Eps | AB17: Eps | AC17: Eps | AD17: Eps | AE17: Eps | AF17: 0.33105043 | AG17: Eps | AH17: Eps | AI17: 0.013934424 | AJ17: Eps | AK17: Eps | AL17: 0.019864455 | AM17: Eps | AN17: Eps
A18: 9 | C18: =Notes!U17 -> Other cereals | D18: a_ocer | E18: Eps | F18: Eps | G18: Eps | H18: Eps | I18: Eps | J18: Eps | K18: Eps | L18: Eps | M18: Eps | N18: Eps | O18: Eps | P18: Eps | Q18: Eps | R18: Eps | S18: Eps | T18: Eps | U18: Eps | X18: =Notes!U17 -> Other cereals | Y18: a_ocer | Z18: Eps | AA18: Eps | AB18: Eps | AC18: Eps | AD18: Eps | AE18: Eps | AF18: Eps | AG18: Eps | AH18: Eps | AI18: Eps | AJ18: Eps | AK18: Eps | AL18: Eps | AM18: Eps | AN18: Eps
A19: 10 | C19: =Notes!U18 -> Pulses | D19: a_puls | E19: 0.097083773 | F19: 0.071768206 | G19: 0.10132265 | H19: 0.18482441 | I19: 0.44607328 | J19: 0.29640181 | K19: 0.44871997 | L19: Eps | M19: Eps | N19: Eps | O19: 1.4135578 | P19: 2.4976219 | Q19: Eps | R19: 62.552183 | S19: Eps | T19: 11.261959 | U19: 11.261959 | X19: =Notes!U18 -> Pulses | Y19: a_puls | Z19: 1.4135578 | AA19: Eps | AB19: Eps | AC19: Eps | AD19: Eps | AE19: Eps | AF19: 0.18482441 | AG19: Eps | AH19: Eps | AI19: 0.071768206 | AJ19: Eps | AK19: Eps | AL19: 0.097083773 | AM19: Eps | AN19: Eps
A20: 11 | C20: =Notes!U19 -> Groundnuts | D20: a_gnut | E20: Eps | F20: Eps | G20: Eps | H20: Eps | I20: Eps | J20: Eps | K20: Eps | L20: Eps | M20: Eps | N20: Eps | O20: Eps | P20: Eps | Q20: Eps | R20: Eps | S20: Eps | T20: Eps | U20: Eps | X20: =Notes!U19 -> Groundnuts | Y20: a_gnut | Z20: Eps | AA20: Eps | AB20: Eps | AC20: Eps | AD20: Eps | AE20: Eps | AF20: Eps | AG20: Eps | AH20: Eps | AI20: Eps | AJ20: Eps | AK20: Eps | AL20: Eps | AM20: Eps | AN20: Eps
A21: 12 | C21: =Notes!U20 -> Other oilseeds | D21: a_oils | E21: 0.17907292 | F21: 0.11760405 | G21: 0.25315463 | H21: 0.25840135 | I21: 0.60133246 | J21: 0.052687335 | K21: 0.61103431 | L21: Eps | M21: Eps | N21: Eps | O21: 1.6621684 | P21: 0.270933 | Q21: Eps | R21: 54.300435 | S21: Eps | T21: 12.826277 | U21: 12.826277 | X21: =Notes!U20 -> Other oilseeds | Y21: a_oils | Z21: 1.6621684 | AA21: 1.3935964 | AB21: 0.63484001 | AC21: Eps | AD21: Eps | AE21: Eps | AF21: 0.25840135 | AG21: 1.2899384e-05 | AH21: 2.7215869e-06 | AI21: 0.11760405 | AJ21: Eps | AK21: Eps | AL21: 0.17907292 | AM21: Eps | AN21: Eps
A22: 13 | C22: =Notes!U21 -> Cassava | D22: a_cass | E22: Eps | F22: Eps | G22: Eps | H22: Eps | I22: Eps | J22: Eps | K22: Eps | L22: Eps | M22: Eps | N22: Eps | O22: Eps | P22: Eps | Q22: Eps | R22: Eps | S22: Eps | T22: Eps | U22: Eps | X22: =Notes!U21 -> Cassava | Y22: a_cass | Z22: Eps | AA22: Eps | AB22: Eps | AC22: Eps | AD22: Eps | AE22: Eps | AF22: Eps | AG22: Eps | AH22: Eps | AI22: Eps | AJ22: Eps | AK22: Eps | AL22: Eps | AM22: Eps | AN22: Eps
A23: 14 | C23: =Notes!U22 -> Irish potatoes | D23: a_ipot | E23: 0.15284804 | F23: 0.179351 | G23: 0.19812525 | H23: 0.17228927 | I23: 0.22602178 | J23: 0.37148202 | K23: 0.22344957 | L23: Eps | M23: Eps | N23: Eps | O23: Eps | P23: 1.2525987 | Q23: Eps | R23: Eps | S23: Eps | T23: Eps | U23: 9.7765135 | X23: =Notes!U22 -> Irish potatoes | Y23: a_ipot | Z23: Eps | AA23: Eps | AB23: Eps | AC23: Eps | AD23: Eps | AE23: Eps | AF23: 0.17228927 | AG23: Eps | AH23: Eps | AI23: 0.179351 | AJ23: Eps | AK23: Eps | AL23: 0.15284804 | AM23: Eps | AN23: Eps
A24: 15 | C24: =Notes!U23 -> Sweet potatoes | D24: a_spot | E24: Eps | F24: Eps | G24: Eps | H24: Eps | I24: Eps | J24: Eps | K24: Eps | L24: Eps | M24: Eps | N24: Eps | O24: Eps | P24: Eps | Q24: Eps | R24: Eps | S24: Eps | T24: Eps | U24: Eps | X24: =Notes!U23 -> Sweet potatoes | Y24: a_spot | Z24: Eps | AA24: Eps | AB24: Eps | AC24: Eps | AD24: Eps | AE24: Eps | AF24: Eps | AG24: Eps | AH24: Eps | AI24: Eps | AJ24: Eps | AK24: Eps | AL24: Eps | AM24: Eps | AN24: Eps
A25: 16 | C25: =Notes!U24 -> Other roots | D25: a_root | E25: Eps | F25: Eps | G25: Eps | H25: Eps | I25: Eps | J25: Eps | K25: Eps | L25: Eps | M25: Eps | N25: Eps | O25: Eps | P25: Eps | Q25: Eps | R25: Eps | S25: Eps | T25: Eps | U25: Eps | X25: =Notes!U24 -> Other roots | Y25: a_root | Z25: Eps | AA25: Eps | AB25: Eps | AC25: Eps | AD25: Eps | AE25: Eps | AF25: Eps | AG25: Eps | AH25: Eps | AI25: Eps | AJ25: Eps | AK25: Eps | AL25: Eps | AM25: Eps | AN25: Eps
A26: 17 | C26: =Notes!U25 -> Leafy vegetables | D26: a_leaf | E26: 0.13963036 | F26: 0.099928008 | G26: 0.16669182 | H26: 0.10870114 | I26: 0.37103589 | J26: 1.6291178 | K26: 0.34878888 | L26: Eps | M26: Eps | N26: Eps | O26: Eps | P26: 9.8592346 | Q26: Eps | R26: Eps | S26: Eps | T26: Eps | U26: 27.26847 | X26: =Notes!U25 -> Leafy vegetables | Y26: a_leaf | Z26: Eps | AA26: Eps | AB26: Eps | AC26: Eps | AD26: Eps | AE26: Eps | AF26: 0.10870114 | AG26: Eps | AH26: Eps | AI26: 0.099928008 | AJ26: Eps | AK26: Eps | AL26: 0.13963036 | AM26: Eps | AN26: Eps
A27: 18 | C27: =Notes!U26 -> Other vegetables | D27: a_vege | E27: 0.3074146 | F27: 0.22028886 | G27: 0.3668882 | H27: 0.28779819 | I27: 0.81368072 | J27: 3.5726511 | K27: 0.76489308 | L27: Eps | M27: Eps | N27: Eps | O27: 0.5461967 | P27: 9.8078993 | Q27: Eps | R27: 18.592568 | S27: Eps | T27: 25.568411 | U27: 25.568411 | X27: =Notes!U26 -> Other vegetables | Y27: a_vege | Z27: 0.5461967 | AA27: 0.47027658 | AB27: 0.070397086 | AC27: Eps | AD27: Eps | AE27: Eps | AF27: 0.28779819 | AG27: Eps | AH27: Eps | AI27: 0.22028886 | AJ27: Eps | AK27: Eps | AL27: 0.3074146 | AM27: Eps | AN27: Eps
A28: 19 | C28: =Notes!U27 -> Sugarcane | D28: a_sugr | E28: 0.082417407 | F28: 0.078609442 | G28: 0.099107279 | H28: 0.081424427 | I28: 0.0019455905 | J28: 0.1119699 | K28: Eps | L28: Eps | M28: Eps | N28: Eps | O28: Eps | P28: 0.86139931 | Q28: Eps | R28: Eps | S28: Eps | T28: Eps | U28: 15.993837 | X28: =Notes!U27 -> Sugarcane | Y28: a_sugr | Z28: Eps | AA28: Eps | AB28: Eps | AC28: Eps | AD28: Eps | AE28: Eps | AF28: 0.081424427 | AG28: Eps | AH28: Eps | AI28: 0.078609442 | AJ28: Eps | AK28: Eps | AL28: 0.082417407 | AM28: Eps | AN28: Eps
A29: 20 | C29: =Notes!U28 -> Tobacco | D29: a_toba | E29: 0.21507085 | F29: 0.22170607 | G29: 0.28371126 | H29: 0.21299529 | I29: 0.00064422136 | J29: 0.037075327 | K29: Eps | L29: Eps | M29: Eps | N29: Eps | O29: Eps | P29: 0.10113124 | Q29: Eps | R29: Eps | S29: Eps | T29: Eps | U29: 8.7324243 | X29: =Notes!U28 -> Tobacco | Y29: a_toba | Z29: Eps | AA29: Eps | AB29: Eps | AC29: Eps | AD29: Eps | AE29: Eps | AF29: 0.21299529 | AG29: Eps | AH29: Eps | AI29: 0.22170607 | AJ29: Eps | AK29: Eps | AL29: 0.21507085 | AM29: Eps | AN29: Eps
A30: 21 | C30: =Notes!U29 -> Cotton and fibres | D30: a_cott | E30: 0.0012261848 | F30: 0.00069174165 | G30: 0.0010244216 | H30: 0.11663325 | I30: Eps | J30: Eps | K30: Eps | L30: Eps | M30: Eps | N30: Eps | O30: 1.5760217 | P30: Eps | Q30: Eps | R30: 99.47202 | S30: Eps | T30: 1.4055052 | U30: 1.4055052 | X30: =Notes!U29 -> Cotton and fibres | Y30: a_cott | Z30: 1.5760217 | AA30: 0.0036142005 | AB30: 0.0015610856 | AC30: Eps | AD30: Eps | AE30: Eps | AF30: 0.11663325 | AG30: Eps | AH30: Eps | AI30: 0.00069174165 | AJ30: Eps | AK30: Eps | AL30: 0.0012261848 | AM30: Eps | AN30: Eps
A31: 22 | C31: =Notes!U30 -> Jute | D31: a_jute | E31: 0.25549077 | F31: 0.1722585 | G31: 0.41817349 | H31: 0.13423423 | I31: Eps | J31: Eps | K31: Eps | L31: Eps | M31: Eps | N31: 0.77696186 | O31: 0.03672612 | P31: Eps | Q31: 21.761417 | R31: 2.2036656 | S31: 9.8918325 | T31: 9.8918325 | U31: 9.8918325 | X31: =Notes!U30 -> Jute | Y31: a_jute | Z31: 0.03672612 | AA31: Eps | AB31: Eps | AC31: 0.77696186 | AD31: Eps | AE31: Eps | AF31: 0.13423423 | AG31: Eps | AH31: Eps | AI31: 0.1722585 | AJ31: Eps | AK31: Eps | AL31: 0.25549077 | AM31: Eps | AN31: Eps
A32: 23 | C32: =Notes!U31 -> Nuts | D32: a_nuts | E32: 0.10133306 | F32: 0.060723846 | G32: 0.022485198 | H32: 0.061379817 | I32: 0.10282034 | J32: 0.15859799 | K32: 0.10183401 | L32: Eps | M32: Eps | N32: Eps | O32: Eps | P32: 1.579488 | Q32: Eps | R32: Eps | S32: Eps | T32: Eps | U32: 14.539061 | X32: =Notes!U31 -> Nuts | Y32: a_nuts | Z32: Eps | AA32: Eps | AB32: Eps | AC32: Eps | AD32: Eps | AE32: Eps | AF32: 0.061379817 | AG32: Eps | AH32: Eps | AI32: 0.060723846 | AJ32: Eps | AK32: Eps | AL32: 0.10133306 | AM32: Eps | AN32: Eps
A33: 24 | C33: =Notes!U32 -> Bananas and plantains | D33: a_bana | E33: 0.044765728 | F33: 0.027203959 | G33: 0.010646074 | H33: 0.024807189 | I33: 0.080848223 | J33: 0.37277973 | K33: 0.075685917 | L33: Eps | M33: Eps | N33: Eps | O33: Eps | P33: 8.2870148 | Q33: Eps | R33: Eps | S33: Eps | T33: Eps | U33: 11.725809 | X33: =Notes!U32 -> Bananas and plantains | Y33: a_bana | Z33: Eps | AA33: Eps | AB33: Eps | AC33: Eps | AD33: Eps | AE33: Eps | AF33: 0.024807189 | AG33: Eps | AH33: Eps | AI33: 0.027203959 | AJ33: Eps | AK33: Eps | AL33: 0.044765728 | AM33: Eps | AN33: Eps
A34: 25 | C34: =Notes!U33 -> Other fruits | D34: a_frui | E34: 0.26395265 | F34: 0.15952221 | G34: 0.061102709 | H34: 0.29650429 | I34: 0.88840452 | J34: 3.77898 | K34: 0.83728967 | L34: Eps | M34: Eps | N34: Eps | O34: 1.4152583 | P34: 14.326212 | Q34: Eps | R34: 52.865249 | S34: Eps | T34: 14.168776 | U34: 14.168776 | X34: =Notes!U33 -> Other fruits | Y34: a_frui | Z34: 1.4152583 | AA34: 30.982355 | AB34: 12.017175 | AC34: Eps | AD34: Eps | AE34: Eps | AF34: 0.29650429 | AG34: Eps | AH34: Eps | AI34: 0.15952221 | AJ34: Eps | AK34: Eps | AL34: 0.26395265 | AM34: Eps | AN34: Eps
A35: 26 | C35: =Notes!U34 -> Leaf tea | D35: a_teal | E35: 0.027250198 | F35: 0.021425868 | G35: 0.031940231 | H35: 0.020194155 | I35: 0.00043158996 | J35: 0.024838262 | K35: Eps | L35: Eps | M35: Eps | N35: Eps | O35: Eps | P35: 0.7010689 | Q35: Eps | R35: Eps | S35: Eps | T35: Eps | U35: 7.5289707 | X35: =Notes!U34 -> Leaf tea | Y35: a_teal | Z35: Eps | AA35: Eps | AB35: Eps | AC35: Eps | AD35: Eps | AE35: Eps | AF35: 0.020194155 | AG35: Eps | AH35: Eps | AI35: 0.021425868 | AJ35: Eps | AK35: Eps | AL35: 0.027250198 | AM35: Eps | AN35: Eps
A36: 27 | C36: =Notes!U35 -> Coffee | D36: a_coff | E36: Eps | F36: Eps | G36: Eps | H36: Eps | I36: Eps | J36: Eps | K36: Eps | L36: Eps | M36: Eps | N36: Eps | O36: Eps | P36: Eps | Q36: Eps | R36: Eps | S36: Eps | T36: Eps | U36: Eps | X36: =Notes!U35 -> Coffee | Y36: a_coff | Z36: Eps | AA36: Eps | AB36: Eps | AC36: Eps | AD36: Eps | AE36: Eps | AF36: Eps | AG36: Eps | AH36: Eps | AI36: Eps | AJ36: Eps | AK36: Eps | AL36: Eps | AM36: Eps | AN36: Eps
A37: 28 | C37: =Notes!U36 -> Cocoa | D37: a_coco | E37: Eps | F37: Eps | G37: Eps | H37: Eps | I37: Eps | J37: Eps | K37: Eps | L37: Eps | M37: Eps | N37: Eps | O37: Eps | P37: Eps | Q37: Eps | R37: Eps | S37: Eps | T37: Eps | U37: Eps | X37: =Notes!U36 -> Cocoa | Y37: a_coco | Z37: Eps | AA37: Eps | AB37: Eps | AC37: Eps | AD37: Eps | AE37: Eps | AF37: Eps | AG37: Eps | AH37: Eps | AI37: Eps | AJ37: Eps | AK37: Eps | AL37: Eps | AM37: Eps | AN37: Eps
A38: 29 | C38: =Notes!U37 -> Cut flowers | D38: a_flwr | E38: Eps | F38: Eps | G38: Eps | H38: Eps | I38: Eps | J38: Eps | K38: Eps | L38: Eps | M38: Eps | N38: Eps | O38: Eps | P38: Eps | Q38: Eps | R38: Eps | S38: Eps | T38: Eps | U38: Eps | X38: =Notes!U37 -> Cut flowers | Y38: a_flwr | Z38: Eps | AA38: Eps | AB38: Eps | AC38: Eps | AD38: Eps | AE38: Eps | AF38: Eps | AG38: Eps | AH38: Eps | AI38: Eps | AJ38: Eps | AK38: Eps | AL38: Eps | AM38: Eps | AN38: Eps
A39: 30 | C39: =Notes!U38 -> Rubber | D39: a_rubb | E39: Eps | F39: Eps | G39: Eps | H39: Eps | I39: Eps | J39: Eps | K39: Eps | L39: Eps | M39: Eps | N39: Eps | O39: Eps | P39: Eps | Q39: Eps | R39: Eps | S39: Eps | T39: Eps | U39: Eps | X39: =Notes!U38 -> Rubber | Y39: a_rubb | Z39: Eps | AA39: Eps | AB39: Eps | AC39: Eps | AD39: Eps | AE39: Eps | AF39: Eps | AG39: Eps | AH39: Eps | AI39: Eps | AJ39: Eps | AK39: Eps | AL39: Eps | AM39: Eps | AN39: Eps
A40: 31 | C40: =Notes!U39 -> Other crops | D40: a_ocrp | E40: 0.35974115 | F40: 0.25513224 | G40: 0.39547924 | H40: 0.31065581 | I40: Eps | J40: Eps | K40: Eps | L40: Eps | M40: Eps | N40: Eps | O40: 0.62931444 | P40: Eps | Q40: Eps | R40: 19.416224 | S40: Eps | T40: 10.232283 | U40: 10.232283 | X40: =Notes!U39 -> Other crops | Y40: a_ocrp | Z40: 0.62931444 | AA40: 18.13133 | AB40: 3.1271565 | AC40: Eps | AD40: Eps | AE40: Eps | AF40: 0.31065581 | AG40: 0.35249526 | AH40: 0.089411056 | AI40: 0.25513224 | AJ40: Eps | AK40: Eps | AL40: 0.35974115 | AM40: Eps | AN40: Eps
A41: 32 | C41: =Notes!U40 -> Livestock | D41: aa_LIVE | E41: 1.7216311 | F41: 2.1205224 | G41: 1.6180891 | H41: 1.7115213 | I41: 3.5124525 | J41: 73.183561 | K41: 2.2804389 | L41: Eps | M41: Eps | N41: Eps | O41: 0.024905271 | P41: 20.871257 | Q41: Eps | R41: 0.13756077 | S41: Eps | T41: 9.5435376 | U41: 13.832993 | X41: =Notes!U40 -> Livestock | Y41: aa_LIVE | Z41: 0.024905271 | AA41: 17.822213 | AB41: 0.12164805 | AC41: Eps | AD41: Eps | AE41: Eps | AF41: 1.7115213 | AG41: Eps | AH41: Eps | AI41: 2.1205224 | AJ41: Eps | AK41: Eps | AL41: 1.7216311 | AM41: Eps | AN41: Eps
A42: 33 | C42: =Notes!U41 -> Cattle | D42: a_catt | E42: 0.41802316 | F42: 0.65258335 | G42: 0.39920543 | H42: 0.61620979 | I42: 0.11126271 | J42: 6.4032358 | K42: Eps | L42: Eps | M42: Eps | N42: Eps | O42: Eps | P42: 5.9339167 | Q42: Eps | R42: Eps | S42: Eps | T42: Eps | U42: 12.564295 | X42: =Notes!U41 -> Cattle | Y42: a_catt | Z42: Eps | AA42: Eps | AB42: Eps | AC42: Eps | AD42: Eps | AE42: Eps | AF42: 0.61620979 | AG42: Eps | AH42: Eps | AI42: 0.65258335 | AJ42: Eps | AK42: Eps | AL42: 0.41802316 | AM42: Eps | AN42: Eps
...

Sheet Macro
A1: Macroeconomic Results | N1: Tables: | O1: =C5 -> Quantities, price indices, and GDP shares
C5: Quantities, price indices, and GDP shares
C6: Init = Base year value or share of total GDP | Base = Average annual growth rate (%) | Sims = Deviation in average annual growth rate from baseline (%-point)
F7: init | G7: base | H7: sim1 | I7: sim2 | J7: sim3 | K7: sim4 | L7: sim5 | M7: sim6 | N7: sim7 | O7: sim8 | P7: sim9 | Q7: sim10 | R7: sim11 | S7: sim12 | T7: sim13 | U7: sim14 | V7: sim15
A8: 1 | C8: Quantities | D8: Absorption | E8: QABSTOT | F8: 52862.932 | G8: 3.0684079 | H8: Eps | I8: Eps | J8: Eps | K8: Eps | L8: Eps | M8: Eps | N8: Eps | O8: Eps | P8: Eps | Q8: Eps | R8: Eps | S8: Eps | T8: Eps | U8: Eps | V8: Eps
A9: 2 | D9: Private consumption | E9: QHTOT | F9: 33987.205 | G9: 3.0405704 | H9: Eps | I9: Eps | J9: Eps | K9: Eps | L9: Eps | M9: Eps | N9: Eps | O9: Eps | P9: Eps | Q9: Eps | R9: Eps | S9: Eps | T9: Eps | U9: Eps | V9: Eps
A10: 3 | D10: Government consumption | E10: QGTOT | F10: 3146.0385 | G10: 3.5 | H10: Eps | I10: Eps | J10: Eps | K10: Eps | L10: Eps | M10: Eps | N10: Eps | O10: Eps | P10: Eps | Q10: Eps | R10: Eps | S10: Eps | T10: Eps | U10: Eps | V10: Eps
A11: 4 | D11: Gross capital formation | E11: QINVTOT | F11: 15729.688 | G11: 3.0410731 | H11: Eps | I11: Eps | J11: Eps | K11: Eps | L11: Eps | M11: Eps | N11: Eps | O11: Eps | P11: Eps | Q11: Eps | R11: Eps | S11: Eps | T11: Eps | U11: Eps | V11: Eps
A12: 5 | D12: Exports | E12: QETOT | F12: 5228.6748 | G12: 2.9317433 | H12: Eps | I12: Eps | J12: Eps | K12: Eps | L12: Eps | M12: Eps | N12: Eps | O12: Eps | P12: Eps | Q12: Eps | R12: Eps | S12: Eps | T12: Eps | U12: Eps | V12: Eps
A13: 6 | D13: Imports | E13: QMTOT | F13: 8074.9039 | G13: 3.0511199 | H13: Eps | I13: Eps | J13: Eps | K13: Eps | L13: Eps | M13: Eps | N13: Eps | O13: Eps | P13: Eps | Q13: Eps | R13: Eps | S13: Eps | T13: Eps | U13: Eps | V13: Eps
A14: 7 | C14: Price indices | D14: Real exchange rate | E14: REXR | F14: 100 | G14: -0.01801394 | H14: Eps | I14: Eps | J14: Eps | K14: Eps | L14: Eps | M14: Eps | N14: Eps | O14: Eps | P14: Eps | Q14: Eps | R14: Eps | S14: Eps | T14: Eps | U14: Eps | V14: Eps
A15: 8 | D15: Nominal exchange rate | E15: NEXR | F15: 100 | G15: -0.018013939 | H15: Eps | I15: Eps | J15: Eps | K15: Eps | L15: Eps | M15: Eps | N15: Eps | O15: Eps | P15: Eps | Q15: Eps | R15: Eps | S15: Eps | T15: Eps | U15: Eps | V15: Eps
A16: 9 | D16: World export price index | E16: PWEIND | F16: 100 | G16: Eps | H16: Eps | I16: Eps | J16: Eps | K16: Eps | L16: Eps | M16: Eps | N16: Eps | O16: Eps | P16: Eps | Q16: Eps | R16: Eps | S16: Eps | T16: Eps | U16: Eps | V16: Eps
A17: 10 | D17: World import price index | E17: PWMIND | F17: 100 | G17: Eps | H17: Eps | I17: Eps | J17: Eps | K17: Eps | L17: Eps | M17: Eps | N17: Eps | O17: Eps | P17: Eps | Q17: Eps | R17: Eps | S17: Eps | T17: Eps | U17: Eps | V17: Eps
A18: 11 | D18: World price index | E18: PWIND | F18: 100 | G18: Eps | H18: Eps | I18: Eps | J18: Eps | K18: Eps | L18: Eps | M18: Eps | N18: Eps | O18: Eps | P18: Eps | Q18: Eps | R18: Eps | S18: Eps | T18: Eps | U18: Eps | V18: Eps
A19: 12 | D19: Domestic price index | E19: PDIND | F19: 100 | G19: 7.9924956e-10 | H19: Eps | I19: Eps | J19: Eps | K19: Eps | L19: Eps | M19: Eps | N19: Eps | O19: Eps | P19: Eps | Q19: Eps | R19: Eps | S19: Eps | T19: Eps | U19: Eps | V19: Eps
A20: 13 | D20: Consumer price index | E20: CPI | F20: 100 | G20: -0.00016062873 | H20: Eps | I20: Eps | J20: Eps | K20: Eps | L20: Eps | M20: Eps | N20: Eps | O20: Eps | P20: Eps | Q20: Eps | R20: Eps | S20: Eps | T20: Eps | U20: Eps | V20: Eps
A21: 14 | D21: Terms-of-trade | E21: TOFT | F21: 100 | G21: Eps | H21: Eps | I21: Eps | J21: Eps | K21: Eps | L21: Eps | M21: Eps | N21: Eps | O21: Eps | P21: Eps | Q21: Eps | R21: Eps | S21: Eps | T21: Eps | U21: Eps | V21: Eps
A22: 15 | C22: GDP shares | D22: Investment / GDP | E22: INVGDP | F22: 31.44887 | G22: -0.044809076 | H22: Eps | I22: Eps | J22: Eps | K22: Eps | L22: Eps | M22: Eps | N22: Eps | O22: Eps | P22: Eps | Q22: Eps | R22: Eps | S22: Eps | T22: Eps | U22: Eps | V22: Eps
D23: Savings / GDP | E23: TSAVGDP | F23: 31.44887 | G23: -0.04480908 | H23: Eps | I23: Eps | J23: Eps | K23: Eps | L23: Eps | M23: Eps | N23: Eps | O23: Eps | P23: Eps | Q23: Eps | R23: Eps | S23: Eps | T23: Eps | U23: Eps | V23: Eps
A24: 16 | D24: Private savings / GDP | E24: PRVSAVGDP | F24: 32.111755 | G24: -0.1461332 | H24: Eps | I24: Eps | J24: Eps | K24: Eps | L24: Eps | M24: Eps | N24: Eps | O24: Eps | P24: Eps | Q24: Eps | R24: Eps | S24: Eps | T24: Eps | U24: Eps | V24: Eps
A25: 17 | D25: Government savings / GDP | E25: GOVSAVGDP | F25: -2.5917392 | G25: 0.11248925 | H25: Eps | I25: Eps | J25: Eps | K25: Eps | L25: Eps | M25: Eps | N25: Eps | O25: Eps | P25: Eps | Q25: Eps | R25: Eps | S25: Eps | T25: Eps | U25: Eps | V25: Eps
A26: 18 | D26: Foreign savings / GDP | E26: FORSAVGDP | F26: 1.9288538 | G26: -0.011165135 | H26: Eps | I26: Eps | J26: Eps | K26: Eps | L26: Eps | M26: Eps | N26: Eps | O26: Eps | P26: Eps | Q26: Eps | R26: Eps | S26: Eps | T26: Eps | U26: Eps | V26: Eps
A27: 19 | D27: Trade deficit / GDP | E27: TRDDEFGDP | F27: 9.7200714 | G27: 0.057433811 | H27: Eps | I27: Eps | J27: Eps | K27: Eps | L27: Eps | M27: Eps | N27: Eps | O27: Eps | P27: Eps | Q27: Eps | R27: Eps | S27: Eps | T27: Eps | U27: Eps | V27: Eps
A28: 20 | D28: Tax revenue / GDP | E28: TOTTXGDP | F28: 5.1475267 | G28: -0.01848243 | H28: Eps | I28: Eps | J28: Eps | K28: Eps | L28: Eps | M28: Eps | N28: Eps | O28: Eps | P28: Eps | Q28: Eps | R28: Eps | S28: Eps | T28: Eps | U28: Eps | V28: Eps
A29: 21 | D29: Indirect tax revenue / GDP | E29: INDTXGDP | F29: 3.3134533 | G29: -0.0066687152 | H29: Eps | I29: Eps | J29: Eps | K29: Eps | L29: Eps | M29: Eps | N29: Eps | O29: Eps | P29: Eps | Q29: Eps | R29: Eps | S29: Eps | T29: Eps | U29: Eps | V29: Eps
A30: 22 | D30: Activity taxes / GDP | E30: ACTTXGDP | F30: Eps | G30: Eps | H30: Eps | I30: Eps | J30: Eps | K30: Eps | L30: Eps | M30: Eps | N30: Eps | O30: Eps | P30: Eps | Q30: Eps | R30: Eps | S30: Eps | T30: Eps | U30: Eps | V30: Eps
A31: 23 | D31: Value-added taxes / GDP | E31: VADTXGDP | F31: Eps | G31: Eps | H31: Eps | I31: Eps | J31: Eps | K31: Eps | L31: Eps | M31: Eps | N31: Eps | O31: Eps | P31: Eps | Q31: Eps | R31: Eps | S31: Eps | T31: Eps | U31: Eps | V31: Eps
A32: 24 | D32: Sales taxes / GDP | E32: COMTXGDP | F32: 2.7243681 | G32: -0.0057883392 | H32: Eps | I32: Eps | J32: Eps | K32: Eps | L32: Eps | M32: Eps | N32: Eps | O32: Eps | P32: Eps | Q32: Eps | R32: Eps | S32: Eps | T32: Eps | U32: Eps | V32: Eps
A33: 25 | D33: Export taxes / GDP | E33: EXPTXGDP | F33: 1.0984692e-05 | G33: -1.4555339e-07 | H33: Eps | I33: Eps | J33: Eps | K33: Eps | L33: Eps | M33: Eps | N33: Eps | O33: Eps | P33: Eps | Q33: Eps | R33: Eps | S33: Eps | T33: Eps | U33: Eps | V33: Eps
A34: 26 | D34: Import tariffs / GDP | E34: IMPTXGDP | F34: 0.58907425 | G34: -0.00088023043 | H34: Eps | I34: Eps | J34: Eps | K34: Eps | L34: Eps | M34: Eps | N34: Eps | O34: Eps | P34: Eps | Q34: Eps | R34: Eps | S34: Eps | T34: Eps | U34: Eps | V34: Eps
A35: 27 | D35: Direct tax revenue / GDP | E35: DIRTXGDP | F35: 1.8340734 | G35: -0.011813715 | H35: Eps | I35: Eps | J35: Eps | K35: Eps | L35: Eps | M35: Eps | N35: Eps | O35: Eps | P35: Eps | Q35: Eps | R35: Eps | S35: Eps | T35: Eps | U35: Eps | V35: Eps
A36: 28 | D36: Factor taxes / GDP | E36: FACTXGDP | F36: 0.01833389 | G36: -2.9622284e-05 | H36: Eps | I36: Eps | J36: Eps | K36: Eps | L36: Eps | M36: Eps | N36: Eps | O36: Eps | P36: Eps | Q36: Eps | R36: Eps | S36: Eps | T36: Eps | U36: Eps | V36: Eps
A37: 29 | D37: Institution taxes / GDP | E37: INSTXGDP | F37: 1.8157395 | G37: -0.011784093 | H37: Eps | I37: Eps | J37: Eps | K37: Eps | L37: Eps | M37: Eps | N37: Eps | O37: Eps | P37: Eps | Q37: Eps | R37: Eps | S37: Eps | T37: Eps | U37: Eps | V37: Eps
A38: 30
A39: 31

Sheet GDP
A1: Gross Domestic Product (GDP) | O1: Tables: | P1: =C5 -> GDP by expenditure component
P2: =Z5 -> Share of total GDP at market prices
C5: GDP by expenditure component | Z5: Share of total GDP at market prices
C6: Init = Base year share of GDP at market prices | Base = Average annual growth rate (%) | Sims = Deviation in average annual growth rate from baseline (%-point) | Z6: Init = Base year share of GDP at market prices | Base = Final deviation in share from base year (%-point) | Sims = Deviation in final share from baseline final share (%-point)
G7: init | H7: base | I7: sim1 | J7: sim2 | K7: sim3 | L7: sim4 | M7: sim5 | N7: sim6 | O7: sim7 | P7: sim8 | Q7: sim9 | R7: sim10 | S7: sim11 | T7: sim12 | U7: sim13 | V7: sim14 | W7: sim15 | AD7: init | AE7: base | AF7: sim1 | AG7: sim2 | AH7: sim3 | AI7: sim4 | AJ7: sim5 | AK7: sim6 | AL7: sim7 | AM7: sim8 | AN7: sim9 | AO7: sim10 | AP7: sim11 | AQ7: sim12 | AR7: sim13 | AS7: sim14 | AT7: sim15
A8: 1 | C8: Nominal | D8: GDP at factor cost | E8: NOMINAL | F8: r_GDPFC | G8: 96.686547 | H8: 3.067902 | I8: Eps | J8: Eps | K8: Eps | L8: Eps | M8: Eps | N8: Eps | O8: Eps | P8: Eps | Q8: Eps | R8: Eps | S8: Eps | T8: Eps | U8: Eps | V8: Eps | W8: Eps | Z8: Nominal | AA8: GDP at factor cost | AB8: NOMINAL | AC8: r_GDPFC | AD8: 96.686547 | AE8: 0.006668712 | AF8: Eps | AG8: Eps | AH8: Eps | AI8: Eps | AJ8: Eps | AK8: Eps | AL8: Eps | AM8: Eps | AN8: Eps | AO8: Eps | AP8: Eps | AQ8: Eps | AR8: Eps | AS8: Eps | AT8: Eps
A9: 2 | D9: Net indirect taxes | E9: NOMINAL | F9: r_NETITAX | G9: 3.3134533 | H9: 3.0372275 | I9: Eps | J9: Eps | K9: Eps | L9: Eps | M9: Eps | N9: Eps | O9: Eps | P9: Eps | Q9: Eps | R9: Eps | S9: Eps | T9: Eps | U9: Eps | V9: Eps | W9: Eps | AA9: Net indirect taxes | AB9: NOMINAL | AC9: r_NETITAX | AD9: 3.3134533 | AE9: -0.006668712 | AF9: Eps | AG9: Eps | AH9: Eps | AI9: Eps | AJ9: Eps | AK9: Eps | AL9: Eps | AM9: Eps | AN9: Eps | AO9: Eps | AP9: Eps | AQ9: Eps | AR9: Eps | AS9: Eps | AT9: Eps
A10: 3 | D10: GDP at market prices | E10: NOMINAL | F10: r_GDPMP | G10: 100 | H10: 3.0668865 | I10: Eps | J10: Eps | K10: Eps | L10: Eps | M10: Eps | N10: Eps | O10: Eps | P10: Eps | Q10: Eps | R10: Eps | S10: Eps | T10: Eps | U10: Eps | V10: Eps | W10: Eps | AA10: GDP at market prices | AB10: NOMINAL | AC10: r_GDPMP | AD10: 100 | AE10: Eps | AF10: Eps | AG10: Eps | AH10: Eps | AI10: Eps | AJ10: Eps | AK10: Eps | AL10: Eps | AM10: Eps | AN10: Eps | AO10: Eps | AP10: Eps | AQ10: Eps | AR10: Eps | AS10: Eps | AT10: Eps
A11: 4 | D11: Absorption | E11: NOMINAL | F11: r_ABSORP | G11: 105.69056 | H11: 3.0767781 | I11: Eps | J11: Eps | K11: Eps | L11: Eps | M11: Eps | N11: Eps | O11: Eps | P11: Eps | Q11: Eps | R11: Eps | S11: Eps | T11: Eps | U11: Eps | V11: Eps | W11: Eps | AA11: Absorption | AB11: NOMINAL | AC11: r_ABSORP | AD11: 105.69056 | AE11: 0.071024075 | AF11: Eps | AG11: Eps | AH11: Eps | AI11: Eps | AJ11: Eps | AK11: Eps | AL11: Eps | AM11: Eps | AN11: Eps | AO11: Eps | AP11: Eps | AQ11: Eps | AR11: Eps | AS11: Eps | AT11: Eps
A12: 5 | D12: Private consumption | E12: NOMINAL | F12: r_PRVCON | G12: 67.951711 | H12: 3.0411835 | I12: Eps | J12: Eps | K12: Eps | L12: Eps | M12: Eps | N12: Eps | O12: Eps | P12: Eps | Q12: Eps | R12: Eps | S12: Eps | T12: Eps | U12: Eps | V12: Eps | W12: Eps | AA12: Private consumption | AB12: NOMINAL | AC12: r_PRVCON | AD12: 67.951711 | AE12: -0.11853269 | AF12: Eps | AG12: Eps | AH12: Eps | AI12: Eps | AJ12: Eps | AK12: Eps | AL12: Eps | AM12: Eps | AN12: Eps | AO12: Eps | AP12: Eps | AQ12: Eps | AR12: Eps | AS12: Eps | AT12: Eps
A13: 6 | D13: Government consumption | E13: NOMINAL | F13: r_GOVCON | G13: 6.2899758 | H13: 3.6069362 | I13: Eps | J13: Eps | K13: Eps | L13: Eps | M13: Eps | N13: Eps | O13: Eps | P13: Eps | Q13: Eps | R13: Eps | S13: Eps | T13: Eps | U13: Eps | V13: Eps | W13: Eps | AA13: Government consumption | AB13: NOMINAL | AC13: r_GOVCON | AD13: 6.2899758 | AE13: 0.23436585 | AF13: Eps | AG13: Eps | AH13: Eps | AI13: Eps | AJ13: Eps | AK13: Eps | AL13: Eps | AM13: Eps | AN13: Eps | AO13: Eps | AP13: Eps | AQ13: Eps | AR13: Eps | AS13: Eps | AT13: Eps
A14: 7 | D14: Gross capital formation | E14: NOMINAL | F14: r_GCF | G14: 31.44887 | H14: 3.0458948 | I14: Eps | J14: Eps | K14: Eps | L14: Eps | M14: Eps | N14: Eps | O14: Eps | P14: Eps | Q14: Eps | R14: Eps | S14: Eps | T14: Eps | U14: Eps | V14: Eps | W14: Eps | AA14: Gross capital formation | AB14: NOMINAL | AC14: r_GCF | AD14: 31.44887 | AE14: -0.044809076 | AF14: Eps | AG14: Eps | AH14: Eps | AI14: Eps | AJ14: Eps | AK14: Eps | AL14: Eps | AM14: Eps | AN14: Eps | AO14: Eps | AP14: Eps | AQ14: Eps | AR14: Eps | AS14: Eps | AT14: Eps
A15: 8 | D15: Fixed capital formation | E15: NOMINAL | F15: r_GFCF | G15: 31.498388 | H15: 3.0415334 | I15: Eps | J15: Eps | K15: Eps | L15: Eps | M15: Eps | N15: Eps | O15: Eps | P15: Eps | Q15: Eps | R15: Eps | S15: Eps | T15: Eps | U15: Eps | V15: Eps | W15: Eps | AA15: Fixed capital formation | AB15: NOMINAL | AC15: r_GFCF | AD15: 31.498388 | AE15: -0.054197325 | AF15: Eps | AG15: Eps | AH15: Eps | AI15: Eps | AJ15: Eps | AK15: Eps | AL15: Eps | AM15: Eps | AN15: Eps | AO15: Eps | AP15: Eps | AQ15: Eps | AR15: Eps | AS15: Eps | AT15: Eps
A16: 9 | D16: Change in stocks | E16: NOMINAL | F16: r_STK | G16: -0.049517693 | H16: 0.017660504 | I16: Eps | J16: Eps | K16: Eps | L16: Eps | M16: Eps | N16: Eps | O16: Eps | P16: Eps | Q16: Eps | R16: Eps | S16: Eps | T16: Eps | U16: Eps | V16: Eps | W16: Eps | AA16: Change in stocks | AB16: NOMINAL | AC16: r_STK | AD16: -0.049517693 | AE16: 0.0093882485 | AF16: Eps | AG16: Eps | AH16: Eps | AI16: Eps | AJ16: Eps | AK16: Eps | AL16: Eps | AM16: Eps | AN16: Eps | AO16: Eps | AP16: Eps | AQ16: Eps | AR16: Eps | AS16: Eps | AT16: Eps
A17: 10 | D17: Net trade balance | E17: NOMINAL | F17: r_TRDBAL | G17: -5.6905573 | H17: 3.2496799 | I17: Eps | J17: Eps | K17: Eps | L17: Eps | M17: Eps | N17: Eps | O17: Eps | P17: Eps | Q17: Eps | R17: Eps | S17: Eps | T17: Eps | U17: Eps | V17: Eps | W17: Eps | AA17: Net trade balance | AB17: NOMINAL | AC17: r_TRDBAL | AD17: -5.6905573 | AE17: -0.071024075 | AF17: Eps | AG17: Eps | AH17: Eps | AI17: Eps | AJ17: Eps | AK17: Eps | AL17: Eps | AM17: Eps | AN17: Eps | AO17: Eps | AP17: Eps | AQ17: Eps | AR17: Eps | AS17: Eps | AT17: Eps
A18: 11 | D18: Exports | E18: NOMINAL | F18: r_EXP | G18: 10.453857 | H18: 2.9132012 | I18: Eps | J18: Eps | K18: Eps | L18: Eps | M18: Eps | N18: Eps | O18: Eps | P18: Eps | Q18: Eps | R18: Eps | S18: Eps | T18: Eps | U18: Eps | V18: Eps | W18: Eps | AA18: Exports | AB18: NOMINAL | AC18: r_EXP | AD18: 10.453857 | AE18: -0.10862894 | AF18: Eps | AG18: Eps | AH18: Eps | AI18: Eps | AJ18: Eps | AK18: Eps | AL18: Eps | AM18: Eps | AN18: Eps | AO18: Eps | AP18: Eps | AQ18: Eps | AR18: Eps | AS18: Eps | AT18: Eps
A19: 12 | D19: Imports | E19: NOMINAL | F19: r_IMP | G19: 16.144415 | H19: 3.0325563 | I19: Eps | J19: Eps | K19: Eps | L19: Eps | M19: Eps | N19: Eps | O19: Eps | P19: Eps | Q19: Eps | R19: Eps | S19: Eps | T19: Eps | U19: Eps | V19: Eps | W19: Eps | AA19: Imports | AB19: NOMINAL | AC19: r_IMP | AD19: 16.144415 | AE19: -0.037604863 | AF19: Eps | AG19: Eps | AH19: Eps | AI19: Eps | AJ19: Eps | AK19: Eps | AL19: Eps | AM19: Eps | AN19: Eps | AO19: Eps | AP19: Eps | AQ19: Eps | AR19: Eps | AS19: Eps | AT19: Eps
A20: 13 | C20: Real | D20: GDP at factor cost | E20: REAL | F20: r_GDPFC | G20: 96.686547 | H20: 3.0571208 | I20: Eps | J20: Eps | K20: Eps | L20: Eps | M20: Eps | N20: Eps | O20: Eps | P20: Eps | Q20: Eps | R20: Eps | S20: Eps | T20: Eps | U20: Eps | V20: Eps | W20: Eps | Z20: Real | AA20: GDP at factor cost | AB20: REAL | AC20: r_GDPFC | AD20: 96.686547 | AE20: 0.0010312575 | AF20: Eps | AG20: Eps | AH20: Eps | AI20: Eps | AJ20: Eps | AK20: Eps | AL20: Eps | AM20: Eps | AN20: Eps | AO20: Eps | AP20: Eps | AQ20: Eps | AR20: Eps | AS20: Eps | AT20: Eps
A21: 14 | D21: Net indirect taxes | E21: REAL | F21: r_NETITAX | G21: 3.3134533 | H21: 3.052381 | I21: Eps | J21: Eps | K21: Eps | L21: Eps | M21: Eps | N21: Eps | O21: Eps | P21: Eps | Q21: Eps | R21: Eps | S21: Eps | T21: Eps | U21: Eps | V21: Eps | W21: Eps | AA21: Net indirect taxes | AB21: REAL | AC21: r_NETITAX | AD21: 3.3134533 | AE21: -0.0010312575 | AF21: Eps | AG21: Eps | AH21: Eps | AI21: Eps | AJ21: Eps | AK21: Eps | AL21: Eps | AM21: Eps | AN21: Eps | AO21: Eps | AP21: Eps | AQ21: Eps | AR21: Eps | AS21: Eps | AT21: Eps
A22: 15 | D22: GDP at market prices | E22: REAL | F22: r_GDPMP | G22: 100 | H22: 3.0569638 | I22: Eps | J22: Eps | K22: Eps | L22: Eps | M22: Eps | N22: Eps | O22: Eps | P22: Eps | Q22: Eps | R22: Eps | S22: Eps | T22: Eps | U22: Eps | V22: Eps | W22: Eps | AA22: GDP at market prices | AB22: REAL | AC22: r_GDPMP | AD22: 100 | AE22: Eps | AF22: Eps | AG22: Eps | AH22: Eps | AI22: Eps | AJ22: Eps | AK22: Eps | AL22: Eps | AM22: Eps | AN22: Eps | AO22: Eps | AP22: Eps | AQ22: Eps | AR22: Eps | AS22: Eps | AT22: Eps
A23: 16 | D23: Absorption | E23: REAL | F23: r_ABSORP | G23: 105.69056 | H23: 3.0684079 | I23: Eps | J23: Eps | K23: Eps | L23: Eps | M23: Eps | N23: Eps | O23: Eps | P23: Eps | Q23: Eps | R23: Eps | S23: Eps | T23: Eps | U23: Eps | V23: Eps | W23: Eps | AA23: Absorption | AB23: REAL | AC23: r_ABSORP | AD23: 105.69056 | AE23: 0.082183802 | AF23: Eps | AG23: Eps | AH23: Eps | AI23: Eps | AJ23: Eps | AK23: Eps | AL23: Eps | AM23: Eps | AN23: Eps | AO23: Eps | AP23: Eps | AQ23: Eps | AR23: Eps | AS23: Eps | AT23: Eps
A24: 17 | D24: Private consumption | E24: REAL | F24: r_PRVCON | G24: 67.951711 | H24: 3.0405704 | I24: Eps | J24: Eps | K24: Eps | L24: Eps | M24: Eps | N24: Eps | O24: Eps | P24: Eps | Q24: Eps | R24: Eps | S24: Eps | T24: Eps | U24: Eps | V24: Eps | W24: Eps | AA24: Private consumption | AB24: REAL | AC24: r_PRVCON | AD24: 67.951711 | AE24: -0.075627994 | AF24: Eps | AG24: Eps | AH24: Eps | AI24: Eps | AJ24: Eps | AK24: Eps | AL24: Eps | AM24: Eps | AN24: Eps | AO24: Eps | AP24: Eps | AQ24: Eps | AR24: Eps | AS24: Eps | AT24: Eps
A25: 18 | D25: Government consumption | E25: REAL | F25: r_GOVCON | G25: 6.2899758 | H25: 3.5 | I25: Eps | J25: Eps | K25: Eps | L25: Eps | M25: Eps | N25: Eps | O25: Eps | P25: Eps | Q25: Eps | R25: Eps | S25: Eps | T25: Eps | U25: Eps | V25: Eps | W25: Eps | AA25: Government consumption | AB25: REAL | AC25: r_GOVCON | AD25: 6.2899758 | AE25: 0.19174054 | AF25: Eps | AG25: Eps | AH25: Eps | AI25: Eps | AJ25: Eps | AK25: Eps | AL25: Eps | AM25: Eps | AN25: Eps | AO25: Eps | AP25: Eps | AQ25: Eps | AR25: Eps | AS25: Eps | AT25: Eps
A26: 19 | D26: Gross capital formation | E26: REAL | F26: r_GCF | G26: 31.44887 | H26: 3.0410731 | I26: Eps | J26: Eps | K26: Eps | L26: Eps | M26: Eps | N26: Eps | O26: Eps | P26: Eps | Q26: Eps | R26: Eps | S26: Eps | T26: Eps | U26: Eps | V26: Eps | W26: Eps | AA26: Gross capital formation | AB26: REAL | AC26: r_GCF | AD26: 31.44887 | AE26: -0.03392874 | AF26: Eps | AG26: Eps | AH26: Eps | AI26: Eps | AJ26: Eps | AK26: Eps | AL26: Eps | AM26: Eps | AN26: Eps | AO26: Eps | AP26: Eps | AQ26: Eps | AR26: Eps | AS26: Eps | AT26: Eps
A27: 20 | D27: Fixed capital formation | E27: REAL | F27: r_GFCF | G27: 31.498388 | H27: 3.0366948 | I27: Eps | J27: Eps | K27: Eps | L27: Eps | M27: Eps | N27: Eps | O27: Eps | P27: Eps | Q27: Eps | R27: Eps | S27: Eps | T27: Eps | U27: Eps | V27: Eps | W27: Eps | AA27: Fixed capital formation | AB27: REAL | AC27: r_GFCF | AD27: 31.498388 | AE27: -0.043339542 | AF27: Eps | AG27: Eps | AH27: Eps | AI27: Eps | AJ27: Eps | AK27: Eps | AL27: Eps | AM27: Eps | AN27: Eps | AO27: Eps | AP27: Eps | AQ27: Eps | AR27: Eps | AS27: Eps | AT27: Eps
A28: 21 | D28: Change in stocks | E28: REAL | F28: r_STK | G28: -0.049517693 | H28: Eps | I28: Eps | J28: Eps | K28: Eps | L28: Eps | M28: Eps | N28: Eps | O28: Eps | P28: Eps | Q28: Eps | R28: Eps | S28: Eps | T28: Eps | U28: Eps | V28: Eps | W28: Eps | AA28: Change in stocks | AB28: REAL | AC28: r_STK | AD28: -0.049517693 | AE28: 0.0094108017 | AF28: Eps | AG28: Eps | AH28: Eps | AI28: Eps | AJ28: Eps | AK28: Eps | AL28: Eps | AM28: Eps | AN28: Eps | AO28: Eps | AP28: Eps | AQ28: Eps | AR28: Eps | AS28: Eps | AT28: Eps
A29: 22 | D29: Net trade balance | E29: REAL | F29: r_TRDBAL | G29: -5.6905573 | H29: 3.2682826 | I29: Eps | J29: Eps | K29: Eps | L29: Eps | M29: Eps | N29: Eps | O29: Eps | P29: Eps | Q29: Eps | R29: Eps | S29: Eps | T29: Eps | U29: Eps | V29: Eps | W29: Eps | AA29: Net trade balance | AB29: REAL | AC29: r_TRDBAL | AD29: -5.6905573 | AE29: -0.082183802 | AF29: Eps | AG29: Eps | AH29: Eps | AI29: Eps | AJ29: Eps | AK29: Eps | AL29: Eps | AM29: Eps | AN29: Eps | AO29: Eps | AP29: Eps | AQ29: Eps | AR29: Eps | AS29: Eps | AT29: Eps
A30: 23 | D30: Exports | E30: REAL | F30: r_EXP | G30: 10.453857 | H30: 2.9317433 | I30: Eps | J30: Eps | K30: Eps | L30: Eps | M30: Eps | N30: Eps | O30: Eps | P30: Eps | Q30: Eps | R30: Eps | S30: Eps | T30: Eps | U30: Eps | V30: Eps | W30: Eps | AA30: Exports | AB30: REAL | AC30: r_EXP | AD30: 10.453857 | AE30: -0.088591051 | AF30: Eps | AG30: Eps | AH30: Eps | AI30: Eps | AJ30: Eps | AK30: Eps | AL30: Eps | AM30: Eps | AN30: Eps | AO30: Eps | AP30: Eps | AQ30: Eps | AR30: Eps | AS30: Eps | AT30: Eps
A31: 24 | D31: Imports | E31: REAL | F31: r_IMP | G31: 16.144415 | H31: 3.0511199 | I31: Eps | J31: Eps | K31: Eps | L31: Eps | M31: Eps | N31: Eps | O31: Eps | P31: Eps | Q31: Eps | R31: Eps | S31: Eps | T31: Eps | U31: Eps | V31: Eps | W31: Eps | AA31: Imports | AB31: REAL | AC31: r_IMP | AD31: 16.144415 | AE31: -0.0064072486 | AF31: Eps | AG31: Eps | AH31: Eps | AI31: Eps | AJ31: Eps | AK31: Eps | AL31: Eps | AM31: Eps | AN31: Eps | AO31: Eps | AP31: Eps | AQ31: Eps | AR31: Eps | AS31: Eps | AT31: Eps
A32: 150

Sheet Sector
A1: Sectoral Gross Domestic Product (GDP) | M1: Tables: | N1: =C5 -> GDP at factor cost (PVA×QVA)
N2: =X5 -> Share of total GDP at factor cost (PVA×QVA)
C5: GDP at factor cost (PVA×QVA) | X5: Share of total GDP at factor cost (PVA×QVA)
C6: Init = Base year share of total GDP | Base = Average annual growth rate (%) | Sims = Deviation in average annual growth rate from baseline (%-point) | X6: Init = Base year share of total GDP | Base = Final deviation in share from base year (%-point) | Sims = Deviation in final share from baseline final share (%-point)
E7: init | F7: base | G7: sim1 | H7: sim2 | I7: sim3 | J7: sim4 | K7: sim5 | L7: sim6 | M7: sim7 | N7: sim8 | O7: sim9 | P7: sim10 | Q7: sim11 | R7: sim12 | S7: sim13 | T7: sim14 | U7: sim15 | Z7: init | AA7: base | AB7: sim1 | AC7: sim2 | AD7: sim3 | AE7: sim4 | AF7: sim5 | AG7: sim6 | AH7: sim7 | AI7: sim8 | AJ7: sim9 | AK7: sim10 | AL7: sim11 | AM7: sim12 | AN7: sim13 | AO7: sim14 | AP7: sim15
A8: 1 | C8: =Notes!T9 -> All sectors | D8: aa_GDP | E8: 100 | F8: 3.0571208 | G8: Eps | H8: Eps | I8: Eps | J8: Eps | K8: Eps | L8: Eps | M8: Eps | N8: Eps | O8: Eps | P8: Eps | Q8: Eps | R8: Eps | S8: Eps | T8: Eps | U8: Eps | X8: =Notes!T9 -> All sectors | Y8: aa_GDP | Z8: 100 | AA8: Eps | AB8: Eps | AC8: Eps | AD8: Eps | AE8: Eps | AF8: Eps | AG8: Eps | AH8: Eps | AI8: Eps | AJ8: Eps | AK8: Eps | AL8: Eps | AM8: Eps | AN8: Eps | AO8: Eps | AP8: Eps
