Workbook

Sheet Notes
A1: ="Dynamic Simulations | "&D3&" ("&D4&")" -> Dynamic Simulations | Bangladesh (2023)
C3: Country | D3: Bangladesh | K3: Shock years
C4: Year | D4: 2023 | K4: First | L4: =INDEX(Main!$H$5:$H$58,2) -> 2024
C5: Units | D5: Billions of Taka | K5: Last | L5: =MAX(Main!H5:H58) -> 2040
C7: Activities | G7: Commodities | K7: Factors | O7: Households | S7: Other accounts
C8: Accounts | D8: Description | K8: Accounts | L8: Description | O8: Accounts | P8: Description | S8: Accounts | T8: Description
C9: amaiz | D9: Maize | G9: cmaiz | H9: Maize | K9: flab-rn | L9: Labor - rural uneducated | O9: hhd-r0 | P9: Rural - decile 1 | S9: trc | T9: Transaction costs
C10: asorg | D10: Sorghum and millet | G10: csorg | H10: Sorghum and millet | K10: flab-rp | L10: Labor - rural primary | O10: hhd-r1 | P10: Rural - decile 2 | S10: ent | T10: Enterprises
C11: aaman | D11: Rice paddy (Aman) | G11: caman | H11: Rice paddy (Aman) | K11: flab-rs | L11: Labor - rural secondary | O11: hhd-r2 | P11: Rural - decile 3 | S11: gov | T11: Government
C12: aboro | D12: Rice paddy (Boro) | G12: cboro | H12: Rice paddy (Boro) | K12: flab-rt | L12: Labor - rural tertiary | O12: hhd-r3 | P12: Rural - decile 4 | S12: atax | T12: Taxes - activity
C13: awhea | D13: Wheat and barley | G13: cwhea | H13: Wheat and barley | K13: flab-un | L13: Labor - urban uneducated | O13: hhd-r4 | P13: Rural - decile 5 | S13: dtax | T13: Taxes - direct
C14: aocer | D14: Other cereals | G14: cocer | H14: Other cereals | K14: flab-up | L14: Labor - urban primary | O14: hhd-r5 | P14: Rural - decile 6 | S14: etax | T14: Taxes - export
C15: apuls | D15: Pulses | G15: cpuls | H15: Pulses | K15: flab-us | L15: Labor - urban secondary | O15: hhd-r6 | P15: Rural - decile 7 | S15: ftax | T15: Taxes - factor
C16: agnut | D16: Groundnuts | G16: cgnut | H16: Groundnuts | K16: flab-ut | L16: Labor - urban tertiary | O16: hhd-r7 | P16: Rural - decile 8 | S16: mtax | T16: Taxes - import
C17: aoils | D17: Other oilseeds | G17: coils | H17: Other oilseeds | K17: flnd | L17: Crop land | O17: hhd-r8 | P17: Rural - decile 9 | S17: stax | T17: Taxes - sales
C18: acass | D18: Cassava | G18: ccass | H18: Cassava | K18: fcap-c | L18: Capital - crops | O18: hhd-r9 | P18: Rural - decile 10 | S18: vtax | T18: Taxes - value-added
C19: aipot | D19: Irish potatoes | G19: cipot | H19: Irish potatoes | K19: fcap-l | L19: Capital - livestock | O19: hhd-u0 | P19: Urban - decile 1 | S19: s-i | T19: Savings-investment
C20: aspot | D20: Sweet potatoes | G20: cspot | H20: Sweet potatoes | K20: fcap-m | L20: Capital - mining | O20: hhd-u1 | P20: Urban - decile 2 | S20: dstk | T20: Change in stocks
C21: aroot | D21: Other roots | G21: croot | H21: Other roots | K21: fcap-n | L21: Capital - non-primary | O21: hhd-u2 | P21: Urban - decile 3 | S21: row | T21: Rest of world
C22: aleaf | D22: Leafy vegetables | G22: cleaf | H22: Leafy vegetables | O22: hhd-u3 | P22: Urban - decile 4 | S22: total | T22: Total
C23: avege | D23: Other vegetables | G23: cvege | H23: Other vegetables | O23: hhd-u4 | P23: Urban - decile 5
C24: asugr | D24: Sugarcane | G24: csugr | H24: Sugarcane | O24: hhd-u5 | P24: Urban - decile 6
C25: atoba | D25: Tobacco | G25: ctoba | H25: Tobacco | O25: hhd-u6 | P25: Urban - decile 7
C26: acott | D26: Cotton and fibres | G26: ccott | H26: Cotton and fibres | O26: hhd-u7 | P26: Urban - decile 8
C27: ajute | D27: Jute | G27: cjute | H27: Jute | O27: hhd-u8 | P27: Urban - decile 9
C28: anuts | D28: Nuts | G28: cnuts | H28: Nuts | O28: hhd-u9 | P28: Urban - decile 10
C29: abana | D29: Bananas and plantains | G29: cbana | H29: Bananas and plantains
C30: afrui | D30: Other fruits | G30: cfrui | H30: Other fruits
C31: ateal | D31: Leaf tea | G31: cteal | H31: Leaf tea
C32: acoff | D32: Coffee | G32: ccoff | H32: Coffee
C33: acoco | D33: Cocoa | G33: ccoco | H33: Cocoa
C34: aflwr | D34: Cut flowers | G34: cflwr | H34: Cut flowers
C35: arubb | D35: Rubber | G35: crubb | H35: Rubber
C36: aocrp | D36: Other crops | G36: cocrp | H36: Other crops
C37: acatt | D37: Cattle | G37: ccatt | H37: Cattle
C38: amilk | D38: Raw milk | G38: cmilk | H38: Raw milk
C39: apoul | D39: Poultry | G39: cpoul | H39: Poultry
C40: aeggs | D40: Eggs | G40: ceggs | H40: Eggs
... C100: aosrv | D100: Other services | G100: cosrv | H100: Other services

Sheet Main
A1: Activate Simulations and Select Closures
C3: Activate simulations | H3: Time periods | L3: Macro closures
C4: Active? (0 = no | 1 = yes) | H4: All | I4: Active | M4: base | N4: {=TRANSPOSE(C7:C21)} -> sim1 | O4: sim2 | P4: sim3 | Q4: sim4 | R4: sim5 | S4: sim6 | T4: sim7 | U4: sim8 | V4: sim9 | W4: sim10 | X4: sim11 | Y4: sim12 | Z4: sim13 | AA4: sim14 | AB4: sim15 | AE4: Numeraire:
C5: init | E5: Base year | H5: 2023 | I5: 2023 | L5: Numeraire | M5: 2 | N5: 2 | O5: 2 | P5: 2 | Q5: 2 | R5: 2 | S5: 2 | T5: 2 | U5: 2 | V5: 2 | W5: 2 | X5: 2 | Y5: 2 | Z5: 2 | AA5: 2 | AB5: 2 | AE5: 1 | AF5: CPI is fixed numeraire (DPI is flexible)
C6: base | D6: 1 | E6: Base scenario | H6: 2024 | I6: 2024 | L6: Savings-investment | M6: 3 | N6: 3 | O6: 3 | P6: 3 | Q6: 3 | R6: 3 | S6: 3 | T6: 3 | U6: 3 | V6: 3 | W6: 3 | X6: 3 | Y6: 3 | Z6: 3 | AA6: 3 | AB6: 3 | AE6: 2 | AF6: DPI is fixed numeraire (CPI is flexible)
C7: sim1 | H7: 2025 | I7: 2025 | L7: Current-account | M7: 1 | N7: 1 | O7: 1 | P7: 1 | Q7: 1 | R7: 1 | S7: 1 | T7: 1 | U7: 1 | V7: 1 | W7: 1 | X7: 1 | Y7: 1 | Z7: 1 | AA7: 1 | AB7: 1
C8: sim2 | H8: 2026 | I8: 2026 | L8: Government-account | M8: 1 | N8: 1 | O8: 1 | P8: 1 | Q8: 1 | R8: 1 | S8: 1 | T8: 1 | U8: 1 | V8: 1 | W8: 1 | X8: 1 | Y8: 1 | Z8: 1 | AA8: 1 | AB8: 1 | AE8: Factor closures:
C9: sim3 | H9: 2027 | I9: 2027 | AE9: 1 | AF9: Fully employed and mobile
C10: sim4 | H10: 2028 | I10: 2028 | AE10: 2 | AF10: Fully employed and activity-specific
C11: sim5 | H11: 2029 | I11: 2029 | L11: Factor market closures | AE11: 3 | AF11: Unemployed and mobile
C12: sim6 | H12: 2030 | I12: 2030 | M12: base | N12: {=TRANSPOSE(C7:C21)} -> sim1 | O12: sim2 | P12: sim3 | Q12: sim4 | R12: sim5 | S12: sim6 | T12: sim7 | U12: sim8 | V12: sim9 | W12: sim10 | X12: sim11 | Y12: sim12 | Z12: sim13 | AA12: sim14 | AB12: sim15
C13: sim7 | H13: 2031 | L13: flab-rn | M13: 1 | N13: 1 | O13: 1 | P13: 1 | Q13: 1 | R13: 1 | S13: 1 | T13: 1 | U13: 1 | V13: 1 | W13: 1 | X13: 1 | Y13: 1 | Z13: 1 | AA13: 1 | AB13: 1 | AE13: Savings-investment closures:
C14: sim8 | H14: 2032 | L14: flab-rp | M14: 1 | N14: 1 | O14: 1 | P14: 1 | Q14: 1 | R14: 1 | S14: 1 | T14: 1 | U14: 1 | V14: 1 | W14: 1 | X14: 1 | Y14: 1 | Z14: 1 | AA14: 1 | AB14: 1 | AE14: 1 | AF14: Investment-driven savings - uniform MPS adjustment (identical point change in marginal propensities to save across selected institutions)
C15: sim9 | H15: 2033 | L15: flab-rs | M15: 1 | N15: 1 | O15: 1 | P15: 1 | Q15: 1 | R15: 1 | S15: 1 | T15: 1 | U15: 1 | V15: 1 | W15: 1 | X15: 1 | Y15: 1 | Z15: 1 | AA15: 1 | AB15: 1 | AE15: 2 | AF15: Investment-driven savings - scaled MPS adjustment (proportional change in marginal propensities to save across selected institutions)
C16: sim10 | H16: 2034 | L16: flab-rt | M16: 1 | N16: 1 | O16: 1 | P16: 1 | Q16: 1 | R16: 1 | S16: 1 | T16: 1 | U16: 1 | V16: 1 | W16: 1 | X16: 1 | Y16: 1 | Z16: 1 | AA16: 1 | AB16: 1 | AE16: 3 | AF16: Investment is savings-driven
C17: sim11 | H17: 2035 | L17: flab-un | M17: 1 | N17: 1 | O17: 1 | P17: 1 | Q17: 1 | R17: 1 | S17: 1 | T17: 1 | U17: 1 | V17: 1 | W17: 1 | X17: 1 | Y17: 1 | Z17: 1 | AA17: 1 | AB17: 1 | AE17: 4 | AF17: Balanced: Investment is fixed share of absorption - uniform MPS adjustment (identical point change in marginal propensity to save)
C18: sim12 | H18: 2036 | L18: flab-up | M18: 1 | N18: 1 | O18: 1 | P18: 1 | Q18: 1 | R18: 1 | S18: 1 | T18: 1 | U18: 1 | V18: 1 | W18: 1 | X18: 1 | Y18: 1 | Z18: 1 | AA18: 1 | AB18: 1 | AE18: 5 | AF18: Balanced: Investment is fixed share of absorption - scaled MPS adjustment (proportional change in marginal propensity to save)
C19: sim13 | H19: 2037 | L19: flab-us | M19: 1 | N19: 1 | O19: 1 | P19: 1 | Q19: 1 | R19: 1 | S19: 1 | T19: 1 | U19: 1 | V19: 1 | W19: 1 | X19: 1 | Y19: 1 | Z19: 1 | AA19: 1 | AB19: 1
C20: sim14 | H20: 2038 | L20: flab-ut | M20: 1 | N20: 1 | O20: 1 | P20: 1 | Q20: 1 | R20: 1 | S20: 1 | T20: 1 | U20: 1 | V20: 1 | W20: 1 | X20: 1 | Y20: 1 | Z20: 1 | AA20: 1 | AB20: 1 | AE20: Current account closures:
C21: sim15 | H21: 2039 | L21: flnd | M21: 1 | N21: 1 | O21: 1 | P21: 1 | Q21: 1 | R21: 1 | S21: 1 | T21: 1 | U21: 1 | V21: 1 | W21: 1 | X21: 1 | Y21: 1 | Z21: 1 | AA21: 1 | AB21: 1 | AE21: 1 | AF21: Exchange rate EXR is flexible (foreign savings are fixed)
H22: 2040 | L22: fcap-c | M22: 2 | N22: 2 | O22: 2 | P22: 2 | Q22: 2 | R22: 2 | S22: 2 | T22: 2 | U22: 2 | V22: 2 | W22: 2 | X22: 2 | Y22: 2 | Z22: 2 | AA22: 2 | AB22: 2 | AE22: 2 | AF22: Foreign savings FSAV are flexible (exchange rate is fixed)
L23: fcap-l | M23: 2 | N23: 2 | O23: 2 | P23: 2 | Q23: 2 | R23: 2 | S23: 2 | T23: 2 | U23: 2 | V23: 2 | W23: 2 | X23: 2 | Y23: 2 | Z23: 2 | AA23: 2 | AB23: 2
L24: fcap-m | M24: 2 | N24: 2 | O24: 2 | P24: 2 | Q24: 2 | R24: 2 | S24: 2 | T24: 2 | U24: 2 | V24: 2 | W24: 2 | X24: 2 | Y24: 2 | Z24: 2 | AA24: 2 | AB24: 2 | AE24: Government account closures:
L25: fcap-n | M25: 2 | N25: 2 | O25: 2 | P25: 2 | Q25: 2 | R25: 2 | S25: 2 | T25: 2 | U25: 2 | V25: 2 | W25: 2 | X25: 2 | Y25: 2 | Z25: 2 | AA25: 2 | AB25: 2 | AE25: 1 | AF25: Government savings GSAV are flexible (all direct and indirect tax rates is fixed)
AE26: 2 | AF26: Government savings are fixed - uniform TI adjustment (identical point change in direct tax rate for selected institutions)
AE27: 3 | AF27: Government savings are fixed - scaled TI adjustment (proportional change in direct tax rate for selected institutions)
AE28: 4 | AF28: Government savings are fixed - uniform TQ adjustment (identical point change in sales tax rate)
AE29: 5 | AF29: Government savings are fixed - scaled TQ adjustment (proportional change in sales tax rate)
AE30: 6 | AF30: Government savings are fixed - uniform TA adjustment (identical point change in activity tax rate)
AE31: 7 | AF31: Government savings are fixed - scaled TA adjustment (proportional change in activity tax rate)
AE32: 8 | AF32: Government savings are fixed - uniform TM adjustment (identical point change in import tariff rate)
AE33: 9 | AF33: Government savings are fixed - scaled TM adjustment (proportional change in import tariff rate)
AE34: 10 | AF34: Government savings are fixed - uniform TE adjustment (identical point change in export tax rate)
AE35: 11 | AF35: Government savings are fixed - scaled TE adjustment (proportional change in export tax rate)
AE36: 12 | AF36: Government savings are fixed - uniform TV adjustment (identical point change in activity value-added tax rate)
AE37: 13 | AF37: Government savings are fixed - scaled TV adjustment (proportional change in activity value-added tax rate)
... AE39: 15 | AF39: Government savings are fixed - scaled TF adjustment (proportional change in factor tax rate for selected factors)

Sheet Base
A1: Baseline Scenario | AC1: =Main!C7 -> sim1 | AD1: =IF(Main!E7<>"",Main!E7,"")
C3: Commodity trends | O3: Activity trends | Y3: Factor trends | AK3: Household and enterprise trends | AW3: Macro trends
D4: World prices | F4: Commodity taxes | I4: Transaction costs | L4: Closures | P4: TFP | Q4: Activity taxes | S4: Fixed factors | U4: Closures | Z4: Wage | AA4: Factor | AB4: Product- | AC4: Factor | AD4: Transfers to… | AF4: Transfers from… | AH4: Closures | AL4: Pop. | AM4: Savings | AN4: Direct | AO4: Transfers to… | AQ4: Transfers from… | AS4: Closures | AY4: Shock
D5: Exports | E5: Imports | F5: Exports | G5: Imports | H5: Sales | I5: Exports | J5: Imports | K5: Domestic | L5: Taxes | Q5: Activity | R5: VAD | S5: Fix cap. | T5: Fix land | U5: Prod. shk | V5: Taxes | Z5: rate | AA5: supply | AB5: ivity | AC5: taxes | AD5: Gov. | AE5: World | AF5: Gov. | AG5: World | AH5: Taxes | AL5: change | AM5: rate | AN5: tax | AO5: Gov. | AP5: World | AQ5: Gov. | AR5: World | AS5: Savings | AT5: Taxes | AY5: shk
AW6: Exchange rate | AX6: exr | AY6: 0
D7: pwe | E7: pwm | F7: te | G7: tm | H7: tq | I7: ice | J7: icm | K7: icd | L7: tax | P7: alphava | Q7: ta | R7: tv | S7: fixcap | T7: fixlnd | U7: alphaf | V7: tax | Z7: wf | AA7: qfs | AB7: alphaf | AC7: tf | AD7: trtg | AE7: trtw | AF7: trfg | AG7: trfw | AH7: tax | AL7: pop | AM7: mps | AN7: ti | AO7: trtg | AP7: trtw | AQ7: trfg | AR7: trfw | AS7: save | AT7: tax | AW7: Foreign savings | AX7: fsav | AY7: 3
C8: cmaiz | D8: 0 | E8: 0 | F8: 0 | G8: 0 | H8: 0 | I8: 0 | J8: 0 | K8: 0 | L8: 1 | O8: amaiz | P8: 1 | Q8: 0 | R8: 0 | S8: 0 | T8: 0 | U8: 1 | V8: 1 | Y8: flab-rn | Z8: 0 | AA8: 2 | AB8: 0 | AC8: 0 | AD8: 0 | AE8: 0 | AF8: 0 | AG8: 0 | AH8: 1 | AK8: ent | AL8: 0 | AM8: 0 | AN8: 0 | AO8: 0 | AP8: 0 | AQ8: 3.5 | AR8: 3.5 | AS8: 1 | AT8: 1 | AW8: Investment | AX8: iadj | AY8: 0
C9: csorg | D9: 0 | E9: 0 | F9: 0 | G9: 0 | H9: 0 | I9: 0 | J9: 0 | K9: 0 | L9: 1 | O9: asorg | P9: 1 | Q9: 0 | R9: 0 | S9: 0 | T9: 0 | U9: 1 | V9: 1 | Y9: flab-rp | Z9: 0 | AA9: 2 | AB9: 0 | AC9: 0 | AD9: 0 | AE9: 0 | AF9: 0 | AG9: 0 | AH9: 1 | AK9: hhd-r0 | AL9: 2 | AM9: 0 | AN9: 0 | AO9: 0 | AP9: 0 | AQ9: 3.5 | AR9: 3.5 | AS9: 1 | AT9: 1 | AW9: Inv. absorp. share | AX9: invshr | AY9: 0
C10: caman | D10: 0 | E10: 0 | F10: 0 | G10: 0 | H10: 0 | I10: 0 | J10: 0 | K10: 0 | L10: 1 | O10: aaman | P10: 1 | Q10: 0 | R10: 0 | S10: 0 | T10: 0 | U10: 1 | V10: 1 | Y10: flab-rs | Z10: 0 | AA10: 2 | AB10: 0 | AC10: 0 | AD10: 0 | AE10: 0 | AF10: 0 | AG10: 0 | AH10: 1 | AK10: hhd-r1 | AL10: 2 | AM10: 0 | AN10: 0 | AO10: 0 | AP10: 0 | AQ10: 3.5 | AR10: 3.5 | AS10: 1 | AT10: 1 | AW10: Savings rates | AX10: mps | AY10: 0
C11: cboro | D11: 0 | E11: 0 | F11: 0 | G11: 0 | H11: 0 | I11: 0 | J11: 0 | K11: 0 | L11: 1 | O11: aboro | P11: 1 | Q11: 0 | R11: 0 | S11: 0 | T11: 0 | U11: 1 | V11: 1 | Y11: flab-rt | Z11: 0 | AA11: 2 | AB11: 0 | AC11: 0 | AD11: 0 | AE11: 0 | AF11: 0 | AG11: 0 | AH11: 1 | AK11: hhd-r2 | AL11: 2 | AM11: 0 | AN11: 0 | AO11: 0 | AP11: 0 | AQ11: 3.5 | AR11: 3.5 | AS11: 1 | AT11: 1 | AW11: Gov. savings | AX11: gsav | AY11: 0
C12: cwhea | D12: 0 | E12: 0 | F12: 0 | G12: 0 | H12: 0 | I12: 0 | J12: 0 | K12: 0 | L12: 1 | O12: awhea | P12: 1 | Q12: 0 | R12: 0 | S12: 0 | T12: 0 | U12: 1 | V12: 1 | Y12: flab-un | Z12: 0 | AA12: 2 | AB12: 0 | AC12: 0 | AD12: 0 | AE12: 0 | AF12: 0 | AG12: 0 | AH12: 1 | AK12: hhd-r3 | AL12: 2 | AM12: 0 | AN12: 0 | AO12: 0 | AP12: 0 | AQ12: 3.5 | AR12: 3.5 | AS12: 1 | AT12: 1 | AW12: Gov. spending | AX12: gadj | AY12: 3.5
C13: cocer | D13: 0 | E13: 0 | F13: 0 | G13: 0 | H13: 0 | I13: 0 | J13: 0 | K13: 0 | L13: 1 | O13: aocer | P13: 1 | Q13: 0 | R13: 0 | S13: 0 | T13: 0 | U13: 1 | V13: 1 | Y13: flab-up | Z13: 0 | AA13: 2 | AB13: 0 | AC13: 0 | AD13: 0 | AE13: 0 | AF13: 0 | AG13: 0 | AH13: 1 | AK13: hhd-r4 | AL13: 2 | AM13: 0 | AN13: 0 | AO13: 0 | AP13: 0 | AQ13: 3.5 | AR13: 3.5 | AS13: 1 | AT13: 1 | AW13: Gov. absorp. share | AX13: govshr | AY13: 0
C14: cpuls | D14: 0 | E14: 0 | F14: 0 | G14: 0 | H14: 0 | I14: 0 | J14: 0 | K14: 0 | L14: 1 | O14: apuls | P14: 1 | Q14: 0 | R14: 0 | S14: 0 | T14: 0 | U14: 1 | V14: 1 | Y14: flab-us | Z14: 0 | AA14: 2 | AB14: 0 | AC14: 0 | AD14: 0 | AE14: 0 | AF14: 0 | AG14: 0 | AH14: 1 | AK14: hhd-r5 | AL14: 2 | AM14: 0 | AN14: 0 | AO14: 0 | AP14: 0 | AQ14: 3.5 | AR14: 3.5 | AS14: 1 | AT14: 1 | AW14: Gov. tran. to world | AX14: trtw | AY14: 3.5
C15: cgnut | D15: 0 | E15: 0 | F15: 0 | G15: 0 | H15: 0 | I15: 0 | J15: 0 | K15: 0 | L15: 1 | O15: agnut | P15: 1 | Q15: 0 | R15: 0 | S15: 0 | T15: 0 | U15: 1 | V15: 1 | Y15: flab-ut | Z15: 0 | AA15: 2 | AB15: 0 | AC15: 0 | AD15: 0 | AE15: 0 | AF15: 0 | AG15: 0 | AH15: 1 | AK15: hhd-r6 | AL15: 2 | AM15: 0 | AN15: 0 | AO15: 0 | AP15: 0 | AQ15: 3.5 | AR15: 3.5 | AS15: 1 | AT15: 1 | AW15: Gov. tran. from world | AX15: trfw | AY15: 3.5
C16: coils | D16: 0 | E16: 0 | F16: 0 | G16: 0 | H16: 0 | I16: 0 | J16: 0 | K16: 0 | L16: 1 | O16: aoils | P16: 1 | Q16: 0 | R16: 0 | S16: 0 | T16: 0 | U16: 1 | V16: 1 | Y16: flnd | Z16: 0 | AA16: 2 | AB16: 0 | AC16: 0 | AD16: 0 | AE16: 0 | AF16: 0 | AG16: 0 | AH16: 1 | AK16: hhd-r7 | AL16: 2 | AM16: 0 | AN16: 0 | AO16: 0 | AP16: 0 | AQ16: 3.5 | AR16: 3.5 | AS16: 1 | AT16: 1 | AW16: Export taxes | AX16: te | AY16: 0
C17: ccass | D17: 0 | E17: 0 | F17: 0 | G17: 0 | H17: 0 | I17: 0 | J17: 0 | K17: 0 | L17: 1 | O17: acass | P17: 1 | Q17: 0 | R17: 0 | S17: 0 | T17: 0 | U17: 1 | V17: 1 | Y17: fcap-c | Z17: 0 | AA17: 2 | AB17: 0 | AC17: 0 | AD17: 0 | AE17: 0 | AF17: 0 | AG17: 0 | AH17: 1 | AK17: hhd-r8 | AL17: 2 | AM17: 0 | AN17: 0 | AO17: 0 | AP17: 0 | AQ17: 3.5 | AR17: 3.5 | AS17: 1 | AT17: 1 | AW17: Import tariffs | AX17: tm | AY17: 0
C18: cipot | D18: 0 | E18: 0 | F18: 0 | G18: 0 | H18: 0 | I18: 0 | J18: 0 | K18: 0 | L18: 1 | O18: aipot | P18: 1 | Q18: 0 | R18: 0 | S18: 0 | T18: 0 | U18: 1 | V18: 1 | Y18: fcap-l | Z18: 0 | AA18: 2 | AB18: 0 | AC18: 0 | AD18: 0 | AE18: 0 | AF18: 0 | AG18: 0 | AH18: 1 | AK18: hhd-r9 | AL18: 2 | AM18: 0 | AN18: 0 | AO18: 0 | AP18: 0 | AQ18: 3.5 | AR18: 3.5 | AS18: 1 | AT18: 1 | AW18: Sales taxes | AX18: tq | AY18: 0
C19: cspot | D19: 0 | E19: 0 | F19: 0 | G19: 0 | H19: 0 | I19: 0 | J19: 0 | K19: 0 | L19: 1 | O19: aspot | P19: 1 | Q19: 0 | R19: 0 | S19: 0 | T19: 0 | U19: 1 | V19: 1 | Y19: fcap-m | Z19: 0 | AA19: 2 | AB19: 0 | AC19: 0 | AD19: 0 | AE19: 0 | AF19: 0 | AG19: 0 | AH19: 1 | AK19: hhd-u0 | AL19: 2 | AM19: 0 | AN19: 0 | AO19: 0 | AP19: 0 | AQ19: 3.5 | AR19: 3.5 | AS19: 1 | AT19: 1 | AW19: Activity taxes | AX19: ta | AY19: 0
C20: croot | D20: 0 | E20: 0 | F20: 0 | G20: 0 | H20: 0 | I20: 0 | J20: 0 | K20: 0 | L20: 1 | O20: aroot | P20: 1 | Q20: 0 | R20: 0 | S20: 0 | T20: 0 | U20: 1 | V20: 1 | Y20: fcap-n | Z20: 0 | AA20: 2 | AB20: 0 | AC20: 0 | AD20: 0 | AE20: 0 | AF20: 0 | AG20: 0 | AH20: 1 | AK20: hhd-u1 | AL20: 2 | AM20: 0 | AN20: 0 | AO20: 0 | AP20: 0 | AQ20: 3.5 | AR20: 3.5 | AS20: 1 | AT20: 1 | AW20: Value-added taxes | AX20: tv | AY20: 0
C21: cleaf | D21: 0 | E21: 0 | F21: 0 | G21: 0 | H21: 0 | I21: 0 | J21: 0 | K21: 0 | L21: 1 | O21: aleaf | P21: 1 | Q21: 0 | R21: 0 | S21: 0 | T21: 0 | U21: 1 | V21: 1 | AK21: hhd-u2 | AL21: 2 | AM21: 0 | AN21: 0 | AO21: 0 | AP21: 0 | AQ21: 3.5 | AR21: 3.5 | AS21: 1 | AT21: 1 | AW21: Factor taxes | AX21: tf | AY21: 0
C22: cvege | D22: 0 | E22: 0 | F22: 0 | G22: 0 | H22: 0 | I22: 0 | J22: 0 | K22: 0 | L22: 1 | O22: avege | P22: 1 | Q22: 0 | R22: 0 | S22: 0 | T22: 0 | U22: 1 | V22: 1 | AK22: hhd-u3 | AL22: 2 | AM22: 0 | AN22: 0 | AO22: 0 | AP22: 0 | AQ22: 3.5 | AR22: 3.5 | AS22: 1 | AT22: 1 | AW22: Direct taxes | AX22: ti | AY22: 0
C23: csugr | D23: 0 | E23: 0 | F23: 0 | G23: 0 | H23: 0 | I23: 0 | J23: 0 | K23: 0 | L23: 1 | O23: asugr | P23: 1 | Q23: 0 | R23: 0 | S23: 0 | T23: 2 | U23: 1 | V23: 1 | AK23: hhd-u4 | AL23: 2 | AM23: 0 | AN23: 0 | AO23: 0 | AP23: 0 | AQ23: 3.5 | AR23: 3.5 | AS23: 1 | AT23: 1 | AW23: Depreciation rate | AX23: drate | AY23: 5
C24: ctoba | D24: 0 | E24: 0 | F24: 0 | G24: 0 | H24: 0 | I24: 0 | J24: 0 | K24: 0 | L24: 1 | O24: atoba | P24: 1 | Q24: 0 | R24: 0 | S24: 0 | T24: 2 | U24: 1 | V24: 1 | AK24: hhd-u5 | AL24: 2 | AM24: 0 | AN24: 0 | AO24: 0 | AP24: 0 | AQ24: 3.5 | AR24: 3.5 | AS24: 1 | AT24: 1
C25: ccott | D25: 0 | E25: 0 | F25: 0 | G25: 0 | H25: 0 | I25: 0 | J25: 0 | K25: 0 | L25: 1 | O25: acott | P25: 1 | Q25: 0 | R25: 0 | S25: 0 | T25: 2 | U25: 1 | V25: 1 | AK25: hhd-u6 | AL25: 2 | AM25: 0 | AN25: 0 | AO25: 0 | AP25: 0 | AQ25: 3.5 | AR25: 3.5 | AS25: 1 | AT25: 1
C26: cjute | D26: 0 | E26: 0 | F26: 0 | G26: 0 | H26: 0 | I26: 0 | J26: 0 | K26: 0 | L26: 1 | O26: ajute | P26: 1 | Q26: 0 | R26: 0 | S26: 0 | T26: 2 | U26: 1 | V26: 1 | AK26: hhd-u7 | AL26: 2 | AM26: 0 | AN26: 0 | AO26: 0 | AP26: 0 | AQ26: 3.5 | AR26: 3.5 | AS26: 1 | AT26: 1
C27: cnuts | D27: 0 | E27: 0 | F27: 0 | G27: 0 | H27: 0 | I27: 0 | J27: 0 | K27: 0 | L27: 1 | O27: anuts | P27: 1 | Q27: 0 | R27: 0 | S27: 0 | T27: 2 | U27: 1 | V27: 1 | AK27: hhd-u8 | AL27: 2 | AM27: 0 | AN27: 0 | AO27: 0 | AP27: 0 | AQ27: 3.5 | AR27: 3.5 | AS27: 1 | AT27: 1
C28: cbana | D28: 0 | E28: 0 | F28: 0 | G28: 0 | H28: 0 | I28: 0 | J28: 0 | K28: 0 | L28: 1 | O28: abana | P28: 1 | Q28: 0 | R28: 0 | S28: 0 | T28: 2 | U28: 1 | V28: 1 | AK28: hhd-u9 | AL28: 2 | AM28: 0 | AN28: 0 | AO28: 0 | AP28: 0 | AQ28: 3.5 | AR28: 3.5 | AS28: 1 | AT28: 1
C29: cfrui | D29: 0 | E29: 0 | F29: 0 | G29: 0 | H29: 0 | I29: 0 | J29: 0 | K29: 0 | L29: 1 | O29: afrui | P29: 1 | Q29: 0 | R29: 0 | S29: 0 | T29: 2 | U29: 1 | V29: 1
C30: cteal | D30: 0 | E30: 0 | F30: 0 | G30: 0 | H30: 0 | I30: 0 | J30: 0 | K30: 0 | L30: 1 | O30: ateal | P30: 1 | Q30: 0 | R30: 0 | S30: 0 | T30: 2 | U30: 1 | V30: 1
C31: ccoff | D31: 0 | E31: 0 | F31: 0 | G31: 0 | H31: 0 | I31: 0 | J31: 0 | K31: 0 | L31: 1 | O31: acoff | P31: 1 | Q31: 0 | R31: 0 | S31: 0 | T31: 2 | U31: 1 | V31: 1
C32: ccoco | D32: 0 | E32: 0 | F32: 0 | G32: 0 | H32: 0 | I32: 0 | J32: 0 | K32: 0 | L32: 1 | O32: acoco | P32: 1 | Q32: 0 | R32: 0 | S32: 0 | T32: 2 | U32: 1 | V32: 1
C33: cflwr | D33: 0 | E33: 0 | F33: 0 | G33: 0 | H33: 0 | I33: 0 | J33: 0 | K33: 0 | L33: 1 | O33: aflwr | P33: 1 | Q33: 0 | R33: 0 | S33: 0 | T33: 2 | U33: 1 | V33: 1
C34: crubb | D34: 0 | E34: 0 | F34: 0 | G34: 0 | H34: 0 | I34: 0 | J34: 0 | K34: 0 | L34: 1 | O34: arubb | P34: 1 | Q34: 0 | R34: 0 | S34: 0 | T34: 2 | U34: 1 | V34: 1
C35: cocrp | D35: 0 | E35: 0 | F35: 0 | G35: 0 | H35: 0 | I35: 0 | J35: 0 | K35: 0 | L35: 1 | O35: aocrp | P35: 1 | Q35: 0 | R35: 0 | S35: 0 | T35: 2 | U35: 1 | V35: 1
C36: ccatt | D36: 0 | E36: 0 | F36: 0 | G36: 0 | H36: 0 | I36: 0 | J36: 0 | K36: 0 | L36: 1 | O36: acatt | P36: 1 | Q36: 0 | R36: 0 | S36: 0 | T36: 0 | U36: 1 | V36: 1
C37: cmilk | D37: 0 | E37: 0 | F37: 0 | G37: 0 | H37: 0 | I37: 0 | J37: 0 | K37: 0 | L37: 1 | O37: amilk | P37: 1 | Q37: 0 | R37: 0 | S37: 0 | T37: 0 | U37: 1 | V37: 1
C38: cpoul | D38: 0 | E38: 0 | F38: 0 | G38: 0 | H38: 0 | I38: 0 | J38: 0 | K38: 0 | L38: 1 | O38: apoul | P38: 1 | Q38: 0 | R38: 0 | S38: 0 | T38: 0 | U38: 1 | V38: 1
C39: ceggs | D39: 0 | E39: 0 | F39: 0 | G39: 0 | H39: 0 | I39: 0 | J39: 0 | K39: 0 | L39: 1 | O39: aeggs | P39: 1 | Q39: 0 | R39: 0 | S39: 0 | T39: 0 | U39: 1 | V39: 1
C40: csmlr | D40: 0 | E40: 0 | F40: 0 | G40: 0 | H40: 0 | I40: 0 | J40: 0 | K40: 0 | L40: 1 | O40: asmlr | P40: 1 | Q40: 0 | R40: 0 | S40: 0 | T40: 0 | U40: 1 | V40: 1
... C99: cosrv | D99: 0 | E99: 0 | F99: 0 | G99: 0 | H99: 0 | I99: 0 | J99: 0 | K99: 0 | L99: 1 | O99: aosrv | P99: 1 | Q99: 0 | R99: 0 | S99: 0 | T99: 0 | U99: 1 | V99: 1

Sheet S1
A1: ="Simulation "&AC1&IF(AD1<>""," : "&AD1,"") -> Simulation sim1 | AC1: =Main!C7 -> sim1 | AD1: =IF(Main!E7<>"",Main!E7,"")
C3: Commodity shocks | O3: Activity shocks | Y3: Factor shocks | AK3: Household and enterprise shocks | AW3: Macro shocks
D4: World prices | F4: Commodity taxes | I4: Transaction costs | L4: Closures | P4: TFP | Q4: Activity taxes | S4: Fixed factors | U4: Closures | Z4: Wage | AA4: Factor | AB4: Product- | AC4: Factor | AD4: Transfers to… | AF4: Transfers from… | AH4: Closures | AL4: Pop. | AM4: Savings | AN4: Direct | AO4: Transfers to… | AQ4: Transfers from… | AS4: Closures | AY4: Start | AZ4: End | BA4: Shock | BB4: Multi-
D5: Exports | E5: Imports | F5: Exports | G5: Imports | H5: Sales | I5: Exports | J5: Imports | K5: Domestic | L5: Taxes | Q5: Activity | R5: VAD | S5: Fix cap. | T5: Fix land | U5: Prod. shk | V5: Taxes | Z5: rate | AA5: supply | AB5: ivity | AC5: taxes | AD5: Gov. | AE5: World | AF5: Gov. | AG5: World | AH5: Taxes | AL5: change | AM5: rate | AN5: tax | AO5: Gov. | AP5: World | AQ5: Gov. | AR5: World | AS5: Savings | AT5: Taxes | BB5: plicative
AW6: Scalar parameter | AY6: start | AZ6: end | BA6: shk | BB6: type
D7: pwe | E7: pwm | F7: te | G7: tm | H7: tq | I7: ice | J7: icm | K7: icd | P7: alphava | Q7: ta | R7: tv | S7: fixcap | T7: fixlnd | Z7: wf | AA7: qfs | AB7: alphaf | AC7: tf | AD7: trtg | AE7: trtw | AF7: trfg | AG7: trfw | AL7: pop | AM7: mps | AN7: ti | AO7: trtg | AP7: trtw | AQ7: trfg | AR7: trfw | AW7: Exchange rate | AX7: exr | AY7: =Notes!$L$4 -> 2024 | AZ7: =Notes!$L$5 -> 2040 | BA7: 0 | BB7: 1
C8: Start | D8: =Notes!$L4 -> 2024 | E8: =Notes!$L4 -> 2024 | F8: =Notes!$L4 -> 2024 | G8: =Notes!$L4 -> 2024 | H8: =Notes!$L4 -> 2024 | I8: =Notes!$L4 -> 2024 | J8: =Notes!$L4 -> 2024 | K8: =Notes!$L4 -> 2024 | O8: Start | P8: =Notes!$L4 -> 2024 | Q8: =Notes!$L4 -> 2024 | R8: =Notes!$L4 -> 2024 | S8: =Notes!$L4 -> 2024 | T8: =Notes!$L4 -> 2024 | Y8: Start | Z8: =Notes!$L4 -> 2024 | AA8: =Notes!$L4 -> 2024 | AB8: =Notes!$L4 -> 2024 | AC8: =Notes!$L4 -> 2024 | AD8: =Notes!$L4 -> 2024 | AE8: =Notes!$L4 -> 2024 | AF8: =Notes!$L4 -> 2024 | AG8: =Notes!$L4 -> 2024 | AK8: Start | AL8: =Notes!$L4 -> 2024 | AM8: =Notes!$L4 -> 2024 | AN8: =Notes!$L4 -> 2024 | AO8: =Notes!$L4 -> 2024 | AP8: =Notes!$L4 -> 2024 | AQ8: =Notes!$L$4 -> 2024 | AR8: =Notes!$L4 -> 2024 | AW8: Foreign savings | AX8: fsav | AY8: =Notes!$L$4 -> 2024 | AZ8: =Notes!$L$5 -> 2040 | BA8: 0 | BB8: 1
C9: End | D9: =Notes!$L5 -> 2040 | E9: =Notes!$L5 -> 2040 | F9: =Notes!$L5 -> 2040 | G9: =Notes!$L5 -> 2040 | H9: =Notes!$L5 -> 2040 | I9: =Notes!$L5 -> 2040 | J9: =Notes!$L5 -> 2040 | K9: =Notes!$L5 -> 2040 | O9: End | P9: =Notes!$L5 -> 2040 | Q9: =Notes!$L5 -> 2040 | R9: =Notes!$L5 -> 2040 | S9: =Notes!$L5 -> 2040 | T9: =Notes!$L5 -> 2040 | Y9: End | Z9: =Notes!$L5 -> 2040 | AA9: =Notes!$L5 -> 2040 | AB9: =Notes!$L5 -> 2040 | AC9: =Notes!$L5 -> 2040 | AD9: =Notes!$L5 -> 2040 | AE9: =Notes!$L5 -> 2040 | AF9: =Notes!$L5 -> 2040 | AG9: =Notes!$L5 -> 2040 | AK9: End | AL9: =Notes!$L5 -> 2040 | AM9: =Notes!$L5 -> 2040 | AN9: =Notes!$L5 -> 2040 | AO9: =Notes!$L5 -> 2040 | AP9: =Notes!$L5 -> 2040 | AQ9: =Notes!$L5 -> 2040 | AR9: =Notes!$L5 -> 2040 | AW9: Investment | AX9: iadj | AY9: =Notes!$L$4 -> 2024 | AZ9: =Notes!$L$5 -> 2040 | BA9: 0 | BB9: 1
AW10: Inv. absorp. share | AX10: invshr | AY10: =Notes!$L$4 -> 2024 | AZ10: =Notes!$L$5 -> 2040 | BA10: 0 | BB10: 1
C11: Multiplicative? (1 = yes | 2 = additive) | O11: Multiplicative? (1 = yes | 2 = additive) | Y11: Multiplicative? (1 = yes | 2 = additive) | AK11: Multiplicative? (1 = yes | 2 = additive) | AW11: Savings rates | AX11: mps | AY11: =Notes!$L$4 -> 2024 | AZ11: =Notes!$L$5 -> 2040 | BA11: 0 | BB11: 1
D12: pwe | E12: pwm | F12: te | G12: tm | H12: tq | I12: ice | J12: icm | K12: icd | P12: alphava | Q12: ta | R12: tv | Z12: wf | AA12: qfs | AB12: alphaf | AC12: tf | AD12: trtg | AE12: trtw | AF12: trfg | AG12: trfw | AL12: pop | AM12: mps | AN12: ti | AO12: trtg | AP12: trtw | AQ12: trfg | AR12: trfw | AW12: Gov. savings | AX12: gsav | AY12: =Notes!$L$4 -> 2024 | AZ12: =Notes!$L$5 -> 2040 | BA12: 0 | BB12: 1
D13: 1 | E13: 1 | F13: 1 | G13: 1 | H13: 1 | I13: 1 | J13: 1 | K13: 1 | P13: 1 | Q13: 1 | R13: 1 | Z13: 1 | AA13: 1 | AB13: 1 | AC13: 1 | AD13: 1 | AE13: 1 | AF13: 1 | AG13: 1 | AL13: 1 | AM13: 1 | AN13: 1 | AO13: 1 | AP13: 1 | AQ13: 1 | AR13: 1 | AW13: Gov. spending | AX13: gadj | AY13: =Notes!$L$4 -> 2024 | AZ13: =Notes!$L$5 -> 2040 | BA13: 0 | BB13: 1
AW14: Gov. absorp. share | AX14: govshr | AY14: =Notes!$L$4 -> 2024 | AZ14: =Notes!$L$5 -> 2040 | BA14: 0 | BB14: 1
C15: Shock | O15: Shock | Y15: Shock | AK15: Shock | AW15: Gov. tran. to world | AX15: trtw | AY15: =Notes!$L$4 -> 2024 | AZ15: =Notes!$L$5 -> 2040 | BA15: 0 | BB15: 1
D16: pwe | E16: pwm | F16: te | G16: tm | H16: tq | I16: ice | J16: icm | K16: icd | L16: tax | P16: alphava | Q16: ta | R16: tv | S16: fixcap | T16: fixlnd | U16: alphaf | V16: tax | Z16: wf | AA16: qfs | AB16: alphaf | AC16: tf | AD16: trtg | AE16: trtw | AF16: trfg | AG16: trfw | AH16: tax | AL16: pop | AM16: mps | AN16: ti | AO16: trtg | AP16: trtw | AQ16: trfg | AR16: trfw | AS16: save | AT16: tax | AW16: Gov. tran. from world | AX16: trfw | AY16: =Notes!$L$4 -> 2024 | AZ16: =Notes!$L$5 -> 2040 | BA16: 0 | BB16: 1
C17: cmaiz | D17: 0 | E17: 0 | F17: 0 | G17: 0 | H17: 0 | I17: 0 | J17: 0 | K17: 0 | L17: 1 | O17: amaiz | P17: 0 | Q17: 0 | R17: 0 | S17: 0 | T17: 0 | U17: 1 | V17: 1 | Y17: flab-rn | Z17: 0 | AA17: 0 | AB17: 0 | AC17: 0 | AD17: 0 | AE17: 0 | AF17: 0 | AG17: 0 | AH17: 1 | AK17: ent | AL17: 0 | AM17: 0 | AN17: 0 | AO17: 0 | AP17: 0 | AQ17: 0 | AR17: 0 | AS17: 1 | AT17: 1 | AW17: Export taxes | AX17: te | AY17: =Notes!$L$4 -> 2024 | AZ17: =Notes!$L$5 -> 2040 | BA17: 0 | BB17: 1
C18: csorg | D18: 0 | E18: 0 | F18: 0 | G18: 0 | H18: 0 | I18: 0 | J18: 0 | K18: 0 | L18: 1 | O18: asorg | P18: 0 | Q18: 0 | R18: 0 | S18: 0 | T18: 0 | U18: 1 | V18: 1 | Y18: flab-rp | Z18: 0 | AA18: 0 | AB18: 0 | AC18: 0 | AD18: 0 | AE18: 0 | AF18: 0 | AG18: 0 | AH18: 1 | AK18: hhd-r0 | AL18: 0 | AM18: 0 | AN18: 0 | AO18: 0 | AP18: 0 | AQ18: 0 | AR18: 0 | AS18: 1 | AT18: 1 | AW18: Import tariffs | AX18: tm | AY18: =Notes!$L$4 -> 2024 | AZ18: =Notes!$L$5 -> 2040 | BA18: 0 | BB18: 1
C19: caman | D19: 0 | E19: 0 | F19: 0 | G19: 0 | H19: 0 | I19: 0 | J19: 0 | K19: 0 | L19: 1 | O19: aaman | P19: 0 | Q19: 0 | R19: 0 | S19: 0 | T19: 0 | U19: 1 | V19: 1 | Y19: flab-rs | Z19: 0 | AA19: 0 | AB19: 0 | AC19: 0 | AD19: 0 | AE19: 0 | AF19: 0 | AG19: 0 | AH19: 1 | AK19: hhd-r1 | AL19: 0 | AM19: 0 | AN19: 0 | AO19: 0 | AP19: 0 | AQ19: 0 | AR19: 0 | AS19: 1 | AT19: 1 | AW19: Sales taxes | AX19: tq | AY19: =Notes!$L$4 -> 2024 | AZ19: =Notes!$L$5 -> 2040 | BA19: 0 | BB19: 1
C20: cboro | D20: 0 | E20: 0 | F20: 0 | G20: 0 | H20: 0 | I20: 0 | J20: 0 | K20: 0 | L20: 1 | O20: aboro | P20: 0 | Q20: 0 | R20: 0 | S20: 0 | T20: 0 | U20: 1 | V20: 1 | Y20: flab-rt | Z20: 0 | AA20: 0 | AB20: 0 | AC20: 0 | AD20: 0 | AE20: 0 | AF20: 0 | AG20: 0 | AH20: 1 | AK20: hhd-r2 | AL20: 0 | AM20: 0 | AN20: 0 | AO20: 0 | AP20: 0 | AQ20: 0 | AR20: 0 | AS20: 1 | AT20: 1 | AW20: Activity taxes | AX20: ta | AY20: =Notes!$L$4 -> 2024 | AZ20: =Notes!$L$5 -> 2040 | BA20: 0 | BB20: 1
C21: cwhea | D21: 0 | E21: 0 | F21: 0 | G21: 0 | H21: 0 | I21: 0 | J21: 0 | K21: 0 | L21: 1 | O21: awhea | P21: 0 | Q21: 0 | R21: 0 | S21: 0 | T21: 0 | U21: 1 | V21: 1 | Y21: flab-un | Z21: 0 | AA21: 0 | AB21: 0 | AC21: 0 | AD21: 0 | AE21: 0 | AF21: 0 | AG21: 0 | AH21: 1 | AK21: hhd-r3 | AL21: 0 | AM21: 0 | AN21: 0 | AO21: 0 | AP21: 0 | AQ21: 0 | AR21: 0 | AS21: 1 | AT21: 1 | AW21: Value-added taxes | AX21: tv | AY21: =Notes!$L$4 -> 2024 | AZ21: =Notes!$L$5 -> 2040 | BA21: 0 | BB21: 1
C22: cocer | D22: 0 | E22: 0 | F22: 0 | G22: 0 | H22: 0 | I22: 0 | J22: 0 | K22: 0 | L22: 1 | O22: aocer | P22: 0 | Q22: 0 | R22: 0 | S22: 0 | T22: 0 | U22: 1 | V22: 1 | Y22: flab-up | Z22: 0 | AA22: 0 | AB22: 0 | AC22: 0 | AD22: 0 | AE22: 0 | AF22: 0 | AG22: 0 | AH22: 1 | AK22: hhd-r4 | AL22: 0 | AM22: 0 | AN22: 0 | AO22: 0 | AP22: 0 | AQ22: 0 | AR22: 0 | AS22: 1 | AT22: 1 | AW22: Factor taxes | AX22: tf | AY22: =Notes!$L$4 -> 2024 | AZ22: =Notes!$L$5 -> 2040 | BA22: 0 | BB22: 1
C23: cpuls | D23: 0 | E23: 0 | F23: 0 | G23: 0 | H23: 0 | I23: 0 | J23: 0 | K23: 0 | L23: 1 | O23: apuls | P23: 0 | Q23: 0 | R23: 0 | S23: 0 | T23: 0 | U23: 1 | V23: 1 | Y23: flab-us | Z23: 0 | AA23: 0 | AB23: 0 | AC23: 0 | AD23: 0 | AE23: 0 | AF23: 0 | AG23: 0 | AH23: 1 | AK23: hhd-r5 | AL23: 0 | AM23: 0 | AN23: 0 | AO23: 0 | AP23: 0 | AQ23: 0 | AR23: 0 | AS23: 1 | AT23: 1 | AW23: Direct taxes | AX23: ti | AY23: =Notes!$L$4 -> 2024 | AZ23: =Notes!$L$5 -> 2040 | BA23: 0 | BB23: 1
C24: cgnut | D24: 0 | E24: 0 | F24: 0 | G24: 0 | H24: 0 | I24: 0 | J24: 0 | K24: 0 | L24: 1 | O24: agnut | P24: 0 | Q24: 0 | R24: 0 | S24: 0 | T24: 0 | U24: 1 | V24: 1 | Y24: flab-ut | Z24: 0 | AA24: 0 | AB24: 0 | AC24: 0 | AD24: 0 | AE24: 0 | AF24: 0 | AG24: 0 | AH24: 1 | AK24: hhd-r6 | AL24: 0 | AM24: 0 | AN24: 0 | AO24: 0 | AP24: 0 | AQ24: 0 | AR24: 0 | AS24: 1 | AT24: 1 | AW24: Depreciation rate | AX24: drate | AY24: =Notes!$L$4 -> 2024 | AZ24: =Notes!$L$5 -> 2040 | BA24: 0 | BB24: 1
C25: coils | D25: 0 | E25: 0 | F25: 0 | G25: 0 | H25: 0 | I25: 0 | J25: 0 | K25: 0 | L25: 1 | O25: aoils | P25: 0 | Q25: 0 | R25: 0 | S25: 0 | T25: 0 | U25: 1 | V25: 1 | Y25: flnd | Z25: 0 | AA25: 0 | AB25: 0 | AC25: 0 | AD25: 0 | AE25: 0 | AF25: 0 | AG25: 0 | AH25: 1 | AK25: hhd-r7 | AL25: 0 | AM25: 0 | AN25: 0 | AO25: 0 | AP25: 0 | AQ25: 0 | AR25: 0 | AS25: 1 | AT25: 1
C26: ccass | D26: 0 | E26: 0 | F26: 0 | G26: 0 | H26: 0 | I26: 0 | J26: 0 | K26: 0 | L26: 1 | O26: acass | P26: 0 | Q26: 0 | R26: 0 | S26: 0 | T26: 0 | U26: 1 | V26: 1 | Y26: fcap-c | Z26: 0 | AA26: 0 | AB26: 0 | AC26: 0 | AD26: 0 | AE26: 0 | AF26: 0 | AG26: 0 | AH26: 1 | AK26: hhd-r8 | AL26: 0 | AM26: 0 | AN26: 0 | AO26: 0 | AP26: 0 | AQ26: 0 | AR26: 0 | AS26: 1 | AT26: 1
C27: cipot | D27: 0 | E27: 0 | F27: 0 | G27: 0 | H27: 0 | I27: 0 | J27: 0 | K27: 0 | L27: 1 | O27: aipot | P27: 0 | Q27: 0 | R27: 0 | S27: 0 | T27: 0 | U27: 1 | V27: 1 | Y27: fcap-l | Z27: 0 | AA27: 0 | AB27: 0 | AC27: 0 | AD27: 0 | AE27: 0 | AF27: 0 | AG27: 0 | AH27: 1 | AK27: hhd-r9 | AL27: 0 | AM27: 0 | AN27: 0 | AO27: 0 | AP27: 0 | AQ27: 0 | AR27: 0 | AS27: 1 | AT27: 1
C28: cspot | D28: 0 | E28: 0 | F28: 0 | G28: 0 | H28: 0 | I28: 0 | J28: 0 | K28: 0 | L28: 1 | O28: aspot | P28: 0 | Q28: 0 | R28: 0 | S28: 0 | T28: 0 | U28: 1 | V28: 1 | Y28: fcap-m | Z28: 0 | AA28: 0 | AB28: 0 | AC28: 0 | AD28: 0 | AE28: 0 | AF28: 0 | AG28: 0 | AH28: 1 | AK28: hhd-u0 | AL28: 0 | AM28: 0 | AN28: 0 | AO28: 0 | AP28: 0 | AQ28: 0 | AR28: 0 | AS28: 1 | AT28: 1
C29: croot | D29: 0 | E29: 0 | F29: 0 | G29: 0 | H29: 0 | I29: 0 | J29: 0 | K29: 0 | L29: 1 | O29: aroot | P29: 0 | Q29: 0 | R29: 0 | S29: 0 | T29: 0 | U29: 1 | V29: 1 | Y29: fcap-n | Z29: 0 | AA29: 0 | AB29: 0 | AC29: 0 | AD29: 0 | AE29: 0 | AF29: 0 | AG29: 0 | AH29: 1 | AK29: hhd-u1 | AL29: 0 | AM29: 0 | AN29: 0 | AO29: 0 | AP29: 0 | AQ29: 0 | AR29: 0 | AS29: 1 | AT29: 1
C30: cleaf | D30: 0 | E30: 0 | F30: 0 | G30: 0 | H30: 0 | I30: 0 | J30: 0 | K30: 0 | L30: 1 | O30: aleaf | P30: 0 | Q30: 0 | R30: 0 | S30: 0 | T30: 0 | U30: 1 | V30: 1 | AK30: hhd-u2 | AL30: 0 | AM30: 0 | AN30: 0 | AO30: 0 | AP30: 0 | AQ30: 0 | AR30: 0 | AS30: 1 | AT30: 1
C31: cvege | D31: 0 | E31: 0 | F31: 0 | G31: 0 | H31: 0 | I31: 0 | J31: 0 | K31: 0 | L31: 1 | O31: avege | P31: 0 | Q31: 0 | R31: 0 | S31: 0 | T31: 0 | U31: 1 | V31: 1 | AK31: hhd-u3 | AL31: 0 | AM31: 0 | AN31: 0 | AO31: 0 | AP31: 0 | AQ31: 0 | AR31: 0 | AS31: 1 | AT31: 1
C32: csugr | D32: 0 | E32: 0 | F32: 0 | G32: 0 | H32: 0 | I32: 0 | J32: 0 | K32: 0 | L32: 1 | O32: asugr | P32: 0 | Q32: 0 | R32: 0 | S32: 0 | T32: 0 | U32: 1 | V32: 1 | AK32: hhd-u4 | AL32: 0 | AM32: 0 | AN32: 0 | AO32: 0 | AP32: 0 | AQ32: 0 | AR32: 0 | AS32: 1 | AT32: 1
C33: ctoba | D33: 0 | E33: 0 | F33: 0 | G33: 0 | H33: 0 | I33: 0 | J33: 0 | K33: 0 | L33: 1 | O33: atoba | P33: 0 | Q33: 0 | R33: 0 | S33: 0 | T33: 0 | U33: 1 | V33: 1 | AK33: hhd-u5 | AL33: 0 | AM33: 0 | AN33: 0 | AO33: 0 | AP33: 0 | AQ33: 0 | AR33: 0 | AS33: 1 | AT33: 1
C34: ccott | D34: 0 | E34: 0 | F34: 0 | G34: 0 | H34: 0 | I34: 0 | J34: 0 | K34: 0 | L34: 1 | O34: acott | P34: 0 | Q34: 0 | R34: 0 | S34: 0 | T34: 0 | U34: 1 | V34: 1 | AK34: hhd-u6 | AL34: 0 | AM34: 0 | AN34: 0 | AO34: 0 | AP34: 0 | AQ34: 0 | AR34: 0 | AS34: 1 | AT34: 1
C35: cjute | D35: 0 | E35: 0 | F35: 0 | G35: 0 | H35: 0 | I35: 0 | J35: 0 | K35: 0 | L35: 1 | O35: ajute | P35: 0 | Q35: 0 | R35: 0 | S35: 0 | T35: 0 | U35: 1 | V35: 1 | AK35: hhd-u7 | AL35: 0 | AM35: 0 | AN35: 0 | AO35: 0 | AP35: 0 | AQ35: 0 | AR35: 0 | AS35: 1 | AT35: 1
C36: cnuts | D36: 0 | E36: 0 | F36: 0 | G36: 0 | H36: 0 | I36: 0 | J36: 0 | K36: 0 | L36: 1 | O36: anuts | P36: 0 | Q36: 0 | R36: 0 | S36: 0 | T36: 0 | U36: 1 | V36: 1 | AK36: hhd-u8 | AL36: 0 | AM36: 0 | AN36: 0 | AO36: 0 | AP36: 0 | AQ36: 0 | AR36: 0 | AS36: 1 | AT36: 1
C37: cbana | D37: 0 | E37: 0 | F37: 0 | G37: 0 | H37: 0 | I37: 0 | J37: 0 | K37: 0 | L37: 1 | O37: abana | P37: 0 | Q37: 0 | R37: 0 | S37: 0 | T37: 0 | U37: 1 | V37: 1 | AK37: hhd-u9 | AL37: 0 | AM37: 0 | AN37: 0 | AO37: 0 | AP37: 0 | AQ37: 0 | AR37: 0 | AS37: 1 | AT37: 1
C38: cfrui | D38: 0 | E38: 0 | F38: 0 | G38: 0 | H38: 0 | I38: 0 | J38: 0 | K38: 0 | L38: 1 | O38: afrui | P38: 0 | Q38: 0 | R38: 0 | S38: 0 | T38: 0 | U38: 1 | V38: 1
C39: cteal | D39: 0 | E39: 0 | F39: 0 | G39: 0 | H39: 0 | I39: 0 | J39: 0 | K39: 0 | L39: 1 | O39: ateal | P39: 0 | Q39: 0 | R39: 0 | S39: 0 | T39: 0 | U39: 1 | V39: 1
C40: ccoff | D40: 0 | E40: 0 | F40: 0 | G40: 0 | H40: 0 | I40: 0 | J40: 0 | K40: 0 | L40: 1 | O40: acoff | P40: 0 | Q40: 0 | R40: 0 | S40: 0 | T40: 0 | U40: 1 | V40: 1
C41: ccoco | D41: 0 | E41: 0 | F41: 0 | G41: 0 | H41: 0 | I41: 0 | J41: 0 | K41: 0 | L41: 1 | O41: acoco | P41: 0 | Q41: 0 | R41: 0 | S41: 0 | T41: 0 | U41: 1 | V41: 1
...

Sheet S2
A1: ="Simulation "&AC1&IF(AD1<>""," : "&AD1,"") -> Simulation sim2 | AC1: =Main!C8 -> sim2 | AD1: =IF(Main!E8<>"",Main!E8,"")
C3: Commodity shocks | O3: Activity shocks | Y3: Factor shocks | AK3: Household and enterprise shocks | AW3: Macro shocks
D4: World prices | F4: Commodity taxes | I4: Transaction costs | L4: Closures | P4: TFP | Q4: Activity taxes | S4: Fixed factors | U4: Closures | Z4: Wage | AA4: Factor | AB4: Product- | AC4: Factor | AD4: Transfers to… | AF4: Transfers from… | AH4: Closures | AL4: Pop. | AM4: Savings | AN4: Direct | AO4: Transfers to… | AQ4: Transfers from… | AS4: Closures | AY4: Start | AZ4: End | BA4: Shock | BB4: Multi-
D5: Exports | E5: Imports | F5: Exports | G5: Imports | H5: Sales | I5: Exports | J5: Imports | K5: Domestic | L5: Taxes | Q5: Activity | R5: VAD | S5: Fix cap. | T5: Fix land | U5: Prod. shk | V5: Taxes | Z5: rate | AA5: supply | AB5: ivity | AC5: taxes | AD5: Gov. | AE5: World | AF5: Gov. | AG5: World | AH5: Taxes | AL5: change | AM5: rate | AN5: tax | AO5: Gov. | AP5: World | AQ5: Gov. | AR5: World | AS5: Savings | AT5: Taxes | BB5: plicative
AW6: Scalar parameter | AY6: start | AZ6: end | BA6: shk | BB6: type
D7: pwe | E7: pwm | F7: te | G7: tm | H7: tq | I7: ice | J7: icm | K7: icd | P7: alphava | Q7: ta | R7: tv | S7: fixcap | T7: fixlnd | Z7: wf | AA7: qfs | AB7: alphaf | AC7: tf | AD7: trtg | AE7: trtw | AF7: trfg | AG7: trfw | AL7: pop | AM7: mps | AN7: ti | AO7: trtg | AP7: trtw | AQ7: trfg | AR7: trfw | AW7: Exchange rate | AX7: exr | AY7: =Notes!$L$4 -> 2024 | AZ7: =Notes!$L$5 -> 2040 | BA7: 0 | BB7: 1
C8: Start | D8: =Notes!$L4 -> 2024 | E8: =Notes!$L4 -> 2024 | F8: =Notes!$L4 -> 2024 | G8: =Notes!$L4 -> 2024 | H8: =Notes!$L4 -> 2024 | I8: =Notes!$L4 -> 2024 | J8: =Notes!$L4 -> 2024 | K8: =Notes!$L4 -> 2024 | O8: Start | P8: =Notes!$L4 -> 2024 | Q8: =Notes!$L4 -> 2024 | R8: =Notes!$L4 -> 2024 | S8: =Notes!$L4 -> 2024 | T8: =Notes!$L4 -> 2024 | Y8: Start | Z8: =Notes!$L4 -> 2024 | AA8: =Notes!$L4 -> 2024 | AB8: =Notes!$L4 -> 2024 | AC8: =Notes!$L4 -> 2024 | AD8: =Notes!$L4 -> 2024 | AE8: =Notes!$L4 -> 2024 | AF8: =Notes!$L4 -> 2024 | AG8: =Notes!$L4 -> 2024 | AK8: Start | AL8: =Notes!$L4 -> 2024 | AM8: =Notes!$L4 -> 2024 | AN8: =Notes!$L4 -> 2024 | AO8: =Notes!$L4 -> 2024 | AP8: =Notes!$L4 -> 2024 | AQ8: =Notes!$L$4 -> 2024 | AR8: =Notes!$L4 -> 2024 | AW8: Foreign savings | AX8: fsav | AY8: =Notes!$L$4 -> 2024 | AZ8: =Notes!$L$5 -> 2040 | BA8: 0 | BB8: 1
C9: End | D9: =Notes!$L5 -> 2040 | E9: =Notes!$L5 -> 2040 | F9: =Notes!$L5 -> 2040 | G9: =Notes!$L5 -> 2040 | H9: =Notes!$L5 -> 2040 | I9: =Notes!$L5 -> 2040 | J9: =Notes!$L5 -> 2040 | K9: =Notes!$L5 -> 2040 | O9: End | P9: =Notes!$L5 -> 2040 | Q9: =Notes!$L5 -> 2040 | R9: =Notes!$L5 -> 2040 | S9: =Notes!$L5 -> 2040 | T9: =Notes!$L5 -> 2040 | Y9: End | Z9: =Notes!$L5 -> 2040 | AA9: =Notes!$L5 -> 2040 | AB9: =Notes!$L5 -> 2040 | AC9: =Notes!$L5 -> 2040 | AD9: =Notes!$L5 -> 2040 | AE9: =Notes!$L5 -> 2040 | AF9: =Notes!$L5 -> 2040 | AG9: =Notes!$L5 -> 2040 | AK9: End | AL9: =Notes!$L5 -> 2040 | AM9: =Notes!$L5 -> 2040 | AN9: =Notes!$L5 -> 2040 | AO9: =Notes!$L5 -> 2040 | AP9: =Notes!$L5 -> 2040 | AQ9: =Notes!$L5 -> 2040 | AR9: =Notes!$L5 -> 2040 | AW9: Investment | AX9: iadj | AY9: =Notes!$L$4 -> 2024 | AZ9: =Notes!$L$5 -> 2040 | BA9: 0 | BB9: 1
AW10: Inv. absorp. share | AX10: invshr | AY10: =Notes!$L$4 -> 2024 | AZ10: =Notes!$L$5 -> 2040 | BA10: 0 | BB10: 1
C11: Multiplicative? (1 = yes | 2 = additive) | O11: Multiplicative? (1 = yes | 2 = additive) | Y11: Multiplicative? (1 = yes | 2 = additive) | AK11: Multiplicative? (1 = yes | 2 = additive) | AW11: Savings rates | AX11: mps | AY11: =Notes!$L$4 -> 2024 | AZ11: =Notes!$L$5 -> 2040 | BA11: 0 | BB11: 1
D12: pwe | E12: pwm | F12: te | G12: tm | H12: tq | I12: ice | J12: icm | K12: icd | P12: alphava | Q12: ta | R12: tv | Z12: wf | AA12: qfs | AB12: alphaf | AC12: tf | AD12: trtg | AE12: trtw | AF12: trfg | AG12: trfw | AL12: pop | AM12: mps | AN12: ti | AO12: trtg | AP12: trtw | AQ12: trfg | AR12: trfw | AW12: Gov. savings | AX12: gsav | AY12: =Notes!$L$4 -> 2024 | AZ12: =Notes!$L$5 -> 2040 | BA12: 0 | BB12: 1
D13: 1 | E13: 1 | F13: 1 | G13: 1 | H13: 1 | I13: 1 | J13: 1 | K13: 1 | P13: 1 | Q13: 1 | R13: 1 | Z13: 1 | AA13: 1 | AB13: 1 | AC13: 1 | AD13: 1 | AE13: 1 | AF13: 1 | AG13: 1 | AL13: 1 | AM13: 1 | AN13: 1 | AO13: 1 | AP13: 1 | AQ13: 1 | AR13: 1 | AW13: Gov. spending | AX13: gadj | AY13: =Notes!$L$4 -> 2024 | AZ13: =Notes!$L$5 -> 2040 | BA13: 0 | BB13: 1
AW14: Gov. absorp. share | AX14: govshr | AY14: =Notes!$L$4 -> 2024 | AZ14: =Notes!$L$5 -> 2040 | BA14: 0 | BB14: 1
C15: Shock | O15: Shock | Y15: Shock | AK15: Shock | AW15: Gov. tran. to world | AX15: trtw | AY15: =Notes!$L$4 -> 2024 | AZ15: =Notes!$L$5 -> 2040 | BA15: 0 | BB15: 1
D16: pwe | E16: pwm | F16: te | G16: tm | H16: tq | I16: ice | J16: icm | K16: icd | L16: tax | P16: alphava | Q16: ta | R16: tv | S16: fixcap | T16: fixlnd | U16: alphaf | V16: tax | Z16: wf | AA16: qfs | AB16: alphaf | AC16: tf | AD16: trtg | AE16: trtw | AF16: trfg | AG16: trfw | AH16: tax | AL16: pop | AM16: mps | AN16: ti | AO16: trtg | AP16: trtw | AQ16: trfg | AR16: trfw | AS16: save | AT16: tax | AW16: Gov. tran. from world | AX16: trfw | AY16: =Notes!$L$4 -> 2024 | AZ16: =Notes!$L$5 -> 2040 | BA16: 0 | BB16: 1
C17: cmaiz | D17: 0 | E17: 0 | F17: 0 | G17: 0 | H17: 0 | I17: 0 | J17: 0 | K17: 0 | L17: 1 | O17: amaiz | P17: 0 | Q17: 0 | R17: 0 | S17: 0 | T17: 0 | U17: 1 | V17: 1 | Y17: flab-rn | Z17: 0 | AA17: 0 | AB17: 0 | AC17: 0 | AD17: 0 | AE17: 0 | AF17: 0 | AG17: 0 | AH17: 1 | AK17: ent | AL17: 0 | AM17: 0 | AN17: 0 | AO17: 0 | AP17: 0 | AQ17: 0 | AR17: 0 | AS17: 1 | AT17: 1 | AW17: Export taxes | AX17: te | AY17: =Notes!$L$4 -> 2024 | AZ17: =Notes!$L$5 -> 2040 | BA17: 0 | BB17: 1
C18: csorg | D18: 0 | E18: 0 | F18: 0 | G18: 0 | H18: 0 | I18: 0 | J18: 0 | K18: 0 | L18: 1 | O18: asorg | P18: 0 | Q18: 0 | R18: 0 | S18: 0 | T18: 0 | U18: 1 | V18: 1 | Y18: flab-rp | Z18: 0 | AA18: 0 | AB18: 0 | AC18: 0 | AD18: 0 | AE18: 0 | AF18: 0 | AG18: 0 | AH18: 1 | AK18: hhd-r0 | AL18: 0 | AM18: 0 | AN18: 0 | AO18: 0 | AP18: 0 | AQ18: 0 | AR18: 0 | AS18: 1 | AT18: 1 | AW18: Import tariffs | AX18: tm | AY18: =Notes!$L$4 -> 2024 | AZ18: =Notes!$L$5 -> 2040 | BA18: 0 | BB18: 1
C19: caman | D19: 0 | E19: 0 | F19: 0 | G19: 0 | H19: 0 | I19: 0 | J19: 0 | K19: 0 | L19: 1 | O19: aaman | P19: 0 | Q19: 0 | R19: 0 | S19: 0 | T19: 0 | U19: 1 | V19: 1 | Y19: flab-rs | Z19: 0 | AA19: 0 | AB19: 0 | AC19: 0 | AD19: 0 | AE19: 0 | AF19: 0 | AG19: 0 | AH19: 1 | AK19: hhd-r1 | AL19: 0 | AM19: 0 | AN19: 0 | AO19: 0 | AP19: 0 | AQ19: 0 | AR19: 0 | AS19: 1 | AT19: 1 | AW19: Sales taxes | AX19: tq | AY19: =Notes!$L$4 -> 2024 | AZ19: =Notes!$L$5 -> 2040 | BA19: 0 | BB19: 1
C20: cboro | D20: 0 | E20: 0 | F20: 0 | G20: 0 | H20: 0 | I20: 0 | J20: 0 | K20: 0 | L20: 1 | O20: aboro | P20: 0 | Q20: 0 | R20: 0 | S20: 0 | T20: 0 | U20: 1 | V20: 1 | Y20: flab-rt | Z20: 0 | AA20: 0 | AB20: 0 | AC20: 0 | AD20: 0 | AE20: 0 | AF20: 0 | AG20: 0 | AH20: 1 | AK20: hhd-r2 | AL20: 0 | AM20: 0 | AN20: 0 | AO20: 0 | AP20: 0 | AQ20: 0 | AR20: 0 | AS20: 1 | AT20: 1 | AW20: Activity taxes | AX20: ta | AY20: =Notes!$L$4 -> 2024 | AZ20: =Notes!$L$5 -> 2040 | BA20: 0 | BB20: 1
C21: cwhea | D21: 0 | E21: 0 | F21: 0 | G21: 0 | H21: 0 | I21: 0 | J21: 0 | K21: 0 | L21: 1 | O21: awhea | P21: 0 | Q21: 0 | R21: 0 | S21: 0 | T21: 0 | U21: 1 | V21: 1 | Y21: flab-un | Z21: 0 | AA21: 0 | AB21: 0 | AC21: 0 | AD21: 0 | AE21: 0 | AF21: 0 | AG21: 0 | AH21: 1 | AK21: hhd-r3 | AL21: 0 | AM21: 0 | AN21: 0 | AO21: 0 | AP21: 0 | AQ21: 0 | AR21: 0 | AS21: 1 | AT21: 1 | AW21: Value-added taxes | AX21: tv | AY21: =Notes!$L$4 -> 2024 | AZ21: =Notes!$L$5 -> 2040 | BA21: 0 | BB21: 1
C22: cocer | D22: 0 | E22: 0 | F22: 0 | G22: 0 | H22: 0 | I22: 0 | J22: 0 | K22: 0 | L22: 1 | O22: aocer | P22: 0 | Q22: 0 | R22: 0 | S22: 0 | T22: 0 | U22: 1 | V22: 1 | Y22: flab-up | Z22: 0 | AA22: 0 | AB22: 0 | AC22: 0 | AD22: 0 | AE22: 0 | AF22: 0 | AG22: 0 | AH22: 1 | AK22: hhd-r4 | AL22: 0 | AM22: 0 | AN22: 0 | AO22: 0 | AP22: 0 | AQ22: 0 | AR22: 0 | AS22: 1 | AT22: 1 | AW22: Factor taxes | AX22: tf | AY22: =Notes!$L$4 -> 2024 | AZ22: =Notes!$L$5 -> 2040 | BA22: 0 | BB22: 1
C23: cpuls | D23: 0 | E23: 0 | F23: 0 | G23: 0 | H23: 0 | I23: 0 | J23: 0 | K23: 0 | L23: 1 | O23: apuls | P23: 0 | Q23: 0 | R23: 0 | S23: 0 | T23: 0 | U23: 1 | V23: 1 | Y23: flab-us | Z23: 0 | AA23: 0 | AB23: 0 | AC23: 0 | AD23: 0 | AE23: 0 | AF23: 0 | AG23: 0 | AH23: 1 | AK23: hhd-r5 | AL23: 0 | AM23: 0 | AN23: 0 | AO23: 0 | AP23: 0 | AQ23: 0 | AR23: 0 | AS23: 1 | AT23: 1 | AW23: Direct taxes | AX23: ti | AY23: =Notes!$L$4 -> 2024 | AZ23: =Notes!$L$5 -> 2040 | BA23: 0 | BB23: 1
C24: cgnut | D24: 0 | E24: 0 | F24: 0 | G24: 0 | H24: 0 | I24: 0 | J24: 0 | K24: 0 | L24: 1 | O24: agnut | P24: 0 | Q24: 0 | R24: 0 | S24: 0 | T24: 0 | U24: 1 | V24: 1 | Y24: flab-ut | Z24: 0 | AA24: 0 | AB24: 0 | AC24: 0 | AD24: 0 | AE24: 0 | AF24: 0 | AG24: 0 | AH24: 1 | AK24: hhd-r6 | AL24: 0 | AM24: 0 | AN24: 0 | AO24: 0 | AP24: 0 | AQ24: 0 | AR24: 0 | AS24: 1 | AT24: 1 | AW24: Depreciation rate | AX24: drate | AY24: =Notes!$L$4 -> 2024 | AZ24: =Notes!$L$5 -> 2040 | BA24: 0 | BB24: 1
C25: coils | D25: 0 | E25: 0 | F25: 0 | G25: 0 | H25: 0 | I25: 0 | J25: 0 | K25: 0 | L25: 1 | O25: aoils | P25: 0 | Q25: 0 | R25: 0 | S25: 0 | T25: 0 | U25: 1 | V25: 1 | Y25: flnd | Z25: 0 | AA25: 0 | AB25: 0 | AC25: 0 | AD25: 0 | AE25: 0 | AF25: 0 | AG25: 0 | AH25: 1 | AK25: hhd-r7 | AL25: 0 | AM25: 0 | AN25: 0 | AO25: 0 | AP25: 0 | AQ25: 0 | AR25: 0 | AS25: 1 | AT25: 1
C26: ccass | D26: 0 | E26: 0 | F26: 0 | G26: 0 | H26: 0 | I26: 0 | J26: 0 | K26: 0 | L26: 1 | O26: acass | P26: 0 | Q26: 0 | R26: 0 | S26: 0 | T26: 0 | U26: 1 | V26: 1 | Y26: fcap-c | Z26: 0 | AA26: 0 | AB26: 0 | AC26: 0 | AD26: 0 | AE26: 0 | AF26: 0 | AG26: 0 | AH26: 1 | AK26: hhd-r8 | AL26: 0 | AM26: 0 | AN26: 0 | AO26: 0 | AP26: 0 | AQ26: 0 | AR26: 0 | AS26: 1 | AT26: 1
C27: cipot | D27: 0 | E27: 0 | F27: 0 | G27: 0 | H27: 0 | I27: 0 | J27: 0 | K27: 0 | L27: 1 | O27: aipot | P27: 0 | Q27: 0 | R27: 0 | S27: 0 | T27: 0 | U27: 1 | V27: 1 | Y27: fcap-l | Z27: 0 | AA27: 0 | AB27: 0 | AC27: 0 | AD27: 0 | AE27: 0 | AF27: 0 | AG27: 0 | AH27: 1 | AK27: hhd-r9 | AL27: 0 | AM27: 0 | AN27: 0 | AO27: 0 | AP27: 0 | AQ27: 0 | AR27: 0 | AS27: 1 | AT27: 1
C28: cspot | D28: 0 | E28: 0 | F28: 0 | G28: 0 | H28: 0 | I28: 0 | J28: 0 | K28: 0 | L28: 1 | O28: aspot | P28: 0 | Q28: 0 | R28: 0 | S28: 0 | T28: 0 | U28: 1 | V28: 1 | Y28: fcap-m | Z28: 0 | AA28: 0 | AB28: 0 | AC28: 0 | AD28: 0 | AE28: 0 | AF28: 0 | AG28: 0 | AH28: 1 | AK28: hhd-u0 | AL28: 0 | AM28: 0 | AN28: 0 | AO28: 0 | AP28: 0 | AQ28: 0 | AR28: 0 | AS28: 1 | AT28: 1
C29: croot | D29: 0 | E29: 0 | F29: 0 | G29: 0 | H29: 0 | I29: 0 | J29: 0 | K29: 0 | L29: 1 | O29: aroot | P29: 0 | Q29: 0 | R29: 0 | S29: 0 | T29: 0 | U29: 1 | V29: 1 | Y29: fcap-n | Z29: 0 | AA29: 0 | AB29: 0 | AC29: 0 | AD29: 0 | AE29: 0 | AF29: 0 | AG29: 0 | AH29: 1 | AK29: hhd-u1 | AL29: 0 | AM29: 0 | AN29: 0 | AO29: 0 | AP29: 0 | AQ29: 0 | AR29: 0 | AS29: 1 | AT29: 1
C30: cleaf | D30: 0 | E30: 0 | F30: 0 | G30: 0 | H30: 0 | I30: 0 | J30: 0 | K30: 0 | L30: 1 | O30: aleaf | P30: 0 | Q30: 0 | R30: 0 | S30: 0 | T30: 0 | U30: 1 | V30: 1 | AK30: hhd-u2 | AL30: 0 | AM30: 0 | AN30: 0 | AO30: 0 | AP30: 0 | AQ30: 0 | AR30: 0 | AS30: 1 | AT30: 1
C31: cvege | D31: 0 | E31: 0 | F31: 0 | G31: 0 | H31: 0 | I31: 0 | J31: 0 | K31: 0 | L31: 1 | O31: avege | P31: 0 | Q31: 0 | R31: 0 | S31: 0 | T31: 0 | U31: 1 | V31: 1 | AK31: hhd-u3 | AL31: 0 | AM31: 0 | AN31: 0 | AO31: 0 | AP31: 0 | AQ31: 0 | AR31: 0 | AS31: 1 | AT31: 1
C32: csugr | D32: 0 | E32: 0 | F32: 0 | G32: 0 | H32: 0 | I32: 0 | J32: 0 | K32: 0 | L32: 1 | O32: asugr | P32: 0 | Q32: 0 | R32: 0 | S32: 0 | T32: 0 | U32: 1 | V32: 1 | AK32: hhd-u4 | AL32: 0 | AM32: 0 | AN32: 0 | AO32: 0 | AP32: 0 | AQ32: 0 | AR32: 0 | AS32: 1 | AT32: 1
C33: ctoba | D33: 0 | E33: 0 | F33: 0 | G33: 0 | H33: 0 | I33: 0 | J33: 0 | K33: 0 | L33: 1 | O33: atoba | P33: 0 | Q33: 0 | R33: 0 | S33: 0 | T33: 0 | U33: 1 | V33: 1 | AK33: hhd-u5 | AL33: 0 | AM33: 0 | AN33: 0 | AO33: 0 | AP33: 0 | AQ33: 0 | AR33: 0 | AS33: 1 | AT33: 1
C34: ccott | D34: 0 | E34: 0 | F34: 0 | G34: 0 | H34: 0 | I34: 0 | J34: 0 | K34: 0 | L34: 1 | O34: acott | P34: 0 | Q34: 0 | R34: 0 | S34: 0 | T34: 0 | U34: 1 | V34: 1 | AK34: hhd-u6 | AL34: 0 | AM34: 0 | AN34: 0 | AO34: 0 | AP34: 0 | AQ34: 0 | AR34: 0 | AS34: 1 | AT34: 1
C35: cjute | D35: 0 | E35: 0 | F35: 0 | G35: 0 | H35: 0 | I35: 0 | J35: 0 | K35: 0 | L35: 1 | O35: ajute | P35: 0 | Q35: 0 | R35: 0 | S35: 0 | T35: 0 | U35: 1 | V35: 1 | AK35: hhd-u7 | AL35: 0 | AM35: 0 | AN35: 0 | AO35: 0 | AP35: 0 | AQ35: 0 | AR35: 0 | AS35: 1 | AT35: 1
C36: cnuts | D36: 0 | E36: 0 | F36: 0 | G36: 0 | H36: 0 | I36: 0 | J36: 0 | K36: 0 | L36: 1 | O36: anuts | P36: 0 | Q36: 0 | R36: 0 | S36: 0 | T36: 0 | U36: 1 | V36: 1 | AK36: hhd-u8 | AL36: 0 | AM36: 0 | AN36: 0 | AO36: 0 | AP36: 0 | AQ36: 0 | AR36: 0 | AS36: 1 | AT36: 1
C37: cbana | D37: 0 | E37: 0 | F37: 0 | G37: 0 | H37: 0 | I37: 0 | J37: 0 | K37: 0 | L37: 1 | O37: abana | P37: 0 | Q37: 0 | R37: 0 | S37: 0 | T37: 0 | U37: 1 | V37: 1 | AK37: hhd-u9 | AL37: 0 | AM37: 0 | AN37: 0 | AO37: 0 | AP37: 0 | AQ37: 0 | AR37: 0 | AS37: 1 | AT37: 1
C38: cfrui | D38: 0 | E38: 0 | F38: 0 | G38: 0 | H38: 0 | I38: 0 | J38: 0 | K38: 0 | L38: 1 | O38: afrui | P38: 0 | Q38: 0 | R38: 0 | S38: 0 | T38: 0 | U38: 1 | V38: 1
C39: cteal | D39: 0 | E39: 0 | F39: 0 | G39: 0 | H39: 0 | I39: 0 | J39: 0 | K39: 0 | L39: 1 | O39: ateal | P39: 0 | Q39: 0 | R39: 0 | S39: 0 | T39: 0 | U39: 1 | V39: 1
C40: ccoff | D40: 0 | E40: 0 | F40: 0 | G40: 0 | H40: 0 | I40: 0 | J40: 0 | K40: 0 | L40: 1 | O40: acoff | P40: 0 | Q40: 0 | R40: 0 | S40: 0 | T40: 0 | U40: 1 | V40: 1
C41: ccoco | D41: 0 | E41: 0 | F41: 0 | G41: 0 | H41: 0 | I41: 0 | J41: 0 | K41: 0 | L41: 1 | O41: acoco | P41: 0 | Q41: 0 | R41: 0 | S41: 0 | T41: 0 | U41: 1 | V41: 1
...

Sheet S3
A1: ="Simulation "&AC1&IF(AD1<>""," : "&AD1,"") -> Simulation sim3 | AC1: =Main!C9 -> sim3 | AD1: =IF(Main!E9<>"",Main!E9,"")
C3: Commodity shocks | O3: Activity shocks | Y3: Factor shocks | AK3: Household and enterprise shocks | AW3: Macro shocks
D4: World prices | F4: Commodity taxes | I4: Transaction costs | L4: Closures | P4: TFP | Q4: Activity taxes | S4: Fixed factors | U4: Closures | Z4: Wage | AA4: Factor | AB4: Product- | AC4: Factor | AD4: Transfers to… | AF4: Transfers from… | AH4: Closures | AL4: Pop. | AM4: Savings | AN4: Direct | AO4: Transfers to… | AQ4: Transfers from… | AS4: Closures | AY4: Start | AZ4: End | BA4: Shock | BB4: Multi-
D5: Exports | E5: Imports | F5: Exports | G5: Imports | H5: Sales | I5: Exports | J5: Imports | K5: Domestic | L5: Taxes | Q5: Activity | R5: VAD | S5: Fix cap. | T5: Fix land | U5: Prod. shk | V5: Taxes | Z5: rate | AA5: supply | AB5: ivity | AC5: taxes | AD5: Gov. | AE5: World | AF5: Gov. | AG5: World | AH5: Taxes | AL5: change | AM5: rate | AN5: tax | AO5: Gov. | AP5: World | AQ5: Gov. | AR5: World | AS5: Savings | AT5: Taxes | BB5: plicative
AW6: Scalar parameter | AY6: start | AZ6: end | BA6: shk | BB6: type
D7: pwe | E7: pwm | F7: te | G7: tm | H7: tq | I7: ice | J7: icm | K7: icd | P7: alphava | Q7: ta | R7: tv | S7: fixcap | T7: fixlnd | Z7: wf | AA7: qfs | AB7: alphaf | AC7: tf | AD7: trtg | AE7: trtw | AF7: trfg | AG7: trfw | AL7: pop | AM7: mps | AN7: ti | AO7: trtg | AP7: trtw | AQ7: trfg | AR7: trfw | AW7: Exchange rate | AX7: exr | AY7: =Notes!$L$4 -> 2024 | AZ7: =Notes!$L$5 -> 2040 | BA7: 0 | BB7: 1
C8: Start | D8: =Notes!$L4 -> 2024 | E8: =Notes!$L4 -> 2024 | F8: =Notes!$L4 -> 2024 | G8: =Notes!$L4 -> 2024 | H8: =Notes!$L4 -> 2024 | I8: =Notes!$L4 -> 2024 | J8: =Notes!$L4 -> 2024 | K8: =Notes!$L4 -> 2024 | O8: Start | P8: =Notes!$L4 -> 2024 | Q8: =Notes!$L4 -> 2024 | R8: =Notes!$L4 -> 2024 | S8: =Notes!$L4 -> 2024 | T8: =Notes!$L4 -> 2024 | Y8: Start | Z8: =Notes!$L4 -> 2024 | AA8: =Notes!$L4 -> 2024 | AB8: =Notes!$L4 -> 2024 | AC8: =Notes!$L4 -> 2024 | AD8: =Notes!$L4 -> 2024 | AE8: =Notes!$L4 -> 2024 | AF8: =Notes!$L4 -> 2024 | AG8: =Notes!$L4 -> 2024 | AK8: Start | AL8: =Notes!$L4 -> 2024 | AM8: =Notes!$L4 -> 2024 | AN8: =Notes!$L4 -> 2024 | AO8: =Notes!$L4 -> 2024 | AP8: =Notes!$L4 -> 2024 | AQ8: =Notes!$L$4 -> 2024 | AR8: =Notes!$L4 -> 2024 | AW8: Foreign savings | AX8: fsav | AY8: =Notes!$L$4 -> 2024 | AZ8: =Notes!$L$5 -> 2040 | BA8: 0 | BB8: 1
C9: End | D9: =Notes!$L5 -> 2040 | E9: =Notes!$L5 -> 2040 | F9: =Notes!$L5 -> 2040 | G9: =Notes!$L5 -> 2040 | H9: =Notes!$L5 -> 2040 | I9: =Notes!$L5 -> 2040 | J9: =Notes!$L5 -> 2040 | K9: =Notes!$L5 -> 2040 | O9: End | P9: =Notes!$L5 -> 2040 | Q9: =Notes!$L5 -> 2040 | R9: =Notes!$L5 -> 2040 | S9: =Notes!$L5 -> 2040 | T9: =Notes!$L5 -> 2040 | Y9: End | Z9: =Notes!$L5 -> 2040 | AA9: =Notes!$L5 -> 2040 | AB9: =Notes!$L5 -> 2040 | AC9: =Notes!$L5 -> 2040 | AD9: =Notes!$L5 -> 2040 | AE9: =Notes!$L5 -> 2040 | AF9: =Notes!$L5 -> 2040 | AG9: =Notes!$L5 -> 2040 | AK9: End | AL9: =Notes!$L5 -> 2040 | AM9: =Notes!$L5 -> 2040 | AN9: =Notes!$L5 -> 2040 | AO9: =Notes!$L5 -> 2040 | AP9: =Notes!$L5 -> 2040 | AQ9: =Notes!$L5 -> 2040 | AR9: =Notes!$L5 -> 2040 | AW9: Investment | AX9: iadj | AY9: =Notes!$L$4 -> 2024 | AZ9: =Notes!$L$5 -> 2040 | BA9: 0 | BB9: 1
AW10: Inv. absorp. share | AX10: invshr | AY10: =Notes!$L$4 -> 2024 | AZ10: =Notes!$L$5 -> 2040 | BA10: 0 | BB10: 1
C11: Multiplicative? (1 = yes | 2 = additive) | O11: Multiplicative? (1 = yes | 2 = additive) | Y11: Multiplicative? (1 = yes | 2 = additive) | AK11: Multiplicative? (1 = yes | 2 = additive) | AW11: Savings rates | AX11: mps | AY11: =Notes!$L$4 -> 2024 | AZ11: =Notes!$L$5 -> 2040 | BA11: 0 | BB11: 1
D12: pwe | E12: pwm | F12: te | G12: tm | H12: tq | I12: ice | J12: icm | K12: icd | P12: alphava | Q12: ta | R12: tv | Z12: wf | AA12: qfs | AB12: alphaf | AC12: tf | AD12: trtg | AE12: trtw | AF12: trfg | AG12: trfw | AL12: pop | AM12: mps | AN12: ti | AO12: trtg | AP12: trtw | AQ12: trfg | AR12: trfw | AW12: Gov. savings | AX12: gsav | AY12: =Notes!$L$4 -> 2024 | AZ12: =Notes!$L$5 -> 2040 | BA12: 0 | BB12: 1
D13: 1 | E13: 1 | F13: 1 | G13: 1 | H13: 1 | I13: 1 | J13: 1 | K13: 1 | P13: 1 | Q13: 1 | R13: 1 | Z13: 1 | AA13: 1 | AB13: 1 | AC13: 1 | AD13: 1 | AE13: 1 | AF13: 1 | AG13: 1 | AL13: 1 | AM13: 1 | AN13: 1 | AO13: 1 | AP13: 1 | AQ13: 1 | AR13: 1 | AW13: Gov. spending | AX13: gadj | AY13: =Notes!$L$4 -> 2024 | AZ13: =Notes!$L$5 -> 2040 | BA13: 0 | BB13: 1
AW14: Gov. absorp. share | AX14: govshr | AY14: =Notes!$L$4 -> 2024 | AZ14: =Notes!$L$5 -> 2040 | BA14: 0 | BB14: 1
C15: Shock | O15: Shock | Y15: Shock | AK15: Shock | AW15: Gov. tran. to world | AX15: trtw | AY15: =Notes!$L$4 -> 2024 | AZ15: =Notes!$L$5 -> 2040 | BA15: 0 | BB15: 1
D16: pwe | E16: pwm | F16: te | G16: tm | H16: tq | I16: ice | J16: icm | K16: icd | L16: tax | P16: alphava | Q16: ta | R16: tv | S16: fixcap | T16: fixlnd | U16: alphaf | V16: tax | Z16: wf | AA16: qfs | AB16: alphaf | AC16: tf | AD16: trtg | AE16: trtw | AF16: trfg | AG16: trfw | AH16: tax | AL16: pop | AM16: mps | AN16: ti | AO16: trtg | AP16: trtw | AQ16: trfg | AR16: trfw | AS16: save | AT16: tax | AW16: Gov. tran. from world | AX16: trfw | AY16: =Notes!$L$4 -> 2024 | AZ16: =Notes!$L$5 -> 2040 | BA16: 0 | BB16: 1
C17: cmaiz | D17: 0 | E17: 0 | F17: 0 | G17: 0 | H17: 0 | I17: 0 | J17: 0 | K17: 0 | L17: 1 | O17: amaiz | P17: 0 | Q17: 0 | R17: 0 | S17: 0 | T17: 0 | U17: 1 | V17: 1 | Y17: flab-rn | Z17: 0 | AA17: 0 | AB17: 0 | AC17: 0 | AD17: 0 | AE17: 0 | AF17: 0 | AG17: 0 | AH17: 1 | AK17: ent | AL17: 0 | AM17: 0 | AN17: 0 | AO17: 0 | AP17: 0 | AQ17: 0 | AR17: 0 | AS17: 1 | AT17: 1 | AW17: Export taxes | AX17: te | AY17: =Notes!$L$4 -> 2024 | AZ17: =Notes!$L$5 -> 2040 | BA17: 0 | BB17: 1
C18: csorg | D18: 0 | E18: 0 | F18: 0 | G18: 0 | H18: 0 | I18: 0 | J18: 0 | K18: 0 | L18: 1 | O18: asorg | P18: 0 | Q18: 0 | R18: 0 | S18: 0 | T18: 0 | U18: 1 | V18: 1 | Y18: flab-rp | Z18: 0 | AA18: 0 | AB18: 0 | AC18: 0 | AD18: 0 | AE18: 0 | AF18: 0 | AG18: 0 | AH18: 1 | AK18: hhd-r0 | AL18: 0 | AM18: 0 | AN18: 0 | AO18: 0 | AP18: 0 | AQ18: 0 | AR18: 0 | AS18: 1 | AT18: 1 | AW18: Import tariffs | AX18: tm | AY18: =Notes!$L$4 -> 2024 | AZ18: =Notes!$L$5 -> 2040 | BA18: 0 | BB18: 1
C19: caman | D19: 0 | E19: 0 | F19: 0 | G19: 0 | H19: 0 | I19: 0 | J19: 0 | K19: 0 | L19: 1 | O19: aaman | P19: 0 | Q19: 0 | R19: 0 | S19: 0 | T19: 0 | U19: 1 | V19: 1 | Y19: flab-rs | Z19: 0 | AA19: 0 | AB19: 0 | AC19: 0 | AD19: 0 | AE19: 0 | AF19: 0 | AG19: 0 | AH19: 1 | AK19: hhd-r1 | AL19: 0 | AM19: 0 | AN19: 0 | AO19: 0 | AP19: 0 | AQ19: 0 | AR19: 0 | AS19: 1 | AT19: 1 | AW19: Sales taxes | AX19: tq | AY19: =Notes!$L$4 -> 2024 | AZ19: =Notes!$L$5 -> 2040 | BA19: 0 | BB19: 1
C20: cboro | D20: 0 | E20: 0 | F20: 0 | G20: 0 | H20: 0 | I20: 0 | J20: 0 | K20: 0 | L20: 1 | O20: aboro | P20: 0 | Q20: 0 | R20: 0 | S20: 0 | T20: 0 | U20: 1 | V20: 1 | Y20: flab-rt | Z20: 0 | AA20: 0 | AB20: 0 | AC20: 0 | AD20: 0 | AE20: 0 | AF20: 0 | AG20: 0 | AH20: 1 | AK20: hhd-r2 | AL20: 0 | AM20: 0 | AN20: 0 | AO20: 0 | AP20: 0 | AQ20: 0 | AR20: 0 | AS20: 1 | AT20: 1 | AW20: Activity taxes | AX20: ta | AY20: =Notes!$L$4 -> 2024 | AZ20: =Notes!$L$5 -> 2040 | BA20: 0 | BB20: 1
C21: cwhea | D21: 0 | E21: 0 | F21: 0 | G21: 0 | H21: 0 | I21: 0 | J21: 0 | K21: 0 | L21: 1 | O21: awhea | P21: 0 | Q21: 0 | R21: 0 | S21: 0 | T21: 0 | U21: 1 | V21: 1 | Y21: flab-un | Z21: 0 | AA21: 0 | AB21: 0 | AC21: 0 | AD21: 0 | AE21: 0 | AF21: 0 | AG21: 0 | AH21: 1 | AK21: hhd-r3 | AL21: 0 | AM21: 0 | AN21: 0 | AO21: 0 | AP21: 0 | AQ21: 0 | AR21: 0 | AS21: 1 | AT21: 1 | AW21: Value-added taxes | AX21: tv | AY21: =Notes!$L$4 -> 2024 | AZ21: =Notes!$L$5 -> 2040 | BA21: 0 | BB21: 1
C22: cocer | D22: 0 | E22: 0 | F22: 0 | G22: 0 | H22: 0 | I22: 0 | J22: 0 | K22: 0 | L22: 1 | O22: aocer | P22: 0 | Q22: 0 | R22: 0 | S22: 0 | T22: 0 | U22: 1 | V22: 1 | Y22: flab-up | Z22: 0 | AA22: 0 | AB22: 0 | AC22: 0 | AD22: 0 | AE22: 0 | AF22: 0 | AG22: 0 | AH22: 1 | AK22: hhd-r4 | AL22: 0 | AM22: 0 | AN22: 0 | AO22: 0 | AP22: 0 | AQ22: 0 | AR22: 0 | AS22: 1 | AT22: 1 | AW22: Factor taxes | AX22: tf | AY22: =Notes!$L$4 -> 2024 | AZ22: =Notes!$L$5 -> 2040 | BA22: 0 | BB22: 1
C23: cpuls | D23: 0 | E23: 0 | F23: 0 | G23: 0 | H23: 0 | I23: 0 | J23: 0 | K23: 0 | L23: 1 | O23: apuls | P23: 0 | Q23: 0 | R23: 0 | S23: 0 | T23: 0 | U23: 1 | V23: 1 | Y23: flab-us | Z23: 0 | AA23: 0 | AB23: 0 | AC23: 0 | AD23: 0 | AE23: 0 | AF23: 0 | AG23: 0 | AH23: 1 | AK23: hhd-r5 | AL23: 0 | AM23: 0 | AN23: 0 | AO23: 0 | AP23: 0 | AQ23: 0 | AR23: 0 | AS23: 1 | AT23: 1 | AW23: Direct taxes | AX23: ti | AY23: =Notes!$L$4 -> 2024 | AZ23: =Notes!$L$5 -> 2040 | BA23: 0 | BB23: 1
C24: cgnut | D24: 0 | E24: 0 | F24: 0 | G24: 0 | H24: 0 | I24: 0 | J24: 0 | K24: 0 | L24: 1 | O24: agnut | P24: 0 | Q24: 0 | R24: 0 | S24: 0 | T24: 0 | U24: 1 | V24: 1 | Y24: flab-ut | Z24: 0 | AA24: 0 | AB24: 0 | AC24: 0 | AD24: 0 | AE24: 0 | AF24: 0 | AG24: 0 | AH24: 1 | AK24: hhd-r6 | AL24: 0 | AM24: 0 | AN24: 0 | AO24: 0 | AP24: 0 | AQ24: 0 | AR24: 0 | AS24: 1 | AT24: 1 | AW24: Depreciation rate | AX24: drate | AY24: =Notes!$L$4 -> 2024 | AZ24: =Notes!$L$5 -> 2040 | BA24: 0 | BB24: 1
