Workbook

Sheet Notes
A1: =CONCATENATE(B4," ",B3," Standard Excel Interface Model") -> 2017 Rwanda Standard Excel Interface Model
A3: Country | B3: Rwanda
A4: Year | B4: 2017
A5: Units | B5: Billions of Rwanda Francs
A7: Activities and commodities | E7: Factors | H7: Households | K7: Other accounts
A8: asorg | B8: csorg | C8: Sorghum (A111) | E8: flab-rn | F8: Labor - rural uneducated | H8: hhd-f1 | I8: Rural - farm q1 | K8: trc | L8: Transaction costs
A9: amaiz | B9: cmaiz | C9: Maize (A112) | E9: flab-rp | F9: Labor - rural primary | H9: hhd-f2 | I9: Rural - farm q2 | K9: flab | L9: Labor
A10: awhea | B10: cwhea | C10: Wheat (A113) | E10: flab-rs | F10: Labor - rural secondary | H10: hhd-f3 | I10: Rural - farm q3 | K10: flnd | L10: Land
A11: arice | B11: crice | C11: Paddy & husked rice (A116) | E11: flab-rt | F11: Labor - rural tertiary | H11: hhd-f4 | I11: Rural - farm q4 | K11: fcap | L11: Capital
A12: aocer | B12: cocer | C12: Other cereals (A119) | E12: flab-un | F12: Labor - urban uneducated | H12: hhd-f5 | I12: Rural - farm q5 | K12: ent | L12: Enterprises
A13: aipot | B13: cipot | C13: Irish potatoes (A121) | E13: flab-up | F13: Labor - urban primary | H13: hhd-n1 | I13: Rural - nonfarm q1 | K13: hhd | L13: Households
A14: aspot | B14: cspot | C14: Sweet potatoes (A122) | E14: flab-us | F14: Labor - urban secondary | H14: hhd-n2 | I14: Rural - nonfarm q2 | K14: gov | L14: Government
A15: acass | B15: ccass | C15: Cassava (A123) | E15: flab-ut | F15: Labor - urban tertiary | H15: hhd-n3 | I15: Rural - nonfarm q3 | K15: atax | L15: Taxes - activity (production)
A16: aroot | B16: croot | C16: Other roots & tubers (A129) | E16: flab-kn | F16: Labor - Kigali uneducated | H16: hhd-n4 | I16: Rural - nonfarm q4 | K16: ctax | L16: Taxes - customs duties (imports)
A17: abean | B17: cbean | C17: Dried beans (A131) | E17: flab-kp | F17: Labor - Kigali primary | H17: hhd-n5 | I17: Rural - nonfarm q5 | K17: dtax | L17: Taxes - direct (corporate, private)
A18: apeas | B18: cpeas | C18: Peas & other legumes (A132) | E18: flab-ks | F18: Labor - Kigali secondary | H18: hhd-u1 | I18: Urban - q1 | K18: etax | L18: Taxes - exports
A19: avege | B19: cvege | C19: Other vegetables (A139) | E19: flab-kt | F19: Labor - Kigali tertiary | H19: hhd-u2 | I19: Urban - q2 | K19: ftax | L19: Taxes - factors (royalities)
... A24: agnut | B24: cgnut | C24: Ground nuts (A151) | E24: fcap-n | F24: Capital - non-primary | H24: hhd-k2 | I24: Kigali - q2 | K24: s-i | L24: Savings-investment
A25: asoya | B25: csoya | C25: Soya (A152) | H25: hhd-k3 | I25: Kigali - q3 | K25: dstk | L25: Change in stocks
A26: aoils | B26: coils | C26: Other oil seeds (A159) | H26: hhd-k4 | I26: Kigali - q4 | K26: row | L26: Rest of world
A27: acoff | B27: ccoff | C27: Coffee, not roasted, not decaffeinated (A210) | H27: hhd-k5 | I27: Kigali - q5 | K27: total | L27: Total
A28: ateal | B28: cteal | C28: Tea (unprocessed green leaf) (A220)
A29: atoba | B29: ctoba | C29: Tobacco, raw (A291)
A30: asugr | B30: csugr | C30: Sugar cane (A292)
A31: apyre | B31: cpyre | C31: Pyrethrum (A293)
A32: aocrp | B32: cocrp | C32: Agricultural products n.e.c. (A299)
A33: acatt | B33: ccatt | C33: Bovine cattle, live (A311)
A34: asmlr | B34: csmlr | C34: Sheep, goats, pigs,live (A312)
A35: apoul | B35: cpoul | C35: Poultry, live (A313)
A36: aoliv | B36: coliv | C36: Other live animals (A319)
A37: amilk | B37: cmilk | C37: Raw milk (A321)
A38: aeggs | B38: ceggs | C38: Eggs (A322)
A39: ahony | B39: chony | C39: Natural honey (A323)
... A111: atrdc | B111: ctrdc | C111: Travel debits & credits (V00)

Sheet Main
A1: Activate Simulations and Select Closures
A3: Activate simulations | F3: Macroeconomic closures
A4: Active? (0=no; 1=yes) | G4: {=TRANSPOSE(A6:A14)} -> Chem_wp_shk | H4: Food_shk | I4: Fuel&gas_shk | J4: HH shk | K4: sim5 | L4: sim6 | M4: sim7 | N4: sim8 | O4: sim9
A5: base | B5: 1 | C5: Base scenario | F5: Numeraire | G5: 2 | H5: 2 | I5: 2 | J5: 2 | K5: 2 | L5: 2 | M5: 2 | N5: 2 | O5: 2
A6: Chem_wp_shk | B6: 0 | C6: 50%_incr_cchem | F6: Savings-investment | G6: 3 | H6: 3 | I6: 3 | J6: 3 | K6: 3 | L6: 3 | M6: 3 | N6: 3 | O6: 3
A7: Food_shk | B7: 0 | C7: 50 % Incr_pwm_cereal&ed.oil | F7: Government account | G7: 1 | H7: 1 | I7: 1 | J7: 1 | K7: 1 | L7: 1 | M7: 1 | N7: 1 | O7: 1
A8: Fuel&gas_shk | B8: 0 | C8: Incr_pmw_oil | F8: Current account | G8: 1 | H8: 1 | I8: 1 | J8: 1 | K8: 1 | L8: 1 | M8: 1 | N8: 1 | O8: 1
A9: HH shk
A10: sim5 | F10: Factor market closures
A11: sim6 | G11: {=TRANSPOSE(A6:A14)} -> Chem_wp_shk | H11: Food_shk | I11: Fuel&gas_shk | J11: HH shk | K11: sim5 | L11: sim6 | M11: sim7 | N11: sim8 | O11: sim9
A12: sim7 | F12: Labor - rural uneducated | G12: 1 | H12: 3 | I12: 3 | J12: 1 | K12: 1 | L12: 1 | M12: 1 | N12: 1 | O12: 1
A13: sim8 | F13: Labor - rural primary | G13: 1 | H13: 3 | I13: 3 | J13: 1 | K13: 1 | L13: 1 | M13: 1 | N13: 1 | O13: 1
A14: sim9 | F14: Labor - rural secondary | G14: 1 | H14: 1 | I14: 1 | J14: 3 | K14: 1 | L14: 1 | M14: 1 | N14: 1 | O14: 1
F15: Labor - rural tertiary | G15: 1 | H15: 1 | I15: 1 | J15: 3 | K15: 1 | L15: 1 | M15: 1 | N15: 1 | O15: 1
F16: Labor - urban uneducated | G16: 1 | H16: 3 | I16: 3 | J16: 1 | K16: 3 | L16: 1 | M16: 1 | N16: 1 | O16: 1
F17: Labor - urban primary | G17: 1 | H17: 3 | I17: 3 | J17: 1 | K17: 3 | L17: 1 | M17: 1 | N17: 1 | O17: 1
F18: Labor - urban secondary | G18: 1 | H18: 1 | I18: 1 | J18: 3 | K18: 1 | L18: 1 | M18: 1 | N18: 1 | O18: 1
F19: Labor - urban tertiary | G19: 1 | H19: 1 | I19: 1 | J19: 3 | K19: 1 | L19: 1 | M19: 1 | N19: 1 | O19: 1
F20: Labor - Kigali uneducated | G20: 1 | H20: 3 | I20: 3 | J20: 1 | K20: 1 | L20: 1 | M20: 1 | N20: 1 | O20: 1
F21: Labor - Kigali primary | G21: 1 | H21: 3 | I21: 3 | J21: 1 | K21: 3 | L21: 1 | M21: 1 | N21: 1 | O21: 1
F22: Labor - Kigali secondary | G22: 1 | H22: 1 | I22: 1 | J22: 3 | K22: 3 | L22: 1 | M22: 1 | N22: 1 | O22: 1
F23: Labor - Kigali tertiary | G23: 1 | H23: 1 | I23: 1 | J23: 3 | K23: 1 | L23: 1 | M23: 1 | N23: 1 | O23: 1
F24: Crop land | G24: 1 | H24: 1 | I24: 1 | J24: 1 | K24: 1 | L24: 1 | M24: 1 | N24: 1 | O24: 1
F25: Capital - crops | G25: 2 | H25: 2 | I25: 2 | J25: 2 | K25: 2 | L25: 2 | M25: 2 | N25: 2 | O25: 2
F26: Capital - livestock | G26: 2 | H26: 2 | I26: 2 | J26: 2 | K26: 2 | L26: 2 | M26: 2 | N26: 2 | O26: 2
... F28: Capital - non-primary | G28: 2 | H28: 2 | I28: 2 | J28: 2 | K28: 2 | L28: 2 | M28: 2 | N28: 2 | O28: 2
A32: Numeraire
A33: 1 | B33: CPI is numeraire (and fixed) -- DPI is flexible
A34: 2 | B34: DPI is numeraire (and fixed) -- CPI is flexible
A36: Factor closure options
A37: 1 | B37: fully employed and mobile
A38: 2 | B38: fully employed and activity-specific
A39: 3 | B39: unemployed and mobile
A41: Savings-investment closure options
A42: 1 | B42: investment-driven savings -- uniform mps rate point change for selected institutions
A43: 2 | B43: investment-driven savings -- scaled mps for for selected institutions
A44: 3 | B44: investment is savings-driven
A45: 4 | B45: investment is fixed absolute share - uniform mps rate point change - balanced closure
A46: 5 | B46: investment is fixed abs share - scaled mps - balanced closure
A48: Current account closure options
...

Sheet S1
A1: ="Simulation "&Y1&IF(X1<>""," : "&X1,"") -> Simulation Chem_wp_shk : 50%_incr_cchem | X1: =IF(Main!C6<>"",Main!C6,"") -> 50%_incr_cchem | Y1: =Main!A6 -> Chem_wp_shk
A3: Commodity shocks | N3: Activity shocks | V3: Factor shocks
B4: World prices | D4: Commodity taxes | G4: Transaction costs | J4: Import | O4: Fix cap? | P4: TFP | Q4: Activity taxes | W4: Factor | X4: Wage | Y4: Factor
B5: Exports | C5: Imports | D5: Exports | E5: Imports | F5: Sales | G5: Exports | H5: Imports | I5: Domestic | J5: subsidy | O5: (1=yes) | Q5: Activity | R5: ValAd. | W5: taxes | X5: rate | Y5: supply
B6: pwe | C6: pwm | D6: te | E6: tm | F6: tq | G6: ice | H6: icm | I6: icd | J6: tms | O6: fixcap | P6: alphava | Q6: ta | R6: tva | W6: tf | X6: wf | Y6: qfs
A7: csorg | B7: eps | C7: eps | D7: eps | E7: eps | F7: eps | G7: eps | H7: eps | I7: eps | J7: eps | N7: asorg | O7: 0 | P7: eps | Q7: eps | R7: eps | V7: flab-rn | W7: eps | X7: eps | Y7: eps
A8: cmaiz | B8: eps | C8: eps | D8: eps | E8: eps | F8: eps | G8: eps | H8: eps | I8: eps | J8: eps | N8: amaiz | O8: 0 | P8: eps | Q8: eps | R8: eps | V8: flab-rp | W8: eps | X8: eps | Y8: eps
A9: cwhea | B9: eps | C9: eps | D9: eps | E9: eps | F9: eps | G9: eps | H9: eps | I9: eps | J9: eps | N9: awhea | O9: 0 | P9: eps | Q9: eps | R9: eps | V9: flab-rs | W9: eps | X9: eps | Y9: eps
A10: crice | B10: eps | C10: eps | D10: eps | E10: eps | F10: eps | G10: eps | H10: eps | I10: eps | J10: eps | N10: arice | O10: 0 | P10: eps | Q10: eps | R10: eps | V10: flab-rt | W10: eps | X10: eps | Y10: eps
A11: cocer | B11: eps | C11: eps | D11: eps | E11: eps | F11: eps | G11: eps | H11: eps | I11: eps | J11: eps | N11: aocer | O11: 0 | P11: eps | Q11: eps | R11: eps | V11: flab-un | W11: eps | X11: eps | Y11: eps
A12: cipot | B12: eps | C12: eps | D12: eps | E12: eps | F12: eps | G12: eps | H12: eps | I12: eps | J12: eps | N12: aipot | O12: 0 | P12: eps | Q12: eps | R12: eps | V12: flab-up | W12: eps | X12: eps | Y12: eps
A13: cspot | B13: eps | C13: eps | D13: eps | E13: eps | F13: eps | G13: eps | H13: eps | I13: eps | J13: eps | N13: aspot | O13: 0 | P13: eps | Q13: eps | R13: eps | V13: flab-us | W13: eps | X13: eps | Y13: eps
A14: ccass | B14: eps | C14: eps | D14: eps | E14: eps | F14: eps | G14: eps | H14: eps | I14: eps | J14: eps | N14: acass | O14: 0 | P14: eps | Q14: eps | R14: eps | V14: flab-ut | W14: eps | X14: eps | Y14: eps
A15: croot | B15: eps | C15: eps | D15: eps | E15: eps | F15: eps | G15: eps | H15: eps | I15: eps | J15: eps | N15: aroot | O15: 0 | P15: eps | Q15: eps | R15: eps | V15: flab-kn | W15: eps | X15: eps | Y15: eps
A16: cbean | B16: eps | C16: eps | D16: eps | E16: eps | F16: eps | G16: eps | H16: eps | I16: eps | J16: eps | N16: abean | O16: 0 | P16: eps | Q16: eps | R16: eps | V16: flab-kp | W16: eps | X16: eps | Y16: eps
A17: cpeas | B17: eps | C17: eps | D17: eps | E17: eps | F17: eps | G17: eps | H17: eps | I17: eps | J17: eps | N17: apeas | O17: 0 | P17: eps | Q17: eps | R17: eps | V17: flab-ks | W17: eps | X17: eps | Y17: eps
A18: cvege | B18: eps | C18: eps | D18: eps | E18: eps | F18: eps | G18: eps | H18: eps | I18: eps | J18: eps | N18: avege | O18: 0 | P18: eps | Q18: eps | R18: eps | V18: flab-kt | W18: eps | X18: eps | Y18: eps
... A23: cgnut | B23: eps | C23: eps | D23: eps | E23: eps | F23: eps | G23: eps | H23: eps | I23: eps | J23: eps | N23: agnut | O23: 0 | P23: eps | Q23: eps | R23: eps | V23: fcap-n | W23: eps | X23: eps | Y23: eps
A24: csoya | B24: eps | C24: eps | D24: eps | E24: eps | F24: eps | G24: eps | H24: eps | I24: eps | J24: eps | N24: asoya | O24: 0 | P24: eps | Q24: eps | R24: eps
A25: coils | B25: eps | C25: eps | D25: eps | E25: eps | F25: eps | G25: eps | H25: eps | I25: eps | J25: eps | N25: aoils | O25: 0 | P25: eps | Q25: eps | R25: eps | V25: Household income shocks
A26: ccoff | B26: eps | C26: eps | D26: eps | E26: eps | F26: eps | G26: eps | H26: eps | I26: eps | J26: eps | N26: acoff | O26: 0 | P26: eps | Q26: eps | R26: eps | X26: Gov. | Y26: World
A27: cteal | B27: eps | C27: eps | D27: eps | E27: eps | F27: eps | G27: eps | H27: eps | I27: eps | J27: eps | N27: ateal | O27: 0 | P27: eps | Q27: eps | R27: eps | X27: trn | Y27: rem
A28: ctoba | B28: eps | C28: eps | D28: eps | E28: eps | F28: eps | G28: eps | H28: eps | I28: eps | J28: eps | N28: atoba | O28: 0 | P28: eps | Q28: eps | R28: eps | V28: Farm | W28: hhd-r1 | X28: eps | Y28: eps
A29: csugr | B29: eps | C29: eps | D29: eps | E29: eps | F29: eps | G29: eps | H29: eps | I29: eps | J29: eps | N29: asugr | O29: 0 | P29: eps | Q29: eps | R29: eps | W29: hhd-r2 | X29: eps | Y29: eps
A30: cpyre | B30: eps | C30: eps | D30: eps | E30: eps | F30: eps | G30: eps | H30: eps | I30: eps | J30: eps | N30: apyre | O30: 0 | P30: eps | Q30: eps | R30: eps | W30: hhd-r3 | X30: eps | Y30: eps
A31: cocrp | B31: eps | C31: eps | D31: eps | E31: eps | F31: eps | G31: eps | H31: eps | I31: eps | J31: eps | N31: aocrp | O31: 0 | P31: eps | Q31: eps | R31: eps | W31: hhd-r4 | X31: eps | Y31: eps
A32: ccatt | B32: eps | C32: eps | D32: eps | E32: eps | F32: eps | G32: eps | H32: eps | I32: eps | J32: eps | N32: acatt | O32: 0 | P32: eps | Q32: eps | R32: eps | W32: hhd-r5 | X32: eps | Y32: eps
A33: csmlr | B33: eps | C33: eps | D33: eps | E33: eps | F33: eps | G33: eps | H33: eps | I33: eps | J33: eps | N33: asmlr | O33: 0 | P33: eps | Q33: eps | R33: eps | V33: Nonfarm | W33: hhd-u1 | X33: eps | Y33: eps
A34: cpoul | B34: eps | C34: eps | D34: eps | E34: eps | F34: eps | G34: eps | H34: eps | I34: eps | J34: eps | N34: apoul | O34: 0 | P34: eps | Q34: eps | R34: eps | W34: hhd-u2 | X34: eps | Y34: eps
A35: coliv | B35: eps | C35: eps | D35: eps | E35: eps | F35: eps | G35: eps | H35: eps | I35: eps | J35: eps | N35: aoliv | O35: 0 | P35: eps | Q35: eps | R35: eps | W35: hhd-u3 | X35: eps | Y35: eps
A36: cmilk | B36: eps | C36: eps | D36: eps | E36: eps | F36: eps | G36: eps | H36: eps | I36: eps | J36: eps | N36: amilk | O36: 0 | P36: eps | Q36: eps | R36: eps | W36: hhd-u4 | X36: eps | Y36: eps
A37: ceggs | B37: eps | C37: eps | D37: eps | E37: eps | F37: eps | G37: eps | H37: eps | I37: eps | J37: eps | N37: aeggs | O37: 0 | P37: eps | Q37: eps | R37: eps | W37: hhd-u5 | X37: eps | Y37: eps
A38: chony | B38: eps | C38: eps | D38: eps | E38: eps | F38: eps | G38: eps | H38: eps | I38: eps | J38: eps | N38: ahony | O38: 0 | P38: eps | Q38: eps | R38: eps | V38: Urban | W38: hhd-k1 | X38: eps | Y38: eps
A39: chunt | B39: eps | C39: eps | D39: eps | E39: eps | F39: eps | G39: eps | H39: eps | I39: eps | J39: eps | N39: ahunt | O39: 0 | P39: eps | Q39: eps | R39: eps | W39: hhd-k2 | X39: eps | Y39: eps
A40: cfuel | B40: eps | C40: eps | D40: eps | E40: eps | F40: eps | G40: eps | H40: eps | I40: eps | J40: eps | N40: afuel | O40: 0 | P40: eps | Q40: eps | R40: eps | W40: hhd-k3 | X40: eps | Y40: eps
A41: cchar | B41: eps | C41: eps | D41: eps | E41: eps | F41: eps | G41: eps | H41: eps | I41: eps | J41: eps | N41: achar | O41: 0 | P41: eps | Q41: eps | R41: eps | W41: hhd-k4 | X41: eps | Y41: eps
A42: cfore | B42: eps | C42: eps | D42: eps | E42: eps | F42: eps | G42: eps | H42: eps | I42: eps | J42: eps | N42: afore | O42: 0 | P42: eps | Q42: eps | R42: eps | W42: hhd-k5 | X42: eps | Y42: eps
A43: cfish | B43: eps | C43: eps | D43: eps | E43: eps | F43: eps | G43: eps | H43: eps | I43: eps | J43: eps | N43: afish | O43: 0 | P43: eps | Q43: eps | R43: eps
A44: cngas | B44: eps | C44: eps | D44: eps | E44: eps | F44: eps | G44: eps | H44: eps | I44: eps | J44: eps | N44: angas | O44: 0 | P44: eps | Q44: eps | R44: eps | V44: Scalar shocks
A45: cmore | B45: eps | C45: eps | D45: eps | E45: eps | F45: eps | G45: eps | H45: eps | I45: eps | J45: eps | N45: amore | O45: 0 | P45: eps | Q45: eps | R45: eps
...

Sheet S2
A1: ="Simulation "&Y1&IF(X1<>""," : "&X1,"") -> Simulation Food_shk : 50%_incr_cchem | X1: =IF(Main!C6<>"",Main!C6,"") -> 50%_incr_cchem | Y1: =Main!A7 -> Food_shk
A3: Commodity shocks | N3: Activity shocks | V3: Factor shocks
B4: World prices | D4: Commodity taxes | G4: Transaction costs | J4: Import | O4: Fix cap? | P4: TFP | Q4: Activity taxes | W4: Factor | X4: Wage | Y4: Factor
B5: Exports | C5: Imports | D5: Exports | E5: Imports | F5: Sales | G5: Exports | H5: Imports | I5: Domestic | J5: subsidy | O5: (1=yes) | Q5: Activity | R5: ValAd. | W5: taxes | X5: rate | Y5: supply
B6: pwe | C6: pwm | D6: te | E6: tm | F6: tq | G6: ice | H6: icm | I6: icd | J6: tms | O6: fixcap | P6: alphava | Q6: ta | R6: tva | W6: tf | X6: wf | Y6: qfs
A7: csorg | B7: eps | C7: eps | D7: eps | E7: eps | F7: eps | G7: eps | H7: eps | I7: eps | J7: eps | N7: asorg | O7: 0 | P7: eps | Q7: eps | R7: eps | V7: flab-rn | W7: eps | X7: eps | Y7: eps
A8: cmaiz | B8: eps | C8: 10 | D8: eps | E8: eps | F8: eps | G8: eps | H8: eps | I8: eps | J8: eps | N8: amaiz | O8: 0 | P8: eps | Q8: eps | R8: eps | V8: flab-rp | W8: eps | X8: eps | Y8: eps
A9: cwhea | B9: eps | C9: 100 | D9: eps | E9: eps | F9: eps | G9: eps | H9: eps | I9: eps | J9: eps | N9: awhea | O9: 0 | P9: eps | Q9: eps | R9: eps | V9: flab-rs | W9: eps | X9: eps | Y9: eps
A10: crice | B10: eps | C10: -13 | D10: eps | E10: eps | F10: eps | G10: eps | H10: eps | I10: eps | J10: eps | N10: arice | O10: 0 | P10: eps | Q10: eps | R10: eps | V10: flab-rt | W10: eps | X10: eps | Y10: eps
A11: cocer | B11: eps | C11: eps | D11: eps | E11: eps | F11: eps | G11: eps | H11: eps | I11: eps | J11: eps | N11: aocer | O11: 0 | P11: eps | Q11: eps | R11: eps | V11: flab-un | W11: eps | X11: eps | Y11: eps
A12: cipot | B12: eps | C12: eps | D12: eps | E12: eps | F12: eps | G12: eps | H12: eps | I12: eps | J12: eps | N12: aipot | O12: 0 | P12: eps | Q12: eps | R12: eps | V12: flab-up | W12: eps | X12: eps | Y12: eps
A13: cspot | B13: eps | C13: eps | D13: eps | E13: eps | F13: eps | G13: eps | H13: eps | I13: eps | J13: eps | N13: aspot | O13: 0 | P13: eps | Q13: eps | R13: eps | V13: flab-us | W13: eps | X13: eps | Y13: eps
A14: ccass | B14: eps | C14: eps | D14: eps | E14: eps | F14: eps | G14: eps | H14: eps | I14: eps | J14: eps | N14: acass | O14: 0 | P14: eps | Q14: eps | R14: eps | V14: flab-ut | W14: eps | X14: eps | Y14: eps
A15: croot | B15: eps | C15: eps | D15: eps | E15: eps | F15: eps | G15: eps | H15: eps | I15: eps | J15: eps | N15: aroot | O15: 0 | P15: eps | Q15: eps | R15: eps | V15: flab-kn | W15: eps | X15: eps | Y15: eps
A16: cbean | B16: eps | C16: eps | D16: eps | E16: eps | F16: eps | G16: eps | H16: eps | I16: eps | J16: eps | N16: abean | O16: 0 | P16: eps | Q16: eps | R16: eps | V16: flab-kp | W16: eps | X16: eps | Y16: eps
A17: cpeas | B17: eps | C17: eps | D17: eps | E17: eps | F17: eps | G17: eps | H17: eps | I17: eps | J17: eps | N17: apeas | O17: 0 | P17: eps | Q17: eps | R17: eps | V17: flab-ks | W17: eps | X17: eps | Y17: eps
A18: cvege | B18: eps | C18: eps | D18: eps | E18: eps | F18: eps | G18: eps | H18: eps | I18: eps | J18: eps | N18: avege | O18: 0 | P18: eps | Q18: eps | R18: eps | V18: flab-kt | W18: eps | X18: eps | Y18: eps
A19: cbanb | B19: eps | C19: eps | D19: eps | E19: eps | F19: eps | G19: eps | H19: eps | I19: eps | J19: eps | N19: abanb | O19: 0 | P19: eps | Q19: eps | R19: eps | V19: flnd | W19: eps | X19: eps | Y19: eps
A20: cbanc | B20: eps | C20: eps | D20: eps | E20: eps | F20: eps | G20: eps | H20: eps | I20: eps | J20: eps | N20: abanc | O20: 0 | P20: eps | Q20: eps | R20: eps | V20: fcap-c | W20: eps | X20: eps | Y20: eps
A21: cbans | B21: eps | C21: eps | D21: eps | E21: eps | F21: eps | G21: eps | H21: eps | I21: eps | J21: eps | N21: abans | O21: 0 | P21: eps | Q21: eps | R21: eps | V21: fcap-l | W21: eps | X21: eps | Y21: eps
A22: cfrui | B22: eps | C22: eps | D22: eps | E22: eps | F22: eps | G22: eps | H22: eps | I22: eps | J22: eps | N22: afrui | O22: 0 | P22: eps | Q22: eps | R22: eps | V22: fcap-m | W22: eps | X22: eps | Y22: eps
A23: cgnut | B23: eps | C23: eps | D23: eps | E23: eps | F23: eps | G23: eps | H23: eps | I23: eps | J23: eps | N23: agnut | O23: 0 | P23: eps | Q23: eps | R23: eps | V23: fcap-n | W23: eps | X23: eps | Y23: eps
A24: csoya | B24: eps | C24: eps | D24: eps | E24: eps | F24: eps | G24: eps | H24: eps | I24: eps | J24: eps | N24: asoya | O24: 0 | P24: eps | Q24: eps | R24: eps
A25: coils | B25: eps | C25: eps | D25: eps | E25: eps | F25: eps | G25: eps | H25: eps | I25: eps | J25: eps | N25: aoils | O25: 0 | P25: eps | Q25: eps | R25: eps | V25: Household income shocks
A26: ccoff | B26: eps | C26: eps | D26: eps | E26: eps | F26: eps | G26: eps | H26: eps | I26: eps | J26: eps | N26: acoff | O26: 0 | P26: eps | Q26: eps | R26: eps | X26: Gov. | Y26: World
A27: cteal | B27: eps | C27: eps | D27: eps | E27: eps | F27: eps | G27: eps | H27: eps | I27: eps | J27: eps | N27: ateal | O27: 0 | P27: eps | Q27: eps | R27: eps | X27: trn | Y27: rem
A28: ctoba | B28: eps | C28: eps | D28: eps | E28: eps | F28: eps | G28: eps | H28: eps | I28: eps | J28: eps | N28: atoba | O28: 0 | P28: eps | Q28: eps | R28: eps | V28: Farm | W28: hhd-r1 | X28: eps | Y28: eps
A29: csugr | B29: eps | C29: eps | D29: eps | E29: eps | F29: eps | G29: eps | H29: eps | I29: eps | J29: eps | N29: asugr | O29: 0 | P29: eps | Q29: eps | R29: eps | W29: hhd-r2 | X29: eps | Y29: eps
A30: cpyre | B30: eps | C30: eps | D30: eps | E30: eps | F30: eps | G30: eps | H30: eps | I30: eps | J30: eps | N30: apyre | O30: 0 | P30: eps | Q30: eps | R30: eps | W30: hhd-r3 | X30: eps | Y30: eps
A31: cocrp | B31: eps | C31: eps | D31: eps | E31: eps | F31: eps | G31: eps | H31: eps | I31: eps | J31: eps | N31: aocrp | O31: 0 | P31: eps | Q31: eps | R31: eps | W31: hhd-r4 | X31: eps | Y31: eps
A32: ccatt | B32: eps | C32: eps | D32: eps | E32: eps | F32: eps | G32: eps | H32: eps | I32: eps | J32: eps | N32: acatt | O32: 0 | P32: eps | Q32: eps | R32: eps | W32: hhd-r5 | X32: eps | Y32: eps
A33: csmlr | B33: eps | C33: eps | D33: eps | E33: eps | F33: eps | G33: eps | H33: eps | I33: eps | J33: eps | N33: asmlr | O33: 0 | P33: eps | Q33: eps | R33: eps | V33: Nonfarm | W33: hhd-u1 | X33: eps | Y33: eps
A34: cpoul | B34: eps | C34: eps | D34: eps | E34: eps | F34: eps | G34: eps | H34: eps | I34: eps | J34: eps | N34: apoul | O34: 0 | P34: eps | Q34: eps | R34: eps | W34: hhd-u2 | X34: eps | Y34: eps
A35: coliv | B35: eps | C35: eps | D35: eps | E35: eps | F35: eps | G35: eps | H35: eps | I35: eps | J35: eps | N35: aoliv | O35: 0 | P35: eps | Q35: eps | R35: eps | W35: hhd-u3 | X35: eps | Y35: eps
A36: cmilk | B36: eps | C36: eps | D36: eps | E36: eps | F36: eps | G36: eps | H36: eps | I36: eps | J36: eps | N36: amilk | O36: 0 | P36: eps | Q36: eps | R36: eps | W36: hhd-u4 | X36: eps | Y36: eps
A37: ceggs | B37: eps | C37: eps | D37: eps | E37: eps | F37: eps | G37: eps | H37: eps | I37: eps | J37: eps | N37: aeggs | O37: 0 | P37: eps | Q37: eps | R37: eps | W37: hhd-u5 | X37: eps | Y37: eps
A38: chony | B38: eps | C38: eps | D38: eps | E38: eps | F38: eps | G38: eps | H38: eps | I38: eps | J38: eps | N38: ahony | O38: 0 | P38: eps | Q38: eps | R38: eps | V38: Urban | W38: hhd-k1 | X38: eps | Y38: eps
A39: chunt | B39: eps | C39: eps | D39: eps | E39: eps | F39: eps | G39: eps | H39: eps | I39: eps | J39: eps | N39: ahunt | O39: 0 | P39: eps | Q39: eps | R39: eps | W39: hhd-k2 | X39: eps | Y39: eps
A40: cfuel | B40: eps | C40: eps | D40: eps | E40: eps | F40: eps | G40: eps | H40: eps | I40: eps | J40: eps | N40: afuel | O40: 0 | P40: eps | Q40: eps | R40: eps | W40: hhd-k3 | X40: eps | Y40: eps
A41: cchar | B41: eps | C41: eps | D41: eps | E41: eps | F41: eps | G41: eps | H41: eps | I41: eps | J41: eps | N41: achar | O41: 0 | P41: eps | Q41: eps | R41: eps | W41: hhd-k4 | X41: eps | Y41: eps
...

Sheet S3
A1: ="Simulation "&Y1&IF(X1<>""," : "&X1,"") -> Simulation Fuel&gas_shk : 50%_incr_cchem | X1: =IF(Main!C6<>"",Main!C6,"") -> 50%_incr_cchem | Y1: =Main!A8 -> Fuel&gas_shk
A3: Commodity shocks | N3: Activity shocks | V3: Factor shocks
B4: World prices | D4: Commodity taxes | G4: Transaction costs | J4: Import | O4: Fix cap? | P4: TFP | Q4: Activity taxes | W4: Factor | X4: Wage | Y4: Factor
B5: Exports | C5: Imports | D5: Exports | E5: Imports | F5: Sales | G5: Exports | H5: Imports | I5: Domestic | J5: subsidy | O5: (1=yes) | Q5: Activity | R5: ValAd. | W5: taxes | X5: rate | Y5: supply
B6: pwe | C6: pwm | D6: te | E6: tm | F6: tq | G6: ice | H6: icm | I6: icd | J6: tms | O6: fixcap | P6: alphava | Q6: ta | R6: tva | W6: tf | X6: wf | Y6: qfs
A7: csorg | B7: eps | C7: eps | D7: eps | E7: eps | F7: eps | G7: eps | H7: eps | I7: eps | J7: eps | N7: asorg | O7: 0 | P7: eps | Q7: eps | R7: eps | V7: flab-rn | W7: eps | X7: eps | Y7: eps
A8: cmaiz | B8: eps | C8: eps | D8: eps | E8: eps | F8: eps | G8: eps | H8: eps | I8: eps | J8: eps | N8: amaiz | O8: 0 | P8: eps | Q8: eps | R8: eps | V8: flab-rp | W8: eps | X8: eps | Y8: eps
A9: cwhea | B9: eps | C9: eps | D9: eps | E9: eps | F9: eps | G9: eps | H9: eps | I9: eps | J9: eps | N9: awhea | O9: 0 | P9: eps | Q9: eps | R9: eps | V9: flab-rs | W9: eps | X9: eps | Y9: eps
A10: crice | B10: eps | C10: eps | D10: eps | E10: eps | F10: eps | G10: eps | H10: eps | I10: eps | J10: eps | N10: arice | O10: 0 | P10: eps | Q10: eps | R10: eps | V10: flab-rt | W10: eps | X10: eps | Y10: eps
A11: cocer | B11: eps | C11: eps | D11: eps | E11: eps | F11: eps | G11: eps | H11: eps | I11: eps | J11: eps | N11: aocer | O11: 0 | P11: eps | Q11: eps | R11: eps | V11: flab-un | W11: eps | X11: eps | Y11: eps
A12: cipot | B12: eps | C12: eps | D12: eps | E12: eps | F12: eps | G12: eps | H12: eps | I12: eps | J12: eps | N12: aipot | O12: 0 | P12: eps | Q12: eps | R12: eps | V12: flab-up | W12: eps | X12: eps | Y12: eps
A13: cspot | B13: eps | C13: eps | D13: eps | E13: eps | F13: eps | G13: eps | H13: eps | I13: eps | J13: eps | N13: aspot | O13: 0 | P13: eps | Q13: eps | R13: eps | V13: flab-us | W13: eps | X13: eps | Y13: eps
A14: ccass | B14: eps | C14: eps | D14: eps | E14: eps | F14: eps | G14: eps | H14: eps | I14: eps | J14: eps | N14: acass | O14: 0 | P14: eps | Q14: eps | R14: eps | V14: flab-ut | W14: eps | X14: eps | Y14: eps
A15: croot | B15: eps | C15: eps | D15: eps | E15: eps | F15: eps | G15: eps | H15: eps | I15: eps | J15: eps | N15: aroot | O15: 0 | P15: eps | Q15: eps | R15: eps | V15: flab-kn | W15: eps | X15: eps | Y15: eps
A16: cbean | B16: eps | C16: eps | D16: eps | E16: eps | F16: eps | G16: eps | H16: eps | I16: eps | J16: eps | N16: abean | O16: 0 | P16: eps | Q16: eps | R16: eps | V16: flab-kp | W16: eps | X16: eps | Y16: eps
A17: cpeas | B17: eps | C17: eps | D17: eps | E17: eps | F17: eps | G17: eps | H17: eps | I17: eps | J17: eps | N17: apeas | O17: 0 | P17: eps | Q17: eps | R17: eps | V17: flab-ks | W17: eps | X17: eps | Y17: eps
A18: cvege | B18: eps | C18: eps | D18: eps | E18: eps | F18: eps | G18: eps | H18: eps | I18: eps | J18: eps | N18: avege | O18: 0 | P18: eps | Q18: eps | R18: eps | V18: flab-kt | W18: eps | X18: eps | Y18: eps
... A23: cgnut | B23: eps | C23: eps | D23: eps | E23: eps | F23: eps | G23: eps | H23: eps | I23: eps | J23: eps | N23: agnut | O23: 0 | P23: eps | Q23: eps | R23: eps | V23: fcap-n | W23: eps | X23: eps | Y23: eps
A24: csoya | B24: eps | C24: eps | D24: eps | E24: eps | F24: eps | G24: eps | H24: eps | I24: eps | J24: eps | N24: asoya | O24: 0 | P24: eps | Q24: eps | R24: eps
A25: coils | B25: eps | C25: eps | D25: eps | E25: eps | F25: eps | G25: eps | H25: eps | I25: eps | J25: eps | N25: aoils | O25: 0 | P25: eps | Q25: eps | R25: eps | V25: Household income shocks
A26: ccoff | B26: eps | C26: eps | D26: eps | E26: eps | F26: eps | G26: eps | H26: eps | I26: eps | J26: eps | N26: acoff | O26: 0 | P26: eps | Q26: eps | R26: eps | X26: Gov. | Y26: World
A27: cteal | B27: eps | C27: eps | D27: eps | E27: eps | F27: eps | G27: eps | H27: eps | I27: eps | J27: eps | N27: ateal | O27: 0 | P27: eps | Q27: eps | R27: eps | X27: trn | Y27: rem
A28: ctoba | B28: eps | C28: eps | D28: eps | E28: eps | F28: eps | G28: eps | H28: eps | I28: eps | J28: eps | N28: atoba | O28: 0 | P28: eps | Q28: eps | R28: eps | V28: Farm | W28: hhd-r1 | X28: eps | Y28: eps
A29: csugr | B29: eps | C29: eps | D29: eps | E29: eps | F29: eps | G29: eps | H29: eps | I29: eps | J29: eps | N29: asugr | O29: 0 | P29: eps | Q29: eps | R29: eps | W29: hhd-r2 | X29: eps | Y29: eps
A30: cpyre | B30: eps | C30: eps | D30: eps | E30: eps | F30: eps | G30: eps | H30: eps | I30: eps | J30: eps | N30: apyre | O30: 0 | P30: eps | Q30: eps | R30: eps | W30: hhd-r3 | X30: eps | Y30: eps
A31: cocrp | B31: eps | C31: eps | D31: eps | E31: eps | F31: eps | G31: eps | H31: eps | I31: eps | J31: eps | N31: aocrp | O31: 0 | P31: eps | Q31: eps | R31: eps | W31: hhd-r4 | X31: eps | Y31: eps
A32: ccatt | B32: eps | C32: eps | D32: eps | E32: eps | F32: eps | G32: eps | H32: eps | I32: eps | J32: eps | N32: acatt | O32: 0 | P32: eps | Q32: eps | R32: eps | W32: hhd-r5 | X32: eps | Y32: eps
A33: csmlr | B33: eps | C33: eps | D33: eps | E33: eps | F33: eps | G33: eps | H33: eps | I33: eps | J33: eps | N33: asmlr | O33: 0 | P33: eps | Q33: eps | R33: eps | V33: Nonfarm | W33: hhd-u1 | X33: eps | Y33: eps
A34: cpoul | B34: eps | C34: eps | D34: eps | E34: eps | F34: eps | G34: eps | H34: eps | I34: eps | J34: eps | N34: apoul | O34: 0 | P34: eps | Q34: eps | R34: eps | W34: hhd-u2 | X34: eps | Y34: eps
A35: coliv | B35: eps | C35: eps | D35: eps | E35: eps | F35: eps | G35: eps | H35: eps | I35: eps | J35: eps | N35: aoliv | O35: 0 | P35: eps | Q35: eps | R35: eps | W35: hhd-u3 | X35: eps | Y35: eps
A36: cmilk | B36: eps | C36: eps | D36: eps | E36: eps | F36: eps | G36: eps | H36: eps | I36: eps | J36: eps | N36: amilk | O36: 0 | P36: eps | Q36: eps | R36: eps | W36: hhd-u4 | X36: eps | Y36: eps
A37: ceggs | B37: eps | C37: eps | D37: eps | E37: eps | F37: eps | G37: eps | H37: eps | I37: eps | J37: eps | N37: aeggs | O37: 0 | P37: eps | Q37: eps | R37: eps | W37: hhd-u5 | X37: eps | Y37: eps
A38: chony | B38: eps | C38: eps | D38: eps | E38: eps | F38: eps | G38: eps | H38: eps | I38: eps | J38: eps | N38: ahony | O38: 0 | P38: eps | Q38: eps | R38: eps | V38: Urban | W38: hhd-k1 | X38: eps | Y38: eps
A39: chunt | B39: eps | C39: eps | D39: eps | E39: eps | F39: eps | G39: eps | H39: eps | I39: eps | J39: eps | N39: ahunt | O39: 0 | P39: eps | Q39: eps | R39: eps | W39: hhd-k2 | X39: eps | Y39: eps
A40: cfuel | B40: eps | C40: eps | D40: eps | E40: eps | F40: eps | G40: eps | H40: eps | I40: eps | J40: eps | N40: afuel | O40: 0 | P40: eps | Q40: eps | R40: eps | W40: hhd-k3 | X40: eps | Y40: eps
A41: cchar | B41: eps | C41: eps | D41: eps | E41: eps | F41: eps | G41: eps | H41: eps | I41: eps | J41: eps | N41: achar | O41: 0 | P41: eps | Q41: eps | R41: eps | W41: hhd-k4 | X41: eps | Y41: eps
A42: cfore | B42: eps | C42: eps | D42: eps | E42: eps | F42: eps | G42: eps | H42: eps | I42: eps | J42: eps | N42: afore | O42: 0 | P42: eps | Q42: eps | R42: eps | W42: hhd-k5 | X42: eps | Y42: eps
A43: cfish | B43: eps | C43: eps | D43: eps | E43: eps | F43: eps | G43: eps | H43: eps | I43: eps | J43: eps | N43: afish | O43: 0 | P43: eps | Q43: eps | R43: eps
A44: cngas | B44: eps | C44: 34 | D44: eps | E44: eps | F44: eps | G44: eps | H44: eps | I44: eps | J44: eps | N44: angas | O44: 0 | P44: eps | Q44: eps | R44: eps | V44: Scalar shocks
A45: cmore | B45: eps | C45: eps | D45: eps | E45: eps | F45: eps | G45: eps | H45: eps | I45: eps | J45: eps | N45: amore | O45: 0 | P45: eps | Q45: eps | R45: eps
...

Sheet S4
A1: ="Simulation "&Y1&IF(X1<>""," : "&X1,"") -> Simulation HH shk : 50%_incr_cchem | X1: =IF(Main!C6<>"",Main!C6,"") -> 50%_incr_cchem | Y1: =Main!A9 -> HH shk
A3: Commodity shocks | N3: Activity shocks | V3: Factor shocks
B4: World prices | D4: Commodity taxes | G4: Transaction costs | J4: Import | O4: Fix cap? | P4: TFP | Q4: Activity taxes | W4: Factor | X4: Wage | Y4: Factor
B5: Exports | C5: Imports | D5: Exports | E5: Imports | F5: Sales | G5: Exports | H5: Imports | I5: Domestic | J5: subsidy | O5: (1=yes) | Q5: Activity | R5: ValAd. | W5: taxes | X5: rate | Y5: supply
B6: pwe | C6: pwm | D6: te | E6: tm | F6: tq | G6: ice | H6: icm | I6: icd | J6: tms | O6: fixcap | P6: alphava | Q6: ta | R6: tva | W6: tf | X6: wf | Y6: qfs
A7: csorg | B7: eps | C7: eps | D7: eps | E7: eps | F7: eps | G7: eps | H7: eps | I7: eps | J7: eps | N7: asorg | O7: 0 | P7: eps | Q7: eps | R7: eps | V7: flab-rn | W7: eps | X7: eps | Y7: eps
A8: cmaiz | B8: eps | C8: 11 | D8: eps | E8: eps | F8: eps | G8: eps | H8: eps | I8: eps | J8: eps | N8: amaiz | O8: 0 | P8: eps | Q8: eps | R8: eps | V8: flab-rp | W8: eps | X8: eps | Y8: eps
A9: cwhea | B9: eps | C9: 100 | D9: eps | E9: eps | F9: eps | G9: eps | H9: eps | I9: eps | J9: eps | N9: awhea | O9: 0 | P9: eps | Q9: eps | R9: eps | V9: flab-rs | W9: eps | X9: eps | Y9: eps
A10: crice | B10: eps | C10: -13 | D10: eps | E10: eps | F10: eps | G10: eps | H10: eps | I10: eps | J10: eps | N10: arice | O10: 0 | P10: eps | Q10: eps | R10: eps | V10: flab-rt | W10: eps | X10: eps | Y10: eps
A11: cocer | B11: eps | C11: eps | D11: eps | E11: eps | F11: eps | G11: eps | H11: eps | I11: eps | J11: eps | N11: aocer | O11: 0 | P11: eps | Q11: eps | R11: eps | V11: flab-un | W11: eps | X11: eps | Y11: eps
A12: cipot | B12: eps | C12: eps | D12: eps | E12: eps | F12: eps | G12: eps | H12: eps | I12: eps | J12: eps | N12: aipot | O12: 0 | P12: eps | Q12: eps | R12: eps | V12: flab-up | W12: eps | X12: eps | Y12: eps
A13: cspot | B13: eps | C13: eps | D13: eps | E13: eps | F13: eps | G13: eps | H13: eps | I13: eps | J13: eps | N13: aspot | O13: 0 | P13: eps | Q13: eps | R13: eps | V13: flab-us | W13: eps | X13: eps | Y13: eps
A14: ccass | B14: eps | C14: eps | D14: eps | E14: eps | F14: eps | G14: eps | H14: eps | I14: eps | J14: eps | N14: acass | O14: 0 | P14: eps | Q14: eps | R14: eps | V14: flab-ut | W14: eps | X14: eps | Y14: eps
A15: croot | B15: eps | C15: eps | D15: eps | E15: eps | F15: eps | G15: eps | H15: eps | I15: eps | J15: eps | N15: aroot | O15: 0 | P15: eps | Q15: eps | R15: eps | V15: flab-kn | W15: eps | X15: eps | Y15: eps
A16: cbean | B16: eps | C16: eps | D16: eps | E16: eps | F16: eps | G16: eps | H16: eps | I16: eps | J16: eps | N16: abean | O16: 0 | P16: eps | Q16: eps | R16: eps | V16: flab-kp | W16: eps | X16: eps | Y16: eps
A17: cpeas | B17: eps | C17: eps | D17: eps | E17: eps | F17: eps | G17: eps | H17: eps | I17: eps | J17: eps | N17: apeas | O17: 0 | P17: eps | Q17: eps | R17: eps | V17: flab-ks | W17: eps | X17: eps | Y17: eps
A18: cvege | B18: eps | C18: eps | D18: eps | E18: eps | F18: eps | G18: eps | H18: eps | I18: eps | J18: eps | N18: avege | O18: 0 | P18: eps | Q18: eps | R18: eps | V18: flab-kt | W18: eps | X18: eps | Y18: eps
A19: cbanb | B19: eps | C19: eps | D19: eps | E19: eps | F19: eps | G19: eps | H19: eps | I19: eps | J19: eps | N19: abanb | O19: 0 | P19: eps | Q19: eps | R19: eps | V19: flnd | W19: eps | X19: eps | Y19: eps
A20: cbanc | B20: eps | C20: eps | D20: eps | E20: eps | F20: eps | G20: eps | H20: eps | I20: eps | J20: eps | N20: abanc | O20: 0 | P20: eps | Q20: eps | R20: eps | V20: fcap-c | W20: eps | X20: eps | Y20: eps
A21: cbans | B21: eps | C21: eps | D21: eps | E21: eps | F21: eps | G21: eps | H21: eps | I21: eps | J21: eps | N21: abans | O21: 0 | P21: eps | Q21: eps | R21: eps | V21: fcap-l | W21: eps | X21: eps | Y21: eps
A22: cfrui | B22: eps | C22: eps | D22: eps | E22: eps | F22: eps | G22: eps | H22: eps | I22: eps | J22: eps | N22: afrui | O22: 0 | P22: eps | Q22: eps | R22: eps | V22: fcap-m | W22: eps | X22: eps | Y22: eps
A23: cgnut | B23: eps | C23: eps | D23: eps | E23: eps | F23: eps | G23: eps | H23: eps | I23: eps | J23: eps | N23: agnut | O23: 0 | P23: eps | Q23: eps | R23: eps | V23: fcap-n | W23: eps | X23: eps | Y23: eps
A24: csoya | B24: eps | C24: eps | D24: eps | E24: eps | F24: eps | G24: eps | H24: eps | I24: eps | J24: eps | N24: asoya | O24: 0 | P24: eps | Q24: eps | R24: eps
A25: coils | B25: eps | C25: eps | D25: eps | E25: eps | F25: eps | G25: eps | H25: eps | I25: eps | J25: eps | N25: aoils | O25: 0 | P25: eps | Q25: eps | R25: eps | V25: Household income shocks
A26: ccoff | B26: eps | C26: eps | D26: eps | E26: eps | F26: eps | G26: eps | H26: eps | I26: eps | J26: eps | N26: acoff | O26: 0 | P26: eps | Q26: eps | R26: eps | X26: Gov. | Y26: World
A27: cteal | B27: eps | C27: eps | D27: eps | E27: eps | F27: eps | G27: eps | H27: eps | I27: eps | J27: eps | N27: ateal | O27: 0 | P27: eps | Q27: eps | R27: eps | X27: trn | Y27: rem
A28: ctoba | B28: eps | C28: eps | D28: eps | E28: eps | F28: eps | G28: eps | H28: eps | I28: eps | J28: eps | N28: atoba | O28: 0 | P28: eps | Q28: eps | R28: eps | V28: Farm | W28: hhd-r1 | X28: eps | Y28: eps
A29: csugr | B29: eps | C29: eps | D29: eps | E29: eps | F29: eps | G29: eps | H29: eps | I29: eps | J29: eps | N29: asugr | O29: 0 | P29: eps | Q29: eps | R29: eps | W29: hhd-r2 | X29: eps | Y29: eps
A30: cpyre | B30: eps | C30: eps | D30: eps | E30: eps | F30: eps | G30: eps | H30: eps | I30: eps | J30: eps | N30: apyre | O30: 0 | P30: eps | Q30: eps | R30: eps | W30: hhd-r3 | X30: eps | Y30: eps
A31: cocrp | B31: eps | C31: eps | D31: eps | E31: eps | F31: eps | G31: eps | H31: eps | I31: eps | J31: eps | N31: aocrp | O31: 0 | P31: eps | Q31: eps | R31: eps | W31: hhd-r4 | X31: eps | Y31: eps
A32: ccatt | B32: eps | C32: eps | D32: eps | E32: eps | F32: eps | G32: eps | H32: eps | I32: eps | J32: eps | N32: acatt | O32: 0 | P32: eps | Q32: eps | R32: eps | W32: hhd-r5 | X32: eps | Y32: eps
A33: csmlr | B33: eps | C33: eps | D33: eps | E33: eps | F33: eps | G33: eps | H33: eps | I33: eps | J33: eps | N33: asmlr | O33: 0 | P33: eps | Q33: eps | R33: eps | V33: Nonfarm | W33: hhd-u1 | X33: eps | Y33: eps
A34: cpoul | B34: eps | C34: eps | D34: eps | E34: eps | F34: eps | G34: eps | H34: eps | I34: eps | J34: eps | N34: apoul | O34: 0 | P34: eps | Q34: eps | R34: eps | W34: hhd-u2 | X34: eps | Y34: eps
A35: coliv | B35: eps | C35: eps | D35: eps | E35: eps | F35: eps | G35: eps | H35: eps | I35: eps | J35: eps | N35: aoliv | O35: 0 | P35: eps | Q35: eps | R35: eps | W35: hhd-u3 | X35: eps | Y35: eps
A36: cmilk | B36: eps | C36: eps | D36: eps | E36: eps | F36: eps | G36: eps | H36: eps | I36: eps | J36: eps | N36: amilk | O36: 0 | P36: eps | Q36: eps | R36: eps | W36: hhd-u4 | X36: eps | Y36: eps
A37: ceggs | B37: eps | C37: eps | D37: eps | E37: eps | F37: eps | G37: eps | H37: eps | I37: eps | J37: eps | N37: aeggs | O37: 0 | P37: eps | Q37: eps | R37: eps | W37: hhd-u5 | X37: eps | Y37: eps
A38: chony | B38: eps | C38: eps | D38: eps | E38: eps | F38: eps | G38: eps | H38: eps | I38: eps | J38: eps | N38: ahony | O38: 0 | P38: eps | Q38: eps | R38: eps | V38: Urban | W38: hhd-k1 | X38: eps | Y38: eps
A39: chunt | B39: eps | C39: eps | D39: eps | E39: eps | F39: eps | G39: eps | H39: eps | I39: eps | J39: eps | N39: ahunt | O39: 0 | P39: eps | Q39: eps | R39: eps | W39: hhd-k2 | X39: eps | Y39: eps
A40: cfuel | B40: eps | C40: eps | D40: eps | E40: eps | F40: eps | G40: eps | H40: eps | I40: eps | J40: eps | N40: afuel | O40: 0 | P40: eps | Q40: eps | R40: eps | W40: hhd-k3 | X40: eps | Y40: eps
A41: cchar | B41: eps | C41: eps | D41: eps | E41: eps | F41: eps | G41: eps | H41: eps | I41: eps | J41: eps | N41: achar | O41: 0 | P41: eps | Q41: eps | R41: eps | W41: hhd-k4 | X41: eps | Y41: eps
...

Sheet S5
A1: ="Simulation "&Y1&IF(X1<>""," : "&X1,"") -> Simulation sim5 : 50%_incr_cchem | X1: =IF(Main!C6<>"",Main!C6,"") -> 50%_incr_cchem | Y1: =Main!A10 -> sim5
A3: Commodity shocks | N3: Activity shocks | V3: Factor shocks
B4: World prices | D4: Commodity taxes | G4: Transaction costs | J4: Import | O4: Fix cap? | P4: TFP | Q4: Activity taxes | W4: Factor | X4: Wage | Y4: Factor
B5: Exports | C5: Imports | D5: Exports | E5: Imports | F5: Sales | G5: Exports | H5: Imports | I5: Domestic | J5: subsidy | O5: (1=yes) | Q5: Activity | R5: ValAd. | W5: taxes | X5: rate | Y5: supply
B6: pwe | C6: pwm | D6: te | E6: tm | F6: tq | G6: ice | H6: icm | I6: icd | J6: tms | O6: fixcap | P6: alphava | Q6: ta | R6: tva | W6: tf | X6: wf | Y6: qfs
A7: csorg | B7: eps | C7: eps | D7: eps | E7: eps | F7: eps | G7: eps | H7: eps | I7: eps | J7: eps | N7: asorg | O7: 0 | P7: eps | Q7: eps | R7: eps | V7: flab-rn | W7: eps | X7: eps | Y7: eps
A8: cmaiz | B8: eps | C8: eps | D8: eps | E8: eps | F8: eps | G8: eps | H8: eps | I8: eps | J8: eps | N8: amaiz | O8: 0 | P8: eps | Q8: eps | R8: eps | V8: flab-rp | W8: eps | X8: eps | Y8: eps
A9: cwhea | B9: eps | C9: eps | D9: eps | E9: eps | F9: eps | G9: eps | H9: eps | I9: eps | J9: eps | N9: awhea | O9: 0 | P9: eps | Q9: eps | R9: eps | V9: flab-rs | W9: eps | X9: eps | Y9: eps
A10: crice | B10: eps | C10: eps | D10: eps | E10: eps | F10: eps | G10: eps | H10: eps | I10: eps | J10: eps | N10: arice | O10: 0 | P10: eps | Q10: eps | R10: eps | V10: flab-rt | W10: eps | X10: eps | Y10: eps
A11: cocer | B11: eps | C11: eps | D11: eps | E11: eps | F11: eps | G11: eps | H11: eps | I11: eps | J11: eps | N11: aocer | O11: 0 | P11: eps | Q11: eps | R11: eps | V11: flab-un | W11: eps | X11: eps | Y11: eps
A12: cipot | B12: eps | C12: eps | D12: eps | E12: eps | F12: eps | G12: eps | H12: eps | I12: eps | J12: eps | N12: aipot | O12: 0 | P12: eps | Q12: eps | R12: eps | V12: flab-up | W12: eps | X12: eps | Y12: eps
A13: cspot | B13: eps | C13: eps | D13: eps | E13: eps | F13: eps | G13: eps | H13: eps | I13: eps | J13: eps | N13: aspot | O13: 0 | P13: eps | Q13: eps | R13: eps | V13: flab-us | W13: eps | X13: eps | Y13: eps
A14: ccass | B14: eps | C14: eps | D14: eps | E14: eps | F14: eps | G14: eps | H14: eps | I14: eps | J14: eps | N14: acass | O14: 0 | P14: eps | Q14: eps | R14: eps | V14: flab-ut | W14: eps | X14: eps | Y14: eps
A15: croot | B15: eps | C15: eps | D15: eps | E15: eps | F15: eps | G15: eps | H15: eps | I15: eps | J15: eps | N15: aroot | O15: 0 | P15: eps | Q15: eps | R15: eps | V15: flab-kn | W15: eps | X15: eps | Y15: eps
A16: cbean | B16: eps | C16: eps | D16: eps | E16: eps | F16: eps | G16: eps | H16: eps | I16: eps | J16: eps | N16: abean | O16: 0 | P16: eps | Q16: eps | R16: eps | V16: flab-kp | W16: eps | X16: eps | Y16: eps
A17: cpeas | B17: eps | C17: eps | D17: eps | E17: eps | F17: eps | G17: eps | H17: eps | I17: eps | J17: eps | N17: apeas | O17: 0 | P17: eps | Q17: eps | R17: eps | V17: flab-ks | W17: eps | X17: eps | Y17: eps
A18: cvege | B18: eps | C18: eps | D18: eps | E18: eps | F18: eps | G18: eps | H18: eps | I18: eps | J18: eps | N18: avege | O18: 0 | P18: eps | Q18: eps | R18: eps | V18: flab-kt | W18: eps | X18: eps | Y18: eps
... A23: cgnut | B23: eps | C23: eps | D23: eps | E23: eps | F23: eps | G23: eps | H23: eps | I23: eps | J23: eps | N23: agnut | O23: 0 | P23: eps | Q23: eps | R23: eps | V23: fcap-n | W23: eps | X23: eps | Y23: eps
A24: csoya | B24: eps | C24: eps | D24: eps | E24: eps | F24: eps | G24: eps | H24: eps | I24: eps | J24: eps | N24: asoya | O24: 0 | P24: eps | Q24: eps | R24: eps
A25: coils | B25: eps | C25: eps | D25: eps | E25: eps | F25: eps | G25: eps | H25: eps | I25: eps | J25: eps | N25: aoils | O25: 0 | P25: eps | Q25: eps | R25: eps | V25: Household income shocks
A26: ccoff | B26: eps | C26: eps | D26: eps | E26: eps | F26: eps | G26: eps | H26: eps | I26: eps | J26: eps | N26: acoff | O26: 0 | P26: eps | Q26: eps | R26: eps | X26: Gov. | Y26: World
A27: cteal | B27: eps | C27: eps | D27: eps | E27: eps | F27: eps | G27: eps | H27: eps | I27: eps | J27: eps | N27: ateal | O27: 0 | P27: eps | Q27: eps | R27: eps | X27: trn | Y27: rem
A28: ctoba | B28: eps | C28: eps | D28: eps | E28: eps | F28: eps | G28: eps | H28: eps | I28: eps | J28: eps | N28: atoba | O28: 0 | P28: eps | Q28: eps | R28: eps | V28: Farm | W28: hhd-r1 | X28: eps | Y28: eps
A29: csugr | B29: eps | C29: eps | D29: eps | E29: eps | F29: eps | G29: eps | H29: eps | I29: eps | J29: eps | N29: asugr | O29: 0 | P29: eps | Q29: eps | R29: eps | W29: hhd-r2 | X29: eps | Y29: eps
A30: cpyre | B30: eps | C30: eps | D30: eps | E30: eps | F30: eps | G30: eps | H30: eps | I30: eps | J30: eps | N30: apyre | O30: 0 | P30: eps | Q30: eps | R30: eps | W30: hhd-r3 | X30: eps | Y30: eps
A31: cocrp | B31: eps | C31: eps | D31: eps | E31: eps | F31: eps | G31: eps | H31: eps | I31: eps | J31: eps | N31: aocrp | O31: 0 | P31: eps | Q31: eps | R31: eps | W31: hhd-r4 | X31: eps | Y31: eps
A32: ccatt | B32: eps | C32: eps | D32: eps | E32: eps | F32: eps | G32: eps | H32: eps | I32: eps | J32: eps | N32: acatt | O32: 0 | P32: eps | Q32: eps | R32: eps | W32: hhd-r5 | X32: eps | Y32: eps
A33: csmlr | B33: eps | C33: eps | D33: eps | E33: eps | F33: eps | G33: eps | H33: eps | I33: eps | J33: eps | N33: asmlr | O33: 0 | P33: eps | Q33: eps | R33: eps | V33: Nonfarm | W33: hhd-u1 | X33: eps | Y33: eps
A34: cpoul | B34: eps | C34: eps | D34: eps | E34: eps | F34: eps | G34: eps | H34: eps | I34: eps | J34: eps | N34: apoul | O34: 0 | P34: eps | Q34: eps | R34: eps | W34: hhd-u2 | X34: eps | Y34: eps
A35: coliv | B35: eps | C35: eps | D35: eps | E35: eps | F35: eps | G35: eps | H35: eps | I35: eps | J35: eps | N35: aoliv | O35: 0 | P35: eps | Q35: eps | R35: eps | W35: hhd-u3 | X35: eps | Y35: eps
A36: cmilk | B36: eps | C36: eps | D36: eps | E36: eps | F36: eps | G36: eps | H36: eps | I36: eps | J36: eps | N36: amilk | O36: 0 | P36: eps | Q36: eps | R36: eps | W36: hhd-u4 | X36: eps | Y36: eps
A37: ceggs | B37: eps | C37: eps | D37: eps | E37: eps | F37: eps | G37: eps | H37: eps | I37: eps | J37: eps | N37: aeggs | O37: 0 | P37: eps | Q37: eps | R37: eps | W37: hhd-u5 | X37: eps | Y37: eps
A38: chony | B38: eps | C38: eps | D38: eps | E38: eps | F38: eps | G38: eps | H38: eps | I38: eps | J38: eps | N38: ahony | O38: 0 | P38: eps | Q38: eps | R38: eps | V38: Urban | W38: hhd-k1 | X38: eps | Y38: eps
A39: chunt | B39: eps | C39: eps | D39: eps | E39: eps | F39: eps | G39: eps | H39: eps | I39: eps | J39: eps | N39: ahunt | O39: 0 | P39: eps | Q39: eps | R39: eps | W39: hhd-k2 | X39: eps | Y39: eps
A40: cfuel | B40: eps | C40: eps | D40: eps | E40: eps | F40: eps | G40: eps | H40: eps | I40: eps | J40: eps | N40: afuel | O40: 0 | P40: eps | Q40: eps | R40: eps | W40: hhd-k3 | X40: eps | Y40: eps
A41: cchar | B41: eps | C41: eps | D41: eps | E41: eps | F41: eps | G41: eps | H41: eps | I41: eps | J41: eps | N41: achar | O41: 0 | P41: eps | Q41: eps | R41: eps | W41: hhd-k4 | X41: eps | Y41: eps
A42: cfore | B42: eps | C42: eps | D42: eps | E42: eps | F42: eps | G42: eps | H42: eps | I42: eps | J42: eps | N42: afore | O42: 0 | P42: eps | Q42: eps | R42: eps | W42: hhd-k5 | X42: eps | Y42: eps
A43: cfish | B43: eps | C43: eps | D43: eps | E43: eps | F43: eps | G43: eps | H43: eps | I43: eps | J43: eps | N43: afish | O43: 0 | P43: eps | Q43: eps | R43: eps
A44: cngas | B44: eps | C44: eps | D44: eps | E44: eps | F44: eps | G44: eps | H44: eps | I44: eps | J44: eps | N44: angas | O44: 0 | P44: eps | Q44: eps | R44: eps | V44: Scalar shocks
A45: cmore | B45: eps | C45: eps | D45: eps | E45: eps | F45: eps | G45: eps | H45: eps | I45: eps | J45: eps | N45: amore | O45: 0 | P45: eps | Q45: eps | R45: eps
...

Sheet S6
A1: ="Simulation "&Y1&IF(X1<>""," : "&X1,"") -> Simulation sim6 : 50%_incr_cchem | X1: =IF(Main!C6<>"",Main!C6,"") -> 50%_incr_cchem | Y1: =Main!A11 -> sim6
A3: Commodity shocks | N3: Activity shocks | V3: Factor shocks
B4: World prices | D4: Commodity taxes | G4: Transaction costs | J4: Import | O4: Fix cap? | P4: TFP | Q4: Activity taxes | W4: Factor | X4: Wage | Y4: Factor
B5: Exports | C5: Imports | D5: Exports | E5: Imports | F5: Sales | G5: Exports | H5: Imports | I5: Domestic | J5: subsidy | O5: (1=yes) | Q5: Activity | R5: ValAd. | W5: taxes | X5: rate | Y5: supply
B6: pwe | C6: pwm | D6: te | E6: tm | F6: tq | G6: ice | H6: icm | I6: icd | J6: tms | O6: fixcap | P6: alphava | Q6: ta | R6: tva | W6: tf | X6: wf | Y6: qfs
A7: csorg | B7: eps | C7: eps | D7: eps | E7: eps | F7: eps | G7: eps | H7: eps | I7: eps | J7: eps | N7: asorg | O7: 0 | P7: eps | Q7: eps | R7: eps | V7: flab-rn | W7: eps | X7: eps | Y7: eps
A8: cmaiz | B8: eps | C8: eps | D8: eps | E8: eps | F8: eps | G8: eps | H8: eps | I8: eps | J8: eps | N8: amaiz | O8: 0 | P8: eps | Q8: eps | R8: eps | V8: flab-rp | W8: eps | X8: eps | Y8: eps
A9: cwhea | B9: eps | C9: eps | D9: eps | E9: eps | F9: eps | G9: eps | H9: eps | I9: eps | J9: eps | N9: awhea | O9: 0 | P9: eps | Q9: eps | R9: eps | V9: flab-rs | W9: eps | X9: eps | Y9: eps
A10: crice | B10: eps | C10: eps | D10: eps | E10: eps | F10: eps | G10: eps | H10: eps | I10: eps | J10: eps | N10: arice | O10: 0 | P10: eps | Q10: eps | R10: eps | V10: flab-rt | W10: eps | X10: eps | Y10: eps
A11: cocer | B11: eps | C11: eps | D11: eps | E11: eps | F11: eps | G11: eps | H11: eps | I11: eps | J11: eps | N11: aocer | O11: 0 | P11: eps | Q11: eps | R11: eps | V11: flab-un | W11: eps | X11: eps | Y11: eps
A12: cipot | B12: eps | C12: eps | D12: eps | E12: eps | F12: eps | G12: eps | H12: eps | I12: eps | J12: eps | N12: aipot | O12: 0 | P12: eps | Q12: eps | R12: eps | V12: flab-up | W12: eps | X12: eps | Y12: eps
A13: cspot | B13: eps | C13: eps | D13: eps | E13: eps | F13: eps | G13: eps | H13: eps | I13: eps | J13: eps | N13: aspot | O13: 0 | P13: eps | Q13: eps | R13: eps | V13: flab-us | W13: eps | X13: eps | Y13: eps
A14: ccass | B14: eps | C14: eps | D14: eps | E14: eps | F14: eps | G14: eps | H14: eps | I14: eps | J14: eps | N14: acass | O14: 0 | P14: eps | Q14: eps | R14: eps | V14: flab-ut | W14: eps | X14: eps | Y14: eps
A15: croot | B15: eps | C15: eps | D15: eps | E15: eps | F15: eps | G15: eps | H15: eps | I15: eps | J15: eps | N15: aroot | O15: 0 | P15: eps | Q15: eps | R15: eps | V15: flab-kn | W15: eps | X15: eps | Y15: eps
A16: cbean | B16: eps | C16: eps | D16: eps | E16: eps | F16: eps | G16: eps | H16: eps | I16: eps | J16: eps | N16: abean | O16: 0 | P16: eps | Q16: eps | R16: eps | V16: flab-kp | W16: eps | X16: eps | Y16: eps
A17: cpeas | B17: eps | C17: eps | D17: eps | E17: eps | F17: eps | G17: eps | H17: eps | I17: eps | J17: eps | N17: apeas | O17: 0 | P17: eps | Q17: eps | R17: eps | V17: flab-ks | W17: eps | X17: eps | Y17: eps
A18: cvege | B18: eps | C18: eps | D18: eps | E18: eps | F18: eps | G18: eps | H18: eps | I18: eps | J18: eps | N18: avege | O18: 0 | P18: eps | Q18: eps | R18: eps | V18: flab-kt | W18: eps | X18: eps | Y18: eps
... A23: cgnut | B23: eps | C23: eps | D23: eps | E23: eps | F23: eps | G23: eps | H23: eps | I23: eps | J23: eps | N23: agnut | O23: 0 | P23: eps | Q23: eps | R23: eps | V23: fcap-n | W23: eps | X23: eps | Y23: eps
A24: csoya | B24: eps | C24: eps | D24: eps | E24: eps | F24: eps | G24: eps | H24: eps | I24: eps | J24: eps | N24: asoya | O24: 0 | P24: eps | Q24: eps | R24: eps
A25: coils | B25: eps | C25: eps | D25: eps | E25: eps | F25: eps | G25: eps | H25: eps | I25: eps | J25: eps | N25: aoils | O25: 0 | P25: eps | Q25: eps | R25: eps | V25: Household income shocks
A26: ccoff | B26: eps | C26: eps | D26: eps | E26: eps | F26: eps | G26: eps | H26: eps | I26: eps | J26: eps | N26: acoff | O26: 0 | P26: eps | Q26: eps | R26: eps | X26: Gov. | Y26: World
A27: cteal | B27: eps | C27: eps | D27: eps | E27: eps | F27: eps | G27: eps | H27: eps | I27: eps | J27: eps | N27: ateal | O27: 0 | P27: eps | Q27: eps | R27: eps | X27: trn | Y27: rem
A28: ctoba | B28: eps | C28: eps | D28: eps | E28: eps | F28: eps | G28: eps | H28: eps | I28: eps | J28: eps | N28: atoba | O28: 0 | P28: eps | Q28: eps | R28: eps | V28: Farm | W28: hhd-r1 | X28: eps | Y28: eps
A29: csugr | B29: eps | C29: eps | D29: eps | E29: eps | F29: eps | G29: eps | H29: eps | I29: eps | J29: eps | N29: asugr | O29: 0 | P29: eps | Q29: eps | R29: eps | W29: hhd-r2 | X29: eps | Y29: eps
A30: cpyre | B30: eps | C30: eps | D30: eps | E30: eps | F30: eps | G30: eps | H30: eps | I30: eps | J30: eps | N30: apyre | O30: 0 | P30: eps | Q30: eps | R30: eps | W30: hhd-r3 | X30: eps | Y30: eps
A31: cocrp | B31: eps | C31: eps | D31: eps | E31: eps | F31: eps | G31: eps | H31: eps | I31: eps | J31: eps | N31: aocrp | O31: 0 | P31: eps | Q31: eps | R31: eps | W31: hhd-r4 | X31: eps | Y31: eps
A32: ccatt | B32: eps | C32: eps | D32: eps | E32: eps | F32: eps | G32: eps | H32: eps | I32: eps | J32: eps | N32: acatt | O32: 0 | P32: eps | Q32: eps | R32: eps | W32: hhd-r5 | X32: eps | Y32: eps
A33: csmlr | B33: eps | C33: eps | D33: eps | E33: eps | F33: eps | G33: eps | H33: eps | I33: eps | J33: eps | N33: asmlr | O33: 0 | P33: eps | Q33: eps | R33: eps | V33: Nonfarm | W33: hhd-u1 | X33: eps | Y33: eps
A34: cpoul | B34: eps | C34: eps | D34: eps | E34: eps | F34: eps | G34: eps | H34: eps | I34: eps | J34: eps | N34: apoul | O34: 0 | P34: eps | Q34: eps | R34: eps | W34: hhd-u2 | X34: eps | Y34: eps
A35: coliv | B35: eps | C35: eps | D35: eps | E35: eps | F35: eps | G35: eps | H35: eps | I35: eps | J35: eps | N35: aoliv | O35: 0 | P35: eps | Q35: eps | R35: eps | W35: hhd-u3 | X35: eps | Y35: eps
A36: cmilk | B36: eps | C36: eps | D36: eps | E36: eps | F36: eps | G36: eps | H36: eps | I36: eps | J36: eps | N36: amilk | O36: 0 | P36: eps | Q36: eps | R36: eps | W36: hhd-u4 | X36: eps | Y36: eps
A37: ceggs | B37: eps | C37: eps | D37: eps | E37: eps | F37: eps | G37: eps | H37: eps | I37: eps | J37: eps | N37: aeggs | O37: 0 | P37: eps | Q37: eps | R37: eps | W37: hhd-u5 | X37: eps | Y37: eps
A38: chony | B38: eps | C38: eps | D38: eps | E38: eps | F38: eps | G38: eps | H38: eps | I38: eps | J38: eps | N38: ahony | O38: 0 | P38: eps | Q38: eps | R38: eps | V38: Urban | W38: hhd-k1 | X38: eps | Y38: eps
A39: chunt | B39: eps | C39: eps | D39: eps | E39: eps | F39: eps | G39: eps | H39: eps | I39: eps | J39: eps | N39: ahunt | O39: 0 | P39: eps | Q39: eps | R39: eps | W39: hhd-k2 | X39: eps | Y39: eps
A40: cfuel | B40: eps | C40: eps | D40: eps | E40: eps | F40: eps | G40: eps | H40: eps | I40: eps | J40: eps | N40: afuel | O40: 0 | P40: eps | Q40: eps | R40: eps | W40: hhd-k3 | X40: eps | Y40: eps
A41: cchar | B41: eps | C41: eps | D41: eps | E41: eps | F41: eps | G41: eps | H41: eps | I41: eps | J41: eps | N41: achar | O41: 0 | P41: eps | Q41: eps | R41: eps | W41: hhd-k4 | X41: eps | Y41: eps
A42: cfore | B42: eps | C42: eps | D42: eps | E42: eps | F42: eps | G42: eps | H42: eps | I42: eps | J42: eps | N42: afore | O42: 0 | P42: eps | Q42: eps | R42: eps | W42: hhd-k5 | X42: eps | Y42: eps
A43: cfish | B43: eps | C43: eps | D43: eps | E43: eps | F43: eps | G43: eps | H43: eps | I43: eps | J43: eps | N43: afish | O43: 0 | P43: eps | Q43: eps | R43: eps
A44: cngas | B44: eps | C44: eps | D44: eps | E44: eps | F44: eps | G44: eps | H44: eps | I44: eps | J44: eps | N44: angas | O44: 0 | P44: eps | Q44: eps | R44: eps | V44: Scalar shocks
A45: cmore | B45: eps | C45: eps | D45: eps | E45: eps | F45: eps | G45: eps | H45: eps | I45: eps | J45: eps | N45: amore | O45: 0 | P45: eps | Q45: eps | R45: eps
...

Sheet S7
A1: ="Simulation "&Y1&IF(X1<>""," : "&X1,"") -> Simulation sim7 : 50%_incr_cchem | X1: =IF(Main!C6<>"",Main!C6,"") -> 50%_incr_cchem | Y1: =Main!A12 -> sim7
A3: Commodity shocks | N3: Activity shocks | V3: Factor shocks
B4: World prices | D4: Commodity taxes | G4: Transaction costs | J4: Import | O4: Fix cap? | P4: TFP | Q4: Activity taxes | W4: Factor | X4: Wage | Y4: Factor
B5: Exports | C5: Imports | D5: Exports | E5: Imports | F5: Sales | G5: Exports | H5: Imports | I5: Domestic | J5: subsidy | O5: (1=yes) | Q5: Activity | R5: ValAd. | W5: taxes | X5: rate | Y5: supply
B6: pwe | C6: pwm | D6: te | E6: tm | F6: tq | G6: ice | H6: icm | I6: icd | J6: tms | O6: fixcap | P6: alphava | Q6: ta | R6: tva | W6: tf | X6: wf | Y6: qfs
A7: csorg | B7: eps | C7: eps | D7: eps | E7: eps | F7: eps | G7: eps | H7: eps | I7: eps | J7: eps | N7: asorg | O7: 0 | P7: eps | Q7: eps | R7: eps | V7: flab-rn | W7: eps | X7: eps | Y7: eps
A8: cmaiz | B8: eps | C8: eps | D8: eps | E8: eps | F8: eps | G8: eps | H8: eps | I8: eps | J8: eps | N8: amaiz | O8: 0 | P8: eps | Q8: eps | R8: eps | V8: flab-rp | W8: eps | X8: eps | Y8: eps
A9: cwhea | B9: eps | C9: eps | D9: eps | E9: eps | F9: eps | G9: eps | H9: eps | I9: eps | J9: eps | N9: awhea | O9: 0 | P9: eps | Q9: eps | R9: eps | V9: flab-rs | W9: eps | X9: eps | Y9: eps
A10: crice | B10: eps | C10: eps | D10: eps | E10: eps | F10: eps | G10: eps | H10: eps | I10: eps | J10: eps | N10: arice | O10: 0 | P10: eps | Q10: eps | R10: eps | V10: flab-rt | W10: eps | X10: eps | Y10: eps
A11: cocer | B11: eps | C11: eps | D11: eps | E11: eps | F11: eps | G11: eps | H11: eps | I11: eps | J11: eps | N11: aocer | O11: 0 | P11: eps | Q11: eps | R11: eps | V11: flab-un | W11: eps | X11: eps | Y11: eps
A12: cipot | B12: eps | C12: eps | D12: eps | E12: eps | F12: eps | G12: eps | H12: eps | I12: eps | J12: eps | N12: aipot | O12: 0 | P12: eps | Q12: eps | R12: eps | V12: flab-up | W12: eps | X12: eps | Y12: eps
A13: cspot | B13: eps | C13: eps | D13: eps | E13: eps | F13: eps | G13: eps | H13: eps | I13: eps | J13: eps | N13: aspot | O13: 0 | P13: eps | Q13: eps | R13: eps | V13: flab-us | W13: eps | X13: eps | Y13: eps
A14: ccass | B14: eps | C14: eps | D14: eps | E14: eps | F14: eps | G14: eps | H14: eps | I14: eps | J14: eps | N14: acass | O14: 0 | P14: eps | Q14: eps | R14: eps | V14: flab-ut | W14: eps | X14: eps | Y14: eps
A15: croot | B15: eps | C15: eps | D15: eps | E15: eps | F15: eps | G15: eps | H15: eps | I15: eps | J15: eps | N15: aroot | O15: 0 | P15: eps | Q15: eps | R15: eps | V15: flab-kn | W15: eps | X15: eps | Y15: eps
A16: cbean | B16: eps | C16: eps | D16: eps | E16: eps | F16: eps | G16: eps | H16: eps | I16: eps | J16: eps | N16: abean | O16: 0 | P16: eps | Q16: eps | R16: eps | V16: flab-kp | W16: eps | X16: eps | Y16: eps
A17: cpeas | B17: eps | C17: eps | D17: eps | E17: eps | F17: eps | G17: eps | H17: eps | I17: eps | J17: eps | N17: apeas | O17: 0 | P17: eps | Q17: eps | R17: eps | V17: flab-ks | W17: eps | X17: eps | Y17: eps
A18: cvege | B18: eps | C18: eps | D18: eps | E18: eps | F18: eps | G18: eps | H18: eps | I18: eps | J18: eps | N18: avege | O18: 0 | P18: eps | Q18: eps | R18: eps | V18: flab-kt | W18: eps | X18: eps | Y18: eps
... A23: cgnut | B23: eps | C23: eps | D23: eps | E23: eps | F23: eps | G23: eps | H23: eps | I23: eps | J23: eps | N23: agnut | O23: 0 | P23: eps | Q23: eps | R23: eps | V23: fcap-n | W23: eps | X23: eps | Y23: eps
A24: csoya | B24: eps | C24: eps | D24: eps | E24: eps | F24: eps | G24: eps | H24: eps | I24: eps | J24: eps | N24: asoya | O24: 0 | P24: eps | Q24: eps | R24: eps
A25: coils | B25: eps | C25: eps | D25: eps | E25: eps | F25: eps | G25: eps | H25: eps | I25: eps | J25: eps | N25: aoils | O25: 0 | P25: eps | Q25: eps | R25: eps | V25: Household income shocks
A26: ccoff | B26: eps | C26: eps | D26: eps | E26: eps | F26: eps | G26: eps | H26: eps | I26: eps | J26: eps | N26: acoff | O26: 0 | P26: eps | Q26: eps | R26: eps | X26: Gov. | Y26: World
A27: cteal | B27: eps | C27: eps | D27: eps | E27: eps | F27: eps | G27: eps | H27: eps | I27: eps | J27: eps | N27: ateal | O27: 0 | P27: eps | Q27: eps | R27: eps | X27: trn | Y27: rem
A28: ctoba | B28: eps | C28: eps | D28: eps | E28: eps | F28: eps | G28: eps | H28: eps | I28: eps | J28: eps | N28: atoba | O28: 0 | P28: eps | Q28: eps | R28: eps | V28: Farm | W28: hhd-r1 | X28: eps | Y28: eps
A29: csugr | B29: eps | C29: eps | D29: eps | E29: eps | F29: eps | G29: eps | H29: eps | I29: eps | J29: eps | N29: asugr | O29: 0 | P29: eps | Q29: eps | R29: eps | W29: hhd-r2 | X29: eps | Y29: eps
A30: cpyre | B30: eps | C30: eps | D30: eps | E30: eps | F30: eps | G30: eps | H30: eps | I30: eps | J30: eps | N30: apyre | O30: 0 | P30: eps | Q30: eps | R30: eps | W30: hhd-r3 | X30: eps | Y30: eps
A31: cocrp | B31: eps | C31: eps | D31: eps | E31: eps | F31: eps | G31: eps | H31: eps | I31: eps | J31: eps | N31: aocrp | O31: 0 | P31: eps | Q31: eps | R31: eps | W31: hhd-r4 | X31: eps | Y31: eps
A32: ccatt | B32: eps | C32: eps | D32: eps | E32: eps | F32: eps | G32: eps | H32: eps | I32: eps | J32: eps | N32: acatt | O32: 0 | P32: eps | Q32: eps | R32: eps | W32: hhd-r5 | X32: eps | Y32: eps
A33: csmlr | B33: eps | C33: eps | D33: eps | E33: eps | F33: eps | G33: eps | H33: eps | I33: eps | J33: eps | N33: asmlr | O33: 0 | P33: eps | Q33: eps | R33: eps | V33: Nonfarm | W33: hhd-u1 | X33: eps | Y33: eps
A34: cpoul | B34: eps | C34: eps | D34: eps | E34: eps | F34: eps | G34: eps | H34: eps | I34: eps | J34: eps | N34: apoul | O34: 0 | P34: eps | Q34: eps | R34: eps | W34: hhd-u2 | X34: eps | Y34: eps
A35: coliv | B35: eps | C35: eps | D35: eps | E35: eps | F35: eps | G35: eps | H35: eps | I35: eps | J35: eps | N35: aoliv | O35: 0 | P35: eps | Q35: eps | R35: eps | W35: hhd-u3 | X35: eps | Y35: eps
